Workbook

Sheet 6511(당일)
A1: 기준일 | B1: =TODAY() -> 46036
M2: IMDH(Market, Code, Field, StartDay, EndDay, Count, Option)
A3: 순서 | B3: 대륙구분 | C3: 국가명 | D3: 지수명 | E3: 코드 | F3: 시가 | G3: 고가 | H3: 저가 | I3: 종가 | J3: 전일대비 | M3: =_xll.IMDH("FRN",E19,"현재가","2024-12-30","2024-01-14") -> 조회[VNI:VIDX]
A4: 1 | B4: 아시아 | C4: 뉴질랜드 | D4: NZX50 | E4: NZI:NZ50 | F4: =_xll.IMDP("FRN",$E4,F$3,$B$1) -> 0 | G4: =_xll.IMDP("FRN",$E4,G$3,$B$1) -> 0 | H4: =_xll.IMDP("FRN",$E4,H$3,$B$1) -> 0 | I4: =_xll.IMDP("FRN",$E4,I$3,$B$1) -> 13656.05 | J4: =_xll.IMDP("FRN",$E4,J$3,$B$1) -> 0
A5: 2 | B5: 아시아 | C5: 호주 | D5: ALL ORDS | E5: AUI:AORD | F5: =_xll.IMDP("FRN",$E5,F$3,$B$1) -> 9127.6 | G5: =_xll.IMDP("FRN",$E5,G$3,$B$1) -> 9185.5 | H5: =_xll.IMDP("FRN",$E5,H$3,$B$1) -> 9118.7 | I5: =_xll.IMDP("FRN",$E5,I$3,$B$1) -> 9138.49 | J5: =_xll.IMDP("FRN",$E5,J$3,$B$1) -> 45.84
A6: 3 | B6: 아시아 | C6: 일본 | D6: NIKKEI225 | E6: NII:NI225 | F6: =_xll.IMDP("FRN",$E6,F$3,$B$1) -> 53827.24 | G6: =_xll.IMDP("FRN",$E6,G$3,$B$1) -> 54487.32 | H6: =_xll.IMDP("FRN",$E6,H$3,$B$1) -> 53792.68 | I6: =_xll.IMDP("FRN",$E6,I$3,$B$1) -> 54179.59 | J6: =_xll.IMDP("FRN",$E6,J$3,$B$1) -> 630.43
A7: 4 | B7: 아시아 | C7: 대만 | D7: TAIEX | E7: TWS:TI01 | F7: =_xll.IMDP("FRN",$E7,F$3,$B$1) -> 30742.53 | G7: =_xll.IMDP("FRN",$E7,G$3,$B$1) -> 30994.81 | H7: =_xll.IMDP("FRN",$E7,H$3,$B$1) -> 30742.53 | I7: =_xll.IMDP("FRN",$E7,I$3,$B$1) -> 30884.39 | J7: =_xll.IMDP("FRN",$E7,J$3,$B$1) -> 177.17
A8: 5 | B8: 아시아 | C8: 싱가포르 | D8: STI | E8: SGI:STI | F8: =_xll.IMDP("FRN",$E8,F$3,$B$1) -> 4800.99 | G8: =_xll.IMDP("FRN",$E8,G$3,$B$1) -> 4807.07 | H8: =_xll.IMDP("FRN",$E8,H$3,$B$1) -> 4786.42 | I8: =_xll.IMDP("FRN",$E8,I$3,$B$1) -> 4806.27 | J8: =_xll.IMDP("FRN",$E8,J$3,$B$1) -> -0.86
A9: 6 | B9: 아시아 | C9: 말레이시아 | D9: KLCI | E9: MYI:KLSE | F9: =_xll.IMDP("FRN",$E9,F$3,$B$1) -> 1705.88 | G9: =_xll.IMDP("FRN",$E9,G$3,$B$1) -> 1711.66 | H9: =_xll.IMDP("FRN",$E9,H$3,$B$1) -> 1704.03 | I9: =_xll.IMDP("FRN",$E9,I$3,$B$1) -> 1707.22 | J9: =_xll.IMDP("FRN",$E9,J$3,$B$1) -> -0.98
A10: 7 | B10: 아시아 | C10: 필리핀 | D10: PSEi | E10: PHI:COMP | F10: =_xll.IMDP("FRN",$E10,F$3,$B$1) -> 0 | G10: =_xll.IMDP("FRN",$E10,G$3,$B$1) -> 0 | H10: =_xll.IMDP("FRN",$E10,H$3,$B$1) -> 0 | I10: =_xll.IMDP("FRN",$E10,I$3,$B$1) -> 6419.96 | J10: =_xll.IMDP("FRN",$E10,J$3,$B$1) -> 0
A11: 8 | B11: 아시아 | C11: 중국(상해종합) | D11: SSE Composite Shares | E11: SHS:000001 | F11: =_xll.IMDP("FRN",$E11,F$3,$B$1) -> 4138.65 | G11: =_xll.IMDP("FRN",$E11,G$3,$B$1) -> 4190.87 | H11: =_xll.IMDP("FRN",$E11,H$3,$B$1) -> 4138.65 | I11: =_xll.IMDP("FRN",$E11,I$3,$B$1) -> 4188.24 | J11: =_xll.IMDP("FRN",$E11,J$3,$B$1) -> 49.48
A12: 9 | B12: 아시아 | C12: 중국(심천종합) | D12: Shezhen Composite Index | E12: SZS:399106 | F12: =_xll.IMDP("FRN",$E12,F$3,$B$1) -> 2677.69 | G12: =_xll.IMDP("FRN",$E12,G$3,$B$1) -> 2733.18 | H12: =_xll.IMDP("FRN",$E12,H$3,$B$1) -> 2677.69 | I12: =_xll.IMDP("FRN",$E12,I$3,$B$1) -> 2733.02 | J12: =_xll.IMDP("FRN",$E12,J$3,$B$1) -> 56.98
A13: 10 | B13: 아시아 | C13: 중국(CSI 300) | D13: CSI 300 | E13: SHS:000300 | F13: =_xll.IMDP("FRN",$E13,F$3,$B$1) -> 4767.7 | G13: =_xll.IMDP("FRN",$E13,G$3,$B$1) -> 4818.1 | H13: =_xll.IMDP("FRN",$E13,H$3,$B$1) -> 4767.7 | I13: =_xll.IMDP("FRN",$E13,I$3,$B$1) -> 4812.48 | J13: =_xll.IMDP("FRN",$E13,J$3,$B$1) -> 51.45
A14: 11 | B14: 아시아 | C14: 홍콩(항셍) | D14: HSI | E14: HSI:HSI | F14: =_xll.IMDP("FRN",$E14,F$3,$B$1) -> 26971.97 | G14: =_xll.IMDP("FRN",$E14,G$3,$B$1) -> 27097.72 | H14: =_xll.IMDP("FRN",$E14,H$3,$B$1) -> 26852.57 | I14: =_xll.IMDP("FRN",$E14,I$3,$B$1) -> 27092.98 | J14: =_xll.IMDP("FRN",$E14,J$3,$B$1) -> 244.51
A15: 12 | B15: 아시아 | C15: 홍콩(항셍 H) | D15: HSI-H | E15: HSI:HSCE | F15: =_xll.IMDP("FRN",$E15,F$3,$B$1) -> 9328.05 | G15: =_xll.IMDP("FRN",$E15,G$3,$B$1) -> 9370.33 | H15: =_xll.IMDP("FRN",$E15,H$3,$B$1) -> 9272.24 | I15: =_xll.IMDP("FRN",$E15,I$3,$B$1) -> 9367.28 | J15: =_xll.IMDP("FRN",$E15,J$3,$B$1) -> 81.87
... A65: 62 | B65: 아메리카 | C65: 콜롬비아 | D65: COLUMBIA IGBC | E65: COI:IGBC | F65: =_xll.IMDP("FRN",$E65,F$3,$B$1) -> 2188.74 | G65: =_xll.IMDP("FRN",$E65,G$3,$B$1) -> 2213.35 | H65: =_xll.IMDP("FRN",$E65,H$3,$B$1) -> 2181.5 | I65: =_xll.IMDP("FRN",$E65,I$3,$B$1) -> 2213.35 | J65: =_xll.IMDP("FRN",$E65,J$3,$B$1) -> 26.28

Sheet 6511 (일주일)
A1: 6511 확인 | F1: =TEXT(F2,"AAA") -> 수 | G1: =TEXT(G2,"AAA") -> 화 | H1: =TEXT(H2,"AAA") -> 월 | I1: =TEXT(I2,"AAA") -> 일 | J1: =TEXT(J2,"AAA") -> 토 | K1: =TEXT(K2,"AAA") -> 금 | L1: =TEXT(L2,"AAA") -> 목 | M1: =TEXT(M2,"AAA") -> 수 | ... S1: =TEXT(S2,"AAA") -> 목
A2: 순서 | B2: 대륙구분 | C2: 국가명 | D2: 지수명 | E2: 코드 | F2: ='6511 (히스토리)'!G15 -> 46036 | G2: =F2-1 -> 46035 | H2: =G2-1 -> 46034 | I2: =H2-1 -> 46033 | J2: =I2-1 -> 46032 | K2: =J2-1 -> 46031 | L2: =K2-1 -> 46030 | M2: =L2-1 -> 46029 | N2: =M2-1 -> 46028 | ... S2: =R2-1 -> 46023
A3: 1 | B3: 아시아 | C3: 뉴질랜드 | D3: NZX50 | E3: NZI:NZ50 | F3: {=SUMPRODUCT(('6511 (히스토리)'!$G$15:$G$34='6511 (일주일)'!F$2)*('6511 (히스토리)'!$H$15:$H$34))} -> 1901.02 | G3: {=SUMPRODUCT(('6511 (히스토리)'!$G$15:$G$34='6511 (일주일)'!G$2)*('6511 (히스토리)'!$H$15:$H$34))} -> 1902.93 | H3: {=SUMPRODUCT(('6511 (히스토리)'!$G$15:$G$34='6511 (일주일)'!H$2)*('6511 (히스토리)'!$H$15:$H$34))} -> 1877.33 | I3: {=SUMPRODUCT(('6511 (히스토리)'!$G$15:$G$34='6511 (일주일)'!I$2)*('6511 (히스토리)'!$H$15:$H$34))} -> 0 | J3: {=SUMPRODUCT(('6511 (히스토리)'!$G$15:$G$34='6511 (일주일)'!J$2)*('6511 (히스토리)'!$H$15:$H$34))} -> 0 | K3: {=SUMPRODUCT(('6511 (히스토리)'!$G$15:$G$34='6511 (일주일)'!K$2)*('6511 (히스토리)'!$H$15:$H$34))} -> 1867.9 | L3: {=SUMPRODUCT(('6511 (히스토리)'!$G$15:$G$34='6511 (일주일)'!L$2)*('6511 (히스토리)'!$H$15:$H$34))} -> 1855.56 | M3: {=SUMPRODUCT(('6511 (히스토리)'!$G$15:$G$34='6511 (일주일)'!M$2)*('6511 (히스토리)'!$H$15:$H$34))} -> 1861.58 | ... S3: {=SUMPRODUCT(('6511 (히스토리)'!$G$15:$G$34='6511 (일주일)'!S$2)*('6511 (히스토리)'!$H$15:$H$34))} -> 0
A4: 2 | B4: 아시아 | C4: 호주 | D4: ALL ORDS | E4: AUI:AORD | F4: {=SUMPRODUCT(('6511 (히스토리)'!$I$15:$I$34='6511 (일주일)'!F$2)*('6511 (히스토리)'!$J$15:$J$34))} -> 9138.5 | G4: {=SUMPRODUCT(('6511 (히스토리)'!$I$15:$I$34='6511 (일주일)'!G$2)*('6511 (히스토리)'!$J$15:$J$34))} -> 9138.49 | H4: {=SUMPRODUCT(('6511 (히스토리)'!$I$15:$I$34='6511 (일주일)'!H$2)*('6511 (히스토리)'!$J$15:$J$34))} -> 9092.65 | I4: {=SUMPRODUCT(('6511 (히스토리)'!$I$15:$I$34='6511 (일주일)'!I$2)*('6511 (히스토리)'!$J$15:$J$34))} -> 0 | J4: {=SUMPRODUCT(('6511 (히스토리)'!$I$15:$I$34='6511 (일주일)'!J$2)*('6511 (히스토리)'!$J$15:$J$34))} -> 0 | K4: {=SUMPRODUCT(('6511 (히스토리)'!$I$15:$I$34='6511 (일주일)'!K$2)*('6511 (히스토리)'!$J$15:$J$34))} -> 9045.92 | L4: {=SUMPRODUCT(('6511 (히스토리)'!$I$15:$I$34='6511 (일주일)'!L$2)*('6511 (히스토리)'!$J$15:$J$34))} -> 9046.52 | M4: {=SUMPRODUCT(('6511 (히스토리)'!$I$15:$I$34='6511 (일주일)'!M$2)*('6511 (히스토리)'!$J$15:$J$34))} -> 9018 | ... S4: {=SUMPRODUCT(('6511 (히스토리)'!$I$15:$I$34='6511 (일주일)'!S$2)*('6511 (히스토리)'!$J$15:$J$34))} -> 0
A5: 3 | B5: 아시아 | C5: 일본 | D5: NIKKEI225 | E5: NII:NI225 | F5: {=SUMPRODUCT(('6511 (히스토리)'!$K$15:$K$34='6511 (일주일)'!F$2)*('6511 (히스토리)'!$L$15:$L$34))} -> 54179.59 | G5: {=SUMPRODUCT(('6511 (히스토리)'!$K$15:$K$34='6511 (일주일)'!G$2)*('6511 (히스토리)'!$L$15:$L$34))} -> 53549.16 | H5: {=SUMPRODUCT(('6511 (히스토리)'!$K$15:$K$34='6511 (일주일)'!H$2)*('6511 (히스토리)'!$L$15:$L$34))} -> 0 | I5: {=SUMPRODUCT(('6511 (히스토리)'!$K$15:$K$34='6511 (일주일)'!I$2)*('6511 (히스토리)'!$L$15:$L$34))} -> 0 | J5: {=SUMPRODUCT(('6511 (히스토리)'!$K$15:$K$34='6511 (일주일)'!J$2)*('6511 (히스토리)'!$L$15:$L$34))} -> 0 | K5: {=SUMPRODUCT(('6511 (히스토리)'!$K$15:$K$34='6511 (일주일)'!K$2)*('6511 (히스토리)'!$L$15:$L$34))} -> 51939.89 | L5: {=SUMPRODUCT(('6511 (히스토리)'!$K$15:$K$34='6511 (일주일)'!L$2)*('6511 (히스토리)'!$L$15:$L$34))} -> 51117.26 | M5: {=SUMPRODUCT(('6511 (히스토리)'!$K$15:$K$34='6511 (일주일)'!M$2)*('6511 (히스토리)'!$L$15:$L$34))} -> 51961.98 | ... S5: {=SUMPRODUCT(('6511 (히스토리)'!$K$15:$K$34='6511 (일주일)'!S$2)*('6511 (히스토리)'!$L$15:$L$34))} -> 0
A6: 4 | B6: 아시아 | C6: 대만 | D6: TAIEX | E6: TWS:TI01 | F6: {=SUMPRODUCT(('6511 (히스토리)'!$M$15:$M$34='6511 (일주일)'!F$2)*('6511 (히스토리)'!$N$15:$N$34))} -> 30884.39 | G6: {=SUMPRODUCT(('6511 (히스토리)'!$M$15:$M$34='6511 (일주일)'!G$2)*('6511 (히스토리)'!$N$15:$N$34))} -> 30707.22 | H6: {=SUMPRODUCT(('6511 (히스토리)'!$M$15:$M$34='6511 (일주일)'!H$2)*('6511 (히스토리)'!$N$15:$N$34))} -> 30567.29 | I6: {=SUMPRODUCT(('6511 (히스토리)'!$M$15:$M$34='6511 (일주일)'!I$2)*('6511 (히스토리)'!$N$15:$N$34))} -> 0 | J6: {=SUMPRODUCT(('6511 (히스토리)'!$M$15:$M$34='6511 (일주일)'!J$2)*('6511 (히스토리)'!$N$15:$N$34))} -> 0 | K6: {=SUMPRODUCT(('6511 (히스토리)'!$M$15:$M$34='6511 (일주일)'!K$2)*('6511 (히스토리)'!$N$15:$N$34))} -> 30288.96 | L6: {=SUMPRODUCT(('6511 (히스토리)'!$M$15:$M$34='6511 (일주일)'!L$2)*('6511 (히스토리)'!$N$15:$N$34))} -> 30360.55 | M6: {=SUMPRODUCT(('6511 (히스토리)'!$M$15:$M$34='6511 (일주일)'!M$2)*('6511 (히스토리)'!$N$15:$N$34))} -> 30435.47 | ... S6: {=SUMPRODUCT(('6511 (히스토리)'!$M$15:$M$34='6511 (일주일)'!S$2)*('6511 (히스토리)'!$N$15:$N$34))} -> 0
A7: 5 | B7: 아시아 | C7: 싱가포르 | D7: STI | E7: SGI:STI | F7: {=SUMPRODUCT(('6511 (히스토리)'!$O$15:$O$34='6511 (일주일)'!F$2)*('6511 (히스토리)'!$P$15:$P$34))} -> 4806.27 | G7: {=SUMPRODUCT(('6511 (히스토리)'!$O$15:$O$34='6511 (일주일)'!G$2)*('6511 (히스토리)'!$P$15:$P$34))} -> 4807.13 | H7: {=SUMPRODUCT(('6511 (히스토리)'!$O$15:$O$34='6511 (일주일)'!H$2)*('6511 (히스토리)'!$P$15:$P$34))} -> 4766.78 | I7: {=SUMPRODUCT(('6511 (히스토리)'!$O$15:$O$34='6511 (일주일)'!I$2)*('6511 (히스토리)'!$P$15:$P$34))} -> 0 | J7: {=SUMPRODUCT(('6511 (히스토리)'!$O$15:$O$34='6511 (일주일)'!J$2)*('6511 (히스토리)'!$P$15:$P$34))} -> 0 | K7: {=SUMPRODUCT(('6511 (히스토리)'!$O$15:$O$34='6511 (일주일)'!K$2)*('6511 (히스토리)'!$P$15:$P$34))} -> 4744.66 | L7: {=SUMPRODUCT(('6511 (히스토리)'!$O$15:$O$34='6511 (일주일)'!L$2)*('6511 (히스토리)'!$P$15:$P$34))} -> 4739.07 | M7: {=SUMPRODUCT(('6511 (히스토리)'!$O$15:$O$34='6511 (일주일)'!M$2)*('6511 (히스토리)'!$P$15:$P$34))} -> 4747.62 | ... S7: {=SUMPRODUCT(('6511 (히스토리)'!$O$15:$O$34='6511 (일주일)'!S$2)*('6511 (히스토리)'!$P$15:$P$34))} -> 0
A8: 6 | B8: 아시아 | C8: 말레이시아 | D8: KLCI | E8: MYI:KLSE | F8: {=SUMPRODUCT(('6511 (히스토리)'!$Q$15:$Q$34='6511 (일주일)'!F$2)*('6511 (히스토리)'!$R$15:$R$34))} -> 1707.22 | G8: {=SUMPRODUCT(('6511 (히스토리)'!$Q$15:$Q$34='6511 (일주일)'!G$2)*('6511 (히스토리)'!$R$15:$R$34))} -> 1708.2 | H8: {=SUMPRODUCT(('6511 (히스토리)'!$Q$15:$Q$34='6511 (일주일)'!H$2)*('6511 (히스토리)'!$R$15:$R$34))} -> 1695.44 | I8: {=SUMPRODUCT(('6511 (히스토리)'!$Q$15:$Q$34='6511 (일주일)'!I$2)*('6511 (히스토리)'!$R$15:$R$34))} -> 0 | J8: {=SUMPRODUCT(('6511 (히스토리)'!$Q$15:$Q$34='6511 (일주일)'!J$2)*('6511 (히스토리)'!$R$15:$R$34))} -> 0 | K8: {=SUMPRODUCT(('6511 (히스토리)'!$Q$15:$Q$34='6511 (일주일)'!K$2)*('6511 (히스토리)'!$R$15:$R$34))} -> 1686.54 | L8: {=SUMPRODUCT(('6511 (히스토리)'!$Q$15:$Q$34='6511 (일주일)'!L$2)*('6511 (히스토리)'!$R$15:$R$34))} -> 1669.57 | M8: {=SUMPRODUCT(('6511 (히스토리)'!$Q$15:$Q$34='6511 (일주일)'!M$2)*('6511 (히스토리)'!$R$15:$R$34))} -> 1676.83 | ... S8: {=SUMPRODUCT(('6511 (히스토리)'!$Q$15:$Q$34='6511 (일주일)'!S$2)*('6511 (히스토리)'!$R$15:$R$34))} -> 0
A9: 7 | B9: 아시아 | C9: 필리핀 | D9: PSEi | E9: PHI:COMP | F9: {=SUMPRODUCT(('6511 (히스토리)'!$S$15:$S$34='6511 (일주일)'!F$2)*('6511 (히스토리)'!$T$15:$T$34))} -> 6419.96 | G9: {=SUMPRODUCT(('6511 (히스토리)'!$S$15:$S$34='6511 (일주일)'!G$2)*('6511 (히스토리)'!$T$15:$T$34))} -> 6408.76 | H9: {=SUMPRODUCT(('6511 (히스토리)'!$S$15:$S$34='6511 (일주일)'!H$2)*('6511 (히스토리)'!$T$15:$T$34))} -> 6419.96 | I9: {=SUMPRODUCT(('6511 (히스토리)'!$S$15:$S$34='6511 (일주일)'!I$2)*('6511 (히스토리)'!$T$15:$T$34))} -> 0 | J9: {=SUMPRODUCT(('6511 (히스토리)'!$S$15:$S$34='6511 (일주일)'!J$2)*('6511 (히스토리)'!$T$15:$T$34))} -> 0 | K9: {=SUMPRODUCT(('6511 (히스토리)'!$S$15:$S$34='6511 (일주일)'!K$2)*('6511 (히스토리)'!$T$15:$T$34))} -> 6348.14 | L9: {=SUMPRODUCT(('6511 (히스토리)'!$S$15:$S$34='6511 (일주일)'!L$2)*('6511 (히스토리)'!$T$15:$T$34))} -> 6320.67 | M9: {=SUMPRODUCT(('6511 (히스토리)'!$S$15:$S$34='6511 (일주일)'!M$2)*('6511 (히스토리)'!$T$15:$T$34))} -> 6292.09 | ... S9: {=SUMPRODUCT(('6511 (히스토리)'!$S$15:$S$34='6511 (일주일)'!S$2)*('6511 (히스토리)'!$T$15:$T$34))} -> 0
A10: 8 | B10: 아시아 | C10: 중국(상해종합) | D10: SSE Composite Shares | E10: SHS:000001 | F10: {=SUMPRODUCT(('6511 (히스토리)'!$U$15:$U$34='6511 (일주일)'!F$2)*('6511 (히스토리)'!$V$15:$V$34))} -> 4188.24 | G10: {=SUMPRODUCT(('6511 (히스토리)'!$U$15:$U$34='6511 (일주일)'!G$2)*('6511 (히스토리)'!$V$15:$V$34))} -> 4138.76 | H10: {=SUMPRODUCT(('6511 (히스토리)'!$U$15:$U$34='6511 (일주일)'!H$2)*('6511 (히스토리)'!$V$15:$V$34))} -> 4165.29 | I10: {=SUMPRODUCT(('6511 (히스토리)'!$U$15:$U$34='6511 (일주일)'!I$2)*('6511 (히스토리)'!$V$15:$V$34))} -> 0 | J10: {=SUMPRODUCT(('6511 (히스토리)'!$U$15:$U$34='6511 (일주일)'!J$2)*('6511 (히스토리)'!$V$15:$V$34))} -> 0 | K10: {=SUMPRODUCT(('6511 (히스토리)'!$U$15:$U$34='6511 (일주일)'!K$2)*('6511 (히스토리)'!$V$15:$V$34))} -> 4120.43 | L10: {=SUMPRODUCT(('6511 (히스토리)'!$U$15:$U$34='6511 (일주일)'!L$2)*('6511 (히스토리)'!$V$15:$V$34))} -> 4082.98 | M10: {=SUMPRODUCT(('6511 (히스토리)'!$U$15:$U$34='6511 (일주일)'!M$2)*('6511 (히스토리)'!$V$15:$V$34))} -> 4085.77 | ... S10: {=SUMPRODUCT(('6511 (히스토리)'!$U$15:$U$34='6511 (일주일)'!S$2)*('6511 (히스토리)'!$V$15:$V$34))} -> 0
A11: 9 | B11: 아시아 | C11: 중국(심천종합) | D11: Shezhen Composite Index | E11: SZS:399106 | F11: {=SUMPRODUCT(('6511 (히스토리)'!$W$15:$W$34='6511 (일주일)'!F$2)*('6511 (히스토리)'!$X$15:$X$34))} -> 2733.02 | G11: {=SUMPRODUCT(('6511 (히스토리)'!$W$15:$W$34='6511 (일주일)'!G$2)*('6511 (히스토리)'!$X$15:$X$34))} -> 2676.04 | H11: {=SUMPRODUCT(('6511 (히스토리)'!$W$15:$W$34='6511 (일주일)'!H$2)*('6511 (히스토리)'!$X$15:$X$34))} -> 2714.52 | I11: {=SUMPRODUCT(('6511 (히스토리)'!$W$15:$W$34='6511 (일주일)'!I$2)*('6511 (히스토리)'!$X$15:$X$34))} -> 0 | J11: {=SUMPRODUCT(('6511 (히스토리)'!$W$15:$W$34='6511 (일주일)'!J$2)*('6511 (히스토리)'!$X$15:$X$34))} -> 0 | K11: {=SUMPRODUCT(('6511 (히스토리)'!$W$15:$W$34='6511 (일주일)'!K$2)*('6511 (히스토리)'!$X$15:$X$34))} -> 2660.05 | L11: {=SUMPRODUCT(('6511 (히스토리)'!$W$15:$W$34='6511 (일주일)'!L$2)*('6511 (히스토리)'!$X$15:$X$34))} -> 2624.99 | M11: {=SUMPRODUCT(('6511 (히스토리)'!$W$15:$W$34='6511 (일주일)'!M$2)*('6511 (히스토리)'!$X$15:$X$34))} -> 2620.52 | ... S11: {=SUMPRODUCT(('6511 (히스토리)'!$W$15:$W$34='6511 (일주일)'!S$2)*('6511 (히스토리)'!$X$15:$X$34))} -> 0
A12: 10 | B12: 아시아 | C12: 중국(CSI 300) | D12: CSI 300 | E12: SHS:000300 | F12: {=SUMPRODUCT(('6511 (히스토리)'!$Y$15:$Y$34='6511 (일주일)'!F$2)*('6511 (히스토리)'!$Z$15:$Z$34))} -> 4812.48 | G12: {=SUMPRODUCT(('6511 (히스토리)'!$Y$15:$Y$34='6511 (일주일)'!G$2)*('6511 (히스토리)'!$Z$15:$Z$34))} -> 4761.03 | H12: {=SUMPRODUCT(('6511 (히스토리)'!$Y$15:$Y$34='6511 (일주일)'!H$2)*('6511 (히스토리)'!$Z$15:$Z$34))} -> 4789.92 | I12: {=SUMPRODUCT(('6511 (히스토리)'!$Y$15:$Y$34='6511 (일주일)'!I$2)*('6511 (히스토리)'!$Z$15:$Z$34))} -> 0 | J12: {=SUMPRODUCT(('6511 (히스토리)'!$Y$15:$Y$34='6511 (일주일)'!J$2)*('6511 (히스토리)'!$Z$15:$Z$34))} -> 0 | K12: {=SUMPRODUCT(('6511 (히스토리)'!$Y$15:$Y$34='6511 (일주일)'!K$2)*('6511 (히스토리)'!$Z$15:$Z$34))} -> 4758.92 | L12: {=SUMPRODUCT(('6511 (히스토리)'!$Y$15:$Y$34='6511 (일주일)'!L$2)*('6511 (히스토리)'!$Z$15:$Z$34))} -> 4737.65 | M12: {=SUMPRODUCT(('6511 (히스토리)'!$Y$15:$Y$34='6511 (일주일)'!M$2)*('6511 (히스토리)'!$Z$15:$Z$34))} -> 4776.67 | ... S12: {=SUMPRODUCT(('6511 (히스토리)'!$Y$15:$Y$34='6511 (일주일)'!S$2)*('6511 (히스토리)'!$Z$15:$Z$34))} -> 0
A13: 11 | B13: 아시아 | C13: 홍콩(항셍) | D13: HIS | E13: HSI:HSI | F13: {=SUMPRODUCT(('6511 (히스토리)'!$AA$15:$AA$34='6511 (일주일)'!F$2)*('6511 (히스토리)'!$AB$15:$AB$34))} -> 27092.98 | G13: {=SUMPRODUCT(('6511 (히스토리)'!$AA$15:$AA$34='6511 (일주일)'!G$2)*('6511 (히스토리)'!$AB$15:$AB$34))} -> 26848.47 | H13: {=SUMPRODUCT(('6511 (히스토리)'!$AA$15:$AA$34='6511 (일주일)'!H$2)*('6511 (히스토리)'!$AB$15:$AB$34))} -> 26608.48 | I13: {=SUMPRODUCT(('6511 (히스토리)'!$AA$15:$AA$34='6511 (일주일)'!I$2)*('6511 (히스토리)'!$AB$15:$AB$34))} -> 0 | J13: {=SUMPRODUCT(('6511 (히스토리)'!$AA$15:$AA$34='6511 (일주일)'!J$2)*('6511 (히스토리)'!$AB$15:$AB$34))} -> 0 | K13: {=SUMPRODUCT(('6511 (히스토리)'!$AA$15:$AA$34='6511 (일주일)'!K$2)*('6511 (히스토리)'!$AB$15:$AB$34))} -> 26231.79 | L13: {=SUMPRODUCT(('6511 (히스토리)'!$AA$15:$AA$34='6511 (일주일)'!L$2)*('6511 (히스토리)'!$AB$15:$AB$34))} -> 26149.31 | M13: {=SUMPRODUCT(('6511 (히스토리)'!$AA$15:$AA$34='6511 (일주일)'!M$2)*('6511 (히스토리)'!$AB$15:$AB$34))} -> 26458.95 | ... S13: {=SUMPRODUCT(('6511 (히스토리)'!$AA$15:$AA$34='6511 (일주일)'!S$2)*('6511 (히스토리)'!$AB$15:$AB$34))} -> 0
A14: 12 | B14: 아시아 | C14: 홍콩(항셍 H) | D14: HSI-H | E14: HSI:HSCE | F14: {=SUMPRODUCT(('6511 (히스토리)'!$AC$15:$AC$34='6511 (일주일)'!F$2)*('6511 (히스토리)'!$AD$15:$AD$34))} -> 9367.28 | G14: {=SUMPRODUCT(('6511 (히스토리)'!$AC$15:$AC$34='6511 (일주일)'!G$2)*('6511 (히스토리)'!$AD$15:$AD$34))} -> 9285.41 | H14: {=SUMPRODUCT(('6511 (히스토리)'!$AC$15:$AC$34='6511 (일주일)'!H$2)*('6511 (히스토리)'!$AD$15:$AD$34))} -> 9220.08 | I14: {=SUMPRODUCT(('6511 (히스토리)'!$AC$15:$AC$34='6511 (일주일)'!I$2)*('6511 (히스토리)'!$AD$15:$AD$34))} -> 0 | J14: {=SUMPRODUCT(('6511 (히스토리)'!$AC$15:$AC$34='6511 (일주일)'!J$2)*('6511 (히스토리)'!$AD$15:$AD$34))} -> 0 | K14: {=SUMPRODUCT(('6511 (히스토리)'!$AC$15:$AC$34='6511 (일주일)'!K$2)*('6511 (히스토리)'!$AD$15:$AD$34))} -> 9048.53 | L14: {=SUMPRODUCT(('6511 (히스토리)'!$AC$15:$AC$34='6511 (일주일)'!L$2)*('6511 (히스토리)'!$AD$15:$AD$34))} -> 9039.34 | M14: {=SUMPRODUCT(('6511 (히스토리)'!$AC$15:$AC$34='6511 (일주일)'!M$2)*('6511 (히스토리)'!$AD$15:$AD$34))} -> 9138.75 | ... S14: {=SUMPRODUCT(('6511 (히스토리)'!$AC$15:$AC$34='6511 (일주일)'!S$2)*('6511 (히스토리)'!$AD$15:$AD$34))} -> 0
A15: 13 | B15: 아시아 | C15: 인도네시아 | D15: IHSG | E15: IDI:JKSE | F15: {=SUMPRODUCT(('6511 (히스토리)'!$AE$15:$AE$34='6511 (일주일)'!F$2)*('6511 (히스토리)'!$AF$15:$AF$34))} -> 9025.76 | G15: {=SUMPRODUCT(('6511 (히스토리)'!$AE$15:$AE$34='6511 (일주일)'!G$2)*('6511 (히스토리)'!$AF$15:$AF$34))} -> 8948.3 | H15: {=SUMPRODUCT(('6511 (히스토리)'!$AE$15:$AE$34='6511 (일주일)'!H$2)*('6511 (히스토리)'!$AF$15:$AF$34))} -> 8884.72 | I15: {=SUMPRODUCT(('6511 (히스토리)'!$AE$15:$AE$34='6511 (일주일)'!I$2)*('6511 (히스토리)'!$AF$15:$AF$34))} -> 0 | J15: {=SUMPRODUCT(('6511 (히스토리)'!$AE$15:$AE$34='6511 (일주일)'!J$2)*('6511 (히스토리)'!$AF$15:$AF$34))} -> 0 | K15: {=SUMPRODUCT(('6511 (히스토리)'!$AE$15:$AE$34='6511 (일주일)'!K$2)*('6511 (히스토리)'!$AF$15:$AF$34))} -> 8936.75 | L15: {=SUMPRODUCT(('6511 (히스토리)'!$AE$15:$AE$34='6511 (일주일)'!L$2)*('6511 (히스토리)'!$AF$15:$AF$34))} -> 8925.47 | M15: {=SUMPRODUCT(('6511 (히스토리)'!$AE$15:$AE$34='6511 (일주일)'!M$2)*('6511 (히스토리)'!$AF$15:$AF$34))} -> 8944.81 | ... S15: {=SUMPRODUCT(('6511 (히스토리)'!$AE$15:$AE$34='6511 (일주일)'!S$2)*('6511 (히스토리)'!$AF$15:$AF$34))} -> 0
A16: 14 | B16: 아시아 | C16: 태국 | D16: SET Index | E16: THI:SET | F16: {=SUMPRODUCT(('6511 (히스토리)'!$AG$15:$AG$34='6511 (일주일)'!F$2)*('6511 (히스토리)'!$AH$15:$AH$34))} -> 0 | G16: {=SUMPRODUCT(('6511 (히스토리)'!$AG$15:$AG$34='6511 (일주일)'!G$2)*('6511 (히스토리)'!$AH$15:$AH$34))} -> 1235.3 | H16: {=SUMPRODUCT(('6511 (히스토리)'!$AG$15:$AG$34='6511 (일주일)'!H$2)*('6511 (히스토리)'!$AH$15:$AH$34))} -> 1242.2 | I16: {=SUMPRODUCT(('6511 (히스토리)'!$AG$15:$AG$34='6511 (일주일)'!I$2)*('6511 (히스토리)'!$AH$15:$AH$34))} -> 0 | J16: {=SUMPRODUCT(('6511 (히스토리)'!$AG$15:$AG$34='6511 (일주일)'!J$2)*('6511 (히스토리)'!$AH$15:$AH$34))} -> 0 | K16: {=SUMPRODUCT(('6511 (히스토리)'!$AG$15:$AG$34='6511 (일주일)'!K$2)*('6511 (히스토리)'!$AH$15:$AH$34))} -> 1254.09 | L16: {=SUMPRODUCT(('6511 (히스토리)'!$AG$15:$AG$34='6511 (일주일)'!L$2)*('6511 (히스토리)'!$AH$15:$AH$34))} -> 1253.6 | M16: {=SUMPRODUCT(('6511 (히스토리)'!$AG$15:$AG$34='6511 (일주일)'!M$2)*('6511 (히스토리)'!$AH$15:$AH$34))} -> 1280.82 | ... S16: {=SUMPRODUCT(('6511 (히스토리)'!$AG$15:$AG$34='6511 (일주일)'!S$2)*('6511 (히스토리)'!$AH$15:$AH$34))} -> 0
A17: 15 | B17: 아시아 | C17: 인도 | D17: SENSEX | E17: INI:BSE30 | F17: {=SUMPRODUCT(('6511 (히스토리)'!$AI$15:$AI$34='6511 (일주일)'!F$2)*('6511 (히스토리)'!$AJ$15:$AJ$34))} -> 83523.65 | G17: {=SUMPRODUCT(('6511 (히스토리)'!$AI$15:$AI$34='6511 (일주일)'!G$2)*('6511 (히스토리)'!$AJ$15:$AJ$34))} -> 83627.69 | H17: {=SUMPRODUCT(('6511 (히스토리)'!$AI$15:$AI$34='6511 (일주일)'!H$2)*('6511 (히스토리)'!$AJ$15:$AJ$34))} -> 83878.17 | I17: {=SUMPRODUCT(('6511 (히스토리)'!$AI$15:$AI$34='6511 (일주일)'!I$2)*('6511 (히스토리)'!$AJ$15:$AJ$34))} -> 0 | J17: {=SUMPRODUCT(('6511 (히스토리)'!$AI$15:$AI$34='6511 (일주일)'!J$2)*('6511 (히스토리)'!$AJ$15:$AJ$34))} -> 0 | K17: {=SUMPRODUCT(('6511 (히스토리)'!$AI$15:$AI$34='6511 (일주일)'!K$2)*('6511 (히스토리)'!$AJ$15:$AJ$34))} -> 83576.24 | L17: {=SUMPRODUCT(('6511 (히스토리)'!$AI$15:$AI$34='6511 (일주일)'!L$2)*('6511 (히스토리)'!$AJ$15:$AJ$34))} -> 84180.96 | M17: {=SUMPRODUCT(('6511 (히스토리)'!$AI$15:$AI$34='6511 (일주일)'!M$2)*('6511 (히스토리)'!$AJ$15:$AJ$34))} -> 84961.14 | ... S17: {=SUMPRODUCT(('6511 (히스토리)'!$AI$15:$AI$34='6511 (일주일)'!S$2)*('6511 (히스토리)'!$AJ$15:$AJ$34))} -> 85188.6
A18: 16 | B18: 아시아 | C18: 베트남 | D18: HO CHI MINH STO | E18: VNI:VIDX | F18: {=SUMPRODUCT(('6511 (히스토리)'!$AK$15:$AK$34='6511 (일주일)'!F$2)*('6511 (히스토리)'!$AL$15:$AL$34))} -> 1901.02 | G18: {=SUMPRODUCT(('6511 (히스토리)'!$AK$15:$AK$34='6511 (일주일)'!G$2)*('6511 (히스토리)'!$AL$15:$AL$34))} -> 1902.93 | H18: {=SUMPRODUCT(('6511 (히스토리)'!$AK$15:$AK$34='6511 (일주일)'!H$2)*('6511 (히스토리)'!$AL$15:$AL$34))} -> 1877.33 | I18: {=SUMPRODUCT(('6511 (히스토리)'!$AK$15:$AK$34='6511 (일주일)'!I$2)*('6511 (히스토리)'!$AL$15:$AL$34))} -> 0 | J18: {=SUMPRODUCT(('6511 (히스토리)'!$AK$15:$AK$34='6511 (일주일)'!J$2)*('6511 (히스토리)'!$AL$15:$AL$34))} -> 0 | K18: {=SUMPRODUCT(('6511 (히스토리)'!$AK$15:$AK$34='6511 (일주일)'!K$2)*('6511 (히스토리)'!$AL$15:$AL$34))} -> 1867.9 | L18: {=SUMPRODUCT(('6511 (히스토리)'!$AK$15:$AK$34='6511 (일주일)'!L$2)*('6511 (히스토리)'!$AL$15:$AL$34))} -> 1855.56 | M18: {=SUMPRODUCT(('6511 (히스토리)'!$AK$15:$AK$34='6511 (일주일)'!M$2)*('6511 (히스토리)'!$AL$15:$AL$34))} -> 1861.58 | ... S18: {=SUMPRODUCT(('6511 (히스토리)'!$AK$15:$AK$34='6511 (일주일)'!S$2)*('6511 (히스토리)'!$AL$15:$AL$34))} -> 0
A19: 17 | B19: 아시아 | C19: 파키스탄 | D19: KSE 100 | E19: PKI:KSE100 | F19: {=SUMPRODUCT(('6511 (히스토리)'!$AM$15:$AM$34='6511 (일주일)'!F$2)*('6511 (히스토리)'!$AN$15:$AN$34))} -> 183951.51 | G19: {=SUMPRODUCT(('6511 (히스토리)'!$AM$15:$AM$34='6511 (일주일)'!G$2)*('6511 (히스토리)'!$AN$15:$AN$34))} -> 183951.51 | H19: {=SUMPRODUCT(('6511 (히스토리)'!$AM$15:$AM$34='6511 (일주일)'!H$2)*('6511 (히스토리)'!$AN$15:$AN$34))} -> 182384.15 | I19: {=SUMPRODUCT(('6511 (히스토리)'!$AM$15:$AM$34='6511 (일주일)'!I$2)*('6511 (히스토리)'!$AN$15:$AN$34))} -> 0 | J19: {=SUMPRODUCT(('6511 (히스토리)'!$AM$15:$AM$34='6511 (일주일)'!J$2)*('6511 (히스토리)'!$AN$15:$AN$34))} -> 0 | K19: {=SUMPRODUCT(('6511 (히스토리)'!$AM$15:$AM$34='6511 (일주일)'!K$2)*('6511 (히스토리)'!$AN$15:$AN$34))} -> 184409.67 | L19: {=SUMPRODUCT(('6511 (히스토리)'!$AM$15:$AM$34='6511 (일주일)'!L$2)*('6511 (히스토리)'!$AN$15:$AN$34))} -> 185589.9 | M19: {=SUMPRODUCT(('6511 (히스토리)'!$AM$15:$AM$34='6511 (일주일)'!M$2)*('6511 (히스토리)'!$AN$15:$AN$34))} -> 186518.72 | ... S19: {=SUMPRODUCT(('6511 (히스토리)'!$AM$15:$AM$34='6511 (일주일)'!S$2)*('6511 (히스토리)'!$AN$15:$AN$34))} -> 176355.49
A20: 18 | B20: 아시아 | C20: 오만 | D20: MSM 30 | E20: OMI:MSMI | F20: {=SUMPRODUCT(('6511 (히스토리)'!$AO$15:$AO$34='6511 (일주일)'!F$2)*('6511 (히스토리)'!$AP$15:$AP$34))} -> 6178.11 | G20: {=SUMPRODUCT(('6511 (히스토리)'!$AO$15:$AO$34='6511 (일주일)'!G$2)*('6511 (히스토리)'!$AP$15:$AP$34))} -> 6178.11 | H20: {=SUMPRODUCT(('6511 (히스토리)'!$AO$15:$AO$34='6511 (일주일)'!H$2)*('6511 (히스토리)'!$AP$15:$AP$34))} -> 6192.57 | I20: {=SUMPRODUCT(('6511 (히스토리)'!$AO$15:$AO$34='6511 (일주일)'!I$2)*('6511 (히스토리)'!$AP$15:$AP$34))} -> 0 | J20: {=SUMPRODUCT(('6511 (히스토리)'!$AO$15:$AO$34='6511 (일주일)'!J$2)*('6511 (히스토리)'!$AP$15:$AP$34))} -> 0 | K20: {=SUMPRODUCT(('6511 (히스토리)'!$AO$15:$AO$34='6511 (일주일)'!K$2)*('6511 (히스토리)'!$AP$15:$AP$34))} -> 6163.73 | L20: {=SUMPRODUCT(('6511 (히스토리)'!$AO$15:$AO$34='6511 (일주일)'!L$2)*('6511 (히스토리)'!$AP$15:$AP$34))} -> 6126 | M20: {=SUMPRODUCT(('6511 (히스토리)'!$AO$15:$AO$34='6511 (일주일)'!M$2)*('6511 (히스토리)'!$AP$15:$AP$34))} -> 6099.7 | ... S20: {=SUMPRODUCT(('6511 (히스토리)'!$AO$15:$AO$34='6511 (일주일)'!S$2)*('6511 (히스토리)'!$AP$15:$AP$34))} -> 5895.83
A21: 19 | B21: 아시아 | C21: 아랍에미레이트 | D21: Dubai Financial | E21: AEI:DFM | F21: {=SUMPRODUCT(('6511 (히스토리)'!$AQ$15:$AQ$34='6511 (일주일)'!F$2)*('6511 (히스토리)'!$AR$15:$AR$34))} -> 6319.3 | G21: {=SUMPRODUCT(('6511 (히스토리)'!$AQ$15:$AQ$34='6511 (일주일)'!G$2)*('6511 (히스토리)'!$AR$15:$AR$34))} -> 6319.3 | H21: {=SUMPRODUCT(('6511 (히스토리)'!$AQ$15:$AQ$34='6511 (일주일)'!H$2)*('6511 (히스토리)'!$AR$15:$AR$34))} -> 6268.31 | I21: {=SUMPRODUCT(('6511 (히스토리)'!$AQ$15:$AQ$34='6511 (일주일)'!I$2)*('6511 (히스토리)'!$AR$15:$AR$34))} -> 0 | J21: {=SUMPRODUCT(('6511 (히스토리)'!$AQ$15:$AQ$34='6511 (일주일)'!J$2)*('6511 (히스토리)'!$AR$15:$AR$34))} -> 0 | K21: {=SUMPRODUCT(('6511 (히스토리)'!$AQ$15:$AQ$34='6511 (일주일)'!K$2)*('6511 (히스토리)'!$AR$15:$AR$34))} -> 6225.94 | L21: {=SUMPRODUCT(('6511 (히스토리)'!$AQ$15:$AQ$34='6511 (일주일)'!L$2)*('6511 (히스토리)'!$AR$15:$AR$34))} -> 6252.99 | M21: {=SUMPRODUCT(('6511 (히스토리)'!$AQ$15:$AQ$34='6511 (일주일)'!M$2)*('6511 (히스토리)'!$AR$15:$AR$34))} -> 6248.56 | ... S21: {=SUMPRODUCT(('6511 (히스토리)'!$AQ$15:$AQ$34='6511 (일주일)'!S$2)*('6511 (히스토리)'!$AR$15:$AR$34))} -> 0
A22: 20 | B22: 아시아 | C22: 쿠웨이트 | D22: KSE Index | E22: KWI:MKIX | F22: {=SUMPRODUCT(('6511 (히스토리)'!$AS$15:$AS$34='6511 (일주일)'!F$2)*('6511 (히스토리)'!$AT$15:$AT$34))} -> 9424.15 | G22: {=SUMPRODUCT(('6511 (히스토리)'!$AS$15:$AS$34='6511 (일주일)'!G$2)*('6511 (히스토리)'!$AT$15:$AT$34))} -> 9424.15 | H22: {=SUMPRODUCT(('6511 (히스토리)'!$AS$15:$AS$34='6511 (일주일)'!H$2)*('6511 (히스토리)'!$AT$15:$AT$34))} -> 9343.74 | I22: {=SUMPRODUCT(('6511 (히스토리)'!$AS$15:$AS$34='6511 (일주일)'!I$2)*('6511 (히스토리)'!$AT$15:$AT$34))} -> 0 | J22: {=SUMPRODUCT(('6511 (히스토리)'!$AS$15:$AS$34='6511 (일주일)'!J$2)*('6511 (히스토리)'!$AT$15:$AT$34))} -> 0 | K22: {=SUMPRODUCT(('6511 (히스토리)'!$AS$15:$AS$34='6511 (일주일)'!K$2)*('6511 (히스토리)'!$AT$15:$AT$34))} -> 9389.64 | L22: {=SUMPRODUCT(('6511 (히스토리)'!$AS$15:$AS$34='6511 (일주일)'!L$2)*('6511 (히스토리)'!$AT$15:$AT$34))} -> 9443.72 | M22: {=SUMPRODUCT(('6511 (히스토리)'!$AS$15:$AS$34='6511 (일주일)'!M$2)*('6511 (히스토리)'!$AT$15:$AT$34))} -> 9463.38 | ... S22: {=SUMPRODUCT(('6511 (히스토리)'!$AS$15:$AS$34='6511 (일주일)'!S$2)*('6511 (히스토리)'!$AT$15:$AT$34))} -> 0
A23: 21 | B23: 아시아 | C23: 카타르 | D23: DSM 20 | E23: QAI:MKIX | F23: {=SUMPRODUCT(('6511 (히스토리)'!$AU$15:$AU$34='6511 (일주일)'!F$2)*('6511 (히스토리)'!$AV$15:$AV$34))} -> 11229.22 | G23: {=SUMPRODUCT(('6511 (히스토리)'!$AU$15:$AU$34='6511 (일주일)'!G$2)*('6511 (히스토리)'!$AV$15:$AV$34))} -> 11229.22 | H23: {=SUMPRODUCT(('6511 (히스토리)'!$AU$15:$AU$34='6511 (일주일)'!H$2)*('6511 (히스토리)'!$AV$15:$AV$34))} -> 11162.54 | I23: {=SUMPRODUCT(('6511 (히스토리)'!$AU$15:$AU$34='6511 (일주일)'!I$2)*('6511 (히스토리)'!$AV$15:$AV$34))} -> 0 | J23: {=SUMPRODUCT(('6511 (히스토리)'!$AU$15:$AU$34='6511 (일주일)'!J$2)*('6511 (히스토리)'!$AV$15:$AV$34))} -> 0 | K23: {=SUMPRODUCT(('6511 (히스토리)'!$AU$15:$AU$34='6511 (일주일)'!K$2)*('6511 (히스토리)'!$AV$15:$AV$34))} -> 11088.79 | L23: {=SUMPRODUCT(('6511 (히스토리)'!$AU$15:$AU$34='6511 (일주일)'!L$2)*('6511 (히스토리)'!$AV$15:$AV$34))} -> 10969.33 | M23: {=SUMPRODUCT(('6511 (히스토리)'!$AU$15:$AU$34='6511 (일주일)'!M$2)*('6511 (히스토리)'!$AV$15:$AV$34))} -> 11061.78 | ... S23: {=SUMPRODUCT(('6511 (히스토리)'!$AU$15:$AU$34='6511 (일주일)'!S$2)*('6511 (히스토리)'!$AV$15:$AV$34))} -> 0
A24: 22 | B24: 아시아 | C24: 요르단 | D24: ASE Index | E24: JOI:FTI | F24: {=SUMPRODUCT(('6511 (히스토리)'!$AW$15:$AW$34='6511 (일주일)'!F$2)*('6511 (히스토리)'!$AX$15:$AX$34))} -> 3555.87 | G24: {=SUMPRODUCT(('6511 (히스토리)'!$AW$15:$AW$34='6511 (일주일)'!G$2)*('6511 (히스토리)'!$AX$15:$AX$34))} -> 3555.87 | H24: {=SUMPRODUCT(('6511 (히스토리)'!$AW$15:$AW$34='6511 (일주일)'!H$2)*('6511 (히스토리)'!$AX$15:$AX$34))} -> 3548.39 | I24: {=SUMPRODUCT(('6511 (히스토리)'!$AW$15:$AW$34='6511 (일주일)'!I$2)*('6511 (히스토리)'!$AX$15:$AX$34))} -> 0 | J24: {=SUMPRODUCT(('6511 (히스토리)'!$AW$15:$AW$34='6511 (일주일)'!J$2)*('6511 (히스토리)'!$AX$15:$AX$34))} -> 0 | K24: {=SUMPRODUCT(('6511 (히스토리)'!$AW$15:$AW$34='6511 (일주일)'!K$2)*('6511 (히스토리)'!$AX$15:$AX$34))} -> 3560.35 | L24: {=SUMPRODUCT(('6511 (히스토리)'!$AW$15:$AW$34='6511 (일주일)'!L$2)*('6511 (히스토리)'!$AX$15:$AX$34))} -> 3553.35 | M24: {=SUMPRODUCT(('6511 (히스토리)'!$AW$15:$AW$34='6511 (일주일)'!M$2)*('6511 (히스토리)'!$AX$15:$AX$34))} -> 3560.72 | ... S24: {=SUMPRODUCT(('6511 (히스토리)'!$AW$15:$AW$34='6511 (일주일)'!S$2)*('6511 (히스토리)'!$AX$15:$AX$34))} -> 0
A25: 23 | B25: 아시아 | C25: 사우디아라비아 | D25: TASI | E25: SAI:TASI | F25: {=SUMPRODUCT(('6511 (히스토리)'!$AY$15:$AY$34='6511 (일주일)'!F$2)*('6511 (히스토리)'!$AZ$15:$AZ$34))} -> 10893.63 | G25: {=SUMPRODUCT(('6511 (히스토리)'!$AY$15:$AY$34='6511 (일주일)'!G$2)*('6511 (히스토리)'!$AZ$15:$AZ$34))} -> 10893.63 | H25: {=SUMPRODUCT(('6511 (히스토리)'!$AY$15:$AY$34='6511 (일주일)'!H$2)*('6511 (히스토리)'!$AZ$15:$AZ$34))} -> 10745.45 | I25: {=SUMPRODUCT(('6511 (히스토리)'!$AY$15:$AY$34='6511 (일주일)'!I$2)*('6511 (히스토리)'!$AZ$15:$AZ$34))} -> 0 | J25: {=SUMPRODUCT(('6511 (히스토리)'!$AY$15:$AY$34='6511 (일주일)'!J$2)*('6511 (히스토리)'!$AZ$15:$AZ$34))} -> 0 | K25: {=SUMPRODUCT(('6511 (히스토리)'!$AY$15:$AY$34='6511 (일주일)'!K$2)*('6511 (히스토리)'!$AZ$15:$AZ$34))} -> 10609.76 | L25: {=SUMPRODUCT(('6511 (히스토리)'!$AY$15:$AY$34='6511 (일주일)'!L$2)*('6511 (히스토리)'!$AZ$15:$AZ$34))} -> 10473.23 | M25: {=SUMPRODUCT(('6511 (히스토리)'!$AY$15:$AY$34='6511 (일주일)'!M$2)*('6511 (히스토리)'!$AZ$15:$AZ$34))} -> 10455.14 | ... S25: {=SUMPRODUCT(('6511 (히스토리)'!$AY$15:$AY$34='6511 (일주일)'!S$2)*('6511 (히스토리)'!$AZ$15:$AZ$34))} -> 10549.08
A26: 24 | B26: 아시아 | C26: 이스라엘 | D26: TA-100 | E26: ILI:TA100 | F26: {=SUMPRODUCT(('6511 (히스토리)'!$BA$15:$BA$34='6511 (일주일)'!F$2)*('6511 (히스토리)'!$BB$15:$BB$34))} -> 3913.39 | G26: {=SUMPRODUCT(('6511 (히스토리)'!$BA$15:$BA$34='6511 (일주일)'!G$2)*('6511 (히스토리)'!$BB$15:$BB$34))} -> 3913.39 | H26: {=SUMPRODUCT(('6511 (히스토리)'!$BA$15:$BA$34='6511 (일주일)'!H$2)*('6511 (히스토리)'!$BB$15:$BB$34))} -> 3926.38 | I26: {=SUMPRODUCT(('6511 (히스토리)'!$BA$15:$BA$34='6511 (일주일)'!I$2)*('6511 (히스토리)'!$BB$15:$BB$34))} -> 0 | J26: {=SUMPRODUCT(('6511 (히스토리)'!$BA$15:$BA$34='6511 (일주일)'!J$2)*('6511 (히스토리)'!$BB$15:$BB$34))} -> 0 | K26: {=SUMPRODUCT(('6511 (히스토리)'!$BA$15:$BA$34='6511 (일주일)'!K$2)*('6511 (히스토리)'!$BB$15:$BB$34))} -> 3907.26 | L26: {=SUMPRODUCT(('6511 (히스토리)'!$BA$15:$BA$34='6511 (일주일)'!L$2)*('6511 (히스토리)'!$BB$15:$BB$34))} -> 3878.85 | M26: {=SUMPRODUCT(('6511 (히스토리)'!$BA$15:$BA$34='6511 (일주일)'!M$2)*('6511 (히스토리)'!$BB$15:$BB$34))} -> 3893.87 | ... S26: {=SUMPRODUCT(('6511 (히스토리)'!$BA$15:$BA$34='6511 (일주일)'!S$2)*('6511 (히스토리)'!$BB$15:$BB$34))} -> 3733.08
A27: 25 | B27: 유럽 | C27: 러시아 | D27: RTSI | E27: RUI:RTSI | F27: {=SUMPRODUCT(('6511 (히스토리)'!$BC$15:$BC$34='6511 (일주일)'!F$2)*('6511 (히스토리)'!$BD$15:$BD$34))} -> 1077.44 | G27: {=SUMPRODUCT(('6511 (히스토리)'!$BC$15:$BC$34='6511 (일주일)'!G$2)*('6511 (히스토리)'!$BD$15:$BD$34))} -> 1077.44 | H27: {=SUMPRODUCT(('6511 (히스토리)'!$BC$15:$BC$34='6511 (일주일)'!H$2)*('6511 (히스토리)'!$BD$15:$BD$34))} -> 1080.28 | I27: {=SUMPRODUCT(('6511 (히스토리)'!$BC$15:$BC$34='6511 (일주일)'!I$2)*('6511 (히스토리)'!$BD$15:$BD$34))} -> 0 | J27: {=SUMPRODUCT(('6511 (히스토리)'!$BC$15:$BC$34='6511 (일주일)'!J$2)*('6511 (히스토리)'!$BD$15:$BD$34))} -> 0 | K27: {=SUMPRODUCT(('6511 (히스토리)'!$BC$15:$BC$34='6511 (일주일)'!K$2)*('6511 (히스토리)'!$BD$15:$BD$34))} -> 1097.31 | L27: {=SUMPRODUCT(('6511 (히스토리)'!$BC$15:$BC$34='6511 (일주일)'!L$2)*('6511 (히스토리)'!$BD$15:$BD$34))} -> 1094.8 | M27: {=SUMPRODUCT(('6511 (히스토리)'!$BC$15:$BC$34='6511 (일주일)'!M$2)*('6511 (히스토리)'!$BD$15:$BD$34))} -> 0 | ... S27: {=SUMPRODUCT(('6511 (히스토리)'!$BC$15:$BC$34='6511 (일주일)'!S$2)*('6511 (히스토리)'!$BD$15:$BD$34))} -> 0
A28: 26 | B28: 유럽 | C28: 터키 | D28: ISE Nation Index | E28: TRI:ISE100 | F28: {=SUMPRODUCT(('6511 (히스토리)'!$BE$15:$BE$34='6511 (일주일)'!F$2)*('6511 (히스토리)'!$BF$15:$BF$34))} -> 12385.61 | G28: {=SUMPRODUCT(('6511 (히스토리)'!$BE$15:$BE$34='6511 (일주일)'!G$2)*('6511 (히스토리)'!$BF$15:$BF$34))} -> 12385.61 | H28: {=SUMPRODUCT(('6511 (히스토리)'!$BE$15:$BE$34='6511 (일주일)'!H$2)*('6511 (히스토리)'!$BF$15:$BF$34))} -> 12254.83 | I28: {=SUMPRODUCT(('6511 (히스토리)'!$BE$15:$BE$34='6511 (일주일)'!I$2)*('6511 (히스토리)'!$BF$15:$BF$34))} -> 0 | J28: {=SUMPRODUCT(('6511 (히스토리)'!$BE$15:$BE$34='6511 (일주일)'!J$2)*('6511 (히스토리)'!$BF$15:$BF$34))} -> 0 | K28: {=SUMPRODUCT(('6511 (히스토리)'!$BE$15:$BE$34='6511 (일주일)'!K$2)*('6511 (히스토리)'!$BF$15:$BF$34))} -> 12200.95 | L28: {=SUMPRODUCT(('6511 (히스토리)'!$BE$15:$BE$34='6511 (일주일)'!L$2)*('6511 (히스토리)'!$BF$15:$BF$34))} -> 12087.97 | M28: {=SUMPRODUCT(('6511 (히스토리)'!$BE$15:$BE$34='6511 (일주일)'!M$2)*('6511 (히스토리)'!$BF$15:$BF$34))} -> 12028.84 | ... S28: {=SUMPRODUCT(('6511 (히스토리)'!$BE$15:$BE$34='6511 (일주일)'!S$2)*('6511 (히스토리)'!$BF$15:$BF$34))} -> 0
A29: 27 | B29: 유럽 | C29: 덴마크 | D29: OMX Copenhgagen20 | E29: DKI:KFX | F29: {=SUMPRODUCT(('6511 (히스토리)'!$BG$15:$BG$34='6511 (일주일)'!F$2)*('6511 (히스토리)'!$BH$15:$BH$34))} -> 1751.79 | G29: {=SUMPRODUCT(('6511 (히스토리)'!$BG$15:$BG$34='6511 (일주일)'!G$2)*('6511 (히스토리)'!$BH$15:$BH$34))} -> 1751.793 | H29: {=SUMPRODUCT(('6511 (히스토리)'!$BG$15:$BG$34='6511 (일주일)'!H$2)*('6511 (히스토리)'!$BH$15:$BH$34))} -> 1734.637 | I29: {=SUMPRODUCT(('6511 (히스토리)'!$BG$15:$BG$34='6511 (일주일)'!I$2)*('6511 (히스토리)'!$BH$15:$BH$34))} -> 0 | J29: {=SUMPRODUCT(('6511 (히스토리)'!$BG$15:$BG$34='6511 (일주일)'!J$2)*('6511 (히스토리)'!$BH$15:$BH$34))} -> 0 | K29: {=SUMPRODUCT(('6511 (히스토리)'!$BG$15:$BG$34='6511 (일주일)'!K$2)*('6511 (히스토리)'!$BH$15:$BH$34))} -> 1740.5 | L29: {=SUMPRODUCT(('6511 (히스토리)'!$BG$15:$BG$34='6511 (일주일)'!L$2)*('6511 (히스토리)'!$BH$15:$BH$34))} -> 1715.96 | M29: {=SUMPRODUCT(('6511 (히스토리)'!$BG$15:$BG$34='6511 (일주일)'!M$2)*('6511 (히스토리)'!$BH$15:$BH$34))} -> 1714.74 | ... S29: {=SUMPRODUCT(('6511 (히스토리)'!$BG$15:$BG$34='6511 (일주일)'!S$2)*('6511 (히스토리)'!$BH$15:$BH$34))} -> 0
A30: 28 | B30: 유럽 | C30: 노르웨이 | D30: OBX | E30: NOI:OSEAX | F30: {=SUMPRODUCT(('6511 (히스토리)'!$BI$15:$BI$34='6511 (일주일)'!F$2)*('6511 (히스토리)'!$BJ$15:$BJ$34))} -> 1985.2 | G30: {=SUMPRODUCT(('6511 (히스토리)'!$BI$15:$BI$34='6511 (일주일)'!G$2)*('6511 (히스토리)'!$BJ$15:$BJ$34))} -> 1985.2 | H30: {=SUMPRODUCT(('6511 (히스토리)'!$BI$15:$BI$34='6511 (일주일)'!H$2)*('6511 (히스토리)'!$BJ$15:$BJ$34))} -> 1964.84 | I30: {=SUMPRODUCT(('6511 (히스토리)'!$BI$15:$BI$34='6511 (일주일)'!I$2)*('6511 (히스토리)'!$BJ$15:$BJ$34))} -> 0 | J30: {=SUMPRODUCT(('6511 (히스토리)'!$BI$15:$BI$34='6511 (일주일)'!J$2)*('6511 (히스토리)'!$BJ$15:$BJ$34))} -> 0 | K30: {=SUMPRODUCT(('6511 (히스토리)'!$BI$15:$BI$34='6511 (일주일)'!K$2)*('6511 (히스토리)'!$BJ$15:$BJ$34))} -> 1957.94 | L30: {=SUMPRODUCT(('6511 (히스토리)'!$BI$15:$BI$34='6511 (일주일)'!L$2)*('6511 (히스토리)'!$BJ$15:$BJ$34))} -> 1940.35 | M30: {=SUMPRODUCT(('6511 (히스토리)'!$BI$15:$BI$34='6511 (일주일)'!M$2)*('6511 (히스토리)'!$BJ$15:$BJ$34))} -> 1936.8 | ... S30: {=SUMPRODUCT(('6511 (히스토리)'!$BI$15:$BI$34='6511 (일주일)'!S$2)*('6511 (히스토리)'!$BJ$15:$BJ$34))} -> 0
A31: 29 | B31: 유럽 | C31: 스페인 | D31: IBEX-35 | E31: ESI:IBEX | F31: {=SUMPRODUCT(('6511 (히스토리)'!$BK$15:$BK$34='6511 (일주일)'!F$2)*('6511 (히스토리)'!$BL$15:$BL$34))} -> 17687.1 | G31: {=SUMPRODUCT(('6511 (히스토리)'!$BK$15:$BK$34='6511 (일주일)'!G$2)*('6511 (히스토리)'!$BL$15:$BL$34))} -> 17687.1 | H31: {=SUMPRODUCT(('6511 (히스토리)'!$BK$15:$BK$34='6511 (일주일)'!H$2)*('6511 (히스토리)'!$BL$15:$BL$34))} -> 17673.8 | I31: {=SUMPRODUCT(('6511 (히스토리)'!$BK$15:$BK$34='6511 (일주일)'!I$2)*('6511 (히스토리)'!$BL$15:$BL$34))} -> 0 | J31: {=SUMPRODUCT(('6511 (히스토리)'!$BK$15:$BK$34='6511 (일주일)'!J$2)*('6511 (히스토리)'!$BL$15:$BL$34))} -> 0 | K31: {=SUMPRODUCT(('6511 (히스토리)'!$BK$15:$BK$34='6511 (일주일)'!K$2)*('6511 (히스토리)'!$BL$15:$BL$34))} -> 17649 | L31: {=SUMPRODUCT(('6511 (히스토리)'!$BK$15:$BK$34='6511 (일주일)'!L$2)*('6511 (히스토리)'!$BL$15:$BL$34))} -> 17654.7 | M31: {=SUMPRODUCT(('6511 (히스토리)'!$BK$15:$BK$34='6511 (일주일)'!M$2)*('6511 (히스토리)'!$BL$15:$BL$34))} -> 17596.4 | ... S31: {=SUMPRODUCT(('6511 (히스토리)'!$BK$15:$BK$34='6511 (일주일)'!S$2)*('6511 (히스토리)'!$BL$15:$BL$34))} -> 0
A32: 30 | B32: 유럽 | C32: 벨기에 | D32: BEL-20 | E32: BEI:MFX | F32: {=SUMPRODUCT(('6511 (히스토리)'!$BM$15:$BM$34='6511 (일주일)'!F$2)*('6511 (히스토리)'!$BN$15:$BN$34))} -> 5250.09 | G32: {=SUMPRODUCT(('6511 (히스토리)'!$BM$15:$BM$34='6511 (일주일)'!G$2)*('6511 (히스토리)'!$BN$15:$BN$34))} -> 5250.09 | H32: {=SUMPRODUCT(('6511 (히스토리)'!$BM$15:$BM$34='6511 (일주일)'!H$2)*('6511 (히스토리)'!$BN$15:$BN$34))} -> 5213.94 | I32: {=SUMPRODUCT(('6511 (히스토리)'!$BM$15:$BM$34='6511 (일주일)'!I$2)*('6511 (히스토리)'!$BN$15:$BN$34))} -> 0 | J32: {=SUMPRODUCT(('6511 (히스토리)'!$BM$15:$BM$34='6511 (일주일)'!J$2)*('6511 (히스토리)'!$BN$15:$BN$34))} -> 0 | K32: {=SUMPRODUCT(('6511 (히스토리)'!$BM$15:$BM$34='6511 (일주일)'!K$2)*('6511 (히스토리)'!$BN$15:$BN$34))} -> 5240.44 | L32: {=SUMPRODUCT(('6511 (히스토리)'!$BM$15:$BM$34='6511 (일주일)'!L$2)*('6511 (히스토리)'!$BN$15:$BN$34))} -> 5228.77 | M32: {=SUMPRODUCT(('6511 (히스토리)'!$BM$15:$BM$34='6511 (일주일)'!M$2)*('6511 (히스토리)'!$BN$15:$BN$34))} -> 5220.95 | ... S32: {=SUMPRODUCT(('6511 (히스토리)'!$BM$15:$BM$34='6511 (일주일)'!S$2)*('6511 (히스토리)'!$BN$15:$BN$34))} -> 0
A33: 31 | B33: 유럽 | C33: 스위스 | D33: SMI | E33: CHI:SSMI | F33: {=SUMPRODUCT(('6511 (히스토리)'!$BO$15:$BO$34='6511 (일주일)'!F$2)*('6511 (히스토리)'!$BP$15:$BP$34))} -> 13364.73 | G33: {=SUMPRODUCT(('6511 (히스토리)'!$BO$15:$BO$34='6511 (일주일)'!G$2)*('6511 (히스토리)'!$BP$15:$BP$34))} -> 13364.73 | H33: {=SUMPRODUCT(('6511 (히스토리)'!$BO$15:$BO$34='6511 (일주일)'!H$2)*('6511 (히스토리)'!$BP$15:$BP$34))} -> 13426.98 | I33: {=SUMPRODUCT(('6511 (히스토리)'!$BO$15:$BO$34='6511 (일주일)'!I$2)*('6511 (히스토리)'!$BP$15:$BP$34))} -> 0 | J33: {=SUMPRODUCT(('6511 (히스토리)'!$BO$15:$BO$34='6511 (일주일)'!J$2)*('6511 (히스토리)'!$BP$15:$BP$34))} -> 0 | K33: {=SUMPRODUCT(('6511 (히스토리)'!$BO$15:$BO$34='6511 (일주일)'!K$2)*('6511 (히스토리)'!$BP$15:$BP$34))} -> 13421.82 | L33: {=SUMPRODUCT(('6511 (히스토리)'!$BO$15:$BO$34='6511 (일주일)'!L$2)*('6511 (히스토리)'!$BP$15:$BP$34))} -> 13350.82 | M33: {=SUMPRODUCT(('6511 (히스토리)'!$BO$15:$BO$34='6511 (일주일)'!M$2)*('6511 (히스토리)'!$BP$15:$BP$34))} -> 13324.03 | ... S33: {=SUMPRODUCT(('6511 (히스토리)'!$BO$15:$BO$34='6511 (일주일)'!S$2)*('6511 (히스토리)'!$BP$15:$BP$34))} -> 0
A34: 32 | B34: 유럽 | C34: 독일 | D34: DAX | E34: XTR:DAX30 | F34: {=SUMPRODUCT(('6511 (히스토리)'!$BQ$15:$BQ$34='6511 (일주일)'!F$2)*('6511 (히스토리)'!$BR$15:$BR$34))} -> 25420.66 | G34: {=SUMPRODUCT(('6511 (히스토리)'!$BQ$15:$BQ$34='6511 (일주일)'!G$2)*('6511 (히스토리)'!$BR$15:$BR$34))} -> 25420.66 | H34: {=SUMPRODUCT(('6511 (히스토리)'!$BQ$15:$BQ$34='6511 (일주일)'!H$2)*('6511 (히스토리)'!$BR$15:$BR$34))} -> 25405.34 | I34: {=SUMPRODUCT(('6511 (히스토리)'!$BQ$15:$BQ$34='6511 (일주일)'!I$2)*('6511 (히스토리)'!$BR$15:$BR$34))} -> 0 | J34: {=SUMPRODUCT(('6511 (히스토리)'!$BQ$15:$BQ$34='6511 (일주일)'!J$2)*('6511 (히스토리)'!$BR$15:$BR$34))} -> 0 | K34: {=SUMPRODUCT(('6511 (히스토리)'!$BQ$15:$BQ$34='6511 (일주일)'!K$2)*('6511 (히스토리)'!$BR$15:$BR$34))} -> 25261.64 | L34: {=SUMPRODUCT(('6511 (히스토리)'!$BQ$15:$BQ$34='6511 (일주일)'!L$2)*('6511 (히스토리)'!$BR$15:$BR$34))} -> 25127.46 | M34: {=SUMPRODUCT(('6511 (히스토리)'!$BQ$15:$BQ$34='6511 (일주일)'!M$2)*('6511 (히스토리)'!$BR$15:$BR$34))} -> 25122.26 | ... S34: {=SUMPRODUCT(('6511 (히스토리)'!$BQ$15:$BQ$34='6511 (일주일)'!S$2)*('6511 (히스토리)'!$BR$15:$BR$34))} -> 0
A35: 33 | B35: 유럽 | C35: 영국 | D35: FTSE 100 | E35: LNS:FTSE100 | F35: {=SUMPRODUCT(('6511 (히스토리)'!$BS$15:$BS$34='6511 (일주일)'!F$2)*('6511 (히스토리)'!$BT$15:$BT$34))} -> 10137.35 | G35: {=SUMPRODUCT(('6511 (히스토리)'!$BS$15:$BS$34='6511 (일주일)'!G$2)*('6511 (히스토리)'!$BT$15:$BT$34))} -> 10137.35 | H35: {=SUMPRODUCT(('6511 (히스토리)'!$BS$15:$BS$34='6511 (일주일)'!H$2)*('6511 (히스토리)'!$BT$15:$BT$34))} -> 10140.7 | I35: {=SUMPRODUCT(('6511 (히스토리)'!$BS$15:$BS$34='6511 (일주일)'!I$2)*('6511 (히스토리)'!$BT$15:$BT$34))} -> 0 | J35: {=SUMPRODUCT(('6511 (히스토리)'!$BS$15:$BS$34='6511 (일주일)'!J$2)*('6511 (히스토리)'!$BT$15:$BT$34))} -> 0 | K35: {=SUMPRODUCT(('6511 (히스토리)'!$BS$15:$BS$34='6511 (일주일)'!K$2)*('6511 (히스토리)'!$BT$15:$BT$34))} -> 10124.6 | L35: {=SUMPRODUCT(('6511 (히스토리)'!$BS$15:$BS$34='6511 (일주일)'!L$2)*('6511 (히스토리)'!$BT$15:$BT$34))} -> 10044.69 | M35: {=SUMPRODUCT(('6511 (히스토리)'!$BS$15:$BS$34='6511 (일주일)'!M$2)*('6511 (히스토리)'!$BT$15:$BT$34))} -> 10048.21 | ... S35: {=SUMPRODUCT(('6511 (히스토리)'!$BS$15:$BS$34='6511 (일주일)'!S$2)*('6511 (히스토리)'!$BT$15:$BT$34))} -> 0
A36: 34 | B36: 유럽 | C36: 스웨덴 | D36: OMX Stockholm30 | E36: SEI:SXASI | F36: {=SUMPRODUCT(('6511 (히스토리)'!$BU$15:$BU$34='6511 (일주일)'!F$2)*('6511 (히스토리)'!$BV$15:$BV$34))} -> 1071.31 | G36: {=SUMPRODUCT(('6511 (히스토리)'!$BU$15:$BU$34='6511 (일주일)'!G$2)*('6511 (히스토리)'!$BV$15:$BV$34))} -> 1071.31 | H36: {=SUMPRODUCT(('6511 (히스토리)'!$BU$15:$BU$34='6511 (일주일)'!H$2)*('6511 (히스토리)'!$BV$15:$BV$34))} -> 1072.09 | I36: {=SUMPRODUCT(('6511 (히스토리)'!$BU$15:$BU$34='6511 (일주일)'!I$2)*('6511 (히스토리)'!$BV$15:$BV$34))} -> 0 | J36: {=SUMPRODUCT(('6511 (히스토리)'!$BU$15:$BU$34='6511 (일주일)'!J$2)*('6511 (히스토리)'!$BV$15:$BV$34))} -> 0 | K36: {=SUMPRODUCT(('6511 (히스토리)'!$BU$15:$BU$34='6511 (일주일)'!K$2)*('6511 (히스토리)'!$BV$15:$BV$34))} -> 1072.31 | L36: {=SUMPRODUCT(('6511 (히스토리)'!$BU$15:$BU$34='6511 (일주일)'!L$2)*('6511 (히스토리)'!$BV$15:$BV$34))} -> 1059.86 | M36: {=SUMPRODUCT(('6511 (히스토리)'!$BU$15:$BU$34='6511 (일주일)'!M$2)*('6511 (히스토리)'!$BV$15:$BV$34))} -> 1069.68 | ... S36: {=SUMPRODUCT(('6511 (히스토리)'!$BU$15:$BU$34='6511 (일주일)'!S$2)*('6511 (히스토리)'!$BV$15:$BV$34))} -> 0
A37: 35 | B37: 유럽 | C37: 네덜란드 | D37: AEX | E37: NLI:AEX | F37: {=SUMPRODUCT(('6511 (히스토리)'!$BW$15:$BW$34='6511 (일주일)'!F$2)*('6511 (히스토리)'!$BX$15:$BX$34))} -> 997.17 | G37: {=SUMPRODUCT(('6511 (히스토리)'!$BW$15:$BW$34='6511 (일주일)'!G$2)*('6511 (히스토리)'!$BX$15:$BX$34))} -> 997.17 | H37: {=SUMPRODUCT(('6511 (히스토리)'!$BW$15:$BW$34='6511 (일주일)'!H$2)*('6511 (히스토리)'!$BX$15:$BX$34))} -> 993.54 | I37: {=SUMPRODUCT(('6511 (히스토리)'!$BW$15:$BW$34='6511 (일주일)'!I$2)*('6511 (히스토리)'!$BX$15:$BX$34))} -> 0 | J37: {=SUMPRODUCT(('6511 (히스토리)'!$BW$15:$BW$34='6511 (일주일)'!J$2)*('6511 (히스토리)'!$BX$15:$BX$34))} -> 0 | K37: {=SUMPRODUCT(('6511 (히스토리)'!$BW$15:$BW$34='6511 (일주일)'!K$2)*('6511 (히스토리)'!$BX$15:$BX$34))} -> 988.17 | L37: {=SUMPRODUCT(('6511 (히스토리)'!$BW$15:$BW$34='6511 (일주일)'!L$2)*('6511 (히스토리)'!$BX$15:$BX$34))} -> 965.03 | M37: {=SUMPRODUCT(('6511 (히스토리)'!$BW$15:$BW$34='6511 (일주일)'!M$2)*('6511 (히스토리)'!$BX$15:$BX$34))} -> 979.15 | ... S37: {=SUMPRODUCT(('6511 (히스토리)'!$BW$15:$BW$34='6511 (일주일)'!S$2)*('6511 (히스토리)'!$BX$15:$BX$34))} -> 0
A38: 36 | B38: 유럽 | C38: 프랑스 | D38: CAC 40 INDEX | E38: PAS:CAC40 | F38: {=SUMPRODUCT(('6511 (히스토리)'!$BY$15:$BY$34='6511 (일주일)'!F$2)*('6511 (히스토리)'!$BZ$15:$BZ$34))} -> 8347.2 | G38: {=SUMPRODUCT(('6511 (히스토리)'!$BY$15:$BY$34='6511 (일주일)'!G$2)*('6511 (히스토리)'!$BZ$15:$BZ$34))} -> 8347.2 | H38: {=SUMPRODUCT(('6511 (히스토리)'!$BY$15:$BY$34='6511 (일주일)'!H$2)*('6511 (히스토리)'!$BZ$15:$BZ$34))} -> 8358.76 | I38: {=SUMPRODUCT(('6511 (히스토리)'!$BY$15:$BY$34='6511 (일주일)'!I$2)*('6511 (히스토리)'!$BZ$15:$BZ$34))} -> 0 | J38: {=SUMPRODUCT(('6511 (히스토리)'!$BY$15:$BY$34='6511 (일주일)'!J$2)*('6511 (히스토리)'!$BZ$15:$BZ$34))} -> 0 | K38: {=SUMPRODUCT(('6511 (히스토리)'!$BY$15:$BY$34='6511 (일주일)'!K$2)*('6511 (히스토리)'!$BZ$15:$BZ$34))} -> 8362.09 | L38: {=SUMPRODUCT(('6511 (히스토리)'!$BY$15:$BY$34='6511 (일주일)'!L$2)*('6511 (히스토리)'!$BZ$15:$BZ$34))} -> 8243.47 | M38: {=SUMPRODUCT(('6511 (히스토리)'!$BY$15:$BY$34='6511 (일주일)'!M$2)*('6511 (히스토리)'!$BZ$15:$BZ$34))} -> 8233.92 | ... S38: {=SUMPRODUCT(('6511 (히스토리)'!$BY$15:$BY$34='6511 (일주일)'!S$2)*('6511 (히스토리)'!$BZ$15:$BZ$34))} -> 0
A39: 37 | B39: 유럽 | C39: 그리스 | D39: ATHEX | E39: GRI:ASE | F39: {=SUMPRODUCT(('6511 (히스토리)'!$CA$15:$CA$34='6511 (일주일)'!F$2)*('6511 (히스토리)'!$CB$15:$CB$34))} -> 2206.3 | G39: {=SUMPRODUCT(('6511 (히스토리)'!$CA$15:$CA$34='6511 (일주일)'!G$2)*('6511 (히스토리)'!$CB$15:$CB$34))} -> 2206.3 | H39: {=SUMPRODUCT(('6511 (히스토리)'!$CA$15:$CA$34='6511 (일주일)'!H$2)*('6511 (히스토리)'!$CB$15:$CB$34))} -> 2210.85 | I39: {=SUMPRODUCT(('6511 (히스토리)'!$CA$15:$CA$34='6511 (일주일)'!I$2)*('6511 (히스토리)'!$CB$15:$CB$34))} -> 0 | J39: {=SUMPRODUCT(('6511 (히스토리)'!$CA$15:$CA$34='6511 (일주일)'!J$2)*('6511 (히스토리)'!$CB$15:$CB$34))} -> 0 | K39: {=SUMPRODUCT(('6511 (히스토리)'!$CA$15:$CA$34='6511 (일주일)'!K$2)*('6511 (히스토리)'!$CB$15:$CB$34))} -> 2207.73 | L39: {=SUMPRODUCT(('6511 (히스토리)'!$CA$15:$CA$34='6511 (일주일)'!L$2)*('6511 (히스토리)'!$CB$15:$CB$34))} -> 2204.24 | M39: {=SUMPRODUCT(('6511 (히스토리)'!$CA$15:$CA$34='6511 (일주일)'!M$2)*('6511 (히스토리)'!$CB$15:$CB$34))} -> 2163.88 | ... S39: {=SUMPRODUCT(('6511 (히스토리)'!$CA$15:$CA$34='6511 (일주일)'!S$2)*('6511 (히스토리)'!$CB$15:$CB$34))} -> 0
A40: 38 | B40: 유럽 | C40: 이탈리아 | D40: FTSE MIB | E40: ITI:FTSEMIB | F40: {=SUMPRODUCT(('6511 (히스토리)'!$CC$15:$CC$34='6511 (일주일)'!F$2)*('6511 (히스토리)'!$CD$15:$CD$34))} -> 45525.1 | G40: {=SUMPRODUCT(('6511 (히스토리)'!$CC$15:$CC$34='6511 (일주일)'!G$2)*('6511 (히스토리)'!$CD$15:$CD$34))} -> 45525.1 | H40: {=SUMPRODUCT(('6511 (히스토리)'!$CC$15:$CC$34='6511 (일주일)'!H$2)*('6511 (히스토리)'!$CD$15:$CD$34))} -> 45732.2 | I40: {=SUMPRODUCT(('6511 (히스토리)'!$CC$15:$CC$34='6511 (일주일)'!I$2)*('6511 (히스토리)'!$CD$15:$CD$34))} -> 0 | J40: {=SUMPRODUCT(('6511 (히스토리)'!$CC$15:$CC$34='6511 (일주일)'!J$2)*('6511 (히스토리)'!$CD$15:$CD$34))} -> 0 | K40: {=SUMPRODUCT(('6511 (히스토리)'!$CC$15:$CC$34='6511 (일주일)'!K$2)*('6511 (히스토리)'!$CD$15:$CD$34))} -> 45719.26 | L40: {=SUMPRODUCT(('6511 (히스토리)'!$CC$15:$CC$34='6511 (일주일)'!L$2)*('6511 (히스토리)'!$CD$15:$CD$34))} -> 45671.7 | M40: {=SUMPRODUCT(('6511 (히스토리)'!$CC$15:$CC$34='6511 (일주일)'!M$2)*('6511 (히스토리)'!$CD$15:$CD$34))} -> 45558.68 | ... S40: {=SUMPRODUCT(('6511 (히스토리)'!$CC$15:$CC$34='6511 (일주일)'!S$2)*('6511 (히스토리)'!$CD$15:$CD$34))} -> 0
...

Sheet 6511 (히스토리)
A1: 데이터 정보 | F1: 0,1,12 : 그 외에 모가 있는지 모르겠네
A2: 시작 | B2: 종료 | C2: Data 갯수 | D2: 정렬 | E2: 주기 | F2: 영업일
A3: =TODAY()-60 -> 45976 | B3: =TODAY() -> 46036 | C3: 30 | D3: A | E3: 일 | F3: 12
G8: IMDH(Market, Code, Field, StartDay, EndDay, Count, Option)
A11: 국가명 | B11: 코드 | C11: 대분류코드 | G11: 베트남
A12: 베트남 | B12: =INDEX(표.코드표[코드],MATCH(표2[국가명],표.코드표[국가명],0)) -> VNI:VIDX | C12: FRN | G12: =INDEX(표.코드표[코드],MATCH('6511 (히스토리)'!G11,표.코드표[국가명],0)) -> VNI:VIDX
G13: =_xll.IMDH("FRN",G12,G14:H14,$A$3,$B$3,$C$3,"Per="&$D$3&",sort="&$E$3&",real=true,Bizday="&$F$3&",Pos=20,Orient=V,Title="&코드표!A3&",DtFmt=1,TmFmt=1") -> 2 | I13: =_xll.IMDH("FRN",코드표!E3,I14:J14,$A$3,$B$3,$C$3,"Per="&$D$3&",sort="&$E$3&",real=true,Bizday="&$F$3&",Pos=20,Orient=V,Title="&코드표!C3&",DtFmt=1,TmFmt=1") -> 호주 | K13: =_xll.IMDH("FRN",코드표!E4,K14:L14,$A$3,$B$3,$C$3,"Per="&$D$3&",sort="&$E$3&",real=true,Bizday="&$F$3&",Pos=20,Orient=V,Title="&코드표!C4&",DtFmt=1,TmFmt=1") -> 일본 | M13: =_xll.IMDH("FRN",코드표!E5,M14:N14,$A$3,$B$3,$C$3,"Per="&$D$3&",sort="&$E$3&",real=true,Bizday="&$F$3&",Pos=20,Orient=V,Title="&코드표!C5&",DtFmt=1,TmFmt=1") -> 대만 | O13: =_xll.IMDH("FRN",코드표!E6,O14:P14,$A$3,$B$3,$C$3,"Per="&$D$3&",sort="&$E$3&",real=true,Bizday="&$F$3&",Pos=20,Orient=V,Title="&코드표!C6&",DtFmt=1,TmFmt=1") -> 싱가포르 | Q13: =_xll.IMDH("FRN",코드표!E7,Q14:R14,$A$3,$B$3,$C$3,"Per="&$D$3&",sort="&$E$3&",real=true,Bizday="&$F$3&",Pos=20,Orient=V,Title="&코드표!C7&",DtFmt=1,TmFmt=1") -> 말레이시아 | S13: =_xll.IMDH("FRN",코드표!E8,S14:T14,$A$3,$B$3,$C$3,"Per="&$D$3&",sort="&$E$3&",real=true,Bizday="&$F$3&",Pos=20,Orient=V,Title="&코드표!C8&",DtFmt=1,TmFmt=1") -> 필리핀 | U13: =_xll.IMDH("FRN",코드표!E9,U14:V14,$A$3,$B$3,$C$3,"Per="&$D$3&",sort="&$E$3&",real=true,Bizday="&$F$3&",Pos=20,Orient=V,Title="&코드표!C9&",DtFmt=1,TmFmt=1") -> 중국(상해종합) | W13: =_xll.IMDH("FRN",코드표!E10,U14:V14,$A$3,$B$3,$C$3,"Per="&$D$3&",sort="&$E$3&",real=true,Bizday="&$F$3&",Pos=20,Orient=V,Title="&코드표!C10&",DtFmt=1,TmFmt=1") -> 중국(심천종합) | Y13: =_xll.IMDH("FRN",코드표!E11,U14:V14,$A$3,$B$3,$C$3,"Per="&$D$3&",sort="&$E$3&",real=true,Bizday="&$F$3&",Pos=20,Orient=V,Title="&코드표!C11&",DtFmt=1,TmFmt=1") -> 중국(CSI 300) | AA13: =_xll.IMDH("FRN",코드표!E12,AA14:AB14,$A$3,$B$3,$C$3,"Per="&$D$3&",sort="&$E$3&",real=true,Bizday="&$F$3&",Pos=20,Orient=V,Title="&코드표!C12&",DtFmt=1,TmFmt=1") -> 홍콩(항셍) | AC13: =_xll.IMDH("FRN",코드표!E13,AC14:AD14,$A$3,$B$3,$C$3,"Per="&$D$3&",sort="&$E$3&",real=true,Bizday="&$F$3&",Pos=20,Orient=V,Title="&코드표!C13&",DtFmt=1,TmFmt=1") -> 홍콩(항셍 H) | AE13: =_xll.IMDH("FRN",코드표!E14,AE14:AF14,$A$3,$B$3,$C$3,"Per="&$D$3&",sort="&$E$3&",real=true,Bizday="&$F$3&",Pos=20,Orient=V,Title="&코드표!C14&",DtFmt=1,TmFmt=1") -> 인도네시아 | AG13: =_xll.IMDH("FRN",코드표!E15,AG14:AH14,$A$3,$B$3,$C$3,"Per="&$D$3&",sort="&$E$3&",real=true,Bizday="&$F$3&",Pos=20,Orient=V,Title="&코드표!C15&",DtFmt=1,TmFmt=1") -> 태국 | AI13: =_xll.IMDH("FRN",코드표!E16,AI14:AJ14,$A$3,$B$3,$C$3,"Per="&$D$3&",sort="&$E$3&",real=true,Bizday="&$F$3&",Pos=20,Orient=V,Title="&코드표!C16&",DtFmt=1,TmFmt=1") -> 인도 | AK13: =_xll.IMDH("FRN",코드표!E17,AK14:AL14,$A$3,$B$3,$C$3,"Per="&$D$3&",sort="&$E$3&",real=true,Bizday="&$F$3&",Pos=20,Orient=V,Title="&코드표!C17&",DtFmt=1,TmFmt=1") -> 베트남 | AM13: =_xll.IMDH("FRN",코드표!E18,AM14:AN14,$A$3,$B$3,$C$3,"Per="&$D$3&",sort="&$E$3&",real=true,Bizday="&$F$3&",Pos=20,Orient=V,Title="&코드표!C18&",DtFmt=1,TmFmt=1") -> 파키스탄 | AO13: =_xll.IMDH("FRN",코드표!E19,AO14:AP14,$A$3,$B$3,$C$3,"Per="&$D$3&",sort="&$E$3&",real=true,Bizday="&$F$3&",Pos=20,Orient=V,Title="&코드표!C19&",DtFmt=1,TmFmt=1") -> 오만 | AQ13: =_xll.IMDH("FRN",코드표!E20,AQ14:AR14,$A$3,$B$3,$C$3,"Per="&$D$3&",sort="&$E$3&",real=true,Bizday="&$F$3&",Pos=20,Orient=V,Title="&코드표!C20&",DtFmt=1,TmFmt=1") -> 아랍에미레이트 | AS13: =_xll.IMDH("FRN",코드표!E21,AS14:AT14,$A$3,$B$3,$C$3,"Per="&$D$3&",sort="&$E$3&",real=true,Bizday="&$F$3&",Pos=20,Orient=V,Title="&코드표!C21&",DtFmt=1,TmFmt=1") -> 쿠웨이트 | AU13: =_xll.IMDH("FRN",코드표!E22,AU14:AV14,$A$3,$B$3,$C$3,"Per="&$D$3&",sort="&$E$3&",real=true,Bizday="&$F$3&",Pos=20,Orient=V,Title="&코드표!C22&",DtFmt=1,TmFmt=1") -> 카타르 | AW13: =_xll.IMDH("FRN",코드표!E23,AW14:AX14,$A$3,$B$3,$C$3,"Per="&$D$3&",sort="&$E$3&",real=true,Bizday="&$F$3&",Pos=20,Orient=V,Title="&코드표!C23&",DtFmt=1,TmFmt=1") -> 요르단 | AY13: =_xll.IMDH("FRN",코드표!E24,AY14:AZ14,$A$3,$B$3,$C$3,"Per="&$D$3&",sort="&$E$3&",real=true,Bizday="&$F$3&",Pos=20,Orient=V,Title="&코드표!C24&",DtFmt=1,TmFmt=1") -> 사우디아라비아 | BA13: =_xll.IMDH("FRN",코드표!E25,BA14:BB14,$A$3,$B$3,$C$3,"Per="&$D$3&",sort="&$E$3&",real=true,Bizday="&$F$3&",Pos=20,Orient=V,Title="&코드표!C25&",DtFmt=1,TmFmt=1") -> 이스라엘 | BC13: =_xll.IMDH("FRN",코드표!E26,BC14:BD14,$A$3,$B$3,$C$3,"Per="&$D$3&",sort="&$E$3&",real=true,Bizday="&$F$3&",Pos=20,Orient=V,Title="&코드표!C26&",DtFmt=1,TmFmt=1") -> 러시아 | BE13: =_xll.IMDH("FRN",코드표!E27,BE14:BF14,$A$3,$B$3,$C$3,"Per="&$D$3&",sort="&$E$3&",real=true,Bizday="&$F$3&",Pos=20,Orient=V,Title="&코드표!C27&",DtFmt=1,TmFmt=1") -> 터키 | BG13: =_xll.IMDH("FRN",코드표!E28,BG14:BH14,$A$3,$B$3,$C$3,"Per="&$D$3&",sort="&$E$3&",real=true,Bizday="&$F$3&",Pos=20,Orient=V,Title="&코드표!C28&",DtFmt=1,TmFmt=1") -> 덴마크 | BI13: =_xll.IMDH("FRN",코드표!E29,BI14:BJ14,$A$3,$B$3,$C$3,"Per="&$D$3&",sort="&$E$3&",real=true,Bizday="&$F$3&",Pos=20,Orient=V,Title="&코드표!C29&",DtFmt=1,TmFmt=1") -> 노르웨이 | BK13: =_xll.IMDH("FRN",코드표!E30,BK14:BL14,$A$3,$B$3,$C$3,"Per="&$D$3&",sort="&$E$3&",real=true,Bizday="&$F$3&",Pos=20,Orient=V,Title="&코드표!C30&",DtFmt=1,TmFmt=1") -> 스페인 | BM13: =_xll.IMDH("FRN",코드표!E31,BM14:BN14,$A$3,$B$3,$C$3,"Per="&$D$3&",sort="&$E$3&",real=true,Bizday="&$F$3&",Pos=20,Orient=V,Title="&코드표!C31&",DtFmt=1,TmFmt=1") -> 벨기에 | BO13: =_xll.IMDH("FRN",코드표!E32,BO14:BP14,$A$3,$B$3,$C$3,"Per="&$D$3&",sort="&$E$3&",real=true,Bizday="&$F$3&",Pos=20,Orient=V,Title="&코드표!C32&",DtFmt=1,TmFmt=1") -> 스위스 | BQ13: =_xll.IMDH("FRN",코드표!E33,BQ14:BR14,$A$3,$B$3,$C$3,"Per="&$D$3&",sort="&$E$3&",real=true,Bizday="&$F$3&",Pos=20,Orient=V,Title="&코드표!C33&",DtFmt=1,TmFmt=1") -> 독일 | BS13: =_xll.IMDH("FRN",코드표!E34,BS14:BT14,$A$3,$B$3,$C$3,"Per="&$D$3&",sort="&$E$3&",real=true,Bizday="&$F$3&",Pos=20,Orient=V,Title="&코드표!C34&",DtFmt=1,TmFmt=1") -> 영국 | BU13: =_xll.IMDH("FRN",코드표!E35,BU14:BV14,$A$3,$B$3,$C$3,"Per="&$D$3&",sort="&$E$3&",real=true,Bizday="&$F$3&",Pos=20,Orient=V,Title="&코드표!C35&",DtFmt=1,TmFmt=1") -> 스웨덴 | BW13: =_xll.IMDH("FRN",코드표!E36,BW14:BX14,$A$3,$B$3,$C$3,"Per="&$D$3&",sort="&$E$3&",real=true,Bizday="&$F$3&",Pos=20,Orient=V,Title="&코드표!C36&",DtFmt=1,TmFmt=1") -> 네덜란드 | BY13: =_xll.IMDH("FRN",코드표!E37,BY14:BZ14,$A$3,$B$3,$C$3,"Per="&$D$3&",sort="&$E$3&",real=true,Bizday="&$F$3&",Pos=20,Orient=V,Title="&코드표!C37&",DtFmt=1,TmFmt=1") -> 프랑스 | CA13: =_xll.IMDH("FRN",코드표!E38,CA14:CB14,$A$3,$B$3,$C$3,"Per="&$D$3&",sort="&$E$3&",real=true,Bizday="&$F$3&",Pos=20,Orient=V,Title="&코드표!C38&",DtFmt=1,TmFmt=1") -> 그리스 | CC13: =_xll.IMDH("FRN",코드표!E39,CC14:CD14,$A$3,$B$3,$C$3,"Per="&$D$3&",sort="&$E$3&",real=true,Bizday="&$F$3&",Pos=20,Orient=V,Title="&코드표!C39&",DtFmt=1,TmFmt=1") -> 이탈리아 | CE13: =_xll.IMDH("FRN",코드표!E40,CE14:CF14,$A$3,$B$3,$C$3,"Per="&$D$3&",sort="&$E$3&",real=true,Bizday="&$F$3&",Pos=20,Orient=V,Title="&코드표!C40&",DtFmt=1,TmFmt=1") -> 폴란드 | CG13: =_xll.IMDH("FRN",코드표!E41,CG14:CH14,$A$3,$B$3,$C$3,"Per="&$D$3&",sort="&$E$3&",real=true,Bizday="&$F$3&",Pos=20,Orient=V,Title="&코드표!C41&",DtFmt=1,TmFmt=1") -> 포르투칼 | CI13: =_xll.IMDH("FRN",코드표!E42,CI14:CJ14,$A$3,$B$3,$C$3,"Per="&$D$3&",sort="&$E$3&",real=true,Bizday="&$F$3&",Pos=20,Orient=V,Title="&코드표!C42&",DtFmt=1,TmFmt=1") -> 오스트리아 | CK13: =_xll.IMDH("FRN",코드표!E43,CK14:CL14,$A$3,$B$3,$C$3,"Per="&$D$3&",sort="&$E$3&",real=true,Bizday="&$F$3&",Pos=20,Orient=V,Title="&코드표!C43&",DtFmt=1,TmFmt=1") -> 라투비아 | CM13: =_xll.IMDH("FRN",코드표!E44,CM14:CN14,$A$3,$B$3,$C$3,"Per="&$D$3&",sort="&$E$3&",real=true,Bizday="&$F$3&",Pos=20,Orient=V,Title="&코드표!C44&",DtFmt=1,TmFmt=1") -> 불가리아 | CO13: =_xll.IMDH("FRN",코드표!E45,CO14:CP14,$A$3,$B$3,$C$3,"Per="&$D$3&",sort="&$E$3&",real=true,Bizday="&$F$3&",Pos=20,Orient=V,Title="&코드표!C45&",DtFmt=1,TmFmt=1") -> 핀란드 | CQ13: =_xll.IMDH("FRN",코드표!E46,CQ14:CR14,$A$3,$B$3,$C$3,"Per="&$D$3&",sort="&$E$3&",real=true,Bizday="&$F$3&",Pos=20,Orient=V,Title="&코드표!C46&",DtFmt=1,TmFmt=1") -> 헝가리 | CS13: =_xll.IMDH("FRN",코드표!E47,CS14:CT14,$A$3,$B$3,$C$3,"Per="&$D$3&",sort="&$E$3&",real=true,Bizday="&$F$3&",Pos=20,Orient=V,Title="&코드표!C47&",DtFmt=1,TmFmt=1") -> 아일랜드 | CU13: =_xll.IMDH("FRN",코드표!E48,CU14:CV14,$A$3,$B$3,$C$3,"Per="&$D$3&",sort="&$E$3&",real=true,Bizday="&$F$3&",Pos=20,Orient=V,Title="&코드표!C48&",DtFmt=1,TmFmt=1") -> 이집트 | CW13: =_xll.IMDH("FRN",코드표!E49,CW14:CX14,$A$3,$B$3,$C$3,"Per="&$D$3&",sort="&$E$3&",real=true,Bizday="&$F$3&",Pos=20,Orient=V,Title="&코드표!C49&",DtFmt=1,TmFmt=1") -> 룩셈부르크 | CY13: =_xll.IMDH("FRN",코드표!E50,CW14:CX14,$A$3,$B$3,$C$3,"Per="&$D$3&",sort="&$E$3&",real=true,Bizday="&$F$3&",Pos=20,Orient=V,Title="&코드표!C50&",DtFmt=1,TmFmt=1") -> 체코 | DA13: =_xll.IMDH("FRN",코드표!E51,CW14:CX14,$A$3,$B$3,$C$3,"Per="&$D$3&",sort="&$E$3&",real=true,Bizday="&$F$3&",Pos=20,Orient=V,Title="&코드표!C51&",DtFmt=1,TmFmt=1") -> 유로스톡스50 | DC13: =_xll.IMDH("FRN",코드표!E52,CW14:CX14,$A$3,$B$3,$C$3,"Per="&$D$3&",sort="&$E$3&",real=true,Bizday="&$F$3&",Pos=20,Orient=V,Title="&코드표!C52&",DtFmt=1,TmFmt=1") -> FTSE 300 | DE13: =_xll.IMDH("FRN",코드표!E53,DE14:DF14,$A$3,$B$3,$C$3,"Per="&$D$3&",sort="&$E$3&",real=true,Bizday="&$F$3&",Pos=20,Orient=V,Title="&코드표!C53&",DtFmt=1,TmFmt=1") -> 칠레 | DG13: =_xll.IMDH("FRN",코드표!E54,DG14:DH14,$A$3,$B$3,$C$3,"Per="&$D$3&",sort="&$E$3&",real=true,Bizday="&$F$3&",Pos=20,Orient=V,Title="&코드표!C54&",DtFmt=1,TmFmt=1") -> 브라질 | DI13: =_xll.IMDH("FRN",코드표!E55,DI14:DJ14,$A$3,$B$3,$C$3,"Per="&$D$3&",sort="&$E$3&",real=true,Bizday="&$F$3&",Pos=20,Orient=V,Title="&코드표!C55&",DtFmt=1,TmFmt=1") -> 아르헨티나 | DK13: =_xll.IMDH("FRN",코드표!E56,DK14:DL14,$A$3,$B$3,$C$3,"Per="&$D$3&",sort="&$E$3&",real=true,Bizday="&$F$3&",Pos=20,Orient=V,Title="&코드표!C56&",DtFmt=1,TmFmt=1") -> 페루 | DM13: =_xll.IMDH("FRN",코드표!E57,DM14:DN14,$A$3,$B$3,$C$3,"Per="&$D$3&",sort="&$E$3&",real=true,Bizday="&$F$3&",Pos=20,Orient=V,Title="&코드표!C57&",DtFmt=1,TmFmt=1") -> 캐나다 | DO13: =_xll.IMDH("FRN",코드표!E58,DO14:DP14,$A$3,$B$3,$C$3,"Per="&$D$3&",sort="&$E$3&",real=true,Bizday="&$F$3&",Pos=20,Orient=V,Title="&코드표!C58&",DtFmt=1,TmFmt=1") -> 미국(DJI) | DQ13: =_xll.IMDH("FRN",코드표!E59,DQ14:DR14,$A$3,$B$3,$C$3,"Per="&$D$3&",sort="&$E$3&",real=true,Bizday="&$F$3&",Pos=20,Orient=V,Title="&코드표!C59&",DtFmt=1,TmFmt=1") -> 미국(NASDAQ) | DS13: =_xll.IMDH("FRN",코드표!E60,DS14:DT14,$A$3,$B$3,$C$3,"Per="&$D$3&",sort="&$E$3&",real=true,Bizday="&$F$3&",Pos=20,Orient=V,Title="&코드표!C60&",DtFmt=1,TmFmt=1") -> 미국(S&P) | DU13: =_xll.IMDH("FRN",코드표!E61,DU14:DV14,$A$3,$B$3,$C$3,"Per="&$D$3&",sort="&$E$3&",real=true,Bizday="&$F$3&",Pos=20,Orient=V,Title="&코드표!C61&",DtFmt=1,TmFmt=1") -> 멕시코 | DW13: =_xll.IMDH("FRN",코드표!E62,DW14:DX14,$A$3,$B$3,$C$3,"Per="&$D$3&",sort="&$E$3&",real=true,Bizday="&$F$3&",Pos=20,Orient=V,Title="&코드표!C62&",DtFmt=1,TmFmt=1") -> 베네수엘라 | DY13: =_xll.IMDH("FRN",코드표!E63,DY14:DZ14,$A$3,$B$3,$C$3,"Per="&$D$3&",sort="&$E$3&",real=true,Bizday="&$F$3&",Pos=20,Orient=V,Title="&코드표!C63&",DtFmt=1,TmFmt=1") -> 콜롬비아
A14: =_xll.IMDH("FRN",G12,G14:H14,$A$3,$B$3,$C$3,"Per="&$D$3&",sort="&$E$3&",real=true,Bizday="&$F$3&",Pos=20,Orient=V,Title="&표2[국가명]&",DtFmt=1,TmFmt=1") -> 베트남 | G14: 일자 | H14: 종가 | I14: 일자 | J14: 종가 | K14: 일자 | L14: 종가 | M14: 일자 | N14: 종가 | O14: 일자 | P14: 종가 | Q14: 일자 | R14: 종가 | S14: 일자 | T14: 종가 | U14: 일자 | V14: 종가 | W14: 일자 | X14: 종가 | Y14: 일자 | Z14: 종가 | AA14: 일자 | AB14: 종가 | AC14: 일자 | AD14: 종가 | AE14: 일자 | AF14: 종가 | AG14: 일자 | AH14: 종가 | AI14: 일자 | AJ14: 종가 | AK14: 일자 | AL14: 종가 | AM14: 일자 | AN14: 종가 | AO14: 일자 | AP14: 종가 | AQ14: 일자 | AR14: 종가 | AS14: 일자 | AT14: 종가 | AU14: 일자 | AV14: 종가 | AW14: 일자 | AX14: 종가 | AY14: 일자 | AZ14: 종가 | BA14: 일자 | BB14: 종가 | BC14: 일자 | BD14: 종가 | BE14: 일자 | BF14: 종가 | BG14: 일자 | BH14: 종가 | BI14: 일자 | BJ14: 종가 | BK14: 일자 | BL14: 종가 | BM14: 일자 | BN14: 종가 | BO14: 일자 | BP14: 종가 | BQ14: 일자 | BR14: 종가 | BS14: 일자 | BT14: 종가 | BU14: 일자 | BV14: 종가 | BW14: 일자 | BX14: 종가 | BY14: 일자 | BZ14: 종가 | CA14: 일자 | CB14: 종가 | CC14: 일자 | CD14: 종가 | CE14: 일자 | CF14: 종가 | CG14: 일자 | CH14: 종가 | CI14: 일자 | CJ14: 종가 | CK14: 일자 | CL14: 종가 | CM14: 일자 | CN14: 종가 | CO14: 일자 | CP14: 종가 | CQ14: 일자 | CR14: 종가 | CS14: 일자 | CT14: 종가 | CU14: 일자 | CV14: 종가 | CW14: 일자 | CX14: 종가 | CY14: 일자 | CZ14: 종가 | DA14: 일자 | DB14: 종가 | DC14: 일자 | DD14: 종가 | DE14: 일자 | DF14: 종가 | DG14: 일자 | DH14: 종가 | DI14: 일자 | DJ14: 종가 | DK14: 일자 | DL14: 종가 | DM14: 일자 | DN14: 종가 | DO14: 일자 | DP14: 종가 | DQ14: 일자 | DR14: 종가 | DS14: 일자 | DT14: 종가 | DU14: 일자 | DV14: 종가 | DW14: 일자 | DX14: 종가 | DY14: 일자 | DZ14: 종가
G15: 46036 | H15: 1901.02 | I15: 46036 | J15: 9138.5 | K15: 46036 | L15: 54179.59 | M15: 46036 | N15: 30884.39 | O15: 46036 | P15: 4806.27 | Q15: 46036 | R15: 1707.22 | S15: 46036 | T15: 6419.96 | U15: 46036 | V15: 4188.24 | W15: 46036 | X15: 2733.02 | Y15: 46036 | Z15: 4812.48 | AA15: 46036 | AB15: 27092.98 | AC15: 46036 | AD15: 9367.28 | AE15: 46036 | AF15: 9025.76 | AG15: 46036 | AI15: 46036 | AJ15: 83523.65 | AK15: 46036 | AL15: 1901.02 | AM15: 46036 | AN15: 183951.51 | AO15: 46036 | AP15: 6178.11 | AQ15: 46036 | AR15: 6319.3 | AS15: 46036 | AT15: 9424.15 | AU15: 46036 | AV15: 11229.22 | AW15: 46036 | AX15: 3555.87 | AY15: 46036 | AZ15: 10893.63 | BA15: 46036 | BB15: 3913.39 | BC15: 46036 | BD15: 1077.44 | BE15: 46036 | BF15: 12385.61 | BG15: 46036 | BH15: 1751.79 | BI15: 46036 | BJ15: 1985.2 | BK15: 46036 | BL15: 17687.1 | BM15: 46036 | BN15: 5250.09 | BO15: 46036 | BP15: 13364.73 | BQ15: 46036 | BR15: 25420.66 | BS15: 46036 | BT15: 10137.35 | BU15: 46036 | BV15: 1071.31 | BW15: 46036 | BX15: 997.17 | BY15: 46036 | BZ15: 8347.2 | CA15: 46036 | CB15: 2206.3 | CC15: 46036 | CD15: 45525.1 | CE15: 46036 | CF15: 121794.45 | CG15: 46036 | CH15: 8559.09 | CI15: 46036 | CJ15: 5410.3 | CK15: 46036 | CM15: 46036 | CO15: 46036 | CP15: 5792.43 | CQ15: 46036 | CR15: 118863.12 | CS15: 46036 | CT15: 12972.66 | CU15: 46036 | CV15: 43684.22 | CW15: 46036 | CX15: 1885.13 | CY15: 46036 | DA15: 46036 | DB15: 6029.83 | DC15: 46036 | DE15: 46036 | DG15: 46036 | DI15: 46036 | DK15: 46036 | DM15: 46036 | DO15: 46036 | DQ15: 46036 | DS15: 46036 | DU15: 46036 | DW15: 46036 | DY15: 46036
A16: 46036 | B16: 1901.02 | G16: 46035 | H16: 1902.93 | I16: 46035 | J16: 9138.49 | K16: 46035 | L16: 53549.16 | M16: 46035 | N16: 30707.22 | O16: 46035 | P16: 4807.13 | Q16: 46035 | R16: 1708.2 | S16: 46035 | T16: 6408.76 | U16: 46035 | V16: 4138.76 | W16: 46035 | X16: 2676.04 | Y16: 46035 | Z16: 4761.03 | AA16: 46035 | AB16: 26848.47 | AC16: 46035 | AD16: 9285.41 | AE16: 46035 | AF16: 8948.3 | AG16: 46035 | AH16: 1235.3 | AI16: 46035 | AJ16: 83627.69 | AK16: 46035 | AL16: 1902.93 | AM16: 46035 | AN16: 183951.51 | AO16: 46035 | AP16: 6178.11 | AQ16: 46035 | AR16: 6319.3 | AS16: 46035 | AT16: 9424.15 | AU16: 46035 | AV16: 11229.22 | AW16: 46035 | AX16: 3555.87 | AY16: 46035 | AZ16: 10893.63 | BA16: 46035 | BB16: 3913.39 | BC16: 46035 | BD16: 1077.44 | BE16: 46035 | BF16: 12385.61 | BG16: 46035 | BH16: 1751.793 | BI16: 46035 | BJ16: 1985.2 | BK16: 46035 | BL16: 17687.1 | BM16: 46035 | BN16: 5250.09 | BO16: 46035 | BP16: 13364.73 | BQ16: 46035 | BR16: 25420.66 | BS16: 46035 | BT16: 10137.35 | BU16: 46035 | BV16: 1071.31 | BW16: 46035 | BX16: 997.17 | BY16: 46035 | BZ16: 8347.2 | CA16: 46035 | CB16: 2206.3 | CC16: 46035 | CD16: 45525.1 | CE16: 46035 | CF16: 121794.45 | CG16: 46035 | CH16: 8559.09 | CI16: 46035 | CJ16: 5410.3 | CK16: 46035 | CL16: 928.08 | CM16: 46035 | CN16: 1371.7 | CO16: 46035 | CP16: 5792.43 | CQ16: 46035 | CR16: 118863.12 | CS16: 46035 | CT16: 12972.66 | CU16: 46035 | CV16: 43684.22 | CW16: 46035 | CX16: 1885.132 | CY16: 46035 | CZ16: 2743.44 | DA16: 46035 | DB16: 6029.83 | DC16: 46035 | DD16: 2436.95 | DE16: 46035 | DF16: 56483.24 | DG16: 46035 | DH16: 161973.05 | DI16: 46035 | DJ16: 3036292.5 | DK16: 46035 | DL16: 34937.73 | DM16: 46035 | DN16: 32870.36 | DO16: 46035 | DP16: 49191.99 | DQ16: 46035 | DR16: 23709.87 | DS16: 46035 | DT16: 6963.74 | DU16: 46035 | DV16: 66337.42 | DW16: 46035 | DX16: 5808.58 | DY16: 46035 | DZ16: 2236.51
