Workbook

Sheet Sheet1
C2: 국가별 금리 및 스프레드
C4: =TODAY() -> 45842
C6: 10 | D6: {=INDEX(Sheet2!$C$3:$C$36, C6)} -> US | E6: =D6 -> US | F6: 17 | G6: {=INDEX(Sheet2!$C$3:$C$36, F6)} -> GB | H6: =G6 -> GB | I6: 18 | J6: {=INDEX(Sheet2!$C$3:$C$36, I6)} -> EU | K6: =J6 -> EU | L6: 22 | M6: {=INDEX(Sheet2!$C$3:$C$36, L6)} -> JP | N6: =M6 -> JP | O6: 33 | P6: {=INDEX(Sheet2!$C$3:$C$36, O6)} -> AU | Q6: =P6 -> AU | R6: 34 | S6: {=INDEX(Sheet2!$C$3:$C$36, R6)} -> HK | T6: =S6 -> HK | U6: 23 | V6: {=INDEX(Sheet2!$C$3:$C$36, U6)} -> RM | W6: =V6 -> RM | X6: 5 | Y6: {=INDEX(Sheet2!$C$3:$C$36, X6)} -> TW | Z6: =Y6 -> TW | AA6: 7 | AB6: {=INDEX(Sheet2!$C$3:$C$36, AA6)} -> DE | AC6: =AB6 -> DE | AD6: 30 | AE6: {=INDEX(Sheet2!$C$3:$C$36, AD6)} -> FR | AF6: =AE6 -> FR | AG6: 19 | AH6: {=INDEX(Sheet2!$C$3:$C$36, AG6)} -> IT | AI6: =AH6 -> IT | AJ6: 24 | AK6: {=INDEX(Sheet2!$C$3:$C$36, AJ6)} -> CA | AL6: =AK6 -> CA
C7: 기물 | D7: BID | E7: ASK | F7: 기물 | G7: BID | H7: ASK | I7: 기물 | J7: BID | K7: ASK | L7: 기물 | M7: BID | N7: ASK | O7: 기물 | P7: BID | Q7: ASK | R7: 기물 | S7: BID | T7: ASK | U7: 기물 | V7: BID | W7: ASK | X7: 기물 | Y7: BID | Z7: ASK | AA7: 기물 | AB7: BID | AC7: ASK | AD7: 기물 | AE7: BID | AF7: ASK | AG7: 기물 | AH7: BID | AI7: ASK | AJ7: 기물 | AK7: BID | AL7: ASK
B8: 1 | C8: {=INDEX(Sheet2!$I$3:$AP$18, $B8, Sheet1!C$6)} -> 01M | D8: {=_xll.IMDP("IR", D$6&C8, "BID_Close", $C$4)} -> 4.229 | E8: {=_xll.IMDP("IR", E$6&C8, "ASK_Close", $C$4)} -> 4.218 | F8: {=INDEX(Sheet2!$I$3:$AP$18, $B8, Sheet1!F$6)} -> 01Y | G8: {=_xll.IMDP("IR", G$6&F8, "BID_Close", $C$4)} -> 3.7422 | H8: {=_xll.IMDP("IR", H$6&F8, "ASK_Close", $C$4)} -> 3.7222 | I8: {=INDEX(Sheet2!$I$3:$AP$18, $B8, Sheet1!I$6)} -> 01Y | J8: {=_xll.IMDP("IR", J$6&I8, "BID_Close", $C$4)} -> 1.8211 | K8: {=_xll.IMDP("IR", K$6&I8, "ASK_Close", $C$4)} -> 1.7891 | L8: {=INDEX(Sheet2!$I$3:$AP$18, $B8, Sheet1!L$6)} -> 01Y | M8: {=_xll.IMDP("IR", M$6&L8, "BID_Close", $C$4)} -> 0.5857 | N8: {=_xll.IMDP("IR", N$6&L8, "ASK_Close", $C$4)} -> 0.5757 | O8: {=INDEX(Sheet2!$I$3:$AP$18, $B8, Sheet1!O$6)} -> 01Y | P8: {=_xll.IMDP("IR", P$6&O8, "BID_Close", $C$4)} -> 3.3734 | Q8: {=_xll.IMDP("IR", Q$6&O8, "ASK_Close", $C$4)} -> 3.3534 | R8: {=INDEX(Sheet2!$I$3:$AP$18, $B8, Sheet1!R$6)} -> 01Y | S8: {=_xll.IMDP("IR", S$6&R8, "BID_Close", $C$4)} -> 1.77 | T8: {=_xll.IMDP("IR", T$6&R8, "ASK_Close", $C$4)} -> 1.7 | U8: {=INDEX(Sheet2!$I$3:$AP$18, $B8, Sheet1!U$6)} -> 01Y | V8: {=_xll.IMDP("IR", V$6&U8, "BID_Close", $C$4)} -> 1.3573 | W8: {=_xll.IMDP("IR", W$6&U8, "ASK_Close", $C$4)} -> 1.3154 | X8: {=INDEX(Sheet2!$I$3:$AP$18, $B8, Sheet1!X$6)} -> 02Y | Y8: {=_xll.IMDP("IR", Y$6&X8, "BID_Close", $C$4)} -> 1.22 | Z8: {=_xll.IMDP("IR", Z$6&X8, "ASK_Close", $C$4)} -> 1.18 | AA8: {=INDEX(Sheet2!$I$3:$AP$18, $B8, Sheet1!AA$6)} -> 01Y | AB8: {=_xll.IMDP("IR", AB$6&AA8, "BID_Close", $C$4)} -> 1.8211 | AC8: {=_xll.IMDP("IR", AC$6&AA8, "ASK_Close", $C$4)} -> 1.7891 | AD8: {=INDEX(Sheet2!$I$3:$AP$18, $B8, Sheet1!AD$6)} -> 01Y | AE8: {=_xll.IMDP("IR", AE$6&AD8, "BID_Close", $C$4)} -> 1.8874 | AF8: {=_xll.IMDP("IR", AF$6&AD8, "ASK_Close", $C$4)} -> 1.8523 | AG8: {=INDEX(Sheet2!$I$3:$AP$18, $B8, Sheet1!AG$6)} -> 01Y | AH8: {=_xll.IMDP("IR", AH$6&AG8, "BID_Close", $C$4)} -> 1.9961 | AI8: {=_xll.IMDP("IR", AI$6&AG8, "ASK_Close", $C$4)} -> 1.9654 | AJ8: {=INDEX(Sheet2!$I$3:$AP$18, $B8, Sheet1!AJ$6)} -> 02Y | AK8: {=_xll.IMDP("IR", AK$6&AJ8, "BID_Close", $C$4)} -> 2.6911 | AL8: {=_xll.IMDP("IR", AL$6&AJ8, "ASK_Close", $C$4)} -> 2.6895
B9: 2 | C9: {=INDEX(Sheet2!$I$3:$AP$18, $B9, Sheet1!C$6)} -> 02M | D9: {=_xll.IMDP("IR", D$6&C9, "BID_Close", $C$4)} -> 4.381 | E9: {=_xll.IMDP("IR", E$6&C9, "ASK_Close", $C$4)} -> 4.371 | F9: {=INDEX(Sheet2!$I$3:$AP$18, $B9, Sheet1!F$6)} -> 02Y | G9: {=_xll.IMDP("IR", G$6&F9, "BID_Close", $C$4)} -> 3.8458 | H9: {=_xll.IMDP("IR", H$6&F9, "ASK_Close", $C$4)} -> 3.821 | I9: {=INDEX(Sheet2!$I$3:$AP$18, $B9, Sheet1!I$6)} -> 02Y | J9: {=_xll.IMDP("IR", J$6&I9, "BID_Close", $C$4)} -> 1.8274 | K9: {=_xll.IMDP("IR", K$6&I9, "ASK_Close", $C$4)} -> 1.8113 | L9: {=INDEX(Sheet2!$I$3:$AP$18, $B9, Sheet1!L$6)} -> 02Y | M9: {=_xll.IMDP("IR", M$6&L9, "BID_Close", $C$4)} -> 0.7441 | N9: {=_xll.IMDP("IR", N$6&L9, "ASK_Close", $C$4)} -> 0.7341 | O9: {=INDEX(Sheet2!$I$3:$AP$18, $B9, Sheet1!O$6)} -> 02Y | P9: {=_xll.IMDP("IR", P$6&O9, "BID_Close", $C$4)} -> 3.2614 | Q9: {=_xll.IMDP("IR", Q$6&O9, "ASK_Close", $C$4)} -> 3.2414 | R9: {=INDEX(Sheet2!$I$3:$AP$18, $B9, Sheet1!R$6)} -> 02Y | S9: {=_xll.IMDP("IR", S$6&R9, "BID_Close", $C$4)} -> 1.82 | T9: {=_xll.IMDP("IR", T$6&R9, "ASK_Close", $C$4)} -> 1.74 | U9: {=INDEX(Sheet2!$I$3:$AP$18, $B9, Sheet1!U$6)} -> 02Y | V9: {=_xll.IMDP("IR", V$6&U9, "BID_Close", $C$4)} -> 1.3734 | W9: {=_xll.IMDP("IR", W$6&U9, "ASK_Close", $C$4)} -> 1.3325 | X9: {=INDEX(Sheet2!$I$3:$AP$18, $B9, Sheet1!X$6)} -> 05Y | Y9: {=_xll.IMDP("IR", Y$6&X9, "BID_Close", $C$4)} -> 1.35 | Z9: {=_xll.IMDP("IR", Z$6&X9, "ASK_Close", $C$4)} -> 1.31 | AA9: {=INDEX(Sheet2!$I$3:$AP$18, $B9, Sheet1!AA$6)} -> 02Y | AB9: {=_xll.IMDP("IR", AB$6&AA9, "BID_Close", $C$4)} -> 1.8274 | AC9: {=_xll.IMDP("IR", AC$6&AA9, "ASK_Close", $C$4)} -> 1.8113 | AD9: {=INDEX(Sheet2!$I$3:$AP$18, $B9, Sheet1!AD$6)} -> 02Y | AE9: {=_xll.IMDP("IR", AE$6&AD9, "BID_Close", $C$4)} -> 2.1326 | AF9: {=_xll.IMDP("IR", AF$6&AD9, "ASK_Close", $C$4)} -> 2.1124 | AG9: {=INDEX(Sheet2!$I$3:$AP$18, $B9, Sheet1!AG$6)} -> 02Y | AH9: {=_xll.IMDP("IR", AH$6&AG9, "BID_Close", $C$4)} -> 2.0683 | AI9: {=_xll.IMDP("IR", AI$6&AG9, "ASK_Close", $C$4)} -> 2.0432 | AJ9: {=INDEX(Sheet2!$I$3:$AP$18, $B9, Sheet1!AJ$6)} -> 04Y | AK9: {=_xll.IMDP("IR", AK$6&AJ9, "BID_Close", $C$4)} -> 2.815 | AL9: {=_xll.IMDP("IR", AL$6&AJ9, "ASK_Close", $C$4)} -> 2.8142
B10: 3 | C10: {=INDEX(Sheet2!$I$3:$AP$18, $B10, Sheet1!C$6)} -> 03M | D10: {=_xll.IMDP("IR", D$6&C10, "BID_Close", $C$4)} -> 4.354 | E10: {=_xll.IMDP("IR", E$6&C10, "ASK_Close", $C$4)} -> 4.343 | F10: {=INDEX(Sheet2!$I$3:$AP$18, $B10, Sheet1!F$6)} -> 03Y | G10: {=_xll.IMDP("IR", G$6&F10, "BID_Close", $C$4)} -> 3.6603 | H10: {=_xll.IMDP("IR", H$6&F10, "ASK_Close", $C$4)} -> 3.6431 | I10: {=INDEX(Sheet2!$I$3:$AP$18, $B10, Sheet1!I$6)} -> 03Y | J10: {=_xll.IMDP("IR", J$6&I10, "BID_Close", $C$4)} -> 1.8699 | K10: {=_xll.IMDP("IR", K$6&I10, "ASK_Close", $C$4)} -> 1.855 | L10: {=INDEX(Sheet2!$I$3:$AP$18, $B10, Sheet1!L$6)} -> 03Y | M10: {=_xll.IMDP("IR", M$6&L10, "BID_Close", $C$4)} -> 0.8037 | N10: {=_xll.IMDP("IR", N$6&L10, "ASK_Close", $C$4)} -> 0.7937 | O10: {=INDEX(Sheet2!$I$3:$AP$18, $B10, Sheet1!O$6)} -> 03Y | P10: {=_xll.IMDP("IR", P$6&O10, "BID_Close", $C$4)} -> 3.3049 | Q10: {=_xll.IMDP("IR", Q$6&O10, "ASK_Close", $C$4)} -> 3.2849 | R10: {=INDEX(Sheet2!$I$3:$AP$18, $B10, Sheet1!R$6)} -> 03Y | S10: {=_xll.IMDP("IR", S$6&R10, "BID_Close", $C$4)} -> 1.92 | T10: {=_xll.IMDP("IR", T$6&R10, "ASK_Close", $C$4)} -> 1.85 | U10: {=INDEX(Sheet2!$I$3:$AP$18, $B10, Sheet1!U$6)} -> 03Y | V10: {=_xll.IMDP("IR", V$6&U10, "BID_Close", $C$4)} -> 1.3983 | W10: {=_xll.IMDP("IR", W$6&U10, "ASK_Close", $C$4)} -> 1.3577 | X10: {=INDEX(Sheet2!$I$3:$AP$18, $B10, Sheet1!X$6)} -> 10Y | Y10: {=_xll.IMDP("IR", Y$6&X10, "BID_Close", $C$4)} -> 1.41 | Z10: {=_xll.IMDP("IR", Z$6&X10, "ASK_Close", $C$4)} -> 1.37 | AA10: {=INDEX(Sheet2!$I$3:$AP$18, $B10, Sheet1!AA$6)} -> 03Y | AB10: {=_xll.IMDP("IR", AB$6&AA10, "BID_Close", $C$4)} -> 1.8699 | AC10: {=_xll.IMDP("IR", AC$6&AA10, "ASK_Close", $C$4)} -> 1.855 | AD10: {=INDEX(Sheet2!$I$3:$AP$18, $B10, Sheet1!AD$6)} -> 03Y | AE10: {=_xll.IMDP("IR", AE$6&AD10, "BID_Close", $C$4)} -> 2.3463 | AF10: {=_xll.IMDP("IR", AF$6&AD10, "ASK_Close", $C$4)} -> 2.3319 | AG10: {=INDEX(Sheet2!$I$3:$AP$18, $B10, Sheet1!AG$6)} -> 03Y | AH10: {=_xll.IMDP("IR", AH$6&AG10, "BID_Close", $C$4)} -> 2.2666 | AI10: {=_xll.IMDP("IR", AI$6&AG10, "ASK_Close", $C$4)} -> 2.2453 | AJ10: {=INDEX(Sheet2!$I$3:$AP$18, $B10, Sheet1!AJ$6)} -> 05Y | AK10: {=_xll.IMDP("IR", AK$6&AJ10, "BID_Close", $C$4)} -> 2.9446 | AL10: {=_xll.IMDP("IR", AL$6&AJ10, "ASK_Close", $C$4)} -> 2.944
B11: 4 | C11: {=INDEX(Sheet2!$I$3:$AP$18, $B11, Sheet1!C$6)} -> 04M | D11: {=_xll.IMDP("IR", D$6&C11, "BID_Close", $C$4)} -> 4.339 | E11: {=_xll.IMDP("IR", E$6&C11, "ASK_Close", $C$4)} -> 4.329 | F11: {=INDEX(Sheet2!$I$3:$AP$18, $B11, Sheet1!F$6)} -> 04Y | G11: {=_xll.IMDP("IR", G$6&F11, "BID_Close", $C$4)} -> 3.834 | H11: {=_xll.IMDP("IR", H$6&F11, "ASK_Close", $C$4)} -> 3.816 | I11: {=INDEX(Sheet2!$I$3:$AP$18, $B11, Sheet1!I$6)} -> 04Y | J11: {=_xll.IMDP("IR", J$6&I11, "BID_Close", $C$4)} -> 2.0157 | K11: {=_xll.IMDP("IR", K$6&I11, "ASK_Close", $C$4)} -> 2.0018 | L11: {=INDEX(Sheet2!$I$3:$AP$18, $B11, Sheet1!L$6)} -> 04Y | M11: {=_xll.IMDP("IR", M$6&L11, "BID_Close", $C$4)} -> 0.9257 | N11: {=_xll.IMDP("IR", N$6&L11, "ASK_Close", $C$4)} -> 0.9157 | O11: {=INDEX(Sheet2!$I$3:$AP$18, $B11, Sheet1!O$6)} -> 04Y | P11: {=_xll.IMDP("IR", P$6&O11, "BID_Close", $C$4)} -> 3.3924 | Q11: {=_xll.IMDP("IR", Q$6&O11, "ASK_Close", $C$4)} -> 3.3724 | R11: {=INDEX(Sheet2!$I$3:$AP$18, $B11, Sheet1!R$6)} -> 05Y | S11: {=_xll.IMDP("IR", S$6&R11, "BID_Close", $C$4)} -> 2.02 | T11: {=_xll.IMDP("IR", T$6&R11, "ASK_Close", $C$4)} -> 1.92 | U11: {=INDEX(Sheet2!$I$3:$AP$18, $B11, Sheet1!U$6)} -> 05Y | V11: {=_xll.IMDP("IR", V$6&U11, "BID_Close", $C$4)} -> 1.5033 | W11: {=_xll.IMDP("IR", W$6&U11, "ASK_Close", $C$4)} -> 1.463 | X11: {=INDEX(Sheet2!$I$3:$AP$18, $B11, Sheet1!X$6)} -> 20Y | Y11: {=_xll.IMDP("IR", Y$6&X11, "BID_Close", $C$4)} -> 1.58 | Z11: {=_xll.IMDP("IR", Z$6&X11, "ASK_Close", $C$4)} -> 1.54 | AA11: {=INDEX(Sheet2!$I$3:$AP$18, $B11, Sheet1!AA$6)} -> 04Y | AB11: {=_xll.IMDP("IR", AB$6&AA11, "BID_Close", $C$4)} -> 2.0157 | AC11: {=_xll.IMDP("IR", AC$6&AA11, "ASK_Close", $C$4)} -> 2.0018 | AD11: {=INDEX(Sheet2!$I$3:$AP$18, $B11, Sheet1!AD$6)} -> 04Y | AE11: {=_xll.IMDP("IR", AE$6&AD11, "BID_Close", $C$4)} -> 2.5188 | AF11: {=_xll.IMDP("IR", AF$6&AD11, "ASK_Close", $C$4)} -> 2.505 | AG11: {=INDEX(Sheet2!$I$3:$AP$18, $B11, Sheet1!AG$6)} -> 04Y | AH11: {=_xll.IMDP("IR", AH$6&AG11, "BID_Close", $C$4)} -> 2.4258 | AI11: {=_xll.IMDP("IR", AI$6&AG11, "ASK_Close", $C$4)} -> 2.4097 | AJ11: {=INDEX(Sheet2!$I$3:$AP$18, $B11, Sheet1!AJ$6)} -> 06Y | AK11: {=_xll.IMDP("IR", AK$6&AJ11, "BID_Close", $C$4)} -> 3.086 | AL11: {=_xll.IMDP("IR", AL$6&AJ11, "ASK_Close", $C$4)} -> 3.0855
B12: 5 | C12: {=INDEX(Sheet2!$I$3:$AP$18, $B12, Sheet1!C$6)} -> 06M | D12: {=_xll.IMDP("IR", D$6&C12, "BID_Close", $C$4)} -> 4.302 | E12: {=_xll.IMDP("IR", E$6&C12, "ASK_Close", $C$4)} -> 4.291 | F12: {=INDEX(Sheet2!$I$3:$AP$18, $B12, Sheet1!F$6)} -> 05Y | G12: {=_xll.IMDP("IR", G$6&F12, "BID_Close", $C$4)} -> 3.9831 | H12: {=_xll.IMDP("IR", H$6&F12, "ASK_Close", $C$4)} -> 3.9691 | I12: {=INDEX(Sheet2!$I$3:$AP$18, $B12, Sheet1!I$6)} -> 05Y | J12: {=_xll.IMDP("IR", J$6&I12, "BID_Close", $C$4)} -> 2.1261 | K12: {=_xll.IMDP("IR", K$6&I12, "ASK_Close", $C$4)} -> 2.1151 | L12: {=INDEX(Sheet2!$I$3:$AP$18, $B12, Sheet1!L$6)} -> 05Y | M12: {=_xll.IMDP("IR", M$6&L12, "BID_Close", $C$4)} -> 0.9821 | N12: {=_xll.IMDP("IR", N$6&L12, "ASK_Close", $C$4)} -> 0.9721 | O12: {=INDEX(Sheet2!$I$3:$AP$18, $B12, Sheet1!O$6)} -> 05Y | P12: {=_xll.IMDP("IR", P$6&O12, "BID_Close", $C$4)} -> 3.5134 | Q12: {=_xll.IMDP("IR", Q$6&O12, "ASK_Close", $C$4)} -> 3.4934 | R12: {=INDEX(Sheet2!$I$3:$AP$18, $B12, Sheet1!R$6)} -> 07Y | S12: {=_xll.IMDP("IR", S$6&R12, "BID_Close", $C$4)} | T12: {=_xll.IMDP("IR", T$6&R12, "ASK_Close", $C$4)} | U12: {=INDEX(Sheet2!$I$3:$AP$18, $B12, Sheet1!U$6)} -> 07Y | V12: {=_xll.IMDP("IR", V$6&U12, "BID_Close", $C$4)} -> 1.5879 | W12: {=_xll.IMDP("IR", W$6&U12, "ASK_Close", $C$4)} -> 1.5478 | X12: {=INDEX(Sheet2!$I$3:$AP$18, $B12, Sheet1!X$6)} -> 30Y | Y12: {=_xll.IMDP("IR", Y$6&X12, "BID_Close", $C$4)} -> 1.705 | Z12: {=_xll.IMDP("IR", Z$6&X12, "ASK_Close", $C$4)} -> 1.665 | AA12: {=INDEX(Sheet2!$I$3:$AP$18, $B12, Sheet1!AA$6)} -> 05Y | AB12: {=_xll.IMDP("IR", AB$6&AA12, "BID_Close", $C$4)} -> 2.1261 | AC12: {=_xll.IMDP("IR", AC$6&AA12, "ASK_Close", $C$4)} -> 2.1151 | AD12: {=INDEX(Sheet2!$I$3:$AP$18, $B12, Sheet1!AD$6)} -> 05Y | AE12: {=_xll.IMDP("IR", AE$6&AD12, "BID_Close", $C$4)} -> 2.6954 | AF12: {=_xll.IMDP("IR", AF$6&AD12, "ASK_Close", $C$4)} -> 2.6838 | AG12: {=INDEX(Sheet2!$I$3:$AP$18, $B12, Sheet1!AG$6)} -> 05Y | AH12: {=_xll.IMDP("IR", AH$6&AG12, "BID_Close", $C$4)} -> 2.6941 | AI12: {=_xll.IMDP("IR", AI$6&AG12, "ASK_Close", $C$4)} -> 2.6789 | AJ12: {=INDEX(Sheet2!$I$3:$AP$18, $B12, Sheet1!AJ$6)} -> 07Y | AK12: {=_xll.IMDP("IR", AK$6&AJ12, "BID_Close", $C$4)} -> 3.1388 | AL12: {=_xll.IMDP("IR", AL$6&AJ12, "ASK_Close", $C$4)} -> 3.1384
B13: 6 | C13: {=INDEX(Sheet2!$I$3:$AP$18, $B13, Sheet1!C$6)} -> 01Y | D13: {=_xll.IMDP("IR", D$6&C13, "BID_Close", $C$4)} -> 4.08 | E13: {=_xll.IMDP("IR", E$6&C13, "ASK_Close", $C$4)} -> 4.069 | F13: {=INDEX(Sheet2!$I$3:$AP$18, $B13, Sheet1!F$6)} -> 06Y | G13: {=_xll.IMDP("IR", G$6&F13, "BID_Close", $C$4)} -> 3.9285 | H13: {=_xll.IMDP("IR", H$6&F13, "ASK_Close", $C$4)} -> 3.9164 | I13: {=INDEX(Sheet2!$I$3:$AP$18, $B13, Sheet1!I$6)} -> 06Y | J13: {=_xll.IMDP("IR", J$6&I13, "BID_Close", $C$4)} -> 2.2182 | K13: {=_xll.IMDP("IR", K$6&I13, "ASK_Close", $C$4)} -> 2.2067 | L13: {=INDEX(Sheet2!$I$3:$AP$18, $B13, Sheet1!L$6)} -> 06Y | M13: {=_xll.IMDP("IR", M$6&L13, "BID_Close", $C$4)} -> 1.0964 | N13: {=_xll.IMDP("IR", N$6&L13, "ASK_Close", $C$4)} -> 1.0864 | O13: {=INDEX(Sheet2!$I$3:$AP$18, $B13, Sheet1!O$6)} -> 07Y | P13: {=_xll.IMDP("IR", P$6&O13, "BID_Close", $C$4)} -> 3.8514 | Q13: {=_xll.IMDP("IR", Q$6&O13, "ASK_Close", $C$4)} -> 3.8314 | R13: {=INDEX(Sheet2!$I$3:$AP$18, $B13, Sheet1!R$6)} | S13: {=_xll.IMDP("IR", S$6&R13, "BID_Close", $C$4)} | T13: {=_xll.IMDP("IR", T$6&R13, "ASK_Close", $C$4)} | U13: {=INDEX(Sheet2!$I$3:$AP$18, $B13, Sheet1!U$6)} -> 10Y | V13: {=_xll.IMDP("IR", V$6&U13, "BID_Close", $C$4)} -> 1.6621 | W13: {=_xll.IMDP("IR", W$6&U13, "ASK_Close", $C$4)} -> 1.6219 | X13: {=INDEX(Sheet2!$I$3:$AP$18, $B13, Sheet1!X$6)} | Y13: {=_xll.IMDP("IR", Y$6&X13, "BID_Close", $C$4)} | Z13: {=_xll.IMDP("IR", Z$6&X13, "ASK_Close", $C$4)} | AA13: {=INDEX(Sheet2!$I$3:$AP$18, $B13, Sheet1!AA$6)} -> 06Y | AB13: {=_xll.IMDP("IR", AB$6&AA13, "BID_Close", $C$4)} -> 2.2182 | AC13: {=_xll.IMDP("IR", AC$6&AA13, "ASK_Close", $C$4)} -> 2.2067 | AD13: {=INDEX(Sheet2!$I$3:$AP$18, $B13, Sheet1!AD$6)} -> 06Y | AE13: {=_xll.IMDP("IR", AE$6&AD13, "BID_Close", $C$4)} -> 2.7957 | AF13: {=_xll.IMDP("IR", AF$6&AD13, "ASK_Close", $C$4)} -> 2.7841 | AG13: {=INDEX(Sheet2!$I$3:$AP$18, $B13, Sheet1!AG$6)} -> 06Y | AH13: {=_xll.IMDP("IR", AH$6&AG13, "BID_Close", $C$4)} -> 2.7917 | AI13: {=_xll.IMDP("IR", AI$6&AG13, "ASK_Close", $C$4)} -> 2.7754 | AJ13: {=INDEX(Sheet2!$I$3:$AP$18, $B13, Sheet1!AJ$6)} -> 08Y | AK13: {=_xll.IMDP("IR", AK$6&AJ13, "BID_Close", $C$4)} -> 3.216 | AL13: {=_xll.IMDP("IR", AL$6&AJ13, "ASK_Close", $C$4)} -> 3.2156
B14: 7 | C14: {=INDEX(Sheet2!$I$3:$AP$18, $B14, Sheet1!C$6)} -> 02Y | D14: {=_xll.IMDP("IR", D$6&C14, "BID_Close", $C$4)} -> 3.886 | E14: {=_xll.IMDP("IR", E$6&C14, "ASK_Close", $C$4)} -> 3.874 | F14: {=INDEX(Sheet2!$I$3:$AP$18, $B14, Sheet1!F$6)} -> 07Y | G14: {=_xll.IMDP("IR", G$6&F14, "BID_Close", $C$4)} -> 4.1439 | H14: {=_xll.IMDP("IR", H$6&F14, "ASK_Close", $C$4)} -> 4.1293 | I14: {=INDEX(Sheet2!$I$3:$AP$18, $B14, Sheet1!I$6)} -> 07Y | J14: {=_xll.IMDP("IR", J$6&I14, "BID_Close", $C$4)} -> 2.3262 | K14: {=_xll.IMDP("IR", K$6&I14, "ASK_Close", $C$4)} -> 2.3135 | L14: {=INDEX(Sheet2!$I$3:$AP$18, $B14, Sheet1!L$6)} -> 07Y | M14: {=_xll.IMDP("IR", M$6&L14, "BID_Close", $C$4)} -> 1.2064 | N14: {=_xll.IMDP("IR", N$6&L14, "ASK_Close", $C$4)} -> 1.1964 | O14: {=INDEX(Sheet2!$I$3:$AP$18, $B14, Sheet1!O$6)} -> 09Y | P14: {=_xll.IMDP("IR", P$6&O14, "BID_Close", $C$4)} -> 4.0954 | Q14: {=_xll.IMDP("IR", Q$6&O14, "ASK_Close", $C$4)} -> 4.0754 | R14: {=INDEX(Sheet2!$I$3:$AP$18, $B14, Sheet1!R$6)} | S14: {=_xll.IMDP("IR", S$6&R14, "BID_Close", $C$4)} | T14: {=_xll.IMDP("IR", T$6&R14, "ASK_Close", $C$4)} | U14: {=INDEX(Sheet2!$I$3:$AP$18, $B14, Sheet1!U$6)} -> 15Y | V14: {=_xll.IMDP("IR", V$6&U14, "BID_Close", $C$4)} -> 1.905 | W14: {=_xll.IMDP("IR", W$6&U14, "ASK_Close", $C$4)} -> 1.865 | X14: {=INDEX(Sheet2!$I$3:$AP$18, $B14, Sheet1!X$6)} | Y14: {=_xll.IMDP("IR", Y$6&X14, "BID_Close", $C$4)} | Z14: {=_xll.IMDP("IR", Z$6&X14, "ASK_Close", $C$4)} | AA14: {=INDEX(Sheet2!$I$3:$AP$18, $B14, Sheet1!AA$6)} -> 07Y | AB14: {=_xll.IMDP("IR", AB$6&AA14, "BID_Close", $C$4)} -> 2.3262 | AC14: {=_xll.IMDP("IR", AC$6&AA14, "ASK_Close", $C$4)} -> 2.3135 | AD14: {=INDEX(Sheet2!$I$3:$AP$18, $B14, Sheet1!AD$6)} -> 07Y | AE14: {=_xll.IMDP("IR", AE$6&AD14, "BID_Close", $C$4)} -> 2.8864 | AF14: {=_xll.IMDP("IR", AF$6&AD14, "ASK_Close", $C$4)} -> 2.8754 | AG14: {=INDEX(Sheet2!$I$3:$AP$18, $B14, Sheet1!AG$6)} -> 07Y | AH14: {=_xll.IMDP("IR", AH$6&AG14, "BID_Close", $C$4)} -> 3.0675 | AI14: {=_xll.IMDP("IR", AI$6&AG14, "ASK_Close", $C$4)} -> 3.0547 | AJ14: {=INDEX(Sheet2!$I$3:$AP$18, $B14, Sheet1!AJ$6)} -> 09Y | AK14: {=_xll.IMDP("IR", AK$6&AJ14, "BID_Close", $C$4)} -> 3.2692 | AL14: {=_xll.IMDP("IR", AL$6&AJ14, "ASK_Close", $C$4)} -> 3.2688
B15: 8 | C15: {=INDEX(Sheet2!$I$3:$AP$18, $B15, Sheet1!C$6)} -> 03Y | D15: {=_xll.IMDP("IR", D$6&C15, "BID_Close", $C$4)} -> 3.846 | E15: {=_xll.IMDP("IR", E$6&C15, "ASK_Close", $C$4)} -> 3.837 | F15: {=INDEX(Sheet2!$I$3:$AP$18, $B15, Sheet1!F$6)} -> 08Y | G15: {=_xll.IMDP("IR", G$6&F15, "BID_Close", $C$4)} -> 4.3006 | H15: {=_xll.IMDP("IR", H$6&F15, "ASK_Close", $C$4)} -> 4.2876 | I15: {=INDEX(Sheet2!$I$3:$AP$18, $B15, Sheet1!I$6)} -> 08Y | J15: {=_xll.IMDP("IR", J$6&I15, "BID_Close", $C$4)} -> 2.4351 | K15: {=_xll.IMDP("IR", K$6&I15, "ASK_Close", $C$4)} -> 2.4242 | L15: {=INDEX(Sheet2!$I$3:$AP$18, $B15, Sheet1!L$6)} -> 08Y | M15: {=_xll.IMDP("IR", M$6&L15, "BID_Close", $C$4)} -> 1.2734 | N15: {=_xll.IMDP("IR", N$6&L15, "ASK_Close", $C$4)} -> 1.2634 | O15: {=INDEX(Sheet2!$I$3:$AP$18, $B15, Sheet1!O$6)} -> 10Y | P15: {=_xll.IMDP("IR", P$6&O15, "BID_Close", $C$4)} -> 4.202 | Q15: {=_xll.IMDP("IR", Q$6&O15, "ASK_Close", $C$4)} -> 4.182 | R15: {=INDEX(Sheet2!$I$3:$AP$18, $B15, Sheet1!R$6)} | S15: {=_xll.IMDP("IR", S$6&R15, "BID_Close", $C$4)} | T15: {=_xll.IMDP("IR", T$6&R15, "ASK_Close", $C$4)} | U15: {=INDEX(Sheet2!$I$3:$AP$18, $B15, Sheet1!U$6)} -> 20Y | V15: {=_xll.IMDP("IR", V$6&U15, "BID_Close", $C$4)} -> 1.9107 | W15: {=_xll.IMDP("IR", W$6&U15, "ASK_Close", $C$4)} -> 1.8705 | X15: {=INDEX(Sheet2!$I$3:$AP$18, $B15, Sheet1!X$6)} | Y15: {=_xll.IMDP("IR", Y$6&X15, "BID_Close", $C$4)} | Z15: {=_xll.IMDP("IR", Z$6&X15, "ASK_Close", $C$4)} | AA15: {=INDEX(Sheet2!$I$3:$AP$18, $B15, Sheet1!AA$6)} -> 08Y | AB15: {=_xll.IMDP("IR", AB$6&AA15, "BID_Close", $C$4)} -> 2.4351 | AC15: {=_xll.IMDP("IR", AC$6&AA15, "ASK_Close", $C$4)} -> 2.4242 | AD15: {=INDEX(Sheet2!$I$3:$AP$18, $B15, Sheet1!AD$6)} -> 08Y | AE15: {=_xll.IMDP("IR", AE$6&AD15, "BID_Close", $C$4)} -> 3.0278 | AF15: {=_xll.IMDP("IR", AF$6&AD15, "ASK_Close", $C$4)} -> 3.0177 | AG15: {=INDEX(Sheet2!$I$3:$AP$18, $B15, Sheet1!AG$6)} -> 08Y | AH15: {=_xll.IMDP("IR", AH$6&AG15, "BID_Close", $C$4)} -> 3.1308 | AI15: {=_xll.IMDP("IR", AI$6&AG15, "ASK_Close", $C$4)} -> 3.1196 | AJ15: {=INDEX(Sheet2!$I$3:$AP$18, $B15, Sheet1!AJ$6)} -> 10Y | AK15: {=_xll.IMDP("IR", AK$6&AJ15, "BID_Close", $C$4)} -> 3.3561 | AL15: {=_xll.IMDP("IR", AL$6&AJ15, "ASK_Close", $C$4)} -> 3.3558
B16: 9 | C16: {=INDEX(Sheet2!$I$3:$AP$18, $B16, Sheet1!C$6)} -> 05Y | D16: {=_xll.IMDP("IR", D$6&C16, "BID_Close", $C$4)} -> 3.934 | E16: {=_xll.IMDP("IR", E$6&C16, "ASK_Close", $C$4)} -> 3.929 | F16: {=INDEX(Sheet2!$I$3:$AP$18, $B16, Sheet1!F$6)} -> 09Y | G16: {=_xll.IMDP("IR", G$6&F16, "BID_Close", $C$4)} -> 4.4196 | H16: {=_xll.IMDP("IR", H$6&F16, "ASK_Close", $C$4)} -> 4.4084 | I16: {=INDEX(Sheet2!$I$3:$AP$18, $B16, Sheet1!I$6)} -> 09Y | J16: {=_xll.IMDP("IR", J$6&I16, "BID_Close", $C$4)} -> 2.5233 | K16: {=_xll.IMDP("IR", K$6&I16, "ASK_Close", $C$4)} -> 2.5134 | L16: {=INDEX(Sheet2!$I$3:$AP$18, $B16, Sheet1!L$6)} -> 09Y | M16: {=_xll.IMDP("IR", M$6&L16, "BID_Close", $C$4)} -> 1.3594 | N16: {=_xll.IMDP("IR", N$6&L16, "ASK_Close", $C$4)} -> 1.3494 | O16: {=INDEX(Sheet2!$I$3:$AP$18, $B16, Sheet1!O$6)} -> 15Y | P16: {=_xll.IMDP("IR", P$6&O16, "BID_Close", $C$4)} -> 4.4294 | Q16: {=_xll.IMDP("IR", Q$6&O16, "ASK_Close", $C$4)} -> 4.4094 | R16: {=INDEX(Sheet2!$I$3:$AP$18, $B16, Sheet1!R$6)} | S16: {=_xll.IMDP("IR", S$6&R16, "BID_Close", $C$4)} | T16: {=_xll.IMDP("IR", T$6&R16, "ASK_Close", $C$4)} | U16: {=INDEX(Sheet2!$I$3:$AP$18, $B16, Sheet1!U$6)} -> 30Y | V16: {=_xll.IMDP("IR", V$6&U16, "BID_Close", $C$4)} -> 1.8699 | W16: {=_xll.IMDP("IR", W$6&U16, "ASK_Close", $C$4)} -> 1.8297 | X16: {=INDEX(Sheet2!$I$3:$AP$18, $B16, Sheet1!X$6)} | Y16: {=_xll.IMDP("IR", Y$6&X16, "BID_Close", $C$4)} | Z16: {=_xll.IMDP("IR", Z$6&X16, "ASK_Close", $C$4)} | AA16: {=INDEX(Sheet2!$I$3:$AP$18, $B16, Sheet1!AA$6)} -> 09Y | AB16: {=_xll.IMDP("IR", AB$6&AA16, "BID_Close", $C$4)} -> 2.5233 | AC16: {=_xll.IMDP("IR", AC$6&AA16, "ASK_Close", $C$4)} -> 2.5134 | AD16: {=INDEX(Sheet2!$I$3:$AP$18, $B16, Sheet1!AD$6)} -> 09Y | AE16: {=_xll.IMDP("IR", AE$6&AD16, "BID_Close", $C$4)} -> 3.1657 | AF16: {=_xll.IMDP("IR", AF$6&AD16, "ASK_Close", $C$4)} -> 3.1557 | AG16: {=INDEX(Sheet2!$I$3:$AP$18, $B16, Sheet1!AG$6)} -> 09Y | AH16: {=_xll.IMDP("IR", AH$6&AG16, "BID_Close", $C$4)} -> 3.2581 | AI16: {=_xll.IMDP("IR", AI$6&AG16, "ASK_Close", $C$4)} -> 3.2477 | AJ16: {=INDEX(Sheet2!$I$3:$AP$18, $B16, Sheet1!AJ$6)} -> 20Y | AK16: {=_xll.IMDP("IR", AK$6&AJ16, "BID_Close", $C$4)} -> 3.5668 | AL16: {=_xll.IMDP("IR", AL$6&AJ16, "ASK_Close", $C$4)} -> 3.5666
B17: 10 | C17: {=INDEX(Sheet2!$I$3:$AP$18, $B17, Sheet1!C$6)} -> 07Y | D17: {=_xll.IMDP("IR", D$6&C17, "BID_Close", $C$4)} -> 4.121 | E17: {=_xll.IMDP("IR", E$6&C17, "ASK_Close", $C$4)} -> 4.118 | F17: {=INDEX(Sheet2!$I$3:$AP$18, $B17, Sheet1!F$6)} -> 10Y | G17: {=_xll.IMDP("IR", G$6&F17, "BID_Close", $C$4)} -> 4.5445 | H17: {=_xll.IMDP("IR", H$6&F17, "ASK_Close", $C$4)} -> 4.5342 | I17: {=INDEX(Sheet2!$I$3:$AP$18, $B17, Sheet1!I$6)} -> 10Y | J17: {=_xll.IMDP("IR", J$6&I17, "BID_Close", $C$4)} -> 2.595 | K17: {=_xll.IMDP("IR", K$6&I17, "ASK_Close", $C$4)} -> 2.5859 | L17: {=INDEX(Sheet2!$I$3:$AP$18, $B17, Sheet1!L$6)} -> 10Y | M17: {=_xll.IMDP("IR", M$6&L17, "BID_Close", $C$4)} -> 1.4551 | N17: {=_xll.IMDP("IR", N$6&L17, "ASK_Close", $C$4)} -> 1.4451 | O17: {=INDEX(Sheet2!$I$3:$AP$18, $B17, Sheet1!O$6)} -> 20Y | P17: {=_xll.IMDP("IR", P$6&O17, "BID_Close", $C$4)} -> 4.7594 | Q17: {=_xll.IMDP("IR", Q$6&O17, "ASK_Close", $C$4)} -> 4.7394 | R17: {=INDEX(Sheet2!$I$3:$AP$18, $B17, Sheet1!R$6)} | S17: {=_xll.IMDP("IR", S$6&R17, "BID_Close", $C$4)} | T17: {=_xll.IMDP("IR", T$6&R17, "ASK_Close", $C$4)} | U17: {=INDEX(Sheet2!$I$3:$AP$18, $B17, Sheet1!U$6)} | V17: {=_xll.IMDP("IR", V$6&U17, "BID_Close", $C$4)} | W17: {=_xll.IMDP("IR", W$6&U17, "ASK_Close", $C$4)} | X17: {=INDEX(Sheet2!$I$3:$AP$18, $B17, Sheet1!X$6)} | Y17: {=_xll.IMDP("IR", Y$6&X17, "BID_Close", $C$4)} | Z17: {=_xll.IMDP("IR", Z$6&X17, "ASK_Close", $C$4)} | AA17: {=INDEX(Sheet2!$I$3:$AP$18, $B17, Sheet1!AA$6)} -> 10Y | AB17: {=_xll.IMDP("IR", AB$6&AA17, "BID_Close", $C$4)} -> 2.595 | AC17: {=_xll.IMDP("IR", AC$6&AA17, "ASK_Close", $C$4)} -> 2.5859 | AD17: {=INDEX(Sheet2!$I$3:$AP$18, $B17, Sheet1!AD$6)} -> 10Y | AE17: {=_xll.IMDP("IR", AE$6&AD17, "BID_Close", $C$4)} -> 3.2806 | AF17: {=_xll.IMDP("IR", AF$6&AD17, "ASK_Close", $C$4)} -> 3.2721 | AG17: {=INDEX(Sheet2!$I$3:$AP$18, $B17, Sheet1!AG$6)} -> 10Y | AH17: {=_xll.IMDP("IR", AH$6&AG17, "BID_Close", $C$4)} -> 3.4558 | AI17: {=_xll.IMDP("IR", AI$6&AG17, "ASK_Close", $C$4)} -> 3.4463 | AJ17: {=INDEX(Sheet2!$I$3:$AP$18, $B17, Sheet1!AJ$6)} -> 30Y | AK17: {=_xll.IMDP("IR", AK$6&AJ17, "BID_Close", $C$4)} -> 3.6706 | AL17: {=_xll.IMDP("IR", AL$6&AJ17, "ASK_Close", $C$4)} -> 3.6705
B18: 11 | C18: {=INDEX(Sheet2!$I$3:$AP$18, $B18, Sheet1!C$6)} -> 10Y | D18: {=_xll.IMDP("IR", D$6&C18, "BID_Close", $C$4)} -> 4.346 | E18: {=_xll.IMDP("IR", E$6&C18, "ASK_Close", $C$4)} -> 4.336 | F18: {=INDEX(Sheet2!$I$3:$AP$18, $B18, Sheet1!F$6)} -> 12Y | G18: {=_xll.IMDP("IR", G$6&F18, "BID_Close", $C$4)} -> 4.7402 | H18: {=_xll.IMDP("IR", H$6&F18, "ASK_Close", $C$4)} -> 4.7297 | I18: {=INDEX(Sheet2!$I$3:$AP$18, $B18, Sheet1!I$6)} -> 15Y | J18: {=_xll.IMDP("IR", J$6&I18, "BID_Close", $C$4)} -> 2.9058 | K18: {=_xll.IMDP("IR", K$6&I18, "ASK_Close", $C$4)} -> 2.8993 | L18: {=INDEX(Sheet2!$I$3:$AP$18, $B18, Sheet1!L$6)} -> 15Y | M18: {=_xll.IMDP("IR", M$6&L18, "BID_Close", $C$4)} -> 2.2691 | N18: {=_xll.IMDP("IR", N$6&L18, "ASK_Close", $C$4)} -> 2.2591 | O18: {=INDEX(Sheet2!$I$3:$AP$18, $B18, Sheet1!O$6)} -> 30Y | P18: {=_xll.IMDP("IR", P$6&O18, "BID_Close", $C$4)} -> 4.8634 | Q18: {=_xll.IMDP("IR", Q$6&O18, "ASK_Close", $C$4)} -> 4.8434 | R18: {=INDEX(Sheet2!$I$3:$AP$18, $B18, Sheet1!R$6)} | S18: {=_xll.IMDP("IR", S$6&R18, "BID_Close", $C$4)} | T18: {=_xll.IMDP("IR", T$6&R18, "ASK_Close", $C$4)} | U18: {=INDEX(Sheet2!$I$3:$AP$18, $B18, Sheet1!U$6)} | V18: {=_xll.IMDP("IR", V$6&U18, "BID_Close", $C$4)} | W18: {=_xll.IMDP("IR", W$6&U18, "ASK_Close", $C$4)} | X18: {=INDEX(Sheet2!$I$3:$AP$18, $B18, Sheet1!X$6)} | Y18: {=_xll.IMDP("IR", Y$6&X18, "BID_Close", $C$4)} | Z18: {=_xll.IMDP("IR", Z$6&X18, "ASK_Close", $C$4)} | AA18: {=INDEX(Sheet2!$I$3:$AP$18, $B18, Sheet1!AA$6)} -> 15Y | AB18: {=_xll.IMDP("IR", AB$6&AA18, "BID_Close", $C$4)} -> 2.9058 | AC18: {=_xll.IMDP("IR", AC$6&AA18, "ASK_Close", $C$4)} -> 2.8993 | AD18: {=INDEX(Sheet2!$I$3:$AP$18, $B18, Sheet1!AD$6)} -> 15Y | AE18: {=_xll.IMDP("IR", AE$6&AD18, "BID_Close", $C$4)} -> 3.66 | AF18: {=_xll.IMDP("IR", AF$6&AD18, "ASK_Close", $C$4)} -> 3.651 | AG18: {=INDEX(Sheet2!$I$3:$AP$18, $B18, Sheet1!AG$6)} -> 15Y | AH18: {=_xll.IMDP("IR", AH$6&AG18, "BID_Close", $C$4)} -> 3.9083 | AI18: {=_xll.IMDP("IR", AI$6&AG18, "ASK_Close", $C$4)} -> 3.9011 | AJ18: {=INDEX(Sheet2!$I$3:$AP$18, $B18, Sheet1!AJ$6)} | AK18: {=_xll.IMDP("IR", AK$6&AJ18, "BID_Close", $C$4)} | AL18: {=_xll.IMDP("IR", AL$6&AJ18, "ASK_Close", $C$4)}
B19: 12 | C19: {=INDEX(Sheet2!$I$3:$AP$18, $B19, Sheet1!C$6)} -> 20Y | D19: {=_xll.IMDP("IR", D$6&C19, "BID_Close", $C$4)} -> 4.868 | E19: {=_xll.IMDP("IR", E$6&C19, "ASK_Close", $C$4)} -> 4.863 | F19: {=INDEX(Sheet2!$I$3:$AP$18, $B19, Sheet1!F$6)} -> 15Y | G19: {=_xll.IMDP("IR", G$6&F19, "BID_Close", $C$4)} -> 4.9239 | H19: {=_xll.IMDP("IR", H$6&F19, "ASK_Close", $C$4)} -> 4.9156 | I19: {=INDEX(Sheet2!$I$3:$AP$18, $B19, Sheet1!I$6)} -> 20Y | J19: {=_xll.IMDP("IR", J$6&I19, "BID_Close", $C$4)} -> 2.9634 | K19: {=_xll.IMDP("IR", K$6&I19, "ASK_Close", $C$4)} -> 2.958 | L19: {=INDEX(Sheet2!$I$3:$AP$18, $B19, Sheet1!L$6)} -> 20Y | M19: {=_xll.IMDP("IR", M$6&L19, "BID_Close", $C$4)} -> 2.3671 | N19: {=_xll.IMDP("IR", N$6&L19, "ASK_Close", $C$4)} -> 2.3571 | O19: {=INDEX(Sheet2!$I$3:$AP$18, $B19, Sheet1!O$6)} | P19: {=_xll.IMDP("IR", P$6&O19, "BID_Close", $C$4)} | Q19: {=_xll.IMDP("IR", Q$6&O19, "ASK_Close", $C$4)} | R19: {=INDEX(Sheet2!$I$3:$AP$18, $B19, Sheet1!R$6)} | S19: {=_xll.IMDP("IR", S$6&R19, "BID_Close", $C$4)} | T19: {=_xll.IMDP("IR", T$6&R19, "ASK_Close", $C$4)} | U19: {=INDEX(Sheet2!$I$3:$AP$18, $B19, Sheet1!U$6)} | V19: {=_xll.IMDP("IR", V$6&U19, "BID_Close", $C$4)} | W19: {=_xll.IMDP("IR", W$6&U19, "ASK_Close", $C$4)} | X19: {=INDEX(Sheet2!$I$3:$AP$18, $B19, Sheet1!X$6)} | Y19: {=_xll.IMDP("IR", Y$6&X19, "BID_Close", $C$4)} | Z19: {=_xll.IMDP("IR", Z$6&X19, "ASK_Close", $C$4)} | AA19: {=INDEX(Sheet2!$I$3:$AP$18, $B19, Sheet1!AA$6)} -> 20Y | AB19: {=_xll.IMDP("IR", AB$6&AA19, "BID_Close", $C$4)} -> 2.9634 | AC19: {=_xll.IMDP("IR", AC$6&AA19, "ASK_Close", $C$4)} -> 2.958 | AD19: {=INDEX(Sheet2!$I$3:$AP$18, $B19, Sheet1!AD$6)} -> 20Y | AE19: {=_xll.IMDP("IR", AE$6&AD19, "BID_Close", $C$4)} -> 3.7568 | AF19: {=_xll.IMDP("IR", AF$6&AD19, "ASK_Close", $C$4)} -> 3.7486 | AG19: {=INDEX(Sheet2!$I$3:$AP$18, $B19, Sheet1!AG$6)} -> 20Y | AH19: {=_xll.IMDP("IR", AH$6&AG19, "BID_Close", $C$4)} -> 3.9734 | AI19: {=_xll.IMDP("IR", AI$6&AG19, "ASK_Close", $C$4)} -> 3.9658 | AJ19: {=INDEX(Sheet2!$I$3:$AP$18, $B19, Sheet1!AJ$6)} | AK19: {=_xll.IMDP("IR", AK$6&AJ19, "BID_Close", $C$4)} | AL19: {=_xll.IMDP("IR", AL$6&AJ19, "ASK_Close", $C$4)}
... B23: 16 | C23: {=INDEX(Sheet2!$I$3:$AP$18, $B23, Sheet1!C$6)} | D23: {=_xll.IMDP("IR", D$6&C23, "BID_Close", $C$4)} | E23: {=_xll.IMDP("IR", E$6&C23, "ASK_Close", $C$4)} | F23: {=INDEX(Sheet2!$I$3:$AP$18, $B23, Sheet1!F$6)} -> 50Y | G23: {=_xll.IMDP("IR", G$6&F23, "BID_Close", $C$4)} -> 4.682 | H23: {=_xll.IMDP("IR", H$6&F23, "ASK_Close", $C$4)} -> 4.6725 | I23: {=INDEX(Sheet2!$I$3:$AP$18, $B23, Sheet1!I$6)} | J23: {=_xll.IMDP("IR", J$6&I23, "BID_Close", $C$4)} | K23: {=_xll.IMDP("IR", K$6&I23, "ASK_Close", $C$4)} | L23: {=INDEX(Sheet2!$I$3:$AP$18, $B23, Sheet1!L$6)} | M23: {=_xll.IMDP("IR", M$6&L23, "BID_Close", $C$4)} | N23: {=_xll.IMDP("IR", N$6&L23, "ASK_Close", $C$4)} | O23: {=INDEX(Sheet2!$I$3:$AP$18, $B23, Sheet1!O$6)} | P23: {=_xll.IMDP("IR", P$6&O23, "BID_Close", $C$4)} | Q23: {=_xll.IMDP("IR", Q$6&O23, "ASK_Close", $C$4)} | R23: {=INDEX(Sheet2!$I$3:$AP$18, $B23, Sheet1!R$6)} | S23: {=_xll.IMDP("IR", S$6&R23, "BID_Close", $C$4)} | T23: {=_xll.IMDP("IR", T$6&R23, "ASK_Close", $C$4)} | U23: {=INDEX(Sheet2!$I$3:$AP$18, $B23, Sheet1!U$6)} | V23: {=_xll.IMDP("IR", V$6&U23, "BID_Close", $C$4)} | W23: {=_xll.IMDP("IR", W$6&U23, "ASK_Close", $C$4)} | X23: {=INDEX(Sheet2!$I$3:$AP$18, $B23, Sheet1!X$6)} | Y23: {=_xll.IMDP("IR", Y$6&X23, "BID_Close", $C$4)} | Z23: {=_xll.IMDP("IR", Z$6&X23, "ASK_Close", $C$4)} | AA23: {=INDEX(Sheet2!$I$3:$AP$18, $B23, Sheet1!AA$6)} | AB23: {=_xll.IMDP("IR", AB$6&AA23, "BID_Close", $C$4)} | AC23: {=_xll.IMDP("IR", AC$6&AA23, "ASK_Close", $C$4)} | AD23: {=INDEX(Sheet2!$I$3:$AP$18, $B23, Sheet1!AD$6)} | AE23: {=_xll.IMDP("IR", AE$6&AD23, "BID_Close", $C$4)} | AF23: {=_xll.IMDP("IR", AF$6&AD23, "ASK_Close", $C$4)} | AG23: {=INDEX(Sheet2!$I$3:$AP$18, $B23, Sheet1!AG$6)} | AH23: {=_xll.IMDP("IR", AH$6&AG23, "BID_Close", $C$4)} | AI23: {=_xll.IMDP("IR", AI$6&AG23, "ASK_Close", $C$4)} | AJ23: {=INDEX(Sheet2!$I$3:$AP$18, $B23, Sheet1!AJ$6)} | AK23: {=_xll.IMDP("IR", AK$6&AJ23, "BID_Close", $C$4)} | AL23: {=_xll.IMDP("IR", AL$6&AJ23, "ASK_Close", $C$4)}
C26: 스프레드
C28: 10 | D28: {=INDEX(Sheet2!$C$3:$C$36, C28)} -> US
C29: 기물 | D29: =LEFT(Sheet2!$G$4, 3) -> BID | E29: 그리스 | F29: 네덜란드 | G29: 노르웨이 | H29: 뉴질랜드 | I29: 대만 | J29: 덴마크 | K29: 독일 | L29: 말레이시아 | M29: 멕시코 | N29: 미국 | O29: 벨기에 | P29: 브라질 | Q29: 스웨덴 | R29: 스페인 | S29: 싱가포르 | T29: 아일랜드 | U29: 영국 | V29: 유럽연합 | W29: 이탈리아 | X29: 인도 | Y29: 인도네시아 | Z29: 일본 | AA29: 중국 | AB29: 캐나다 | AC29: 콜롬비아 | AD29: 태국 | AE29: 터키 | AF29: 포르투갈 | AG29: 폴란드 | AH29: 프랑스 | AI29: 필리핀 | AJ29: 헝가리 | AK29: 호주 | AL29: 홍콩
C30: {=INDEX(Sheet2!$I$3:$AP$18, $B8, Sheet1!C$6)} -> 01M | D30: {=_xll.IMDP("IR", D$28&$C30, "BID_Close", $C$4)} -> 4.229 | E30: =IFERROR( ($D30-E49)*100, "") | F30: =IFERROR( ($D30-F49)*100, "") | G30: =IFERROR( ($D30-G49)*100, "") | H30: =IFERROR( ($D30-H49)*100, "") | I30: =IFERROR( ($D30-I49)*100, "") | J30: =IFERROR( ($D30-J49)*100, "") | K30: =IFERROR( ($D30-K49)*100, "") | L30: =IFERROR( ($D30-L49)*100, "") | ... AL30: =IFERROR( ($D30-AL49)*100, "")
C31: {=INDEX(Sheet2!$I$3:$AP$18, $B9, Sheet1!C$6)} -> 02M | D31: {=_xll.IMDP("IR", D$28&$C31, "BID_Close", $C$4)} -> 4.381 | E31: =IFERROR( ($D31-E50)*100, "") | F31: =IFERROR( ($D31-F50)*100, "") | G31: =IFERROR( ($D31-G50)*100, "") | H31: =IFERROR( ($D31-H50)*100, "") | I31: =IFERROR( ($D31-I50)*100, "") | J31: =IFERROR( ($D31-J50)*100, "") | K31: =IFERROR( ($D31-K50)*100, "") | L31: =IFERROR( ($D31-L50)*100, "") | ... AL31: =IFERROR( ($D31-AL50)*100, "")
C32: {=INDEX(Sheet2!$I$3:$AP$18, $B10, Sheet1!C$6)} -> 03M | D32: {=_xll.IMDP("IR", D$28&$C32, "BID_Close", $C$4)} -> 4.354 | E32: =IFERROR( ($D32-E51)*100, "") | F32: =IFERROR( ($D32-F51)*100, "") | G32: =IFERROR( ($D32-G51)*100, "") | H32: =IFERROR( ($D32-H51)*100, "") | I32: =IFERROR( ($D32-I51)*100, "") | J32: =IFERROR( ($D32-J51)*100, "") | K32: =IFERROR( ($D32-K51)*100, "") | L32: =IFERROR( ($D32-L51)*100, "") | ... AL32: =IFERROR( ($D32-AL51)*100, "")
C33: {=INDEX(Sheet2!$I$3:$AP$18, $B11, Sheet1!C$6)} -> 04M | D33: {=_xll.IMDP("IR", D$28&$C33, "BID_Close", $C$4)} -> 4.339 | E33: =IFERROR( ($D33-E52)*100, "") | F33: =IFERROR( ($D33-F52)*100, "") | G33: =IFERROR( ($D33-G52)*100, "") | H33: =IFERROR( ($D33-H52)*100, "") | I33: =IFERROR( ($D33-I52)*100, "") | J33: =IFERROR( ($D33-J52)*100, "") | K33: =IFERROR( ($D33-K52)*100, "") | L33: =IFERROR( ($D33-L52)*100, "") | ... AL33: =IFERROR( ($D33-AL52)*100, "")
C34: {=INDEX(Sheet2!$I$3:$AP$18, $B12, Sheet1!C$6)} -> 06M | D34: {=_xll.IMDP("IR", D$28&$C34, "BID_Close", $C$4)} -> 4.302 | E34: =IFERROR( ($D34-E53)*100, "") | F34: =IFERROR( ($D34-F53)*100, "") | G34: =IFERROR( ($D34-G53)*100, "") | H34: =IFERROR( ($D34-H53)*100, "") | I34: =IFERROR( ($D34-I53)*100, "") | J34: =IFERROR( ($D34-J53)*100, "") | K34: =IFERROR( ($D34-K53)*100, "") | L34: =IFERROR( ($D34-L53)*100, "") | ... AL34: =IFERROR( ($D34-AL53)*100, "")
C35: {=INDEX(Sheet2!$I$3:$AP$18, $B13, Sheet1!C$6)} -> 01Y | D35: {=_xll.IMDP("IR", D$28&$C35, "BID_Close", $C$4)} -> 4.08 | E35: =IFERROR( ($D35-E54)*100, "") | F35: =IFERROR( ($D35-F54)*100, "") -> 221.29 | G35: =IFERROR( ($D35-G54)*100, "") | H35: =IFERROR( ($D35-H54)*100, "") | I35: =IFERROR( ($D35-I54)*100, "") | J35: =IFERROR( ($D35-J54)*100, "") | K35: =IFERROR( ($D35-K54)*100, "") -> 225.89 | L35: =IFERROR( ($D35-L54)*100, "") | ... AL35: =IFERROR( ($D35-AL54)*100, "") -> 231
C36: {=INDEX(Sheet2!$I$3:$AP$18, $B14, Sheet1!C$6)} -> 02Y | D36: {=_xll.IMDP("IR", D$28&$C36, "BID_Close", $C$4)} -> 3.886 | E36: =IFERROR( ($D36-E55)*100, "") -> 189.42 | F36: =IFERROR( ($D36-F55)*100, "") -> 199.89 | G36: =IFERROR( ($D36-G55)*100, "") -> 35.73 | H36: =IFERROR( ($D36-H55)*100, "") -> 58.31 | I36: =IFERROR( ($D36-I55)*100, "") -> 266.6 | J36: =IFERROR( ($D36-J55)*100, "") -> 238.39 | K36: =IFERROR( ($D36-K55)*100, "") -> 205.86 | L36: =IFERROR( ($D36-L55)*100, "") | ... AL36: =IFERROR( ($D36-AL55)*100, "") -> 206.6
C37: {=INDEX(Sheet2!$I$3:$AP$18, $B15, Sheet1!C$6)} -> 03Y | D37: {=_xll.IMDP("IR", D$28&$C37, "BID_Close", $C$4)} -> 3.846 | E37: =IFERROR( ($D37-E56)*100, "") | F37: =IFERROR( ($D37-F56)*100, "") -> 182.67 | G37: =IFERROR( ($D37-G56)*100, "") | H37: =IFERROR( ($D37-H56)*100, "") | I37: =IFERROR( ($D37-I56)*100, "") | J37: =IFERROR( ($D37-J56)*100, "") -> 217.97 | K37: =IFERROR( ($D37-K56)*100, "") -> 197.61 | L37: =IFERROR( ($D37-L56)*100, "") -> 70.1 | ... AL37: =IFERROR( ($D37-AL56)*100, "") -> 192.6
C38: {=INDEX(Sheet2!$I$3:$AP$18, $B16, Sheet1!C$6)} -> 05Y | D38: {=_xll.IMDP("IR", D$28&$C38, "BID_Close", $C$4)} -> 3.934 | E38: =IFERROR( ($D38-E57)*100, "") -> 136.42 | F38: =IFERROR( ($D38-F57)*100, "") -> 163.59 | G38: =IFERROR( ($D38-G57)*100, "") -> 28.18 | H38: =IFERROR( ($D38-H57)*100, "") -> 7.11 | I38: =IFERROR( ($D38-I57)*100, "") -> 258.4 | J38: =IFERROR( ($D38-J57)*100, "") -> 197.57 | K38: =IFERROR( ($D38-K57)*100, "") -> 180.79 | L38: =IFERROR( ($D38-L57)*100, "") -> 72.9 | ... AL38: =IFERROR( ($D38-AL57)*100, "") -> 191.4
C39: {=INDEX(Sheet2!$I$3:$AP$18, $B17, Sheet1!C$6)} -> 07Y | D39: {=_xll.IMDP("IR", D$28&$C39, "BID_Close", $C$4)} -> 4.121 | E39: =IFERROR( ($D39-E58)*100, "") | F39: =IFERROR( ($D39-F58)*100, "") -> 159.66 | G39: =IFERROR( ($D39-G58)*100, "") -> 38.52 | H39: =IFERROR( ($D39-H58)*100, "") | I39: =IFERROR( ($D39-I58)*100, "") | J39: =IFERROR( ($D39-J58)*100, "") | K39: =IFERROR( ($D39-K58)*100, "") -> 179.48 | L39: =IFERROR( ($D39-L58)*100, "") -> 72.6 | ... AL39: =IFERROR( ($D39-AL58)*100, "")
C40: {=INDEX(Sheet2!$I$3:$AP$18, $B18, Sheet1!C$6)} -> 10Y | D40: {=_xll.IMDP("IR", D$28&$C40, "BID_Close", $C$4)} -> 4.346 | E40: =IFERROR( ($D40-E59)*100, "") -> 106.16 | F40: =IFERROR( ($D40-F59)*100, "") -> 155.66 | G40: =IFERROR( ($D40-G59)*100, "") -> 55.1 | H40: =IFERROR( ($D40-H59)*100, "") -> -19.79 | I40: =IFERROR( ($D40-I59)*100, "") -> 293.6 | J40: =IFERROR( ($D40-J59)*100, "") -> 183.33 | K40: =IFERROR( ($D40-K59)*100, "") -> 175.1 | L40: =IFERROR( ($D40-L59)*100, "") -> 83.1 | ... AL40: =IFERROR( ($D40-AL59)*100, "")
C41: {=INDEX(Sheet2!$I$3:$AP$18, $B19, Sheet1!C$6)} -> 20Y | D41: {=_xll.IMDP("IR", D$28&$C41, "BID_Close", $C$4)} -> 4.868 | E41: =IFERROR( ($D41-E60)*100, "") -> 110.78 | F41: =IFERROR( ($D41-F60)*100, "") -> 175.2 | G41: =IFERROR( ($D41-G60)*100, "") | H41: =IFERROR( ($D41-H60)*100, "") -> -10.79 | I41: =IFERROR( ($D41-I60)*100, "") -> 328.8 | J41: =IFERROR( ($D41-J60)*100, "") -> 216.29 | K41: =IFERROR( ($D41-K60)*100, "") -> 190.46 | L41: =IFERROR( ($D41-L60)*100, "") -> 107.3 | ... AL41: =IFERROR( ($D41-AL60)*100, "")
... C45: {=INDEX(Sheet2!$I$3:$AP$18, $B23, Sheet1!C$6)} | D45: {=_xll.IMDP("IR", D$28&$C45, "BID_Close", $C$4)} | E45: =IFERROR( ($D45-E64)*100, "") | F45: =IFERROR( ($D45-F64)*100, "") | G45: =IFERROR( ($D45-G64)*100, "") | H45: =IFERROR( ($D45-H64)*100, "") | I45: =IFERROR( ($D45-I64)*100, "") | J45: =IFERROR( ($D45-J64)*100, "") | K45: =IFERROR( ($D45-K64)*100, "") | L45: =IFERROR( ($D45-L64)*100, "") | ... AL45: =IFERROR( ($D45-AL64)*100, "")
E48: GR | F48: NL | G48: NO | H48: NZ | I48: TW | J48: DK | K48: DE | L48: MY | M48: MX | N48: US | O48: BE | P48: BR | Q48: SE | R48: ES | S48: SG | T48: IE | U48: GB | V48: EU | W48: IT | X48: IN | Y48: ID | Z48: JP | AA48: RM | AB48: CA | AC48: CO | AD48: TH | AE48: TR | AF48: PT | AG48: PL | AH48: FR | AI48: PH | AJ48: HU | AK48: AU | AL48: HK
E49: {=_xll.IMDP("IR", E$48&$C30, Sheet2!$G$4, $C$4)} | F49: {=_xll.IMDP("IR", F$48&$C30, Sheet2!$G$4, $C$4)} | G49: {=_xll.IMDP("IR", G$48&$C30, Sheet2!$G$4, $C$4)} | H49: {=_xll.IMDP("IR", H$48&$C30, Sheet2!$G$4, $C$4)} | I49: {=_xll.IMDP("IR", I$48&$C30, Sheet2!$G$4, $C$4)} | J49: {=_xll.IMDP("IR", J$48&$C30, Sheet2!$G$4, $C$4)} | K49: {=_xll.IMDP("IR", K$48&$C30, Sheet2!$G$4, $C$4)} | L49: {=_xll.IMDP("IR", L$48&$C30, Sheet2!$G$4, $C$4)} | ... AL49: {=_xll.IMDP("IR", AL$48&$C30, Sheet2!$G$4, $C$4)}
E50: {=_xll.IMDP("IR", E$48&$C31, Sheet2!$G$4, $C$4)} | F50: {=_xll.IMDP("IR", F$48&$C31, Sheet2!$G$4, $C$4)} | G50: {=_xll.IMDP("IR", G$48&$C31, Sheet2!$G$4, $C$4)} | H50: {=_xll.IMDP("IR", H$48&$C31, Sheet2!$G$4, $C$4)} | I50: {=_xll.IMDP("IR", I$48&$C31, Sheet2!$G$4, $C$4)} | J50: {=_xll.IMDP("IR", J$48&$C31, Sheet2!$G$4, $C$4)} | K50: {=_xll.IMDP("IR", K$48&$C31, Sheet2!$G$4, $C$4)} | L50: {=_xll.IMDP("IR", L$48&$C31, Sheet2!$G$4, $C$4)} | ... AL50: {=_xll.IMDP("IR", AL$48&$C31, Sheet2!$G$4, $C$4)}
E51: {=_xll.IMDP("IR", E$48&$C32, Sheet2!$G$4, $C$4)} | F51: {=_xll.IMDP("IR", F$48&$C32, Sheet2!$G$4, $C$4)} | G51: {=_xll.IMDP("IR", G$48&$C32, Sheet2!$G$4, $C$4)} | H51: {=_xll.IMDP("IR", H$48&$C32, Sheet2!$G$4, $C$4)} | I51: {=_xll.IMDP("IR", I$48&$C32, Sheet2!$G$4, $C$4)} | J51: {=_xll.IMDP("IR", J$48&$C32, Sheet2!$G$4, $C$4)} | K51: {=_xll.IMDP("IR", K$48&$C32, Sheet2!$G$4, $C$4)} | L51: {=_xll.IMDP("IR", L$48&$C32, Sheet2!$G$4, $C$4)} | ... AL51: {=_xll.IMDP("IR", AL$48&$C32, Sheet2!$G$4, $C$4)}
E52: {=_xll.IMDP("IR", E$48&$C33, Sheet2!$G$4, $C$4)} | F52: {=_xll.IMDP("IR", F$48&$C33, Sheet2!$G$4, $C$4)} | G52: {=_xll.IMDP("IR", G$48&$C33, Sheet2!$G$4, $C$4)} | H52: {=_xll.IMDP("IR", H$48&$C33, Sheet2!$G$4, $C$4)} | I52: {=_xll.IMDP("IR", I$48&$C33, Sheet2!$G$4, $C$4)} | J52: {=_xll.IMDP("IR", J$48&$C33, Sheet2!$G$4, $C$4)} | K52: {=_xll.IMDP("IR", K$48&$C33, Sheet2!$G$4, $C$4)} | L52: {=_xll.IMDP("IR", L$48&$C33, Sheet2!$G$4, $C$4)} | ... AL52: {=_xll.IMDP("IR", AL$48&$C33, Sheet2!$G$4, $C$4)}
E53: {=_xll.IMDP("IR", E$48&$C34, Sheet2!$G$4, $C$4)} | F53: {=_xll.IMDP("IR", F$48&$C34, Sheet2!$G$4, $C$4)} | G53: {=_xll.IMDP("IR", G$48&$C34, Sheet2!$G$4, $C$4)} | H53: {=_xll.IMDP("IR", H$48&$C34, Sheet2!$G$4, $C$4)} | I53: {=_xll.IMDP("IR", I$48&$C34, Sheet2!$G$4, $C$4)} | J53: {=_xll.IMDP("IR", J$48&$C34, Sheet2!$G$4, $C$4)} | K53: {=_xll.IMDP("IR", K$48&$C34, Sheet2!$G$4, $C$4)} | L53: {=_xll.IMDP("IR", L$48&$C34, Sheet2!$G$4, $C$4)} | ... AL53: {=_xll.IMDP("IR", AL$48&$C34, Sheet2!$G$4, $C$4)}
E54: {=_xll.IMDP("IR", E$48&$C35, Sheet2!$G$4, $C$4)} | F54: {=_xll.IMDP("IR", F$48&$C35, Sheet2!$G$4, $C$4)} -> 1.8671 | G54: {=_xll.IMDP("IR", G$48&$C35, Sheet2!$G$4, $C$4)} | H54: {=_xll.IMDP("IR", H$48&$C35, Sheet2!$G$4, $C$4)} | I54: {=_xll.IMDP("IR", I$48&$C35, Sheet2!$G$4, $C$4)} | J54: {=_xll.IMDP("IR", J$48&$C35, Sheet2!$G$4, $C$4)} | K54: {=_xll.IMDP("IR", K$48&$C35, Sheet2!$G$4, $C$4)} -> 1.8211 | L54: {=_xll.IMDP("IR", L$48&$C35, Sheet2!$G$4, $C$4)} | ... AL54: {=_xll.IMDP("IR", AL$48&$C35, Sheet2!$G$4, $C$4)} -> 1.77
...

Sheet Sheet2
I2: GR | J2: NL | K2: NO | L2: NZ | M2: TW | N2: DK | O2: DE | P2: MY | Q2: MX | R2: US | S2: BE | T2: BR | U2: SE | V2: ES | W2: SG | X2: IE | Y2: GB | Z2: EU | AA2: IT | AB2: IN | AC2: ID | AD2: JP | AE2: RM | AF2: CA | AG2: CO | AH2: TH | AI2: TR | AJ2: PT | AK2: PL | AL2: FR | AM2: PH | AN2: HU | AO2: AU | AP2: HK
B3: 그리스 | C3: GR | E3: 01M | G3: 1 | I3: 02Y | J3: 01Y | K3: 02Y | L3: 02Y | M3: 02Y | N3: 02Y | O3: 01Y | P3: 03Y | Q3: 01M | R3: 01M | S3: 01Y | T3: 06M | U3: 02Y | V3: 02Y | W3: 02Y | X3: 01Y | Y3: 01Y | Z3: 01Y | AA3: 01Y | AB3: 01Y | AC3: 01M | AD3: 01Y | AE3: 01Y | AF3: 02Y | AG3: 03Y | AH3: 02Y | AI3: 01Y | AJ3: 02Y | AK3: 02Y | AL3: 01Y | AM3: 02Y | AN3: 02Y | AO3: 01Y | AP3: 01Y
B4: 네덜란드 | C4: NL | E4: 02M | G4: =CHOOSE($G$3, "BID_Close", "ASK_Close") -> BID_Close | I4: 05Y | J4: 02Y | K4: 05Y | L4: 05Y | M4: 05Y | N4: 03Y | O4: 02Y | P4: 05Y | Q4: 03M | R4: 02M | S4: 02Y | T4: 01Y | U4: 05Y | V4: 03Y | W4: 05Y | X4: 02Y | Y4: 02Y | Z4: 02Y | AA4: 02Y | AB4: 02Y | AC4: 03M | AD4: 02Y | AE4: 02Y | AF4: 04Y | AG4: 05Y | AH4: 05Y | AI4: 02Y | AJ4: 03Y | AK4: 05Y | AL4: 02Y | AM4: 03Y | AN4: 05Y | AO4: 02Y | AP4: 02Y
B5: 노르웨이 | C5: NO | E5: 03M | I5: 10Y | J5: 03Y | K5: 07Y | L5: 10Y | M5: 10Y | N5: 05Y | O5: 03Y | P5: 07Y | Q5: 06M | R5: 03M | S5: 03Y | T5: 02Y | U5: 07Y | V5: 04Y | W5: 10Y | X5: 03Y | Y5: 03Y | Z5: 03Y | AA5: 03Y | AB5: 05Y | AC5: 06M | AD5: 03Y | AE5: 03Y | AF5: 05Y | AG5: 10Y | AH5: 10Y | AI5: 03Y | AJ5: 04Y | AK5: 10Y | AL5: 03Y | AM5: 04Y | AN5: 10Y | AO5: 03Y | AP5: 03Y
B6: 뉴질랜드 | C6: NZ | E6: 04M | I6: 15Y | J6: 04Y | K6: 10Y | L6: 15Y | M6: 20Y | N6: 10Y | O6: 04Y | P6: 10Y | Q6: 09M | R6: 04M | S6: 04Y | T6: 03Y | U6: 09Y | V6: 05Y | W6: 15Y | X6: 05Y | Y6: 04Y | Z6: 04Y | AA6: 04Y | AB6: 07Y | AC6: 01Y | AD6: 04Y | AE6: 05Y | AF6: 06Y | AG6: 15Y | AH6: 15Y | AI6: 05Y | AJ6: 05Y | AL6: 04Y | AM6: 05Y | AO6: 04Y | AP6: 05Y
B7: 대만 | C7: TW | E7: 06M | I7: 20Y | J7: 05Y | L7: 20Y | M7: 30Y | N7: 20Y | O7: 05Y | P7: 15Y | Q7: 01Y | R7: 06M | S7: 05Y | T7: 05Y | U7: 10Y | V7: 06Y | W7: 20Y | X7: 08Y | Y7: 05Y | Z7: 05Y | AA7: 05Y | AB7: 10Y | AC7: 03Y | AD7: 05Y | AE7: 07Y | AF7: 07Y | AI7: 10Y | AJ7: 06Y | AL7: 05Y | AM7: 07Y | AO7: 05Y | AP7: 07Y
B8: 덴마크 | C8: DK | E8: 09M | J8: 06Y | O8: 06Y | P8: 20Y | Q8: 03Y | R8: 01Y | S8: 06Y | T8: 10Y | U8: 20Y | V8: 07Y | W8: 30Y | X8: 10Y | Y8: 06Y | Z8: 06Y | AA8: 06Y | AB8: 11Y | AC8: 05Y | AD8: 06Y | AE8: 10Y | AF8: 08Y | AJ8: 07Y | AL8: 06Y | AM8: 10Y | AO8: 07Y
B9: 독일 | C9: DE | E9: 01Y | J9: 07Y | O9: 07Y | P9: 30Y | Q9: 05Y | R9: 02Y | S9: 07Y | V9: 08Y | X9: 15Y | Y9: 07Y | Z9: 07Y | AA9: 07Y | AB9: 20Y | AC9: 10Y | AD9: 07Y | AE9: 15Y | AF9: 09Y | AJ9: 09Y | AL9: 07Y | AM9: 20Y | AO9: 09Y
B10: 말레이시아 | C10: MY | E10: 02Y | J10: 08Y | O10: 08Y | Q10: 10Y | R10: 03Y | S10: 08Y | V10: 09Y | Y10: 08Y | Z10: 08Y | AA10: 08Y | AB10: 25Y | AC10: 15Y | AD10: 08Y | AE10: 20Y | AF10: 10Y | AJ10: 10Y | AL10: 08Y | AO10: 10Y
B11: 멕시코 | C11: MX | E11: 03Y | J11: 09Y | O11: 09Y | Q11: 20Y | R11: 05Y | S11: 09Y | V11: 10Y | Y11: 09Y | Z11: 09Y | AA11: 09Y | AC11: 20Y | AD11: 09Y | AE11: 30Y | AF11: 20Y | AJ11: 20Y | AL11: 09Y | AO11: 15Y
B12: 미국 | C12: US | E12: 04Y | J12: 10Y | O12: 10Y | Q12: 30Y | R12: 07Y | S12: 10Y | V12: 20Y | Y12: 10Y | Z12: 10Y | AA12: 10Y | AC12: 25Y | AD12: 10Y | AF12: 30Y | AL12: 10Y | AO12: 20Y
B13: 벨기에 | C13: BE | E13: 05Y | J13: 15Y | O13: 15Y | R13: 10Y | S13: 15Y | V13: 30Y | Y13: 12Y | Z13: 15Y | AA13: 15Y | AC13: 30Y | AD13: 15Y | AL13: 15Y | AO13: 30Y
B14: 브라질 | C14: BR | E14: 06Y | J14: 20Y | O14: 20Y | R14: 20Y | S14: 20Y | Y14: 15Y | Z14: 20Y | AA14: 20Y | AD14: 20Y | AL14: 20Y
B15: 스웨덴 | C15: SE | E15: 07Y | J15: 30Y | O15: 25Y | R15: 30Y | S15: 30Y | Y15: 20Y | Z15: 25Y | AA15: 25Y | AD15: 30Y | AL15: 25Y
B16: 스페인 | C16: ES | E16: 08Y | O16: 30Y | Y16: 25Y | Z16: 30Y | AA16: 30Y | AD16: 40Y | AL16: 30Y
B17: 싱가포르 | C17: SG | E17: 09Y | Y17: 30Y | Z17: 50Y | AL17: 50Y
B18: 아일랜드 | C18: IE | E18: 10Y | Y18: 50Y
B19: 영국 | C19: GB | E19: 11Y
B20: 유럽연합 | C20: EU | E20: 12Y
B21: 이탈리아 | C21: IT | E21: 15Y
B22: 인도 | C22: IN | E22: 20Y
B23: 인도네시아 | C23: ID | E23: 25Y
B24: 일본 | C24: JP | E24: 30Y
B25: 중국 | C25: RM | E25: 40Y
B26: 캐나다 | C26: CA | E26: 50Y
B27: 콜롬비아 | C27: CO
B28: 태국 | C28: TH
B29: 터키 | C29: TR
B30: 포르투갈 | C30: PT
B31: 폴란드 | C31: PL
B32: 프랑스 | C32: FR
B33: 필리핀 | C33: PH
B34: 헝가리 | C34: HU
B35: 호주 | C35: AU
B36: 홍콩 | C36: HK
