Workbook
Name code_list: BOND!$CK$2:$CK$84
Name name_list: BOND!$CJ$2:$CJ$84

Sheet BOND&IRS_SP
P2: 1 | Q2: 2 | R2: 3 | S2: 4 | T2: 5 | U2: 6 | V2: 7 | W2: 8 | X2: 9 | Y2: 10 | Z2: 11 | AA2: 12
E3: BOND&IRS SPREAD
E5: 주요금리 | F5: 한은 기준금리 | G5: =_xll.IMDP(BOND!$CN$3,BOND!$CO$3,BOND!$CP$3) -> 2.75 | H5: 국고1Y | I5: =_xll.IMDP(BOND!$CN$4,BOND!$CO$4,BOND!$CP$4) -> 2.62 | J5: 통안1Y | K5: =_xll.IMDP(BOND!$CN$7,BOND!$CO$7,BOND!$CP$7) -> 2.63 | L5: IRS 1Y | M5: =_xll.IMDP(BOND!$CN$12,BOND!$CO$12,BOND!$CP$12) -> 2.69
F6: CD금리 | G6: =_xll.IMDP(BOND!$CN$10,BOND!$CO$10,BOND!$CP$10) -> 2.85 | H6: 국고2Y | I6: =_xll.IMDP(BOND!$CN$5,BOND!$CO$5,BOND!$CP$5) -> 2.677 | J6: 통안1.5Y | K6: =_xll.IMDP(BOND!$CN$8,BOND!$CO$8,BOND!$CP$8) -> 2.69 | L6: IRS 2Y | M6: =_xll.IMDP(BOND!$CN$13,BOND!$CO$13,BOND!$CP$13) -> 2.625
C7: 2 | F7: CP금리 | G7: =_xll.IMDP(BOND!$CN$11,BOND!$CO$11,BOND!$CP$11) -> 2.98 | H7: 국고3Y | I7: =_xll.IMDP(BOND!$CN$6,BOND!$CO$6,BOND!$CP$6) -> 2.605 | J7: 통안2Y | K7: =_xll.IMDP(BOND!$CN$9,BOND!$CO$9,BOND!$CP$9) -> 2.668 | L7: IRS 3Y | M7: =_xll.IMDP(BOND!$CN$14,BOND!$CO$14,BOND!$CP$14) -> 2.615
E9: Date | F9: =BOND!$B19 -> 45741 | G9: =BOND!$B20 -> 45740 | H9: =BOND!$B21 -> 45737 | I9: =BOND!$B22 -> 45736 | J9: =BOND!$B23 -> 45735 | K9: =BOND!$B24 -> 45734 | L9: =BOND!$B25 -> 45733 | M9: =BOND!$B26 -> 45730 | N9: =BOND!$B27 -> 45729 | O9: =BOND!$B28 -> 45728
B10: IR | C10: ECO
B11: BONDKSDCAL08 | C11: 68 | E11: CD-한은 기준금리
B12: 대표수익률 | C12: 현재가 | E12: =_xll.IMDP($B$10,$B$11,$B$12,"fill=true")-_xll.IMDP($C$10,$C$11,$C$12,"fill=true") -> 0.1
C13: 1 | E13: 국고채권 | F13: =F$9 -> 45741 | G13: =G$9 -> 45740 | H13: =H$9 -> 45737 | I13: =I$9 -> 45736 | J13: =J$9 -> 45735 | K13: =K$9 -> 45734 | L13: =L$9 -> 45733 | M13: =M$9 -> 45730 | ... O13: =O$9 -> 45728 | P13: 20D | S13: 60D | V13: 120D | Y13: 250D
B14: =INDEX(code_list,$C13,1) -> BONDAVG01 | C14: =INDEX(name_list,$C13,1) -> 국고채권 | P14: Ave | Q14: Min | R14: Max | S14: Ave | T14: Min | U14: Max | V14: Ave | W14: Min | X14: Max | Y14: Ave | Z14: Min | AA14: Max
B15: =_xll.IMDH("IR",$B$14,$C15,$O$9,$F$9,10,"Per=일, sort=D, real=true, Bizday=0, Quote=종가,Pos=40,Orient=H,DtFmt=1.TmFmt=1") -> 조회[BONDAVG01] | C15: 6월이하(당일) | E15: 06M | F15: 2.622 | G15: 2.617 | H15: 2.61 | I15: 2.603 | J15: 2.605 | K15: 2.603 | L15: 2.605 | M15: 2.605 | N15: 2.605 | O15: 2.606 | P15: =IF( INDEX(BOND!$B$2:$CH$13, P$2, MATCH($B$14, BOND!$B$16:$CH$16, 0)+MATCH($C15, BOND!$C$18:$N$18,0) )=0, "", INDEX(BOND!$B$2:$CH$13, P$2, MATCH($B$14, BOND!$B$16:$CH$16, 0)+MATCH($C15, BOND!$C$18:$N$18,0)) ) -> 2.62635 | Q15: =IF( INDEX(BOND!$B$2:$CH$13, Q$2, MATCH($B$14, BOND!$B$16:$CH$16, 0)+MATCH($C15, BOND!$C$18:$N$18,0) )=0, "", INDEX(BOND!$B$2:$CH$13, Q$2, MATCH($B$14, BOND!$B$16:$CH$16, 0)+MATCH($C15, BOND!$C$18:$N$18,0)) ) -> 2.603 | R15: =IF( INDEX(BOND!$B$2:$CH$13, R$2, MATCH($B$14, BOND!$B$16:$CH$16, 0)+MATCH($C15, BOND!$C$18:$N$18,0) )=0, "", INDEX(BOND!$B$2:$CH$13, R$2, MATCH($B$14, BOND!$B$16:$CH$16, 0)+MATCH($C15, BOND!$C$18:$N$18,0)) ) -> 2.666 | S15: =IF( INDEX(BOND!$B$2:$CH$13, S$2, MATCH($B$14, BOND!$B$16:$CH$16, 0)+MATCH($C15, BOND!$C$18:$N$18,0) )=0, "", INDEX(BOND!$B$2:$CH$13, S$2, MATCH($B$14, BOND!$B$16:$CH$16, 0)+MATCH($C15, BOND!$C$18:$N$18,0)) ) -> 2.69985 | T15: =IF( INDEX(BOND!$B$2:$CH$13, T$2, MATCH($B$14, BOND!$B$16:$CH$16, 0)+MATCH($C15, BOND!$C$18:$N$18,0) )=0, "", INDEX(BOND!$B$2:$CH$13, T$2, MATCH($B$14, BOND!$B$16:$CH$16, 0)+MATCH($C15, BOND!$C$18:$N$18,0)) ) -> 2.603 | U15: =IF( INDEX(BOND!$B$2:$CH$13, U$2, MATCH($B$14, BOND!$B$16:$CH$16, 0)+MATCH($C15, BOND!$C$18:$N$18,0) )=0, "", INDEX(BOND!$B$2:$CH$13, U$2, MATCH($B$14, BOND!$B$16:$CH$16, 0)+MATCH($C15, BOND!$C$18:$N$18,0)) ) -> 2.795 | V15: =IF( INDEX(BOND!$B$2:$CH$13, V$2, MATCH($B$14, BOND!$B$16:$CH$16, 0)+MATCH($C15, BOND!$C$18:$N$18,0) )=0, "", INDEX(BOND!$B$2:$CH$13, V$2, MATCH($B$14, BOND!$B$16:$CH$16, 0)+MATCH($C15, BOND!$C$18:$N$18,0)) ) -> 2.8096583 | W15: =IF( INDEX(BOND!$B$2:$CH$13, W$2, MATCH($B$14, BOND!$B$16:$CH$16, 0)+MATCH($C15, BOND!$C$18:$N$18,0) )=0, "", INDEX(BOND!$B$2:$CH$13, W$2, MATCH($B$14, BOND!$B$16:$CH$16, 0)+MATCH($C15, BOND!$C$18:$N$18,0)) ) -> 2.603 | ... AA15: =IF( INDEX(BOND!$B$2:$CH$13, AA$2, MATCH($B$14, BOND!$B$16:$CH$16, 0)+MATCH($C15, BOND!$C$18:$N$18,0) )=0, "", INDEX(BOND!$B$2:$CH$13, AA$2, MATCH($B$14, BOND!$B$16:$CH$16, 0)+MATCH($C15, BOND!$C$18:$N$18,0)) ) -> 3.468
E16: 스프레드 | F16: =IF(F15=0,"",(F15-AD16)*IF($C$7=1,-1,1)) -> -0.1505 | G16: =IF(G15=0,"",(G15-AE16)*IF($C$7=1,-1,1)) -> -0.148 | H16: =IF(H15=0,"",(H15-AF16)*IF($C$7=1,-1,1)) -> -0.1525 | I16: =IF(I15=0,"",(I15-AG16)*IF($C$7=1,-1,1)) -> -0.157 | J16: =IF(J15=0,"",(J15-AH16)*IF($C$7=1,-1,1)) -> -0.1625 | K16: =IF(K15=0,"",(K15-AI16)*IF($C$7=1,-1,1)) -> -0.162 | L16: =IF(L15=0,"",(L15-AJ16)*IF($C$7=1,-1,1)) -> -0.16 | M16: =IF(M15=0,"",(M15-AK16)*IF($C$7=1,-1,1)) -> -0.155 | ... O16: =IF(O15=0,"",(O15-AM16)*IF($C$7=1,-1,1)) -> -0.139 | P16: =IF( P15="", "", (P15 - INDEX(IRS!$B$2:$Y$13, P$2, MATCH($E15,IRS!$B$1:$Y$1, 0)) ) * IF($C$7=1,-1,1) ) -> -0.1394 | Q16: =IF( Q15="", "", (Q15 - INDEX(IRS!$B$2:$Y$13, Q$2, MATCH($E15,IRS!$B$1:$Y$1, 0)) ) * IF($C$7=1,-1,1) ) -> -0.142 | R16: =IF( R15="", "", (R15 - INDEX(IRS!$B$2:$Y$13, R$2, MATCH($E15,IRS!$B$1:$Y$1, 0)) ) * IF($C$7=1,-1,1) ) -> -0.134 | S16: =IF( S15="", "", (S15 - INDEX(IRS!$B$2:$Y$13, S$2, MATCH($E15,IRS!$B$1:$Y$1, 0)) ) * IF($C$7=1,-1,1) ) -> -0.178025 | T16: =IF( T15="", "", (T15 - INDEX(IRS!$B$2:$Y$13, T$2, MATCH($E15,IRS!$B$1:$Y$1, 0)) ) * IF($C$7=1,-1,1) ) -> -0.142 | U16: =IF( U15="", "", (U15 - INDEX(IRS!$B$2:$Y$13, U$2, MATCH($E15,IRS!$B$1:$Y$1, 0)) ) * IF($C$7=1,-1,1) ) -> -0.3925 | V16: =IF( V15="", "", (V15 - INDEX(IRS!$B$2:$Y$13, V$2, MATCH($E15,IRS!$B$1:$Y$1, 0)) ) * IF($C$7=1,-1,1) ) -> -0.2549875 | W16: =IF( W15="", "", (W15 - INDEX(IRS!$B$2:$Y$13, W$2, MATCH($E15,IRS!$B$1:$Y$1, 0)) ) * IF($C$7=1,-1,1) ) -> -0.142 | ... AA16: =IF( AA15="", "", (AA15 - INDEX(IRS!$B$2:$Y$13, AA$2, MATCH($E15,IRS!$B$1:$Y$1, 0)) ) * IF($C$7=1,-1,1) ) -> -0.1695 | AC16: =_xll.IMDH("IR",BOND!$CO15,BOND!$CP15,$O$9,$F$9,10,"Per=일, sort=D, real=true, Bizday=0, Quote=종가,Pos=10,Orient=H,DtFmt=1.TmFmt=1") -> 조회[IRSTP1KRW06M] | AD16: 2.7725 | AE16: 2.765 | AF16: 2.7625 | AG16: 2.76 | AH16: 2.7675 | AI16: 2.765 | AJ16: 2.765 | AK16: 2.76 | AL16: 2.7575 | AM16: 2.745
B17: =_xll.IMDH("IR",$B$14,$C17,$O$9,$F$9,10,"Per=일, sort=D, real=true, Bizday=0, Quote=종가,Pos=40,Orient=H,DtFmt=1.TmFmt=1") -> 조회[BONDAVG01] | C17: 9월이하(당일) | E17: 09M | F17: 2.632 | G17: 2.627 | H17: 2.618 | I17: 2.61 | J17: 2.611 | K17: 2.606 | L17: 2.608 | M17: 2.608 | N17: 2.593 | O17: 2.588 | P17: =IF( INDEX(BOND!$B$2:$CH$13, P$2, MATCH($B$14, BOND!$B$16:$CH$16, 0)+MATCH($C17, BOND!$C$18:$N$18,0) )=0, "", INDEX(BOND!$B$2:$CH$13, P$2, MATCH($B$14, BOND!$B$16:$CH$16, 0)+MATCH($C17, BOND!$C$18:$N$18,0)) ) -> 2.61425 | Q17: =IF( INDEX(BOND!$B$2:$CH$13, Q$2, MATCH($B$14, BOND!$B$16:$CH$16, 0)+MATCH($C17, BOND!$C$18:$N$18,0) )=0, "", INDEX(BOND!$B$2:$CH$13, Q$2, MATCH($B$14, BOND!$B$16:$CH$16, 0)+MATCH($C17, BOND!$C$18:$N$18,0)) ) -> 2.588 | R17: =IF( INDEX(BOND!$B$2:$CH$13, R$2, MATCH($B$14, BOND!$B$16:$CH$16, 0)+MATCH($C17, BOND!$C$18:$N$18,0) )=0, "", INDEX(BOND!$B$2:$CH$13, R$2, MATCH($B$14, BOND!$B$16:$CH$16, 0)+MATCH($C17, BOND!$C$18:$N$18,0)) ) -> 2.632 | S17: =IF( INDEX(BOND!$B$2:$CH$13, S$2, MATCH($B$14, BOND!$B$16:$CH$16, 0)+MATCH($C17, BOND!$C$18:$N$18,0) )=0, "", INDEX(BOND!$B$2:$CH$13, S$2, MATCH($B$14, BOND!$B$16:$CH$16, 0)+MATCH($C17, BOND!$C$18:$N$18,0)) ) -> 2.6387833 | T17: =IF( INDEX(BOND!$B$2:$CH$13, T$2, MATCH($B$14, BOND!$B$16:$CH$16, 0)+MATCH($C17, BOND!$C$18:$N$18,0) )=0, "", INDEX(BOND!$B$2:$CH$13, T$2, MATCH($B$14, BOND!$B$16:$CH$16, 0)+MATCH($C17, BOND!$C$18:$N$18,0)) ) -> 2.588 | U17: =IF( INDEX(BOND!$B$2:$CH$13, U$2, MATCH($B$14, BOND!$B$16:$CH$16, 0)+MATCH($C17, BOND!$C$18:$N$18,0) )=0, "", INDEX(BOND!$B$2:$CH$13, U$2, MATCH($B$14, BOND!$B$16:$CH$16, 0)+MATCH($C17, BOND!$C$18:$N$18,0)) ) -> 2.713 | V17: =IF( INDEX(BOND!$B$2:$CH$13, V$2, MATCH($B$14, BOND!$B$16:$CH$16, 0)+MATCH($C17, BOND!$C$18:$N$18,0) )=0, "", INDEX(BOND!$B$2:$CH$13, V$2, MATCH($B$14, BOND!$B$16:$CH$16, 0)+MATCH($C17, BOND!$C$18:$N$18,0)) ) -> 2.7675 | W17: =IF( INDEX(BOND!$B$2:$CH$13, W$2, MATCH($B$14, BOND!$B$16:$CH$16, 0)+MATCH($C17, BOND!$C$18:$N$18,0) )=0, "", INDEX(BOND!$B$2:$CH$13, W$2, MATCH($B$14, BOND!$B$16:$CH$16, 0)+MATCH($C17, BOND!$C$18:$N$18,0)) ) -> 2.588 | ... AA17: =IF( INDEX(BOND!$B$2:$CH$13, AA$2, MATCH($B$14, BOND!$B$16:$CH$16, 0)+MATCH($C17, BOND!$C$18:$N$18,0) )=0, "", INDEX(BOND!$B$2:$CH$13, AA$2, MATCH($B$14, BOND!$B$16:$CH$16, 0)+MATCH($C17, BOND!$C$18:$N$18,0)) ) -> 3.451
E18: 스프레드 | F18: =IF(F17=0,"",(F17-AD18)*IF($C$7=1,-1,1)) -> -0.0805 | G18: =IF(G17=0,"",(G17-AE18)*IF($C$7=1,-1,1)) -> -0.0755 | H18: =IF(H17=0,"",(H17-AF18)*IF($C$7=1,-1,1)) -> -0.082 | I18: =IF(I17=0,"",(I17-AG18)*IF($C$7=1,-1,1)) -> -0.0875 | J18: =IF(J17=0,"",(J17-AH18)*IF($C$7=1,-1,1)) -> -0.094 | K18: =IF(K17=0,"",(K17-AI18)*IF($C$7=1,-1,1)) -> -0.094 | L18: =IF(L17=0,"",(L17-AJ18)*IF($C$7=1,-1,1)) -> -0.092 | M18: =IF(M17=0,"",(M17-AK18)*IF($C$7=1,-1,1)) -> -0.087 | ... O18: =IF(O17=0,"",(O17-AM18)*IF($C$7=1,-1,1)) -> -0.0845 | P18: =IF( P17="", "", (P17 - INDEX(IRS!$B$2:$Y$13, P$2, MATCH($E17,IRS!$B$1:$Y$1, 0)) ) * IF($C$7=1,-1,1) ) -> -0.08275 | Q18: =IF( Q17="", "", (Q17 - INDEX(IRS!$B$2:$Y$13, Q$2, MATCH($E17,IRS!$B$1:$Y$1, 0)) ) * IF($C$7=1,-1,1) ) -> -0.0845 | R18: =IF( R17="", "", (R17 - INDEX(IRS!$B$2:$Y$13, R$2, MATCH($E17,IRS!$B$1:$Y$1, 0)) ) * IF($C$7=1,-1,1) ) -> -0.098 | S18: =IF( S17="", "", (S17 - INDEX(IRS!$B$2:$Y$13, S$2, MATCH($E17,IRS!$B$1:$Y$1, 0)) ) * IF($C$7=1,-1,1) ) -> -0.14163333 | T18: =IF( T17="", "", (T17 - INDEX(IRS!$B$2:$Y$13, T$2, MATCH($E17,IRS!$B$1:$Y$1, 0)) ) * IF($C$7=1,-1,1) ) -> -0.0845 | U18: =IF( U17="", "", (U17 - INDEX(IRS!$B$2:$Y$13, U$2, MATCH($E17,IRS!$B$1:$Y$1, 0)) ) * IF($C$7=1,-1,1) ) -> -0.2945 | V18: =IF( V17="", "", (V17 - INDEX(IRS!$B$2:$Y$13, V$2, MATCH($E17,IRS!$B$1:$Y$1, 0)) ) * IF($C$7=1,-1,1) ) -> -0.18577083 | W18: =IF( W17="", "", (W17 - INDEX(IRS!$B$2:$Y$13, W$2, MATCH($E17,IRS!$B$1:$Y$1, 0)) ) * IF($C$7=1,-1,1) ) -> -0.0845 | ... AA18: =IF( AA17="", "", (AA17 - INDEX(IRS!$B$2:$Y$13, AA$2, MATCH($E17,IRS!$B$1:$Y$1, 0)) ) * IF($C$7=1,-1,1) ) -> -0.159 | AC18: =_xll.IMDH("IR",BOND!$CO16,BOND!$CP16,$O$9,$F$9,10,"Per=일, sort=D, real=true, Bizday=0, Quote=종가,Pos=10,Orient=H,DtFmt=1.TmFmt=1") -> 조회[IRSTP1KRW09M] | AD18: 2.7125 | AE18: 2.7025 | AF18: 2.7 | AG18: 2.6975 | AH18: 2.705 | AI18: 2.7 | AJ18: 2.7 | AK18: 2.695 | AL18: 2.6875 | AM18: 2.6725
B19: =_xll.IMDH("IR",$B$14,$C19,$O$9,$F$9,10,"Per=일, sort=D, real=true, Bizday=0, Quote=종가,Pos=40,Orient=H,DtFmt=1.TmFmt=1") -> 조회[BONDAVG01] | C19: 1년이하(당일) | E19: 01Y | F19: 2.62 | G19: 2.615 | H19: 2.602 | I19: 2.59 | J19: 2.591 | K19: 2.583 | L19: 2.58 | M19: 2.583 | N19: 2.57 | O19: 2.55 | P19: =IF( INDEX(BOND!$B$2:$CH$13, P$2, MATCH($B$14, BOND!$B$16:$CH$16, 0)+MATCH($C19, BOND!$C$18:$N$18,0) )=0, "", INDEX(BOND!$B$2:$CH$13, P$2, MATCH($B$14, BOND!$B$16:$CH$16, 0)+MATCH($C19, BOND!$C$18:$N$18,0)) ) -> 2.59955 | Q19: =IF( INDEX(BOND!$B$2:$CH$13, Q$2, MATCH($B$14, BOND!$B$16:$CH$16, 0)+MATCH($C19, BOND!$C$18:$N$18,0) )=0, "", INDEX(BOND!$B$2:$CH$13, Q$2, MATCH($B$14, BOND!$B$16:$CH$16, 0)+MATCH($C19, BOND!$C$18:$N$18,0)) ) -> 2.55 | R19: =IF( INDEX(BOND!$B$2:$CH$13, R$2, MATCH($B$14, BOND!$B$16:$CH$16, 0)+MATCH($C19, BOND!$C$18:$N$18,0) )=0, "", INDEX(BOND!$B$2:$CH$13, R$2, MATCH($B$14, BOND!$B$16:$CH$16, 0)+MATCH($C19, BOND!$C$18:$N$18,0)) ) -> 2.623 | S19: =IF( INDEX(BOND!$B$2:$CH$13, S$2, MATCH($B$14, BOND!$B$16:$CH$16, 0)+MATCH($C19, BOND!$C$18:$N$18,0) )=0, "", INDEX(BOND!$B$2:$CH$13, S$2, MATCH($B$14, BOND!$B$16:$CH$16, 0)+MATCH($C19, BOND!$C$18:$N$18,0)) ) -> 2.6362667 | T19: =IF( INDEX(BOND!$B$2:$CH$13, T$2, MATCH($B$14, BOND!$B$16:$CH$16, 0)+MATCH($C19, BOND!$C$18:$N$18,0) )=0, "", INDEX(BOND!$B$2:$CH$13, T$2, MATCH($B$14, BOND!$B$16:$CH$16, 0)+MATCH($C19, BOND!$C$18:$N$18,0)) ) -> 2.55 | U19: =IF( INDEX(BOND!$B$2:$CH$13, U$2, MATCH($B$14, BOND!$B$16:$CH$16, 0)+MATCH($C19, BOND!$C$18:$N$18,0) )=0, "", INDEX(BOND!$B$2:$CH$13, U$2, MATCH($B$14, BOND!$B$16:$CH$16, 0)+MATCH($C19, BOND!$C$18:$N$18,0)) ) -> 2.703 | V19: =IF( INDEX(BOND!$B$2:$CH$13, V$2, MATCH($B$14, BOND!$B$16:$CH$16, 0)+MATCH($C19, BOND!$C$18:$N$18,0) )=0, "", INDEX(BOND!$B$2:$CH$13, V$2, MATCH($B$14, BOND!$B$16:$CH$16, 0)+MATCH($C19, BOND!$C$18:$N$18,0)) ) -> 2.7272667 | W19: =IF( INDEX(BOND!$B$2:$CH$13, W$2, MATCH($B$14, BOND!$B$16:$CH$16, 0)+MATCH($C19, BOND!$C$18:$N$18,0) )=0, "", INDEX(BOND!$B$2:$CH$13, W$2, MATCH($B$14, BOND!$B$16:$CH$16, 0)+MATCH($C19, BOND!$C$18:$N$18,0)) ) -> 2.55 | ... AA19: =IF( INDEX(BOND!$B$2:$CH$13, AA$2, MATCH($B$14, BOND!$B$16:$CH$16, 0)+MATCH($C19, BOND!$C$18:$N$18,0) )=0, "", INDEX(BOND!$B$2:$CH$13, AA$2, MATCH($B$14, BOND!$B$16:$CH$16, 0)+MATCH($C19, BOND!$C$18:$N$18,0)) ) -> 3.476
E20: 스프레드 | F20: =IF(F19=0,"",(F19-AD20)*IF($C$7=1,-1,1)) -> -0.06 | G20: =IF(G19=0,"",(G19-AE20)*IF($C$7=1,-1,1)) -> -0.05 | H20: =IF(H19=0,"",(H19-AF20)*IF($C$7=1,-1,1)) -> -0.0605 | I20: =IF(I19=0,"",(I19-AG20)*IF($C$7=1,-1,1)) -> -0.07 | J20: =IF(J19=0,"",(J19-AH20)*IF($C$7=1,-1,1)) -> -0.0765 | K20: =IF(K19=0,"",(K19-AI20)*IF($C$7=1,-1,1)) -> -0.077 | L20: =IF(L19=0,"",(L19-AJ20)*IF($C$7=1,-1,1)) -> -0.08 | M20: =IF(M19=0,"",(M19-AK20)*IF($C$7=1,-1,1)) -> -0.0695 | ... O20: =IF(O19=0,"",(O19-AM20)*IF($C$7=1,-1,1)) -> -0.075 | P20: =IF( P19="", "", (P19 - INDEX(IRS!$B$2:$Y$13, P$2, MATCH($E19,IRS!$B$1:$Y$1, 0)) ) * IF($C$7=1,-1,1) ) -> -0.0532 | Q20: =IF( Q19="", "", (Q19 - INDEX(IRS!$B$2:$Y$13, Q$2, MATCH($E19,IRS!$B$1:$Y$1, 0)) ) * IF($C$7=1,-1,1) ) -> -0.075 | R20: =IF( R19="", "", (R19 - INDEX(IRS!$B$2:$Y$13, R$2, MATCH($E19,IRS!$B$1:$Y$1, 0)) ) * IF($C$7=1,-1,1) ) -> -0.057 | S20: =IF( S19="", "", (S19 - INDEX(IRS!$B$2:$Y$13, S$2, MATCH($E19,IRS!$B$1:$Y$1, 0)) ) * IF($C$7=1,-1,1) ) -> -0.077483333 | T20: =IF( T19="", "", (T19 - INDEX(IRS!$B$2:$Y$13, T$2, MATCH($E19,IRS!$B$1:$Y$1, 0)) ) * IF($C$7=1,-1,1) ) -> -0.075 | U20: =IF( U19="", "", (U19 - INDEX(IRS!$B$2:$Y$13, U$2, MATCH($E19,IRS!$B$1:$Y$1, 0)) ) * IF($C$7=1,-1,1) ) -> -0.1745 | V20: =IF( V19="", "", (V19 - INDEX(IRS!$B$2:$Y$13, V$2, MATCH($E19,IRS!$B$1:$Y$1, 0)) ) * IF($C$7=1,-1,1) ) -> -0.14350417 | W20: =IF( W19="", "", (W19 - INDEX(IRS!$B$2:$Y$13, W$2, MATCH($E19,IRS!$B$1:$Y$1, 0)) ) * IF($C$7=1,-1,1) ) -> -0.075 | ... AA20: =IF( AA19="", "", (AA19 - INDEX(IRS!$B$2:$Y$13, AA$2, MATCH($E19,IRS!$B$1:$Y$1, 0)) ) * IF($C$7=1,-1,1) ) -> -0.144 | AC20: =_xll.IMDH("IR",BOND!$CO17,BOND!$CP17,$O$9,$F$9,10,"Per=일, sort=D, real=true, Bizday=0, Quote=종가,Pos=10,Orient=H,DtFmt=1.TmFmt=1") -> 조회[IRSTP1KRW01Y] | AD20: 2.68 | AE20: 2.665 | AF20: 2.6625 | AG20: 2.66 | AH20: 2.6675 | AI20: 2.66 | AJ20: 2.66 | AK20: 2.6525 | AL20: 2.6425 | AM20: 2.625
B21: =_xll.IMDH("IR",$B$14,$C21,$O$9,$F$9,10,"Per=일, sort=D, real=true, Bizday=0, Quote=종가,Pos=40,Orient=H,DtFmt=1.TmFmt=1") -> 조회[BONDAVG01] | C21: 1.5년이하(당일) | E21: 1.5Y | F21: 2.689 | G21: 2.684 | H21: 2.673 | I21: 2.669 | J21: 2.676 | K21: 2.657 | L21: 2.664 | M21: 2.666 | N21: 2.658 | O21: 2.65 | P21: =IF( INDEX(BOND!$B$2:$CH$13, P$2, MATCH($B$14, BOND!$B$16:$CH$16, 0)+MATCH($C21, BOND!$C$18:$N$18,0) )=0, "", INDEX(BOND!$B$2:$CH$13, P$2, MATCH($B$14, BOND!$B$16:$CH$16, 0)+MATCH($C21, BOND!$C$18:$N$18,0)) ) -> 2.66295 | Q21: =IF( INDEX(BOND!$B$2:$CH$13, Q$2, MATCH($B$14, BOND!$B$16:$CH$16, 0)+MATCH($C21, BOND!$C$18:$N$18,0) )=0, "", INDEX(BOND!$B$2:$CH$13, Q$2, MATCH($B$14, BOND!$B$16:$CH$16, 0)+MATCH($C21, BOND!$C$18:$N$18,0)) ) -> 2.637 | R21: =IF( INDEX(BOND!$B$2:$CH$13, R$2, MATCH($B$14, BOND!$B$16:$CH$16, 0)+MATCH($C21, BOND!$C$18:$N$18,0) )=0, "", INDEX(BOND!$B$2:$CH$13, R$2, MATCH($B$14, BOND!$B$16:$CH$16, 0)+MATCH($C21, BOND!$C$18:$N$18,0)) ) -> 2.694 | S21: =IF( INDEX(BOND!$B$2:$CH$13, S$2, MATCH($B$14, BOND!$B$16:$CH$16, 0)+MATCH($C21, BOND!$C$18:$N$18,0) )=0, "", INDEX(BOND!$B$2:$CH$13, S$2, MATCH($B$14, BOND!$B$16:$CH$16, 0)+MATCH($C21, BOND!$C$18:$N$18,0)) ) -> 2.67285 | T21: =IF( INDEX(BOND!$B$2:$CH$13, T$2, MATCH($B$14, BOND!$B$16:$CH$16, 0)+MATCH($C21, BOND!$C$18:$N$18,0) )=0, "", INDEX(BOND!$B$2:$CH$13, T$2, MATCH($B$14, BOND!$B$16:$CH$16, 0)+MATCH($C21, BOND!$C$18:$N$18,0)) ) -> 2.621 | U21: =IF( INDEX(BOND!$B$2:$CH$13, U$2, MATCH($B$14, BOND!$B$16:$CH$16, 0)+MATCH($C21, BOND!$C$18:$N$18,0) )=0, "", INDEX(BOND!$B$2:$CH$13, U$2, MATCH($B$14, BOND!$B$16:$CH$16, 0)+MATCH($C21, BOND!$C$18:$N$18,0)) ) -> 2.781 | V21: =IF( INDEX(BOND!$B$2:$CH$13, V$2, MATCH($B$14, BOND!$B$16:$CH$16, 0)+MATCH($C21, BOND!$C$18:$N$18,0) )=0, "", INDEX(BOND!$B$2:$CH$13, V$2, MATCH($B$14, BOND!$B$16:$CH$16, 0)+MATCH($C21, BOND!$C$18:$N$18,0)) ) -> 2.7658 | W21: =IF( INDEX(BOND!$B$2:$CH$13, W$2, MATCH($B$14, BOND!$B$16:$CH$16, 0)+MATCH($C21, BOND!$C$18:$N$18,0) )=0, "", INDEX(BOND!$B$2:$CH$13, W$2, MATCH($B$14, BOND!$B$16:$CH$16, 0)+MATCH($C21, BOND!$C$18:$N$18,0)) ) -> 2.621 | ... AA21: =IF( INDEX(BOND!$B$2:$CH$13, AA$2, MATCH($B$14, BOND!$B$16:$CH$16, 0)+MATCH($C21, BOND!$C$18:$N$18,0) )=0, "", INDEX(BOND!$B$2:$CH$13, AA$2, MATCH($B$14, BOND!$B$16:$CH$16, 0)+MATCH($C21, BOND!$C$18:$N$18,0)) ) -> 3.482
E22: 스프레드 | F22: =IF(F21=0,"",(F21-AD22)*IF($C$7=1,-1,1)) -> 0.054 | G22: =IF(G21=0,"",(G21-AE22)*IF($C$7=1,-1,1)) -> 0.0615 | H22: =IF(H21=0,"",(H21-AF22)*IF($C$7=1,-1,1)) -> 0.058 | I22: =IF(I21=0,"",(I21-AG22)*IF($C$7=1,-1,1)) -> 0.059 | J22: =IF(J21=0,"",(J21-AH22)*IF($C$7=1,-1,1)) -> 0.056 | K22: =IF(K21=0,"",(K21-AI22)*IF($C$7=1,-1,1)) -> 0.047 | L22: =IF(L21=0,"",(L21-AJ22)*IF($C$7=1,-1,1)) -> 0.054 | M22: =IF(M21=0,"",(M21-AK22)*IF($C$7=1,-1,1)) -> 0.061 | ... O22: =IF(O21=0,"",(O21-AM22)*IF($C$7=1,-1,1)) -> 0.0775 | P22: =IF( P21="", "", (P21 - INDEX(IRS!$B$2:$Y$13, P$2, MATCH($E21,IRS!$B$1:$Y$1, 0)) ) * IF($C$7=1,-1,1) ) -> 0.0562 | Q22: =IF( Q21="", "", (Q21 - INDEX(IRS!$B$2:$Y$13, Q$2, MATCH($E21,IRS!$B$1:$Y$1, 0)) ) * IF($C$7=1,-1,1) ) -> 0.0645 | R22: =IF( R21="", "", (R21 - INDEX(IRS!$B$2:$Y$13, R$2, MATCH($E21,IRS!$B$1:$Y$1, 0)) ) * IF($C$7=1,-1,1) ) -> 0.059 | S22: =IF( S21="", "", (S21 - INDEX(IRS!$B$2:$Y$13, S$2, MATCH($E21,IRS!$B$1:$Y$1, 0)) ) * IF($C$7=1,-1,1) ) -> 0.01585 | T22: =IF( T21="", "", (T21 - INDEX(IRS!$B$2:$Y$13, T$2, MATCH($E21,IRS!$B$1:$Y$1, 0)) ) * IF($C$7=1,-1,1) ) -> 0.0485 | U22: =IF( U21="", "", (U21 - INDEX(IRS!$B$2:$Y$13, U$2, MATCH($E21,IRS!$B$1:$Y$1, 0)) ) * IF($C$7=1,-1,1) ) -> -0.0215 | V22: =IF( V21="", "", (V21 - INDEX(IRS!$B$2:$Y$13, V$2, MATCH($E21,IRS!$B$1:$Y$1, 0)) ) * IF($C$7=1,-1,1) ) -> -0.024804167 | W22: =IF( W21="", "", (W21 - INDEX(IRS!$B$2:$Y$13, W$2, MATCH($E21,IRS!$B$1:$Y$1, 0)) ) * IF($C$7=1,-1,1) ) -> 0.0485 | ... AA22: =IF( AA21="", "", (AA21 - INDEX(IRS!$B$2:$Y$13, AA$2, MATCH($E21,IRS!$B$1:$Y$1, 0)) ) * IF($C$7=1,-1,1) ) -> -0.118 | AC22: =_xll.IMDH("IR",BOND!$CO18,BOND!$CP18,$O$9,$F$9,10,"Per=일, sort=D, real=true, Bizday=0, Quote=종가,Pos=10,Orient=H,DtFmt=1.TmFmt=1") -> 조회[IRSTP1KRW18M] | AD22: 2.635 | AE22: 2.6225 | AF22: 2.615 | AG22: 2.61 | AH22: 2.62 | AI22: 2.61 | AJ22: 2.61 | AK22: 2.605 | AL22: 2.59 | AM22: 2.5725
B23: =_xll.IMDH("IR",$B$14,$C23,$O$9,$F$9,10,"Per=일, sort=D, real=true, Bizday=0, Quote=종가,Pos=40,Orient=H,DtFmt=1.TmFmt=1") -> 조회[BONDAVG01] | C23: 2년이하(당일) | E23: 02Y | F23: 2.677 | G23: 2.671 | H23: 2.664 | I23: 2.657 | J23: 2.674 | K23: 2.664 | L23: 2.665 | M23: 2.654 | N23: 2.64 | O23: 2.625 | P23: =IF( INDEX(BOND!$B$2:$CH$13, P$2, MATCH($B$14, BOND!$B$16:$CH$16, 0)+MATCH($C23, BOND!$C$18:$N$18,0) )=0, "", INDEX(BOND!$B$2:$CH$13, P$2, MATCH($B$14, BOND!$B$16:$CH$16, 0)+MATCH($C23, BOND!$C$18:$N$18,0)) ) -> 2.66105 | Q23: =IF( INDEX(BOND!$B$2:$CH$13, Q$2, MATCH($B$14, BOND!$B$16:$CH$16, 0)+MATCH($C23, BOND!$C$18:$N$18,0) )=0, "", INDEX(BOND!$B$2:$CH$13, Q$2, MATCH($B$14, BOND!$B$16:$CH$16, 0)+MATCH($C23, BOND!$C$18:$N$18,0)) ) -> 2.625 | R23: =IF( INDEX(BOND!$B$2:$CH$13, R$2, MATCH($B$14, BOND!$B$16:$CH$16, 0)+MATCH($C23, BOND!$C$18:$N$18,0) )=0, "", INDEX(BOND!$B$2:$CH$13, R$2, MATCH($B$14, BOND!$B$16:$CH$16, 0)+MATCH($C23, BOND!$C$18:$N$18,0)) ) -> 2.696 | S23: =IF( INDEX(BOND!$B$2:$CH$13, S$2, MATCH($B$14, BOND!$B$16:$CH$16, 0)+MATCH($C23, BOND!$C$18:$N$18,0) )=0, "", INDEX(BOND!$B$2:$CH$13, S$2, MATCH($B$14, BOND!$B$16:$CH$16, 0)+MATCH($C23, BOND!$C$18:$N$18,0)) ) -> 2.6796667 | T23: =IF( INDEX(BOND!$B$2:$CH$13, T$2, MATCH($B$14, BOND!$B$16:$CH$16, 0)+MATCH($C23, BOND!$C$18:$N$18,0) )=0, "", INDEX(BOND!$B$2:$CH$13, T$2, MATCH($B$14, BOND!$B$16:$CH$16, 0)+MATCH($C23, BOND!$C$18:$N$18,0)) ) -> 2.62 | U23: =IF( INDEX(BOND!$B$2:$CH$13, U$2, MATCH($B$14, BOND!$B$16:$CH$16, 0)+MATCH($C23, BOND!$C$18:$N$18,0) )=0, "", INDEX(BOND!$B$2:$CH$13, U$2, MATCH($B$14, BOND!$B$16:$CH$16, 0)+MATCH($C23, BOND!$C$18:$N$18,0)) ) -> 2.797 | V23: =IF( INDEX(BOND!$B$2:$CH$13, V$2, MATCH($B$14, BOND!$B$16:$CH$16, 0)+MATCH($C23, BOND!$C$18:$N$18,0) )=0, "", INDEX(BOND!$B$2:$CH$13, V$2, MATCH($B$14, BOND!$B$16:$CH$16, 0)+MATCH($C23, BOND!$C$18:$N$18,0)) ) -> 2.7616167 | W23: =IF( INDEX(BOND!$B$2:$CH$13, W$2, MATCH($B$14, BOND!$B$16:$CH$16, 0)+MATCH($C23, BOND!$C$18:$N$18,0) )=0, "", INDEX(BOND!$B$2:$CH$13, W$2, MATCH($B$14, BOND!$B$16:$CH$16, 0)+MATCH($C23, BOND!$C$18:$N$18,0)) ) -> 2.62 | ... AA23: =IF( INDEX(BOND!$B$2:$CH$13, AA$2, MATCH($B$14, BOND!$B$16:$CH$16, 0)+MATCH($C23, BOND!$C$18:$N$18,0) )=0, "", INDEX(BOND!$B$2:$CH$13, AA$2, MATCH($B$14, BOND!$B$16:$CH$16, 0)+MATCH($C23, BOND!$C$18:$N$18,0)) ) -> 3.525
E24: 스프레드 | F24: =IF(F23=0,"",(F23-AD24)*IF($C$7=1,-1,1)) -> 0.067 | G24: =IF(G23=0,"",(G23-AE24)*IF($C$7=1,-1,1)) -> 0.0735 | H24: =IF(H23=0,"",(H23-AF24)*IF($C$7=1,-1,1)) -> 0.0765 | I24: =IF(I23=0,"",(I23-AG24)*IF($C$7=1,-1,1)) -> 0.0795 | J24: =IF(J23=0,"",(J23-AH24)*IF($C$7=1,-1,1)) -> 0.089 | K24: =IF(K23=0,"",(K23-AI24)*IF($C$7=1,-1,1)) -> 0.094 | L24: =IF(L23=0,"",(L23-AJ24)*IF($C$7=1,-1,1)) -> 0.095 | M24: =IF(M23=0,"",(M23-AK24)*IF($C$7=1,-1,1)) -> 0.0865 | ... O24: =IF(O23=0,"",(O23-AM24)*IF($C$7=1,-1,1)) -> 0.095 | P24: =IF( P23="", "", (P23 - INDEX(IRS!$B$2:$Y$13, P$2, MATCH($E23,IRS!$B$1:$Y$1, 0)) ) * IF($C$7=1,-1,1) ) -> 0.08655 | Q24: =IF( Q23="", "", (Q23 - INDEX(IRS!$B$2:$Y$13, Q$2, MATCH($E23,IRS!$B$1:$Y$1, 0)) ) * IF($C$7=1,-1,1) ) -> 0.095 | R24: =IF( R23="", "", (R23 - INDEX(IRS!$B$2:$Y$13, R$2, MATCH($E23,IRS!$B$1:$Y$1, 0)) ) * IF($C$7=1,-1,1) ) -> 0.086 | S24: =IF( S23="", "", (S23 - INDEX(IRS!$B$2:$Y$13, S$2, MATCH($E23,IRS!$B$1:$Y$1, 0)) ) * IF($C$7=1,-1,1) ) -> 0.053958333 | T24: =IF( T23="", "", (T23 - INDEX(IRS!$B$2:$Y$13, T$2, MATCH($E23,IRS!$B$1:$Y$1, 0)) ) * IF($C$7=1,-1,1) ) -> 0.09 | U24: =IF( U23="", "", (U23 - INDEX(IRS!$B$2:$Y$13, U$2, MATCH($E23,IRS!$B$1:$Y$1, 0)) ) * IF($C$7=1,-1,1) ) -> 0.022 | V24: =IF( V23="", "", (V23 - INDEX(IRS!$B$2:$Y$13, V$2, MATCH($E23,IRS!$B$1:$Y$1, 0)) ) * IF($C$7=1,-1,1) ) -> 0.012929167 | W24: =IF( W23="", "", (W23 - INDEX(IRS!$B$2:$Y$13, W$2, MATCH($E23,IRS!$B$1:$Y$1, 0)) ) * IF($C$7=1,-1,1) ) -> 0.09 | ... AA24: =IF( AA23="", "", (AA23 - INDEX(IRS!$B$2:$Y$13, AA$2, MATCH($E23,IRS!$B$1:$Y$1, 0)) ) * IF($C$7=1,-1,1) ) -> -0.055 | AC24: =_xll.IMDH("IR",BOND!$CO19,BOND!$CP19,$O$9,$F$9,10,"Per=일, sort=D, real=true, Bizday=0, Quote=종가,Pos=10,Orient=H,DtFmt=1.TmFmt=1") -> 조회[IRSTP1KRW02Y] | AD24: 2.61 | AE24: 2.5975 | AF24: 2.5875 | AG24: 2.5775 | AH24: 2.585 | AI24: 2.57 | AJ24: 2.57 | AK24: 2.5675 | AL24: 2.5475 | AM24: 2.53
B25: =_xll.IMDH("IR",$B$14,$C25,$O$9,$F$9,10,"Per=일, sort=D, real=true, Bizday=0, Quote=종가,Pos=40,Orient=H,DtFmt=1.TmFmt=1") -> 조회[BONDAVG01] | C25: 3년이하(당일) | E25: 03Y | F25: 2.605 | G25: 2.597 | H25: 2.59 | I25: 2.597 | J25: 2.616 | K25: 2.6 | L25: 2.597 | M25: 2.587 | N25: 2.567 | O25: 2.545 | P25: =IF( INDEX(BOND!$B$2:$CH$13, P$2, MATCH($B$14, BOND!$B$16:$CH$16, 0)+MATCH($C25, BOND!$C$18:$N$18,0) )=0, "", INDEX(BOND!$B$2:$CH$13, P$2, MATCH($B$14, BOND!$B$16:$CH$16, 0)+MATCH($C25, BOND!$C$18:$N$18,0)) ) -> 2.58345 | Q25: =IF( INDEX(BOND!$B$2:$CH$13, Q$2, MATCH($B$14, BOND!$B$16:$CH$16, 0)+MATCH($C25, BOND!$C$18:$N$18,0) )=0, "", INDEX(BOND!$B$2:$CH$13, Q$2, MATCH($B$14, BOND!$B$16:$CH$16, 0)+MATCH($C25, BOND!$C$18:$N$18,0)) ) -> 2.542 | R25: =IF( INDEX(BOND!$B$2:$CH$13, R$2, MATCH($B$14, BOND!$B$16:$CH$16, 0)+MATCH($C25, BOND!$C$18:$N$18,0) )=0, "", INDEX(BOND!$B$2:$CH$13, R$2, MATCH($B$14, BOND!$B$16:$CH$16, 0)+MATCH($C25, BOND!$C$18:$N$18,0)) ) -> 2.616 | S25: =IF( INDEX(BOND!$B$2:$CH$13, S$2, MATCH($B$14, BOND!$B$16:$CH$16, 0)+MATCH($C25, BOND!$C$18:$N$18,0) )=0, "", INDEX(BOND!$B$2:$CH$13, S$2, MATCH($B$14, BOND!$B$16:$CH$16, 0)+MATCH($C25, BOND!$C$18:$N$18,0)) ) -> 2.5910833 | T25: =IF( INDEX(BOND!$B$2:$CH$13, T$2, MATCH($B$14, BOND!$B$16:$CH$16, 0)+MATCH($C25, BOND!$C$18:$N$18,0) )=0, "", INDEX(BOND!$B$2:$CH$13, T$2, MATCH($B$14, BOND!$B$16:$CH$16, 0)+MATCH($C25, BOND!$C$18:$N$18,0)) ) -> 2.47 | U25: =IF( INDEX(BOND!$B$2:$CH$13, U$2, MATCH($B$14, BOND!$B$16:$CH$16, 0)+MATCH($C25, BOND!$C$18:$N$18,0) )=0, "", INDEX(BOND!$B$2:$CH$13, U$2, MATCH($B$14, BOND!$B$16:$CH$16, 0)+MATCH($C25, BOND!$C$18:$N$18,0)) ) -> 2.68 | V25: =IF( INDEX(BOND!$B$2:$CH$13, V$2, MATCH($B$14, BOND!$B$16:$CH$16, 0)+MATCH($C25, BOND!$C$18:$N$18,0) )=0, "", INDEX(BOND!$B$2:$CH$13, V$2, MATCH($B$14, BOND!$B$16:$CH$16, 0)+MATCH($C25, BOND!$C$18:$N$18,0)) ) -> 2.6963917 | W25: =IF( INDEX(BOND!$B$2:$CH$13, W$2, MATCH($B$14, BOND!$B$16:$CH$16, 0)+MATCH($C25, BOND!$C$18:$N$18,0) )=0, "", INDEX(BOND!$B$2:$CH$13, W$2, MATCH($B$14, BOND!$B$16:$CH$16, 0)+MATCH($C25, BOND!$C$18:$N$18,0)) ) -> 2.47 | ... AA25: =IF( INDEX(BOND!$B$2:$CH$13, AA$2, MATCH($B$14, BOND!$B$16:$CH$16, 0)+MATCH($C25, BOND!$C$18:$N$18,0) )=0, "", INDEX(BOND!$B$2:$CH$13, AA$2, MATCH($B$14, BOND!$B$16:$CH$16, 0)+MATCH($C25, BOND!$C$18:$N$18,0)) ) -> 3.54
E26: 스프레드 | F26: =IF(F25=0,"",(F25-AD26)*IF($C$7=1,-1,1)) -> 0.01 | G26: =IF(G25=0,"",(G25-AE26)*IF($C$7=1,-1,1)) -> 0.0145 | H26: =IF(H25=0,"",(H25-AF26)*IF($C$7=1,-1,1)) -> 0.0175 | I26: =IF(I25=0,"",(I25-AG26)*IF($C$7=1,-1,1)) -> 0.0345 | J26: =IF(J25=0,"",(J25-AH26)*IF($C$7=1,-1,1)) -> 0.046 | K26: =IF(K25=0,"",(K25-AI26)*IF($C$7=1,-1,1)) -> 0.0475 | L26: =IF(L25=0,"",(L25-AJ26)*IF($C$7=1,-1,1)) -> 0.042 | M26: =IF(M25=0,"",(M25-AK26)*IF($C$7=1,-1,1)) -> 0.0345 | ... O26: =IF(O25=0,"",(O25-AM26)*IF($C$7=1,-1,1)) -> 0.0325 | P26: =IF( P25="", "", (P25 - INDEX(IRS!$B$2:$Y$13, P$2, MATCH($E25,IRS!$B$1:$Y$1, 0)) ) * IF($C$7=1,-1,1) ) -> 0.024325 | Q26: =IF( Q25="", "", (Q25 - INDEX(IRS!$B$2:$Y$13, Q$2, MATCH($E25,IRS!$B$1:$Y$1, 0)) ) * IF($C$7=1,-1,1) ) -> 0.0295 | R26: =IF( R25="", "", (R25 - INDEX(IRS!$B$2:$Y$13, R$2, MATCH($E25,IRS!$B$1:$Y$1, 0)) ) * IF($C$7=1,-1,1) ) -> 0.016 | S26: =IF( S25="", "", (S25 - INDEX(IRS!$B$2:$Y$13, S$2, MATCH($E25,IRS!$B$1:$Y$1, 0)) ) * IF($C$7=1,-1,1) ) -> -0.018708333 | T26: =IF( T25="", "", (T25 - INDEX(IRS!$B$2:$Y$13, T$2, MATCH($E25,IRS!$B$1:$Y$1, 0)) ) * IF($C$7=1,-1,1) ) -> -0.0425 | U26: =IF( U25="", "", (U25 - INDEX(IRS!$B$2:$Y$13, U$2, MATCH($E25,IRS!$B$1:$Y$1, 0)) ) * IF($C$7=1,-1,1) ) -> -0.065 | V26: =IF( V25="", "", (V25 - INDEX(IRS!$B$2:$Y$13, V$2, MATCH($E25,IRS!$B$1:$Y$1, 0)) ) * IF($C$7=1,-1,1) ) -> -0.019545833 | W26: =IF( W25="", "", (W25 - INDEX(IRS!$B$2:$Y$13, W$2, MATCH($E25,IRS!$B$1:$Y$1, 0)) ) * IF($C$7=1,-1,1) ) -> -0.0425 | ... AA26: =IF( AA25="", "", (AA25 - INDEX(IRS!$B$2:$Y$13, AA$2, MATCH($E25,IRS!$B$1:$Y$1, 0)) ) * IF($C$7=1,-1,1) ) -> -0.02 | AC26: =_xll.IMDH("IR",BOND!$CO20,BOND!$CP20,$O$9,$F$9,10,"Per=일, sort=D, real=true, Bizday=0, Quote=종가,Pos=10,Orient=H,DtFmt=1.TmFmt=1") -> 조회[IRSTP1KRW03Y] | AD26: 2.595 | AE26: 2.5825 | AF26: 2.5725 | AG26: 2.5625 | AH26: 2.57 | AI26: 2.5525 | AJ26: 2.555 | AK26: 2.5525 | AL26: 2.5325 | AM26: 2.5125
B27: =_xll.IMDH("IR",$B$14,$C27,$O$9,$F$9,10,"Per=일, sort=D, real=true, Bizday=0, Quote=종가,Pos=40,Orient=H,DtFmt=1.TmFmt=1") -> 조회[BONDAVG01] | C27: 4년이하(당일) | E27: 04Y | F27: 2.733 | G27: 2.715 | H27: 2.705 | I27: 2.705 | J27: 2.719 | K27: 2.71 | L27: 2.709 | M27: 2.699 | N27: 2.683 | O27: 2.667 | P27: =IF( INDEX(BOND!$B$2:$CH$13, P$2, MATCH($B$14, BOND!$B$16:$CH$16, 0)+MATCH($C27, BOND!$C$18:$N$18,0) )=0, "", INDEX(BOND!$B$2:$CH$13, P$2, MATCH($B$14, BOND!$B$16:$CH$16, 0)+MATCH($C27, BOND!$C$18:$N$18,0)) ) -> 2.6926 | Q27: =IF( INDEX(BOND!$B$2:$CH$13, Q$2, MATCH($B$14, BOND!$B$16:$CH$16, 0)+MATCH($C27, BOND!$C$18:$N$18,0) )=0, "", INDEX(BOND!$B$2:$CH$13, Q$2, MATCH($B$14, BOND!$B$16:$CH$16, 0)+MATCH($C27, BOND!$C$18:$N$18,0)) ) -> 2.64 | R27: =IF( INDEX(BOND!$B$2:$CH$13, R$2, MATCH($B$14, BOND!$B$16:$CH$16, 0)+MATCH($C27, BOND!$C$18:$N$18,0) )=0, "", INDEX(BOND!$B$2:$CH$13, R$2, MATCH($B$14, BOND!$B$16:$CH$16, 0)+MATCH($C27, BOND!$C$18:$N$18,0)) ) -> 2.733 | S27: =IF( INDEX(BOND!$B$2:$CH$13, S$2, MATCH($B$14, BOND!$B$16:$CH$16, 0)+MATCH($C27, BOND!$C$18:$N$18,0) )=0, "", INDEX(BOND!$B$2:$CH$13, S$2, MATCH($B$14, BOND!$B$16:$CH$16, 0)+MATCH($C27, BOND!$C$18:$N$18,0)) ) -> 2.7179 | T27: =IF( INDEX(BOND!$B$2:$CH$13, T$2, MATCH($B$14, BOND!$B$16:$CH$16, 0)+MATCH($C27, BOND!$C$18:$N$18,0) )=0, "", INDEX(BOND!$B$2:$CH$13, T$2, MATCH($B$14, BOND!$B$16:$CH$16, 0)+MATCH($C27, BOND!$C$18:$N$18,0)) ) -> 2.64 | U27: =IF( INDEX(BOND!$B$2:$CH$13, U$2, MATCH($B$14, BOND!$B$16:$CH$16, 0)+MATCH($C27, BOND!$C$18:$N$18,0) )=0, "", INDEX(BOND!$B$2:$CH$13, U$2, MATCH($B$14, BOND!$B$16:$CH$16, 0)+MATCH($C27, BOND!$C$18:$N$18,0)) ) -> 2.865 | V27: =IF( INDEX(BOND!$B$2:$CH$13, V$2, MATCH($B$14, BOND!$B$16:$CH$16, 0)+MATCH($C27, BOND!$C$18:$N$18,0) )=0, "", INDEX(BOND!$B$2:$CH$13, V$2, MATCH($B$14, BOND!$B$16:$CH$16, 0)+MATCH($C27, BOND!$C$18:$N$18,0)) ) -> 2.80655 | W27: =IF( INDEX(BOND!$B$2:$CH$13, W$2, MATCH($B$14, BOND!$B$16:$CH$16, 0)+MATCH($C27, BOND!$C$18:$N$18,0) )=0, "", INDEX(BOND!$B$2:$CH$13, W$2, MATCH($B$14, BOND!$B$16:$CH$16, 0)+MATCH($C27, BOND!$C$18:$N$18,0)) ) -> 2.631 | ... AA27: =IF( INDEX(BOND!$B$2:$CH$13, AA$2, MATCH($B$14, BOND!$B$16:$CH$16, 0)+MATCH($C27, BOND!$C$18:$N$18,0) )=0, "", INDEX(BOND!$B$2:$CH$13, AA$2, MATCH($B$14, BOND!$B$16:$CH$16, 0)+MATCH($C27, BOND!$C$18:$N$18,0)) ) -> 3.61
E28: 스프레드 | F28: =IF(F27=0,"",(F27-AD28)*IF($C$7=1,-1,1)) -> 0.1305 | G28: =IF(G27=0,"",(G27-AE28)*IF($C$7=1,-1,1)) -> 0.1225 | H28: =IF(H27=0,"",(H27-AF28)*IF($C$7=1,-1,1)) -> 0.12 | I28: =IF(I27=0,"",(I27-AG28)*IF($C$7=1,-1,1)) -> 0.13 | J28: =IF(J27=0,"",(J27-AH28)*IF($C$7=1,-1,1)) -> 0.134 | K28: =IF(K27=0,"",(K27-AI28)*IF($C$7=1,-1,1)) -> 0.1475 | L28: =IF(L27=0,"",(L27-AJ28)*IF($C$7=1,-1,1)) -> 0.139 | M28: =IF(M27=0,"",(M27-AK28)*IF($C$7=1,-1,1)) -> 0.1265 | ... O28: =IF(O27=0,"",(O27-AM28)*IF($C$7=1,-1,1)) -> 0.1395 | P28: =IF( P27="", "", (P27 - INDEX(IRS!$B$2:$Y$13, P$2, MATCH($E27,IRS!$B$1:$Y$1, 0)) ) * IF($C$7=1,-1,1) ) -> 0.120725 | Q28: =IF( Q27="", "", (Q27 - INDEX(IRS!$B$2:$Y$13, Q$2, MATCH($E27,IRS!$B$1:$Y$1, 0)) ) * IF($C$7=1,-1,1) ) -> 0.1125 | R28: =IF( R27="", "", (R27 - INDEX(IRS!$B$2:$Y$13, R$2, MATCH($E27,IRS!$B$1:$Y$1, 0)) ) * IF($C$7=1,-1,1) ) -> 0.118 | S28: =IF( S27="", "", (S27 - INDEX(IRS!$B$2:$Y$13, S$2, MATCH($E27,IRS!$B$1:$Y$1, 0)) ) * IF($C$7=1,-1,1) ) -> 0.092191667 | T28: =IF( T27="", "", (T27 - INDEX(IRS!$B$2:$Y$13, T$2, MATCH($E27,IRS!$B$1:$Y$1, 0)) ) * IF($C$7=1,-1,1) ) -> 0.1125 | U28: =IF( U27="", "", (U27 - INDEX(IRS!$B$2:$Y$13, U$2, MATCH($E27,IRS!$B$1:$Y$1, 0)) ) * IF($C$7=1,-1,1) ) -> 0.11 | V28: =IF( V27="", "", (V27 - INDEX(IRS!$B$2:$Y$13, V$2, MATCH($E27,IRS!$B$1:$Y$1, 0)) ) * IF($C$7=1,-1,1) ) -> 0.087175 | W28: =IF( W27="", "", (W27 - INDEX(IRS!$B$2:$Y$13, W$2, MATCH($E27,IRS!$B$1:$Y$1, 0)) ) * IF($C$7=1,-1,1) ) -> 0.111 | ... AA28: =IF( AA27="", "", (AA27 - INDEX(IRS!$B$2:$Y$13, AA$2, MATCH($E27,IRS!$B$1:$Y$1, 0)) ) * IF($C$7=1,-1,1) ) -> 0.045 | AC28: =_xll.IMDH("IR",BOND!$CO21,BOND!$CP21,$O$9,$F$9,10,"Per=일, sort=D, real=true, Bizday=0, Quote=종가,Pos=10,Orient=H,DtFmt=1.TmFmt=1") -> 조회[IRSTP1KRW04Y] | AD28: 2.6025 | AE28: 2.5925 | AF28: 2.585 | AG28: 2.575 | AH28: 2.585 | AI28: 2.5625 | AJ28: 2.57 | AK28: 2.5725 | AL28: 2.5475 | AM28: 2.5275
B29: =_xll.IMDH("IR",$B$14,$C29,$O$9,$F$9,10,"Per=일, sort=D, real=true, Bizday=0, Quote=종가,Pos=40,Orient=H,DtFmt=1.TmFmt=1") -> 조회[BONDAVG01] | C29: 5년이하(당일) | E29: 05Y | F29: 2.693 | G29: 2.68 | H29: 2.654 | I29: 2.665 | J29: 2.667 | K29: 2.645 | L29: 2.633 | M29: 2.639 | N29: 2.628 | O29: 2.615 | P29: =IF( INDEX(BOND!$B$2:$CH$13, P$2, MATCH($B$14, BOND!$B$16:$CH$16, 0)+MATCH($C29, BOND!$C$18:$N$18,0) )=0, "", INDEX(BOND!$B$2:$CH$13, P$2, MATCH($B$14, BOND!$B$16:$CH$16, 0)+MATCH($C29, BOND!$C$18:$N$18,0)) ) -> 2.6603 | Q29: =IF( INDEX(BOND!$B$2:$CH$13, Q$2, MATCH($B$14, BOND!$B$16:$CH$16, 0)+MATCH($C29, BOND!$C$18:$N$18,0) )=0, "", INDEX(BOND!$B$2:$CH$13, Q$2, MATCH($B$14, BOND!$B$16:$CH$16, 0)+MATCH($C29, BOND!$C$18:$N$18,0)) ) -> 2.615 | R29: =IF( INDEX(BOND!$B$2:$CH$13, R$2, MATCH($B$14, BOND!$B$16:$CH$16, 0)+MATCH($C29, BOND!$C$18:$N$18,0) )=0, "", INDEX(BOND!$B$2:$CH$13, R$2, MATCH($B$14, BOND!$B$16:$CH$16, 0)+MATCH($C29, BOND!$C$18:$N$18,0)) ) -> 2.711 | S29: =IF( INDEX(BOND!$B$2:$CH$13, S$2, MATCH($B$14, BOND!$B$16:$CH$16, 0)+MATCH($C29, BOND!$C$18:$N$18,0) )=0, "", INDEX(BOND!$B$2:$CH$13, S$2, MATCH($B$14, BOND!$B$16:$CH$16, 0)+MATCH($C29, BOND!$C$18:$N$18,0)) ) -> 2.6979833 | T29: =IF( INDEX(BOND!$B$2:$CH$13, T$2, MATCH($B$14, BOND!$B$16:$CH$16, 0)+MATCH($C29, BOND!$C$18:$N$18,0) )=0, "", INDEX(BOND!$B$2:$CH$13, T$2, MATCH($B$14, BOND!$B$16:$CH$16, 0)+MATCH($C29, BOND!$C$18:$N$18,0)) ) -> 2.615 | U29: =IF( INDEX(BOND!$B$2:$CH$13, U$2, MATCH($B$14, BOND!$B$16:$CH$16, 0)+MATCH($C29, BOND!$C$18:$N$18,0) )=0, "", INDEX(BOND!$B$2:$CH$13, U$2, MATCH($B$14, BOND!$B$16:$CH$16, 0)+MATCH($C29, BOND!$C$18:$N$18,0)) ) -> 2.825 | V29: =IF( INDEX(BOND!$B$2:$CH$13, V$2, MATCH($B$14, BOND!$B$16:$CH$16, 0)+MATCH($C29, BOND!$C$18:$N$18,0) )=0, "", INDEX(BOND!$B$2:$CH$13, V$2, MATCH($B$14, BOND!$B$16:$CH$16, 0)+MATCH($C29, BOND!$C$18:$N$18,0)) ) -> 2.7797333 | W29: =IF( INDEX(BOND!$B$2:$CH$13, W$2, MATCH($B$14, BOND!$B$16:$CH$16, 0)+MATCH($C29, BOND!$C$18:$N$18,0) )=0, "", INDEX(BOND!$B$2:$CH$13, W$2, MATCH($B$14, BOND!$B$16:$CH$16, 0)+MATCH($C29, BOND!$C$18:$N$18,0)) ) -> 2.572 | ... AA29: =IF( INDEX(BOND!$B$2:$CH$13, AA$2, MATCH($B$14, BOND!$B$16:$CH$16, 0)+MATCH($C29, BOND!$C$18:$N$18,0) )=0, "", INDEX(BOND!$B$2:$CH$13, AA$2, MATCH($B$14, BOND!$B$16:$CH$16, 0)+MATCH($C29, BOND!$C$18:$N$18,0)) ) -> 3.625
E30: 스프레드 | F30: =IF(F29=0,"",(F29-AD30)*IF($C$7=1,-1,1)) -> 0.0805 | G30: =IF(G29=0,"",(G29-AE30)*IF($C$7=1,-1,1)) -> 0.0775 | H30: =IF(H29=0,"",(H29-AF30)*IF($C$7=1,-1,1)) -> 0.059 | I30: =IF(I29=0,"",(I29-AG30)*IF($C$7=1,-1,1)) -> 0.0825 | J30: =IF(J29=0,"",(J29-AH30)*IF($C$7=1,-1,1)) -> 0.0745 | K30: =IF(K29=0,"",(K29-AI30)*IF($C$7=1,-1,1)) -> 0.0725 | L30: =IF(L29=0,"",(L29-AJ30)*IF($C$7=1,-1,1)) -> 0.0505 | M30: =IF(M29=0,"",(M29-AK30)*IF($C$7=1,-1,1)) -> 0.054 | ... O30: =IF(O29=0,"",(O29-AM30)*IF($C$7=1,-1,1)) -> 0.0775 | P30: =IF( P29="", "", (P29 - INDEX(IRS!$B$2:$Y$13, P$2, MATCH($E29,IRS!$B$1:$Y$1, 0)) ) * IF($C$7=1,-1,1) ) -> 0.080175 | Q30: =IF( Q29="", "", (Q29 - INDEX(IRS!$B$2:$Y$13, Q$2, MATCH($E29,IRS!$B$1:$Y$1, 0)) ) * IF($C$7=1,-1,1) ) -> 0.08 | R30: =IF( R29="", "", (R29 - INDEX(IRS!$B$2:$Y$13, R$2, MATCH($E29,IRS!$B$1:$Y$1, 0)) ) * IF($C$7=1,-1,1) ) -> 0.086 | S30: =IF( S29="", "", (S29 - INDEX(IRS!$B$2:$Y$13, S$2, MATCH($E29,IRS!$B$1:$Y$1, 0)) ) * IF($C$7=1,-1,1) ) -> 0.06365 | T30: =IF( T29="", "", (T29 - INDEX(IRS!$B$2:$Y$13, T$2, MATCH($E29,IRS!$B$1:$Y$1, 0)) ) * IF($C$7=1,-1,1) ) -> 0.08 | U30: =IF( U29="", "", (U29 - INDEX(IRS!$B$2:$Y$13, U$2, MATCH($E29,IRS!$B$1:$Y$1, 0)) ) * IF($C$7=1,-1,1) ) -> 0.065 | V30: =IF( V29="", "", (V29 - INDEX(IRS!$B$2:$Y$13, V$2, MATCH($E29,IRS!$B$1:$Y$1, 0)) ) * IF($C$7=1,-1,1) ) -> 0.058316667 | W30: =IF( W29="", "", (W29 - INDEX(IRS!$B$2:$Y$13, W$2, MATCH($E29,IRS!$B$1:$Y$1, 0)) ) * IF($C$7=1,-1,1) ) -> 0.0645 | ... AA30: =IF( AA29="", "", (AA29 - INDEX(IRS!$B$2:$Y$13, AA$2, MATCH($E29,IRS!$B$1:$Y$1, 0)) ) * IF($C$7=1,-1,1) ) -> 0.0525 | AC30: =_xll.IMDH("IR",BOND!$CO22,BOND!$CP22,$O$9,$F$9,10,"Per=일, sort=D, real=true, Bizday=0, Quote=종가,Pos=10,Orient=H,DtFmt=1.TmFmt=1") -> 조회[IRSTP1KRW05Y] | AD30: 2.6125 | AE30: 2.6025 | AF30: 2.595 | AG30: 2.5825 | AH30: 2.5925 | AI30: 2.5725 | AJ30: 2.5825 | AK30: 2.585 | AL30: 2.5575 | AM30: 2.5375
B31: =_xll.IMDH("IR",$B$14,$C31,$O$9,$F$9,10,"Per=일, sort=D, real=true, Bizday=0, Quote=종가,Pos=40,Orient=H,DtFmt=1.TmFmt=1") -> 조회[BONDAVG01] | C31: 7년이하(당일) | E31: 07Y | F31: 2.84 | G31: 2.831 | H31: 2.825 | I31: 2.821 | J31: 2.83 | K31: 2.816 | L31: 2.816 | M31: 2.822 | N31: 2.795 | O31: 2.781 | P31: =IF( INDEX(BOND!$B$2:$CH$13, P$2, MATCH($B$14, BOND!$B$16:$CH$16, 0)+MATCH($C31, BOND!$C$18:$N$18,0) )=0, "", INDEX(BOND!$B$2:$CH$13, P$2, MATCH($B$14, BOND!$B$16:$CH$16, 0)+MATCH($C31, BOND!$C$18:$N$18,0)) ) -> 2.80725 | Q31: =IF( INDEX(BOND!$B$2:$CH$13, Q$2, MATCH($B$14, BOND!$B$16:$CH$16, 0)+MATCH($C31, BOND!$C$18:$N$18,0) )=0, "", INDEX(BOND!$B$2:$CH$13, Q$2, MATCH($B$14, BOND!$B$16:$CH$16, 0)+MATCH($C31, BOND!$C$18:$N$18,0)) ) -> 2.749 | R31: =IF( INDEX(BOND!$B$2:$CH$13, R$2, MATCH($B$14, BOND!$B$16:$CH$16, 0)+MATCH($C31, BOND!$C$18:$N$18,0) )=0, "", INDEX(BOND!$B$2:$CH$13, R$2, MATCH($B$14, BOND!$B$16:$CH$16, 0)+MATCH($C31, BOND!$C$18:$N$18,0)) ) -> 2.84 | S31: =IF( INDEX(BOND!$B$2:$CH$13, S$2, MATCH($B$14, BOND!$B$16:$CH$16, 0)+MATCH($C31, BOND!$C$18:$N$18,0) )=0, "", INDEX(BOND!$B$2:$CH$13, S$2, MATCH($B$14, BOND!$B$16:$CH$16, 0)+MATCH($C31, BOND!$C$18:$N$18,0)) ) -> 2.8652333 | T31: =IF( INDEX(BOND!$B$2:$CH$13, T$2, MATCH($B$14, BOND!$B$16:$CH$16, 0)+MATCH($C31, BOND!$C$18:$N$18,0) )=0, "", INDEX(BOND!$B$2:$CH$13, T$2, MATCH($B$14, BOND!$B$16:$CH$16, 0)+MATCH($C31, BOND!$C$18:$N$18,0)) ) -> 2.749 | U31: =IF( INDEX(BOND!$B$2:$CH$13, U$2, MATCH($B$14, BOND!$B$16:$CH$16, 0)+MATCH($C31, BOND!$C$18:$N$18,0) )=0, "", INDEX(BOND!$B$2:$CH$13, U$2, MATCH($B$14, BOND!$B$16:$CH$16, 0)+MATCH($C31, BOND!$C$18:$N$18,0)) ) -> 3.027 | V31: =IF( INDEX(BOND!$B$2:$CH$13, V$2, MATCH($B$14, BOND!$B$16:$CH$16, 0)+MATCH($C31, BOND!$C$18:$N$18,0) )=0, "", INDEX(BOND!$B$2:$CH$13, V$2, MATCH($B$14, BOND!$B$16:$CH$16, 0)+MATCH($C31, BOND!$C$18:$N$18,0)) ) -> 2.9274917 | W31: =IF( INDEX(BOND!$B$2:$CH$13, W$2, MATCH($B$14, BOND!$B$16:$CH$16, 0)+MATCH($C31, BOND!$C$18:$N$18,0) )=0, "", INDEX(BOND!$B$2:$CH$13, W$2, MATCH($B$14, BOND!$B$16:$CH$16, 0)+MATCH($C31, BOND!$C$18:$N$18,0)) ) -> 2.703 | ... AA31: =IF( INDEX(BOND!$B$2:$CH$13, AA$2, MATCH($B$14, BOND!$B$16:$CH$16, 0)+MATCH($C31, BOND!$C$18:$N$18,0) )=0, "", INDEX(BOND!$B$2:$CH$13, AA$2, MATCH($B$14, BOND!$B$16:$CH$16, 0)+MATCH($C31, BOND!$C$18:$N$18,0)) ) -> 3.7
E32: 스프레드 | F32: =IF(F31=0,"",(F31-AD32)*IF($C$7=1,-1,1)) -> 0.2025 | G32: =IF(G31=0,"",(G31-AE32)*IF($C$7=1,-1,1)) -> 0.2035 | H32: =IF(H31=0,"",(H31-AF32)*IF($C$7=1,-1,1)) -> 0.205 | I32: =IF(I31=0,"",(I31-AG32)*IF($C$7=1,-1,1)) -> 0.211 | J32: =IF(J31=0,"",(J31-AH32)*IF($C$7=1,-1,1)) -> 0.2075 | K32: =IF(K31=0,"",(K31-AI32)*IF($C$7=1,-1,1)) -> 0.206 | L32: =IF(L31=0,"",(L31-AJ32)*IF($C$7=1,-1,1)) -> 0.196 | M32: =IF(M31=0,"",(M31-AK32)*IF($C$7=1,-1,1)) -> 0.197 | ... O32: =IF(O31=0,"",(O31-AM32)*IF($C$7=1,-1,1)) -> 0.216 | P32: =IF( P31="", "", (P31 - INDEX(IRS!$B$2:$Y$13, P$2, MATCH($E31,IRS!$B$1:$Y$1, 0)) ) * IF($C$7=1,-1,1) ) -> 0.199375 | Q32: =IF( Q31="", "", (Q31 - INDEX(IRS!$B$2:$Y$13, Q$2, MATCH($E31,IRS!$B$1:$Y$1, 0)) ) * IF($C$7=1,-1,1) ) -> 0.1915 | R32: =IF( R31="", "", (R31 - INDEX(IRS!$B$2:$Y$13, R$2, MATCH($E31,IRS!$B$1:$Y$1, 0)) ) * IF($C$7=1,-1,1) ) -> 0.1925 | S32: =IF( S31="", "", (S31 - INDEX(IRS!$B$2:$Y$13, S$2, MATCH($E31,IRS!$B$1:$Y$1, 0)) ) * IF($C$7=1,-1,1) ) -> 0.20365 | T32: =IF( T31="", "", (T31 - INDEX(IRS!$B$2:$Y$13, T$2, MATCH($E31,IRS!$B$1:$Y$1, 0)) ) * IF($C$7=1,-1,1) ) -> 0.1915 | U32: =IF( U31="", "", (U31 - INDEX(IRS!$B$2:$Y$13, U$2, MATCH($E31,IRS!$B$1:$Y$1, 0)) ) * IF($C$7=1,-1,1) ) -> 0.2395 | V32: =IF( V31="", "", (V31 - INDEX(IRS!$B$2:$Y$13, V$2, MATCH($E31,IRS!$B$1:$Y$1, 0)) ) * IF($C$7=1,-1,1) ) -> 0.18730417 | W32: =IF( W31="", "", (W31 - INDEX(IRS!$B$2:$Y$13, W$2, MATCH($E31,IRS!$B$1:$Y$1, 0)) ) * IF($C$7=1,-1,1) ) -> 0.188 | ... AA32: =IF( AA31="", "", (AA31 - INDEX(IRS!$B$2:$Y$13, AA$2, MATCH($E31,IRS!$B$1:$Y$1, 0)) ) * IF($C$7=1,-1,1) ) -> 0.1275 | AC32: =_xll.IMDH("IR",BOND!$CO23,BOND!$CP23,$O$9,$F$9,10,"Per=일, sort=D, real=true, Bizday=0, Quote=종가,Pos=10,Orient=H,DtFmt=1.TmFmt=1") -> 조회[IRSTP1KRW07Y] | AD32: 2.6375 | AE32: 2.6275 | AF32: 2.62 | AG32: 2.61 | AH32: 2.6225 | AI32: 2.61 | AJ32: 2.62 | AK32: 2.625 | AL32: 2.5875 | AM32: 2.565
B33: =_xll.IMDH("IR",$B$14,$C33,$O$9,$F$9,10,"Per=일, sort=D, real=true, Bizday=0, Quote=종가,Pos=40,Orient=H,DtFmt=1.TmFmt=1") -> 조회[BONDAVG01] | C33: 10년이하(당일) | E33: 10Y | F33: 2.813 | G33: 2.815 | H33: 2.805 | I33: 2.795 | J33: 2.8 | K33: 2.792 | L33: 2.805 | M33: 2.815 | N33: 2.777 | O33: 2.76 | P33: =IF( INDEX(BOND!$B$2:$CH$13, P$2, MATCH($B$14, BOND!$B$16:$CH$16, 0)+MATCH($C33, BOND!$C$18:$N$18,0) )=0, "", INDEX(BOND!$B$2:$CH$13, P$2, MATCH($B$14, BOND!$B$16:$CH$16, 0)+MATCH($C33, BOND!$C$18:$N$18,0)) ) -> 2.7794 | Q33: =IF( INDEX(BOND!$B$2:$CH$13, Q$2, MATCH($B$14, BOND!$B$16:$CH$16, 0)+MATCH($C33, BOND!$C$18:$N$18,0) )=0, "", INDEX(BOND!$B$2:$CH$13, Q$2, MATCH($B$14, BOND!$B$16:$CH$16, 0)+MATCH($C33, BOND!$C$18:$N$18,0)) ) -> 2.7 | R33: =IF( INDEX(BOND!$B$2:$CH$13, R$2, MATCH($B$14, BOND!$B$16:$CH$16, 0)+MATCH($C33, BOND!$C$18:$N$18,0) )=0, "", INDEX(BOND!$B$2:$CH$13, R$2, MATCH($B$14, BOND!$B$16:$CH$16, 0)+MATCH($C33, BOND!$C$18:$N$18,0)) ) -> 2.815 | S33: =IF( INDEX(BOND!$B$2:$CH$13, S$2, MATCH($B$14, BOND!$B$16:$CH$16, 0)+MATCH($C33, BOND!$C$18:$N$18,0) )=0, "", INDEX(BOND!$B$2:$CH$13, S$2, MATCH($B$14, BOND!$B$16:$CH$16, 0)+MATCH($C33, BOND!$C$18:$N$18,0)) ) -> 2.8208 | T33: =IF( INDEX(BOND!$B$2:$CH$13, T$2, MATCH($B$14, BOND!$B$16:$CH$16, 0)+MATCH($C33, BOND!$C$18:$N$18,0) )=0, "", INDEX(BOND!$B$2:$CH$13, T$2, MATCH($B$14, BOND!$B$16:$CH$16, 0)+MATCH($C33, BOND!$C$18:$N$18,0)) ) -> 2.7 | U33: =IF( INDEX(BOND!$B$2:$CH$13, U$2, MATCH($B$14, BOND!$B$16:$CH$16, 0)+MATCH($C33, BOND!$C$18:$N$18,0) )=0, "", INDEX(BOND!$B$2:$CH$13, U$2, MATCH($B$14, BOND!$B$16:$CH$16, 0)+MATCH($C33, BOND!$C$18:$N$18,0)) ) -> 2.914 | V33: =IF( INDEX(BOND!$B$2:$CH$13, V$2, MATCH($B$14, BOND!$B$16:$CH$16, 0)+MATCH($C33, BOND!$C$18:$N$18,0) )=0, "", INDEX(BOND!$B$2:$CH$13, V$2, MATCH($B$14, BOND!$B$16:$CH$16, 0)+MATCH($C33, BOND!$C$18:$N$18,0)) ) -> 2.889125 | W33: =IF( INDEX(BOND!$B$2:$CH$13, W$2, MATCH($B$14, BOND!$B$16:$CH$16, 0)+MATCH($C33, BOND!$C$18:$N$18,0) )=0, "", INDEX(BOND!$B$2:$CH$13, W$2, MATCH($B$14, BOND!$B$16:$CH$16, 0)+MATCH($C33, BOND!$C$18:$N$18,0)) ) -> 2.64 | ... AA33: =IF( INDEX(BOND!$B$2:$CH$13, AA$2, MATCH($B$14, BOND!$B$16:$CH$16, 0)+MATCH($C33, BOND!$C$18:$N$18,0) )=0, "", INDEX(BOND!$B$2:$CH$13, AA$2, MATCH($B$14, BOND!$B$16:$CH$16, 0)+MATCH($C33, BOND!$C$18:$N$18,0)) ) -> 3.711
E34: 스프레드 | F34: =IF(F33=0,"",(F33-AD34)*IF($C$7=1,-1,1)) -> 0.1405 | G34: =IF(G33=0,"",(G33-AE34)*IF($C$7=1,-1,1)) -> 0.1525 | H34: =IF(H33=0,"",(H33-AF34)*IF($C$7=1,-1,1)) -> 0.15 | I34: =IF(I33=0,"",(I33-AG34)*IF($C$7=1,-1,1)) -> 0.15 | J34: =IF(J33=0,"",(J33-AH34)*IF($C$7=1,-1,1)) -> 0.1425 | K34: =IF(K33=0,"",(K33-AI34)*IF($C$7=1,-1,1)) -> 0.147 | L34: =IF(L33=0,"",(L33-AJ34)*IF($C$7=1,-1,1)) -> 0.15 | M34: =IF(M33=0,"",(M33-AK34)*IF($C$7=1,-1,1)) -> 0.15 | ... O34: =IF(O33=0,"",(O33-AM34)*IF($C$7=1,-1,1)) -> 0.16 | P34: =IF( P33="", "", (P33 - INDEX(IRS!$B$2:$Y$13, P$2, MATCH($E33,IRS!$B$1:$Y$1, 0)) ) * IF($C$7=1,-1,1) ) -> 0.1374 | Q34: =IF( Q33="", "", (Q33 - INDEX(IRS!$B$2:$Y$13, Q$2, MATCH($E33,IRS!$B$1:$Y$1, 0)) ) * IF($C$7=1,-1,1) ) -> 0.115 | R34: =IF( R33="", "", (R33 - INDEX(IRS!$B$2:$Y$13, R$2, MATCH($E33,IRS!$B$1:$Y$1, 0)) ) * IF($C$7=1,-1,1) ) -> 0.1325 | S34: =IF( S33="", "", (S33 - INDEX(IRS!$B$2:$Y$13, S$2, MATCH($E33,IRS!$B$1:$Y$1, 0)) ) * IF($C$7=1,-1,1) ) -> 0.12321667 | T34: =IF( T33="", "", (T33 - INDEX(IRS!$B$2:$Y$13, T$2, MATCH($E33,IRS!$B$1:$Y$1, 0)) ) * IF($C$7=1,-1,1) ) -> 0.115 | U34: =IF( U33="", "", (U33 - INDEX(IRS!$B$2:$Y$13, U$2, MATCH($E33,IRS!$B$1:$Y$1, 0)) ) * IF($C$7=1,-1,1) ) -> 0.0815 | V34: =IF( V33="", "", (V33 - INDEX(IRS!$B$2:$Y$13, V$2, MATCH($E33,IRS!$B$1:$Y$1, 0)) ) * IF($C$7=1,-1,1) ) -> 0.11820833 | W34: =IF( W33="", "", (W33 - INDEX(IRS!$B$2:$Y$13, W$2, MATCH($E33,IRS!$B$1:$Y$1, 0)) ) * IF($C$7=1,-1,1) ) -> 0.105 | ... AA34: =IF( AA33="", "", (AA33 - INDEX(IRS!$B$2:$Y$13, AA$2, MATCH($E33,IRS!$B$1:$Y$1, 0)) ) * IF($C$7=1,-1,1) ) -> 0.1235 | AC34: =_xll.IMDH("IR",BOND!$CO24,BOND!$CP24,$O$9,$F$9,10,"Per=일, sort=D, real=true, Bizday=0, Quote=종가,Pos=10,Orient=H,DtFmt=1.TmFmt=1") -> 조회[IRSTP1KRW10Y] | AD34: 2.6725 | AE34: 2.6625 | AF34: 2.655 | AG34: 2.645 | AH34: 2.6575 | AI34: 2.645 | AJ34: 2.655 | AK34: 2.665 | AL34: 2.625 | AM34: 2.6
B35: =_xll.IMDH("IR",$B$14,$C35,$O$9,$F$9,10,"Per=일, sort=D, real=true, Bizday=0, Quote=종가,Pos=40,Orient=H,DtFmt=1.TmFmt=1") -> 조회[BONDAVG01] | C35: 20년이하(당일) | E35: 20Y | F35: 2.7 | G35: 2.69 | H35: 2.665 | I35: 2.66 | J35: 2.66 | K35: 2.675 | L35: 2.688 | M35: 2.694 | N35: 2.684 | O35: 2.671 | P35: =IF( INDEX(BOND!$B$2:$CH$13, P$2, MATCH($B$14, BOND!$B$16:$CH$16, 0)+MATCH($C35, BOND!$C$18:$N$18,0) )=0, "", INDEX(BOND!$B$2:$CH$13, P$2, MATCH($B$14, BOND!$B$16:$CH$16, 0)+MATCH($C35, BOND!$C$18:$N$18,0)) ) -> 2.6848 | Q35: =IF( INDEX(BOND!$B$2:$CH$13, Q$2, MATCH($B$14, BOND!$B$16:$CH$16, 0)+MATCH($C35, BOND!$C$18:$N$18,0) )=0, "", INDEX(BOND!$B$2:$CH$13, Q$2, MATCH($B$14, BOND!$B$16:$CH$16, 0)+MATCH($C35, BOND!$C$18:$N$18,0)) ) -> 2.64 | R35: =IF( INDEX(BOND!$B$2:$CH$13, R$2, MATCH($B$14, BOND!$B$16:$CH$16, 0)+MATCH($C35, BOND!$C$18:$N$18,0) )=0, "", INDEX(BOND!$B$2:$CH$13, R$2, MATCH($B$14, BOND!$B$16:$CH$16, 0)+MATCH($C35, BOND!$C$18:$N$18,0)) ) -> 2.744 | S35: =IF( INDEX(BOND!$B$2:$CH$13, S$2, MATCH($B$14, BOND!$B$16:$CH$16, 0)+MATCH($C35, BOND!$C$18:$N$18,0) )=0, "", INDEX(BOND!$B$2:$CH$13, S$2, MATCH($B$14, BOND!$B$16:$CH$16, 0)+MATCH($C35, BOND!$C$18:$N$18,0)) ) -> 2.7412333 | T35: =IF( INDEX(BOND!$B$2:$CH$13, T$2, MATCH($B$14, BOND!$B$16:$CH$16, 0)+MATCH($C35, BOND!$C$18:$N$18,0) )=0, "", INDEX(BOND!$B$2:$CH$13, T$2, MATCH($B$14, BOND!$B$16:$CH$16, 0)+MATCH($C35, BOND!$C$18:$N$18,0)) ) -> 2.64 | U35: =IF( INDEX(BOND!$B$2:$CH$13, U$2, MATCH($B$14, BOND!$B$16:$CH$16, 0)+MATCH($C35, BOND!$C$18:$N$18,0) )=0, "", INDEX(BOND!$B$2:$CH$13, U$2, MATCH($B$14, BOND!$B$16:$CH$16, 0)+MATCH($C35, BOND!$C$18:$N$18,0)) ) -> 2.875 | V35: =IF( INDEX(BOND!$B$2:$CH$13, V$2, MATCH($B$14, BOND!$B$16:$CH$16, 0)+MATCH($C35, BOND!$C$18:$N$18,0) )=0, "", INDEX(BOND!$B$2:$CH$13, V$2, MATCH($B$14, BOND!$B$16:$CH$16, 0)+MATCH($C35, BOND!$C$18:$N$18,0)) ) -> 2.80915 | W35: =IF( INDEX(BOND!$B$2:$CH$13, W$2, MATCH($B$14, BOND!$B$16:$CH$16, 0)+MATCH($C35, BOND!$C$18:$N$18,0) )=0, "", INDEX(BOND!$B$2:$CH$13, W$2, MATCH($B$14, BOND!$B$16:$CH$16, 0)+MATCH($C35, BOND!$C$18:$N$18,0)) ) -> 2.565 | ... AA35: =IF( INDEX(BOND!$B$2:$CH$13, AA$2, MATCH($B$14, BOND!$B$16:$CH$16, 0)+MATCH($C35, BOND!$C$18:$N$18,0) )=0, "", INDEX(BOND!$B$2:$CH$13, AA$2, MATCH($B$14, BOND!$B$16:$CH$16, 0)+MATCH($C35, BOND!$C$18:$N$18,0)) ) -> 3.615
E36: 스프레드 | F36: =IF(F35=0,"",(F35-AD36)*IF($C$7=1,-1,1)) -> 0.1675 | G36: =IF(G35=0,"",(G35-AE36)*IF($C$7=1,-1,1)) -> 0.165 | H36: =IF(H35=0,"",(H35-AF36)*IF($C$7=1,-1,1)) -> 0.1475 | I36: =IF(I35=0,"",(I35-AG36)*IF($C$7=1,-1,1)) -> 0.155 | J36: =IF(J35=0,"",(J35-AH36)*IF($C$7=1,-1,1)) -> 0.1425 | K36: =IF(K35=0,"",(K35-AI36)*IF($C$7=1,-1,1)) -> 0.17 | L36: =IF(L35=0,"",(L35-AJ36)*IF($C$7=1,-1,1)) -> 0.173 | M36: =IF(M35=0,"",(M35-AK36)*IF($C$7=1,-1,1)) -> 0.169 | ... O36: =IF(O35=0,"",(O35-AM36)*IF($C$7=1,-1,1)) -> 0.211 | P36: =IF( P35="", "", (P35 - INDEX(IRS!$B$2:$Y$13, P$2, MATCH($E35,IRS!$B$1:$Y$1, 0)) ) * IF($C$7=1,-1,1) ) -> 0.178925 | Q36: =IF( Q35="", "", (Q35 - INDEX(IRS!$B$2:$Y$13, Q$2, MATCH($E35,IRS!$B$1:$Y$1, 0)) ) * IF($C$7=1,-1,1) ) -> 0.19 | R36: =IF( R35="", "", (R35 - INDEX(IRS!$B$2:$Y$13, R$2, MATCH($E35,IRS!$B$1:$Y$1, 0)) ) * IF($C$7=1,-1,1) ) -> 0.159 | S36: =IF( S35="", "", (S35 - INDEX(IRS!$B$2:$Y$13, S$2, MATCH($E35,IRS!$B$1:$Y$1, 0)) ) * IF($C$7=1,-1,1) ) -> 0.205025 | T36: =IF( T35="", "", (T35 - INDEX(IRS!$B$2:$Y$13, T$2, MATCH($E35,IRS!$B$1:$Y$1, 0)) ) * IF($C$7=1,-1,1) ) -> 0.19 | U36: =IF( U35="", "", (U35 - INDEX(IRS!$B$2:$Y$13, U$2, MATCH($E35,IRS!$B$1:$Y$1, 0)) ) * IF($C$7=1,-1,1) ) -> 0.2425 | V36: =IF( V35="", "", (V35 - INDEX(IRS!$B$2:$Y$13, V$2, MATCH($E35,IRS!$B$1:$Y$1, 0)) ) * IF($C$7=1,-1,1) ) -> 0.19187917 | W36: =IF( W35="", "", (W35 - INDEX(IRS!$B$2:$Y$13, W$2, MATCH($E35,IRS!$B$1:$Y$1, 0)) ) * IF($C$7=1,-1,1) ) -> 0.205 | ... AA36: =IF( AA35="", "", (AA35 - INDEX(IRS!$B$2:$Y$13, AA$2, MATCH($E35,IRS!$B$1:$Y$1, 0)) ) * IF($C$7=1,-1,1) ) -> 0.1375 | AC36: =_xll.IMDH("IR",BOND!$CO25,BOND!$CP25,$O$9,$F$9,10,"Per=일, sort=D, real=true, Bizday=0, Quote=종가,Pos=10,Orient=H,DtFmt=1.TmFmt=1") -> 조회[IRSTP1KRW20Y] | AD36: 2.5325 | AE36: 2.525 | AF36: 2.5175 | AG36: 2.505 | AH36: 2.5175 | AI36: 2.505 | AJ36: 2.515 | AK36: 2.525 | AL36: 2.485 | AM36: 2.46
B37: =_xll.IMDH("IR",$B$14,$C37,$O$9,$F$9,10,"Per=일, sort=D, real=true, Bizday=0, Quote=종가,Pos=40,Orient=H,DtFmt=1.TmFmt=1") -> 조회[BONDAVG01] | C37: 30년이하(당일) | E37: 30Y | F37: 2.58 | G37: 2.567 | H37: 2.547 | I37: 2.547 | J37: 2.557 | K37: 2.575 | L37: 2.59 | M37: 2.59 | N37: 2.58 | O37: 2.565 | P37: =IF( INDEX(BOND!$B$2:$CH$13, P$2, MATCH($B$14, BOND!$B$16:$CH$16, 0)+MATCH($C37, BOND!$C$18:$N$18,0) )=0, "", INDEX(BOND!$B$2:$CH$13, P$2, MATCH($B$14, BOND!$B$16:$CH$16, 0)+MATCH($C37, BOND!$C$18:$N$18,0)) ) -> 2.57865 | Q37: =IF( INDEX(BOND!$B$2:$CH$13, Q$2, MATCH($B$14, BOND!$B$16:$CH$16, 0)+MATCH($C37, BOND!$C$18:$N$18,0) )=0, "", INDEX(BOND!$B$2:$CH$13, Q$2, MATCH($B$14, BOND!$B$16:$CH$16, 0)+MATCH($C37, BOND!$C$18:$N$18,0)) ) -> 2.542 | R37: =IF( INDEX(BOND!$B$2:$CH$13, R$2, MATCH($B$14, BOND!$B$16:$CH$16, 0)+MATCH($C37, BOND!$C$18:$N$18,0) )=0, "", INDEX(BOND!$B$2:$CH$13, R$2, MATCH($B$14, BOND!$B$16:$CH$16, 0)+MATCH($C37, BOND!$C$18:$N$18,0)) ) -> 2.645 | S37: =IF( INDEX(BOND!$B$2:$CH$13, S$2, MATCH($B$14, BOND!$B$16:$CH$16, 0)+MATCH($C37, BOND!$C$18:$N$18,0) )=0, "", INDEX(BOND!$B$2:$CH$13, S$2, MATCH($B$14, BOND!$B$16:$CH$16, 0)+MATCH($C37, BOND!$C$18:$N$18,0)) ) -> 2.6634833 | T37: =IF( INDEX(BOND!$B$2:$CH$13, T$2, MATCH($B$14, BOND!$B$16:$CH$16, 0)+MATCH($C37, BOND!$C$18:$N$18,0) )=0, "", INDEX(BOND!$B$2:$CH$13, T$2, MATCH($B$14, BOND!$B$16:$CH$16, 0)+MATCH($C37, BOND!$C$18:$N$18,0)) ) -> 2.542 | U37: =IF( INDEX(BOND!$B$2:$CH$13, U$2, MATCH($B$14, BOND!$B$16:$CH$16, 0)+MATCH($C37, BOND!$C$18:$N$18,0) )=0, "", INDEX(BOND!$B$2:$CH$13, U$2, MATCH($B$14, BOND!$B$16:$CH$16, 0)+MATCH($C37, BOND!$C$18:$N$18,0)) ) -> 2.81 | V37: =IF( INDEX(BOND!$B$2:$CH$13, V$2, MATCH($B$14, BOND!$B$16:$CH$16, 0)+MATCH($C37, BOND!$C$18:$N$18,0) )=0, "", INDEX(BOND!$B$2:$CH$13, V$2, MATCH($B$14, BOND!$B$16:$CH$16, 0)+MATCH($C37, BOND!$C$18:$N$18,0)) ) -> 2.7388833 | W37: =IF( INDEX(BOND!$B$2:$CH$13, W$2, MATCH($B$14, BOND!$B$16:$CH$16, 0)+MATCH($C37, BOND!$C$18:$N$18,0) )=0, "", INDEX(BOND!$B$2:$CH$13, W$2, MATCH($B$14, BOND!$B$16:$CH$16, 0)+MATCH($C37, BOND!$C$18:$N$18,0)) ) -> 2.477 | ... AA37: =IF( INDEX(BOND!$B$2:$CH$13, AA$2, MATCH($B$14, BOND!$B$16:$CH$16, 0)+MATCH($C37, BOND!$C$18:$N$18,0) )=0, "", INDEX(BOND!$B$2:$CH$13, AA$2, MATCH($B$14, BOND!$B$16:$CH$16, 0)+MATCH($C37, BOND!$C$18:$N$18,0)) ) -> 3.523
E38: 스프레드 | F38: =IF(F37=0,"",(F37-AD38)*IF($C$7=1,-1,1)) -> 0.3275 | G38: =IF(G37=0,"",(G37-AE38)*IF($C$7=1,-1,1)) -> 0.297 | H38: =IF(H37=0,"",(H37-AF38)*IF($C$7=1,-1,1)) -> 0.2845 | I38: =IF(I37=0,"",(I37-AG38)*IF($C$7=1,-1,1)) -> 0.297 | J38: =IF(J37=0,"",(J37-AH38)*IF($C$7=1,-1,1)) -> 0.2945 | K38: =IF(K37=0,"",(K37-AI38)*IF($C$7=1,-1,1)) -> 0.325 | L38: =IF(L37=0,"",(L37-AJ38)*IF($C$7=1,-1,1)) -> 0.33 | M38: =IF(M37=0,"",(M37-AK38)*IF($C$7=1,-1,1)) -> 0.32 | ... O38: =IF(O37=0,"",(O37-AM38)*IF($C$7=1,-1,1)) -> 0.36 | P38: =IF( P37="", "", (P37 - INDEX(IRS!$B$2:$Y$13, P$2, MATCH($E37,IRS!$B$1:$Y$1, 0)) ) * IF($C$7=1,-1,1) ) -> 0.329025 | Q38: =IF( Q37="", "", (Q37 - INDEX(IRS!$B$2:$Y$13, Q$2, MATCH($E37,IRS!$B$1:$Y$1, 0)) ) * IF($C$7=1,-1,1) ) -> 0.347 | R38: =IF( R37="", "", (R37 - INDEX(IRS!$B$2:$Y$13, R$2, MATCH($E37,IRS!$B$1:$Y$1, 0)) ) * IF($C$7=1,-1,1) ) -> 0.315 | S38: =IF( S37="", "", (S37 - INDEX(IRS!$B$2:$Y$13, S$2, MATCH($E37,IRS!$B$1:$Y$1, 0)) ) * IF($C$7=1,-1,1) ) -> 0.39056667 | T38: =IF( T37="", "", (T37 - INDEX(IRS!$B$2:$Y$13, T$2, MATCH($E37,IRS!$B$1:$Y$1, 0)) ) * IF($C$7=1,-1,1) ) -> 0.347 | U38: =IF( U37="", "", (U37 - INDEX(IRS!$B$2:$Y$13, U$2, MATCH($E37,IRS!$B$1:$Y$1, 0)) ) * IF($C$7=1,-1,1) ) -> 0.4425 | V38: =IF( V37="", "", (V37 - INDEX(IRS!$B$2:$Y$13, V$2, MATCH($E37,IRS!$B$1:$Y$1, 0)) ) * IF($C$7=1,-1,1) ) -> 0.39534167 | W38: =IF( W37="", "", (W37 - INDEX(IRS!$B$2:$Y$13, W$2, MATCH($E37,IRS!$B$1:$Y$1, 0)) ) * IF($C$7=1,-1,1) ) -> 0.387 | ... AA38: =IF( AA37="", "", (AA37 - INDEX(IRS!$B$2:$Y$13, AA$2, MATCH($E37,IRS!$B$1:$Y$1, 0)) ) * IF($C$7=1,-1,1) ) -> 0.3055 | AC38: =_xll.IMDH("IR",BOND!$CO26,BOND!$CP26,$O$9,$F$9,10,"Per=일, sort=D, real=true, Bizday=0, Quote=종가,Pos=10,Orient=H,DtFmt=1.TmFmt=1") -> 조회[IRSTP1KRW30Y] | AD38: 2.2525 | AE38: 2.27 | AF38: 2.2625 | AG38: 2.25 | AH38: 2.2625 | AI38: 2.25 | AJ38: 2.26 | AK38: 2.27 | AL38: 2.23 | AM38: 2.205
C39: 15 | E39: BOND | F39: =F$9 -> 45741 | G39: =G$9 -> 45740 | H39: =H$9 -> 45737 | I39: =I$9 -> 45736 | J39: =J$9 -> 45735 | K39: =K$9 -> 45734 | L39: =L$9 -> 45733 | M39: =M$9 -> 45730 | ... O39: =O$9 -> 45728 | P39: =$P$13 -> 20D | S39: =$S$13 -> 60D | V39: =$V$13 -> 120D | Y39: =$Y$13 -> 250D
B40: =INDEX(code_list,$C39,1) -> BONDAVG14 | C40: =INDEX(name_list,$C39,1) -> 통안증권 | P40: Ave | Q40: Min | R40: Max | S40: Ave | T40: Min | U40: Max | V40: Ave | W40: Min | X40: Max | Y40: Ave | Z40: Min | AA40: Max
B41: =_xll.IMDH("IR",$B$40,$C41,$O$9,$F$9,10,"Per=일, sort=D, real=true, Bizday=0, Quote=종가,Pos=40,Orient=H,DtFmt=1.TmFmt=1") -> 조회[BONDAVG14] | C41: 6월이하(당일) | E41: 06M | F41: 2.664 | G41: 2.666 | H41: 2.661 | I41: 2.655 | J41: 2.656 | K41: 2.656 | L41: 2.656 | M41: 2.66 | N41: 2.66 | O41: 2.656 | P41: =IF( INDEX(BOND!$B$2:$CH$13, P$2, MATCH($B$40, BOND!$B$16:$CH$16, 0)+MATCH($C41, BOND!$C$18:$N$18,0) )=0, "", INDEX(BOND!$B$2:$CH$13, P$2, MATCH($B$40, BOND!$B$16:$CH$16, 0)+MATCH($C41, BOND!$C$18:$N$18,0)) ) -> 2.6651 | Q41: =IF( INDEX(BOND!$B$2:$CH$13, Q$2, MATCH($B$40, BOND!$B$16:$CH$16, 0)+MATCH($C41, BOND!$C$18:$N$18,0) )=0, "", INDEX(BOND!$B$2:$CH$13, Q$2, MATCH($B$40, BOND!$B$16:$CH$16, 0)+MATCH($C41, BOND!$C$18:$N$18,0)) ) -> 2.655 | R41: =IF( INDEX(BOND!$B$2:$CH$13, R$2, MATCH($B$40, BOND!$B$16:$CH$16, 0)+MATCH($C41, BOND!$C$18:$N$18,0) )=0, "", INDEX(BOND!$B$2:$CH$13, R$2, MATCH($B$40, BOND!$B$16:$CH$16, 0)+MATCH($C41, BOND!$C$18:$N$18,0)) ) -> 2.681 | S41: =IF( INDEX(BOND!$B$2:$CH$13, S$2, MATCH($B$40, BOND!$B$16:$CH$16, 0)+MATCH($C41, BOND!$C$18:$N$18,0) )=0, "", INDEX(BOND!$B$2:$CH$13, S$2, MATCH($B$40, BOND!$B$16:$CH$16, 0)+MATCH($C41, BOND!$C$18:$N$18,0)) ) -> 2.7153667 | T41: =IF( INDEX(BOND!$B$2:$CH$13, T$2, MATCH($B$40, BOND!$B$16:$CH$16, 0)+MATCH($C41, BOND!$C$18:$N$18,0) )=0, "", INDEX(BOND!$B$2:$CH$13, T$2, MATCH($B$40, BOND!$B$16:$CH$16, 0)+MATCH($C41, BOND!$C$18:$N$18,0)) ) -> 2.655 | U41: =IF( INDEX(BOND!$B$2:$CH$13, U$2, MATCH($B$40, BOND!$B$16:$CH$16, 0)+MATCH($C41, BOND!$C$18:$N$18,0) )=0, "", INDEX(BOND!$B$2:$CH$13, U$2, MATCH($B$40, BOND!$B$16:$CH$16, 0)+MATCH($C41, BOND!$C$18:$N$18,0)) ) -> 2.843 | V41: =IF( INDEX(BOND!$B$2:$CH$13, V$2, MATCH($B$40, BOND!$B$16:$CH$16, 0)+MATCH($C41, BOND!$C$18:$N$18,0) )=0, "", INDEX(BOND!$B$2:$CH$13, V$2, MATCH($B$40, BOND!$B$16:$CH$16, 0)+MATCH($C41, BOND!$C$18:$N$18,0)) ) -> 2.8161083 | W41: =IF( INDEX(BOND!$B$2:$CH$13, W$2, MATCH($B$40, BOND!$B$16:$CH$16, 0)+MATCH($C41, BOND!$C$18:$N$18,0) )=0, "", INDEX(BOND!$B$2:$CH$13, W$2, MATCH($B$40, BOND!$B$16:$CH$16, 0)+MATCH($C41, BOND!$C$18:$N$18,0)) ) -> 2.655 | ... AA41: =IF( INDEX(BOND!$B$2:$CH$13, AA$2, MATCH($B$40, BOND!$B$16:$CH$16, 0)+MATCH($C41, BOND!$C$18:$N$18,0) )=0, "", INDEX(BOND!$B$2:$CH$13, AA$2, MATCH($B$40, BOND!$B$16:$CH$16, 0)+MATCH($C41, BOND!$C$18:$N$18,0)) ) -> 3.448
E42: 스프레드 | F42: =IF(F41=0,"",(F41-AD16)*IF($C$7=1,-1,1)) -> -0.1085 | G42: =IF(G41=0,"",(G41-AE16)*IF($C$7=1,-1,1)) -> -0.099 | H42: =IF(H41=0,"",(H41-AF16)*IF($C$7=1,-1,1)) -> -0.1015 | I42: =IF(I41=0,"",(I41-AG16)*IF($C$7=1,-1,1)) -> -0.105 | J42: =IF(J41=0,"",(J41-AH16)*IF($C$7=1,-1,1)) -> -0.1115 | K42: =IF(K41=0,"",(K41-AI16)*IF($C$7=1,-1,1)) -> -0.109 | L42: =IF(L41=0,"",(L41-AJ16)*IF($C$7=1,-1,1)) -> -0.109 | M42: =IF(M41=0,"",(M41-AK16)*IF($C$7=1,-1,1)) -> -0.1 | ... O42: =IF(O41=0,"",(O41-AM16)*IF($C$7=1,-1,1)) -> -0.089 | P42: =IF( P41="", "", (P41 - INDEX(IRS!$B$2:$Y$13, P$2, MATCH($E41,IRS!$B$1:$Y$1, 0)) ) * IF($C$7=1,-1,1) ) -> -0.10065 | Q42: =IF( Q41="", "", (Q41 - INDEX(IRS!$B$2:$Y$13, Q$2, MATCH($E41,IRS!$B$1:$Y$1, 0)) ) * IF($C$7=1,-1,1) ) -> -0.09 | R42: =IF( R41="", "", (R41 - INDEX(IRS!$B$2:$Y$13, R$2, MATCH($E41,IRS!$B$1:$Y$1, 0)) ) * IF($C$7=1,-1,1) ) -> -0.119 | S42: =IF( S41="", "", (S41 - INDEX(IRS!$B$2:$Y$13, S$2, MATCH($E41,IRS!$B$1:$Y$1, 0)) ) * IF($C$7=1,-1,1) ) -> -0.16250833 | T42: =IF( T41="", "", (T41 - INDEX(IRS!$B$2:$Y$13, T$2, MATCH($E41,IRS!$B$1:$Y$1, 0)) ) * IF($C$7=1,-1,1) ) -> -0.09 | U42: =IF( U41="", "", (U41 - INDEX(IRS!$B$2:$Y$13, U$2, MATCH($E41,IRS!$B$1:$Y$1, 0)) ) * IF($C$7=1,-1,1) ) -> -0.3445 | V42: =IF( V41="", "", (V41 - INDEX(IRS!$B$2:$Y$13, V$2, MATCH($E41,IRS!$B$1:$Y$1, 0)) ) * IF($C$7=1,-1,1) ) -> -0.2485375 | W42: =IF( W41="", "", (W41 - INDEX(IRS!$B$2:$Y$13, W$2, MATCH($E41,IRS!$B$1:$Y$1, 0)) ) * IF($C$7=1,-1,1) ) -> -0.09 | ... AA42: =IF( AA41="", "", (AA41 - INDEX(IRS!$B$2:$Y$13, AA$2, MATCH($E41,IRS!$B$1:$Y$1, 0)) ) * IF($C$7=1,-1,1) ) -> -0.1895
