Workbook

Sheet Sheet1
B2: 채권 종합 (4101)
B4: =TODAY() -> 45721
F5: =data!$AD$3 -> 45714
B6: =$B$4 -> 45721 | C6: 금리 | D6: 구분 | E6: 대비(bp) | I6: =TODAY() -> 45721 | J6: 매도 최우선 | M6: 매수 최우선
B7: 국고 2Y | C7: {=IF( $B$6=TODAY(), IF( data!X4=TRUE, _xll.IMDP("IR", data!$Q4, "수익률"), _xll.IMDP("BND", data!$M4, data!$X4)), _xll.IMDP("IR", data!$O4, data!$S4, $B$6) )} -> 2.674 | D7: =IF( $B$4=TODAY(), IF( data!X4=TRUE, "한화", data!Y4), "민평" ) -> 장외 | E7: =IFERROR( (C7-F7)*100, "") -> 1.9 | F7: =data!AD4 -> 2.655 | I7: 국고 2Y | J7: =IF( data!AM4=0, "", data!AM4) -> 60 | K7: =IF( data!AN4=0, "", data!AN4) -> 2.674 | L7: =IF( data!AO4=0, "", data!AO4) -> 10170 | M7: =IF( data!AP4=0, "", data!AP4) -> 10169.5 | N7: =IF( data!AQ4=0, "", data!AQ4) -> 2.678 | O7: =IF( data!AR4=0, "", data!AR4) -> 50
B8: 국고 3Y | C8: {=IF( $B$6=TODAY(), IF( data!X5=TRUE, _xll.IMDP("IR", data!$Q5, "수익률"), _xll.IMDP("BND", data!$M5, data!$X5)), _xll.IMDP("IR", data!$O5, data!$S5, $B$6) )} -> 2.575 | D8: =IF( $B$4=TODAY(), IF( data!X5=TRUE, "한화", data!Y5), "민평" ) -> 장외 | E8: =IFERROR( (C8-F8)*100, "") -> -2 | F8: =data!AD5 -> 2.595 | I8: 국고 3Y | J8: =IF( data!AM5=0, "", data!AM5) -> 50 | K8: =IF( data!AN5=0, "", data!AN5) -> 2.563 | L8: =IF( data!AO5=0, "", data!AO5) -> 10150 | M8: =IF( data!AP5=0, "", data!AP5) -> 10149.5 | N8: =IF( data!AQ5=0, "", data!AQ5) -> 2.565 | O8: =IF( data!AR5=0, "", data!AR5) -> 80
B9: 국고 5Y | C9: {=IF( $B$6=TODAY(), IF( data!X6=TRUE, _xll.IMDP("IR", data!$Q6, "수익률"), _xll.IMDP("BND", data!$M6, data!$X6)), _xll.IMDP("IR", data!$O6, data!$S6, $B$6) )} -> 2.692 | D9: =IF( $B$4=TODAY(), IF( data!X6=TRUE, "한화", data!Y6), "민평" ) -> 장외 | E9: =IFERROR( (C9-F9)*100, "") -> 1.2 | F9: =data!AD6 -> 2.68 | I9: 국고 5Y | J9: =IF( data!AM6=0, "", data!AM6) -> 10 | K9: =IF( data!AN6=0, "", data!AN6) -> 2.675 | L9: =IF( data!AO6=0, "", data!AO6) -> 10283.5 | M9: =IF( data!AP6=0, "", data!AP6) -> 10282.5 | N9: =IF( data!AQ6=0, "", data!AQ6) -> 2.678 | O9: =IF( data!AR6=0, "", data!AR6) -> 100
B10: 국고 10Y | C10: {=IF( $B$6=TODAY(), IF( data!X7=TRUE, _xll.IMDP("IR", data!$Q7, "수익률"), _xll.IMDP("BND", data!$M7, data!$X7)), _xll.IMDP("IR", data!$O7, data!$S7, $B$6) )} -> 2.69 | D10: =IF( $B$4=TODAY(), IF( data!X7=TRUE, "한화", data!Y7), "민평" ) -> 장외 | E10: =IFERROR( (C10-F10)*100, "") -> -6.3 | F10: =data!AD7 -> 2.753 | I10: 국고 10Y | J10: =IF( data!AM7=0, "", data!AM7) -> 30 | K10: =IF( data!AN7=0, "", data!AN7) -> 2.772 | L10: =IF( data!AO7=0, "", data!AO7) -> 10264 | M10: =IF( data!AP7=0, "", data!AP7) -> 10262 | N10: =IF( data!AQ7=0, "", data!AQ7) -> 2.774 | O10: =IF( data!AR7=0, "", data!AR7) -> 100
B11: 국고 20Y | C11: {=IF( $B$6=TODAY(), IF( data!X8=TRUE, _xll.IMDP("IR", data!$Q8, "수익률"), _xll.IMDP("BND", data!$M8, data!$X8)), _xll.IMDP("IR", data!$O8, data!$S8, $B$6) )} -> 2.703 | D11: =IF( $B$4=TODAY(), IF( data!X8=TRUE, "한화", data!Y8), "민평" ) -> 장외 | E11: =IFERROR( (C11-F11)*100, "") -> 0.8 | F11: =data!AD8 -> 2.695 | I11: 국고 20Y | J11: =IF( data!AM8=0, "", data!AM8) -> 10 | K11: =IF( data!AN8=0, "", data!AN8) -> 2.703 | L11: =IF( data!AO8=0, "", data!AO8) -> 10399 | M11: =IF( data!AP8=0, "", data!AP8) -> 10391 | N11: =IF( data!AQ8=0, "", data!AQ8) -> 2.708 | O11: =IF( data!AR8=0, "", data!AR8) -> 20
B12: 국고 30Y | C12: {=IF( $B$6=TODAY(), IF( data!X9=TRUE, _xll.IMDP("IR", data!$Q9, "수익률"), _xll.IMDP("BND", data!$M9, data!$X9)), _xll.IMDP("IR", data!$O9, data!$S9, $B$6) )} -> 2.612 | D12: =IF( $B$4=TODAY(), IF( data!X9=TRUE, "한화", data!Y9), "민평" ) -> 장외 | E12: =IFERROR( (C12-F12)*100, "") -> 1.7 | F12: =data!AD9 -> 2.595 | I12: 국고 30Y | J12: =IF( data!AM9=0, "", data!AM9) -> 10 | K12: =IF( data!AN9=0, "", data!AN9) -> 2.605 | L12: =IF( data!AO9=0, "", data!AO9) -> 10430 | M12: =IF( data!AP9=0, "", data!AP9) -> 10428 | N12: =IF( data!AQ9=0, "", data!AQ9) -> 2.606 | O12: =IF( data!AR9=0, "", data!AR9) -> 30
B13: 통안 91D | C13: {=IF( $B$6=TODAY(), _xll.IMDP("IR", data!$Q10, "수익률"), _xll.IMDP("IR", data!$O10, data!$S10, $B$6) )} -> 2.754 | D13: =IF( $B$4=TODAY(), "한화", "민평" ) -> 한화 | E13: =IFERROR( (C13-F13)*100, "") -> -0.4 | F13: =data!AD10 -> 2.758 | I13: 물가 10Y | J13: =IF( data!AM10=0, "", data!AM10) -> 20 | K13: =IF( data!AN10=0, "", data!AN10) -> 0.415 | L13: =IF( data!AO10=0, "", data!AO10) -> 10321 | M13: =IF( data!AP10=0, "", data!AP10) -> 10317 | N13: =IF( data!AQ10=0, "", data!AQ10) -> 0.42 | O13: =IF( data!AR10=0, "", data!AR10) -> 10
B14: 통안 1Y | C14: {=IF( $B$6=TODAY(), _xll.IMDP("IR", data!$Q11, "수익률"),_xll.IMDP("IR", data!$O11, data!$S11, $B$6) )} -> 2.643 | D14: =IF( $B$4=TODAY(), "한화", "민평" ) -> 한화 | E14: =IFERROR( (C14-F14)*100, "") -> 1.7 | F14: =data!AD11 -> 2.626
B15: 통안 2Y | C15: {=IF( $B$6=TODAY(), IF( data!X12=TRUE, _xll.IMDP("IR", data!$Q12, "수익률"), _xll.IMDP("BND", data!$M12, data!$X12)), _xll.IMDP("IR", data!$O12, data!$S12, $B$6) )} -> 2.653 | D15: =IF( $B$4=TODAY(), IF( data!X12=TRUE, "한화", data!Y12), "민평" ) -> 장외 | E15: =IFERROR( (C15-F15)*100, "") -> 1.3 | F15: =data!AD12 -> 2.64
B16: 통안 3Y | C16: {=IF( $B$6=TODAY(), IF( data!X13=TRUE, _xll.IMDP("IR", data!$Q13, "수익률"), _xll.IMDP("BND", data!$M13, data!$X13)), _xll.IMDP("IR", data!$O13, data!$S13, $B$6) )} -> 2.66 | D16: =IF( $B$4=TODAY(), IF( data!X13=TRUE, "한화", data!Y13), "민평" ) -> 장외 | E16: =IFERROR( (C16-F16)*100, "") -> -0.4 | F16: =data!AD13 -> 2.664
B17: 산금 1Y | C17: {=IF( $B$6=TODAY(), _xll.IMDP("IR", data!$Q14, "수익률"), _xll.IMDP("IR", data!$O14, data!$S14, $B$6) )} -> 2.824 | D17: =IF( $B$4=TODAY(), "한화", "민평" ) -> 한화 | E17: =IFERROR( (C17-F17)*100, "") -> 2.2 | F17: =data!AD14 -> 2.802 | I17: 국가별 금융 종합
B18: 회사채 AA- | C18: {=IF( $B$6=TODAY(), _xll.IMDP("IR", data!$Q15, "수익률"), _xll.IMDP("IR", data!$O15, data!$S15, $B$6) )} -> 3.144 | D18: =IF( $B$4=TODAY(), "한화","민평" ) -> 한화 | E18: =IFERROR( (C18-F18)*100, "") -> -3.1 | F18: =data!AD15 -> 3.175 | I18: =$B$4-2 -> 45719 | K18: 지수 | L18: 등락률 | M18: date | N18: 금리 | O18: 대비(bp) | Q18: date | R18: 환율 (MID) | S18: 전일대비 | T18: date
B19: CD 91D | C19: {=IF( $B$6=TODAY(), _xll.IMDP("IR", data!$Q16, "수익률"), _xll.IMDP("IR", data!$N16, data!$N$2, $B$6) )} -> 2.85 | D19: =IF( $B$4=TODAY(), "한화", "최종" ) -> 한화 | E19: =IFERROR( (C19-F19)*100, "") -> 1 | F19: =data!AD16 -> 2.84 | G19: (최종) | K19: {=_xll.IMDP(data!$C48, data!$D48, "현재가", Sheet1!$I$18, "fill=true")} -> 43191.24 | L19: {=_xll.IMDP(data!$C48, data!$D48, "등락률", Sheet1!$I$18, "fill=true")} -> -1.48 | M19: {=_xll.IMDP(data!$C48, data!$D48, "현재가", Sheet1!$I$18, "fill=true, disp=date")} -> 20250303 | N19: {=IF(data!$C48<>"FRN", _xll.IMDP("IR", "BONDAVG01", data!$I$23, Sheet1!$I$18, "fill=true"), _xll.IMDP("IR", data!$E48, "MID_Close", Sheet1!$I$18, "fill=true"))} -> 4.1565 | O19: {=IFERROR( IF(data!$C48<>"FRN", _xll.IMDP("IR", "BONDAVG01", data!$H$24, Sheet1!$I$18, "fill=true"), _xll.IMDP("IR", data!$E48, "MID_Chg", Sheet1!$I$18, "fill=true") )*100, "")} -> -5.3 | Q19: {=IF($N19="", "", IF(data!$C48<>"FRN", _xll.IMDP("IR", "BONDAVG01", data!$I$23, Sheet1!$I$18, "fill=true, disp=date"), _xll.IMDP("IR", data!$E48, "MID_Close", Sheet1!$I$18, "fill=true, disp=date")))} -> 20250303 | R19: {=IF(data!$C48<>"FRN", _xll.IMDP("FX", data!$F48, "중간값", Sheet1!$I$18, "fill=true"), _xll.IMDP("FX", data!$F48, "NY_MID_Close", Sheet1!$I$18, "fill=true"))} -> 106.606 | S19: {=IF(data!$C48<>"FRN", $R19-_xll.IMDP("FX", data!$F48, "중간값", $T19-1, "fill=true"), _xll.IMDP("FX", data!$F48, "NY_MID_Chg", Sheet1!$I$18))} -> -0.949 | T19: {=IF(data!$C48<>"FRN", _xll.IMDP("FX", data!$F48, "중간값", Sheet1!$I$18, "fill=true, disp=date"), _xll.IMDP("FX", data!$F48, "NY_MID_Close", Sheet1!$I$18, "fill=true, disp=date"))} -> 20250303
B20: CP 91D | C20: {=IF( $B$6=TODAY(), _xll.IMDP("IR", data!$Q17, "수익률"), _xll.IMDP("IR", data!$N17, data!$N$2, $B$6) )} -> 3.01 | D20: =IF( $B$4=TODAY(), "한화", "최종" ) -> 한화 | E20: =IFERROR( (C20-F20)*100, "") -> -6 | F20: =data!AD17 -> 3.07 | G20: (최종) | K20: {=_xll.IMDP(data!$C49, data!$D49, "현재가", Sheet1!$I$18, "fill=true")} -> 18350.19 | L20: {=_xll.IMDP(data!$C49, data!$D49, "등락률", Sheet1!$I$18, "fill=true")} -> -2.64 | M20: {=_xll.IMDP(data!$C49, data!$D49, "현재가", Sheet1!$I$18, "fill=true, disp=date")} -> 20250303 | N20: {=IF(data!$C49<>"FRN", _xll.IMDP("IR", "BONDAVG01", data!$I$23, Sheet1!$I$18, "fill=true"), _xll.IMDP("IR", data!$E49, "MID_Close", Sheet1!$I$18, "fill=true"))} -> 4.1565 | O20: {=IFERROR( IF(data!$C49<>"FRN", _xll.IMDP("IR", "BONDAVG01", data!$H$24, Sheet1!$I$18, "fill=true"), _xll.IMDP("IR", data!$E49, "MID_Chg", Sheet1!$I$18, "fill=true") )*100, "")} -> -5.3 | Q20: {=IF($N20="", "", IF(data!$C49<>"FRN", _xll.IMDP("IR", "BONDAVG01", data!$I$23, Sheet1!$I$18, "fill=true, disp=date"), _xll.IMDP("IR", data!$E49, "MID_Close", Sheet1!$I$18, "fill=true, disp=date")))} -> 20250303 | R20: {=IF(data!$C49<>"FRN", _xll.IMDP("FX", data!$F49, "중간값", Sheet1!$I$18, "fill=true"), _xll.IMDP("FX", data!$F49, "NY_MID_Close", Sheet1!$I$18, "fill=true"))} -> 106.606 | S20: {=IF(data!$C49<>"FRN", $R20-_xll.IMDP("FX", data!$F49, "중간값", $T20-1, "fill=true"), _xll.IMDP("FX", data!$F49, "NY_MID_Chg", Sheet1!$I$18))} -> -0.949 | T20: {=IF(data!$C49<>"FRN", _xll.IMDP("FX", data!$F49, "중간값", Sheet1!$I$18, "fill=true, disp=date"), _xll.IMDP("FX", data!$F49, "NY_MID_Close", Sheet1!$I$18, "fill=true, disp=date"))} -> 20250303
B21: 코리보 6M | C21: {=_xll.IMDP("IR", "IBRKRWFIX06M", "금리", $B$4)} -> 2.88 | D21: 코리보 | E21: =IFERROR( (C21-F21)*100, "") -> 0 | F21: =data!AD18 -> 2.88 | K21: {=_xll.IMDP(data!$C50, data!$D50, "현재가", Sheet1!$I$18, "fill=true")} -> 2532.78 | L21: {=_xll.IMDP(data!$C50, data!$D50, "등락률", Sheet1!$I$18, "fill=true")} -> -3.39 | M21: {=_xll.IMDP(data!$C50, data!$D50, "현재가", Sheet1!$I$18, "fill=true, disp=date")} -> 20250228 | N21: {=IF(data!$C50<>"FRN", _xll.IMDP("IR", "BONDAVG01", data!$I$23, Sheet1!$I$18, "fill=true"), _xll.IMDP("IR", data!$E50, "MID_Close", Sheet1!$I$18, "fill=true"))} -> 2.7 | O21: {=IFERROR( IF(data!$C50<>"FRN", _xll.IMDP("IR", "BONDAVG01", data!$H$24, Sheet1!$I$18, "fill=true"), _xll.IMDP("IR", data!$E50, "MID_Chg", Sheet1!$I$18, "fill=true") )*100, "")} -> -5 | Q21: {=IF($N21="", "", IF(data!$C50<>"FRN", _xll.IMDP("IR", "BONDAVG01", data!$I$23, Sheet1!$I$18, "fill=true, disp=date"), _xll.IMDP("IR", data!$E50, "MID_Close", Sheet1!$I$18, "fill=true, disp=date")))} -> 20250228 | R21: {=IF(data!$C50<>"FRN", _xll.IMDP("FX", data!$F50, "중간값", Sheet1!$I$18, "fill=true"), _xll.IMDP("FX", data!$F50, "NY_MID_Close", Sheet1!$I$18, "fill=true"))} -> 1463.2 | S21: {=IF(data!$C50<>"FRN", $R21-_xll.IMDP("FX", data!$F50, "중간값", $T21-1, "fill=true"), _xll.IMDP("FX", data!$F50, "NY_MID_Chg", Sheet1!$I$18))} -> 20.35 | T21: {=IF(data!$C50<>"FRN", _xll.IMDP("FX", data!$F50, "중간값", Sheet1!$I$18, "fill=true, disp=date"), _xll.IMDP("FX", data!$F50, "NY_MID_Close", Sheet1!$I$18, "fill=true, disp=date"))} -> 20250228
B22: 콜 익일 | C22: {=IF($B$6=TODAY(), IF( data!X19=TRUE, _xll.IMDP("IR", data!$Q$19, "수익률"), _xll.IMDP("IR", data!$M$19, "체결이율")), _xll.IMDP("ECO", "700504", "현재가",$B$6))} -> 2.71 | D22: =IF( $B$4=TODAY(), IF( data!X19=TRUE, "한화", "중개사"), "한은" ) -> 중개사 | E22: =IFERROR( (C22-F22)*100, "") -> -8.2 | F22: =data!AD19 -> 2.792 | G22: (한은) | K22: {=_xll.IMDP(data!$C51, data!$D51, "현재가", Sheet1!$I$18, "fill=true")} -> 743.96 | L22: {=_xll.IMDP(data!$C51, data!$D51, "등락률", Sheet1!$I$18, "fill=true")} -> -3.49 | M22: {=_xll.IMDP(data!$C51, data!$D51, "현재가", Sheet1!$I$18, "fill=true, disp=date")} -> 20250228 | N22: {=IF(data!$C51<>"FRN", _xll.IMDP("IR", "BONDAVG01", data!$I$23, Sheet1!$I$18, "fill=true"), _xll.IMDP("IR", data!$E51, "MID_Close", Sheet1!$I$18, "fill=true"))} -> 2.7 | O22: {=IFERROR( IF(data!$C51<>"FRN", _xll.IMDP("IR", "BONDAVG01", data!$H$24, Sheet1!$I$18, "fill=true"), _xll.IMDP("IR", data!$E51, "MID_Chg", Sheet1!$I$18, "fill=true") )*100, "")} -> -5 | Q22: {=IF($N22="", "", IF(data!$C51<>"FRN", _xll.IMDP("IR", "BONDAVG01", data!$I$23, Sheet1!$I$18, "fill=true, disp=date"), _xll.IMDP("IR", data!$E51, "MID_Close", Sheet1!$I$18, "fill=true, disp=date")))} -> 20250228 | R22: {=IF(data!$C51<>"FRN", _xll.IMDP("FX", data!$F51, "중간값", Sheet1!$I$18, "fill=true"), _xll.IMDP("FX", data!$F51, "NY_MID_Close", Sheet1!$I$18, "fill=true"))} -> 1463.2 | S22: {=IF(data!$C51<>"FRN", $R22-_xll.IMDP("FX", data!$F51, "중간값", $T22-1, "fill=true"), _xll.IMDP("FX", data!$F51, "NY_MID_Chg", Sheet1!$I$18))} -> 20.35 | T22: {=IF(data!$C51<>"FRN", _xll.IMDP("FX", data!$F51, "중간값", Sheet1!$I$18, "fill=true, disp=date"), _xll.IMDP("FX", data!$F51, "NY_MID_Close", Sheet1!$I$18, "fill=true, disp=date"))} -> 20250228
K23: {=_xll.IMDP(data!$C52, data!$D52, "현재가", Sheet1!$I$18, "fill=true")} -> 5849.72 | L23: {=_xll.IMDP(data!$C52, data!$D52, "등락률", Sheet1!$I$18, "fill=true")} -> -1.76 | M23: {=_xll.IMDP(data!$C52, data!$D52, "현재가", Sheet1!$I$18, "fill=true, disp=date")} -> 20250303 | N23: {=IF(data!$C52<>"FRN", _xll.IMDP("IR", "BONDAVG01", data!$I$23, Sheet1!$I$18, "fill=true"), _xll.IMDP("IR", data!$E52, "MID_Close", Sheet1!$I$18, "fill=true"))} -> 1.4046 | O23: {=IFERROR( IF(data!$C52<>"FRN", _xll.IMDP("IR", "BONDAVG01", data!$H$24, Sheet1!$I$18, "fill=true"), _xll.IMDP("IR", data!$E52, "MID_Chg", Sheet1!$I$18, "fill=true") )*100, "")} -> 3.38 | Q23: {=IF($N23="", "", IF(data!$C52<>"FRN", _xll.IMDP("IR", "BONDAVG01", data!$I$23, Sheet1!$I$18, "fill=true, disp=date"), _xll.IMDP("IR", data!$E52, "MID_Close", Sheet1!$I$18, "fill=true, disp=date")))} -> 20250303 | R23: {=IF(data!$C52<>"FRN", _xll.IMDP("FX", data!$F52, "중간값", Sheet1!$I$18, "fill=true"), _xll.IMDP("FX", data!$F52, "NY_MID_Close", Sheet1!$I$18, "fill=true"))} -> 149.405 | S23: {=IF(data!$C52<>"FRN", $R23-_xll.IMDP("FX", data!$F52, "중간값", $T23-1, "fill=true"), _xll.IMDP("FX", data!$F52, "NY_MID_Chg", Sheet1!$I$18))} -> -1.105 | T23: {=IF(data!$C52<>"FRN", _xll.IMDP("FX", data!$F52, "중간값", Sheet1!$I$18, "fill=true, disp=date"), _xll.IMDP("FX", data!$F52, "NY_MID_Close", Sheet1!$I$18, "fill=true, disp=date"))} -> 20250303
K24: {=_xll.IMDP(data!$C53, data!$D53, "현재가", Sheet1!$I$18, "fill=true")} -> 3316.93 | L24: {=_xll.IMDP(data!$C53, data!$D53, "등락률", Sheet1!$I$18, "fill=true")} -> -0.12 | M24: {=_xll.IMDP(data!$C53, data!$D53, "현재가", Sheet1!$I$18, "fill=true, disp=date")} -> 20250303 | N24: {=IF(data!$C53<>"FRN", _xll.IMDP("IR", "BONDAVG01", data!$I$23, Sheet1!$I$18, "fill=true"), _xll.IMDP("IR", data!$E53, "MID_Close", Sheet1!$I$18, "fill=true"))} -> 1.7533 | O24: {=IFERROR( IF(data!$C53<>"FRN", _xll.IMDP("IR", "BONDAVG01", data!$H$24, Sheet1!$I$18, "fill=true"), _xll.IMDP("IR", data!$E53, "MID_Chg", Sheet1!$I$18, "fill=true") )*100, "")} -> -1.5 | Q24: {=IF($N24="", "", IF(data!$C53<>"FRN", _xll.IMDP("IR", "BONDAVG01", data!$I$23, Sheet1!$I$18, "fill=true, disp=date"), _xll.IMDP("IR", data!$E53, "MID_Close", Sheet1!$I$18, "fill=true, disp=date")))} -> 20250303 | R24: {=IF(data!$C53<>"FRN", _xll.IMDP("FX", data!$F53, "중간값", Sheet1!$I$18, "fill=true"), _xll.IMDP("FX", data!$F53, "NY_MID_Close", Sheet1!$I$18, "fill=true"))} -> 7.2854 | S24: {=IF(data!$C53<>"FRN", $R24-_xll.IMDP("FX", data!$F53, "중간값", $T24-1, "fill=true"), _xll.IMDP("FX", data!$F53, "NY_MID_Chg", Sheet1!$I$18))} -> 0.00165 | T24: {=IF(data!$C53<>"FRN", _xll.IMDP("FX", data!$F53, "중간값", Sheet1!$I$18, "fill=true, disp=date"), _xll.IMDP("FX", data!$F53, "NY_MID_Close", Sheet1!$I$18, "fill=true, disp=date"))} -> 20250303
B25: 투자자별 매매동행 (약정 / 억) | K25: {=_xll.IMDP(data!$C54, data!$D54, "현재가", Sheet1!$I$18, "fill=true")} -> 23006.27 | L25: {=_xll.IMDP(data!$C54, data!$D54, "등락률", Sheet1!$I$18, "fill=true")} -> 0.28 | M25: {=_xll.IMDP(data!$C54, data!$D54, "현재가", Sheet1!$I$18, "fill=true, disp=date")} -> 20250303 | N25: {=IF(data!$C54<>"FRN", _xll.IMDP("IR", "BONDAVG01", data!$I$23, Sheet1!$I$18, "fill=true"), _xll.IMDP("IR", data!$E54, "MID_Close", Sheet1!$I$18, "fill=true"))} | O25: {=IFERROR( IF(data!$C54<>"FRN", _xll.IMDP("IR", "BONDAVG01", data!$H$24, Sheet1!$I$18, "fill=true"), _xll.IMDP("IR", data!$E54, "MID_Chg", Sheet1!$I$18, "fill=true") )*100, "")} | Q25: {=IF($N25="", "", IF(data!$C54<>"FRN", _xll.IMDP("IR", "BONDAVG01", data!$I$23, Sheet1!$I$18, "fill=true, disp=date"), _xll.IMDP("IR", data!$E54, "MID_Close", Sheet1!$I$18, "fill=true, disp=date")))} | R25: {=IF(data!$C54<>"FRN", _xll.IMDP("FX", data!$F54, "중간값", Sheet1!$I$18, "fill=true"), _xll.IMDP("FX", data!$F54, "NY_MID_Close", Sheet1!$I$18, "fill=true"))} -> 7.77745 | S25: {=IF(data!$C54<>"FRN", $R25-_xll.IMDP("FX", data!$F54, "중간값", $T25-1, "fill=true"), _xll.IMDP("FX", data!$F54, "NY_MID_Chg", Sheet1!$I$18))} -> 0.00045 | T25: {=IF(data!$C54<>"FRN", _xll.IMDP("FX", data!$F54, "중간값", Sheet1!$I$18, "fill=true, disp=date"), _xll.IMDP("FX", data!$F54, "NY_MID_Close", Sheet1!$I$18, "fill=true, disp=date"))} -> 20250303
B26: =$B$4 -> 45721 | C26: KTB03 | D26: KTB10 | E26: K200ⓕ | F26: 거래소 | G26: 코스닥 | K26: {=_xll.IMDP(data!$C55, data!$D55, "현재가", Sheet1!$I$18, "fill=true")} -> 22756.25 | L26: {=_xll.IMDP(data!$C55, data!$D55, "등락률", Sheet1!$I$18, "fill=true")} -> -1.29 | M26: {=_xll.IMDP(data!$C55, data!$D55, "현재가", Sheet1!$I$18, "fill=true, disp=date")} -> 20250303 | N26: {=IF(data!$C55<>"FRN", _xll.IMDP("IR", "BONDAVG01", data!$I$23, Sheet1!$I$18, "fill=true"), _xll.IMDP("IR", data!$E55, "MID_Close", Sheet1!$I$18, "fill=true"))} -> 1.625 | O26: {=IFERROR( IF(data!$C55<>"FRN", _xll.IMDP("IR", "BONDAVG01", data!$H$24, Sheet1!$I$18, "fill=true"), _xll.IMDP("IR", data!$E55, "MID_Chg", Sheet1!$I$18, "fill=true") )*100, "")} -> 1.5 | Q26: {=IF($N26="", "", IF(data!$C55<>"FRN", _xll.IMDP("IR", "BONDAVG01", data!$I$23, Sheet1!$I$18, "fill=true, disp=date"), _xll.IMDP("IR", data!$E55, "MID_Close", Sheet1!$I$18, "fill=true, disp=date")))} -> 20250303 | R26: {=IF(data!$C55<>"FRN", _xll.IMDP("FX", data!$F55, "중간값", Sheet1!$I$18, "fill=true"), _xll.IMDP("FX", data!$F55, "NY_MID_Close", Sheet1!$I$18, "fill=true"))} -> 32.9048 | S26: {=IF(data!$C55<>"FRN", $R26-_xll.IMDP("FX", data!$F55, "중간값", $T26-1, "fill=true"), _xll.IMDP("FX", data!$F55, "NY_MID_Chg", Sheet1!$I$18))} -> -0.0197 | T26: {=IF(data!$C55<>"FRN", _xll.IMDP("FX", data!$F55, "중간값", Sheet1!$I$18, "fill=true, disp=date"), _xll.IMDP("FX", data!$F55, "NY_MID_Close", Sheet1!$I$18, "fill=true, disp=date"))} -> 20250303
B27: 외인 | C27: =data!M50 -> 21097 | D27: =data!N50 -> -237 | E27: =data!Q50 -> -1842 | F27: =data!O50/100 -> -2242.41 | G27: =data!P50/100 -> 645.67 | K27: {=_xll.IMDP(data!$C56, data!$D56, "현재가", Sheet1!$I$18, "fill=true")} -> 5540.69 | L27: {=_xll.IMDP(data!$C56, data!$D56, "등락률", Sheet1!$I$18, "fill=true")} -> 1.41 | M27: {=_xll.IMDP(data!$C56, data!$D56, "현재가", Sheet1!$I$18, "fill=true, disp=date")} -> 20250303 | N27: {=IF(data!$C56<>"FRN", _xll.IMDP("IR", "BONDAVG01", data!$I$23, Sheet1!$I$18, "fill=true"), _xll.IMDP("IR", data!$E56, "MID_Close", Sheet1!$I$18, "fill=true"))} -> 2.4895 | O27: {=IFERROR( IF(data!$C56<>"FRN", _xll.IMDP("IR", "BONDAVG01", data!$H$24, Sheet1!$I$18, "fill=true"), _xll.IMDP("IR", data!$E56, "MID_Chg", Sheet1!$I$18, "fill=true") )*100, "")} -> 8.475 | Q27: {=IF($N27="", "", IF(data!$C56<>"FRN", _xll.IMDP("IR", "BONDAVG01", data!$I$23, Sheet1!$I$18, "fill=true, disp=date"), _xll.IMDP("IR", data!$E56, "MID_Close", Sheet1!$I$18, "fill=true, disp=date")))} -> 20250303 | R27: {=IF(data!$C56<>"FRN", _xll.IMDP("FX", data!$F56, "중간값", Sheet1!$I$18, "fill=true"), _xll.IMDP("FX", data!$F56, "NY_MID_Close", Sheet1!$I$18, "fill=true"))} -> 1.0482 | S27: {=IF(data!$C56<>"FRN", $R27-_xll.IMDP("FX", data!$F56, "중간값", $T27-1, "fill=true"), _xll.IMDP("FX", data!$F56, "NY_MID_Chg", Sheet1!$I$18))} -> 0.0108 | T27: {=IF(data!$C56<>"FRN", _xll.IMDP("FX", data!$F56, "중간값", Sheet1!$I$18, "fill=true, disp=date"), _xll.IMDP("FX", data!$F56, "NY_MID_Close", Sheet1!$I$18, "fill=true, disp=date"))} -> 20250303
B28: 기금 | C28: =data!M51 -> -491 | D28: =data!N51 -> 1091 | E28: =data!Q51 -> -98 | F28: =data!O51/100 -> 709.16 | G28: =data!P51/100 -> 42.38 | K28: {=_xll.IMDP(data!$C57, data!$D57, "현재가", Sheet1!$I$18, "fill=true")} -> 23147.02 | L28: {=_xll.IMDP(data!$C57, data!$D57, "등락률", Sheet1!$I$18, "fill=true")} -> 2.64 | M28: {=_xll.IMDP(data!$C57, data!$D57, "현재가", Sheet1!$I$18, "fill=true, disp=date")} -> 20250303 | N28: {=IF(data!$C57<>"FRN", _xll.IMDP("IR", "BONDAVG01", data!$I$23, Sheet1!$I$18, "fill=true"), _xll.IMDP("IR", data!$E57, "MID_Close", Sheet1!$I$18, "fill=true"))} -> 2.4895 | O28: {=IFERROR( IF(data!$C57<>"FRN", _xll.IMDP("IR", "BONDAVG01", data!$H$24, Sheet1!$I$18, "fill=true"), _xll.IMDP("IR", data!$E57, "MID_Chg", Sheet1!$I$18, "fill=true") )*100, "")} -> 8.475 | Q28: {=IF($N28="", "", IF(data!$C57<>"FRN", _xll.IMDP("IR", "BONDAVG01", data!$I$23, Sheet1!$I$18, "fill=true, disp=date"), _xll.IMDP("IR", data!$E57, "MID_Close", Sheet1!$I$18, "fill=true, disp=date")))} -> 20250303 | R28: {=IF(data!$C57<>"FRN", _xll.IMDP("FX", data!$F57, "중간값", Sheet1!$I$18, "fill=true"), _xll.IMDP("FX", data!$F57, "NY_MID_Close", Sheet1!$I$18, "fill=true"))} -> 1.0482 | S28: {=IF(data!$C57<>"FRN", $R28-_xll.IMDP("FX", data!$F57, "중간값", $T28-1, "fill=true"), _xll.IMDP("FX", data!$F57, "NY_MID_Chg", Sheet1!$I$18))} -> 0.0108 | T28: {=IF(data!$C57<>"FRN", _xll.IMDP("FX", data!$F57, "중간값", Sheet1!$I$18, "fill=true, disp=date"), _xll.IMDP("FX", data!$F57, "NY_MID_Close", Sheet1!$I$18, "fill=true, disp=date"))} -> 20250303
B29: 투신 | C29: =data!M52 -> 700 | D29: =data!N52 -> 865 | E29: =data!Q52 -> 3766 | F29: =data!O52/100 -> 976.49 | G29: =data!P52/100 -> -52.29
B30: 은행 | C30: =data!M53 -> -1922 | D30: =data!N53 -> 2565 | E30: =data!Q53 -> 110 | F30: =data!O53/100 -> 34.12 | G30: =data!P53/100 -> 12.71 | I30: 전일 외국인 채권동향 (억, %)
B31: 보험 | C31: =data!M54 -> -1617 | D31: =data!N54 -> 124 | E31: =data!Q54 -> -455 | F31: =data!O54/100 -> 254.06 | G31: =data!P54/100 -> -19.95 | I31: =data!$L$43 -> 45720 | K31: 잔고 | L31: 잔고 비중 | M31: 순매수
B32: 개인 | C32: =data!M55 -> -2 | D32: =data!N55 -> 261 | E32: =data!Q55 -> -861 | F32: =data!O55/100 -> 921.15 | G32: =data!P55/100 -> -617.71 | I32: 스트립 포함 | J32: 전체 | K32: =data!M44/10000 -> 2617408.5 | L32: =data!M44/data!N44*100 -> 9.0027118 | M32: =data!O44/100000 -> -15660.769
B33: 증권 | C33: =data!M56 -> -17809 | D33: =data!N56 -> -4659 | E33: =data!Q56 -> -784 | F33: =data!O56/100 -> -2102.22 | G33: =data!P56/100 -> 18.35 | J33: 국고 | K33: =data!M45/10000 -> 2360626.3 | L33: =data!M45/data!N45*100 -> 20.091291 | M33: =data!O45/100000 -> 3338.8136
J34: 통안 | K34: =data!M46/10000 -> 147781.3 | L34: =data!M46/data!N46*100 -> 13.640511 | M34: =data!O46/100000 -> 2500
B36: =$B$4 -> 45721 | D36: 경제지표 발표 | I36: KRX 선물
B37: {=OFFSET(data!$T$50, data!$S$49, 0, 10)} -> 2025.03.05 01:00 | D37: {=OFFSET(data!$U$50, data!$S$49, 0, 10)} -> 01월 러시아 실업률 | I37: =$B$4 -> 45721 | K37: 현재가 | L37: 이론가 | M37: 저평가
B38: 2025.03.05 09:30 | D38: 4분기 호주 실질GDP | I38: =data!$R$22 -> W3000 | J38: 03Y | K38: {=_xll.IMDP("FUT", "C65", "현재가", $I$37)} -> 106.78 | L38: {=IF($I$37<>TODAY(), _xll.IMDP("FUT", "C65", "이론가", $I$37), _xll.IMDP("FUT", 165&data!$R$22, "이론가") )} -> 106.743 | M38: =K38-L38 -> 0.037
B39: 2025.03.05 16:30 | D39: 02월 스위스 소비자물가 | J39: 10Y | K39: {=_xll.IMDP("FUT", "C67", "현재가", $I$37)} -> 118.95 | L39: {=IF($I$37<>TODAY(), _xll.IMDP("FUT", "C67", "이론가", $I$37), _xll.IMDP("FUT", 167&data!$R$22, "이론가") )} -> 118.977 | M39: =K39-L39 -> -0.027
B40: 2025.03.05 16:45 | D40: 01월 프랑스 산업생산 | I40: {=IF($I$37=TODAY(), _xll.IMDP("FUT", "C01", "단축코드", $I$37), "C01")} -> 101W3000 | J40: K200 | K40: {=_xll.IMDP("FUT", "C01", "현재가", $I$37)} -> 336.35 | L40: {=_xll.IMDP("FUT", "C01", "이론가", $I$37)} -> 337.31 | M40: =K40-L40 -> -0.96
B41: 2025.03.05 18:00 | D41: 02월 유로존 서비스업PMI
B42: 2025.03.05 18:00 | D42: 02월 유로존 합성PMI | I42: 콜 익일물
B43: 2025.03.05 19:00 | D43: 01월 유로존 생산자물가 | I43: =$B$4 -> 45721 | K43: 체결 계 (억) | L43: =IF($I$43=TODAY(), "평균이율", "합계평균") -> 평균이율 | M43: =IF($I$43=TODAY(), "체결이율", "최종이율") -> 체결이율
...

Sheet data
N2: 대표수익률 | Q2: 수익률
B3: 국가 | C3: M | D3: 지수 | E3: 금리 | F3: 환율 | H3: 2 | M3: 거래 | N3: 최종호가 | O3: 민평 Matrix | P3: 종목 (국고) | Q3: 한화 | U3: 장내국채-시간 | V3: 장외-시간 | AD3: =DATE(LEFT($AE$4,4), MID($AE$4, 5,2), RIGHT($AE$4, 2)) -> 45714 | AE3: {=Sheet1!$B$4-INDEX(data!$I$9:$I$14, data!$H$8)} -> 45714 | AJ3: 표준코드 | AM3: 장내국채-매도수량1 | AN3: 장내국채-매도수익률1 | AO3: 장내국채-매도가격1 | AP3: 장내국채-매수가격1 | AQ3: 장내국채-매수수익률1 | AR3: 장내국채-매수수량1
B4: 미국(DJI) | C4: FRN | D4: DJI:DJI | E4: US | F4: DOLLAR | H4: 최종호가 | L4: =Sheet1!B7 -> 국고 2Y | M4: =AJ4 -> KR103503GE96 | N4: BONDKSDCAL19 | O4: BONDAVG01 | P4: KR1035G00002 | Q4: BONDHANYLD230 | S4: 2년이하(당일) | U4: {=_xll.IMDP("BND", $M4, U$3,,"TmFmt=1")} -> 0.64466435 | V4: {=_xll.IMDP("BND", $M4, V$3,,"TmFmt=1")} -> 0.66637731 | W4: =MATCH(MAX($U4:$V4), $U4:$V4, 0) -> 2 | X4: =IF(AND(U4="", V4=""),TRUE,CHOOSE(W4, "장내국채-현재수익률", "장외-현재수익률") ) -> 장외-현재수익률 | Y4: =CHOOSE($W4, "장내", "장외") -> 장외 | AB4: =CHOOSE($H$3, $N4, $O4, $AI4) -> BONDAVG01 | AC4: =CHOOSE($H$3, "대표수익률", data!$S4, "민평3사 수익률(산출일) 당일") -> 2년이하(당일) | AD4: {=IF($H$3=3, _xll.IMDP("BND", $M4, $AC4, $AD$3), _xll.IMDP("IR", $AB4, $AC4, $AD$3) )} -> 2.655 | AE4: {=_xll.IMDP("IR", $N$5, $N$2, data!$AE$3, "fill=true, disp=date, DtFmt=1")} -> 20250226 | AG4: {=_xll.IMDH("BND", $AI4, "표준코드", Sheet1!$B$6, Sheet1!$B$6, 1, "Per=일, Sort=D, real=true, Bizday=12, Pos=30, Orient=H")} -> 조회[KR1035G00002] | AH4: 국고 2Y | AI4: KR1035G00002 | AJ4: KR103503GE96 | AM4: {=_xll.IMDP("BND", $AJ4, AM$3)} -> 60 | AN4: {=_xll.IMDP("BND", $AJ4, AN$3)} -> 2.674 | AO4: {=_xll.IMDP("BND", $AJ4, AO$3)} -> 10170 | AP4: {=_xll.IMDP("BND", $AJ4, AP$3)} -> 10169.5 | AQ4: {=_xll.IMDP("BND", $AJ4, AQ$3)} -> 2.678 | AR4: {=_xll.IMDP("BND", $AJ4, AR$3)} -> 50
B5: 미국(NASDAQ) | C5: FRN | D5: NAS:IXIC | E5: US | F5: DOLLAR | H5: 민평 Matrix | L5: =Sheet1!B8 -> 국고 3Y | M5: =AJ5 -> KR103501GEC6 | N5: BONDKSDCAL11 | O5: BONDAVG01 | P5: KR1035G00003 | Q5: BONDHANYLD330 | S5: 3년이하(당일) | U5: {=_xll.IMDP("BND", $M5, U$3,,"TmFmt=1")} -> 0.64581019 | V5: {=_xll.IMDP("BND", $M5, V$3,,"TmFmt=1")} -> 0.69887731 | W5: =MATCH(MAX($U5:$V5), $U5:$V5, 0) -> 2 | X5: =IF(AND(U5="", V5=""),TRUE,CHOOSE(W5, "장내국채-현재수익률", "장외-현재수익률") ) -> 장외-현재수익률 | Y5: =CHOOSE($W5, "장내", "장외") -> 장외 | AB5: =CHOOSE($H$3, $N5, $O5, $AI5) -> BONDAVG01 | AC5: =CHOOSE($H$3, "대표수익률", data!$S5, "민평3사 수익률(산출일) 당일") -> 3년이하(당일) | AD5: {=IF($H$3=3, _xll.IMDP("BND", $M5, $AC5, $AD$3), _xll.IMDP("IR", $AB5, $AC5, $AD$3) )} -> 2.595 | AG5: {=_xll.IMDH("BND", $AI5, "표준코드", Sheet1!$B$6, Sheet1!$B$6, 1, "Per=일, Sort=D, real=true, Bizday=12, Pos=30, Orient=H")} -> 조회[KR1035G00003] | AH5: 국고 3Y | AI5: KR1035G00003 | AJ5: KR103501GEC6 | AM5: {=_xll.IMDP("BND", $AJ5, AM$3)} -> 50 | AN5: {=_xll.IMDP("BND", $AJ5, AN$3)} -> 2.563 | AO5: {=_xll.IMDP("BND", $AJ5, AO$3)} -> 10150 | AP5: {=_xll.IMDP("BND", $AJ5, AP$3)} -> 10149.5 | AQ5: {=_xll.IMDP("BND", $AJ5, AQ$3)} -> 2.565 | AR5: {=_xll.IMDP("BND", $AJ5, AR$3)} -> 80
B6: 미국(S&P) | C6: FRN | D6: SPI:SPX | E6: US | F6: DOLLAR | H6: 종목(국고) | L6: =Sheet1!B9 -> 국고 5Y | M6: =AJ6 -> KR103501GE98 | N6: BONDKSDCAL12 | O6: BONDAVG01 | P6: KR1035G00005 | Q6: BONDHANYLD530 | S6: 5년이하(당일) | U6: {=_xll.IMDP("BND", $M6, U$3,,"TmFmt=1")} -> 0.64578704 | V6: {=_xll.IMDP("BND", $M6, V$3,,"TmFmt=1")} -> 0.70436343 | W6: =MATCH(MAX($U6:$V6), $U6:$V6, 0) -> 2 | X6: =IF(AND(U6="", V6=""),TRUE,CHOOSE(W6, "장내국채-현재수익률", "장외-현재수익률") ) -> 장외-현재수익률 | Y6: =CHOOSE($W6, "장내", "장외") -> 장외 | AB6: =CHOOSE($H$3, $N6, $O6, $AI6) -> BONDAVG01 | AC6: =CHOOSE($H$3, "대표수익률", data!$S6, "민평3사 수익률(산출일) 당일") -> 5년이하(당일) | AD6: {=IF($H$3=3, _xll.IMDP("BND", $M6, $AC6, $AD$3), _xll.IMDP("IR", $AB6, $AC6, $AD$3) )} -> 2.68 | AG6: {=_xll.IMDH("BND", $AI6, "표준코드", Sheet1!$B$6, Sheet1!$B$6, 1, "Per=일, Sort=D, real=true, Bizday=12, Pos=30, Orient=H")} -> 조회[KR1035G00005] | AH6: 국고 5Y | AI6: KR1035G00005 | AJ6: KR103501GE98 | AM6: {=_xll.IMDP("BND", $AJ6, AM$3)} -> 10 | AN6: {=_xll.IMDP("BND", $AJ6, AN$3)} -> 2.675 | AO6: {=_xll.IMDP("BND", $AJ6, AO$3)} -> 10283.5 | AP6: {=_xll.IMDP("BND", $AJ6, AP$3)} -> 10282.5 | AQ6: {=_xll.IMDP("BND", $AJ6, AQ$3)} -> 2.678 | AR6: {=_xll.IMDP("BND", $AJ6, AR$3)} -> 100
B7: 미국(PHLX) | C7: FRN | D7: USI:SOXX | E7: US | F7: DOLLAR | L7: =Sheet1!B10 -> 국고 10Y | M7: =AJ7 -> KR103502GEC4 | N7: BONDKSDCAL13 | O7: BONDAVG01 | P7: KR1035G00010 | Q7: BONDHANYLD540 | S7: 10년이하(당일) | U7: {=_xll.IMDP("BND", $M7, U$3,,"TmFmt=1")} -> 0.64570602 | V7: {=_xll.IMDP("BND", $M7, V$3,,"TmFmt=1")} -> 0.70417824 | W7: =MATCH(MAX($U7:$V7), $U7:$V7, 0) -> 2 | X7: =IF(AND(U7="", V7=""),TRUE,CHOOSE(W7, "장내국채-현재수익률", "장외-현재수익률") ) -> 장외-현재수익률 | Y7: =CHOOSE($W7, "장내", "장외") -> 장외 | AB7: =CHOOSE($H$3, $N7, $O7, $AI7) -> BONDAVG01 | AC7: =CHOOSE($H$3, "대표수익률", data!$S7, "민평3사 수익률(산출일) 당일") -> 10년이하(당일) | AD7: {=IF($H$3=3, _xll.IMDP("BND", $M7, $AC7, $AD$3), _xll.IMDP("IR", $AB7, $AC7, $AD$3) )} -> 2.753 | AG7: {=_xll.IMDH("BND", $AI7, "표준코드", Sheet1!$B$6, Sheet1!$B$6, 1, "Per=일, Sort=D, real=true, Bizday=12, Pos=30, Orient=H")} -> 조회[KR1035G00010] | AH7: 국고 10Y | AI7: KR1035G00010 | AJ7: KR103502GEC4 | AM7: {=_xll.IMDP("BND", $AJ7, AM$3)} -> 30 | AN7: {=_xll.IMDP("BND", $AJ7, AN$3)} -> 2.772 | AO7: {=_xll.IMDP("BND", $AJ7, AO$3)} -> 10264 | AP7: {=_xll.IMDP("BND", $AJ7, AP$3)} -> 10262 | AQ7: {=_xll.IMDP("BND", $AJ7, AQ$3)} -> 2.774 | AR7: {=_xll.IMDP("BND", $AJ7, AR$3)} -> 100
B8: 호주 | C8: FRN | D8: NAS:IXIC | E8: AU | F8: AUDUSD | H8: 2 | L8: =Sheet1!B11 -> 국고 20Y | M8: =AJ8 -> KR103504GE95 | N8: BONDKSDCAL15 | O8: BONDAVG01 | P8: KR1035G00020 | Q8: BONDHANYLD550 | S8: 20년이하(당일) | U8: {=_xll.IMDP("BND", $M8, U$3,,"TmFmt=1")} -> 0.64570602 | V8: {=_xll.IMDP("BND", $M8, V$3,,"TmFmt=1")} -> 0.7000463 | W8: =MATCH(MAX($U8:$V8), $U8:$V8, 0) -> 2 | X8: =IF(AND(U8="", V8=""),TRUE,CHOOSE(W8, "장내국채-현재수익률", "장외-현재수익률") ) -> 장외-현재수익률 | Y8: =CHOOSE($W8, "장내", "장외") -> 장외 | AB8: =CHOOSE($H$3, $N8, $O8, $AI8) -> BONDAVG01 | AC8: =CHOOSE($H$3, "대표수익률", data!$S8, "민평3사 수익률(산출일) 당일") -> 20년이하(당일) | AD8: {=IF($H$3=3, _xll.IMDP("BND", $M8, $AC8, $AD$3), _xll.IMDP("IR", $AB8, $AC8, $AD$3) )} -> 2.695 | AG8: {=_xll.IMDH("BND", $AI8, "표준코드", Sheet1!$B$6, Sheet1!$B$6, 1, "Per=일, Sort=D, real=true, Bizday=12, Pos=30, Orient=H")} -> 조회[KR1035G00020] | AH8: 국고 20Y | AI8: KR1035G00020 | AJ8: KR103504GE95 | AM8: {=_xll.IMDP("BND", $AJ8, AM$3)} -> 10 | AN8: {=_xll.IMDP("BND", $AJ8, AN$3)} -> 2.703 | AO8: {=_xll.IMDP("BND", $AJ8, AO$3)} -> 10399 | AP8: {=_xll.IMDP("BND", $AJ8, AP$3)} -> 10391 | AQ8: {=_xll.IMDP("BND", $AJ8, AQ$3)} -> 2.708 | AR8: {=_xll.IMDP("BND", $AJ8, AR$3)} -> 20
B9: 한국(KOSPI) | C9: IDX | D9: 001 | F9: USDSP_AMBC | H9: 전일 | I9: 1 | L9: =Sheet1!B12 -> 국고 30Y | M9: =AJ9 -> KR103502GE97 | N9: BONDKSDCAL17 | O9: BONDAVG01 | P9: KR1035G00030 | Q9: BONDHANYLD560 | S9: 30년이하(당일) | U9: {=_xll.IMDP("BND", $M9, U$3,,"TmFmt=1")} -> 0.64582176 | V9: {=_xll.IMDP("BND", $M9, V$3,,"TmFmt=1")} -> 0.70436343 | W9: =MATCH(MAX($U9:$V9), $U9:$V9, 0) -> 2 | X9: =IF(AND(U9="", V9=""),TRUE,CHOOSE(W9, "장내국채-현재수익률", "장외-현재수익률") ) -> 장외-현재수익률 | Y9: =CHOOSE($W9, "장내", "장외") -> 장외 | AB9: =CHOOSE($H$3, $N9, $O9, $AI9) -> BONDAVG01 | AC9: =CHOOSE($H$3, "대표수익률", data!$S9, "민평3사 수익률(산출일) 당일") -> 30년이하(당일) | AD9: {=IF($H$3=3, _xll.IMDP("BND", $M9, $AC9, $AD$3), _xll.IMDP("IR", $AB9, $AC9, $AD$3) )} -> 2.595 | AG9: {=_xll.IMDH("BND", $AI9, "표준코드", Sheet1!$B$6, Sheet1!$B$6, 1, "Per=일, Sort=D, real=true, Bizday=12, Pos=30, Orient=H")} -> 조회[KR1035G00030] | AH9: 국고 30Y | AI9: KR1035G00030 | AJ9: KR103502GE97 | AM9: {=_xll.IMDP("BND", $AJ9, AM$3)} -> 10 | AN9: {=_xll.IMDP("BND", $AJ9, AN$3)} -> 2.605 | AO9: {=_xll.IMDP("BND", $AJ9, AO$3)} -> 10430 | AP9: {=_xll.IMDP("BND", $AJ9, AP$3)} -> 10428 | AQ9: {=_xll.IMDP("BND", $AJ9, AQ$3)} -> 2.606 | AR9: {=_xll.IMDP("BND", $AJ9, AR$3)} -> 30
B10: 한국(KOSDAQ) | C10: IDX | D10: 801 | F10: USDSP_AMBC | H10: 1주 전 | I10: 7 | L10: =Sheet1!B13 -> 통안 91D | N10: BONDKSDCAL16 | O10: BONDAVG14 | P10: =O10 -> BONDAVG14 | Q10: BONDHANYLD510 | S10: 3월이하(당일) | AB10: {=INDEX($N10:$P10, 1, $H$3)} -> BONDAVG14 | AC10: =CHOOSE($H$3, "대표수익률", data!$S10, data!$S10) -> 3월이하(당일) | AD10: {=_xll.IMDP("IR", $AB10, $AC10, $AD$3)} -> 2.758 | AG10: {=_xll.IMDH("BND", $AI10, "표준코드", Sheet1!$B$6, Sheet1!$B$6, 1, "Per=일, Sort=D, real=true, Bizday=12, Pos=30, Orient=H")} -> 조회[KR1035M00200] | AH10: 물가 10Y | AI10: KR1035M00200 | AJ10: KR103503GE62 | AM10: {=_xll.IMDP("BND", $AJ10, AM$3)} -> 20 | AN10: {=_xll.IMDP("BND", $AJ10, AN$3)} -> 0.415 | AO10: {=_xll.IMDP("BND", $AJ10, AO$3)} -> 10321 | AP10: {=_xll.IMDP("BND", $AJ10, AP$3)} -> 10317 | AQ10: {=_xll.IMDP("BND", $AJ10, AQ$3)} -> 0.42 | AR10: {=_xll.IMDP("BND", $AJ10, AR$3)} -> 10
B11: 일본 | C11: FRN | D11: SPI:SPX | E11: JP | F11: USDJPY | H11: 1개월 전 | I11: 30 | L11: =Sheet1!B14 -> 통안 1Y | N11: BONDKSDCAL02 | O11: BONDAVG14 | P11: =O11 -> BONDAVG14 | Q11: BONDHANYLD410 | S11: 1년이하(당일) | AB11: {=INDEX($N11:$P11, 1, $H$3)} -> BONDAVG14 | AC11: =CHOOSE($H$3, "대표수익률", data!$S11, data!$S11) -> 1년이하(당일) | AD11: {=_xll.IMDP("IR", $AB11, $AC11, $AD$3)} -> 2.626
B12: 중국(상해종합) | C12: FRN | D12: SHS:000001 | E12: RM | F12: USDCNY | H12: 3개월 전 | I12: 90 | L12: =Sheet1!B15 -> 통안 2Y | M12: =AJ12 -> KR310101GF19 | N12: BONDKSDCAL03 | O12: BONDAVG14 | P12: KR3101000100 | Q12: BONDHANYLD520 | S12: 2년이하(당일) | U12: {=_xll.IMDP("BND", $M12, U$3,,"TmFmt=1")} | V12: {=_xll.IMDP("BND", $M12, V$3,,"TmFmt=1")} -> 0.70311343 | W12: =MATCH(MAX($U12:$V12), $U12:$V12, 0) -> 2 | X12: =IF(AND(U12="", V12=""),TRUE,CHOOSE(W12, "장내국채-현재수익률", "장외-현재수익률") ) -> 장외-현재수익률 | Y12: =CHOOSE($W12, "장내", "장외") -> 장외 | AB12: =CHOOSE($H$3, $N12, $O12, $AI12) -> BONDAVG14 | AC12: =CHOOSE($H$3, "대표수익률", data!$S12, "민평3사 수익률(산출일) 당일") -> 2년이하(당일) | AD12: {=IF($H$3=3, _xll.IMDP("BND", $M12, $AC12, $AD$3), _xll.IMDP("IR", $AB12, $AC12, $AD$3) )} -> 2.64 | AG12: {=_xll.IMDH("BND", $AI12, "표준코드", Sheet1!$B$6, Sheet1!$B$6, 1, "Per=일, Sort=D, real=true, Bizday=12, Pos=30, Orient=H")} -> 조회[KR3101000100] | AH12: 통안 2Y | AI12: KR3101000100 | AJ12: KR310101GF19
B13: 중국(심천종합) | C13: FRN | D13: SZS:399106 | E13: RM | F13: USDCNY | H13: 6개월 전 | I13: 180 | L13: =Sheet1!B16 -> 통안 3Y | M13: =AJ13 -> KR310102GE92 | N13: BONDKSDCAL03 | O13: BONDAVG14 | P13: KR3101000101 | Q13: BONDHANYLD630 | S13: 3년이하(당일) | U13: {=_xll.IMDP("BND", $M13, U$3,,"TmFmt=1")} | V13: {=_xll.IMDP("BND", $M13, V$3,,"TmFmt=1")} -> 0.62520833 | W13: =MATCH(MAX($U13:$V13), $U13:$V13, 0) -> 2 | X13: =IF(AND(U13="", V13=""),TRUE,CHOOSE(W13, "장내국채-현재수익률", "장외-현재수익률") ) -> 장외-현재수익률 | Y13: =CHOOSE($W13, "장내", "장외") -> 장외 | AB13: =CHOOSE($H$3, $N13, $O13, $AI13) -> BONDAVG14 | AC13: =CHOOSE($H$3, "대표수익률", data!$S13, "민평3사 수익률(산출일) 당일") -> 3년이하(당일) | AD13: {=IF($H$3=3, _xll.IMDP("BND", $M13, $AC13, $AD$3), _xll.IMDP("IR", $AB13, $AC13, $AD$3) )} -> 2.664 | AG13: {=_xll.IMDH("BND", $AI13, "표준코드", Sheet1!$B$6, Sheet1!$B$6, 1, "Per=일, Sort=D, real=true, Bizday=12, Pos=30, Orient=H")} -> 조회[KR3101000101] | AH13: 통안 3Y | AI13: KR3101000101 | AJ13: KR310102GE92
B14: 홍콩(항셍) | C14: FRN | D14: HSI:HSI | F14: USDHKD | H14: 1년 전 | I14: 365 | L14: =Sheet1!B17 -> 산금 1Y | N14: BONDKSDCAL05 | O14: BONDAVG16 | P14: =O14 -> BONDAVG16 | Q14: BONDHANYLD421 | S14: 1년이하(당일) | AB14: {=INDEX($N14:$P14, 1, $H$3)} -> BONDAVG16 | AC14: =CHOOSE($H$3, "대표수익률", data!$S14, data!$S14) -> 1년이하(당일) | AD14: {=_xll.IMDP("IR", $AB14, $AC14, $AD$3)} -> 2.802
B15: 홍콩(항셍H) | C15: FRN | D15: HSI:HSCE | F15: USDHKD | L15: =Sheet1!B18 -> 회사채 AA- | N15: BONDKSDCAL07 | O15: BONDAVG58 | P15: =O15 -> BONDAVG58 | Q15: BONDHANYLD615 | S15: 3년이하(당일) | AB15: {=INDEX($N15:$P15, 1, $H$3)} -> BONDAVG58 | AC15: =CHOOSE($H$3, "대표수익률", data!$S15, data!$S15) -> 3년이하(당일) | AD15: {=_xll.IMDP("IR", $AB15, $AC15, $AD$3)} -> 3.175
B16: 대만 | C16: FRN | D16: TWS:TI01 | E16: TW | F16: USDTWD | H16: 4 | I16: {=INDEX($I$17:$I$21, $H$16)} -> 10Y | L16: =Sheet1!B19 -> CD 91D | N16: BONDKSDCAL08 | Q16: BONDHANYLD920 | AB16: =N16 -> BONDKSDCAL08 | AC16: 대표수익률 | AD16: {=_xll.IMDP("IR", $AB16, $AC16, $AD$3)} -> 2.84
B17: 유로스톡스 | C17: FRN | D17: STX:SX5E | E17: EU | F17: EURUSD | H17: 2Y | I17: 02Y | L17: =Sheet1!B20 -> CP 91D | N17: BONDKSDCAL09 | Q17: BONDHANYLD720 | AB17: =N17 -> BONDKSDCAL09 | AC17: 대표수익률 | AD17: {=_xll.IMDP("IR", $AB17, $AC17, $AD$3)} -> 3.07
B18: 독일 | C18: FRN | D18: XTR:DAX30 | E18: DE | F18: EURUSD | H18: 3Y | I18: 03Y | L18: =Sheet1!B21 -> 코리보 6M | P18: IBRKRWFIX06M | AB18: =P18 -> IBRKRWFIX06M | AC18: 금리 | AD18: {=_xll.IMDP("IR", $AB18, $AC18, $AD$3)} -> 2.88
B19: 프랑스 | C19: FRN | D19: PAS:CAC40 | E19: FR | F19: EURUSD | H19: 5Y | I19: 05Y | L19: =Sheet1!B22 -> 콜 익일 | M19: =INDEX($M$22:$M$34, MATCH(MAX($N$22:$N$34), $N$22:$N$34, 0)) -> CALLALLX01 | Q19: BONDHANYLD810 | X19: =ISNA(M19) -> FALSE | AD19: {=_xll.IMDP("ECO", "700504", "현재가", $AD$3)} -> 2.792
B20: 영국 | C20: FRN | D20: LNS:FTSE100 | E20: GB | F20: GBPUSD | H20: 10Y | I20: 10Y
B21: 스위스 | C21: FRN | D21: CHI:SSMI | F21: USDCHF | H21: 30Y | I21: 30Y
B22: 그리스 | C22: FRN | D22: GRI:ASE | E22: GR | F22: EURUSD | K22: =RANK($N22, $N$22:$N$34) -> 1 | L22: {=_xll.IMDH("IR", $M22, "합계금액", Sheet1!$B$6, Sheet1!$B$6, 1, "Per=일, Sort=D, real=true, Bizday=12, Pos=20, Orient=H")} -> 조회[CALLALLX01] | M22: CALLALLX01 | N22: 9047 | Q22: =165 & $R$25 & $S$25 -> 165W3000 | R22: =IF($R$23, RIGHT($Q$22,5), $R$24&$S$24 ) -> W3000
B23: 네덜란드 | C23: FRN | D23: NLI:AEX | E23: NL | F23: EURUSD | H23: BONDAVG01 | I23: {=INDEX($I$24:$I$28, $H$16)} -> 10년이하(당일) | K23: =RANK($N23, $N$22:$N$34) -> #N/A | L23: {=_xll.IMDH("IR", $M23, "합계금액", Sheet1!$B$6, Sheet1!$B$6, 1, "Per=일, Sort=D, real=true, Bizday=12, Pos=20, Orient=H")} -> 조회[CALLALLX02] | M23: CALLALLX02 | R23: {=_xll.IMDP("FUT", $Q$22, "최종거래일",,"DtFmt=1")>TODAY()} -> TRUE | U23: 1 | V23: =MOD(U23-1, 12)+1 -> 1 | W23: =QUOTIENT(U23-1, 12) -> 0
B24: 노르웨이 | C24: FRN | D24: NOI:OSEAX | E24: NO | F24: USDNOK | H24: =SUBSTITUTE($I$23, "당일", "전일대비") -> 10년이하(전일대비) | I24: 2년이하(당일) | K24: =RANK($N24, $N$22:$N$34) -> #N/A | L24: {=_xll.IMDH("IR", $M24, "합계금액", Sheet1!$B$6, Sheet1!$B$6, 1, "Per=일, Sort=D, real=true, Bizday=12, Pos=20, Orient=H")} -> 조회[CALLALLX03] | M24: CALLALLX03 | Q24: =MONTH(TODAY()) -> 3 | R24: {=INDEX($R$26:$R$37, MATCH($Q$25,$Q$26:$Q$37,0)+QUOTIENT($Q$24-1, 12))} -> W | S24: {=INDEX($S$26:$S$37, MOD($Q$24-1, 12)+1)} -> 3000 | U24: 2 | V24: =MOD(U24-1, 12)+1 -> 2 | W24: =QUOTIENT(U24-1, 12) -> 0
B25: 뉴질랜드 | C25: FRN | D25: DJI:DJI | E25: NZ | F25: NZDUSD | I25: 3년이하(당일) | K25: =RANK($N25, $N$22:$N$34) -> #N/A | L25: {=_xll.IMDH("IR", $M25, "합계금액", Sheet1!$B$6, Sheet1!$B$6, 1, "Per=일, Sort=D, real=true, Bizday=12, Pos=20, Orient=H")} -> 조회[CALLALLX04] | M25: CALLALLX04 | Q25: =YEAR(TODAY()) -> 2025 | R25: =INDEX($R$26:$R$37, MATCH($Q$25,$Q$26:$Q$37,0)) -> W | S25: {=INDEX($S$26:$S$37, $Q$24)} -> 3000 | U25: 3 | V25: =MOD(U25-1, 12)+1 -> 3 | W25: =QUOTIENT(U25-1, 12) -> 0
B26: 덴마크 | C26: FRN | D26: DKI:KFX | E26: DK | F26: USDDKK | I26: 5년이하(당일) | K26: =RANK($N26, $N$22:$N$34) -> #N/A | L26: {=_xll.IMDH("IR", $M26, "합계금액", Sheet1!$B$6, Sheet1!$B$6, 1, "Per=일, Sort=D, real=true, Bizday=12, Pos=20, Orient=H")} -> 조회[CALLALLX05] | M26: CALLALLX05 | Q26: 2025 | R26: W | S26: 3000 | U26: 4 | V26: =MOD(U26-1, 12)+1 -> 4 | W26: =QUOTIENT(U26-1, 12) -> 0
B27: 러시아 | C27: FRN | D27: RUI:RTSI | F27: USDRUB | I27: 10년이하(당일) | K27: =RANK($N27, $N$22:$N$34) -> #N/A | L27: {=_xll.IMDH("IR", $M27, "합계금액", Sheet1!$B$6, Sheet1!$B$6, 1, "Per=일, Sort=D, real=true, Bizday=12, Pos=20, Orient=H")} -> 조회[CALLALLX06] | M27: CALLALLX06 | Q27: 2026 | R27: 6 | S27: 3000 | U27: 5 | V27: =MOD(U27-1, 12)+1 -> 5 | W27: =QUOTIENT(U27-1, 12) -> 0
B28: 베트남 | C28: FRN | D28: VNI:VIDX | F28: USDVND | I28: 30년이하(당일) | K28: =RANK($N28, $N$22:$N$34) -> #N/A | L28: {=_xll.IMDH("IR", $M28, "합계금액", Sheet1!$B$6, Sheet1!$B$6, 1, "Per=일, Sort=D, real=true, Bizday=12, Pos=20, Orient=H")} -> 조회[CALLALLX07] | M28: CALLALLX07 | Q28: 2027 | R28: 7 | S28: 3000 | U28: 6 | V28: =MOD(U28-1, 12)+1 -> 6 | W28: =QUOTIENT(U28-1, 12) -> 0
B29: 벨기에 | C29: FRN | D29: BEI:MFX | E29: BE | F29: EURUSD | K29: =RANK($N29, $N$22:$N$34) -> #N/A | L29: {=_xll.IMDH("IR", $M29, "합계금액", Sheet1!$B$6, Sheet1!$B$6, 1, "Per=일, Sort=D, real=true, Bizday=12, Pos=20, Orient=H")} -> 조회[CALLALLX08] | M29: CALLALLX08 | Q29: 2028 | R29: 8 | S29: 6000 | U29: 7 | V29: =MOD(U29-1, 12)+1 -> 7 | W29: =QUOTIENT(U29-1, 12) -> 0
B30: 브라질 | C30: FRN | D30: BRI:BVSP | E30: BR | F30: USDBRL | K30: =RANK($N30, $N$22:$N$34) -> #N/A | L30: {=_xll.IMDH("IR", $M30, "합계금액", Sheet1!$B$6, Sheet1!$B$6, 1, "Per=일, Sort=D, real=true, Bizday=12, Pos=20, Orient=H")} -> 조회[CALLALLX09] | M30: CALLALLX09 | Q30: 2029 | R30: 9 | S30: 6000 | U30: 8 | V30: =MOD(U30-1, 12)+1 -> 8 | W30: =QUOTIENT(U30-1, 12) -> 0
B31: 스웨덴 | C31: FRN | D31: SEI:SXASI | F31: USDSEK | K31: =RANK($N31, $N$22:$N$34) -> #N/A | L31: {=_xll.IMDH("IR", $M31, "합계금액", Sheet1!$B$6, Sheet1!$B$6, 1, "Per=일, Sort=D, real=true, Bizday=12, Pos=20, Orient=H")} -> 조회[CALLALLX10] | M31: CALLALLX10 | Q31: 2030 | R31: 0 | S31: 6000 | U31: 9 | V31: =MOD(U31-1, 12)+1 -> 9 | W31: =QUOTIENT(U31-1, 12) -> 0
B32: 스페인 | C32: FRN | D32: ESI:IBEX | E32: ES | F32: EURUSD | K32: =RANK($N32, $N$22:$N$34) -> #N/A | L32: {=_xll.IMDH("IR", $M32, "합계금액", Sheet1!$B$6, Sheet1!$B$6, 1, "Per=일, Sort=D, real=true, Bizday=12, Pos=20, Orient=H")} -> 조회[CALLALLX11] | M32: CALLALLX11 | Q32: 2031 | R32: 1 | S32: 9000 | U32: 10 | V32: =MOD(U32-1, 12)+1 -> 10 | W32: =QUOTIENT(U32-1, 12) -> 0
B33: 아르헨티나 | C33: FRN | D33: ARI:MERV | F33: USDARS | K33: =RANK($N33, $N$22:$N$34) -> #N/A | L33: {=_xll.IMDH("IR", $M33, "합계금액", Sheet1!$B$6, Sheet1!$B$6, 1, "Per=일, Sort=D, real=true, Bizday=12, Pos=20, Orient=H")} -> 조회[CALLALLX12] | M33: CALLALLX12 | Q33: 2032 | R33: 2 | S33: 9000 | U33: 11 | V33: =MOD(U33-1, 12)+1 -> 11 | W33: =QUOTIENT(U33-1, 12) -> 0
B34: 오스트리아 | C34: FRN | D34: ATI:ATX | F34: EURUSD | K34: =RANK($N34, $N$22:$N$34) -> #N/A | L34: {=_xll.IMDH("IR", $M34, "합계금액", Sheet1!$B$6, Sheet1!$B$6, 1, "Per=일, Sort=D, real=true, Bizday=12, Pos=20, Orient=H")} -> 조회[CALLALLX13] | M34: CALLALLX13 | Q34: 2033 | R34: 3 | S34: 9000 | U34: 12 | V34: =MOD(U34-1, 12)+1 -> 12 | W34: =QUOTIENT(U34-1, 12) -> 0
B35: 이탈리아 | C35: FRN | D35: ITI:FTSEMIB | E35: IT | F35: EURUSD | Q35: 2034 | R35: 4 | S35: C000 | U35: 13 | V35: =MOD(U35-1, 12)+1 -> 1 | W35: =QUOTIENT(U35-1, 12) -> 1
B36: 인도 | C36: FRN | D36: INI:BSE30 | E36: IN | F36: USDINR | K36: 1 | L36: =INDEX($M$22:$M$34, MATCH(K36,$K$22:$K$34,0)) -> CALLALLX01 | Q36: 2035 | R36: 5 | S36: C000
B37: 인도네시아 | C37: FRN | D37: IDI:JKSE | E37: ID | F37: USDIDR | K37: 2 | L37: =INDEX($M$22:$M$34, MATCH(K37,$K$22:$K$34,0)) -> #N/A | Q37: 2036 | R37: A | S37: C000
B38: 캐나다 | C38: FRN | D38: CAI:SPTSX | E38: CA | F38: USDCAD | K38: 3 | L38: =INDEX($M$22:$M$34, MATCH(K38,$K$22:$K$34,0)) -> #N/A
B39: 태국 | C39: FRN | D39: THI:SET | E39: TH | F39: USDTHB
B40: 터키 | C40: FRN | D40: TRI:ISE100 | E40: TR | F40: USDTRY
B41: 포르투갈 | C41: FRN | D41: PTI:PSI20 | E41: PT | F41: EURUSD | L41: =Sheet1!$B$4-1 -> 45720 | M41: {=_xll.IMDP("IR", $L$44, $M$43, $L$41, "fiil=true, disp=date, DtFmt=1")} -> 20250304
...
