Workbook

Sheet 단가계산
E2: 일일단가 금리표 (0.5단가) - 단가
E4: 1 | L4: 2 | S4: 3 | Z4: 4
B5: 1 | C5: 1 | E5: KR103503GB32 | G5: =_xll.IMDP("BND",E5,"한글종목명") -> 국고00750-2303(21-3) | L5: KR103501GAC4 | N5: =_xll.IMDP("BND",L5,"한글종목명") -> 국고00875-2312(20-8) | S5: KR103502GAC2 | U5: =_xll.IMDP("BND",S5,"한글종목명") -> 국고01500-3012(20-9) | Z5: KR103502GA91 | AB5: =_xll.IMDP("BND",Z5,"한글종목명") -> 국고01500-4009(20-7)
B6: 2 | C6: 1 | E6: 만 기 일 | G6: =_xll.IMDP("BND",E5,"만기일") -> 20230310 | I6: 시가평가 | L6: 만 기 일 | N6: =_xll.IMDP("BND",L5,"만기일") -> 20231210 | P6: 시가평가 | S6: 만 기 일 | U6: =_xll.IMDP("BND",S5,"만기일") -> 20301210 | W6: 시가평가 | Z6: 만 기 일 | AB6: =_xll.IMDP("BND",Z5,"만기일") -> 20400910 | AD6: 시가평가
B7: 3 | C7: 1 | E7: 결제일(당일) | G7: =TODAY() -> 44358 | L7: 결제일(당일) | N7: =TODAY() -> 44358 | S7: 결제일(당일) | U7: =TODAY() -> 44358 | Z7: 결제일(당일) | AB7: =TODAY() -> 44358
B8: 4 | C8: 1 | E8: 결제일(익일) | G8: =WORKDAY(TODAY(),1) -> 44361 | I8: =_xll.IMDP("BND",E5,INDEX(Sheet1!$B$2:$C$7,VLOOKUP(E4,$B:$C,2,0),2)) -> 1.075 | L8: 결제일(익일) | N8: =WORKDAY(TODAY(),1) -> 44361 | P8: =_xll.IMDP("BND",L5,INDEX(Sheet1!$B$2:$C$7,VLOOKUP(L4,$B:$C,2,0),2)) -> 1.18 | S8: 결제일(익일) | U8: =WORKDAY(TODAY(),1) -> 44361 | W8: =_xll.IMDP("BND",S5,INDEX(Sheet1!$B$2:$C$7,VLOOKUP(S4,$B:$C,2,0),2)) -> 2.085 | Z8: 결제일(익일) | AB8: =WORKDAY(TODAY(),1) -> 44361 | AD8: =_xll.IMDP("BND",Z5,INDEX(Sheet1!$B$2:$C$7,VLOOKUP(Z4,$B:$C,2,0),2)) -> 2.192
B9: 5 | C9: 1 | E9: 수 익 률 | I9: =_xll.IMDP("BND",E5,INDEX(Sheet1!$B$9:$C$14,VLOOKUP(E4,$B:$C,2,0),2)) -> 9962.66 | L9: 수 익 률 | P9: =_xll.IMDP("BND",L5,INDEX(Sheet1!$B$9:$C$14,VLOOKUP(L4,$B:$C,2,0),2)) -> 9925.23 | S9: 수 익 률 | W9: =_xll.IMDP("BND",S5,INDEX(Sheet1!$B$9:$C$14,VLOOKUP(S4,$B:$C,2,0),2)) -> 9498.72 | Z9: 수 익 률 | AD9: =_xll.IMDP("BND",Z5,INDEX(Sheet1!$B$9:$C$14,VLOOKUP(Z4,$B:$C,2,0),2)) -> 8955.81
B10: 6 | C10: 1 | E10: bp | F10: 수익률 | G10: 당일 | H10: 원 | I10: 익일 | J10: 원 | L10: bp | M10: 수익률 | N10: 당일 | O10: 원 | P10: 익일 | Q10: 원 | S10: bp | T10: 수익률 | U10: 당일 | V10: 원 | W10: 익일 | X10: 원 | Z10: bp | AA10: 수익률 | AB10: 당일 | AC10: 원 | AD10: 익일 | AE10: 원
B11: 7 | C11: 1 | E11: -15.0 | F11: =F27+E11/100 -> 0.925 | G11: =ROUNDDOWN(_xll.IMBC(E5,"세전단가",G7,F11),2) -> 9988.64 | H11: =G11-G12 -> 1.73 | I11: =ROUNDDOWN(_xll.IMBC(E5,"세전단가",G8,F11),2) -> 9989.39 | J11: =I11-I12 -> 1.72 | L11: -15.0 | M11: =M27+L11/100 -> 1.03 | N11: =ROUNDDOWN(_xll.IMBC(L5,"세전단가",N7,M11),2) -> 9962.12 | O11: =N11-N12 -> 2.46 | P11: =ROUNDDOWN(_xll.IMBC(L5,"세전단가",N8,M11),2) -> 9962.95 | Q11: =P11-P12 -> 2.44 | S11: -15.0 | T11: =T27+S11/100 -> 1.935 | U11: =ROUNDDOWN(_xll.IMBC(S5,"세전단가",U7,T11),2) -> 9624.66 | V11: =U11-U12 -> 8.45 | W11: =ROUNDDOWN(_xll.IMBC(S5,"세전단가",U8,T11),2) -> 9626.17 | X11: =W11-W12 -> 8.44 | Z11: -15.0 | AA11: =AA27+Z11/100 -> 2.042 | AB11: =ROUNDDOWN(_xll.IMBC(Z5,"세전단가",AB7,AA11),2) -> 9178.65 | AC11: =AB11-AB12 -> 15.05 | AD11: =ROUNDDOWN(_xll.IMBC(Z5,"세전단가",AB8,AA11),2) -> 9180.17 | AE11: =AD11-AD12 -> 15.04
B12: 8 | C12: 1 | E12: -14.0 | F12: =F27+E12/100 -> 0.935 | G12: =ROUNDDOWN(_xll.IMBC(E5,"세전단가",G7,F12),2) -> 9986.91 | H12: =G12-G13 -> 1.72 | I12: =ROUNDDOWN(_xll.IMBC(E5,"세전단가",G8,F12),2) -> 9987.67 | J12: =I12-I13 -> 1.72 | L12: -14.0 | M12: =M27+L12/100 -> 1.04 | N12: =ROUNDDOWN(_xll.IMBC(L5,"세전단가",N7,M12),2) -> 9959.66 | O12: =N12-N13 -> 2.45 | P12: =ROUNDDOWN(_xll.IMBC(L5,"세전단가",N8,M12),2) -> 9960.51 | Q12: =P12-P13 -> 2.45 | S12: -14.0 | T12: =T27+S12/100 -> 1.945 | U12: =ROUNDDOWN(_xll.IMBC(S5,"세전단가",U7,T12),2) -> 9616.21 | V12: =U12-U13 -> 8.45 | W12: =ROUNDDOWN(_xll.IMBC(S5,"세전단가",U8,T12),2) -> 9617.73 | X12: =W12-W13 -> 8.44 | Z12: -14.0 | AA12: =AA27+Z12/100 -> 2.052 | AB12: =ROUNDDOWN(_xll.IMBC(Z5,"세전단가",AB7,AA12),2) -> 9163.6 | AC12: =AB12-AB13 -> 15.02 | AD12: =ROUNDDOWN(_xll.IMBC(Z5,"세전단가",AB8,AA12),2) -> 9165.13 | AE12: =AD12-AD13 -> 15.02
E13: -13.0 | F13: =F27+E13/100 -> 0.945 | G13: =ROUNDDOWN(_xll.IMBC(E5,"세전단가",G7,F13),2) -> 9985.19 | H13: =G13-G14 -> 1.73 | I13: =ROUNDDOWN(_xll.IMBC(E5,"세전단가",G8,F13),2) -> 9985.95 | J13: =I13-I14 -> 1.71 | L13: -13.0 | M13: =M27+L13/100 -> 1.05 | N13: =ROUNDDOWN(_xll.IMBC(L5,"세전단가",N7,M13),2) -> 9957.21 | O13: =N13-N14 -> 2.45 | P13: =ROUNDDOWN(_xll.IMBC(L5,"세전단가",N8,M13),2) -> 9958.06 | Q13: =P13-P14 -> 2.44 | S13: -13.0 | T13: =T27+S13/100 -> 1.955 | U13: =ROUNDDOWN(_xll.IMBC(S5,"세전단가",U7,T13),2) -> 9607.76 | V13: =U13-U14 -> 8.43 | W13: =ROUNDDOWN(_xll.IMBC(S5,"세전단가",U8,T13),2) -> 9609.29 | X13: =W13-W14 -> 8.43 | Z13: -13.0 | AA13: =AA27+Z13/100 -> 2.062 | AB13: =ROUNDDOWN(_xll.IMBC(Z5,"세전단가",AB7,AA13),2) -> 9148.58 | AC13: =AB13-AB14 -> 15 | AD13: =ROUNDDOWN(_xll.IMBC(Z5,"세전단가",AB8,AA13),2) -> 9150.11 | AE13: =AD13-AD14 -> 14.99
E14: -12.0 | F14: =F27+E14/100 -> 0.955 | G14: =ROUNDDOWN(_xll.IMBC(E5,"세전단가",G7,F14),2) -> 9983.46 | H14: =G14-G15 -> 1.73 | I14: =ROUNDDOWN(_xll.IMBC(E5,"세전단가",G8,F14),2) -> 9984.24 | J14: =I14-I15 -> 1.72 | L14: -12.0 | M14: =M27+L14/100 -> 1.06 | N14: =ROUNDDOWN(_xll.IMBC(L5,"세전단가",N7,M14),2) -> 9954.76 | O14: =N14-N15 -> 2.45 | P14: =ROUNDDOWN(_xll.IMBC(L5,"세전단가",N8,M14),2) -> 9955.62 | Q14: =P14-P15 -> 2.44 | S14: -12.0 | T14: =T27+S14/100 -> 1.965 | U14: =ROUNDDOWN(_xll.IMBC(S5,"세전단가",U7,T14),2) -> 9599.33 | V14: =U14-U15 -> 8.43 | W14: =ROUNDDOWN(_xll.IMBC(S5,"세전단가",U8,T14),2) -> 9600.86 | X14: =W14-W15 -> 8.42 | Z14: -12.0 | AA14: =AA27+Z14/100 -> 2.072 | AB14: =ROUNDDOWN(_xll.IMBC(Z5,"세전단가",AB7,AA14),2) -> 9133.58 | AC14: =AB14-AB15 -> 14.96 | AD14: =ROUNDDOWN(_xll.IMBC(Z5,"세전단가",AB8,AA14),2) -> 9135.12 | AE14: =AD14-AD15 -> 14.96
E15: -11.0 | F15: =F27+E15/100 -> 0.965 | G15: =ROUNDDOWN(_xll.IMBC(E5,"세전단가",G7,F15),2) -> 9981.73 | H15: =G15-G16 -> 1.72 | I15: =ROUNDDOWN(_xll.IMBC(E5,"세전단가",G8,F15),2) -> 9982.52 | J15: =I15-I16 -> 1.72 | L15: -11.0 | M15: =M27+L15/100 -> 1.07 | N15: =ROUNDDOWN(_xll.IMBC(L5,"세전단가",N7,M15),2) -> 9952.31 | O15: =N15-N16 -> 2.45 | P15: =ROUNDDOWN(_xll.IMBC(L5,"세전단가",N8,M15),2) -> 9953.18 | Q15: =P15-P16 -> 2.45 | S15: -11.0 | T15: =T27+S15/100 -> 1.975 | U15: =ROUNDDOWN(_xll.IMBC(S5,"세전단가",U7,T15),2) -> 9590.9 | V15: =U15-U16 -> 8.42 | W15: =ROUNDDOWN(_xll.IMBC(S5,"세전단가",U8,T15),2) -> 9592.44 | X15: =W15-W16 -> 8.42 | Z15: -11.0 | AA15: =AA27+Z15/100 -> 2.082 | AB15: =ROUNDDOWN(_xll.IMBC(Z5,"세전단가",AB7,AA15),2) -> 9118.62 | AC15: =AB15-AB16 -> 14.94 | AD15: =ROUNDDOWN(_xll.IMBC(Z5,"세전단가",AB8,AA15),2) -> 9120.16 | AE15: =AD15-AD16 -> 14.94
E16: -10.0 | F16: =F27+E16/100 -> 0.975 | G16: =ROUNDDOWN(_xll.IMBC(E5,"세전단가",G7,F16),2) -> 9980.01 | H16: =G16-G17 -> 1.73 | I16: =ROUNDDOWN(_xll.IMBC(E5,"세전단가",G8,F16),2) -> 9980.8 | J16: =I16-I17 -> 1.72 | L16: -10.0 | M16: =M27+L16/100 -> 1.08 | N16: =ROUNDDOWN(_xll.IMBC(L5,"세전단가",N7,M16),2) -> 9949.86 | O16: =N16-N17 -> 2.45 | P16: =ROUNDDOWN(_xll.IMBC(L5,"세전단가",N8,M16),2) -> 9950.73 | Q16: =P16-P17 -> 2.44 | S16: -10.0 | T16: =T27+S16/100 -> 1.985 | U16: =ROUNDDOWN(_xll.IMBC(S5,"세전단가",U7,T16),2) -> 9582.48 | V16: =U16-U17 -> 8.41 | W16: =ROUNDDOWN(_xll.IMBC(S5,"세전단가",U8,T16),2) -> 9584.02 | X16: =W16-W17 -> 8.4 | Z16: -10.0 | AA16: =AA27+Z16/100 -> 2.092 | AB16: =ROUNDDOWN(_xll.IMBC(Z5,"세전단가",AB7,AA16),2) -> 9103.68 | AC16: =AB16-AB17 -> 14.91 | AD16: =ROUNDDOWN(_xll.IMBC(Z5,"세전단가",AB8,AA16),2) -> 9105.22 | AE16: =AD16-AD17 -> 14.9
E17: -9.0 | F17: =F27+E17/100 -> 0.985 | G17: =ROUNDDOWN(_xll.IMBC(E5,"세전단가",G7,F17),2) -> 9978.28 | H17: =G17-G18 -> 1.72 | I17: =ROUNDDOWN(_xll.IMBC(E5,"세전단가",G8,F17),2) -> 9979.08 | J17: =I17-I18 -> 1.71 | L17: -9.0 | M17: =M27+L17/100 -> 1.09 | N17: =ROUNDDOWN(_xll.IMBC(L5,"세전단가",N7,M17),2) -> 9947.41 | O17: =N17-N18 -> 2.45 | P17: =ROUNDDOWN(_xll.IMBC(L5,"세전단가",N8,M17),2) -> 9948.29 | Q17: =P17-P18 -> 2.44 | S17: -9.0 | T17: =T27+S17/100 -> 1.995 | U17: =ROUNDDOWN(_xll.IMBC(S5,"세전단가",U7,T17),2) -> 9574.07 | V17: =U17-U18 -> 8.41 | W17: =ROUNDDOWN(_xll.IMBC(S5,"세전단가",U8,T17),2) -> 9575.62 | X17: =W17-W18 -> 8.4 | Z17: -9.0 | AA17: =AA27+Z17/100 -> 2.102 | AB17: =ROUNDDOWN(_xll.IMBC(Z5,"세전단가",AB7,AA17),2) -> 9088.77 | AC17: =AB17-AB18 -> 14.89 | AD17: =ROUNDDOWN(_xll.IMBC(Z5,"세전단가",AB8,AA17),2) -> 9090.32 | AE17: =AD17-AD18 -> 14.88
E18: -8.0 | F18: =F27+E18/100 -> 0.995 | G18: =ROUNDDOWN(_xll.IMBC(E5,"세전단가",G7,F18),2) -> 9976.56 | H18: =G18-G19 -> 1.72 | I18: =ROUNDDOWN(_xll.IMBC(E5,"세전단가",G8,F18),2) -> 9977.37 | J18: =I18-I19 -> 1.72 | L18: -8.0 | M18: =M27+L18/100 -> 1.1 | N18: =ROUNDDOWN(_xll.IMBC(L5,"세전단가",N7,M18),2) -> 9944.96 | O18: =N18-N19 -> 2.45 | P18: =ROUNDDOWN(_xll.IMBC(L5,"세전단가",N8,M18),2) -> 9945.85 | Q18: =P18-P19 -> 2.44 | S18: -8.0 | T18: =T27+S18/100 -> 2.005 | U18: =ROUNDDOWN(_xll.IMBC(S5,"세전단가",U7,T18),2) -> 9565.66 | V18: =U18-U19 -> 8.39 | W18: =ROUNDDOWN(_xll.IMBC(S5,"세전단가",U8,T18),2) -> 9567.22 | X18: =W18-W19 -> 8.39 | Z18: -8.0 | AA18: =AA27+Z18/100 -> 2.112 | AB18: =ROUNDDOWN(_xll.IMBC(Z5,"세전단가",AB7,AA18),2) -> 9073.88 | AC18: =AB18-AB19 -> 14.85 | AD18: =ROUNDDOWN(_xll.IMBC(Z5,"세전단가",AB8,AA18),2) -> 9075.44 | AE18: =AD18-AD19 -> 14.85
E19: -7.0 | F19: =F27+E19/100 -> 1.005 | G19: =ROUNDDOWN(_xll.IMBC(E5,"세전단가",G7,F19),2) -> 9974.84 | H19: =G19-G20 -> 1.73 | I19: =ROUNDDOWN(_xll.IMBC(E5,"세전단가",G8,F19),2) -> 9975.65 | J19: =I19-I20 -> 1.71 | L19: -7.0 | M19: =M27+L19/100 -> 1.11 | N19: =ROUNDDOWN(_xll.IMBC(L5,"세전단가",N7,M19),2) -> 9942.51 | O19: =N19-N20 -> 2.45 | P19: =ROUNDDOWN(_xll.IMBC(L5,"세전단가",N8,M19),2) -> 9943.41 | Q19: =P19-P20 -> 2.44 | S19: -7.0 | T19: =T27+S19/100 -> 2.015 | U19: =ROUNDDOWN(_xll.IMBC(S5,"세전단가",U7,T19),2) -> 9557.27 | V19: =U19-U20 -> 8.39 | W19: =ROUNDDOWN(_xll.IMBC(S5,"세전단가",U8,T19),2) -> 9558.83 | X19: =W19-W20 -> 8.38 | Z19: -7.0 | AA19: =AA27+Z19/100 -> 2.122 | AB19: =ROUNDDOWN(_xll.IMBC(Z5,"세전단가",AB7,AA19),2) -> 9059.03 | AC19: =AB19-AB20 -> 14.83 | AD19: =ROUNDDOWN(_xll.IMBC(Z5,"세전단가",AB8,AA19),2) -> 9060.59 | AE19: =AD19-AD20 -> 14.83
E20: -6.0 | F20: =F27+E20/100 -> 1.015 | G20: =ROUNDDOWN(_xll.IMBC(E5,"세전단가",G7,F20),2) -> 9973.11 | H20: =G20-G21 -> 1.72 | I20: =ROUNDDOWN(_xll.IMBC(E5,"세전단가",G8,F20),2) -> 9973.94 | J20: =I20-I21 -> 1.72 | L20: -6.0 | M20: =M27+L20/100 -> 1.12 | N20: =ROUNDDOWN(_xll.IMBC(L5,"세전단가",N7,M20),2) -> 9940.06 | O20: =N20-N21 -> 2.44 | P20: =ROUNDDOWN(_xll.IMBC(L5,"세전단가",N8,M20),2) -> 9940.97 | Q20: =P20-P21 -> 2.44 | S20: -6.0 | T20: =T27+S20/100 -> 2.025 | U20: =ROUNDDOWN(_xll.IMBC(S5,"세전단가",U7,T20),2) -> 9548.88 | V20: =U20-U21 -> 8.38 | W20: =ROUNDDOWN(_xll.IMBC(S5,"세전단가",U8,T20),2) -> 9550.45 | X20: =W20-W21 -> 8.38 | Z20: -6.0 | AA20: =AA27+Z20/100 -> 2.132 | AB20: =ROUNDDOWN(_xll.IMBC(Z5,"세전단가",AB7,AA20),2) -> 9044.2 | AC20: =AB20-AB21 -> 14.8 | AD20: =ROUNDDOWN(_xll.IMBC(Z5,"세전단가",AB8,AA20),2) -> 9045.76 | AE20: =AD20-AD21 -> 14.79
E21: -5.0 | F21: =F27+E21/100 -> 1.025 | G21: =ROUNDDOWN(_xll.IMBC(E5,"세전단가",G7,F21),2) -> 9971.39 | H21: =G21-G22 -> 1.72 | I21: =ROUNDDOWN(_xll.IMBC(E5,"세전단가",G8,F21),2) -> 9972.22 | J21: =I21-I22 -> 1.71 | L21: -5.0 | M21: =M27+L21/100 -> 1.13 | N21: =ROUNDDOWN(_xll.IMBC(L5,"세전단가",N7,M21),2) -> 9937.62 | O21: =N21-N22 -> 2.45 | P21: =ROUNDDOWN(_xll.IMBC(L5,"세전단가",N8,M21),2) -> 9938.53 | Q21: =P21-P22 -> 2.44 | S21: -5.0 | T21: =T27+S21/100 -> 2.035 | U21: =ROUNDDOWN(_xll.IMBC(S5,"세전단가",U7,T21),2) -> 9540.5 | V21: =U21-U22 -> 8.37 | W21: =ROUNDDOWN(_xll.IMBC(S5,"세전단가",U8,T21),2) -> 9542.07 | X21: =W21-W22 -> 8.36 | Z21: -5.0 | AA21: =AA27+Z21/100 -> 2.142 | AB21: =ROUNDDOWN(_xll.IMBC(Z5,"세전단가",AB7,AA21),2) -> 9029.4 | AC21: =AB21-AB22 -> 14.77 | AD21: =ROUNDDOWN(_xll.IMBC(Z5,"세전단가",AB8,AA21),2) -> 9030.97 | AE21: =AD21-AD22 -> 14.77
E22: -4.0 | F22: =F27+E22/100 -> 1.035 | G22: =ROUNDDOWN(_xll.IMBC(E5,"세전단가",G7,F22),2) -> 9969.67 | H22: =G22-G23 -> 1.72 | I22: =ROUNDDOWN(_xll.IMBC(E5,"세전단가",G8,F22),2) -> 9970.51 | J22: =I22-I23 -> 1.72 | L22: -4.0 | M22: =M27+L22/100 -> 1.14 | N22: =ROUNDDOWN(_xll.IMBC(L5,"세전단가",N7,M22),2) -> 9935.17 | O22: =N22-N23 -> 2.44 | P22: =ROUNDDOWN(_xll.IMBC(L5,"세전단가",N8,M22),2) -> 9936.09 | Q22: =P22-P23 -> 2.43 | S22: -4.0 | T22: =T27+S22/100 -> 2.045 | U22: =ROUNDDOWN(_xll.IMBC(S5,"세전단가",U7,T22),2) -> 9532.13 | V22: =U22-U23 -> 8.37 | W22: =ROUNDDOWN(_xll.IMBC(S5,"세전단가",U8,T22),2) -> 9533.71 | X22: =W22-W23 -> 8.36 | Z22: -4.0 | AA22: =AA27+Z22/100 -> 2.152 | AB22: =ROUNDDOWN(_xll.IMBC(Z5,"세전단가",AB7,AA22),2) -> 9014.63 | AC22: =AB22-AB23 -> 14.75 | AD22: =ROUNDDOWN(_xll.IMBC(Z5,"세전단가",AB8,AA22),2) -> 9016.2 | AE22: =AD22-AD23 -> 14.74
E23: -3.0 | F23: =F27+E23/100 -> 1.045 | G23: =ROUNDDOWN(_xll.IMBC(E5,"세전단가",G7,F23),2) -> 9967.95 | H23: =G23-G24 -> 1.73 | I23: =ROUNDDOWN(_xll.IMBC(E5,"세전단가",G8,F23),2) -> 9968.79 | J23: =I23-I24 -> 1.71 | L23: -3.0 | M23: =M27+L23/100 -> 1.15 | N23: =ROUNDDOWN(_xll.IMBC(L5,"세전단가",N7,M23),2) -> 9932.73 | O23: =N23-N24 -> 2.45 | P23: =ROUNDDOWN(_xll.IMBC(L5,"세전단가",N8,M23),2) -> 9933.66 | Q23: =P23-P24 -> 2.44 | S23: -3.0 | T23: =T27+S23/100 -> 2.055 | U23: =ROUNDDOWN(_xll.IMBC(S5,"세전단가",U7,T23),2) -> 9523.76 | V23: =U23-U24 -> 8.35 | W23: =ROUNDDOWN(_xll.IMBC(S5,"세전단가",U8,T23),2) -> 9525.35 | X23: =W23-W24 -> 8.35 | Z23: -3.0 | AA23: =AA27+Z23/100 -> 2.162 | AB23: =ROUNDDOWN(_xll.IMBC(Z5,"세전단가",AB7,AA23),2) -> 8999.88 | AC23: =AB23-AB24 -> 14.72 | AD23: =ROUNDDOWN(_xll.IMBC(Z5,"세전단가",AB8,AA23),2) -> 9001.46 | AE23: =AD23-AD24 -> 14.72
E24: -2.0 | F24: =F27+E24/100 -> 1.055 | G24: =ROUNDDOWN(_xll.IMBC(E5,"세전단가",G7,F24),2) -> 9966.22 | H24: =G24-G25 -> 1.72 | I24: =ROUNDDOWN(_xll.IMBC(E5,"세전단가",G8,F24),2) -> 9967.08 | J24: =I24-I25 -> 1.72 | L24: -2.0 | M24: =M27+L24/100 -> 1.16 | N24: =ROUNDDOWN(_xll.IMBC(L5,"세전단가",N7,M24),2) -> 9930.28 | O24: =N24-N25 -> 2.44 | P24: =ROUNDDOWN(_xll.IMBC(L5,"세전단가",N8,M24),2) -> 9931.22 | Q24: =P24-P25 -> 2.44 | S24: -2.0 | T24: =T27+S24/100 -> 2.065 | U24: =ROUNDDOWN(_xll.IMBC(S5,"세전단가",U7,T24),2) -> 9515.41 | V24: =U24-U25 -> 8.35 | W24: =ROUNDDOWN(_xll.IMBC(S5,"세전단가",U8,T24),2) -> 9517 | X24: =W24-W25 -> 8.34 | Z24: -2.0 | AA24: =AA27+Z24/100 -> 2.172 | AB24: =ROUNDDOWN(_xll.IMBC(Z5,"세전단가",AB7,AA24),2) -> 8985.16 | AC24: =AB24-AB25 -> 14.69 | AD24: =ROUNDDOWN(_xll.IMBC(Z5,"세전단가",AB8,AA24),2) -> 8986.74 | AE24: =AD24-AD25 -> 14.68
E25: -1.0 | F25: =F27+E25/100 -> 1.065 | G25: =ROUNDDOWN(_xll.IMBC(E5,"세전단가",G7,F25),2) -> 9964.5 | H25: =G25-G26 -> 0.86 | I25: =ROUNDDOWN(_xll.IMBC(E5,"세전단가",G8,F25),2) -> 9965.36 | J25: =I25-I26 -> 0.85 | L25: -1.0 | M25: =M27+L25/100 -> 1.17 | N25: =ROUNDDOWN(_xll.IMBC(L5,"세전단가",N7,M25),2) -> 9927.84 | O25: =N25-N26 -> 1.22 | P25: =ROUNDDOWN(_xll.IMBC(L5,"세전단가",N8,M25),2) -> 9928.78 | Q25: =P25-P26 -> 1.21 | S25: -1.0 | T25: =T27+S25/100 -> 2.075 | U25: =ROUNDDOWN(_xll.IMBC(S5,"세전단가",U7,T25),2) -> 9507.06 | V25: =U25-U26 -> 4.17 | W25: =ROUNDDOWN(_xll.IMBC(S5,"세전단가",U8,T25),2) -> 9508.66 | X25: =W25-W26 -> 4.17 | Z25: -1.0 | AA25: =AA27+Z25/100 -> 2.182 | AB25: =ROUNDDOWN(_xll.IMBC(Z5,"세전단가",AB7,AA25),2) -> 8970.47 | AC25: =AB25-AB26 -> 7.34 | AD25: =ROUNDDOWN(_xll.IMBC(Z5,"세전단가",AB8,AA25),2) -> 8972.06 | AE25: =AD25-AD26 -> 7.34
E26: -0.5 | F26: =F27+E26/100 -> 1.07 | G26: =ROUNDDOWN(_xll.IMBC(E5,"세전단가",G7,F26),2) -> 9963.64 | H26: =G26-G27 -> 0.86 | I26: =ROUNDDOWN(_xll.IMBC(E5,"세전단가",G8,F26),2) -> 9964.51 | J26: =I26-I27 -> 0.86 | L26: -0.5 | M26: =M27+L26/100 -> 1.175 | N26: =ROUNDDOWN(_xll.IMBC(L5,"세전단가",N7,M26),2) -> 9926.62 | O26: =N26-N27 -> 1.23 | P26: =ROUNDDOWN(_xll.IMBC(L5,"세전단가",N8,M26),2) -> 9927.57 | Q26: =P26-P27 -> 1.22 | S26: -0.5 | T26: =T27+S26/100 -> 2.08 | U26: =ROUNDDOWN(_xll.IMBC(S5,"세전단가",U7,T26),2) -> 9502.89 | V26: =U26-U27 -> 4.17 | W26: =ROUNDDOWN(_xll.IMBC(S5,"세전단가",U8,T26),2) -> 9504.49 | X26: =W26-W27 -> 4.16 | Z26: -0.5 | AA26: =AA27+Z26/100 -> 2.187 | AB26: =ROUNDDOWN(_xll.IMBC(Z5,"세전단가",AB7,AA26),2) -> 8963.13 | AC26: =AB26-AB27 -> 7.32 | AD26: =ROUNDDOWN(_xll.IMBC(Z5,"세전단가",AB8,AA26),2) -> 8964.72 | AE26: =AD26-AD27 -> 7.32
E27: 0 | F27: =IF(G9="",I8,ROUNDDOWN(G9,2)) -> 1.075 | G27: =ROUNDDOWN(_xll.IMBC(E5,"세전단가",G7,F27),2) -> 9962.78 | I27: =ROUNDDOWN(_xll.IMBC(E5,"세전단가",G8,F27),2) -> 9963.65 | L27: 0 | M27: =IF(N9="",P8,ROUNDDOWN(N9,2)) -> 1.18 | N27: =ROUNDDOWN(_xll.IMBC(L5,"세전단가",N7,M27),2) -> 9925.39 | P27: =ROUNDDOWN(_xll.IMBC(L5,"세전단가",N8,M27),2) -> 9926.35 | S27: 0 | T27: =IF(U9="",W8,ROUNDDOWN(U9,2)) -> 2.085 | U27: =ROUNDDOWN(_xll.IMBC(S5,"세전단가",U7,T27),2) -> 9498.72 | W27: =ROUNDDOWN(_xll.IMBC(S5,"세전단가",U8,T27),2) -> 9500.33 | Z27: 0 | AA27: =IF(AB9="",AD8,ROUNDDOWN(AB9,2)) -> 2.192 | AB27: =ROUNDDOWN(_xll.IMBC(Z5,"세전단가",AB7,AA27),2) -> 8955.81 | AD27: =ROUNDDOWN(_xll.IMBC(Z5,"세전단가",AB8,AA27),2) -> 8957.4
E28: +0.5 | F28: =F27+E28/100 -> 1.08 | G28: =ROUNDDOWN(_xll.IMBC(E5,"세전단가",G7,F28),2) -> 9961.92 | H28: =G28-G27 -> -0.86 | I28: =ROUNDDOWN(_xll.IMBC(E5,"세전단가",G8,F28),2) -> 9962.79 | J28: =I28-I27 -> -0.86 | L28: +0.5 | M28: =M27+L28/100 -> 1.185 | N28: =ROUNDDOWN(_xll.IMBC(L5,"세전단가",N7,M28),2) -> 9924.17 | O28: =N28-N27 -> -1.22 | P28: =ROUNDDOWN(_xll.IMBC(L5,"세전단가",N8,M28),2) -> 9925.13 | Q28: =P28-P27 -> -1.22 | S28: +0.5 | T28: =T27+S28/100 -> 2.09 | U28: =ROUNDDOWN(_xll.IMBC(S5,"세전단가",U7,T28),2) -> 9494.55 | V28: =U28-U27 -> -4.17 | W28: =ROUNDDOWN(_xll.IMBC(S5,"세전단가",U8,T28),2) -> 9496.16 | X28: =W28-W27 -> -4.17 | Z28: +0.5 | AA28: =AA27+Z28/100 -> 2.197 | AB28: =ROUNDDOWN(_xll.IMBC(Z5,"세전단가",AB7,AA28),2) -> 8948.48 | AC28: =AB28-AB27 -> -7.33 | AD28: =ROUNDDOWN(_xll.IMBC(Z5,"세전단가",AB8,AA28),2) -> 8950.08 | AE28: =AD28-AD27 -> -7.32
E29: +1.0 | F29: =F27+E29/100 -> 1.085 | G29: =ROUNDDOWN(_xll.IMBC(E5,"세전단가",G7,F29),2) -> 9961.06 | H29: =G29-G28 -> -0.86 | I29: =ROUNDDOWN(_xll.IMBC(E5,"세전단가",G8,F29),2) -> 9961.94 | J29: =I29-I28 -> -0.85 | L29: +1.0 | M29: =M27+L29/100 -> 1.19 | N29: =ROUNDDOWN(_xll.IMBC(L5,"세전단가",N7,M29),2) -> 9922.95 | O29: =N29-N28 -> -1.22 | P29: =ROUNDDOWN(_xll.IMBC(L5,"세전단가",N8,M29),2) -> 9923.91 | Q29: =P29-P28 -> -1.22 | S29: +1.0 | T29: =T27+S29/100 -> 2.095 | U29: =ROUNDDOWN(_xll.IMBC(S5,"세전단가",U7,T29),2) -> 9490.39 | V29: =U29-U28 -> -4.16 | W29: =ROUNDDOWN(_xll.IMBC(S5,"세전단가",U8,T29),2) -> 9492 | X29: =W29-W28 -> -4.16 | Z29: +1.0 | AA29: =AA27+Z29/100 -> 2.202 | AB29: =ROUNDDOWN(_xll.IMBC(Z5,"세전단가",AB7,AA29),2) -> 8941.17 | AC29: =AB29-AB28 -> -7.31 | AD29: =ROUNDDOWN(_xll.IMBC(Z5,"세전단가",AB8,AA29),2) -> 8942.77 | AE29: =AD29-AD28 -> -7.31
E30: +2.0 | F30: =F27+E30/100 -> 1.095 | G30: =ROUNDDOWN(_xll.IMBC(E5,"세전단가",G7,F30),2) -> 9959.34 | H30: =G30-G29 -> -1.72 | I30: =ROUNDDOWN(_xll.IMBC(E5,"세전단가",G8,F30),2) -> 9960.23 | J30: =I30-I29 -> -1.71 | L30: +2.0 | M30: =M27+L30/100 -> 1.2 | N30: =ROUNDDOWN(_xll.IMBC(L5,"세전단가",N7,M30),2) -> 9920.51 | O30: =N30-N29 -> -2.44 | P30: =ROUNDDOWN(_xll.IMBC(L5,"세전단가",N8,M30),2) -> 9921.48 | Q30: =P30-P29 -> -2.43 | S30: +2.0 | T30: =T27+S30/100 -> 2.105 | U30: =ROUNDDOWN(_xll.IMBC(S5,"세전단가",U7,T30),2) -> 9482.07 | V30: =U30-U29 -> -8.32 | W30: =ROUNDDOWN(_xll.IMBC(S5,"세전단가",U8,T30),2) -> 9483.69 | X30: =W30-W29 -> -8.31 | Z30: +2.0 | AA30: =AA27+Z30/100 -> 2.212 | AB30: =ROUNDDOWN(_xll.IMBC(Z5,"세전단가",AB7,AA30),2) -> 8926.56 | AC30: =AB30-AB29 -> -14.61 | AD30: =ROUNDDOWN(_xll.IMBC(Z5,"세전단가",AB8,AA30),2) -> 8928.16 | AE30: =AD30-AD29 -> -14.61
E31: +3.0 | F31: =F27+E31/100 -> 1.105 | G31: =ROUNDDOWN(_xll.IMBC(E5,"세전단가",G7,F31),2) -> 9957.62 | H31: =G31-G30 -> -1.72 | I31: =ROUNDDOWN(_xll.IMBC(E5,"세전단가",G8,F31),2) -> 9958.51 | J31: =I31-I30 -> -1.72 | L31: +3.0 | M31: =M27+L31/100 -> 1.21 | N31: =ROUNDDOWN(_xll.IMBC(L5,"세전단가",N7,M31),2) -> 9918.07 | O31: =N31-N30 -> -2.44 | P31: =ROUNDDOWN(_xll.IMBC(L5,"세전단가",N8,M31),2) -> 9919.05 | Q31: =P31-P30 -> -2.43 | S31: +3.0 | T31: =T27+S31/100 -> 2.115 | U31: =ROUNDDOWN(_xll.IMBC(S5,"세전단가",U7,T31),2) -> 9473.75 | V31: =U31-U30 -> -8.32 | W31: =ROUNDDOWN(_xll.IMBC(S5,"세전단가",U8,T31),2) -> 9475.38 | X31: =W31-W30 -> -8.31 | Z31: +3.0 | AA31: =AA27+Z31/100 -> 2.222 | AB31: =ROUNDDOWN(_xll.IMBC(Z5,"세전단가",AB7,AA31),2) -> 8911.98 | AC31: =AB31-AB30 -> -14.58 | AD31: =ROUNDDOWN(_xll.IMBC(Z5,"세전단가",AB8,AA31),2) -> 8913.58 | AE31: =AD31-AD30 -> -14.58
E32: +4.0 | F32: =F27+E32/100 -> 1.115 | G32: =ROUNDDOWN(_xll.IMBC(E5,"세전단가",G7,F32),2) -> 9955.9 | H32: =G32-G31 -> -1.72 | I32: =ROUNDDOWN(_xll.IMBC(E5,"세전단가",G8,F32),2) -> 9956.8 | J32: =I32-I31 -> -1.71 | L32: +4.0 | M32: =M27+L32/100 -> 1.22 | N32: =ROUNDDOWN(_xll.IMBC(L5,"세전단가",N7,M32),2) -> 9915.63 | O32: =N32-N31 -> -2.44 | P32: =ROUNDDOWN(_xll.IMBC(L5,"세전단가",N8,M32),2) -> 9916.62 | Q32: =P32-P31 -> -2.43 | S32: +4.0 | T32: =T27+S32/100 -> 2.125 | U32: =ROUNDDOWN(_xll.IMBC(S5,"세전단가",U7,T32),2) -> 9465.44 | V32: =U32-U31 -> -8.31 | W32: =ROUNDDOWN(_xll.IMBC(S5,"세전단가",U8,T32),2) -> 9467.08 | X32: =W32-W31 -> -8.3 | Z32: +4.0 | AA32: =AA27+Z32/100 -> 2.232 | AB32: =ROUNDDOWN(_xll.IMBC(Z5,"세전단가",AB7,AA32),2) -> 8897.42 | AC32: =AB32-AB31 -> -14.56 | AD32: =ROUNDDOWN(_xll.IMBC(Z5,"세전단가",AB8,AA32),2) -> 8899.03 | AE32: =AD32-AD31 -> -14.55
E33: +5.0 | F33: =F27+E33/100 -> 1.125 | G33: =ROUNDDOWN(_xll.IMBC(E5,"세전단가",G7,F33),2) -> 9954.18 | H33: =G33-G32 -> -1.72 | I33: =ROUNDDOWN(_xll.IMBC(E5,"세전단가",G8,F33),2) -> 9955.09 | J33: =I33-I32 -> -1.71 | L33: +5.0 | M33: =M27+L33/100 -> 1.23 | N33: =ROUNDDOWN(_xll.IMBC(L5,"세전단가",N7,M33),2) -> 9913.19 | O33: =N33-N32 -> -2.44 | P33: =ROUNDDOWN(_xll.IMBC(L5,"세전단가",N8,M33),2) -> 9914.18 | Q33: =P33-P32 -> -2.44 | S33: +5.0 | T33: =T27+S33/100 -> 2.135 | U33: =ROUNDDOWN(_xll.IMBC(S5,"세전단가",U7,T33),2) -> 9457.14 | V33: =U33-U32 -> -8.3 | W33: =ROUNDDOWN(_xll.IMBC(S5,"세전단가",U8,T33),2) -> 9458.78 | X33: =W33-W32 -> -8.3 | Z33: +5.0 | AA33: =AA27+Z33/100 -> 2.242 | AB33: =ROUNDDOWN(_xll.IMBC(Z5,"세전단가",AB7,AA33),2) -> 8882.89 | AC33: =AB33-AB32 -> -14.53 | AD33: =ROUNDDOWN(_xll.IMBC(Z5,"세전단가",AB8,AA33),2) -> 8884.51 | AE33: =AD33-AD32 -> -14.52
E34: +6.0 | F34: =F27+E34/100 -> 1.135 | G34: =ROUNDDOWN(_xll.IMBC(E5,"세전단가",G7,F34),2) -> 9952.46 | H34: =G34-G33 -> -1.72 | I34: =ROUNDDOWN(_xll.IMBC(E5,"세전단가",G8,F34),2) -> 9953.38 | J34: =I34-I33 -> -1.71 | L34: +6.0 | M34: =M27+L34/100 -> 1.24 | N34: =ROUNDDOWN(_xll.IMBC(L5,"세전단가",N7,M34),2) -> 9910.75 | O34: =N34-N33 -> -2.44 | P34: =ROUNDDOWN(_xll.IMBC(L5,"세전단가",N8,M34),2) -> 9911.75 | Q34: =P34-P33 -> -2.43 | S34: +6.0 | T34: =T27+S34/100 -> 2.145 | U34: =ROUNDDOWN(_xll.IMBC(S5,"세전단가",U7,T34),2) -> 9448.85 | V34: =U34-U33 -> -8.29 | W34: =ROUNDDOWN(_xll.IMBC(S5,"세전단가",U8,T34),2) -> 9450.5 | X34: =W34-W33 -> -8.28 | Z34: +6.0 | AA34: =AA27+Z34/100 -> 2.252 | AB34: =ROUNDDOWN(_xll.IMBC(Z5,"세전단가",AB7,AA34),2) -> 8868.39 | AC34: =AB34-AB33 -> -14.5 | AD34: =ROUNDDOWN(_xll.IMBC(Z5,"세전단가",AB8,AA34),2) -> 8870.01 | AE34: =AD34-AD33 -> -14.5
E35: +7.0 | F35: =F27+E35/100 -> 1.145 | G35: =ROUNDDOWN(_xll.IMBC(E5,"세전단가",G7,F35),2) -> 9950.74 | H35: =G35-G34 -> -1.72 | I35: =ROUNDDOWN(_xll.IMBC(E5,"세전단가",G8,F35),2) -> 9951.67 | J35: =I35-I34 -> -1.71 | L35: +7.0 | M35: =M27+L35/100 -> 1.25 | N35: =ROUNDDOWN(_xll.IMBC(L5,"세전단가",N7,M35),2) -> 9908.31 | O35: =N35-N34 -> -2.44 | P35: =ROUNDDOWN(_xll.IMBC(L5,"세전단가",N8,M35),2) -> 9909.32 | Q35: =P35-P34 -> -2.43 | S35: +7.0 | T35: =T27+S35/100 -> 2.155 | U35: =ROUNDDOWN(_xll.IMBC(S5,"세전단가",U7,T35),2) -> 9440.57 | V35: =U35-U34 -> -8.28 | W35: =ROUNDDOWN(_xll.IMBC(S5,"세전단가",U8,T35),2) -> 9442.22 | X35: =W35-W34 -> -8.28 | Z35: +7.0 | AA35: =AA27+Z35/100 -> 2.262 | AB35: =ROUNDDOWN(_xll.IMBC(Z5,"세전단가",AB7,AA35),2) -> 8853.92 | AC35: =AB35-AB34 -> -14.47 | AD35: =ROUNDDOWN(_xll.IMBC(Z5,"세전단가",AB8,AA35),2) -> 8855.54 | AE35: =AD35-AD34 -> -14.47
E36: +8.0 | F36: =F27+E36/100 -> 1.155 | G36: =ROUNDDOWN(_xll.IMBC(E5,"세전단가",G7,F36),2) -> 9949.02 | H36: =G36-G35 -> -1.72 | I36: =ROUNDDOWN(_xll.IMBC(E5,"세전단가",G8,F36),2) -> 9949.96 | J36: =I36-I35 -> -1.71 | L36: +8.0 | M36: =M27+L36/100 -> 1.26 | N36: =ROUNDDOWN(_xll.IMBC(L5,"세전단가",N7,M36),2) -> 9905.88 | O36: =N36-N35 -> -2.43 | P36: =ROUNDDOWN(_xll.IMBC(L5,"세전단가",N8,M36),2) -> 9906.89 | Q36: =P36-P35 -> -2.43 | S36: +8.0 | T36: =T27+S36/100 -> 2.165 | U36: =ROUNDDOWN(_xll.IMBC(S5,"세전단가",U7,T36),2) -> 9432.3 | V36: =U36-U35 -> -8.27 | W36: =ROUNDDOWN(_xll.IMBC(S5,"세전단가",U8,T36),2) -> 9433.95 | X36: =W36-W35 -> -8.27 | Z36: +8.0 | AA36: =AA27+Z36/100 -> 2.272 | AB36: =ROUNDDOWN(_xll.IMBC(Z5,"세전단가",AB7,AA36),2) -> 8839.47 | AC36: =AB36-AB35 -> -14.45 | AD36: =ROUNDDOWN(_xll.IMBC(Z5,"세전단가",AB8,AA36),2) -> 8841.1 | AE36: =AD36-AD35 -> -14.44
E37: +9.0 | F37: =F27+E37/100 -> 1.165 | G37: =ROUNDDOWN(_xll.IMBC(E5,"세전단가",G7,F37),2) -> 9947.31 | H37: =G37-G36 -> -1.71 | I37: =ROUNDDOWN(_xll.IMBC(E5,"세전단가",G8,F37),2) -> 9948.25 | J37: =I37-I36 -> -1.71 | L37: +9.0 | M37: =M27+L37/100 -> 1.27 | N37: =ROUNDDOWN(_xll.IMBC(L5,"세전단가",N7,M37),2) -> 9903.44 | O37: =N37-N36 -> -2.44 | P37: =ROUNDDOWN(_xll.IMBC(L5,"세전단가",N8,M37),2) -> 9904.46 | Q37: =P37-P36 -> -2.43 | S37: +9.0 | T37: =T27+S37/100 -> 2.175 | U37: =ROUNDDOWN(_xll.IMBC(S5,"세전단가",U7,T37),2) -> 9424.03 | V37: =U37-U36 -> -8.27 | W37: =ROUNDDOWN(_xll.IMBC(S5,"세전단가",U8,T37),2) -> 9425.69 | X37: =W37-W36 -> -8.26 | Z37: +9.0 | AA37: =AA27+Z37/100 -> 2.282 | AB37: =ROUNDDOWN(_xll.IMBC(Z5,"세전단가",AB7,AA37),2) -> 8825.05 | AC37: =AB37-AB36 -> -14.42 | AD37: =ROUNDDOWN(_xll.IMBC(Z5,"세전단가",AB8,AA37),2) -> 8826.68 | AE37: =AD37-AD36 -> -14.42
E38: +10.0 | F38: =F27+E38/100 -> 1.175 | G38: =ROUNDDOWN(_xll.IMBC(E5,"세전단가",G7,F38),2) -> 9945.59 | H38: =G38-G37 -> -1.72 | I38: =ROUNDDOWN(_xll.IMBC(E5,"세전단가",G8,F38),2) -> 9946.54 | J38: =I38-I37 -> -1.71 | L38: +10.0 | M38: =M27+L38/100 -> 1.28 | N38: =ROUNDDOWN(_xll.IMBC(L5,"세전단가",N7,M38),2) -> 9901 | O38: =N38-N37 -> -2.44 | P38: =ROUNDDOWN(_xll.IMBC(L5,"세전단가",N8,M38),2) -> 9902.04 | Q38: =P38-P37 -> -2.42 | S38: +10.0 | T38: =T27+S38/100 -> 2.185 | U38: =ROUNDDOWN(_xll.IMBC(S5,"세전단가",U7,T38),2) -> 9415.77 | V38: =U38-U37 -> -8.26 | W38: =ROUNDDOWN(_xll.IMBC(S5,"세전단가",U8,T38),2) -> 9417.44 | X38: =W38-W37 -> -8.25 | Z38: +10.0 | AA38: =AA27+Z38/100 -> 2.292 | AB38: =ROUNDDOWN(_xll.IMBC(Z5,"세전단가",AB7,AA38),2) -> 8810.65 | AC38: =AB38-AB37 -> -14.4 | AD38: =ROUNDDOWN(_xll.IMBC(Z5,"세전단가",AB8,AA38),2) -> 8812.29 | AE38: =AD38-AD37 -> -14.39
E39: +11.0 | F39: =F27+E39/100 -> 1.185 | G39: =ROUNDDOWN(_xll.IMBC(E5,"세전단가",G7,F39),2) -> 9943.87 | H39: =G39-G38 -> -1.72 | I39: =ROUNDDOWN(_xll.IMBC(E5,"세전단가",G8,F39),2) -> 9944.83 | J39: =I39-I38 -> -1.71 | L39: +11.0 | M39: =M27+L39/100 -> 1.29 | N39: =ROUNDDOWN(_xll.IMBC(L5,"세전단가",N7,M39),2) -> 9898.57 | O39: =N39-N38 -> -2.43 | P39: =ROUNDDOWN(_xll.IMBC(L5,"세전단가",N8,M39),2) -> 9899.61 | Q39: =P39-P38 -> -2.43 | S39: +11.0 | T39: =T27+S39/100 -> 2.195 | U39: =ROUNDDOWN(_xll.IMBC(S5,"세전단가",U7,T39),2) -> 9407.52 | V39: =U39-U38 -> -8.25 | W39: =ROUNDDOWN(_xll.IMBC(S5,"세전단가",U8,T39),2) -> 9409.19 | X39: =W39-W38 -> -8.25 | Z39: +11.0 | AA39: =AA27+Z39/100 -> 2.302 | AB39: =ROUNDDOWN(_xll.IMBC(Z5,"세전단가",AB7,AA39),2) -> 8796.28 | AC39: =AB39-AB38 -> -14.37 | AD39: =ROUNDDOWN(_xll.IMBC(Z5,"세전단가",AB8,AA39),2) -> 8797.93 | AE39: =AD39-AD38 -> -14.36
E40: +12.0 | F40: =F27+E40/100 -> 1.195 | G40: =ROUNDDOWN(_xll.IMBC(E5,"세전단가",G7,F40),2) -> 9942.16 | H40: =G40-G39 -> -1.71 | I40: =ROUNDDOWN(_xll.IMBC(E5,"세전단가",G8,F40),2) -> 9943.12 | J40: =I40-I39 -> -1.71 | L40: +12.0 | M40: =M27+L40/100 -> 1.3 | N40: =ROUNDDOWN(_xll.IMBC(L5,"세전단가",N7,M40),2) -> 9896.14 | O40: =N40-N39 -> -2.43 | P40: =ROUNDDOWN(_xll.IMBC(L5,"세전단가",N8,M40),2) -> 9897.18 | Q40: =P40-P39 -> -2.43 | S40: +12.0 | T40: =T27+S40/100 -> 2.205 | U40: =ROUNDDOWN(_xll.IMBC(S5,"세전단가",U7,T40),2) -> 9399.28 | V40: =U40-U39 -> -8.24 | W40: =ROUNDDOWN(_xll.IMBC(S5,"세전단가",U8,T40),2) -> 9400.96 | X40: =W40-W39 -> -8.23 | Z40: +12.0 | AA40: =AA27+Z40/100 -> 2.312 | AB40: =ROUNDDOWN(_xll.IMBC(Z5,"세전단가",AB7,AA40),2) -> 8781.94 | AC40: =AB40-AB39 -> -14.34 | AD40: =ROUNDDOWN(_xll.IMBC(Z5,"세전단가",AB8,AA40),2) -> 8783.59 | AE40: =AD40-AD39 -> -14.34
E41: +13.0 | F41: =F27+E41/100 -> 1.205 | G41: =ROUNDDOWN(_xll.IMBC(E5,"세전단가",G7,F41),2) -> 9940.44 | H41: =G41-G40 -> -1.72 | I41: =ROUNDDOWN(_xll.IMBC(E5,"세전단가",G8,F41),2) -> 9941.41 | J41: =I41-I40 -> -1.71 | L41: +13.0 | M41: =M27+L41/100 -> 1.31 | N41: =ROUNDDOWN(_xll.IMBC(L5,"세전단가",N7,M41),2) -> 9893.7 | O41: =N41-N40 -> -2.44 | P41: =ROUNDDOWN(_xll.IMBC(L5,"세전단가",N8,M41),2) -> 9894.76 | Q41: =P41-P40 -> -2.42 | S41: +13.0 | T41: =T27+S41/100 -> 2.215 | U41: =ROUNDDOWN(_xll.IMBC(S5,"세전단가",U7,T41),2) -> 9391.04 | V41: =U41-U40 -> -8.24 | W41: =ROUNDDOWN(_xll.IMBC(S5,"세전단가",U8,T41),2) -> 9392.73 | X41: =W41-W40 -> -8.23 | Z41: +13.0 | AA41: =AA27+Z41/100 -> 2.322 | AB41: =ROUNDDOWN(_xll.IMBC(Z5,"세전단가",AB7,AA41),2) -> 8767.63 | AC41: =AB41-AB40 -> -14.31 | AD41: =ROUNDDOWN(_xll.IMBC(Z5,"세전단가",AB8,AA41),2) -> 8769.28 | AE41: =AD41-AD40 -> -14.31
E42: +14.0 | F42: =F27+E42/100 -> 1.215 | G42: =ROUNDDOWN(_xll.IMBC(E5,"세전단가",G7,F42),2) -> 9938.72 | H42: =G42-G41 -> -1.72 | I42: =ROUNDDOWN(_xll.IMBC(E5,"세전단가",G8,F42),2) -> 9939.7 | J42: =I42-I41 -> -1.71 | L42: +14.0 | M42: =M27+L42/100 -> 1.32 | N42: =ROUNDDOWN(_xll.IMBC(L5,"세전단가",N7,M42),2) -> 9891.27 | O42: =N42-N41 -> -2.43 | P42: =ROUNDDOWN(_xll.IMBC(L5,"세전단가",N8,M42),2) -> 9892.33 | Q42: =P42-P41 -> -2.43 | S42: +14.0 | T42: =T27+S42/100 -> 2.225 | U42: =ROUNDDOWN(_xll.IMBC(S5,"세전단가",U7,T42),2) -> 9382.81 | V42: =U42-U41 -> -8.23 | W42: =ROUNDDOWN(_xll.IMBC(S5,"세전단가",U8,T42),2) -> 9384.51 | X42: =W42-W41 -> -8.22 | Z42: +14.0 | AA42: =AA27+Z42/100 -> 2.332 | AB42: =ROUNDDOWN(_xll.IMBC(Z5,"세전단가",AB7,AA42),2) -> 8753.34 | AC42: =AB42-AB41 -> -14.29 | AD42: =ROUNDDOWN(_xll.IMBC(Z5,"세전단가",AB8,AA42),2) -> 8755 | AE42: =AD42-AD41 -> -14.28
...

Sheet 수익률계산
E2: 일일단가 금리표 (0.5단가) - 수익률
E4: 1 | M4: 2 | U4: 3 | AC4: 4
B5: 1 | C5: 1 | E5: KR103503GB32 | G5: =_xll.IMDP("BND",E5,"한글종목명") -> 국고00750-2303(21-3) | M5: KR103501GAC4 | O5: =_xll.IMDP("BND",M5,"한글종목명") -> 국고00875-2312(20-8) | U5: KR103502GAC2 | W5: =_xll.IMDP("BND",U5,"한글종목명") -> 국고01500-3012(20-9) | AC5: KR103502GA91 | AE5: =_xll.IMDP("BND",AC5,"한글종목명") -> 국고01500-4009(20-7)
B6: 2 | C6: 1 | E6: 만기일 | G6: =_xll.IMDP("BND",E5,"만기일") -> 20230310 | I6: 기 준 | J6: 시가평가 | M6: 만기일 | O6: =_xll.IMDP("BND",M5,"만기일") -> 20231210 | Q6: 기 준 | R6: 시가평가 | U6: 만기일 | W6: =_xll.IMDP("BND",U5,"만기일") -> 20301210 | Y6: 기 준 | Z6: 시가평가 | AC6: 만기일 | AE6: =_xll.IMDP("BND",AC5,"만기일") -> 20400910 | AG6: 기 준 | AH6: 시가평가
B7: 3 | C7: 1 | E7: 결제일(당일) | G7: =TODAY() -> 44358 | I7: 수익률 | J7: 시가평가 | M7: 결제일(당일) | O7: =TODAY() -> 44358 | Q7: 수익률 | R7: 시가평가 | U7: 결제일(당일) | W7: =TODAY() -> 44358 | Y7: 수익률 | Z7: 시가평가 | AC7: 결제일(당일) | AE7: =TODAY() -> 44358 | AG7: 수익률 | AH7: 시가평가
B8: 4 | C8: 1 | E8: 결제일(익일) | G8: =WORKDAY(TODAY(),1) -> 44361 | I8: 가 격 | J8: =ROUNDDOWN(_xll.IMDP("BND",E5,INDEX(Sheet1!$B$2:$C$7,$C$5,2)),2) -> 1.07 | M8: 결제일(익일) | O8: =WORKDAY(TODAY(),1) -> 44361 | Q8: 가 격 | R8: =ROUNDDOWN(_xll.IMDP("BND",M5,INDEX(Sheet1!$B$2:$C$7,$C$5,2)),2) -> 1.18 | U8: 결제일(익일) | W8: =WORKDAY(TODAY(),1) -> 44361 | Y8: 가 격 | Z8: =ROUNDDOWN(_xll.IMDP("BND",U5,INDEX(Sheet1!$B$2:$C$7,$C$5,2)),2) -> 2.08 | AC8: 결제일(익일) | AE8: =WORKDAY(TODAY(),1) -> 44361 | AG8: 가 격 | AH8: =ROUNDDOWN(_xll.IMDP("BND",AC5,INDEX(Sheet1!$B$2:$C$7,$C$5,2)),2) -> 2.19
B9: 5 | C9: 1 | E9: 수 익 률 | J9: =ROUNDDOWN(_xll.IMDP("BND",E5,INDEX(Sheet1!$B$9:$C$14,$C$5,2)),2) -> 9962.66 | M9: 수 익 률 | R9: =ROUNDDOWN(_xll.IMDP("BND",M5,INDEX(Sheet1!$B$9:$C$14,$C$5,2)),2) -> 9925.23 | U9: 수 익 률 | Z9: =ROUNDDOWN(_xll.IMDP("BND",U5,INDEX(Sheet1!$B$9:$C$14,$C$5,2)),2) -> 9498.72 | AC9: 수 익 률 | AH9: =ROUNDDOWN(_xll.IMDP("BND",AC5,INDEX(Sheet1!$B$9:$C$14,$C$5,2)),2) -> 8955.81
B10: 6 | C10: 1 | E10: 원 | F10: 단가 | G10: 당일 | H10: bp | I10: 단가(+1일) | J10: 익일 | K10: bp | M10: 원 | N10: 단가 | O10: 당일 | P10: bp | Q10: 단가(+1일) | R10: 익일 | S10: bp | U10: 원 | V10: 단가 | W10: 당일 | X10: bp | Y10: 단가(+1일) | Z10: 익일 | AA10: bp | AC10: 원 | AD10: 단가 | AE10: 당일 | AF10: bp | AG10: 단가(+1일) | AH10: 익일 | AI10: bp
B11: 7 | C11: 1 | E11: -15.0 | F11: =F27+E11 -> 9947 | G11: =ROUNDDOWN(_xll.IMBC(E5,"세전수익률",G7,F11,"세전단가"),4) -> 1.166 | H11: =(G11-G12)*100 -> 0.6 | I11: =I27+E11 -> 9949 | J11: =ROUNDDOWN(_xll.IMBC(E5,"세전수익률",G8,F11,"세전단가"),4) -> 1.172 | K11: =(J11-J12)*100 -> 0.6 | M11: -15.0 | N11: =N27+M11 -> 9910 | O11: =ROUNDDOWN(_xll.IMBC(M5,"세전수익률",O7,N11,"세전단가"),4) -> 1.243 | P11: =(O11-O12)*100 -> 0.4 | Q11: =Q27+M11 -> 9911 | R11: =ROUNDDOWN(_xll.IMBC(M5,"세전수익률",O8,N11,"세전단가"),4) -> 1.247 | S11: =(R11-R12)*100 -> 0.4 | U11: -15.0 | V11: =V27+U11 -> 9483 | W11: =ROUNDDOWN(_xll.IMBC(U5,"세전수익률",W7,V11,"세전단가"),4) -> 2.103 | X11: =(W11-W12)*100 -> 0.1 | Y11: =Y27+U11 -> 9489 | Z11: =ROUNDDOWN(_xll.IMBC(U5,"세전수익률",W8,V11,"세전단가"),4) -> 2.105 | AA11: =(Z11-Z12)*100 -> 0.1 | AC11: -15.0 | AD11: =AD27+AC11 -> 8940 | AE11: =ROUNDDOWN(_xll.IMBC(AC5,"세전수익률",AE7,AD11,"세전단가"),4) -> 2.202 | AF11: =(AE11-AE12)*100 -> 0 | AG11: =AG27+AC11 -> 8945 | AH11: =ROUNDDOWN(_xll.IMBC(AC5,"세전수익률",AE8,AD11,"세전단가"),4) -> 2.203 | AI11: =(AH11-AH12)*100 -> 0
B12: 8 | C12: 1 | E12: -14.0 | F12: =F27+E12 -> 9948 | G12: =ROUNDDOWN(_xll.IMBC(E5,"세전수익률",G7,F12,"세전단가"),4) -> 1.16 | H12: =(G12-G13)*100 -> 0.5 | I12: =I27+E12 -> 9950 | J12: =ROUNDDOWN(_xll.IMBC(E5,"세전수익률",G8,F12,"세전단가"),4) -> 1.166 | K12: =(J12-J13)*100 -> 0.6 | M12: -14.0 | N12: =N27+M12 -> 9911 | O12: =ROUNDDOWN(_xll.IMBC(M5,"세전수익률",O7,N12,"세전단가"),4) -> 1.239 | P12: =(O12-O13)*100 -> 0.5 | Q12: =Q27+M12 -> 9912 | R12: =ROUNDDOWN(_xll.IMBC(M5,"세전수익률",O8,N12,"세전단가"),4) -> 1.243 | S12: =(R12-R13)*100 -> 0.4 | U12: -14.0 | V12: =V27+U12 -> 9484 | W12: =ROUNDDOWN(_xll.IMBC(U5,"세전수익률",W7,V12,"세전단가"),4) -> 2.102 | X12: =(W12-W13)*100 -> 0.1 | Y12: =Y27+U12 -> 9490 | Z12: =ROUNDDOWN(_xll.IMBC(U5,"세전수익률",W8,V12,"세전단가"),4) -> 2.104 | AA12: =(Z12-Z13)*100 -> 0.1 | AC12: -14.0 | AD12: =AD27+AC12 -> 8941 | AE12: =ROUNDDOWN(_xll.IMBC(AC5,"세전수익률",AE7,AD12,"세전단가"),4) -> 2.202 | AF12: =(AE12-AE13)*100 -> 0.1 | AG12: =AG27+AC12 -> 8946 | AH12: =ROUNDDOWN(_xll.IMBC(AC5,"세전수익률",AE8,AD12,"세전단가"),4) -> 2.203 | AI12: =(AH12-AH13)*100 -> 0.1
B13: 9 | E13: -13.0 | F13: =F27+E13 -> 9949 | G13: =ROUNDDOWN(_xll.IMBC(E5,"세전수익률",G7,F13,"세전단가"),4) -> 1.155 | H13: =(G13-G14)*100 -> 0.6 | I13: =I27+E13 -> 9951 | J13: =ROUNDDOWN(_xll.IMBC(E5,"세전수익률",G8,F13,"세전단가"),4) -> 1.16 | K13: =(J13-J14)*100 -> 0.6 | M13: -13.0 | N13: =N27+M13 -> 9912 | O13: =ROUNDDOWN(_xll.IMBC(M5,"세전수익률",O7,N13,"세전단가"),4) -> 1.234 | P13: =(O13-O14)*100 -> 0.4 | Q13: =Q27+M13 -> 9913 | R13: =ROUNDDOWN(_xll.IMBC(M5,"세전수익률",O8,N13,"세전단가"),4) -> 1.239 | S13: =(R13-R14)*100 -> 0.5 | U13: -13.0 | V13: =V27+U13 -> 9485 | W13: =ROUNDDOWN(_xll.IMBC(U5,"세전수익률",W7,V13,"세전단가"),4) -> 2.101 | X13: =(W13-W14)*100 -> 0.1 | Y13: =Y27+U13 -> 9491 | Z13: =ROUNDDOWN(_xll.IMBC(U5,"세전수익률",W8,V13,"세전단가"),4) -> 2.103 | AA13: =(Z13-Z14)*100 -> 0.1 | AC13: -13.0 | AD13: =AD27+AC13 -> 8942 | AE13: =ROUNDDOWN(_xll.IMBC(AC5,"세전수익률",AE7,AD13,"세전단가"),4) -> 2.201 | AF13: =(AE13-AE14)*100 -> 0.1 | AG13: =AG27+AC13 -> 8947 | AH13: =ROUNDDOWN(_xll.IMBC(AC5,"세전수익률",AE8,AD13,"세전단가"),4) -> 2.202 | AI13: =(AH13-AH14)*100 -> 0.1
B14: 10 | E14: -12.0 | F14: =F27+E14 -> 9950 | G14: =ROUNDDOWN(_xll.IMBC(E5,"세전수익률",G7,F14,"세전단가"),4) -> 1.149 | H14: =(G14-G15)*100 -> 0.6 | I14: =I27+E14 -> 9952 | J14: =ROUNDDOWN(_xll.IMBC(E5,"세전수익률",G8,F14,"세전단가"),4) -> 1.154 | K14: =(J14-J15)*100 -> 0.6 | M14: -12.0 | N14: =N27+M14 -> 9913 | O14: =ROUNDDOWN(_xll.IMBC(M5,"세전수익률",O7,N14,"세전단가"),4) -> 1.23 | P14: =(O14-O15)*100 -> 0.4 | Q14: =Q27+M14 -> 9914 | R14: =ROUNDDOWN(_xll.IMBC(M5,"세전수익률",O8,N14,"세전단가"),4) -> 1.234 | S14: =(R14-R15)*100 -> 0.4 | U14: -12.0 | V14: =V27+U14 -> 9486 | W14: =ROUNDDOWN(_xll.IMBC(U5,"세전수익률",W7,V14,"세전단가"),4) -> 2.1 | X14: =(W14-W15)*100 -> 0.1 | Y14: =Y27+U14 -> 9492 | Z14: =ROUNDDOWN(_xll.IMBC(U5,"세전수익률",W8,V14,"세전단가"),4) -> 2.102 | AA14: =(Z14-Z15)*100 -> 0.1 | AC14: -12.0 | AD14: =AD27+AC14 -> 8943 | AE14: =ROUNDDOWN(_xll.IMBC(AC5,"세전수익률",AE7,AD14,"세전단가"),4) -> 2.2 | AF14: =(AE14-AE15)*100 -> 0 | AG14: =AG27+AC14 -> 8948 | AH14: =ROUNDDOWN(_xll.IMBC(AC5,"세전수익률",AE8,AD14,"세전단가"),4) -> 2.201 | AI14: =(AH14-AH15)*100 -> 0
E15: -11.0 | F15: =F27+E15 -> 9951 | G15: =ROUNDDOWN(_xll.IMBC(E5,"세전수익률",G7,F15,"세전단가"),4) -> 1.143 | H15: =(G15-G16)*100 -> 0.6 | I15: =I27+E15 -> 9953 | J15: =ROUNDDOWN(_xll.IMBC(E5,"세전수익률",G8,F15,"세전단가"),4) -> 1.148 | K15: =(J15-J16)*100 -> 0.5 | M15: -11.0 | N15: =N27+M15 -> 9914 | O15: =ROUNDDOWN(_xll.IMBC(M5,"세전수익률",O7,N15,"세전단가"),4) -> 1.226 | P15: =(O15-O16)*100 -> 0.4 | Q15: =Q27+M15 -> 9915 | R15: =ROUNDDOWN(_xll.IMBC(M5,"세전수익률",O8,N15,"세전단가"),4) -> 1.23 | S15: =(R15-R16)*100 -> 0.4 | U15: -11.0 | V15: =V27+U15 -> 9487 | W15: =ROUNDDOWN(_xll.IMBC(U5,"세전수익률",W7,V15,"세전단가"),4) -> 2.099 | X15: =(W15-W16)*100 -> 0.2 | Y15: =Y27+U15 -> 9493 | Z15: =ROUNDDOWN(_xll.IMBC(U5,"세전수익률",W8,V15,"세전단가"),4) -> 2.101 | AA15: =(Z15-Z16)*100 -> 0.2 | AC15: -11.0 | AD15: =AD27+AC15 -> 8944 | AE15: =ROUNDDOWN(_xll.IMBC(AC5,"세전수익률",AE7,AD15,"세전단가"),4) -> 2.2 | AF15: =(AE15-AE16)*100 -> 0.1 | AG15: =AG27+AC15 -> 8949 | AH15: =ROUNDDOWN(_xll.IMBC(AC5,"세전수익률",AE8,AD15,"세전단가"),4) -> 2.201 | AI15: =(AH15-AH16)*100 -> 0.1
E16: -10.0 | F16: =F27+E16 -> 9952 | G16: =ROUNDDOWN(_xll.IMBC(E5,"세전수익률",G7,F16,"세전단가"),4) -> 1.137 | H16: =(G16-G17)*100 -> 0.6 | I16: =I27+E16 -> 9954 | J16: =ROUNDDOWN(_xll.IMBC(E5,"세전수익률",G8,F16,"세전단가"),4) -> 1.143 | K16: =(J16-J17)*100 -> 0.6 | M16: -10.0 | N16: =N27+M16 -> 9915 | O16: =ROUNDDOWN(_xll.IMBC(M5,"세전수익률",O7,N16,"세전단가"),4) -> 1.222 | P16: =(O16-O17)*100 -> 0.4 | Q16: =Q27+M16 -> 9916 | R16: =ROUNDDOWN(_xll.IMBC(M5,"세전수익률",O8,N16,"세전단가"),4) -> 1.226 | S16: =(R16-R17)*100 -> 0.4 | U16: -10.0 | V16: =V27+U16 -> 9488 | W16: =ROUNDDOWN(_xll.IMBC(U5,"세전수익률",W7,V16,"세전단가"),4) -> 2.097 | X16: =(W16-W17)*100 -> 0.1 | Y16: =Y27+U16 -> 9494 | Z16: =ROUNDDOWN(_xll.IMBC(U5,"세전수익률",W8,V16,"세전단가"),4) -> 2.099 | AA16: =(Z16-Z17)*100 -> 0.1 | AC16: -10.0 | AD16: =AD27+AC16 -> 8945 | AE16: =ROUNDDOWN(_xll.IMBC(AC5,"세전수익률",AE7,AD16,"세전단가"),4) -> 2.199 | AF16: =(AE16-AE17)*100 -> 0.1 | AG16: =AG27+AC16 -> 8950 | AH16: =ROUNDDOWN(_xll.IMBC(AC5,"세전수익률",AE8,AD16,"세전단가"),4) -> 2.2 | AI16: =(AH16-AH17)*100 -> 0.1
E17: -9.0 | F17: =F27+E17 -> 9953 | G17: =ROUNDDOWN(_xll.IMBC(E5,"세전수익률",G7,F17,"세전단가"),4) -> 1.131 | H17: =(G17-G18)*100 -> 0.5 | I17: =I27+E17 -> 9955 | J17: =ROUNDDOWN(_xll.IMBC(E5,"세전수익률",G8,F17,"세전단가"),4) -> 1.137 | K17: =(J17-J18)*100 -> 0.6 | M17: -9.0 | N17: =N27+M17 -> 9916 | O17: =ROUNDDOWN(_xll.IMBC(M5,"세전수익률",O7,N17,"세전단가"),4) -> 1.218 | P17: =(O17-O18)*100 -> 0.4 | Q17: =Q27+M17 -> 9917 | R17: =ROUNDDOWN(_xll.IMBC(M5,"세전수익률",O8,N17,"세전단가"),4) -> 1.222 | S17: =(R17-R18)*100 -> 0.4 | U17: -9.0 | V17: =V27+U17 -> 9489 | W17: =ROUNDDOWN(_xll.IMBC(U5,"세전수익률",W7,V17,"세전단가"),4) -> 2.096 | X17: =(W17-W18)*100 -> 0.1 | Y17: =Y27+U17 -> 9495 | Z17: =ROUNDDOWN(_xll.IMBC(U5,"세전수익률",W8,V17,"세전단가"),4) -> 2.098 | AA17: =(Z17-Z18)*100 -> 0.1 | AC17: -9.0 | AD17: =AD27+AC17 -> 8946 | AE17: =ROUNDDOWN(_xll.IMBC(AC5,"세전수익률",AE7,AD17,"세전단가"),4) -> 2.198 | AF17: =(AE17-AE18)*100 -> 0 | AG17: =AG27+AC17 -> 8951 | AH17: =ROUNDDOWN(_xll.IMBC(AC5,"세전수익률",AE8,AD17,"세전단가"),4) -> 2.199 | AI17: =(AH17-AH18)*100 -> 0
E18: -8.0 | F18: =F27+E18 -> 9954 | G18: =ROUNDDOWN(_xll.IMBC(E5,"세전수익률",G7,F18,"세전단가"),4) -> 1.126 | H18: =(G18-G19)*100 -> 0.6 | I18: =I27+E18 -> 9956 | J18: =ROUNDDOWN(_xll.IMBC(E5,"세전수익률",G8,F18,"세전단가"),4) -> 1.131 | K18: =(J18-J19)*100 -> 0.6 | M18: -8.0 | N18: =N27+M18 -> 9917 | O18: =ROUNDDOWN(_xll.IMBC(M5,"세전수익률",O7,N18,"세전단가"),4) -> 1.214 | P18: =(O18-O19)*100 -> 0.4 | Q18: =Q27+M18 -> 9918 | R18: =ROUNDDOWN(_xll.IMBC(M5,"세전수익률",O8,N18,"세전단가"),4) -> 1.218 | S18: =(R18-R19)*100 -> 0.4 | U18: -8.0 | V18: =V27+U18 -> 9490 | W18: =ROUNDDOWN(_xll.IMBC(U5,"세전수익률",W7,V18,"세전단가"),4) -> 2.095 | X18: =(W18-W19)*100 -> 0.1 | Y18: =Y27+U18 -> 9496 | Z18: =ROUNDDOWN(_xll.IMBC(U5,"세전수익률",W8,V18,"세전단가"),4) -> 2.097 | AA18: =(Z18-Z19)*100 -> 0.1 | AC18: -8.0 | AD18: =AD27+AC18 -> 8947 | AE18: =ROUNDDOWN(_xll.IMBC(AC5,"세전수익률",AE7,AD18,"세전단가"),4) -> 2.198 | AF18: =(AE18-AE19)*100 -> 0.1 | AG18: =AG27+AC18 -> 8952 | AH18: =ROUNDDOWN(_xll.IMBC(AC5,"세전수익률",AE8,AD18,"세전단가"),4) -> 2.199 | AI18: =(AH18-AH19)*100 -> 0.1
E19: -7.0 | F19: =F27+E19 -> 9955 | G19: =ROUNDDOWN(_xll.IMBC(E5,"세전수익률",G7,F19,"세전단가"),4) -> 1.12 | H19: =(G19-G20)*100 -> 0.6 | I19: =I27+E19 -> 9957 | J19: =ROUNDDOWN(_xll.IMBC(E5,"세전수익률",G8,F19,"세전단가"),4) -> 1.125 | K19: =(J19-J20)*100 -> 0.6 | M19: -7.0 | N19: =N27+M19 -> 9918 | O19: =ROUNDDOWN(_xll.IMBC(M5,"세전수익률",O7,N19,"세전단가"),4) -> 1.21 | P19: =(O19-O20)*100 -> 0.4 | Q19: =Q27+M19 -> 9919 | R19: =ROUNDDOWN(_xll.IMBC(M5,"세전수익률",O8,N19,"세전단가"),4) -> 1.214 | S19: =(R19-R20)*100 -> 0.4 | U19: -7.0 | V19: =V27+U19 -> 9491 | W19: =ROUNDDOWN(_xll.IMBC(U5,"세전수익률",W7,V19,"세전단가"),4) -> 2.094 | X19: =(W19-W20)*100 -> 0.1 | Y19: =Y27+U19 -> 9497 | Z19: =ROUNDDOWN(_xll.IMBC(U5,"세전수익률",W8,V19,"세전단가"),4) -> 2.096 | AA19: =(Z19-Z20)*100 -> 0.1 | AC19: -7.0 | AD19: =AD27+AC19 -> 8948 | AE19: =ROUNDDOWN(_xll.IMBC(AC5,"세전수익률",AE7,AD19,"세전단가"),4) -> 2.197 | AF19: =(AE19-AE20)*100 -> 0.1 | AG19: =AG27+AC19 -> 8953 | AH19: =ROUNDDOWN(_xll.IMBC(AC5,"세전수익률",AE8,AD19,"세전단가"),4) -> 2.198 | AI19: =(AH19-AH20)*100 -> 0.1
E20: -6.0 | F20: =F27+E20 -> 9956 | G20: =ROUNDDOWN(_xll.IMBC(E5,"세전수익률",G7,F20,"세전단가"),4) -> 1.114 | H20: =(G20-G21)*100 -> 0.6 | I20: =I27+E20 -> 9958 | J20: =ROUNDDOWN(_xll.IMBC(E5,"세전수익률",G8,F20,"세전단가"),4) -> 1.119 | K20: =(J20-J21)*100 -> 0.6 | M20: -6.0 | N20: =N27+M20 -> 9919 | O20: =ROUNDDOWN(_xll.IMBC(M5,"세전수익률",O7,N20,"세전단가"),4) -> 1.206 | P20: =(O20-O21)*100 -> 0.4 | Q20: =Q27+M20 -> 9920 | R20: =ROUNDDOWN(_xll.IMBC(M5,"세전수익률",O8,N20,"세전단가"),4) -> 1.21 | S20: =(R20-R21)*100 -> 0.4 | U20: -6.0 | V20: =V27+U20 -> 9492 | W20: =ROUNDDOWN(_xll.IMBC(U5,"세전수익률",W7,V20,"세전단가"),4) -> 2.093 | X20: =(W20-W21)*100 -> 0.2 | Y20: =Y27+U20 -> 9498 | Z20: =ROUNDDOWN(_xll.IMBC(U5,"세전수익률",W8,V20,"세전단가"),4) -> 2.095 | AA20: =(Z20-Z21)*100 -> 0.2 | AC20: -6.0 | AD20: =AD27+AC20 -> 8949 | AE20: =ROUNDDOWN(_xll.IMBC(AC5,"세전수익률",AE7,AD20,"세전단가"),4) -> 2.196 | AF20: =(AE20-AE21)*100 -> 0.1 | AG20: =AG27+AC20 -> 8954 | AH20: =ROUNDDOWN(_xll.IMBC(AC5,"세전수익률",AE8,AD20,"세전단가"),4) -> 2.197 | AI20: =(AH20-AH21)*100 -> 0
E21: -5.0 | F21: =F27+E21 -> 9957 | G21: =ROUNDDOWN(_xll.IMBC(E5,"세전수익률",G7,F21,"세전단가"),4) -> 1.108 | H21: =(G21-G22)*100 -> 0.6 | I21: =I27+E21 -> 9959 | J21: =ROUNDDOWN(_xll.IMBC(E5,"세전수익률",G8,F21,"세전단가"),4) -> 1.113 | K21: =(J21-J22)*100 -> 0.5 | M21: -5.0 | N21: =N27+M21 -> 9920 | O21: =ROUNDDOWN(_xll.IMBC(M5,"세전수익률",O7,N21,"세전단가"),4) -> 1.202 | P21: =(O21-O22)*100 -> 0.4 | Q21: =Q27+M21 -> 9921 | R21: =ROUNDDOWN(_xll.IMBC(M5,"세전수익률",O8,N21,"세전단가"),4) -> 1.206 | S21: =(R21-R22)*100 -> 0.5 | U21: -5.0 | V21: =V27+U21 -> 9493 | W21: =ROUNDDOWN(_xll.IMBC(U5,"세전수익률",W7,V21,"세전단가"),4) -> 2.091 | X21: =(W21-W22)*100 -> 0.1 | Y21: =Y27+U21 -> 9499 | Z21: =ROUNDDOWN(_xll.IMBC(U5,"세전수익률",W8,V21,"세전단가"),4) -> 2.093 | AA21: =(Z21-Z22)*100 -> 0.1 | AC21: -5.0 | AD21: =AD27+AC21 -> 8950 | AE21: =ROUNDDOWN(_xll.IMBC(AC5,"세전수익률",AE7,AD21,"세전단가"),4) -> 2.195 | AF21: =(AE21-AE22)*100 -> 0 | AG21: =AG27+AC21 -> 8955 | AH21: =ROUNDDOWN(_xll.IMBC(AC5,"세전수익률",AE8,AD21,"세전단가"),4) -> 2.197 | AI21: =(AH21-AH22)*100 -> 0.1
E22: -4.0 | F22: =F27+E22 -> 9958 | G22: =ROUNDDOWN(_xll.IMBC(E5,"세전수익률",G7,F22,"세전단가"),4) -> 1.102 | H22: =(G22-G23)*100 -> 0.5 | I22: =I27+E22 -> 9960 | J22: =ROUNDDOWN(_xll.IMBC(E5,"세전수익률",G8,F22,"세전단가"),4) -> 1.108 | K22: =(J22-J23)*100 -> 0.6 | M22: -4.0 | N22: =N27+M22 -> 9921 | O22: =ROUNDDOWN(_xll.IMBC(M5,"세전수익률",O7,N22,"세전단가"),4) -> 1.198 | P22: =(O22-O23)*100 -> 0.5 | Q22: =Q27+M22 -> 9922 | R22: =ROUNDDOWN(_xll.IMBC(M5,"세전수익률",O8,N22,"세전단가"),4) -> 1.201 | S22: =(R22-R23)*100 -> 0.4 | U22: -4.0 | V22: =V27+U22 -> 9494 | W22: =ROUNDDOWN(_xll.IMBC(U5,"세전수익률",W7,V22,"세전단가"),4) -> 2.09 | X22: =(W22-W23)*100 -> 0.1 | Y22: =Y27+U22 -> 9500 | Z22: =ROUNDDOWN(_xll.IMBC(U5,"세전수익률",W8,V22,"세전단가"),4) -> 2.092 | AA22: =(Z22-Z23)*100 -> 0.1 | AC22: -4.0 | AD22: =AD27+AC22 -> 8951 | AE22: =ROUNDDOWN(_xll.IMBC(AC5,"세전수익률",AE7,AD22,"세전단가"),4) -> 2.195 | AF22: =(AE22-AE23)*100 -> 0.1 | AG22: =AG27+AC22 -> 8956 | AH22: =ROUNDDOWN(_xll.IMBC(AC5,"세전수익률",AE8,AD22,"세전단가"),4) -> 2.196 | AI22: =(AH22-AH23)*100 -> 0.1
E23: -3.0 | F23: =F27+E23 -> 9959 | G23: =ROUNDDOWN(_xll.IMBC(E5,"세전수익률",G7,F23,"세전단가"),4) -> 1.097 | H23: =(G23-G24)*100 -> 0.6 | I23: =I27+E23 -> 9961 | J23: =ROUNDDOWN(_xll.IMBC(E5,"세전수익률",G8,F23,"세전단가"),4) -> 1.102 | K23: =(J23-J24)*100 -> 0.6 | M23: -3.0 | N23: =N27+M23 -> 9922 | O23: =ROUNDDOWN(_xll.IMBC(M5,"세전수익률",O7,N23,"세전단가"),4) -> 1.193 | P23: =(O23-O24)*100 -> 0.4 | Q23: =Q27+M23 -> 9923 | R23: =ROUNDDOWN(_xll.IMBC(M5,"세전수익률",O8,N23,"세전단가"),4) -> 1.197 | S23: =(R23-R24)*100 -> 0.4 | U23: -3.0 | V23: =V27+U23 -> 9495 | W23: =ROUNDDOWN(_xll.IMBC(U5,"세전수익률",W7,V23,"세전단가"),4) -> 2.089 | X23: =(W23-W24)*100 -> 0.1 | Y23: =Y27+U23 -> 9501 | Z23: =ROUNDDOWN(_xll.IMBC(U5,"세전수익률",W8,V23,"세전단가"),4) -> 2.091 | AA23: =(Z23-Z24)*100 -> 0.1 | AC23: -3.0 | AD23: =AD27+AC23 -> 8952 | AE23: =ROUNDDOWN(_xll.IMBC(AC5,"세전수익률",AE7,AD23,"세전단가"),4) -> 2.194 | AF23: =(AE23-AE24)*100 -> 0.1 | AG23: =AG27+AC23 -> 8957 | AH23: =ROUNDDOWN(_xll.IMBC(AC5,"세전수익률",AE8,AD23,"세전단가"),4) -> 2.195 | AI23: =(AH23-AH24)*100 -> 0
E24: -2.0 | F24: =F27+E24 -> 9960 | G24: =ROUNDDOWN(_xll.IMBC(E5,"세전수익률",G7,F24,"세전단가"),4) -> 1.091 | H24: =(G24-G25)*100 -> 0.6 | I24: =I27+E24 -> 9962 | J24: =ROUNDDOWN(_xll.IMBC(E5,"세전수익률",G8,F24,"세전단가"),4) -> 1.096 | K24: =(J24-J25)*100 -> 0.6 | M24: -2.0 | N24: =N27+M24 -> 9923 | O24: =ROUNDDOWN(_xll.IMBC(M5,"세전수익률",O7,N24,"세전단가"),4) -> 1.189 | P24: =(O24-O25)*100 -> 0.4 | Q24: =Q27+M24 -> 9924 | R24: =ROUNDDOWN(_xll.IMBC(M5,"세전수익률",O8,N24,"세전단가"),4) -> 1.193 | S24: =(R24-R25)*100 -> 0.4 | U24: -2.0 | V24: =V27+U24 -> 9496 | W24: =ROUNDDOWN(_xll.IMBC(U5,"세전수익률",W7,V24,"세전단가"),4) -> 2.088 | X24: =(W24-W25)*100 -> 0.1 | Y24: =Y27+U24 -> 9502 | Z24: =ROUNDDOWN(_xll.IMBC(U5,"세전수익률",W8,V24,"세전단가"),4) -> 2.09 | AA24: =(Z24-Z25)*100 -> 0.1 | AC24: -2.0 | AD24: =AD27+AC24 -> 8953 | AE24: =ROUNDDOWN(_xll.IMBC(AC5,"세전수익률",AE7,AD24,"세전단가"),4) -> 2.193 | AF24: =(AE24-AE25)*100 -> 0 | AG24: =AG27+AC24 -> 8958 | AH24: =ROUNDDOWN(_xll.IMBC(AC5,"세전수익률",AE8,AD24,"세전단가"),4) -> 2.195 | AI24: =(AH24-AH25)*100 -> 0.1
E25: -1.0 | F25: =F27+E25 -> 9961 | G25: =ROUNDDOWN(_xll.IMBC(E5,"세전수익률",G7,F25,"세전단가"),4) -> 1.085 | H25: =(G25-G26)*100 -> 0.3 | I25: =I27+E25 -> 9963 | J25: =ROUNDDOWN(_xll.IMBC(E5,"세전수익률",G8,F25,"세전단가"),4) -> 1.09 | K25: =(J25-J26)*100 -> 0.3 | M25: -1.0 | N25: =N27+M25 -> 9924 | O25: =ROUNDDOWN(_xll.IMBC(M5,"세전수익률",O7,N25,"세전단가"),4) -> 1.185 | P25: =(O25-O26)*100 -> 0.2 | Q25: =Q27+M25 -> 9925 | R25: =ROUNDDOWN(_xll.IMBC(M5,"세전수익률",O8,N25,"세전단가"),4) -> 1.189 | S25: =(R25-R26)*100 -> 0.2 | U25: -1.0 | V25: =V27+U25 -> 9497 | W25: =ROUNDDOWN(_xll.IMBC(U5,"세전수익률",W7,V25,"세전단가"),4) -> 2.087 | X25: =(W25-W26)*100 -> 0.1 | Y25: =Y27+U25 -> 9503 | Z25: =ROUNDDOWN(_xll.IMBC(U5,"세전수익률",W8,V25,"세전단가"),4) -> 2.089 | AA25: =(Z25-Z26)*100 -> 0.1 | AC25: -1.0 | AD25: =AD27+AC25 -> 8954 | AE25: =ROUNDDOWN(_xll.IMBC(AC5,"세전수익률",AE7,AD25,"세전단가"),4) -> 2.193 | AF25: =(AE25-AE26)*100 -> 0.1 | AG25: =AG27+AC25 -> 8959 | AH25: =ROUNDDOWN(_xll.IMBC(AC5,"세전수익률",AE8,AD25,"세전단가"),4) -> 2.194 | AI25: =(AH25-AH26)*100 -> 0.1
E26: -0.5 | F26: =F27+E26 -> 9961.5 | G26: =ROUNDDOWN(_xll.IMBC(E5,"세전수익률",G7,F26,"세전단가"),4) -> 1.082 | H26: =(G26-G27)*100 -> 0.3 | I26: =I27+E26 -> 9963.5 | J26: =ROUNDDOWN(_xll.IMBC(E5,"세전수익률",G8,F26,"세전단가"),4) -> 1.087 | K26: =(J26-J27)*100 -> 0.3 | M26: -0.5 | N26: =N27+M26 -> 9924.5 | O26: =ROUNDDOWN(_xll.IMBC(M5,"세전수익률",O7,N26,"세전단가"),4) -> 1.183 | P26: =(O26-O27)*100 -> 0.2 | Q26: =Q27+M26 -> 9925.5 | R26: =ROUNDDOWN(_xll.IMBC(M5,"세전수익률",O8,N26,"세전단가"),4) -> 1.187 | S26: =(R26-R27)*100 -> 0.2 | U26: -0.5 | V26: =V27+U26 -> 9497.5 | W26: =ROUNDDOWN(_xll.IMBC(U5,"세전수익률",W7,V26,"세전단가"),4) -> 2.086 | X26: =(W26-W27)*100 -> 0.1 | Y26: =Y27+U26 -> 9503.5 | Z26: =ROUNDDOWN(_xll.IMBC(U5,"세전수익률",W8,V26,"세전단가"),4) -> 2.088 | AA26: =(Z26-Z27)*100 -> 0.1 | AC26: -0.5 | AD26: =AD27+AC26 -> 8954.5 | AE26: =ROUNDDOWN(_xll.IMBC(AC5,"세전수익률",AE7,AD26,"세전단가"),4) -> 2.192 | AF26: =(AE26-AE27)*100 -> 0 | AG26: =AG27+AC26 -> 8959.5 | AH26: =ROUNDDOWN(_xll.IMBC(AC5,"세전수익률",AE8,AD26,"세전단가"),4) -> 2.193 | AI26: =(AH26-AH27)*100 -> 0
E27: 0 | F27: =ROUNDDOWN(_xll.IMBC(E5,"세전단가",G7,G9),0) -> 9962 | G27: =ROUNDDOWN(_xll.IMBC(E5,"세전수익률",G7,F27,"세전단가"),4) -> 1.079 | I27: =ROUNDDOWN(_xll.IMBC(E5,"세전단가",G8,J8),0) -> 9964 | J27: =ROUNDDOWN(_xll.IMBC(E5,"세전수익률",G8,F27,"세전단가"),4) -> 1.084 | M27: 0 | N27: =ROUNDDOWN(_xll.IMBC(M5,"세전단가",O7,O9),0) -> 9925 | O27: =ROUNDDOWN(_xll.IMBC(M5,"세전수익률",O7,N27,"세전단가"),4) -> 1.181 | Q27: =ROUNDDOWN(_xll.IMBC(M5,"세전단가",O8,R8),0) -> 9926 | R27: =ROUNDDOWN(_xll.IMBC(M5,"세전수익률",O8,N27,"세전단가"),4) -> 1.185 | U27: 0 | V27: =ROUNDDOWN(_xll.IMBC(U5,"세전단가",W7,W9),0) -> 9498 | W27: =ROUNDDOWN(_xll.IMBC(U5,"세전수익률",W7,V27,"세전단가"),4) -> 2.085 | Y27: =ROUNDDOWN(_xll.IMBC(U5,"세전단가",W8,Z8),0) -> 9504 | Z27: =ROUNDDOWN(_xll.IMBC(U5,"세전수익률",W8,V27,"세전단가"),4) -> 2.087 | AC27: 0 | AD27: =ROUNDDOWN(_xll.IMBC(AC5,"세전단가",AE7,AE9),0) -> 8955 | AE27: =ROUNDDOWN(_xll.IMBC(AC5,"세전수익률",AE7,AD27,"세전단가"),4) -> 2.192 | AG27: =ROUNDDOWN(_xll.IMBC(AC5,"세전단가",AE8,AH8),0) -> 8960 | AH27: =ROUNDDOWN(_xll.IMBC(AC5,"세전수익률",AE8,AD27,"세전단가"),4) -> 2.193
E28: +0.5 | F28: =F27+E28 -> 9962.5 | G28: =ROUNDDOWN(_xll.IMBC(E5,"세전수익률",G7,F28,"세전단가"),4) -> 1.076 | H28: =(G28-G27)*100 -> -0.3 | I28: =I27+E28 -> 9964.5 | J28: =ROUNDDOWN(_xll.IMBC(E5,"세전수익률",G8,F28,"세전단가"),4) -> 1.081 | K28: =J28-J27 -> -0.003 | M28: +0.5 | N28: =N27+M28 -> 9925.5 | O28: =ROUNDDOWN(_xll.IMBC(M5,"세전수익률",O7,N28,"세전단가"),4) -> 1.179 | P28: =(O28-O27)*100 -> -0.2 | Q28: =Q27+M28 -> 9926.5 | R28: =ROUNDDOWN(_xll.IMBC(M5,"세전수익률",O8,N28,"세전단가"),4) -> 1.183 | S28: =R28-R27 -> -0.002 | U28: +0.5 | V28: =V27+U28 -> 9498.5 | W28: =ROUNDDOWN(_xll.IMBC(U5,"세전수익률",W7,V28,"세전단가"),4) -> 2.085 | X28: =(W28-W27)*100 -> 0 | Y28: =Y27+U28 -> 9504.5 | Z28: =ROUNDDOWN(_xll.IMBC(U5,"세전수익률",W8,V28,"세전단가"),4) -> 2.087 | AA28: =Z28-Z27 -> 0 | AC28: +0.5 | AD28: =AD27+AC28 -> 8955.5 | AE28: =ROUNDDOWN(_xll.IMBC(AC5,"세전수익률",AE7,AD28,"세전단가"),4) -> 2.192 | AF28: =(AE28-AE27)*100 -> 0 | AG28: =AG27+AC28 -> 8960.5 | AH28: =ROUNDDOWN(_xll.IMBC(AC5,"세전수익률",AE8,AD28,"세전단가"),4) -> 2.193 | AI28: =AH28-AH27 -> 0
E29: +1.0 | F29: =F27+E29 -> 9963 | G29: =ROUNDDOWN(_xll.IMBC(E5,"세전수익률",G7,F29,"세전단가"),4) -> 1.073 | H29: =(G29-G28)*100 -> -0.3 | I29: =I27+E29 -> 9965 | J29: =ROUNDDOWN(_xll.IMBC(E5,"세전수익률",G8,F29,"세전단가"),4) -> 1.078 | K29: =J29-J28 -> -0.003 | M29: +1.0 | N29: =N27+M29 -> 9926 | O29: =ROUNDDOWN(_xll.IMBC(M5,"세전수익률",O7,N29,"세전단가"),4) -> 1.177 | P29: =(O29-O28)*100 -> -0.2 | Q29: =Q27+M29 -> 9927 | R29: =ROUNDDOWN(_xll.IMBC(M5,"세전수익률",O8,N29,"세전단가"),4) -> 1.181 | S29: =R29-R28 -> -0.002 | U29: +1.0 | V29: =V27+U29 -> 9499 | W29: =ROUNDDOWN(_xll.IMBC(U5,"세전수익률",W7,V29,"세전단가"),4) -> 2.084 | X29: =(W29-W28)*100 -> -0.1 | Y29: =Y27+U29 -> 9505 | Z29: =ROUNDDOWN(_xll.IMBC(U5,"세전수익률",W8,V29,"세전단가"),4) -> 2.086 | AA29: =Z29-Z28 -> -0.001 | AC29: +1.0 | AD29: =AD27+AC29 -> 8956 | AE29: =ROUNDDOWN(_xll.IMBC(AC5,"세전수익률",AE7,AD29,"세전단가"),4) -> 2.191 | AF29: =(AE29-AE28)*100 -> -0.1 | AG29: =AG27+AC29 -> 8961 | AH29: =ROUNDDOWN(_xll.IMBC(AC5,"세전수익률",AE8,AD29,"세전단가"),4) -> 2.192 | AI29: =AH29-AH28 -> -0.001
E30: +2.0 | F30: =F27+E30 -> 9964 | G30: =ROUNDDOWN(_xll.IMBC(E5,"세전수익률",G7,F30,"세전단가"),4) -> 1.067 | H30: =(G30-G29)*100 -> -0.6 | I30: =I27+E30 -> 9966 | J30: =ROUNDDOWN(_xll.IMBC(E5,"세전수익률",G8,F30,"세전단가"),4) -> 1.072 | K30: =J30-J29 -> -0.006 | M30: +2.0 | N30: =N27+M30 -> 9927 | O30: =ROUNDDOWN(_xll.IMBC(M5,"세전수익률",O7,N30,"세전단가"),4) -> 1.173 | P30: =(O30-O29)*100 -> -0.4 | Q30: =Q27+M30 -> 9928 | R30: =ROUNDDOWN(_xll.IMBC(M5,"세전수익률",O8,N30,"세전단가"),4) -> 1.177 | S30: =R30-R29 -> -0.004 | U30: +2.0 | V30: =V27+U30 -> 9500 | W30: =ROUNDDOWN(_xll.IMBC(U5,"세전수익률",W7,V30,"세전단가"),4) -> 2.083 | X30: =(W30-W29)*100 -> -0.1 | Y30: =Y27+U30 -> 9506 | Z30: =ROUNDDOWN(_xll.IMBC(U5,"세전수익률",W8,V30,"세전단가"),4) -> 2.085 | AA30: =Z30-Z29 -> -0.001 | AC30: +2.0 | AD30: =AD27+AC30 -> 8957 | AE30: =ROUNDDOWN(_xll.IMBC(AC5,"세전수익률",AE7,AD30,"세전단가"),4) -> 2.191 | AF30: =(AE30-AE29)*100 -> 0 | AG30: =AG27+AC30 -> 8962 | AH30: =ROUNDDOWN(_xll.IMBC(AC5,"세전수익률",AE8,AD30,"세전단가"),4) -> 2.192 | AI30: =AH30-AH29 -> 0
E31: +3.0 | F31: =F27+E31 -> 9965 | G31: =ROUNDDOWN(_xll.IMBC(E5,"세전수익률",G7,F31,"세전단가"),4) -> 1.062 | H31: =(G31-G30)*100 -> -0.5 | I31: =I27+E31 -> 9967 | J31: =ROUNDDOWN(_xll.IMBC(E5,"세전수익률",G8,F31,"세전단가"),4) -> 1.067 | K31: =J31-J30 -> -0.005 | M31: +3.0 | N31: =N27+M31 -> 9928 | O31: =ROUNDDOWN(_xll.IMBC(M5,"세전수익률",O7,N31,"세전단가"),4) -> 1.169 | P31: =(O31-O30)*100 -> -0.4 | Q31: =Q27+M31 -> 9929 | R31: =ROUNDDOWN(_xll.IMBC(M5,"세전수익률",O8,N31,"세전단가"),4) -> 1.173 | S31: =R31-R30 -> -0.004 | U31: +3.0 | V31: =V27+U31 -> 9501 | W31: =ROUNDDOWN(_xll.IMBC(U5,"세전수익률",W7,V31,"세전단가"),4) -> 2.082 | X31: =(W31-W30)*100 -> -0.1 | Y31: =Y27+U31 -> 9507 | Z31: =ROUNDDOWN(_xll.IMBC(U5,"세전수익률",W8,V31,"세전단가"),4) -> 2.084 | AA31: =Z31-Z30 -> -0.001 | AC31: +3.0 | AD31: =AD27+AC31 -> 8958 | AE31: =ROUNDDOWN(_xll.IMBC(AC5,"세전수익률",AE7,AD31,"세전단가"),4) -> 2.19 | AF31: =(AE31-AE30)*100 -> -0.1 | AG31: =AG27+AC31 -> 8963 | AH31: =ROUNDDOWN(_xll.IMBC(AC5,"세전수익률",AE8,AD31,"세전단가"),4) -> 2.191 | AI31: =AH31-AH30 -> -0.001
E32: +4.0 | F32: =F27+E32 -> 9966 | G32: =ROUNDDOWN(_xll.IMBC(E5,"세전수익률",G7,F32,"세전단가"),4) -> 1.056 | H32: =(G32-G31)*100 -> -0.6 | I32: =I27+E32 -> 9968 | J32: =ROUNDDOWN(_xll.IMBC(E5,"세전수익률",G8,F32,"세전단가"),4) -> 1.061 | K32: =J32-J31 -> -0.006 | M32: +4.0 | N32: =N27+M32 -> 9929 | O32: =ROUNDDOWN(_xll.IMBC(M5,"세전수익률",O7,N32,"세전단가"),4) -> 1.165 | P32: =(O32-O31)*100 -> -0.4 | Q32: =Q27+M32 -> 9930 | R32: =ROUNDDOWN(_xll.IMBC(M5,"세전수익률",O8,N32,"세전단가"),4) -> 1.169 | S32: =R32-R31 -> -0.004 | U32: +4.0 | V32: =V27+U32 -> 9502 | W32: =ROUNDDOWN(_xll.IMBC(U5,"세전수익률",W7,V32,"세전단가"),4) -> 2.081 | X32: =(W32-W31)*100 -> -0.1 | Y32: =Y27+U32 -> 9508 | Z32: =ROUNDDOWN(_xll.IMBC(U5,"세전수익률",W8,V32,"세전단가"),4) -> 2.082 | AA32: =Z32-Z31 -> -0.002 | AC32: +4.0 | AD32: =AD27+AC32 -> 8959 | AE32: =ROUNDDOWN(_xll.IMBC(AC5,"세전수익률",AE7,AD32,"세전단가"),4) -> 2.189 | AF32: =(AE32-AE31)*100 -> -0.1 | AG32: =AG27+AC32 -> 8964 | AH32: =ROUNDDOWN(_xll.IMBC(AC5,"세전수익률",AE8,AD32,"세전단가"),4) -> 2.19 | AI32: =AH32-AH31 -> -0.001
E33: +5.0 | F33: =F27+E33 -> 9967 | G33: =ROUNDDOWN(_xll.IMBC(E5,"세전수익률",G7,F33,"세전단가"),4) -> 1.05 | H33: =(G33-G32)*100 -> -0.6 | I33: =I27+E33 -> 9969 | J33: =ROUNDDOWN(_xll.IMBC(E5,"세전수익률",G8,F33,"세전단가"),4) -> 1.055 | K33: =J33-J32 -> -0.006 | M33: +5.0 | N33: =N27+M33 -> 9930 | O33: =ROUNDDOWN(_xll.IMBC(M5,"세전수익률",O7,N33,"세전단가"),4) -> 1.161 | P33: =(O33-O32)*100 -> -0.4 | Q33: =Q27+M33 -> 9931 | R33: =ROUNDDOWN(_xll.IMBC(M5,"세전수익률",O8,N33,"세전단가"),4) -> 1.165 | S33: =R33-R32 -> -0.004 | U33: +5.0 | V33: =V27+U33 -> 9503 | W33: =ROUNDDOWN(_xll.IMBC(U5,"세전수익률",W7,V33,"세전단가"),4) -> 2.079 | X33: =(W33-W32)*100 -> -0.2 | Y33: =Y27+U33 -> 9509 | Z33: =ROUNDDOWN(_xll.IMBC(U5,"세전수익률",W8,V33,"세전단가"),4) -> 2.081 | AA33: =Z33-Z32 -> -0.001 | AC33: +5.0 | AD33: =AD27+AC33 -> 8960 | AE33: =ROUNDDOWN(_xll.IMBC(AC5,"세전수익률",AE7,AD33,"세전단가"),4) -> 2.189 | AF33: =(AE33-AE32)*100 -> 0 | AG33: =AG27+AC33 -> 8965 | AH33: =ROUNDDOWN(_xll.IMBC(AC5,"세전수익률",AE8,AD33,"세전단가"),4) -> 2.19 | AI33: =AH33-AH32 -> 0
E34: +6.0 | F34: =F27+E34 -> 9968 | G34: =ROUNDDOWN(_xll.IMBC(E5,"세전수익률",G7,F34,"세전단가"),4) -> 1.044 | H34: =(G34-G33)*100 -> -0.6 | I34: =I27+E34 -> 9970 | J34: =ROUNDDOWN(_xll.IMBC(E5,"세전수익률",G8,F34,"세전단가"),4) -> 1.049 | K34: =J34-J33 -> -0.006 | M34: +6.0 | N34: =N27+M34 -> 9931 | O34: =ROUNDDOWN(_xll.IMBC(M5,"세전수익률",O7,N34,"세전단가"),4) -> 1.157 | P34: =(O34-O33)*100 -> -0.4 | Q34: =Q27+M34 -> 9932 | R34: =ROUNDDOWN(_xll.IMBC(M5,"세전수익률",O8,N34,"세전단가"),4) -> 1.16 | S34: =R34-R33 -> -0.005 | U34: +6.0 | V34: =V27+U34 -> 9504 | W34: =ROUNDDOWN(_xll.IMBC(U5,"세전수익률",W7,V34,"세전단가"),4) -> 2.078 | X34: =(W34-W33)*100 -> -0.1 | Y34: =Y27+U34 -> 9510 | Z34: =ROUNDDOWN(_xll.IMBC(U5,"세전수익률",W8,V34,"세전단가"),4) -> 2.08 | AA34: =Z34-Z33 -> -0.001 | AC34: +6.0 | AD34: =AD27+AC34 -> 8961 | AE34: =ROUNDDOWN(_xll.IMBC(AC5,"세전수익률",AE7,AD34,"세전단가"),4) -> 2.188 | AF34: =(AE34-AE33)*100 -> -0.1 | AG34: =AG27+AC34 -> 8966 | AH34: =ROUNDDOWN(_xll.IMBC(AC5,"세전수익률",AE8,AD34,"세전단가"),4) -> 2.189 | AI34: =AH34-AH33 -> -0.001
E35: +7.0 | F35: =F27+E35 -> 9969 | G35: =ROUNDDOWN(_xll.IMBC(E5,"세전수익률",G7,F35,"세전단가"),4) -> 1.038 | H35: =(G35-G34)*100 -> -0.6 | I35: =I27+E35 -> 9971 | J35: =ROUNDDOWN(_xll.IMBC(E5,"세전수익률",G8,F35,"세전단가"),4) -> 1.043 | K35: =J35-J34 -> -0.006 | M35: +7.0 | N35: =N27+M35 -> 9932 | O35: =ROUNDDOWN(_xll.IMBC(M5,"세전수익률",O7,N35,"세전단가"),4) -> 1.152 | P35: =(O35-O34)*100 -> -0.5 | Q35: =Q27+M35 -> 9933 | R35: =ROUNDDOWN(_xll.IMBC(M5,"세전수익률",O8,N35,"세전단가"),4) -> 1.156 | S35: =R35-R34 -> -0.004 | U35: +7.0 | V35: =V27+U35 -> 9505 | W35: =ROUNDDOWN(_xll.IMBC(U5,"세전수익률",W7,V35,"세전단가"),4) -> 2.077 | X35: =(W35-W34)*100 -> -0.1 | Y35: =Y27+U35 -> 9511 | Z35: =ROUNDDOWN(_xll.IMBC(U5,"세전수익률",W8,V35,"세전단가"),4) -> 2.079 | AA35: =Z35-Z34 -> -0.001 | AC35: +7.0 | AD35: =AD27+AC35 -> 8962 | AE35: =ROUNDDOWN(_xll.IMBC(AC5,"세전수익률",AE7,AD35,"세전단가"),4) -> 2.187 | AF35: =(AE35-AE34)*100 -> -0.1 | AG35: =AG27+AC35 -> 8967 | AH35: =ROUNDDOWN(_xll.IMBC(AC5,"세전수익률",AE8,AD35,"세전단가"),4) -> 2.188 | AI35: =AH35-AH34 -> -0.001
E36: +8.0 | F36: =F27+E36 -> 9970 | G36: =ROUNDDOWN(_xll.IMBC(E5,"세전수익률",G7,F36,"세전단가"),4) -> 1.033 | H36: =(G36-G35)*100 -> -0.5 | I36: =I27+E36 -> 9972 | J36: =ROUNDDOWN(_xll.IMBC(E5,"세전수익률",G8,F36,"세전단가"),4) -> 1.037 | K36: =J36-J35 -> -0.006 | M36: +8.0 | N36: =N27+M36 -> 9933 | O36: =ROUNDDOWN(_xll.IMBC(M5,"세전수익률",O7,N36,"세전단가"),4) -> 1.148 | P36: =(O36-O35)*100 -> -0.4 | Q36: =Q27+M36 -> 9934 | R36: =ROUNDDOWN(_xll.IMBC(M5,"세전수익률",O8,N36,"세전단가"),4) -> 1.152 | S36: =R36-R35 -> -0.004 | U36: +8.0 | V36: =V27+U36 -> 9506 | W36: =ROUNDDOWN(_xll.IMBC(U5,"세전수익률",W7,V36,"세전단가"),4) -> 2.076 | X36: =(W36-W35)*100 -> -0.1 | Y36: =Y27+U36 -> 9512 | Z36: =ROUNDDOWN(_xll.IMBC(U5,"세전수익률",W8,V36,"세전단가"),4) -> 2.078 | AA36: =Z36-Z35 -> -0.001 | AC36: +8.0 | AD36: =AD27+AC36 -> 8963 | AE36: =ROUNDDOWN(_xll.IMBC(AC5,"세전수익률",AE7,AD36,"세전단가"),4) -> 2.187 | AF36: =(AE36-AE35)*100 -> 0 | AG36: =AG27+AC36 -> 8968 | AH36: =ROUNDDOWN(_xll.IMBC(AC5,"세전수익률",AE8,AD36,"세전단가"),4) -> 2.188 | AI36: =AH36-AH35 -> 0
E37: +9.0 | F37: =F27+E37 -> 9971 | G37: =ROUNDDOWN(_xll.IMBC(E5,"세전수익률",G7,F37,"세전단가"),4) -> 1.027 | H37: =(G37-G36)*100 -> -0.6 | I37: =I27+E37 -> 9973 | J37: =ROUNDDOWN(_xll.IMBC(E5,"세전수익률",G8,F37,"세전단가"),4) -> 1.032 | K37: =J37-J36 -> -0.005 | M37: +9.0 | N37: =N27+M37 -> 9934 | O37: =ROUNDDOWN(_xll.IMBC(M5,"세전수익률",O7,N37,"세전단가"),4) -> 1.144 | P37: =(O37-O36)*100 -> -0.4 | Q37: =Q27+M37 -> 9935 | R37: =ROUNDDOWN(_xll.IMBC(M5,"세전수익률",O8,N37,"세전단가"),4) -> 1.148 | S37: =R37-R36 -> -0.004 | U37: +9.0 | V37: =V27+U37 -> 9507 | W37: =ROUNDDOWN(_xll.IMBC(U5,"세전수익률",W7,V37,"세전단가"),4) -> 2.075 | X37: =(W37-W36)*100 -> -0.1 | Y37: =Y27+U37 -> 9513 | Z37: =ROUNDDOWN(_xll.IMBC(U5,"세전수익률",W8,V37,"세전단가"),4) -> 2.076 | AA37: =Z37-Z36 -> -0.002 | AC37: +9.0 | AD37: =AD27+AC37 -> 8964 | AE37: =ROUNDDOWN(_xll.IMBC(AC5,"세전수익률",AE7,AD37,"세전단가"),4) -> 2.186 | AF37: =(AE37-AE36)*100 -> -0.1 | AG37: =AG27+AC37 -> 8969 | AH37: =ROUNDDOWN(_xll.IMBC(AC5,"세전수익률",AE8,AD37,"세전단가"),4) -> 2.187 | AI37: =AH37-AH36 -> -0.001
