Workbook

Sheet code
A1: 1 | H1: 1 | I1: 1 | J1: 1 | K1: 1 | L1: 기준 | M1: 비교 | N1: spread
A2: 3사 평균 | B2: CDYLDAVG1 | C2: CPYLDAVG1 | E2: AAA | F2: A1 | H2: 3사 평균 | I2: =CHOOSE($A$1, $E2, $F2) -> AAA | J2: =K2&"(적용일)" -> 1일(적용일) | K2: 1일 | L2: =IF( INDEX('CD|CP Matrix'!$D$8:$N$55, 6*($I$1-1)+$H$1, MATCH($K2, 'CD|CP Matrix'!$D$7:$N$7, 0) )="", NA(), INDEX('CD|CP Matrix'!$D$8:$N$55, 6*($I$1-1)+$H$1, MATCH($K2, 'CD|CP Matrix'!$D$7:$N$7, 0) ) ) -> 3.5 | M2: =_xll.IMDP("IR", INDEX($B$2:$C$49, 6*($I$1-1)+$H$1, $A$1), $J2, 'CD|CP Matrix'!$T$4, "fill=true") -> 3.35 | N2: =(L2-M2)*100 -> 15
A3: 4사 평균 | B3: CDYLDAV41 | C3: CPYLDAV41 | E3: AA+ | F3: A2+ | H3: 4사 평균 | I3: =CHOOSE($A$1, $E3, $F3) -> AA+ | J3: =K3&"(적용일)" -> 1주(적용일) | K3: 1주 | L3: =IF( INDEX('CD|CP Matrix'!$D$8:$N$55, 6*($I$1-1)+$H$1, MATCH($K3, 'CD|CP Matrix'!$D$7:$N$7, 0) )="", NA(), INDEX('CD|CP Matrix'!$D$8:$N$55, 6*($I$1-1)+$H$1, MATCH($K3, 'CD|CP Matrix'!$D$7:$N$7, 0) ) ) -> 3.56 | M3: =_xll.IMDP("IR", INDEX($B$2:$C$49, 6*($I$1-1)+$H$1, $A$1), $J3, 'CD|CP Matrix'!$T$4, "fill=true") -> 3.37 | N3: =(L3-M3)*100 -> 19
A4: KAP | B4: CDYLDKBP1 | C4: CPYLDKBP1 | E4: AA | F4: A2 | H4: KAP | I4: =CHOOSE($A$1, $E4, $F4) -> AA | J4: =K4&"(적용일)" -> 10일(적용일) | K4: 10일 | L4: =IF( INDEX('CD|CP Matrix'!$D$8:$N$55, 6*($I$1-1)+$H$1, MATCH($K4, 'CD|CP Matrix'!$D$7:$N$7, 0) )="", NA(), INDEX('CD|CP Matrix'!$D$8:$N$55, 6*($I$1-1)+$H$1, MATCH($K4, 'CD|CP Matrix'!$D$7:$N$7, 0) ) ) -> #N/A | M4: =IF( _xll.IMDP("IR", INDEX($B$2:$C$49, 6*($I$1-1)+$H$1, $A$1), $J4, 'CD|CP Matrix'!$T$4, "fill=true")=0, NA(), _xll.IMDP("IR", INDEX($B$2:$C$49, 6*($I$1-1)+$H$1, $A$1), $J4, 'CD|CP Matrix'!$T$4, "fill=true") ) -> #N/A | N4: =(L4-M4)*100 -> #N/A
A5: KIS | B5: CDYLDKIS1 | C5: CPYLDKIS1 | E5: AA- | F5: A2- | H5: KIS | I5: =CHOOSE($A$1, $E5, $F5) -> AA- | J5: =K5&"(적용일)" -> 15일(적용일) | K5: 15일 | L5: =IF( INDEX('CD|CP Matrix'!$D$8:$N$55, 6*($I$1-1)+$H$1, MATCH($K5, 'CD|CP Matrix'!$D$7:$N$7, 0) )="", NA(), INDEX('CD|CP Matrix'!$D$8:$N$55, 6*($I$1-1)+$H$1, MATCH($K5, 'CD|CP Matrix'!$D$7:$N$7, 0) ) ) -> 3.63 | M5: =_xll.IMDP("IR", INDEX($B$2:$C$49, 6*($I$1-1)+$H$1, $A$1), $J5, 'CD|CP Matrix'!$T$4, "fill=true") -> 3.38 | N5: =(L5-M5)*100 -> 25
A6: NICE | B6: CDYLDNIC1 | C6: CPYLDNIC1 | E6: A+ | F6: A3+ | H6: NICE | I6: =CHOOSE($A$1, $E6, $F6) -> A+ | J6: =K6&"(적용일)" -> 1월(적용일) | K6: 1월 | L6: =IF( INDEX('CD|CP Matrix'!$D$8:$N$55, 6*($I$1-1)+$H$1, MATCH($K6, 'CD|CP Matrix'!$D$7:$N$7, 0) )="", NA(), INDEX('CD|CP Matrix'!$D$8:$N$55, 6*($I$1-1)+$H$1, MATCH($K6, 'CD|CP Matrix'!$D$7:$N$7, 0) ) ) -> 3.69 | M6: =_xll.IMDP("IR", INDEX($B$2:$C$49, 6*($I$1-1)+$H$1, $A$1), $J6, 'CD|CP Matrix'!$T$4, "fill=true") -> 3.4 | N6: =(L6-M6)*100 -> 29
A7: FN | B7: CDYLDFNP1 | C7: CPYLDFNP1 | E7: A | F7: A3 | H7: FN | I7: =CHOOSE($A$1, $E7, $F7) -> A | J7: =K7&"(적용일)" -> 2월(적용일) | K7: 2월 | L7: =IF( INDEX('CD|CP Matrix'!$D$8:$N$55, 6*($I$1-1)+$H$1, MATCH($K7, 'CD|CP Matrix'!$D$7:$N$7, 0) )="", NA(), INDEX('CD|CP Matrix'!$D$8:$N$55, 6*($I$1-1)+$H$1, MATCH($K7, 'CD|CP Matrix'!$D$7:$N$7, 0) ) ) -> 3.72 | M7: =_xll.IMDP("IR", INDEX($B$2:$C$49, 6*($I$1-1)+$H$1, $A$1), $J7, 'CD|CP Matrix'!$T$4, "fill=true") -> 3.41 | N7: =(L7-M7)*100 -> 31
B8: CDYLDAVG2 | C8: CPYLDAVG2 | E8: A- | F8: A3- | I8: =CHOOSE($A$1, $E8, $F8) -> A- | J8: =K8&"(적용일)" -> 3월(적용일) | K8: 3월 | L8: =IF( INDEX('CD|CP Matrix'!$D$8:$N$55, 6*($I$1-1)+$H$1, MATCH($K8, 'CD|CP Matrix'!$D$7:$N$7, 0) )="", NA(), INDEX('CD|CP Matrix'!$D$8:$N$55, 6*($I$1-1)+$H$1, MATCH($K8, 'CD|CP Matrix'!$D$7:$N$7, 0) ) ) -> 3.75 | M8: =_xll.IMDP("IR", INDEX($B$2:$C$49, 6*($I$1-1)+$H$1, $A$1), $J8, 'CD|CP Matrix'!$T$4, "fill=true") -> 3.43 | N8: =(L8-M8)*100 -> 32
B9: CDYLDAV42 | C9: CPYLDAV42 | E9: BBB | I9: =CHOOSE($A$1, $E9, $F9) -> BBB | J9: =K9&"(적용일)" -> 4월(적용일) | K9: 4월 | L9: =IF( INDEX('CD|CP Matrix'!$D$8:$N$55, 6*($I$1-1)+$H$1, MATCH($K9, 'CD|CP Matrix'!$D$7:$N$7, 0) )="", NA(), INDEX('CD|CP Matrix'!$D$8:$N$55, 6*($I$1-1)+$H$1, MATCH($K9, 'CD|CP Matrix'!$D$7:$N$7, 0) ) ) -> 3.76 | M9: =_xll.IMDP("IR", INDEX($B$2:$C$49, 6*($I$1-1)+$H$1, $A$1), $J9, 'CD|CP Matrix'!$T$4, "fill=true") -> 3.45 | N9: =(L9-M9)*100 -> 31
B10: CDYLDKBP2 | C10: CPYLDKBP2 | J10: =K10&"(적용일)" -> 6월(적용일) | K10: 6월 | L10: =IF( INDEX('CD|CP Matrix'!$D$8:$N$55, 6*($I$1-1)+$H$1, MATCH($K10, 'CD|CP Matrix'!$D$7:$N$7, 0) )="", NA(), INDEX('CD|CP Matrix'!$D$8:$N$55, 6*($I$1-1)+$H$1, MATCH($K10, 'CD|CP Matrix'!$D$7:$N$7, 0) ) ) -> 3.8 | M10: =_xll.IMDP("IR", INDEX($B$2:$C$49, 6*($I$1-1)+$H$1, $A$1), $J10, 'CD|CP Matrix'!$T$4, "fill=true") -> 3.5 | N10: =(L10-M10)*100 -> 30
B11: CDYLDKIS2 | C11: CPYLDKIS2 | E11: 1 | F11: 1 | J11: =K11&"(적용일)" -> 1년(적용일) | K11: 1년 | L11: =IF( INDEX('CD|CP Matrix'!$D$8:$N$55, 6*($I$1-1)+$H$1, MATCH($K11, 'CD|CP Matrix'!$D$7:$N$7, 0) )="", NA(), INDEX('CD|CP Matrix'!$D$8:$N$55, 6*($I$1-1)+$H$1, MATCH($K11, 'CD|CP Matrix'!$D$7:$N$7, 0) ) ) -> 3.89 | M11: =_xll.IMDP("IR", INDEX($B$2:$C$49, 6*($I$1-1)+$H$1, $A$1), $J11, 'CD|CP Matrix'!$T$4, "fill=true") -> 3.72 | N11: =(L11-M11)*100 -> 17
B12: CDYLDNIC2 | C12: CPYLDNIC2 | E12: =INDEX($B$2:$C$49, 6*($F$12-1)+$F$11, $E$11) -> CDYLDAVG1 | F12: 1 | J12: =K12&"(적용일)" -> 2년(적용일) | K12: 2년 | L12: =IF( INDEX('CD|CP Matrix'!$D$8:$N$55, 6*($I$1-1)+$H$1, MATCH($K12, 'CD|CP Matrix'!$D$7:$N$7, 0) )="", NA(), INDEX('CD|CP Matrix'!$D$8:$N$55, 6*($I$1-1)+$H$1, MATCH($K12, 'CD|CP Matrix'!$D$7:$N$7, 0) ) ) -> 4.34 | M12: =_xll.IMDP("IR", INDEX($B$2:$C$49, 6*($I$1-1)+$H$1, $A$1), $J12, 'CD|CP Matrix'!$T$4, "fill=true") -> 4.13 | N12: =(L12-M12)*100 -> 21
B13: CDYLDFNP2 | C13: CPYLDFNP2 | F13: =CHOOSE($E$11, $E2, $F2) -> AAA
B14: CDYLDAVG3 | C14: CPYLDAVG3 | F14: =CHOOSE($E$11, $E3, $F3) -> AA+
B15: CDYLDAV43 | C15: CPYLDAV43 | F15: =CHOOSE($E$11, $E4, $F4) -> AA
B16: CDYLDKBP3 | C16: CPYLDKBP3 | F16: =CHOOSE($E$11, $E5, $F5) -> AA-
B17: CDYLDKIS3 | C17: CPYLDKIS3 | F17: =CHOOSE($E$11, $E6, $F6) -> A+
B18: CDYLDNIC3 | C18: CPYLDNIC3 | F18: =CHOOSE($E$11, $E7, $F7) -> A
B19: CDYLDFNP3 | C19: CPYLDFNP3 | F19: =CHOOSE($E$11, $E8, $F8) -> A-
B20: CDYLDAVG4 | C20: CPYLDAVG4 | F20: =CHOOSE($E$11, $E9, $F9) -> BBB
B21: CDYLDAV44 | C21: CPYLDAV44
B22: CDYLDKBP4 | C22: CPYLDKBP4
B23: CDYLDKIS4 | C23: CPYLDKIS4
B24: CDYLDNIC4 | C24: CPYLDNIC4
B25: CDYLDFNP4 | C25: CPYLDFNP4
B26: CDYLDAVG5 | C26: CPYLDAVG5
B27: CDYLDAV45 | C27: CPYLDAV45
B28: CDYLDKBP5 | C28: CPYLDKBP5
B29: CDYLDKIS5 | C29: CPYLDKIS5
B30: CDYLDNIC5 | C30: CPYLDNIC5
B31: CDYLDFNP5 | C31: CPYLDFNP5
B32: CDYLDAVG6 | C32: CPYLDAVG6
... B42: CDYLDNIC7 | C42: CPYLDNIC7
B43: CDYLDFNP7 | C43: CPYLDFNP7 | H43: 코드 | I43: =IF($A$51=1, $F$51, INDEX($F$52:$F$58, $E$51)) -> CRDLIST030502
B44: CDYLDAVG8 | G44: =TEXT('CD|CP 발행사'!$C$4-500,"YYYYMMDD") -> 20220226 | H44: 조회건수 | I44: 9999
B45: CDYLDAV48 | G45: =TEXT('CD|CP 발행사'!$C$4, "YYYYMMDD") -> 20230711 | H45: 일자 | I45: =$G$44&"~"&$G$45 -> 20220226~20230711
B46: CDYLDKBP8 | H46: 조회기준 | I46: =INDEX($D$52:$D$62, $D$51) -> 전체
B47: CDYLDKIS8 | H47: 정렬기준 | I47: 채권코드
B48: CDYLDNIC8 | H48: 정렬 | I48: A
B49: CDYLDFNP8 | H49: =_xll.IMDT("등급별기업",I43,H50:J50,I44,I45,I46,I47,"sort="&I48&",DtFmt=1,TmFmt=1,Pos=20,Orient=V") -> 조회[CRDLIST030502] | K49: =INDEX($E$59:$F$63, $K$50, $A$51) -> CDAVG
...

Sheet CD|CP Matrix
B2: CD/CP Matrix
B4: =TODAY() -> 45119 | M4: 데이터 일자: | N4: {=IF( _xll.IMDP("IR", CHOOSE(code!$A$1, code!$B2, code!$C2), D$6, $B$4, "fill=true, disp=date, dtfmt=1")="", $B$4, _xll.IMDP("IR", CHOOSE(code!$A$1, code!$B2, code!$C2), D$6, $B$4, "fill=true, disp=date, dtfmt=1") )} -> 45119 | S4: 비교 시점 | T4: =B4-90 -> 45029
D6: 1일(적용일) | E6: 1주(적용일) | F6: 10일(적용일) | G6: 15일(적용일) | H6: 1월(적용일) | I6: 2월(적용일) | J6: 3월(적용일) | K6: 4월(적용일) | L6: 6월(적용일) | M6: 1년(적용일) | N6: 2년(적용일)
B7: 등급 | C7: 평가사 | D7: 1일 | E7: 1주 | F7: 10일 | G7: 15일 | H7: 1월 | I7: 2월 | J7: 3월 | K7: 4월 | L7: 6월 | M7: 1년 | N7: 2년
B8: {=INDEX(code!$E$2:$F$9, 1, code!$A$1)} -> AAA | C8: 3사 평균 | D8: =_xll.IMDP("IR", CHOOSE(code!$A$1, code!$B2, code!$C2), D$6, $B$4, "fill=true") -> 3.5 | E8: =_xll.IMDP("IR", CHOOSE(code!$A$1, code!$B2, code!$C2), E$6, $B$4, "fill=true") -> 3.56 | F8: =IF( _xll.IMDP("IR", CHOOSE(code!$A$1, code!$B2, code!$C2), F$6, $B$4, "fill=true") = 0, "", _xll.IMDP("IR", CHOOSE(code!$A$1, code!$B2, code!$C2), F$6, $B$4, "fill=true") ) | G8: =_xll.IMDP("IR", CHOOSE(code!$A$1, code!$B2, code!$C2), G$6, $B$4, "fill=true") -> 3.63 | H8: =_xll.IMDP("IR", CHOOSE(code!$A$1, code!$B2, code!$C2), H$6, $B$4, "fill=true") -> 3.69 | I8: =_xll.IMDP("IR", CHOOSE(code!$A$1, code!$B2, code!$C2), I$6, $B$4, "fill=true") -> 3.72 | J8: =_xll.IMDP("IR", CHOOSE(code!$A$1, code!$B2, code!$C2), J$6, $B$4, "fill=true") -> 3.75 | K8: =_xll.IMDP("IR", CHOOSE(code!$A$1, code!$B2, code!$C2), K$6, $B$4, "fill=true") -> 3.76 | L8: =_xll.IMDP("IR", CHOOSE(code!$A$1, code!$B2, code!$C2), L$6, $B$4, "fill=true") -> 3.8 | M8: =_xll.IMDP("IR", CHOOSE(code!$A$1, code!$B2, code!$C2), M$6, $B$4, "fill=true") -> 3.89 | N8: =_xll.IMDP("IR", CHOOSE(code!$A$1, code!$B2, code!$C2), N$6, $B$4, "fill=true") -> 4.34
C9: 4사 평균 | D9: =_xll.IMDP("IR", CHOOSE(code!$A$1, code!$B3, code!$C3), D$6, $B$4, "fill=true") -> 3.51 | E9: =_xll.IMDP("IR", CHOOSE(code!$A$1, code!$B3, code!$C3), E$6, $B$4, "fill=true") -> 3.56 | F9: =IF( _xll.IMDP("IR", CHOOSE(code!$A$1, code!$B3, code!$C3), F$6, $B$4, "fill=true") = 0, "", _xll.IMDP("IR", CHOOSE(code!$A$1, code!$B3, code!$C3), F$6, $B$4, "fill=true") ) | G9: =_xll.IMDP("IR", CHOOSE(code!$A$1, code!$B3, code!$C3), G$6, $B$4, "fill=true") -> 3.63 | H9: =_xll.IMDP("IR", CHOOSE(code!$A$1, code!$B3, code!$C3), H$6, $B$4, "fill=true") -> 3.68 | I9: =_xll.IMDP("IR", CHOOSE(code!$A$1, code!$B3, code!$C3), I$6, $B$4, "fill=true") -> 3.72 | J9: =_xll.IMDP("IR", CHOOSE(code!$A$1, code!$B3, code!$C3), J$6, $B$4, "fill=true") -> 3.75 | K9: =_xll.IMDP("IR", CHOOSE(code!$A$1, code!$B3, code!$C3), K$6, $B$4, "fill=true") -> 3.76 | L9: =_xll.IMDP("IR", CHOOSE(code!$A$1, code!$B3, code!$C3), L$6, $B$4, "fill=true") -> 3.8 | M9: =_xll.IMDP("IR", CHOOSE(code!$A$1, code!$B3, code!$C3), M$6, $B$4, "fill=true") -> 3.89 | N9: =_xll.IMDP("IR", CHOOSE(code!$A$1, code!$B3, code!$C3), N$6, $B$4, "fill=true") -> 4.24
C10: KAP | D10: =_xll.IMDP("IR", CHOOSE(code!$A$1, code!$B4, code!$C4), D$6, $B$4, "fill=true") -> 3.51 | E10: =_xll.IMDP("IR", CHOOSE(code!$A$1, code!$B4, code!$C4), E$6, $B$4, "fill=true") -> 3.57 | F10: =IF( _xll.IMDP("IR", CHOOSE(code!$A$1, code!$B4, code!$C4), F$6, $B$4, "fill=true") = 0, "", _xll.IMDP("IR", CHOOSE(code!$A$1, code!$B4, code!$C4), F$6, $B$4, "fill=true") ) | G10: =_xll.IMDP("IR", CHOOSE(code!$A$1, code!$B4, code!$C4), G$6, $B$4, "fill=true") -> 3.64 | H10: =_xll.IMDP("IR", CHOOSE(code!$A$1, code!$B4, code!$C4), H$6, $B$4, "fill=true") -> 3.7 | I10: =_xll.IMDP("IR", CHOOSE(code!$A$1, code!$B4, code!$C4), I$6, $B$4, "fill=true") -> 3.73 | J10: =_xll.IMDP("IR", CHOOSE(code!$A$1, code!$B4, code!$C4), J$6, $B$4, "fill=true") -> 3.75 | K10: =_xll.IMDP("IR", CHOOSE(code!$A$1, code!$B4, code!$C4), K$6, $B$4, "fill=true") -> 3.76 | L10: =_xll.IMDP("IR", CHOOSE(code!$A$1, code!$B4, code!$C4), L$6, $B$4, "fill=true") -> 3.8 | M10: =_xll.IMDP("IR", CHOOSE(code!$A$1, code!$B4, code!$C4), M$6, $B$4, "fill=true") -> 3.89 | N10: =_xll.IMDP("IR", CHOOSE(code!$A$1, code!$B4, code!$C4), N$6, $B$4, "fill=true") -> 4.74
C11: KIS | D11: =_xll.IMDP("IR", CHOOSE(code!$A$1, code!$B5, code!$C5), D$6, $B$4, "fill=true") -> 3.51 | E11: =_xll.IMDP("IR", CHOOSE(code!$A$1, code!$B5, code!$C5), E$6, $B$4, "fill=true") -> 3.56 | F11: =IF( _xll.IMDP("IR", CHOOSE(code!$A$1, code!$B5, code!$C5), F$6, $B$4, "fill=true") = 0, "", _xll.IMDP("IR", CHOOSE(code!$A$1, code!$B5, code!$C5), F$6, $B$4, "fill=true") ) | G11: =_xll.IMDP("IR", CHOOSE(code!$A$1, code!$B5, code!$C5), G$6, $B$4, "fill=true") -> 3.63 | H11: =_xll.IMDP("IR", CHOOSE(code!$A$1, code!$B5, code!$C5), H$6, $B$4, "fill=true") -> 3.69 | I11: =_xll.IMDP("IR", CHOOSE(code!$A$1, code!$B5, code!$C5), I$6, $B$4, "fill=true") -> 3.72 | J11: =_xll.IMDP("IR", CHOOSE(code!$A$1, code!$B5, code!$C5), J$6, $B$4, "fill=true") -> 3.75 | K11: =_xll.IMDP("IR", CHOOSE(code!$A$1, code!$B5, code!$C5), K$6, $B$4, "fill=true") -> 3.76 | L11: =_xll.IMDP("IR", CHOOSE(code!$A$1, code!$B5, code!$C5), L$6, $B$4, "fill=true") -> 3.8 | M11: =_xll.IMDP("IR", CHOOSE(code!$A$1, code!$B5, code!$C5), M$6, $B$4, "fill=true") -> 3.89 | N11: =_xll.IMDP("IR", CHOOSE(code!$A$1, code!$B5, code!$C5), N$6, $B$4, "fill=true") -> 4.21
C12: NICE | D12: =_xll.IMDP("IR", CHOOSE(code!$A$1, code!$B6, code!$C6), D$6, $B$4, "fill=true") -> 3.5 | E12: =_xll.IMDP("IR", CHOOSE(code!$A$1, code!$B6, code!$C6), E$6, $B$4, "fill=true") -> 3.56 | F12: =IF( _xll.IMDP("IR", CHOOSE(code!$A$1, code!$B6, code!$C6), F$6, $B$4, "fill=true") = 0, "", _xll.IMDP("IR", CHOOSE(code!$A$1, code!$B6, code!$C6), F$6, $B$4, "fill=true") ) | G12: =_xll.IMDP("IR", CHOOSE(code!$A$1, code!$B6, code!$C6), G$6, $B$4, "fill=true") -> 3.63 | H12: =_xll.IMDP("IR", CHOOSE(code!$A$1, code!$B6, code!$C6), H$6, $B$4, "fill=true") -> 3.7 | I12: =_xll.IMDP("IR", CHOOSE(code!$A$1, code!$B6, code!$C6), I$6, $B$4, "fill=true") -> 3.72 | J12: =_xll.IMDP("IR", CHOOSE(code!$A$1, code!$B6, code!$C6), J$6, $B$4, "fill=true") -> 3.75 | K12: =_xll.IMDP("IR", CHOOSE(code!$A$1, code!$B6, code!$C6), K$6, $B$4, "fill=true") -> 3.77 | L12: =_xll.IMDP("IR", CHOOSE(code!$A$1, code!$B6, code!$C6), L$6, $B$4, "fill=true") -> 3.8 | M12: =_xll.IMDP("IR", CHOOSE(code!$A$1, code!$B6, code!$C6), M$6, $B$4, "fill=true") -> 3.89 | N12: =_xll.IMDP("IR", CHOOSE(code!$A$1, code!$B6, code!$C6), N$6, $B$4, "fill=true") -> 4.07
C13: FN | D13: =_xll.IMDP("IR", CHOOSE(code!$A$1, code!$B7, code!$C7), D$6, $B$4, "fill=true") -> 3.53 | E13: =_xll.IMDP("IR", CHOOSE(code!$A$1, code!$B7, code!$C7), E$6, $B$4, "fill=true") -> 3.57 | F13: =IF( _xll.IMDP("IR", CHOOSE(code!$A$1, code!$B7, code!$C7), F$6, $B$4, "fill=true") = 0, "", _xll.IMDP("IR", CHOOSE(code!$A$1, code!$B7, code!$C7), F$6, $B$4, "fill=true") ) | G13: =_xll.IMDP("IR", CHOOSE(code!$A$1, code!$B7, code!$C7), G$6, $B$4, "fill=true") -> 3.63 | H13: =_xll.IMDP("IR", CHOOSE(code!$A$1, code!$B7, code!$C7), H$6, $B$4, "fill=true") -> 3.66 | I13: =_xll.IMDP("IR", CHOOSE(code!$A$1, code!$B7, code!$C7), I$6, $B$4, "fill=true") -> 3.71 | J13: =_xll.IMDP("IR", CHOOSE(code!$A$1, code!$B7, code!$C7), J$6, $B$4, "fill=true") -> 3.75 | K13: =_xll.IMDP("IR", CHOOSE(code!$A$1, code!$B7, code!$C7), K$6, $B$4, "fill=true") -> 3.76 | L13: =_xll.IMDP("IR", CHOOSE(code!$A$1, code!$B7, code!$C7), L$6, $B$4, "fill=true") -> 3.8 | M13: =_xll.IMDP("IR", CHOOSE(code!$A$1, code!$B7, code!$C7), M$6, $B$4, "fill=true") -> 3.89 | N13: =_xll.IMDP("IR", CHOOSE(code!$A$1, code!$B7, code!$C7), N$6, $B$4, "fill=true") -> 3.95
B14: {=INDEX(code!$E$2:$F$9, 2, code!$A$1)} -> AA+ | C14: =$C$8 -> 3사 평균 | D14: =_xll.IMDP("IR", CHOOSE(code!$A$1, code!$B8, code!$C8), D$6, $B$4, "fill=true") -> 3.54 | E14: =_xll.IMDP("IR", CHOOSE(code!$A$1, code!$B8, code!$C8), E$6, $B$4, "fill=true") -> 3.59 | F14: =IF( _xll.IMDP("IR", CHOOSE(code!$A$1, code!$B8, code!$C8), F$6, $B$4, "fill=true") = 0, "", _xll.IMDP("IR", CHOOSE(code!$A$1, code!$B8, code!$C8), F$6, $B$4, "fill=true") ) | G14: =_xll.IMDP("IR", CHOOSE(code!$A$1, code!$B8, code!$C8), G$6, $B$4, "fill=true") -> 3.66 | H14: =_xll.IMDP("IR", CHOOSE(code!$A$1, code!$B8, code!$C8), H$6, $B$4, "fill=true") -> 3.71 | I14: =_xll.IMDP("IR", CHOOSE(code!$A$1, code!$B8, code!$C8), I$6, $B$4, "fill=true") -> 3.74 | J14: =_xll.IMDP("IR", CHOOSE(code!$A$1, code!$B8, code!$C8), J$6, $B$4, "fill=true") -> 3.77 | K14: =_xll.IMDP("IR", CHOOSE(code!$A$1, code!$B8, code!$C8), K$6, $B$4, "fill=true") -> 3.8 | L14: =_xll.IMDP("IR", CHOOSE(code!$A$1, code!$B8, code!$C8), L$6, $B$4, "fill=true") -> 3.87 | M14: =_xll.IMDP("IR", CHOOSE(code!$A$1, code!$B8, code!$C8), M$6, $B$4, "fill=true") -> 4 | N14: =_xll.IMDP("IR", CHOOSE(code!$A$1, code!$B8, code!$C8), N$6, $B$4, "fill=true") -> 4.47
C15: =$C$9 -> 4사 평균 | D15: =_xll.IMDP("IR", CHOOSE(code!$A$1, code!$B9, code!$C9), D$6, $B$4, "fill=true") -> 3.54 | E15: =_xll.IMDP("IR", CHOOSE(code!$A$1, code!$B9, code!$C9), E$6, $B$4, "fill=true") -> 3.59 | F15: =IF( _xll.IMDP("IR", CHOOSE(code!$A$1, code!$B9, code!$C9), F$6, $B$4, "fill=true") = 0, "", _xll.IMDP("IR", CHOOSE(code!$A$1, code!$B9, code!$C9), F$6, $B$4, "fill=true") ) | G15: =_xll.IMDP("IR", CHOOSE(code!$A$1, code!$B9, code!$C9), G$6, $B$4, "fill=true") -> 3.66 | H15: =_xll.IMDP("IR", CHOOSE(code!$A$1, code!$B9, code!$C9), H$6, $B$4, "fill=true") -> 3.71 | I15: =_xll.IMDP("IR", CHOOSE(code!$A$1, code!$B9, code!$C9), I$6, $B$4, "fill=true") -> 3.74 | J15: =_xll.IMDP("IR", CHOOSE(code!$A$1, code!$B9, code!$C9), J$6, $B$4, "fill=true") -> 3.77 | K15: =_xll.IMDP("IR", CHOOSE(code!$A$1, code!$B9, code!$C9), K$6, $B$4, "fill=true") -> 3.8 | L15: =_xll.IMDP("IR", CHOOSE(code!$A$1, code!$B9, code!$C9), L$6, $B$4, "fill=true") -> 3.86 | M15: =_xll.IMDP("IR", CHOOSE(code!$A$1, code!$B9, code!$C9), M$6, $B$4, "fill=true") -> 3.99 | N15: =_xll.IMDP("IR", CHOOSE(code!$A$1, code!$B9, code!$C9), N$6, $B$4, "fill=true") -> 4.37
C16: =$C$10 -> KAP | D16: =_xll.IMDP("IR", CHOOSE(code!$A$1, code!$B10, code!$C10), D$6, $B$4, "fill=true") -> 3.55 | E16: =_xll.IMDP("IR", CHOOSE(code!$A$1, code!$B10, code!$C10), E$6, $B$4, "fill=true") -> 3.61 | F16: =IF( _xll.IMDP("IR", CHOOSE(code!$A$1, code!$B10, code!$C10), F$6, $B$4, "fill=true") = 0, "", _xll.IMDP("IR", CHOOSE(code!$A$1, code!$B10, code!$C10), F$6, $B$4, "fill=true") ) | G16: =_xll.IMDP("IR", CHOOSE(code!$A$1, code!$B10, code!$C10), G$6, $B$4, "fill=true") -> 3.68 | H16: =_xll.IMDP("IR", CHOOSE(code!$A$1, code!$B10, code!$C10), H$6, $B$4, "fill=true") -> 3.72 | I16: =_xll.IMDP("IR", CHOOSE(code!$A$1, code!$B10, code!$C10), I$6, $B$4, "fill=true") -> 3.75 | J16: =_xll.IMDP("IR", CHOOSE(code!$A$1, code!$B10, code!$C10), J$6, $B$4, "fill=true") -> 3.77 | K16: =_xll.IMDP("IR", CHOOSE(code!$A$1, code!$B10, code!$C10), K$6, $B$4, "fill=true") -> 3.79 | L16: =_xll.IMDP("IR", CHOOSE(code!$A$1, code!$B10, code!$C10), L$6, $B$4, "fill=true") -> 3.86 | M16: =_xll.IMDP("IR", CHOOSE(code!$A$1, code!$B10, code!$C10), M$6, $B$4, "fill=true") -> 3.99 | N16: =_xll.IMDP("IR", CHOOSE(code!$A$1, code!$B10, code!$C10), N$6, $B$4, "fill=true") -> 4.85
C17: =$C$11 -> KIS | D17: =_xll.IMDP("IR", CHOOSE(code!$A$1, code!$B11, code!$C11), D$6, $B$4, "fill=true") -> 3.54 | E17: =_xll.IMDP("IR", CHOOSE(code!$A$1, code!$B11, code!$C11), E$6, $B$4, "fill=true") -> 3.59 | F17: =IF( _xll.IMDP("IR", CHOOSE(code!$A$1, code!$B11, code!$C11), F$6, $B$4, "fill=true") = 0, "", _xll.IMDP("IR", CHOOSE(code!$A$1, code!$B11, code!$C11), F$6, $B$4, "fill=true") ) | G17: =_xll.IMDP("IR", CHOOSE(code!$A$1, code!$B11, code!$C11), G$6, $B$4, "fill=true") -> 3.65 | H17: =_xll.IMDP("IR", CHOOSE(code!$A$1, code!$B11, code!$C11), H$6, $B$4, "fill=true") -> 3.71 | I17: =_xll.IMDP("IR", CHOOSE(code!$A$1, code!$B11, code!$C11), I$6, $B$4, "fill=true") -> 3.73 | J17: =_xll.IMDP("IR", CHOOSE(code!$A$1, code!$B11, code!$C11), J$6, $B$4, "fill=true") -> 3.77 | K17: =_xll.IMDP("IR", CHOOSE(code!$A$1, code!$B11, code!$C11), K$6, $B$4, "fill=true") -> 3.82 | L17: =_xll.IMDP("IR", CHOOSE(code!$A$1, code!$B11, code!$C11), L$6, $B$4, "fill=true") -> 3.88 | M17: =_xll.IMDP("IR", CHOOSE(code!$A$1, code!$B11, code!$C11), M$6, $B$4, "fill=true") -> 4 | N17: =_xll.IMDP("IR", CHOOSE(code!$A$1, code!$B11, code!$C11), N$6, $B$4, "fill=true") -> 4.37
C18: =$C$12 -> NICE | D18: =_xll.IMDP("IR", CHOOSE(code!$A$1, code!$B12, code!$C12), D$6, $B$4, "fill=true") -> 3.53 | E18: =_xll.IMDP("IR", CHOOSE(code!$A$1, code!$B12, code!$C12), E$6, $B$4, "fill=true") -> 3.59 | F18: =IF( _xll.IMDP("IR", CHOOSE(code!$A$1, code!$B12, code!$C12), F$6, $B$4, "fill=true") = 0, "", _xll.IMDP("IR", CHOOSE(code!$A$1, code!$B12, code!$C12), F$6, $B$4, "fill=true") ) | G18: =_xll.IMDP("IR", CHOOSE(code!$A$1, code!$B12, code!$C12), G$6, $B$4, "fill=true") -> 3.65 | H18: =_xll.IMDP("IR", CHOOSE(code!$A$1, code!$B12, code!$C12), H$6, $B$4, "fill=true") -> 3.71 | I18: =_xll.IMDP("IR", CHOOSE(code!$A$1, code!$B12, code!$C12), I$6, $B$4, "fill=true") -> 3.74 | J18: =_xll.IMDP("IR", CHOOSE(code!$A$1, code!$B12, code!$C12), J$6, $B$4, "fill=true") -> 3.77 | K18: =_xll.IMDP("IR", CHOOSE(code!$A$1, code!$B12, code!$C12), K$6, $B$4, "fill=true") -> 3.8 | L18: =_xll.IMDP("IR", CHOOSE(code!$A$1, code!$B12, code!$C12), L$6, $B$4, "fill=true") -> 3.87 | M18: =_xll.IMDP("IR", CHOOSE(code!$A$1, code!$B12, code!$C12), M$6, $B$4, "fill=true") -> 4.01 | N18: =_xll.IMDP("IR", CHOOSE(code!$A$1, code!$B12, code!$C12), N$6, $B$4, "fill=true") -> 4.19
C19: =$C$13 -> FN | D19: =_xll.IMDP("IR", CHOOSE(code!$A$1, code!$B13, code!$C13), D$6, $B$4, "fill=true") -> 3.56 | E19: =_xll.IMDP("IR", CHOOSE(code!$A$1, code!$B13, code!$C13), E$6, $B$4, "fill=true") -> 3.6 | F19: =IF( _xll.IMDP("IR", CHOOSE(code!$A$1, code!$B13, code!$C13), F$6, $B$4, "fill=true") = 0, "", _xll.IMDP("IR", CHOOSE(code!$A$1, code!$B13, code!$C13), F$6, $B$4, "fill=true") ) | G19: =_xll.IMDP("IR", CHOOSE(code!$A$1, code!$B13, code!$C13), G$6, $B$4, "fill=true") -> 3.66 | H19: =_xll.IMDP("IR", CHOOSE(code!$A$1, code!$B13, code!$C13), H$6, $B$4, "fill=true") -> 3.7 | I19: =_xll.IMDP("IR", CHOOSE(code!$A$1, code!$B13, code!$C13), I$6, $B$4, "fill=true") -> 3.74 | J19: =_xll.IMDP("IR", CHOOSE(code!$A$1, code!$B13, code!$C13), J$6, $B$4, "fill=true") -> 3.77 | K19: =_xll.IMDP("IR", CHOOSE(code!$A$1, code!$B13, code!$C13), K$6, $B$4, "fill=true") -> 3.79 | L19: =_xll.IMDP("IR", CHOOSE(code!$A$1, code!$B13, code!$C13), L$6, $B$4, "fill=true") -> 3.86 | M19: =_xll.IMDP("IR", CHOOSE(code!$A$1, code!$B13, code!$C13), M$6, $B$4, "fill=true") -> 3.99 | N19: =_xll.IMDP("IR", CHOOSE(code!$A$1, code!$B13, code!$C13), N$6, $B$4, "fill=true") -> 4.07
B20: {=INDEX(code!$E$2:$F$9, 3, code!$A$1)} -> AA | C20: =$C$8 -> 3사 평균 | D20: =_xll.IMDP("IR", CHOOSE(code!$A$1, code!$B14, code!$C14), D$6, $B$4, "fill=true") -> 3.57 | E20: =_xll.IMDP("IR", CHOOSE(code!$A$1, code!$B14, code!$C14), E$6, $B$4, "fill=true") -> 3.64 | F20: =IF( _xll.IMDP("IR", CHOOSE(code!$A$1, code!$B14, code!$C14), F$6, $B$4, "fill=true") = 0, "", _xll.IMDP("IR", CHOOSE(code!$A$1, code!$B14, code!$C14), F$6, $B$4, "fill=true") ) | G20: =_xll.IMDP("IR", CHOOSE(code!$A$1, code!$B14, code!$C14), G$6, $B$4, "fill=true") -> 3.71 | H20: =_xll.IMDP("IR", CHOOSE(code!$A$1, code!$B14, code!$C14), H$6, $B$4, "fill=true") -> 3.77 | I20: =_xll.IMDP("IR", CHOOSE(code!$A$1, code!$B14, code!$C14), I$6, $B$4, "fill=true") -> 3.81 | J20: =_xll.IMDP("IR", CHOOSE(code!$A$1, code!$B14, code!$C14), J$6, $B$4, "fill=true") -> 3.86 | K20: =_xll.IMDP("IR", CHOOSE(code!$A$1, code!$B14, code!$C14), K$6, $B$4, "fill=true") -> 3.9 | L20: =_xll.IMDP("IR", CHOOSE(code!$A$1, code!$B14, code!$C14), L$6, $B$4, "fill=true") -> 4 | M20: =_xll.IMDP("IR", CHOOSE(code!$A$1, code!$B14, code!$C14), M$6, $B$4, "fill=true") -> 4.18 | N20: =_xll.IMDP("IR", CHOOSE(code!$A$1, code!$B14, code!$C14), N$6, $B$4, "fill=true") -> 4.66
C21: =$C$9 -> 4사 평균 | D21: =_xll.IMDP("IR", CHOOSE(code!$A$1, code!$B15, code!$C15), D$6, $B$4, "fill=true") -> 3.59 | E21: =_xll.IMDP("IR", CHOOSE(code!$A$1, code!$B15, code!$C15), E$6, $B$4, "fill=true") -> 3.65 | F21: =IF( _xll.IMDP("IR", CHOOSE(code!$A$1, code!$B15, code!$C15), F$6, $B$4, "fill=true") = 0, "", _xll.IMDP("IR", CHOOSE(code!$A$1, code!$B15, code!$C15), F$6, $B$4, "fill=true") ) | G21: =_xll.IMDP("IR", CHOOSE(code!$A$1, code!$B15, code!$C15), G$6, $B$4, "fill=true") -> 3.72 | H21: =_xll.IMDP("IR", CHOOSE(code!$A$1, code!$B15, code!$C15), H$6, $B$4, "fill=true") -> 3.77 | I21: =_xll.IMDP("IR", CHOOSE(code!$A$1, code!$B15, code!$C15), I$6, $B$4, "fill=true") -> 3.82 | J21: =_xll.IMDP("IR", CHOOSE(code!$A$1, code!$B15, code!$C15), J$6, $B$4, "fill=true") -> 3.86 | K21: =_xll.IMDP("IR", CHOOSE(code!$A$1, code!$B15, code!$C15), K$6, $B$4, "fill=true") -> 3.89 | L21: =_xll.IMDP("IR", CHOOSE(code!$A$1, code!$B15, code!$C15), L$6, $B$4, "fill=true") -> 4.02 | M21: =_xll.IMDP("IR", CHOOSE(code!$A$1, code!$B15, code!$C15), M$6, $B$4, "fill=true") -> 4.19 | N21: =_xll.IMDP("IR", CHOOSE(code!$A$1, code!$B15, code!$C15), N$6, $B$4, "fill=true") -> 4.57
C22: =$C$10 -> KAP | D22: =_xll.IMDP("IR", CHOOSE(code!$A$1, code!$B16, code!$C16), D$6, $B$4, "fill=true") -> 3.59 | E22: =_xll.IMDP("IR", CHOOSE(code!$A$1, code!$B16, code!$C16), E$6, $B$4, "fill=true") -> 3.65 | F22: =IF( _xll.IMDP("IR", CHOOSE(code!$A$1, code!$B16, code!$C16), F$6, $B$4, "fill=true") = 0, "", _xll.IMDP("IR", CHOOSE(code!$A$1, code!$B16, code!$C16), F$6, $B$4, "fill=true") ) | G22: =_xll.IMDP("IR", CHOOSE(code!$A$1, code!$B16, code!$C16), G$6, $B$4, "fill=true") -> 3.72 | H22: =_xll.IMDP("IR", CHOOSE(code!$A$1, code!$B16, code!$C16), H$6, $B$4, "fill=true") -> 3.76 | I22: =_xll.IMDP("IR", CHOOSE(code!$A$1, code!$B16, code!$C16), I$6, $B$4, "fill=true") -> 3.82 | J22: =_xll.IMDP("IR", CHOOSE(code!$A$1, code!$B16, code!$C16), J$6, $B$4, "fill=true") -> 3.86 | K22: =_xll.IMDP("IR", CHOOSE(code!$A$1, code!$B16, code!$C16), K$6, $B$4, "fill=true") -> 3.87 | L22: =_xll.IMDP("IR", CHOOSE(code!$A$1, code!$B16, code!$C16), L$6, $B$4, "fill=true") -> 3.98 | M22: =_xll.IMDP("IR", CHOOSE(code!$A$1, code!$B16, code!$C16), M$6, $B$4, "fill=true") -> 4.14 | N22: =_xll.IMDP("IR", CHOOSE(code!$A$1, code!$B16, code!$C16), N$6, $B$4, "fill=true") -> 5.03
C23: =$C$11 -> KIS | D23: =_xll.IMDP("IR", CHOOSE(code!$A$1, code!$B17, code!$C17), D$6, $B$4, "fill=true") -> 3.56 | E23: =_xll.IMDP("IR", CHOOSE(code!$A$1, code!$B17, code!$C17), E$6, $B$4, "fill=true") -> 3.65 | F23: =IF( _xll.IMDP("IR", CHOOSE(code!$A$1, code!$B17, code!$C17), F$6, $B$4, "fill=true") = 0, "", _xll.IMDP("IR", CHOOSE(code!$A$1, code!$B17, code!$C17), F$6, $B$4, "fill=true") ) | G23: =_xll.IMDP("IR", CHOOSE(code!$A$1, code!$B17, code!$C17), G$6, $B$4, "fill=true") -> 3.72 | H23: =_xll.IMDP("IR", CHOOSE(code!$A$1, code!$B17, code!$C17), H$6, $B$4, "fill=true") -> 3.78 | I23: =_xll.IMDP("IR", CHOOSE(code!$A$1, code!$B17, code!$C17), I$6, $B$4, "fill=true") -> 3.81 | J23: =_xll.IMDP("IR", CHOOSE(code!$A$1, code!$B17, code!$C17), J$6, $B$4, "fill=true") -> 3.86 | K23: =_xll.IMDP("IR", CHOOSE(code!$A$1, code!$B17, code!$C17), K$6, $B$4, "fill=true") -> 3.91 | L23: =_xll.IMDP("IR", CHOOSE(code!$A$1, code!$B17, code!$C17), L$6, $B$4, "fill=true") -> 4.01 | M23: =_xll.IMDP("IR", CHOOSE(code!$A$1, code!$B17, code!$C17), M$6, $B$4, "fill=true") -> 4.21 | N23: =_xll.IMDP("IR", CHOOSE(code!$A$1, code!$B17, code!$C17), N$6, $B$4, "fill=true") -> 4.57
C24: =$C$12 -> NICE | D24: =_xll.IMDP("IR", CHOOSE(code!$A$1, code!$B18, code!$C18), D$6, $B$4, "fill=true") -> 3.57 | E24: =_xll.IMDP("IR", CHOOSE(code!$A$1, code!$B18, code!$C18), E$6, $B$4, "fill=true") -> 3.64 | F24: =IF( _xll.IMDP("IR", CHOOSE(code!$A$1, code!$B18, code!$C18), F$6, $B$4, "fill=true") = 0, "", _xll.IMDP("IR", CHOOSE(code!$A$1, code!$B18, code!$C18), F$6, $B$4, "fill=true") ) | G24: =_xll.IMDP("IR", CHOOSE(code!$A$1, code!$B18, code!$C18), G$6, $B$4, "fill=true") -> 3.7 | H24: =_xll.IMDP("IR", CHOOSE(code!$A$1, code!$B18, code!$C18), H$6, $B$4, "fill=true") -> 3.77 | I24: =_xll.IMDP("IR", CHOOSE(code!$A$1, code!$B18, code!$C18), I$6, $B$4, "fill=true") -> 3.82 | J24: =_xll.IMDP("IR", CHOOSE(code!$A$1, code!$B18, code!$C18), J$6, $B$4, "fill=true") -> 3.87 | K24: =_xll.IMDP("IR", CHOOSE(code!$A$1, code!$B18, code!$C18), K$6, $B$4, "fill=true") -> 3.92 | L24: =_xll.IMDP("IR", CHOOSE(code!$A$1, code!$B18, code!$C18), L$6, $B$4, "fill=true") -> 4.01 | M24: =_xll.IMDP("IR", CHOOSE(code!$A$1, code!$B18, code!$C18), M$6, $B$4, "fill=true") -> 4.21 | N24: =_xll.IMDP("IR", CHOOSE(code!$A$1, code!$B18, code!$C18), N$6, $B$4, "fill=true") -> 4.38
C25: =$C$13 -> FN | D25: =_xll.IMDP("IR", CHOOSE(code!$A$1, code!$B19, code!$C19), D$6, $B$4, "fill=true") -> 3.64 | E25: =_xll.IMDP("IR", CHOOSE(code!$A$1, code!$B19, code!$C19), E$6, $B$4, "fill=true") -> 3.68 | F25: =IF( _xll.IMDP("IR", CHOOSE(code!$A$1, code!$B19, code!$C19), F$6, $B$4, "fill=true") = 0, "", _xll.IMDP("IR", CHOOSE(code!$A$1, code!$B19, code!$C19), F$6, $B$4, "fill=true") ) | G25: =_xll.IMDP("IR", CHOOSE(code!$A$1, code!$B19, code!$C19), G$6, $B$4, "fill=true") -> 3.74 | H25: =_xll.IMDP("IR", CHOOSE(code!$A$1, code!$B19, code!$C19), H$6, $B$4, "fill=true") -> 3.77 | I25: =_xll.IMDP("IR", CHOOSE(code!$A$1, code!$B19, code!$C19), I$6, $B$4, "fill=true") -> 3.83 | J25: =_xll.IMDP("IR", CHOOSE(code!$A$1, code!$B19, code!$C19), J$6, $B$4, "fill=true") -> 3.86 | K25: =_xll.IMDP("IR", CHOOSE(code!$A$1, code!$B19, code!$C19), K$6, $B$4, "fill=true") -> 3.87 | L25: =_xll.IMDP("IR", CHOOSE(code!$A$1, code!$B19, code!$C19), L$6, $B$4, "fill=true") -> 4.1 | M25: =_xll.IMDP("IR", CHOOSE(code!$A$1, code!$B19, code!$C19), M$6, $B$4, "fill=true") -> 4.21 | N25: =_xll.IMDP("IR", CHOOSE(code!$A$1, code!$B19, code!$C19), N$6, $B$4, "fill=true") -> 4.3
B26: {=INDEX(code!$E$2:$F$9, 4, code!$A$1)} -> AA- | C26: =$C$8 -> 3사 평균 | D26: =_xll.IMDP("IR", CHOOSE(code!$A$1, code!$B20, code!$C20), D$6, $B$4, "fill=true") -> 3.63 | E26: =_xll.IMDP("IR", CHOOSE(code!$A$1, code!$B20, code!$C20), E$6, $B$4, "fill=true") -> 3.72 | F26: =IF( _xll.IMDP("IR", CHOOSE(code!$A$1, code!$B20, code!$C20), F$6, $B$4, "fill=true") = 0, "", _xll.IMDP("IR", CHOOSE(code!$A$1, code!$B20, code!$C20), F$6, $B$4, "fill=true") ) | G26: =_xll.IMDP("IR", CHOOSE(code!$A$1, code!$B20, code!$C20), G$6, $B$4, "fill=true") -> 3.8 | H26: =_xll.IMDP("IR", CHOOSE(code!$A$1, code!$B20, code!$C20), H$6, $B$4, "fill=true") -> 3.85 | I26: =_xll.IMDP("IR", CHOOSE(code!$A$1, code!$B20, code!$C20), I$6, $B$4, "fill=true") -> 3.88 | J26: =_xll.IMDP("IR", CHOOSE(code!$A$1, code!$B20, code!$C20), J$6, $B$4, "fill=true") -> 3.92 | K26: =_xll.IMDP("IR", CHOOSE(code!$A$1, code!$B20, code!$C20), K$6, $B$4, "fill=true") -> 3.97 | L26: =_xll.IMDP("IR", CHOOSE(code!$A$1, code!$B20, code!$C20), L$6, $B$4, "fill=true") -> 4.08 | M26: =_xll.IMDP("IR", CHOOSE(code!$A$1, code!$B20, code!$C20), M$6, $B$4, "fill=true") -> 4.29 | N26: =_xll.IMDP("IR", CHOOSE(code!$A$1, code!$B20, code!$C20), N$6, $B$4, "fill=true") -> 4.78
C27: =$C$9 -> 4사 평균 | D27: =_xll.IMDP("IR", CHOOSE(code!$A$1, code!$B21, code!$C21), D$6, $B$4, "fill=true") -> 3.65 | E27: =_xll.IMDP("IR", CHOOSE(code!$A$1, code!$B21, code!$C21), E$6, $B$4, "fill=true") -> 3.73 | F27: =IF( _xll.IMDP("IR", CHOOSE(code!$A$1, code!$B21, code!$C21), F$6, $B$4, "fill=true") = 0, "", _xll.IMDP("IR", CHOOSE(code!$A$1, code!$B21, code!$C21), F$6, $B$4, "fill=true") ) | G27: =_xll.IMDP("IR", CHOOSE(code!$A$1, code!$B21, code!$C21), G$6, $B$4, "fill=true") -> 3.8 | H27: =_xll.IMDP("IR", CHOOSE(code!$A$1, code!$B21, code!$C21), H$6, $B$4, "fill=true") -> 3.85 | I27: =_xll.IMDP("IR", CHOOSE(code!$A$1, code!$B21, code!$C21), I$6, $B$4, "fill=true") -> 3.88 | J27: =_xll.IMDP("IR", CHOOSE(code!$A$1, code!$B21, code!$C21), J$6, $B$4, "fill=true") -> 3.92 | K27: =_xll.IMDP("IR", CHOOSE(code!$A$1, code!$B21, code!$C21), K$6, $B$4, "fill=true") -> 3.96 | L27: =_xll.IMDP("IR", CHOOSE(code!$A$1, code!$B21, code!$C21), L$6, $B$4, "fill=true") -> 4.11 | M27: =_xll.IMDP("IR", CHOOSE(code!$A$1, code!$B21, code!$C21), M$6, $B$4, "fill=true") -> 4.31 | N27: =_xll.IMDP("IR", CHOOSE(code!$A$1, code!$B21, code!$C21), N$6, $B$4, "fill=true") -> 4.7
C28: =$C$10 -> KAP | D28: =_xll.IMDP("IR", CHOOSE(code!$A$1, code!$B22, code!$C22), D$6, $B$4, "fill=true") -> 3.65 | E28: =_xll.IMDP("IR", CHOOSE(code!$A$1, code!$B22, code!$C22), E$6, $B$4, "fill=true") -> 3.72 | F28: =IF( _xll.IMDP("IR", CHOOSE(code!$A$1, code!$B22, code!$C22), F$6, $B$4, "fill=true") = 0, "", _xll.IMDP("IR", CHOOSE(code!$A$1, code!$B22, code!$C22), F$6, $B$4, "fill=true") ) | G28: =_xll.IMDP("IR", CHOOSE(code!$A$1, code!$B22, code!$C22), G$6, $B$4, "fill=true") -> 3.81 | H28: =_xll.IMDP("IR", CHOOSE(code!$A$1, code!$B22, code!$C22), H$6, $B$4, "fill=true") -> 3.85 | I28: =_xll.IMDP("IR", CHOOSE(code!$A$1, code!$B22, code!$C22), I$6, $B$4, "fill=true") -> 3.89 | J28: =_xll.IMDP("IR", CHOOSE(code!$A$1, code!$B22, code!$C22), J$6, $B$4, "fill=true") -> 3.93 | K28: =_xll.IMDP("IR", CHOOSE(code!$A$1, code!$B22, code!$C22), K$6, $B$4, "fill=true") -> 3.94 | L28: =_xll.IMDP("IR", CHOOSE(code!$A$1, code!$B22, code!$C22), L$6, $B$4, "fill=true") -> 4.07 | M28: =_xll.IMDP("IR", CHOOSE(code!$A$1, code!$B22, code!$C22), M$6, $B$4, "fill=true") -> 4.25 | N28: =_xll.IMDP("IR", CHOOSE(code!$A$1, code!$B22, code!$C22), N$6, $B$4, "fill=true") -> 5.17
C29: =$C$11 -> KIS | D29: =_xll.IMDP("IR", CHOOSE(code!$A$1, code!$B23, code!$C23), D$6, $B$4, "fill=true") -> 3.62 | E29: =_xll.IMDP("IR", CHOOSE(code!$A$1, code!$B23, code!$C23), E$6, $B$4, "fill=true") -> 3.73 | F29: =IF( _xll.IMDP("IR", CHOOSE(code!$A$1, code!$B23, code!$C23), F$6, $B$4, "fill=true") = 0, "", _xll.IMDP("IR", CHOOSE(code!$A$1, code!$B23, code!$C23), F$6, $B$4, "fill=true") ) | G29: =_xll.IMDP("IR", CHOOSE(code!$A$1, code!$B23, code!$C23), G$6, $B$4, "fill=true") -> 3.79 | H29: =_xll.IMDP("IR", CHOOSE(code!$A$1, code!$B23, code!$C23), H$6, $B$4, "fill=true") -> 3.85 | I29: =_xll.IMDP("IR", CHOOSE(code!$A$1, code!$B23, code!$C23), I$6, $B$4, "fill=true") -> 3.88 | J29: =_xll.IMDP("IR", CHOOSE(code!$A$1, code!$B23, code!$C23), J$6, $B$4, "fill=true") -> 3.92 | K29: =_xll.IMDP("IR", CHOOSE(code!$A$1, code!$B23, code!$C23), K$6, $B$4, "fill=true") -> 3.98 | L29: =_xll.IMDP("IR", CHOOSE(code!$A$1, code!$B23, code!$C23), L$6, $B$4, "fill=true") -> 4.09 | M29: =_xll.IMDP("IR", CHOOSE(code!$A$1, code!$B23, code!$C23), M$6, $B$4, "fill=true") -> 4.33 | N29: =_xll.IMDP("IR", CHOOSE(code!$A$1, code!$B23, code!$C23), N$6, $B$4, "fill=true") -> 4.72
C30: =$C$12 -> NICE | D30: =_xll.IMDP("IR", CHOOSE(code!$A$1, code!$B24, code!$C24), D$6, $B$4, "fill=true") -> 3.64 | E30: =_xll.IMDP("IR", CHOOSE(code!$A$1, code!$B24, code!$C24), E$6, $B$4, "fill=true") -> 3.73 | F30: =IF( _xll.IMDP("IR", CHOOSE(code!$A$1, code!$B24, code!$C24), F$6, $B$4, "fill=true") = 0, "", _xll.IMDP("IR", CHOOSE(code!$A$1, code!$B24, code!$C24), F$6, $B$4, "fill=true") ) | G30: =_xll.IMDP("IR", CHOOSE(code!$A$1, code!$B24, code!$C24), G$6, $B$4, "fill=true") -> 3.8 | H30: =_xll.IMDP("IR", CHOOSE(code!$A$1, code!$B24, code!$C24), H$6, $B$4, "fill=true") -> 3.85 | I30: =_xll.IMDP("IR", CHOOSE(code!$A$1, code!$B24, code!$C24), I$6, $B$4, "fill=true") -> 3.88 | J30: =_xll.IMDP("IR", CHOOSE(code!$A$1, code!$B24, code!$C24), J$6, $B$4, "fill=true") -> 3.93 | K30: =_xll.IMDP("IR", CHOOSE(code!$A$1, code!$B24, code!$C24), K$6, $B$4, "fill=true") -> 4 | L30: =_xll.IMDP("IR", CHOOSE(code!$A$1, code!$B24, code!$C24), L$6, $B$4, "fill=true") -> 4.08 | M30: =_xll.IMDP("IR", CHOOSE(code!$A$1, code!$B24, code!$C24), M$6, $B$4, "fill=true") -> 4.3 | N30: =_xll.IMDP("IR", CHOOSE(code!$A$1, code!$B24, code!$C24), N$6, $B$4, "fill=true") -> 4.47
C31: =$C$13 -> FN | D31: =_xll.IMDP("IR", CHOOSE(code!$A$1, code!$B25, code!$C25), D$6, $B$4, "fill=true") -> 3.7 | E31: =_xll.IMDP("IR", CHOOSE(code!$A$1, code!$B25, code!$C25), E$6, $B$4, "fill=true") -> 3.76 | F31: =IF( _xll.IMDP("IR", CHOOSE(code!$A$1, code!$B25, code!$C25), F$6, $B$4, "fill=true") = 0, "", _xll.IMDP("IR", CHOOSE(code!$A$1, code!$B25, code!$C25), F$6, $B$4, "fill=true") ) | G31: =_xll.IMDP("IR", CHOOSE(code!$A$1, code!$B25, code!$C25), G$6, $B$4, "fill=true") -> 3.83 | H31: =_xll.IMDP("IR", CHOOSE(code!$A$1, code!$B25, code!$C25), H$6, $B$4, "fill=true") -> 3.87 | I31: =_xll.IMDP("IR", CHOOSE(code!$A$1, code!$B25, code!$C25), I$6, $B$4, "fill=true") -> 3.89 | J31: =_xll.IMDP("IR", CHOOSE(code!$A$1, code!$B25, code!$C25), J$6, $B$4, "fill=true") -> 3.92 | K31: =_xll.IMDP("IR", CHOOSE(code!$A$1, code!$B25, code!$C25), K$6, $B$4, "fill=true") -> 3.94 | L31: =_xll.IMDP("IR", CHOOSE(code!$A$1, code!$B25, code!$C25), L$6, $B$4, "fill=true") -> 4.21 | M31: =_xll.IMDP("IR", CHOOSE(code!$A$1, code!$B25, code!$C25), M$6, $B$4, "fill=true") -> 4.38 | N31: =_xll.IMDP("IR", CHOOSE(code!$A$1, code!$B25, code!$C25), N$6, $B$4, "fill=true") -> 4.45
B32: {=INDEX(code!$E$2:$F$9, 5, code!$A$1)} -> A+ | C32: =$C$8 -> 3사 평균 | D32: =_xll.IMDP("IR", CHOOSE(code!$A$1, code!$B26, code!$C26), D$6, $B$4, "fill=true") -> 3.69 | E32: =_xll.IMDP("IR", CHOOSE(code!$A$1, code!$B26, code!$C26), E$6, $B$4, "fill=true") -> 3.78 | F32: =IF( _xll.IMDP("IR", CHOOSE(code!$A$1, code!$B26, code!$C26), F$6, $B$4, "fill=true") = 0, "", _xll.IMDP("IR", CHOOSE(code!$A$1, code!$B26, code!$C26), F$6, $B$4, "fill=true") ) | G32: =_xll.IMDP("IR", CHOOSE(code!$A$1, code!$B26, code!$C26), G$6, $B$4, "fill=true") -> 3.85 | H32: =_xll.IMDP("IR", CHOOSE(code!$A$1, code!$B26, code!$C26), H$6, $B$4, "fill=true") -> 3.9 | I32: =_xll.IMDP("IR", CHOOSE(code!$A$1, code!$B26, code!$C26), I$6, $B$4, "fill=true") -> 3.94 | J32: =_xll.IMDP("IR", CHOOSE(code!$A$1, code!$B26, code!$C26), J$6, $B$4, "fill=true") -> 3.98 | K32: =_xll.IMDP("IR", CHOOSE(code!$A$1, code!$B26, code!$C26), K$6, $B$4, "fill=true") -> 4.03 | L32: =_xll.IMDP("IR", CHOOSE(code!$A$1, code!$B26, code!$C26), L$6, $B$4, "fill=true") -> 4.14 | M32: =_xll.IMDP("IR", CHOOSE(code!$A$1, code!$B26, code!$C26), M$6, $B$4, "fill=true") -> 4.37 | N32: =_xll.IMDP("IR", CHOOSE(code!$A$1, code!$B26, code!$C26), N$6, $B$4, "fill=true") -> 4.87
C33: =$C$9 -> 4사 평균 | D33: =_xll.IMDP("IR", CHOOSE(code!$A$1, code!$B27, code!$C27), D$6, $B$4, "fill=true") -> 3.7 | E33: =_xll.IMDP("IR", CHOOSE(code!$A$1, code!$B27, code!$C27), E$6, $B$4, "fill=true") -> 3.79 | F33: =IF( _xll.IMDP("IR", CHOOSE(code!$A$1, code!$B27, code!$C27), F$6, $B$4, "fill=true") = 0, "", _xll.IMDP("IR", CHOOSE(code!$A$1, code!$B27, code!$C27), F$6, $B$4, "fill=true") ) | G33: =_xll.IMDP("IR", CHOOSE(code!$A$1, code!$B27, code!$C27), G$6, $B$4, "fill=true") -> 3.85 | H33: =_xll.IMDP("IR", CHOOSE(code!$A$1, code!$B27, code!$C27), H$6, $B$4, "fill=true") -> 3.9 | I33: =_xll.IMDP("IR", CHOOSE(code!$A$1, code!$B27, code!$C27), I$6, $B$4, "fill=true") -> 3.94 | J33: =_xll.IMDP("IR", CHOOSE(code!$A$1, code!$B27, code!$C27), J$6, $B$4, "fill=true") -> 3.98 | K33: =_xll.IMDP("IR", CHOOSE(code!$A$1, code!$B27, code!$C27), K$6, $B$4, "fill=true") -> 4.02 | L33: =_xll.IMDP("IR", CHOOSE(code!$A$1, code!$B27, code!$C27), L$6, $B$4, "fill=true") -> 4.18 | M33: =_xll.IMDP("IR", CHOOSE(code!$A$1, code!$B27, code!$C27), M$6, $B$4, "fill=true") -> 4.39 | N33: =_xll.IMDP("IR", CHOOSE(code!$A$1, code!$B27, code!$C27), N$6, $B$4, "fill=true") -> 4.79
C34: =$C$10 -> KAP | D34: =_xll.IMDP("IR", CHOOSE(code!$A$1, code!$B28, code!$C28), D$6, $B$4, "fill=true") -> 3.72 | E34: =_xll.IMDP("IR", CHOOSE(code!$A$1, code!$B28, code!$C28), E$6, $B$4, "fill=true") -> 3.78 | F34: =IF( _xll.IMDP("IR", CHOOSE(code!$A$1, code!$B28, code!$C28), F$6, $B$4, "fill=true") = 0, "", _xll.IMDP("IR", CHOOSE(code!$A$1, code!$B28, code!$C28), F$6, $B$4, "fill=true") ) | G34: =_xll.IMDP("IR", CHOOSE(code!$A$1, code!$B28, code!$C28), G$6, $B$4, "fill=true") -> 3.86 | H34: =_xll.IMDP("IR", CHOOSE(code!$A$1, code!$B28, code!$C28), H$6, $B$4, "fill=true") -> 3.89 | I34: =_xll.IMDP("IR", CHOOSE(code!$A$1, code!$B28, code!$C28), I$6, $B$4, "fill=true") -> 3.95 | J34: =_xll.IMDP("IR", CHOOSE(code!$A$1, code!$B28, code!$C28), J$6, $B$4, "fill=true") -> 3.98 | K34: =_xll.IMDP("IR", CHOOSE(code!$A$1, code!$B28, code!$C28), K$6, $B$4, "fill=true") -> 3.99 | L34: =_xll.IMDP("IR", CHOOSE(code!$A$1, code!$B28, code!$C28), L$6, $B$4, "fill=true") -> 4.13 | M34: =_xll.IMDP("IR", CHOOSE(code!$A$1, code!$B28, code!$C28), M$6, $B$4, "fill=true") -> 4.34 | N34: =_xll.IMDP("IR", CHOOSE(code!$A$1, code!$B28, code!$C28), N$6, $B$4, "fill=true") -> 5.26
C35: =$C$11 -> KIS | D35: =_xll.IMDP("IR", CHOOSE(code!$A$1, code!$B29, code!$C29), D$6, $B$4, "fill=true") -> 3.67 | E35: =_xll.IMDP("IR", CHOOSE(code!$A$1, code!$B29, code!$C29), E$6, $B$4, "fill=true") -> 3.78 | F35: =IF( _xll.IMDP("IR", CHOOSE(code!$A$1, code!$B29, code!$C29), F$6, $B$4, "fill=true") = 0, "", _xll.IMDP("IR", CHOOSE(code!$A$1, code!$B29, code!$C29), F$6, $B$4, "fill=true") ) | G35: =_xll.IMDP("IR", CHOOSE(code!$A$1, code!$B29, code!$C29), G$6, $B$4, "fill=true") -> 3.84 | H35: =_xll.IMDP("IR", CHOOSE(code!$A$1, code!$B29, code!$C29), H$6, $B$4, "fill=true") -> 3.91 | I35: =_xll.IMDP("IR", CHOOSE(code!$A$1, code!$B29, code!$C29), I$6, $B$4, "fill=true") -> 3.94 | J35: =_xll.IMDP("IR", CHOOSE(code!$A$1, code!$B29, code!$C29), J$6, $B$4, "fill=true") -> 3.99 | K35: =_xll.IMDP("IR", CHOOSE(code!$A$1, code!$B29, code!$C29), K$6, $B$4, "fill=true") -> 4.05 | L35: =_xll.IMDP("IR", CHOOSE(code!$A$1, code!$B29, code!$C29), L$6, $B$4, "fill=true") -> 4.16 | M35: =_xll.IMDP("IR", CHOOSE(code!$A$1, code!$B29, code!$C29), M$6, $B$4, "fill=true") -> 4.4 | N35: =_xll.IMDP("IR", CHOOSE(code!$A$1, code!$B29, code!$C29), N$6, $B$4, "fill=true") -> 4.8
C36: =$C$12 -> NICE | D36: =_xll.IMDP("IR", CHOOSE(code!$A$1, code!$B30, code!$C30), D$6, $B$4, "fill=true") -> 3.68 | E36: =_xll.IMDP("IR", CHOOSE(code!$A$1, code!$B30, code!$C30), E$6, $B$4, "fill=true") -> 3.78 | F36: =IF( _xll.IMDP("IR", CHOOSE(code!$A$1, code!$B30, code!$C30), F$6, $B$4, "fill=true") = 0, "", _xll.IMDP("IR", CHOOSE(code!$A$1, code!$B30, code!$C30), F$6, $B$4, "fill=true") ) | G36: =_xll.IMDP("IR", CHOOSE(code!$A$1, code!$B30, code!$C30), G$6, $B$4, "fill=true") -> 3.85 | H36: =_xll.IMDP("IR", CHOOSE(code!$A$1, code!$B30, code!$C30), H$6, $B$4, "fill=true") -> 3.9 | I36: =_xll.IMDP("IR", CHOOSE(code!$A$1, code!$B30, code!$C30), I$6, $B$4, "fill=true") -> 3.93 | J36: =_xll.IMDP("IR", CHOOSE(code!$A$1, code!$B30, code!$C30), J$6, $B$4, "fill=true") -> 3.98 | K36: =_xll.IMDP("IR", CHOOSE(code!$A$1, code!$B30, code!$C30), K$6, $B$4, "fill=true") -> 4.05 | L36: =_xll.IMDP("IR", CHOOSE(code!$A$1, code!$B30, code!$C30), L$6, $B$4, "fill=true") -> 4.14 | M36: =_xll.IMDP("IR", CHOOSE(code!$A$1, code!$B30, code!$C30), M$6, $B$4, "fill=true") -> 4.38 | N36: =_xll.IMDP("IR", CHOOSE(code!$A$1, code!$B30, code!$C30), N$6, $B$4, "fill=true") -> 4.55
C37: =$C$13 -> FN | D37: =_xll.IMDP("IR", CHOOSE(code!$A$1, code!$B31, code!$C31), D$6, $B$4, "fill=true") -> 3.75 | E37: =_xll.IMDP("IR", CHOOSE(code!$A$1, code!$B31, code!$C31), E$6, $B$4, "fill=true") -> 3.82 | F37: =IF( _xll.IMDP("IR", CHOOSE(code!$A$1, code!$B31, code!$C31), F$6, $B$4, "fill=true") = 0, "", _xll.IMDP("IR", CHOOSE(code!$A$1, code!$B31, code!$C31), F$6, $B$4, "fill=true") ) | G37: =_xll.IMDP("IR", CHOOSE(code!$A$1, code!$B31, code!$C31), G$6, $B$4, "fill=true") -> 3.88 | H37: =_xll.IMDP("IR", CHOOSE(code!$A$1, code!$B31, code!$C31), H$6, $B$4, "fill=true") -> 3.92 | I37: =_xll.IMDP("IR", CHOOSE(code!$A$1, code!$B31, code!$C31), I$6, $B$4, "fill=true") -> 3.94 | J37: =_xll.IMDP("IR", CHOOSE(code!$A$1, code!$B31, code!$C31), J$6, $B$4, "fill=true") -> 3.97 | K37: =_xll.IMDP("IR", CHOOSE(code!$A$1, code!$B31, code!$C31), K$6, $B$4, "fill=true") -> 4.02 | L37: =_xll.IMDP("IR", CHOOSE(code!$A$1, code!$B31, code!$C31), L$6, $B$4, "fill=true") -> 4.29 | M37: =_xll.IMDP("IR", CHOOSE(code!$A$1, code!$B31, code!$C31), M$6, $B$4, "fill=true") -> 4.46 | N37: =_xll.IMDP("IR", CHOOSE(code!$A$1, code!$B31, code!$C31), N$6, $B$4, "fill=true") -> 4.58
B38: {=INDEX(code!$E$2:$F$9, 6, code!$A$1)} -> A | C38: =$C$8 -> 3사 평균 | D38: =_xll.IMDP("IR", CHOOSE(code!$A$1, code!$B32, code!$C32), D$6, $B$4, "fill=true") -> 3.73 | E38: =_xll.IMDP("IR", CHOOSE(code!$A$1, code!$B32, code!$C32), E$6, $B$4, "fill=true") -> 3.83 | F38: =IF( _xll.IMDP("IR", CHOOSE(code!$A$1, code!$B32, code!$C32), F$6, $B$4, "fill=true") = 0, "", _xll.IMDP("IR", CHOOSE(code!$A$1, code!$B32, code!$C32), F$6, $B$4, "fill=true") ) | G38: =_xll.IMDP("IR", CHOOSE(code!$A$1, code!$B32, code!$C32), G$6, $B$4, "fill=true") -> 3.9 | H38: =_xll.IMDP("IR", CHOOSE(code!$A$1, code!$B32, code!$C32), H$6, $B$4, "fill=true") -> 3.94 | I38: =_xll.IMDP("IR", CHOOSE(code!$A$1, code!$B32, code!$C32), I$6, $B$4, "fill=true") -> 4 | J38: =_xll.IMDP("IR", CHOOSE(code!$A$1, code!$B32, code!$C32), J$6, $B$4, "fill=true") -> 4.05 | K38: =_xll.IMDP("IR", CHOOSE(code!$A$1, code!$B32, code!$C32), K$6, $B$4, "fill=true") -> 4.1 | L38: =_xll.IMDP("IR", CHOOSE(code!$A$1, code!$B32, code!$C32), L$6, $B$4, "fill=true") -> 4.21 | M38: =_xll.IMDP("IR", CHOOSE(code!$A$1, code!$B32, code!$C32), M$6, $B$4, "fill=true") -> 4.44 | N38: =_xll.IMDP("IR", CHOOSE(code!$A$1, code!$B32, code!$C32), N$6, $B$4, "fill=true") -> 4.94
C39: =$C$9 -> 4사 평균 | D39: =_xll.IMDP("IR", CHOOSE(code!$A$1, code!$B33, code!$C33), D$6, $B$4, "fill=true") -> 3.75 | E39: =_xll.IMDP("IR", CHOOSE(code!$A$1, code!$B33, code!$C33), E$6, $B$4, "fill=true") -> 3.83 | F39: =IF( _xll.IMDP("IR", CHOOSE(code!$A$1, code!$B33, code!$C33), F$6, $B$4, "fill=true") = 0, "", _xll.IMDP("IR", CHOOSE(code!$A$1, code!$B33, code!$C33), F$6, $B$4, "fill=true") ) | G39: =_xll.IMDP("IR", CHOOSE(code!$A$1, code!$B33, code!$C33), G$6, $B$4, "fill=true") -> 3.9 | H39: =_xll.IMDP("IR", CHOOSE(code!$A$1, code!$B33, code!$C33), H$6, $B$4, "fill=true") -> 3.95 | I39: =_xll.IMDP("IR", CHOOSE(code!$A$1, code!$B33, code!$C33), I$6, $B$4, "fill=true") -> 4 | J39: =_xll.IMDP("IR", CHOOSE(code!$A$1, code!$B33, code!$C33), J$6, $B$4, "fill=true") -> 4.05 | K39: =_xll.IMDP("IR", CHOOSE(code!$A$1, code!$B33, code!$C33), K$6, $B$4, "fill=true") -> 4.09 | L39: =_xll.IMDP("IR", CHOOSE(code!$A$1, code!$B33, code!$C33), L$6, $B$4, "fill=true") -> 4.25 | M39: =_xll.IMDP("IR", CHOOSE(code!$A$1, code!$B33, code!$C33), M$6, $B$4, "fill=true") -> 4.46 | N39: =_xll.IMDP("IR", CHOOSE(code!$A$1, code!$B33, code!$C33), N$6, $B$4, "fill=true") -> 4.87
C40: =$C$10 -> KAP | D40: =_xll.IMDP("IR", CHOOSE(code!$A$1, code!$B34, code!$C34), D$6, $B$4, "fill=true") -> 3.76 | E40: =_xll.IMDP("IR", CHOOSE(code!$A$1, code!$B34, code!$C34), E$6, $B$4, "fill=true") -> 3.82 | F40: =IF( _xll.IMDP("IR", CHOOSE(code!$A$1, code!$B34, code!$C34), F$6, $B$4, "fill=true") = 0, "", _xll.IMDP("IR", CHOOSE(code!$A$1, code!$B34, code!$C34), F$6, $B$4, "fill=true") ) | G40: =_xll.IMDP("IR", CHOOSE(code!$A$1, code!$B34, code!$C34), G$6, $B$4, "fill=true") -> 3.9 | H40: =_xll.IMDP("IR", CHOOSE(code!$A$1, code!$B34, code!$C34), H$6, $B$4, "fill=true") -> 3.93 | I40: =_xll.IMDP("IR", CHOOSE(code!$A$1, code!$B34, code!$C34), I$6, $B$4, "fill=true") -> 4.01 | J40: =_xll.IMDP("IR", CHOOSE(code!$A$1, code!$B34, code!$C34), J$6, $B$4, "fill=true") -> 4.05 | K40: =_xll.IMDP("IR", CHOOSE(code!$A$1, code!$B34, code!$C34), K$6, $B$4, "fill=true") -> 4.06 | L40: =_xll.IMDP("IR", CHOOSE(code!$A$1, code!$B34, code!$C34), L$6, $B$4, "fill=true") -> 4.19 | M40: =_xll.IMDP("IR", CHOOSE(code!$A$1, code!$B34, code!$C34), M$6, $B$4, "fill=true") -> 4.4 | N40: =_xll.IMDP("IR", CHOOSE(code!$A$1, code!$B34, code!$C34), N$6, $B$4, "fill=true") -> 5.34
C41: =$C$11 -> KIS | D41: =_xll.IMDP("IR", CHOOSE(code!$A$1, code!$B35, code!$C35), D$6, $B$4, "fill=true") -> 3.72 | E41: =_xll.IMDP("IR", CHOOSE(code!$A$1, code!$B35, code!$C35), E$6, $B$4, "fill=true") -> 3.84 | F41: =IF( _xll.IMDP("IR", CHOOSE(code!$A$1, code!$B35, code!$C35), F$6, $B$4, "fill=true") = 0, "", _xll.IMDP("IR", CHOOSE(code!$A$1, code!$B35, code!$C35), F$6, $B$4, "fill=true") ) | G41: =_xll.IMDP("IR", CHOOSE(code!$A$1, code!$B35, code!$C35), G$6, $B$4, "fill=true") -> 3.9 | H41: =_xll.IMDP("IR", CHOOSE(code!$A$1, code!$B35, code!$C35), H$6, $B$4, "fill=true") -> 3.96 | I41: =_xll.IMDP("IR", CHOOSE(code!$A$1, code!$B35, code!$C35), I$6, $B$4, "fill=true") -> 4 | J41: =_xll.IMDP("IR", CHOOSE(code!$A$1, code!$B35, code!$C35), J$6, $B$4, "fill=true") -> 4.06 | K41: =_xll.IMDP("IR", CHOOSE(code!$A$1, code!$B35, code!$C35), K$6, $B$4, "fill=true") -> 4.12 | L41: =_xll.IMDP("IR", CHOOSE(code!$A$1, code!$B35, code!$C35), L$6, $B$4, "fill=true") -> 4.23 | M41: =_xll.IMDP("IR", CHOOSE(code!$A$1, code!$B35, code!$C35), M$6, $B$4, "fill=true") -> 4.48 | N41: =_xll.IMDP("IR", CHOOSE(code!$A$1, code!$B35, code!$C35), N$6, $B$4, "fill=true") -> 4.88
C42: =$C$12 -> NICE | D42: =_xll.IMDP("IR", CHOOSE(code!$A$1, code!$B36, code!$C36), D$6, $B$4, "fill=true") -> 3.73 | E42: =_xll.IMDP("IR", CHOOSE(code!$A$1, code!$B36, code!$C36), E$6, $B$4, "fill=true") -> 3.83 | F42: =IF( _xll.IMDP("IR", CHOOSE(code!$A$1, code!$B36, code!$C36), F$6, $B$4, "fill=true") = 0, "", _xll.IMDP("IR", CHOOSE(code!$A$1, code!$B36, code!$C36), F$6, $B$4, "fill=true") ) | G42: =_xll.IMDP("IR", CHOOSE(code!$A$1, code!$B36, code!$C36), G$6, $B$4, "fill=true") -> 3.9 | H42: =_xll.IMDP("IR", CHOOSE(code!$A$1, code!$B36, code!$C36), H$6, $B$4, "fill=true") -> 3.95 | I42: =_xll.IMDP("IR", CHOOSE(code!$A$1, code!$B36, code!$C36), I$6, $B$4, "fill=true") -> 4 | J42: =_xll.IMDP("IR", CHOOSE(code!$A$1, code!$B36, code!$C36), J$6, $B$4, "fill=true") -> 4.05 | K42: =_xll.IMDP("IR", CHOOSE(code!$A$1, code!$B36, code!$C36), K$6, $B$4, "fill=true") -> 4.12 | L42: =_xll.IMDP("IR", CHOOSE(code!$A$1, code!$B36, code!$C36), L$6, $B$4, "fill=true") -> 4.21 | M42: =_xll.IMDP("IR", CHOOSE(code!$A$1, code!$B36, code!$C36), M$6, $B$4, "fill=true") -> 4.45 | N42: =_xll.IMDP("IR", CHOOSE(code!$A$1, code!$B36, code!$C36), N$6, $B$4, "fill=true") -> 4.62
C43: =$C$13 -> FN | D43: =_xll.IMDP("IR", CHOOSE(code!$A$1, code!$B37, code!$C37), D$6, $B$4, "fill=true") -> 3.79 | E43: =_xll.IMDP("IR", CHOOSE(code!$A$1, code!$B37, code!$C37), E$6, $B$4, "fill=true") -> 3.85 | F43: =IF( _xll.IMDP("IR", CHOOSE(code!$A$1, code!$B37, code!$C37), F$6, $B$4, "fill=true") = 0, "", _xll.IMDP("IR", CHOOSE(code!$A$1, code!$B37, code!$C37), F$6, $B$4, "fill=true") ) | G43: =_xll.IMDP("IR", CHOOSE(code!$A$1, code!$B37, code!$C37), G$6, $B$4, "fill=true") -> 3.93 | H43: =_xll.IMDP("IR", CHOOSE(code!$A$1, code!$B37, code!$C37), H$6, $B$4, "fill=true") -> 3.96 | I43: =_xll.IMDP("IR", CHOOSE(code!$A$1, code!$B37, code!$C37), I$6, $B$4, "fill=true") -> 4 | J43: =_xll.IMDP("IR", CHOOSE(code!$A$1, code!$B37, code!$C37), J$6, $B$4, "fill=true") -> 4.04 | K43: =_xll.IMDP("IR", CHOOSE(code!$A$1, code!$B37, code!$C37), K$6, $B$4, "fill=true") -> 4.09 | L43: =_xll.IMDP("IR", CHOOSE(code!$A$1, code!$B37, code!$C37), L$6, $B$4, "fill=true") -> 4.37 | M43: =_xll.IMDP("IR", CHOOSE(code!$A$1, code!$B37, code!$C37), M$6, $B$4, "fill=true") -> 4.53 | N43: =_xll.IMDP("IR", CHOOSE(code!$A$1, code!$B37, code!$C37), N$6, $B$4, "fill=true") -> 4.64
...

Sheet CD|CP 일별추이
B2: CD/CP 일별 추이
C4: =E4-365 -> 44754 | D4: ~ | E4: =TODAY() -> 45119
B5: =_xll.IMDH("IR", code!$E$12, $B$6:$V$6, $C$4, $E$4, 9999, "Bizday=0, Per=일, Sort=D, real=false, Pos=30, Orient=V, DtFmt=1") -> 조회[CDYLDAVG1]
B6: 일자 | C6: 1일(적용일) | D6: 1일(전일대비) | E6: 1주(적용일) | F6: 1주(전일대비) | G6: 15일(적용일) | H6: 15일(전일대비) | I6: 1월(적용일) | J6: 1월(전일대비) | K6: 2월(적용일) | L6: 2월(전일대비) | M6: 3월(적용일) | N6: 3월(전일대비) | O6: 4월(적용일) | P6: 4월(전일대비) | Q6: 6월(적용일) | R6: 6월(전일대비) | S6: 1년(적용일) | T6: 1년(전일대비) | U6: 2년(적용일) | V6: 2년(전일대비)
C7: 1일 | D7: 등락 | E7: 1주 | F7: 등락 | G7: 15일 | H7: 등락 | I7: 1월 | J7: 등락 | K7: 2월 | L7: 등락 | M7: 3월 | N7: 등락 | O7: 4월 | P7: 등락 | Q7: 6월 | R7: 등락 | S7: 1년 | T7: 등락 | U7: 2년 | V7: 등락
B8: 45118 | C8: 3.5 | D8: 0 | E8: 3.56 | F8: 0 | G8: 3.63 | H8: 0 | I8: 3.69 | J8: 0 | K8: 3.72 | L8: 0 | M8: 3.75 | N8: 0 | O8: 3.76 | P8: 0 | Q8: 3.8 | R8: 0 | S8: 3.89 | T8: -0.01 | U8: 4.34 | V8: -0.01
B9: 45117 | C9: 3.5 | D9: 0 | E9: 3.56 | F9: 0 | G9: 3.63 | H9: 0 | I9: 3.69 | J9: 0 | K9: 3.72 | L9: 0 | M9: 3.75 | N9: 0 | O9: 3.76 | P9: 0 | Q9: 3.8 | R9: 0 | S9: 3.9 | T9: 0.01 | U9: 4.35 | V9: 0.01
B10: 45114 | C10: 3.5 | D10: 0 | E10: 3.56 | F10: 0 | G10: 3.63 | H10: 0 | I10: 3.69 | J10: 0 | K10: 3.72 | L10: 0 | M10: 3.75 | N10: 0.01 | O10: 3.76 | P10: 0 | Q10: 3.8 | R10: 0 | S10: 3.89 | T10: 0 | U10: 4.34 | V10: 0
B11: 45113 | C11: 3.5 | D11: 0.01 | E11: 3.56 | F11: 0 | G11: 3.63 | H11: 0 | I11: 3.69 | J11: 0 | K11: 3.72 | L11: 0 | M11: 3.74 | N11: 0 | O11: 3.76 | P11: 0.01 | Q11: 3.8 | R11: 0 | S11: 3.89 | T11: 0 | U11: 4.34 | V11: 0.02
B12: 45112 | C12: 3.49 | D12: 0 | E12: 3.56 | F12: 0 | G12: 3.63 | H12: 0 | I12: 3.69 | J12: 0 | K12: 3.72 | L12: 0 | M12: 3.74 | N12: 0 | O12: 3.75 | P12: 0 | Q12: 3.8 | R12: 0 | S12: 3.89 | T12: 0 | U12: 4.32 | V12: 0
B13: 45111 | C13: 3.49 | D13: -0.01 | E13: 3.56 | F13: -0.01 | G13: 3.63 | H13: -0.01 | I13: 3.69 | J13: -0.01 | K13: 3.72 | L13: -0.01 | M13: 3.74 | N13: -0.01 | O13: 3.75 | P13: -0.01 | Q13: 3.8 | R13: 0 | S13: 3.89 | T13: 0 | U13: 4.32 | V13: 0
B14: 45110 | C14: 3.5 | D14: 0 | E14: 3.57 | F14: 0 | G14: 3.64 | H14: 0 | I14: 3.7 | J14: 0 | K14: 3.73 | L14: 0 | M14: 3.75 | N14: 0 | O14: 3.76 | P14: 0 | Q14: 3.8 | R14: 0 | S14: 3.89 | T14: 0.01 | U14: 4.32 | V14: 0
B15: 45107 | C15: 3.5 | D15: 0.01 | E15: 3.57 | F15: 0.01 | G15: 3.64 | H15: 0 | I15: 3.7 | J15: 0 | K15: 3.73 | L15: 0 | M15: 3.75 | N15: 0 | O15: 3.76 | P15: 0 | Q15: 3.8 | R15: 0 | S15: 3.88 | T15: 0 | U15: 4.32 | V15: 0.01
B16: 45106 | C16: 3.49 | D16: 0 | E16: 3.56 | F16: 0 | G16: 3.64 | H16: 0.01 | I16: 3.7 | J16: 0 | K16: 3.73 | L16: 0.01 | M16: 3.75 | N16: 0 | O16: 3.76 | P16: -0.01 | Q16: 3.8 | R16: 0 | S16: 3.88 | T16: 0 | U16: 4.31 | V16: 0
B17: 45105 | C17: 3.49 | D17: 0 | E17: 3.56 | F17: 0.01 | G17: 3.63 | H17: 0.01 | I17: 3.7 | J17: 0.01 | K17: 3.72 | L17: 0 | M17: 3.75 | N17: 0 | O17: 3.77 | P17: 0 | Q17: 3.8 | R17: 0 | S17: 3.88 | T17: 0 | U17: 4.31 | V17: 0.01
B18: 45104 | C18: 3.49 | D18: 0 | E18: 3.55 | F18: 0 | G18: 3.62 | H18: 0 | I18: 3.69 | J18: 0 | K18: 3.72 | L18: 0 | M18: 3.75 | N18: 0 | O18: 3.77 | P18: 0 | Q18: 3.8 | R18: 0.01 | S18: 3.88 | T18: 0.01 | U18: 4.3 | V18: 0
B19: 45103 | C19: 3.49 | D19: 0 | E19: 3.55 | F19: 0 | G19: 3.62 | H19: 0.01 | I19: 3.69 | J19: 0.01 | K19: 3.72 | L19: 0 | M19: 3.75 | N19: 0 | O19: 3.77 | P19: 0.01 | Q19: 3.79 | R19: 0 | S19: 3.87 | T19: 0 | U19: 4.3 | V19: -0.01
... B256: 44754 | C256: 1.77 | D256: 0.03 | E256: 1.85 | F256: 0.01 | G256: 1.92 | H256: 0.02 | I256: 1.99 | J256: 0.03 | K256: 2.04 | L256: 0.03 | M256: 2.14 | N256: 0.02 | O256: 2.37 | P256: 0.03 | Q256: 2.77 | R256: 0.03 | S256: 3.56 | T256: 0.04 | U256: 3.66 | V256: 0.03

Sheet CD|CP 발행사
C2: 발행사별 Term Structure | F2: ※리스트 로드시 시간이 걸릴 수 있습니다
C4: =TODAY()-1 -> 45118 | Q4: ="기관 수: "&COUNT($C$7:$C$306) -> 기관 수: 15
B6: 코드 | C6: 일자 | D6: 기관코드 | E6: 회사명 | F6: 신용등급 | G6: 1일 | H6: 1주 | I6: 10일 | J6: 15일 | K6: 1월 | L6: 2월 | M6: 3월 | N6: 4월 | O6: 6월 | P6: 1년 | Q6: 2년
B7: =IFERROR( VLOOKUP(ROW()-ROW($B$6), code!$G$51:$K$1483, 5, 0), "") -> CDAVG00001 | C7: =IF($B7="", "", _xll.IMDP("IR", $B7, "1일", $C$4, "fill=true, disp=date")) -> 20230711 | D7: =IF($B7="", "", VLOOKUP(ROW()-ROW($B$6), code!$G$51:$K$1483, 2, 0) ) -> 00001 | E7: =IF($B7="", "", VLOOKUP(ROW()-ROW($B$6), code!$G$51:$K$1483, 3, 0) ) -> 신한은행 | F7: =IF($B7="", "", VLOOKUP(ROW()-ROW($B$6), code!$G$51:$K$1483, 4, 0)) -> AAA | G7: =IF($B7="", "", IF(_xll.IMDP("IR", $B7, G$6, $C$4, "fill=true")=0, "", _xll.IMDP("IR", $B7, G$6, $C$4, "fill=true"))) -> 3.5 | H7: =IF($B7="", "", IF(_xll.IMDP("IR", $B7, H$6, $C$4, "fill=true")=0, "", _xll.IMDP("IR", $B7, H$6, $C$4, "fill=true"))) -> 3.56 | I7: =IF($B7="", "", IF(_xll.IMDP("IR", $B7, I$6, $C$4, "fill=true")=0, "", _xll.IMDP("IR", $B7, I$6, $C$4, "fill=true"))) | J7: =IF($B7="", "", IF(_xll.IMDP("IR", $B7, J$6, $C$4, "fill=true")=0, "", _xll.IMDP("IR", $B7, J$6, $C$4, "fill=true"))) -> 3.63 | K7: =IF($B7="", "", IF(_xll.IMDP("IR", $B7, K$6, $C$4, "fill=true")=0, "", _xll.IMDP("IR", $B7, K$6, $C$4, "fill=true"))) -> 3.69 | L7: =IF($B7="", "", IF(_xll.IMDP("IR", $B7, L$6, $C$4, "fill=true")=0, "", _xll.IMDP("IR", $B7, L$6, $C$4, "fill=true"))) -> 3.72 | M7: =IF($B7="", "", IF(_xll.IMDP("IR", $B7, M$6, $C$4, "fill=true")=0, "", _xll.IMDP("IR", $B7, M$6, $C$4, "fill=true"))) -> 3.74 | N7: =IF($B7="", "", IF(_xll.IMDP("IR", $B7, N$6, $C$4, "fill=true")=0, "", _xll.IMDP("IR", $B7, N$6, $C$4, "fill=true"))) -> 3.76 | ... Q7: =IF($B7="", "", IF(_xll.IMDP("IR", $B7, Q$6, $C$4, "fill=true")=0, "", _xll.IMDP("IR", $B7, Q$6, $C$4, "fill=true"))) -> 4.21
B8: =IFERROR( VLOOKUP(ROW()-ROW($B$6), code!$G$51:$K$1483, 5, 0), "") -> CDAVG00011 | C8: =IF($B8="", "", _xll.IMDP("IR", $B8, "1일", $C$4, "fill=true, disp=date")) -> 20230711 | D8: =IF($B8="", "", VLOOKUP(ROW()-ROW($B$6), code!$G$51:$K$1483, 2, 0) ) -> 00011 | E8: =IF($B8="", "", VLOOKUP(ROW()-ROW($B$6), code!$G$51:$K$1483, 3, 0) ) -> 스탠다드차타드은행 | F8: =IF($B8="", "", VLOOKUP(ROW()-ROW($B$6), code!$G$51:$K$1483, 4, 0)) -> AAA | G8: =IF($B8="", "", IF(_xll.IMDP("IR", $B8, G$6, $C$4, "fill=true")=0, "", _xll.IMDP("IR", $B8, G$6, $C$4, "fill=true"))) -> 3.5 | H8: =IF($B8="", "", IF(_xll.IMDP("IR", $B8, H$6, $C$4, "fill=true")=0, "", _xll.IMDP("IR", $B8, H$6, $C$4, "fill=true"))) -> 3.56 | I8: =IF($B8="", "", IF(_xll.IMDP("IR", $B8, I$6, $C$4, "fill=true")=0, "", _xll.IMDP("IR", $B8, I$6, $C$4, "fill=true"))) | J8: =IF($B8="", "", IF(_xll.IMDP("IR", $B8, J$6, $C$4, "fill=true")=0, "", _xll.IMDP("IR", $B8, J$6, $C$4, "fill=true"))) -> 3.63 | K8: =IF($B8="", "", IF(_xll.IMDP("IR", $B8, K$6, $C$4, "fill=true")=0, "", _xll.IMDP("IR", $B8, K$6, $C$4, "fill=true"))) -> 3.69 | L8: =IF($B8="", "", IF(_xll.IMDP("IR", $B8, L$6, $C$4, "fill=true")=0, "", _xll.IMDP("IR", $B8, L$6, $C$4, "fill=true"))) -> 3.72 | M8: =IF($B8="", "", IF(_xll.IMDP("IR", $B8, M$6, $C$4, "fill=true")=0, "", _xll.IMDP("IR", $B8, M$6, $C$4, "fill=true"))) -> 3.74 | N8: =IF($B8="", "", IF(_xll.IMDP("IR", $B8, N$6, $C$4, "fill=true")=0, "", _xll.IMDP("IR", $B8, N$6, $C$4, "fill=true"))) -> 3.76 | ... Q8: =IF($B8="", "", IF(_xll.IMDP("IR", $B8, Q$6, $C$4, "fill=true")=0, "", _xll.IMDP("IR", $B8, Q$6, $C$4, "fill=true"))) -> 4.21
B9: =IFERROR( VLOOKUP(ROW()-ROW($B$6), code!$G$51:$K$1483, 5, 0), "") -> CDAVG00494 | C9: =IF($B9="", "", _xll.IMDP("IR", $B9, "1일", $C$4, "fill=true, disp=date")) -> 20230711 | D9: =IF($B9="", "", VLOOKUP(ROW()-ROW($B$6), code!$G$51:$K$1483, 2, 0) ) -> 00494 | E9: =IF($B9="", "", VLOOKUP(ROW()-ROW($B$6), code!$G$51:$K$1483, 3, 0) ) -> 하나은행 | F9: =IF($B9="", "", VLOOKUP(ROW()-ROW($B$6), code!$G$51:$K$1483, 4, 0)) -> AAA | G9: =IF($B9="", "", IF(_xll.IMDP("IR", $B9, G$6, $C$4, "fill=true")=0, "", _xll.IMDP("IR", $B9, G$6, $C$4, "fill=true"))) -> 3.5 | H9: =IF($B9="", "", IF(_xll.IMDP("IR", $B9, H$6, $C$4, "fill=true")=0, "", _xll.IMDP("IR", $B9, H$6, $C$4, "fill=true"))) -> 3.56 | I9: =IF($B9="", "", IF(_xll.IMDP("IR", $B9, I$6, $C$4, "fill=true")=0, "", _xll.IMDP("IR", $B9, I$6, $C$4, "fill=true"))) | J9: =IF($B9="", "", IF(_xll.IMDP("IR", $B9, J$6, $C$4, "fill=true")=0, "", _xll.IMDP("IR", $B9, J$6, $C$4, "fill=true"))) -> 3.63 | K9: =IF($B9="", "", IF(_xll.IMDP("IR", $B9, K$6, $C$4, "fill=true")=0, "", _xll.IMDP("IR", $B9, K$6, $C$4, "fill=true"))) -> 3.69 | L9: =IF($B9="", "", IF(_xll.IMDP("IR", $B9, L$6, $C$4, "fill=true")=0, "", _xll.IMDP("IR", $B9, L$6, $C$4, "fill=true"))) -> 3.72 | M9: =IF($B9="", "", IF(_xll.IMDP("IR", $B9, M$6, $C$4, "fill=true")=0, "", _xll.IMDP("IR", $B9, M$6, $C$4, "fill=true"))) -> 3.75 | N9: =IF($B9="", "", IF(_xll.IMDP("IR", $B9, N$6, $C$4, "fill=true")=0, "", _xll.IMDP("IR", $B9, N$6, $C$4, "fill=true"))) -> 3.76 | ... Q9: =IF($B9="", "", IF(_xll.IMDP("IR", $B9, Q$6, $C$4, "fill=true")=0, "", _xll.IMDP("IR", $B9, Q$6, $C$4, "fill=true"))) -> 4.21
