Workbook

Sheet 시가평가_계산
B2: 종목별 시가평가 계산
B4: KR103501GCC0 | D4: {=_xll.IMDP("BND", $B$4, "한글종목명")} -> 국고04250-2512(22-13)
B5: =TODAY() -> 45792
I7: KAP | K7: KIS | M7: NICE | O7: FN | Q7: 이론가
B8: 일자 | C8: 요일 | D8: 수익률 | E8: 대비(bp) | F8: 가격 | G8: 대비 | H8: M.dur | I8: 수익률 | J8: 가격 | K8: 수익률 | L8: 가격 | M8: 수익률 | N8: 가격 | O8: 수익률 | P8: 가격 | Q8: 결제일 | R8: 요일 | S8: 세전단가 | T8: CleanPrice | U8: 경과이자 | V8: bpv
B9: =IF(data!A5="", "", data!A5) -> 45792 | C9: =IF( $B9="", "", INDEX( data!$U$2:$U$8, WEEKDAY($B9) ) ) -> 목 | D9: =IF( $B9="", "", CHOOSE(data!$V$1, data!B5, data!E5, data!V5) ) -> 2.42 | E9: =IF($B10="", "", (D9-D10)*100) -> -1 | F9: =IF( $B9="", "", CHOOSE(data!$V$1, data!C5, data!F5, data!W5) ) -> 10285.12 | G9: =IF($B10="", "", (F9-F10) ) -> 1.25 | H9: =IF( $B9="", "", CHOOSE(data!$V$1, data!D5, data!G5, data!X5) ) -> 0.5563 | I9: =IF(data!H5="", "", data!H5) -> 2.42 | J9: =IF(data!I5="", "", data!I5) -> 10285.12 | K9: =IF(data!J5="", "", data!J5) -> 2.42 | L9: =IF(data!K5="", "", data!K5) -> 10285.12 | M9: =IF(data!L5="", "", data!L5) -> 2.42 | N9: =IF(data!M5="", "", data!M5) -> 10285.12 | O9: =IF(data!N5="", "", data!N5) -> 2.42 | P9: =IF(data!O5="", "", data!O5) -> 10285.12 | Q9: =WORKDAY($B9, data!$AL$1, data!AM5:$AM$2041) -> 45793 | R9: =IF( $Q9="", "", INDEX( data!$U$2:$U$8, WEEKDAY($Q9) ) ) -> 금 | S9: =_xll.IMBC($B$4, S$8, $Q9, $D9, "세전수익률") -> 10285.81 | T9: =_xll.IMBC($B$4, T$8, $Q9, $D9, "세전수익률") -> 10102.5 | U9: =_xll.IMBC($B$4, U$8, $Q9, $D9, "세전수익률") -> 183.3104 | V9: =_xll.IMBC($B$4, V$8, $Q9, $D9, "세전수익률") -> 0.5675
B10: =IF(data!A6="", "", data!A6) -> 45791 | C10: =IF( $B10="", "", INDEX( data!$U$2:$U$8, WEEKDAY($B10) ) ) -> 수 | D10: =IF( $B10="", "", CHOOSE(data!$V$1, data!B6, data!E6, data!V6) ) -> 2.43 | E10: =IF($B11="", "", (D10-D11)*100) -> 0 | F10: =IF( $B10="", "", CHOOSE(data!$V$1, data!C6, data!F6, data!W6) ) -> 10283.87 | G10: =IF($B11="", "", (F10-F11) ) -> 0.69 | H10: =IF( $B10="", "", CHOOSE(data!$V$1, data!D6, data!G6, data!X6) ) -> 0.559 | I10: =IF(data!H6="", "", data!H6) -> 2.43 | J10: =IF(data!I6="", "", data!I6) -> 10283.87 | K10: =IF(data!J6="", "", data!J6) -> 2.43 | L10: =IF(data!K6="", "", data!K6) -> 10283.87 | M10: =IF(data!L6="", "", data!L6) -> 2.425 | N10: =IF(data!M6="", "", data!M6) -> 10284.15 | O10: =IF(data!N6="", "", data!N6) -> 2.43 | P10: =IF(data!O6="", "", data!O6) -> 10283.87 | Q10: =WORKDAY($B10, data!$AL$1, data!AM6:$AM$2041) -> 45792 | R10: =IF( $Q10="", "", INDEX( data!$U$2:$U$8, WEEKDAY($Q10) ) ) -> 목 | S10: =_xll.IMBC($B$4, S$8, $Q10, $D10, "세전수익률") -> 10284.55 | T10: =_xll.IMBC($B$4, T$8, $Q10, $D10, "세전수익률") -> 10102.414 | U10: =_xll.IMBC($B$4, U$8, $Q10, $D10, "세전수익률") -> 182.1428 | V10: =_xll.IMBC($B$4, V$8, $Q10, $D10, "세전수익률") -> 0.5702
B11: =IF(data!A7="", "", data!A7) -> 45790 | C11: =IF( $B11="", "", INDEX( data!$U$2:$U$8, WEEKDAY($B11) ) ) -> 화 | D11: =IF( $B11="", "", CHOOSE(data!$V$1, data!B7, data!E7, data!V7) ) -> 2.43 | E11: =IF($B12="", "", (D11-D12)*100) -> -0.5 | F11: =IF( $B11="", "", CHOOSE(data!$V$1, data!C7, data!F7, data!W7) ) -> 10283.18 | G11: =IF($B12="", "", (F11-F12) ) -> 0.97 | H11: =IF( $B11="", "", CHOOSE(data!$V$1, data!D7, data!G7, data!X7) ) -> 0.5617 | I11: =IF(data!H7="", "", data!H7) -> 2.43 | J11: =IF(data!I7="", "", data!I7) -> 10283.18 | K11: =IF(data!J7="", "", data!J7) -> 2.43 | L11: =IF(data!K7="", "", data!K7) -> 10283.18 | M11: =IF(data!L7="", "", data!L7) -> 2.42 | N11: =IF(data!M7="", "", data!M7) -> 10283.76 | O11: =IF(data!N7="", "", data!N7) -> 2.43 | P11: =IF(data!O7="", "", data!O7) -> 10283.18 | Q11: =WORKDAY($B11, data!$AL$1, data!AM7:$AM$2041) -> 45791 | R11: =IF( $Q11="", "", INDEX( data!$U$2:$U$8, WEEKDAY($Q11) ) ) -> 수 | S11: =_xll.IMBC($B$4, S$8, $Q11, $D11, "세전수익률") -> 10283.87 | T11: =_xll.IMBC($B$4, T$8, $Q11, $D11, "세전수익률") -> 10102.896 | U11: =_xll.IMBC($B$4, U$8, $Q11, $D11, "세전수익률") -> 180.9752 | V11: =_xll.IMBC($B$4, V$8, $Q11, $D11, "세전수익률") -> 0.5729
B12: =IF(data!A8="", "", data!A8) -> 45789 | C12: =IF( $B12="", "", INDEX( data!$U$2:$U$8, WEEKDAY($B12) ) ) -> 월 | D12: =IF( $B12="", "", CHOOSE(data!$V$1, data!B8, data!E8, data!V8) ) -> 2.435 | E12: =IF($B13="", "", (D12-D13)*100) -> 0 | F12: =IF( $B12="", "", CHOOSE(data!$V$1, data!C8, data!F8, data!W8) ) -> 10282.21 | G12: =IF($B13="", "", (F12-F13) ) -> 0.69 | H12: =IF( $B12="", "", CHOOSE(data!$V$1, data!D8, data!G8, data!X8) ) -> 0.56715 | I12: =IF(data!H8="", "", data!H8) -> 2.435 | J12: =IF(data!I8="", "", data!I8) -> 10282.21 | K12: =IF(data!J8="", "", data!J8) -> 2.435 | L12: =IF(data!K8="", "", data!K8) -> 10282.21 | M12: =IF(data!L8="", "", data!L8) -> 2.425 | N12: =IF(data!M8="", "", data!M8) -> 10282.79 | O12: =IF(data!N8="", "", data!N8) -> 2.435 | P12: =IF(data!O8="", "", data!O8) -> 10282.21 | Q12: =WORKDAY($B12, data!$AL$1, data!AM8:$AM$2041) -> 45790 | R12: =IF( $Q12="", "", INDEX( data!$U$2:$U$8, WEEKDAY($Q12) ) ) -> 화 | S12: =_xll.IMBC($B$4, S$8, $Q12, $D12, "세전수익률") -> 10282.89 | T12: =_xll.IMBC($B$4, T$8, $Q12, $D12, "세전수익률") -> 10103.09 | U12: =_xll.IMBC($B$4, U$8, $Q12, $D12, "세전수익률") -> 179.8076 | V12: =_xll.IMBC($B$4, V$8, $Q12, $D12, "세전수익률") -> 0.5756
B13: =IF(data!A9="", "", data!A9) -> 45788 | C13: =IF( $B13="", "", INDEX( data!$U$2:$U$8, WEEKDAY($B13) ) ) -> 일 | D13: =IF( $B13="", "", CHOOSE(data!$V$1, data!B9, data!E9, data!V9) ) -> 2.435 | E13: =IF($B14="", "", (D13-D14)*100) -> 0 | F13: =IF( $B13="", "", CHOOSE(data!$V$1, data!C9, data!F9, data!W9) ) -> 10281.52 | G13: =IF($B14="", "", (F13-F14) ) -> 0.69 | H13: =IF( $B13="", "", CHOOSE(data!$V$1, data!D9, data!G9, data!X9) ) -> 0.5685 | I13: =IF(data!H9="", "", data!H9) -> 2.435 | J13: =IF(data!I9="", "", data!I9) -> 10281.52 | K13: =IF(data!J9="", "", data!J9) -> 2.435 | L13: =IF(data!K9="", "", data!K9) -> 10281.52 | M13: =IF(data!L9="", "", data!L9) -> 2.425 | N13: =IF(data!M9="", "", data!M9) -> 10282.1 | O13: =IF(data!N9="", "", data!N9) -> 2.435 | P13: =IF(data!O9="", "", data!O9) -> 10281.52 | Q13: =WORKDAY($B13, data!$AL$1, data!AM9:$AM$2041) -> 45789 | R13: =IF( $Q13="", "", INDEX( data!$U$2:$U$8, WEEKDAY($Q13) ) ) -> 월 | S13: =_xll.IMBC($B$4, S$8, $Q13, $D13, "세전수익률") -> 10282.21 | T13: =_xll.IMBC($B$4, T$8, $Q13, $D13, "세전수익률") -> 10103.571 | U13: =_xll.IMBC($B$4, U$8, $Q13, $D13, "세전수익률") -> 178.6401 | V13: =_xll.IMBC($B$4, V$8, $Q13, $D13, "세전수익률") -> 0.5784
B14: =IF(data!A10="", "", data!A10) -> 45787 | C14: =IF( $B14="", "", INDEX( data!$U$2:$U$8, WEEKDAY($B14) ) ) -> 토 | D14: =IF( $B14="", "", CHOOSE(data!$V$1, data!B10, data!E10, data!V10) ) -> 2.435 | E14: =IF($B15="", "", (D14-D15)*100) -> 0 | F14: =IF( $B14="", "", CHOOSE(data!$V$1, data!C10, data!F10, data!W10) ) -> 10280.83 | G14: =IF($B15="", "", (F14-F15) ) -> 0.68 | H14: =IF( $B14="", "", CHOOSE(data!$V$1, data!D10, data!G10, data!X10) ) -> 0.56985 | I14: =IF(data!H10="", "", data!H10) -> 2.435 | J14: =IF(data!I10="", "", data!I10) -> 10280.83 | K14: =IF(data!J10="", "", data!J10) -> 2.435 | L14: =IF(data!K10="", "", data!K10) -> 10280.83 | M14: =IF(data!L10="", "", data!L10) -> 2.425 | N14: =IF(data!M10="", "", data!M10) -> 10281.42 | O14: =IF(data!N10="", "", data!N10) -> 2.435 | P14: =IF(data!O10="", "", data!O10) -> 10280.83 | Q14: =WORKDAY($B14, data!$AL$1, data!AM10:$AM$2041) -> 45789 | R14: =IF( $Q14="", "", INDEX( data!$U$2:$U$8, WEEKDAY($Q14) ) ) -> 월 | S14: =_xll.IMBC($B$4, S$8, $Q14, $D14, "세전수익률") -> 10282.21 | T14: =_xll.IMBC($B$4, T$8, $Q14, $D14, "세전수익률") -> 10103.571 | U14: =_xll.IMBC($B$4, U$8, $Q14, $D14, "세전수익률") -> 178.6401 | V14: =_xll.IMBC($B$4, V$8, $Q14, $D14, "세전수익률") -> 0.5784
B15: =IF(data!A11="", "", data!A11) -> 45786 | C15: =IF( $B15="", "", INDEX( data!$U$2:$U$8, WEEKDAY($B15) ) ) -> 금 | D15: =IF( $B15="", "", CHOOSE(data!$V$1, data!B11, data!E11, data!V11) ) -> 2.435 | E15: =IF($B16="", "", (D15-D16)*100) -> 0.5 | F15: =IF( $B15="", "", CHOOSE(data!$V$1, data!C11, data!F11, data!W11) ) -> 10280.15 | G15: =IF($B16="", "", (F15-F16) ) -> 0.39 | H15: =IF( $B15="", "", CHOOSE(data!$V$1, data!D11, data!G11, data!X11) ) -> 0.57255 | I15: =IF(data!H11="", "", data!H11) -> 2.435 | J15: =IF(data!I11="", "", data!I11) -> 10280.15 | K15: =IF(data!J11="", "", data!J11) -> 2.435 | L15: =IF(data!K11="", "", data!K11) -> 10280.15 | M15: =IF(data!L11="", "", data!L11) -> 2.435 | N15: =IF(data!M11="", "", data!M11) -> 10280.15 | O15: =IF(data!N11="", "", data!N11) -> 2.435 | P15: =IF(data!O11="", "", data!O11) -> 10280.15 | Q15: =WORKDAY($B15, data!$AL$1, data!AM11:$AM$2041) -> 45789 | R15: =IF( $Q15="", "", INDEX( data!$U$2:$U$8, WEEKDAY($Q15) ) ) -> 월 | S15: =_xll.IMBC($B$4, S$8, $Q15, $D15, "세전수익률") -> 10282.21 | T15: =_xll.IMBC($B$4, T$8, $Q15, $D15, "세전수익률") -> 10103.571 | U15: =_xll.IMBC($B$4, U$8, $Q15, $D15, "세전수익률") -> 178.6401 | V15: =_xll.IMBC($B$4, V$8, $Q15, $D15, "세전수익률") -> 0.5784
B16: =IF(data!A12="", "", data!A12) -> 45785 | C16: =IF( $B16="", "", INDEX( data!$U$2:$U$8, WEEKDAY($B16) ) ) -> 목 | D16: =IF( $B16="", "", CHOOSE(data!$V$1, data!B12, data!E12, data!V12) ) -> 2.43 | E16: =IF($B17="", "", (D16-D17)*100) -> -2 | F16: =IF( $B16="", "", CHOOSE(data!$V$1, data!C12, data!F12, data!W12) ) -> 10279.76 | G16: =IF($B17="", "", (F16-F17) ) -> 1.87 | H16: =IF( $B16="", "", CHOOSE(data!$V$1, data!D12, data!G12, data!X12) ) -> 0.5753 | I16: =IF(data!H12="", "", data!H12) -> 2.43 | J16: =IF(data!I12="", "", data!I12) -> 10279.76 | K16: =IF(data!J12="", "", data!J12) -> 2.43 | L16: =IF(data!K12="", "", data!K12) -> 10279.76 | M16: =IF(data!L12="", "", data!L12) -> 2.42 | N16: =IF(data!M12="", "", data!M12) -> 10280.35 | O16: =IF(data!N12="", "", data!N12) -> 2.43 | P16: =IF(data!O12="", "", data!O12) -> 10279.76 | Q16: =WORKDAY($B16, data!$AL$1, data!AM12:$AM$2041) -> 45786 | R16: =IF( $Q16="", "", INDEX( data!$U$2:$U$8, WEEKDAY($Q16) ) ) -> 금 | S16: =_xll.IMBC($B$4, S$8, $Q16, $D16, "세전수익률") -> 10280.44 | T16: =_xll.IMBC($B$4, T$8, $Q16, $D16, "세전수익률") -> 10105.308 | U16: =_xll.IMBC($B$4, U$8, $Q16, $D16, "세전수익률") -> 175.1373 | V16: =_xll.IMBC($B$4, V$8, $Q16, $D16, "세전수익률") -> 0.5867
B17: =IF(data!A13="", "", data!A13) -> 45784 | C17: =IF( $B17="", "", INDEX( data!$U$2:$U$8, WEEKDAY($B17) ) ) -> 수 | D17: =IF( $B17="", "", CHOOSE(data!$V$1, data!B13, data!E13, data!V13) ) -> 2.45 | E17: =IF($B18="", "", (D17-D18)*100) -> 0 | F17: =IF( $B17="", "", CHOOSE(data!$V$1, data!C13, data!F13, data!W13) ) -> 10277.89 | G17: =IF($B18="", "", (F17-F18) ) -> 0.69 | H17: =IF( $B17="", "", CHOOSE(data!$V$1, data!D13, data!G13, data!X13) ) -> 0.58335 | I17: =IF(data!H13="", "", data!H13) -> 2.45 | J17: =IF(data!I13="", "", data!I13) -> 10277.89 | K17: =IF(data!J13="", "", data!J13) -> 2.45 | L17: =IF(data!K13="", "", data!K13) -> 10277.89 | M17: =IF(data!L13="", "", data!L13) -> 2.425 | N17: =IF(data!M13="", "", data!M13) -> 10279.37 | O17: =IF(data!N13="", "", data!N13) -> 2.45 | P17: =IF(data!O13="", "", data!O13) -> 10277.89 | Q17: =WORKDAY($B17, data!$AL$1, data!AM13:$AM$2041) -> 45785 | R17: =IF( $Q17="", "", INDEX( data!$U$2:$U$8, WEEKDAY($Q17) ) ) -> 목 | S17: =_xll.IMBC($B$4, S$8, $Q17, $D17, "세전수익률") -> 10278.58 | T17: =_xll.IMBC($B$4, T$8, $Q17, $D17, "세전수익률") -> 10104.611 | U17: =_xll.IMBC($B$4, U$8, $Q17, $D17, "세전수익률") -> 173.9697 | V17: =_xll.IMBC($B$4, V$8, $Q17, $D17, "세전수익률") -> 0.5893
B18: =IF(data!A14="", "", data!A14) -> 45783 | C18: =IF( $B18="", "", INDEX( data!$U$2:$U$8, WEEKDAY($B18) ) ) -> 화 | D18: =IF( $B18="", "", CHOOSE(data!$V$1, data!B14, data!E14, data!V14) ) -> 2.45 | E18: =IF($B19="", "", (D18-D19)*100) -> 0 | F18: =IF( $B18="", "", CHOOSE(data!$V$1, data!C14, data!F14, data!W14) ) -> 10277.2 | G18: =IF($B19="", "", (F18-F19) ) -> 0.69 | H18: =IF( $B18="", "", CHOOSE(data!$V$1, data!D14, data!G14, data!X14) ) -> 0.5847 | I18: =IF(data!H14="", "", data!H14) -> 2.45 | J18: =IF(data!I14="", "", data!I14) -> 10277.2 | K18: =IF(data!J14="", "", data!J14) -> 2.45 | L18: =IF(data!K14="", "", data!K14) -> 10277.2 | M18: =IF(data!L14="", "", data!L14) -> 2.425 | N18: =IF(data!M14="", "", data!M14) -> 10278.68 | O18: =IF(data!N14="", "", data!N14) -> 2.45 | P18: =IF(data!O14="", "", data!O14) -> 10277.2 | Q18: =WORKDAY($B18, data!$AL$1, data!AM14:$AM$2041) -> 45785 | R18: =IF( $Q18="", "", INDEX( data!$U$2:$U$8, WEEKDAY($Q18) ) ) -> 목 | S18: =_xll.IMBC($B$4, S$8, $Q18, $D18, "세전수익률") -> 10278.58 | T18: =_xll.IMBC($B$4, T$8, $Q18, $D18, "세전수익률") -> 10104.611 | U18: =_xll.IMBC($B$4, U$8, $Q18, $D18, "세전수익률") -> 173.9697 | V18: =_xll.IMBC($B$4, V$8, $Q18, $D18, "세전수익률") -> 0.5893
B19: =IF(data!A15="", "", data!A15) -> 45782 | C19: =IF( $B19="", "", INDEX( data!$U$2:$U$8, WEEKDAY($B19) ) ) -> 월 | D19: =IF( $B19="", "", CHOOSE(data!$V$1, data!B15, data!E15, data!V15) ) -> 2.45 | E19: =IF($B20="", "", (D19-D20)*100) -> 0 | F19: =IF( $B19="", "", CHOOSE(data!$V$1, data!C15, data!F15, data!W15) ) -> 10276.51 | G19: =IF($B20="", "", (F19-F20) ) -> 0.69 | H19: =IF( $B19="", "", CHOOSE(data!$V$1, data!D15, data!G15, data!X15) ) -> 0.58605 | I19: =IF(data!H15="", "", data!H15) -> 2.45 | J19: =IF(data!I15="", "", data!I15) -> 10276.51 | K19: =IF(data!J15="", "", data!J15) -> 2.45 | L19: =IF(data!K15="", "", data!K15) -> 10276.51 | M19: =IF(data!L15="", "", data!L15) -> 2.425 | N19: =IF(data!M15="", "", data!M15) -> 10278 | O19: =IF(data!N15="", "", data!N15) -> 2.45 | P19: =IF(data!O15="", "", data!O15) -> 10276.51 | Q19: =WORKDAY($B19, data!$AL$1, data!AM15:$AM$2041) -> 45785 | R19: =IF( $Q19="", "", INDEX( data!$U$2:$U$8, WEEKDAY($Q19) ) ) -> 목 | S19: =_xll.IMBC($B$4, S$8, $Q19, $D19, "세전수익률") -> 10278.58 | T19: =_xll.IMBC($B$4, T$8, $Q19, $D19, "세전수익률") -> 10104.611 | U19: =_xll.IMBC($B$4, U$8, $Q19, $D19, "세전수익률") -> 173.9697 | V19: =_xll.IMBC($B$4, V$8, $Q19, $D19, "세전수익률") -> 0.5893
B20: =IF(data!A16="", "", data!A16) -> 45781 | C20: =IF( $B20="", "", INDEX( data!$U$2:$U$8, WEEKDAY($B20) ) ) -> 일 | D20: =IF( $B20="", "", CHOOSE(data!$V$1, data!B16, data!E16, data!V16) ) -> 2.45 | E20: =IF($B21="", "", (D20-D21)*100) -> 0 | F20: =IF( $B20="", "", CHOOSE(data!$V$1, data!C16, data!F16, data!W16) ) -> 10275.82 | G20: =IF($B21="", "", (F20-F21) ) -> 0.69 | H20: =IF( $B20="", "", CHOOSE(data!$V$1, data!D16, data!G16, data!X16) ) -> 0.5874 | I20: =IF(data!H16="", "", data!H16) -> 2.45 | J20: =IF(data!I16="", "", data!I16) -> 10275.82 | K20: =IF(data!J16="", "", data!J16) -> 2.45 | L20: =IF(data!K16="", "", data!K16) -> 10275.82 | M20: =IF(data!L16="", "", data!L16) -> 2.425 | N20: =IF(data!M16="", "", data!M16) -> 10277.32 | O20: =IF(data!N16="", "", data!N16) -> 2.45 | P20: =IF(data!O16="", "", data!O16) -> 10275.82 | Q20: =WORKDAY($B20, data!$AL$1, data!AM16:$AM$2041) -> 45785 | R20: =IF( $Q20="", "", INDEX( data!$U$2:$U$8, WEEKDAY($Q20) ) ) -> 목 | S20: =_xll.IMBC($B$4, S$8, $Q20, $D20, "세전수익률") -> 10278.58 | T20: =_xll.IMBC($B$4, T$8, $Q20, $D20, "세전수익률") -> 10104.611 | U20: =_xll.IMBC($B$4, U$8, $Q20, $D20, "세전수익률") -> 173.9697 | V20: =_xll.IMBC($B$4, V$8, $Q20, $D20, "세전수익률") -> 0.5893
... B108: =IF(data!A104="", "", data!A104) -> 45693 | C108: =IF( $B108="", "", INDEX( data!$U$2:$U$8, WEEKDAY($B108) ) ) -> 수 | D108: =IF( $B108="", "", CHOOSE(data!$V$1, data!B104, data!E104, data!V104) ) -> 2.675 | E108: =IF($B109="", "", (D108-D109)*100) -> 1.75 | F108: =IF( $B108="", "", CHOOSE(data!$V$1, data!C104, data!F104, data!W104) ) -> 10196.54 | G108: =IF($B109="", "", (F108-F109) ) -> -0.73 | H108: =IF( $B108="", "", CHOOSE(data!$V$1, data!D104, data!G104, data!X104) ) -> 0.82365 | I108: =IF(data!H104="", "", data!H104) -> 2.68 | J108: =IF(data!I104="", "", data!I104) -> 10196.12 | K108: =IF(data!J104="", "", data!J104) -> 2.67 | L108: =IF(data!K104="", "", data!K104) -> 10196.96 | M108: =IF(data!L104="", "", data!L104) -> 2.68 | N108: =IF(data!M104="", "", data!M104) -> 10196.12 | O108: =IF(data!N104="", "", data!N104) -> 2.67 | P108: =IF(data!O104="", "", data!O104) -> 10196.96 | Q108: =WORKDAY($B108, data!$AL$1, data!AM104:$AM$2041) -> 45694 | R108: =IF( $Q108="", "", INDEX( data!$U$2:$U$8, WEEKDAY($Q108) ) ) -> 목 | S108: =_xll.IMBC($B$4, S$8, $Q108, $D108, "세전수익률") -> 10197.28 | T108: =_xll.IMBC($B$4, T$8, $Q108, $D108, "세전수익률") -> 10129.567 | U108: =_xll.IMBC($B$4, U$8, $Q108, $D108, "세전수익률") -> 67.7197 | V108: =_xll.IMBC($B$4, V$8, $Q108, $D108, "세전수익률") -> 0.8355
B109: =IF(data!A105="", "", data!A105) -> 45692 | D109: =IF( $B109="", "", CHOOSE(data!$V$1, data!B105, data!E105, data!V105) ) -> 2.6575 | E109: =IF($B110="", "", (D109-D110)*100) | F109: =IF( $B109="", "", CHOOSE(data!$V$1, data!C105, data!F105, data!W105) ) -> 10197.27 | G109: =IF($B110="", "", (F109-F110) ) | H109: =IF( $B109="", "", CHOOSE(data!$V$1, data!D105, data!G105, data!X105) ) -> 0.82645 | I109: =IF(data!H105="", "", data!H105) -> 2.66 | J109: =IF(data!I105="", "", data!I105) -> 10197.06 | K109: =IF(data!J105="", "", data!J105) -> 2.655 | L109: =IF(data!K105="", "", data!K105) -> 10197.48 | M109: =IF(data!L105="", "", data!L105) -> 2.665 | N109: =IF(data!M105="", "", data!M105) -> 10196.64 | O109: =IF(data!N105="", "", data!N105) -> 2.655 | P109: =IF(data!O105="", "", data!O105) -> 10197.48

Sheet data
A1: 시작 | B1: =D1-365 -> 45427 | C1: 종료 | D1: =시가평가_계산!$B$5 -> 45792 | V1: 3 | W1: 1 | AL1: =CHOOSE($AL$2, 0, 1) -> 1
A2: 1 | U2: 일 | V2: 민평3사 | AL2: 2 | AM2: =TEXT(시가평가_계산!$B$5-500, "YYYYMMDD") & "~" & TEXT(시가평가_계산!$B$5+500, "YYYYMMDD") -> 20240101~20260927
A3: =_xll.IMDH("BND", 시가평가_계산!$B$4, A4:O4, $B$1, $D$1, "101", "Per=일, sort=D, real=false, Bizday=0, Quote=종가, Pos=20, Orient=V, DtFmt=1, TmFmt=1, unit=true") -> 조회[KR103501GCC0] | B3: 민평3사 수익률(산출일) | C3: 민평3사 가격(산출일) | D3: 민평3사 듀레이션(산출일) | E3: 민평4사 수익률(산출일) | F3: 민평4사 가격(산출일) | G3: 민평4사 듀레이션(산출일) | H3: KBP 수익률(산출일) | I3: KBP 가격(산출일) | J3: KIS 수익률(산출일) | K3: KIS 가격(산출일) | L3: NIC 수익률(산출일) | M3: NIC 가격(산출일) | N3: FNP 수익률(산출일) | O3: FNP 가격(산출일) | P3: =_xll.IMDH("BND", 시가평가_계산!$B$4, P4:T4, $B$1-100, $D$1, "201", "Per=일, sort=D, real=false, Bizday=0, Quote=종가, Pos=20, Orient=V, DtFmt=1, TmFmt=1, unit=true") -> 조회[KR103501GCC0] | U3: 월 | V3: 민평4사 | Y3: TRUE | AB3: TRUE | AE3: FALSE | AH3: FALSE | AL3: T+0 | AM3: =_xll.IMDT("세계휴장", "CALENDAR", AM4:AN4, 9999, $AM$2, "한국", "휴장일", "sort=A,DtFmt=1,TmFmt=1,Pos=20,Orient=V") -> 조회[CALENDAR]
A4: 일자 | B4: =B$3&CHOOSE($A$2, "", " 당일") -> 민평3사 수익률(산출일) | C4: =C$3&CHOOSE($A$2, "", " 당일") -> 민평3사 가격(산출일) | D4: =D$3&CHOOSE($A$2, "", " 당일") -> 민평3사 듀레이션(산출일) | E4: =E$3&CHOOSE($A$2, "", " 당일") -> 민평4사 수익률(산출일) | F4: =F$3&CHOOSE($A$2, "", " 당일") -> 민평4사 가격(산출일) | G4: =G$3&CHOOSE($A$2, "", " 당일") -> 민평4사 듀레이션(산출일) | H4: =H$3&CHOOSE($A$2, "", " 당일") -> KBP 수익률(산출일) | I4: =I$3&CHOOSE($A$2, "", " 당일") -> KBP 가격(산출일) | ... O4: =O$3&CHOOSE($A$2, "", " 당일") -> FNP 가격(산출일) | P4: 일자 | Q4: KBP 듀레이션(산출일) | R4: KIS 듀레이션(산출일) | S4: NIC 듀레이션(산출일) | T4: FNP 듀레이션(산출일) | U4: 화 | V4: 계산 | Y4: KAP | AB4: KIS | AE4: NICE | AH4: FN | AL4: T+1 | AM4: 휴장일 | AN4: 내용
A5: 45792 | B5: 2.42 | C5: 10285.12 | D5: 0.5556 | E5: 2.42 | F5: 10285.12 | G5: 0.5577 | H5: 2.42 | I5: 10285.12 | J5: 2.42 | K5: 10285.12 | L5: 2.42 | M5: 10285.12 | N5: 2.42 | O5: 10285.12 | P5: 45792 | Q5: 0.5571 | R5: 0.5555 | S5: 0.5544 | T5: 0.5638 | U5: 수 | V5: =IF($A5="", "", CHOOSE( $W$1, AVERAGE(Y5,AB5,AE5,AH5), GEOMEAN(Y5,AB5,AE5,AH5) ) ) -> 2.42 | W5: =IF($A5="", "", CHOOSE( $W$1, AVERAGE(Z5,AC5,AF5,AI5), GEOMEAN(Z5,AC5,AF5,AI5) ) ) -> 10285.12 | X5: =IF($A5="", "", CHOOSE( $W$1, AVERAGE(AA5,AD5,AG5,AJ5), GEOMEAN(AA5,AD5,AG5,AJ5) ) ) -> 0.5563 | Y5: =IF(AND($Y$3,H5<>""), H5, "") -> 2.42 | Z5: =IF(AND($Y$3,I5<>""), I5, "") -> 10285.12 | AA5: =CHOOSE( $A$2, IF(AND($Y$3,Q5<>""), Q5, ""), IF(AND($Y$3,Q5<>""), INDEX($Q:$Q, MATCH($A5,$P:$P, 0)-1), "") ) -> 0.5571 | AB5: =IF(AND($AB$3,J5<>""), J5, "") -> 2.42 | AC5: =IF(AND($AB$3,K5<>""), K5, "") -> 10285.12 | AD5: =CHOOSE( $A$2, IF(AND($AB$3,R5<>""), R5, ""), IF(AND($AB$3,R5<>""), INDEX($R:$R, MATCH($A5,$P:$P, 0)-1), "") ) -> 0.5555 | AE5: =IF(AND($AE$3,L5<>""), L5, "") | AF5: =IF(AND($AE$3,M5<>""), M5, "") | AG5: =CHOOSE( $A$2, IF(AND($AE$3,S5<>""), S5, ""), IF(AND($AE$3,S5<>""), INDEX($S:$S, MATCH($A5,$P:$P, 0)-1), "") ) | AH5: =IF(AND($AH$3,N5<>""), N5, "") | AI5: =IF(AND($AH$3,O5<>""), O5, "") | AJ5: =CHOOSE( $A$2, IF(AND($AH$3,T5<>""), T5, ""), IF(AND($AH$3,T5<>""), INDEX($T:$T, MATCH($A5,$P:$P, 0)-1), "") ) | AM5: 45292 | AN5: 신정
A6: 45791 | B6: 2.428 | C6: 10283.96 | D6: 0.5583 | E6: 2.428 | F6: 10283.94 | G6: 0.5604 | H6: 2.43 | I6: 10283.87 | J6: 2.43 | K6: 10283.87 | L6: 2.425 | M6: 10284.15 | N6: 2.43 | O6: 10283.87 | P6: 45791 | Q6: 0.5598 | R6: 0.5582 | S6: 0.5571 | T6: 0.5666 | U6: 목 | V6: =IF($A6="", "", CHOOSE( $W$1, AVERAGE(Y6,AB6,AE6,AH6), GEOMEAN(Y6,AB6,AE6,AH6) ) ) -> 2.43 | W6: =IF($A6="", "", CHOOSE( $W$1, AVERAGE(Z6,AC6,AF6,AI6), GEOMEAN(Z6,AC6,AF6,AI6) ) ) -> 10283.87 | X6: =IF($A6="", "", CHOOSE( $W$1, AVERAGE(AA6,AD6,AG6,AJ6), GEOMEAN(AA6,AD6,AG6,AJ6) ) ) -> 0.559 | Y6: =IF(AND($Y$3,H6<>""), H6, "") -> 2.43 | Z6: =IF(AND($Y$3,I6<>""), I6, "") -> 10283.87 | AA6: =CHOOSE( $A$2, IF(AND($Y$3,Q6<>""), Q6, ""), IF(AND($Y$3,Q6<>""), INDEX($Q:$Q, MATCH($A6,$P:$P, 0)-1), "") ) -> 0.5598 | AB6: =IF(AND($AB$3,J6<>""), J6, "") -> 2.43 | AC6: =IF(AND($AB$3,K6<>""), K6, "") -> 10283.87 | AD6: =CHOOSE( $A$2, IF(AND($AB$3,R6<>""), R6, ""), IF(AND($AB$3,R6<>""), INDEX($R:$R, MATCH($A6,$P:$P, 0)-1), "") ) -> 0.5582 | AE6: =IF(AND($AE$3,L6<>""), L6, "") | AF6: =IF(AND($AE$3,M6<>""), M6, "") | AG6: =CHOOSE( $A$2, IF(AND($AE$3,S6<>""), S6, ""), IF(AND($AE$3,S6<>""), INDEX($S:$S, MATCH($A6,$P:$P, 0)-1), "") ) | AH6: =IF(AND($AH$3,N6<>""), N6, "") | AI6: =IF(AND($AH$3,O6<>""), O6, "") | AJ6: =CHOOSE( $A$2, IF(AND($AH$3,T6<>""), T6, ""), IF(AND($AH$3,T6<>""), INDEX($T:$T, MATCH($A6,$P:$P, 0)-1), "") ) | AM6: 45301 | AN6: (금리) 지준일
A7: 45790 | B7: 2.426 | C7: 10283.37 | D7: 0.561 | E7: 2.427 | F7: 10283.32 | G7: 0.5631 | H7: 2.43 | I7: 10283.18 | J7: 2.43 | K7: 10283.18 | L7: 2.42 | M7: 10283.76 | N7: 2.43 | O7: 10283.18 | P7: 45790 | Q7: 0.5625 | R7: 0.5609 | S7: 0.5598 | T7: 0.5693 | U7: 금 | V7: =IF($A7="", "", CHOOSE( $W$1, AVERAGE(Y7,AB7,AE7,AH7), GEOMEAN(Y7,AB7,AE7,AH7) ) ) -> 2.43 | W7: =IF($A7="", "", CHOOSE( $W$1, AVERAGE(Z7,AC7,AF7,AI7), GEOMEAN(Z7,AC7,AF7,AI7) ) ) -> 10283.18 | X7: =IF($A7="", "", CHOOSE( $W$1, AVERAGE(AA7,AD7,AG7,AJ7), GEOMEAN(AA7,AD7,AG7,AJ7) ) ) -> 0.5617 | Y7: =IF(AND($Y$3,H7<>""), H7, "") -> 2.43 | Z7: =IF(AND($Y$3,I7<>""), I7, "") -> 10283.18 | AA7: =CHOOSE( $A$2, IF(AND($Y$3,Q7<>""), Q7, ""), IF(AND($Y$3,Q7<>""), INDEX($Q:$Q, MATCH($A7,$P:$P, 0)-1), "") ) -> 0.5625 | AB7: =IF(AND($AB$3,J7<>""), J7, "") -> 2.43 | AC7: =IF(AND($AB$3,K7<>""), K7, "") -> 10283.18 | AD7: =CHOOSE( $A$2, IF(AND($AB$3,R7<>""), R7, ""), IF(AND($AB$3,R7<>""), INDEX($R:$R, MATCH($A7,$P:$P, 0)-1), "") ) -> 0.5609 | AE7: =IF(AND($AE$3,L7<>""), L7, "") | AF7: =IF(AND($AE$3,M7<>""), M7, "") | AG7: =CHOOSE( $A$2, IF(AND($AE$3,S7<>""), S7, ""), IF(AND($AE$3,S7<>""), INDEX($S:$S, MATCH($A7,$P:$P, 0)-1), "") ) | AH7: =IF(AND($AH$3,N7<>""), N7, "") | AI7: =IF(AND($AH$3,O7<>""), O7, "") | AJ7: =CHOOSE( $A$2, IF(AND($AH$3,T7<>""), T7, ""), IF(AND($AH$3,T7<>""), INDEX($T:$T, MATCH($A7,$P:$P, 0)-1), "") ) | AM7: 45329 | AN7: (금리) 지준일
A8: 45789 | B8: 2.431 | C8: 10282.4 | D8: 0.5656 | E8: 2.432 | F8: 10282.35 | G8: 0.5672 | H8: 2.435 | I8: 10282.21 | J8: 2.435 | K8: 10282.21 | L8: 2.425 | M8: 10282.79 | N8: 2.435 | O8: 10282.21 | P8: 45789 | Q8: 0.5707 | R8: 0.5636 | S8: 0.5625 | T8: 0.5721 | U8: 토 | V8: =IF($A8="", "", CHOOSE( $W$1, AVERAGE(Y8,AB8,AE8,AH8), GEOMEAN(Y8,AB8,AE8,AH8) ) ) -> 2.435 | W8: =IF($A8="", "", CHOOSE( $W$1, AVERAGE(Z8,AC8,AF8,AI8), GEOMEAN(Z8,AC8,AF8,AI8) ) ) -> 10282.21 | X8: =IF($A8="", "", CHOOSE( $W$1, AVERAGE(AA8,AD8,AG8,AJ8), GEOMEAN(AA8,AD8,AG8,AJ8) ) ) -> 0.56715 | Y8: =IF(AND($Y$3,H8<>""), H8, "") -> 2.435 | Z8: =IF(AND($Y$3,I8<>""), I8, "") -> 10282.21 | AA8: =CHOOSE( $A$2, IF(AND($Y$3,Q8<>""), Q8, ""), IF(AND($Y$3,Q8<>""), INDEX($Q:$Q, MATCH($A8,$P:$P, 0)-1), "") ) -> 0.5707 | AB8: =IF(AND($AB$3,J8<>""), J8, "") -> 2.435 | AC8: =IF(AND($AB$3,K8<>""), K8, "") -> 10282.21 | AD8: =CHOOSE( $A$2, IF(AND($AB$3,R8<>""), R8, ""), IF(AND($AB$3,R8<>""), INDEX($R:$R, MATCH($A8,$P:$P, 0)-1), "") ) -> 0.5636 | AE8: =IF(AND($AE$3,L8<>""), L8, "") | AF8: =IF(AND($AE$3,M8<>""), M8, "") | AG8: =CHOOSE( $A$2, IF(AND($AE$3,S8<>""), S8, ""), IF(AND($AE$3,S8<>""), INDEX($S:$S, MATCH($A8,$P:$P, 0)-1), "") ) | AH8: =IF(AND($AH$3,N8<>""), N8, "") | AI8: =IF(AND($AH$3,O8<>""), O8, "") | AJ8: =CHOOSE( $A$2, IF(AND($AH$3,T8<>""), T8, ""), IF(AND($AH$3,T8<>""), INDEX($T:$T, MATCH($A8,$P:$P, 0)-1), "") ) | AM8: 45331 | AN8: 설날
A9: 45788 | B9: 2.431 | C9: 10281.71 | D9: 0.5674 | E9: 2.432 | F9: 10281.66 | G9: 0.5692 | H9: 2.435 | I9: 10281.52 | J9: 2.435 | K9: 10281.52 | L9: 2.425 | M9: 10282.1 | N9: 2.435 | O9: 10281.52 | P9: 45788 | Q9: 0.5707 | R9: 0.5663 | S9: 0.5653 | T9: 0.5748 | V9: =IF($A9="", "", CHOOSE( $W$1, AVERAGE(Y9,AB9,AE9,AH9), GEOMEAN(Y9,AB9,AE9,AH9) ) ) -> 2.435 | W9: =IF($A9="", "", CHOOSE( $W$1, AVERAGE(Z9,AC9,AF9,AI9), GEOMEAN(Z9,AC9,AF9,AI9) ) ) -> 10281.52 | X9: =IF($A9="", "", CHOOSE( $W$1, AVERAGE(AA9,AD9,AG9,AJ9), GEOMEAN(AA9,AD9,AG9,AJ9) ) ) -> 0.5685 | Y9: =IF(AND($Y$3,H9<>""), H9, "") -> 2.435 | Z9: =IF(AND($Y$3,I9<>""), I9, "") -> 10281.52 | AA9: =CHOOSE( $A$2, IF(AND($Y$3,Q9<>""), Q9, ""), IF(AND($Y$3,Q9<>""), INDEX($Q:$Q, MATCH($A9,$P:$P, 0)-1), "") ) -> 0.5707 | AB9: =IF(AND($AB$3,J9<>""), J9, "") -> 2.435 | AC9: =IF(AND($AB$3,K9<>""), K9, "") -> 10281.52 | AD9: =CHOOSE( $A$2, IF(AND($AB$3,R9<>""), R9, ""), IF(AND($AB$3,R9<>""), INDEX($R:$R, MATCH($A9,$P:$P, 0)-1), "") ) -> 0.5663 | AE9: =IF(AND($AE$3,L9<>""), L9, "") | AF9: =IF(AND($AE$3,M9<>""), M9, "") | AG9: =CHOOSE( $A$2, IF(AND($AE$3,S9<>""), S9, ""), IF(AND($AE$3,S9<>""), INDEX($S:$S, MATCH($A9,$P:$P, 0)-1), "") ) | AH9: =IF(AND($AH$3,N9<>""), N9, "") | AI9: =IF(AND($AH$3,O9<>""), O9, "") | AJ9: =CHOOSE( $A$2, IF(AND($AH$3,T9<>""), T9, ""), IF(AND($AH$3,T9<>""), INDEX($T:$T, MATCH($A9,$P:$P, 0)-1), "") ) | AM9: 45332 | AN9: 설날
A10: 45787 | B10: 2.431 | C10: 10281.02 | D10: 0.5692 | E10: 2.432 | F10: 10280.97 | G10: 0.5713 | H10: 2.435 | I10: 10280.83 | J10: 2.435 | K10: 10280.83 | L10: 2.425 | M10: 10281.42 | N10: 2.435 | O10: 10280.83 | P10: 45787 | Q10: 0.5707 | R10: 0.569 | S10: 0.568 | T10: 0.5775 | V10: =IF($A10="", "", CHOOSE( $W$1, AVERAGE(Y10,AB10,AE10,AH10), GEOMEAN(Y10,AB10,AE10,AH10) ) ) -> 2.435 | W10: =IF($A10="", "", CHOOSE( $W$1, AVERAGE(Z10,AC10,AF10,AI10), GEOMEAN(Z10,AC10,AF10,AI10) ) ) -> 10280.83 | X10: =IF($A10="", "", CHOOSE( $W$1, AVERAGE(AA10,AD10,AG10,AJ10), GEOMEAN(AA10,AD10,AG10,AJ10) ) ) -> 0.56985 | Y10: =IF(AND($Y$3,H10<>""), H10, "") -> 2.435 | Z10: =IF(AND($Y$3,I10<>""), I10, "") -> 10280.83 | AA10: =CHOOSE( $A$2, IF(AND($Y$3,Q10<>""), Q10, ""), IF(AND($Y$3,Q10<>""), INDEX($Q:$Q, MATCH($A10,$P:$P, 0)-1), "") ) -> 0.5707 | AB10: =IF(AND($AB$3,J10<>""), J10, "") -> 2.435 | AC10: =IF(AND($AB$3,K10<>""), K10, "") -> 10280.83 | AD10: =CHOOSE( $A$2, IF(AND($AB$3,R10<>""), R10, ""), IF(AND($AB$3,R10<>""), INDEX($R:$R, MATCH($A10,$P:$P, 0)-1), "") ) -> 0.569 | AE10: =IF(AND($AE$3,L10<>""), L10, "") | AF10: =IF(AND($AE$3,M10<>""), M10, "") | AG10: =CHOOSE( $A$2, IF(AND($AE$3,S10<>""), S10, ""), IF(AND($AE$3,S10<>""), INDEX($S:$S, MATCH($A10,$P:$P, 0)-1), "") ) | AH10: =IF(AND($AH$3,N10<>""), N10, "") | AI10: =IF(AND($AH$3,O10<>""), O10, "") | AJ10: =CHOOSE( $A$2, IF(AND($AH$3,T10<>""), T10, ""), IF(AND($AH$3,T10<>""), INDEX($T:$T, MATCH($A10,$P:$P, 0)-1), "") ) | AM10: 45333 | AN10: 설날
A11: 45786 | B11: 2.435 | C11: 10280.15 | D11: 0.5719 | E11: 2.435 | F11: 10280.15 | G11: 0.574 | H11: 2.435 | I11: 10280.15 | J11: 2.435 | K11: 10280.15 | L11: 2.435 | M11: 10280.15 | N11: 2.435 | O11: 10280.15 | P11: 45786 | Q11: 0.5734 | R11: 0.5717 | S11: 0.5707 | T11: 0.5803 | V11: =IF($A11="", "", CHOOSE( $W$1, AVERAGE(Y11,AB11,AE11,AH11), GEOMEAN(Y11,AB11,AE11,AH11) ) ) -> 2.435 | W11: =IF($A11="", "", CHOOSE( $W$1, AVERAGE(Z11,AC11,AF11,AI11), GEOMEAN(Z11,AC11,AF11,AI11) ) ) -> 10280.15 | X11: =IF($A11="", "", CHOOSE( $W$1, AVERAGE(AA11,AD11,AG11,AJ11), GEOMEAN(AA11,AD11,AG11,AJ11) ) ) -> 0.57255 | Y11: =IF(AND($Y$3,H11<>""), H11, "") -> 2.435 | Z11: =IF(AND($Y$3,I11<>""), I11, "") -> 10280.15 | AA11: =CHOOSE( $A$2, IF(AND($Y$3,Q11<>""), Q11, ""), IF(AND($Y$3,Q11<>""), INDEX($Q:$Q, MATCH($A11,$P:$P, 0)-1), "") ) -> 0.5734 | AB11: =IF(AND($AB$3,J11<>""), J11, "") -> 2.435 | AC11: =IF(AND($AB$3,K11<>""), K11, "") -> 10280.15 | AD11: =CHOOSE( $A$2, IF(AND($AB$3,R11<>""), R11, ""), IF(AND($AB$3,R11<>""), INDEX($R:$R, MATCH($A11,$P:$P, 0)-1), "") ) -> 0.5717 | AE11: =IF(AND($AE$3,L11<>""), L11, "") | AF11: =IF(AND($AE$3,M11<>""), M11, "") | AG11: =CHOOSE( $A$2, IF(AND($AE$3,S11<>""), S11, ""), IF(AND($AE$3,S11<>""), INDEX($S:$S, MATCH($A11,$P:$P, 0)-1), "") ) | AH11: =IF(AND($AH$3,N11<>""), N11, "") | AI11: =IF(AND($AH$3,O11<>""), O11, "") | AJ11: =CHOOSE( $A$2, IF(AND($AH$3,T11<>""), T11, ""), IF(AND($AH$3,T11<>""), INDEX($T:$T, MATCH($A11,$P:$P, 0)-1), "") ) | AM11: 45334 | AN11: 설날 (대체)
A12: 45785 | B12: 2.426 | C12: 10279.95 | D12: 0.5746 | E12: 2.427 | F12: 10279.9 | G12: 0.5767 | H12: 2.43 | I12: 10279.76 | J12: 2.43 | K12: 10279.76 | L12: 2.42 | M12: 10280.35 | N12: 2.43 | O12: 10279.76 | P12: 45785 | Q12: 0.5761 | R12: 0.5745 | S12: 0.5734 | T12: 0.583 | V12: =IF($A12="", "", CHOOSE( $W$1, AVERAGE(Y12,AB12,AE12,AH12), GEOMEAN(Y12,AB12,AE12,AH12) ) ) -> 2.43 | W12: =IF($A12="", "", CHOOSE( $W$1, AVERAGE(Z12,AC12,AF12,AI12), GEOMEAN(Z12,AC12,AF12,AI12) ) ) -> 10279.76 | X12: =IF($A12="", "", CHOOSE( $W$1, AVERAGE(AA12,AD12,AG12,AJ12), GEOMEAN(AA12,AD12,AG12,AJ12) ) ) -> 0.5753 | Y12: =IF(AND($Y$3,H12<>""), H12, "") -> 2.43 | Z12: =IF(AND($Y$3,I12<>""), I12, "") -> 10279.76 | AA12: =CHOOSE( $A$2, IF(AND($Y$3,Q12<>""), Q12, ""), IF(AND($Y$3,Q12<>""), INDEX($Q:$Q, MATCH($A12,$P:$P, 0)-1), "") ) -> 0.5761 | AB12: =IF(AND($AB$3,J12<>""), J12, "") -> 2.43 | AC12: =IF(AND($AB$3,K12<>""), K12, "") -> 10279.76 | AD12: =CHOOSE( $A$2, IF(AND($AB$3,R12<>""), R12, ""), IF(AND($AB$3,R12<>""), INDEX($R:$R, MATCH($A12,$P:$P, 0)-1), "") ) -> 0.5745 | AE12: =IF(AND($AE$3,L12<>""), L12, "") | AF12: =IF(AND($AE$3,M12<>""), M12, "") | AG12: =CHOOSE( $A$2, IF(AND($AE$3,S12<>""), S12, ""), IF(AND($AE$3,S12<>""), INDEX($S:$S, MATCH($A12,$P:$P, 0)-1), "") ) | AH12: =IF(AND($AH$3,N12<>""), N12, "") | AI12: =IF(AND($AH$3,O12<>""), O12, "") | AJ12: =CHOOSE( $A$2, IF(AND($AH$3,T12<>""), T12, ""), IF(AND($AH$3,T12<>""), INDEX($T:$T, MATCH($A12,$P:$P, 0)-1), "") ) | AM12: 45352 | AN12: 삼일절
A13: 45784 | B13: 2.441 | C13: 10278.38 | D13: 0.5809 | E13: 2.443 | F13: 10278.26 | G13: 0.5821 | H13: 2.45 | I13: 10277.89 | J13: 2.45 | K13: 10277.89 | L13: 2.425 | M13: 10279.37 | N13: 2.45 | O13: 10277.89 | P13: 45784 | Q13: 0.5896 | R13: 0.5771 | S13: 0.5761 | T13: 0.5858 | V13: =IF($A13="", "", CHOOSE( $W$1, AVERAGE(Y13,AB13,AE13,AH13), GEOMEAN(Y13,AB13,AE13,AH13) ) ) -> 2.45 | W13: =IF($A13="", "", CHOOSE( $W$1, AVERAGE(Z13,AC13,AF13,AI13), GEOMEAN(Z13,AC13,AF13,AI13) ) ) -> 10277.89 | X13: =IF($A13="", "", CHOOSE( $W$1, AVERAGE(AA13,AD13,AG13,AJ13), GEOMEAN(AA13,AD13,AG13,AJ13) ) ) -> 0.58335 | Y13: =IF(AND($Y$3,H13<>""), H13, "") -> 2.45 | Z13: =IF(AND($Y$3,I13<>""), I13, "") -> 10277.89 | AA13: =CHOOSE( $A$2, IF(AND($Y$3,Q13<>""), Q13, ""), IF(AND($Y$3,Q13<>""), INDEX($Q:$Q, MATCH($A13,$P:$P, 0)-1), "") ) -> 0.5896 | AB13: =IF(AND($AB$3,J13<>""), J13, "") -> 2.45 | AC13: =IF(AND($AB$3,K13<>""), K13, "") -> 10277.89 | AD13: =CHOOSE( $A$2, IF(AND($AB$3,R13<>""), R13, ""), IF(AND($AB$3,R13<>""), INDEX($R:$R, MATCH($A13,$P:$P, 0)-1), "") ) -> 0.5771 | AE13: =IF(AND($AE$3,L13<>""), L13, "") | AF13: =IF(AND($AE$3,M13<>""), M13, "") | AG13: =CHOOSE( $A$2, IF(AND($AE$3,S13<>""), S13, ""), IF(AND($AE$3,S13<>""), INDEX($S:$S, MATCH($A13,$P:$P, 0)-1), "") ) | AH13: =IF(AND($AH$3,N13<>""), N13, "") | AI13: =IF(AND($AH$3,O13<>""), O13, "") | AJ13: =CHOOSE( $A$2, IF(AND($AH$3,T13<>""), T13, ""), IF(AND($AH$3,T13<>""), INDEX($T:$T, MATCH($A13,$P:$P, 0)-1), "") ) | AM13: 45357 | AN13: (금리) 지준일
A14: 45783 | B14: 2.441 | C14: 10277.69 | D14: 0.5827 | E14: 2.443 | F14: 10277.57 | G14: 0.5841 | H14: 2.45 | I14: 10277.2 | J14: 2.45 | K14: 10277.2 | L14: 2.425 | M14: 10278.68 | N14: 2.45 | O14: 10277.2 | P14: 45783 | Q14: 0.5896 | R14: 0.5798 | S14: 0.5788 | T14: 0.5885 | V14: =IF($A14="", "", CHOOSE( $W$1, AVERAGE(Y14,AB14,AE14,AH14), GEOMEAN(Y14,AB14,AE14,AH14) ) ) -> 2.45 | W14: =IF($A14="", "", CHOOSE( $W$1, AVERAGE(Z14,AC14,AF14,AI14), GEOMEAN(Z14,AC14,AF14,AI14) ) ) -> 10277.2 | X14: =IF($A14="", "", CHOOSE( $W$1, AVERAGE(AA14,AD14,AG14,AJ14), GEOMEAN(AA14,AD14,AG14,AJ14) ) ) -> 0.5847 | Y14: =IF(AND($Y$3,H14<>""), H14, "") -> 2.45 | Z14: =IF(AND($Y$3,I14<>""), I14, "") -> 10277.2 | AA14: =CHOOSE( $A$2, IF(AND($Y$3,Q14<>""), Q14, ""), IF(AND($Y$3,Q14<>""), INDEX($Q:$Q, MATCH($A14,$P:$P, 0)-1), "") ) -> 0.5896 | AB14: =IF(AND($AB$3,J14<>""), J14, "") -> 2.45 | AC14: =IF(AND($AB$3,K14<>""), K14, "") -> 10277.2 | AD14: =CHOOSE( $A$2, IF(AND($AB$3,R14<>""), R14, ""), IF(AND($AB$3,R14<>""), INDEX($R:$R, MATCH($A14,$P:$P, 0)-1), "") ) -> 0.5798 | AE14: =IF(AND($AE$3,L14<>""), L14, "") | AF14: =IF(AND($AE$3,M14<>""), M14, "") | AG14: =CHOOSE( $A$2, IF(AND($AE$3,S14<>""), S14, ""), IF(AND($AE$3,S14<>""), INDEX($S:$S, MATCH($A14,$P:$P, 0)-1), "") ) | AH14: =IF(AND($AH$3,N14<>""), N14, "") | AI14: =IF(AND($AH$3,O14<>""), O14, "") | AJ14: =CHOOSE( $A$2, IF(AND($AH$3,T14<>""), T14, ""), IF(AND($AH$3,T14<>""), INDEX($T:$T, MATCH($A14,$P:$P, 0)-1), "") ) | AM14: 45391 | AN14: (금리) 지준일 (대체)
A15: 45782 | B15: 2.441 | C15: 10277 | D15: 0.5845 | E15: 2.443 | F15: 10276.88 | G15: 0.5862 | H15: 2.45 | I15: 10276.51 | J15: 2.45 | K15: 10276.51 | L15: 2.425 | M15: 10278 | N15: 2.45 | O15: 10276.51 | P15: 45782 | Q15: 0.5896 | R15: 0.5825 | S15: 0.5815 | T15: 0.5913 | V15: =IF($A15="", "", CHOOSE( $W$1, AVERAGE(Y15,AB15,AE15,AH15), GEOMEAN(Y15,AB15,AE15,AH15) ) ) -> 2.45 | W15: =IF($A15="", "", CHOOSE( $W$1, AVERAGE(Z15,AC15,AF15,AI15), GEOMEAN(Z15,AC15,AF15,AI15) ) ) -> 10276.51 | X15: =IF($A15="", "", CHOOSE( $W$1, AVERAGE(AA15,AD15,AG15,AJ15), GEOMEAN(AA15,AD15,AG15,AJ15) ) ) -> 0.58605 | Y15: =IF(AND($Y$3,H15<>""), H15, "") -> 2.45 | Z15: =IF(AND($Y$3,I15<>""), I15, "") -> 10276.51 | AA15: =CHOOSE( $A$2, IF(AND($Y$3,Q15<>""), Q15, ""), IF(AND($Y$3,Q15<>""), INDEX($Q:$Q, MATCH($A15,$P:$P, 0)-1), "") ) -> 0.5896 | AB15: =IF(AND($AB$3,J15<>""), J15, "") -> 2.45 | AC15: =IF(AND($AB$3,K15<>""), K15, "") -> 10276.51 | AD15: =CHOOSE( $A$2, IF(AND($AB$3,R15<>""), R15, ""), IF(AND($AB$3,R15<>""), INDEX($R:$R, MATCH($A15,$P:$P, 0)-1), "") ) -> 0.5825 | AE15: =IF(AND($AE$3,L15<>""), L15, "") | AF15: =IF(AND($AE$3,M15<>""), M15, "") | AG15: =CHOOSE( $A$2, IF(AND($AE$3,S15<>""), S15, ""), IF(AND($AE$3,S15<>""), INDEX($S:$S, MATCH($A15,$P:$P, 0)-1), "") ) | AH15: =IF(AND($AH$3,N15<>""), N15, "") | AI15: =IF(AND($AH$3,O15<>""), O15, "") | AJ15: =CHOOSE( $A$2, IF(AND($AH$3,T15<>""), T15, ""), IF(AND($AH$3,T15<>""), INDEX($T:$T, MATCH($A15,$P:$P, 0)-1), "") ) | AM15: 45392 | AN15: 국회의원 선거, (금리) 지준일
A16: 45781 | B16: 2.441 | C16: 10276.32 | D16: 0.5863 | E16: 2.443 | F16: 10276.19 | G16: 0.5882 | H16: 2.45 | I16: 10275.82 | J16: 2.45 | K16: 10275.82 | L16: 2.425 | M16: 10277.32 | N16: 2.45 | O16: 10275.82 | P16: 45781 | Q16: 0.5896 | R16: 0.5852 | S16: 0.5843 | T16: 0.594 | V16: =IF($A16="", "", CHOOSE( $W$1, AVERAGE(Y16,AB16,AE16,AH16), GEOMEAN(Y16,AB16,AE16,AH16) ) ) -> 2.45 | W16: =IF($A16="", "", CHOOSE( $W$1, AVERAGE(Z16,AC16,AF16,AI16), GEOMEAN(Z16,AC16,AF16,AI16) ) ) -> 10275.82 | X16: =IF($A16="", "", CHOOSE( $W$1, AVERAGE(AA16,AD16,AG16,AJ16), GEOMEAN(AA16,AD16,AG16,AJ16) ) ) -> 0.5874 | Y16: =IF(AND($Y$3,H16<>""), H16, "") -> 2.45 | Z16: =IF(AND($Y$3,I16<>""), I16, "") -> 10275.82 | AA16: =CHOOSE( $A$2, IF(AND($Y$3,Q16<>""), Q16, ""), IF(AND($Y$3,Q16<>""), INDEX($Q:$Q, MATCH($A16,$P:$P, 0)-1), "") ) -> 0.5896 | AB16: =IF(AND($AB$3,J16<>""), J16, "") -> 2.45 | AC16: =IF(AND($AB$3,K16<>""), K16, "") -> 10275.82 | AD16: =CHOOSE( $A$2, IF(AND($AB$3,R16<>""), R16, ""), IF(AND($AB$3,R16<>""), INDEX($R:$R, MATCH($A16,$P:$P, 0)-1), "") ) -> 0.5852 | AE16: =IF(AND($AE$3,L16<>""), L16, "") | AF16: =IF(AND($AE$3,M16<>""), M16, "") | AG16: =CHOOSE( $A$2, IF(AND($AE$3,S16<>""), S16, ""), IF(AND($AE$3,S16<>""), INDEX($S:$S, MATCH($A16,$P:$P, 0)-1), "") ) | AH16: =IF(AND($AH$3,N16<>""), N16, "") | AI16: =IF(AND($AH$3,O16<>""), O16, "") | AJ16: =CHOOSE( $A$2, IF(AND($AH$3,T16<>""), T16, ""), IF(AND($AH$3,T16<>""), INDEX($T:$T, MATCH($A16,$P:$P, 0)-1), "") ) | AM16: 45413 | AN16: 근로자의날
A17: 45780 | B17: 2.441 | C17: 10275.63 | D17: 0.5881 | E17: 2.443 | F17: 10275.5 | G17: 0.5903 | H17: 2.45 | I17: 10275.13 | J17: 2.45 | K17: 10275.13 | L17: 2.425 | M17: 10276.64 | N17: 2.45 | O17: 10275.13 | P17: 45780 | Q17: 0.5896 | R17: 0.5879 | S17: 0.587 | T17: 0.5968 | V17: =IF($A17="", "", CHOOSE( $W$1, AVERAGE(Y17,AB17,AE17,AH17), GEOMEAN(Y17,AB17,AE17,AH17) ) ) -> 2.45 | W17: =IF($A17="", "", CHOOSE( $W$1, AVERAGE(Z17,AC17,AF17,AI17), GEOMEAN(Z17,AC17,AF17,AI17) ) ) -> 10275.13 | X17: =IF($A17="", "", CHOOSE( $W$1, AVERAGE(AA17,AD17,AG17,AJ17), GEOMEAN(AA17,AD17,AG17,AJ17) ) ) -> 0.58875 | Y17: =IF(AND($Y$3,H17<>""), H17, "") -> 2.45 | Z17: =IF(AND($Y$3,I17<>""), I17, "") -> 10275.13 | AA17: =CHOOSE( $A$2, IF(AND($Y$3,Q17<>""), Q17, ""), IF(AND($Y$3,Q17<>""), INDEX($Q:$Q, MATCH($A17,$P:$P, 0)-1), "") ) -> 0.5896 | AB17: =IF(AND($AB$3,J17<>""), J17, "") -> 2.45 | AC17: =IF(AND($AB$3,K17<>""), K17, "") -> 10275.13 | AD17: =CHOOSE( $A$2, IF(AND($AB$3,R17<>""), R17, ""), IF(AND($AB$3,R17<>""), INDEX($R:$R, MATCH($A17,$P:$P, 0)-1), "") ) -> 0.5879 | AE17: =IF(AND($AE$3,L17<>""), L17, "") | AF17: =IF(AND($AE$3,M17<>""), M17, "") | AG17: =CHOOSE( $A$2, IF(AND($AE$3,S17<>""), S17, ""), IF(AND($AE$3,S17<>""), INDEX($S:$S, MATCH($A17,$P:$P, 0)-1), "") ) | AH17: =IF(AND($AH$3,N17<>""), N17, "") | AI17: =IF(AND($AH$3,O17<>""), O17, "") | AJ17: =CHOOSE( $A$2, IF(AND($AH$3,T17<>""), T17, ""), IF(AND($AH$3,T17<>""), INDEX($T:$T, MATCH($A17,$P:$P, 0)-1), "") ) | AM17: 45417 | AN17: 어린이날
A18: 45779 | B18: 2.441 | C18: 10274.94 | D18: 0.5917 | E18: 2.443 | F18: 10274.81 | G18: 0.5937 | H18: 2.45 | I18: 10274.44 | J18: 2.45 | K18: 10274.44 | L18: 2.425 | M18: 10275.95 | N18: 2.45 | O18: 10274.44 | P18: 45779 | Q18: 0.595 | R18: 0.5906 | S18: 0.5897 | T18: 0.5995 | V18: =IF($A18="", "", CHOOSE( $W$1, AVERAGE(Y18,AB18,AE18,AH18), GEOMEAN(Y18,AB18,AE18,AH18) ) ) -> 2.45 | W18: =IF($A18="", "", CHOOSE( $W$1, AVERAGE(Z18,AC18,AF18,AI18), GEOMEAN(Z18,AC18,AF18,AI18) ) ) -> 10274.44 | X18: =IF($A18="", "", CHOOSE( $W$1, AVERAGE(AA18,AD18,AG18,AJ18), GEOMEAN(AA18,AD18,AG18,AJ18) ) ) -> 0.5928 | Y18: =IF(AND($Y$3,H18<>""), H18, "") -> 2.45 | Z18: =IF(AND($Y$3,I18<>""), I18, "") -> 10274.44 | AA18: =CHOOSE( $A$2, IF(AND($Y$3,Q18<>""), Q18, ""), IF(AND($Y$3,Q18<>""), INDEX($Q:$Q, MATCH($A18,$P:$P, 0)-1), "") ) -> 0.595 | AB18: =IF(AND($AB$3,J18<>""), J18, "") -> 2.45 | AC18: =IF(AND($AB$3,K18<>""), K18, "") -> 10274.44 | AD18: =CHOOSE( $A$2, IF(AND($AB$3,R18<>""), R18, ""), IF(AND($AB$3,R18<>""), INDEX($R:$R, MATCH($A18,$P:$P, 0)-1), "") ) -> 0.5906 | AE18: =IF(AND($AE$3,L18<>""), L18, "") | AF18: =IF(AND($AE$3,M18<>""), M18, "") | AG18: =CHOOSE( $A$2, IF(AND($AE$3,S18<>""), S18, ""), IF(AND($AE$3,S18<>""), INDEX($S:$S, MATCH($A18,$P:$P, 0)-1), "") ) | AH18: =IF(AND($AH$3,N18<>""), N18, "") | AI18: =IF(AND($AH$3,O18<>""), O18, "") | AJ18: =CHOOSE( $A$2, IF(AND($AH$3,T18<>""), T18, ""), IF(AND($AH$3,T18<>""), INDEX($T:$T, MATCH($A18,$P:$P, 0)-1), "") ) | AM18: 45418 | AN18: 어린이날 (대체)
A19: 45778 | B19: 2.441 | C19: 10274.25 | D19: 0.5935 | E19: 2.443 | F19: 10274.13 | G19: 0.5957 | H19: 2.45 | I19: 10273.75 | J19: 2.45 | K19: 10273.75 | L19: 2.425 | M19: 10275.27 | N19: 2.45 | O19: 10273.75 | P19: 45778 | Q19: 0.595 | R19: 0.5933 | S19: 0.5924 | T19: 0.6023 | V19: =IF($A19="", "", CHOOSE( $W$1, AVERAGE(Y19,AB19,AE19,AH19), GEOMEAN(Y19,AB19,AE19,AH19) ) ) -> 2.45 | W19: =IF($A19="", "", CHOOSE( $W$1, AVERAGE(Z19,AC19,AF19,AI19), GEOMEAN(Z19,AC19,AF19,AI19) ) ) -> 10273.75 | X19: =IF($A19="", "", CHOOSE( $W$1, AVERAGE(AA19,AD19,AG19,AJ19), GEOMEAN(AA19,AD19,AG19,AJ19) ) ) -> 0.59415 | Y19: =IF(AND($Y$3,H19<>""), H19, "") -> 2.45 | Z19: =IF(AND($Y$3,I19<>""), I19, "") -> 10273.75 | AA19: =CHOOSE( $A$2, IF(AND($Y$3,Q19<>""), Q19, ""), IF(AND($Y$3,Q19<>""), INDEX($Q:$Q, MATCH($A19,$P:$P, 0)-1), "") ) -> 0.595 | AB19: =IF(AND($AB$3,J19<>""), J19, "") -> 2.45 | AC19: =IF(AND($AB$3,K19<>""), K19, "") -> 10273.75 | AD19: =CHOOSE( $A$2, IF(AND($AB$3,R19<>""), R19, ""), IF(AND($AB$3,R19<>""), INDEX($R:$R, MATCH($A19,$P:$P, 0)-1), "") ) -> 0.5933 | AE19: =IF(AND($AE$3,L19<>""), L19, "") | AF19: =IF(AND($AE$3,M19<>""), M19, "") | AG19: =CHOOSE( $A$2, IF(AND($AE$3,S19<>""), S19, ""), IF(AND($AE$3,S19<>""), INDEX($S:$S, MATCH($A19,$P:$P, 0)-1), "") ) | AH19: =IF(AND($AH$3,N19<>""), N19, "") | AI19: =IF(AND($AH$3,O19<>""), O19, "") | AJ19: =CHOOSE( $A$2, IF(AND($AH$3,T19<>""), T19, ""), IF(AND($AH$3,T19<>""), INDEX($T:$T, MATCH($A19,$P:$P, 0)-1), "") ) | AM19: 45420 | AN19: (금리) 지준일
A20: 45777 | B20: 2.476 | C20: 10271.42 | D20: 0.5962 | E20: 2.476 | F20: 10271.45 | G20: 0.5984 | H20: 2.485 | I20: 10270.91 | J20: 2.48 | K20: 10271.22 | L20: 2.465 | M20: 10272.14 | N20: 2.475 | O20: 10271.53 | P20: 45777 | Q20: 0.5976 | R20: 0.596 | S20: 0.595 | T20: 0.605 | V20: =IF($A20="", "", CHOOSE( $W$1, AVERAGE(Y20,AB20,AE20,AH20), GEOMEAN(Y20,AB20,AE20,AH20) ) ) -> 2.4825 | W20: =IF($A20="", "", CHOOSE( $W$1, AVERAGE(Z20,AC20,AF20,AI20), GEOMEAN(Z20,AC20,AF20,AI20) ) ) -> 10271.065 | X20: =IF($A20="", "", CHOOSE( $W$1, AVERAGE(AA20,AD20,AG20,AJ20), GEOMEAN(AA20,AD20,AG20,AJ20) ) ) -> 0.5968 | Y20: =IF(AND($Y$3,H20<>""), H20, "") -> 2.485 | Z20: =IF(AND($Y$3,I20<>""), I20, "") -> 10270.91 | AA20: =CHOOSE( $A$2, IF(AND($Y$3,Q20<>""), Q20, ""), IF(AND($Y$3,Q20<>""), INDEX($Q:$Q, MATCH($A20,$P:$P, 0)-1), "") ) -> 0.5976 | AB20: =IF(AND($AB$3,J20<>""), J20, "") -> 2.48 | AC20: =IF(AND($AB$3,K20<>""), K20, "") -> 10271.22 | AD20: =CHOOSE( $A$2, IF(AND($AB$3,R20<>""), R20, ""), IF(AND($AB$3,R20<>""), INDEX($R:$R, MATCH($A20,$P:$P, 0)-1), "") ) -> 0.596 | AE20: =IF(AND($AE$3,L20<>""), L20, "") | AF20: =IF(AND($AE$3,M20<>""), M20, "") | AG20: =CHOOSE( $A$2, IF(AND($AE$3,S20<>""), S20, ""), IF(AND($AE$3,S20<>""), INDEX($S:$S, MATCH($A20,$P:$P, 0)-1), "") ) | AH20: =IF(AND($AH$3,N20<>""), N20, "") | AI20: =IF(AND($AH$3,O20<>""), O20, "") | AJ20: =CHOOSE( $A$2, IF(AND($AH$3,T20<>""), T20, ""), IF(AND($AH$3,T20<>""), INDEX($T:$T, MATCH($A20,$P:$P, 0)-1), "") ) | AM20: 45427 | AN20: 부처님오신날
... A95: 45702 | B95: 2.66 | C95: 10204.45 | D95: 0.7988 | E95: 2.66 | F95: 10204.45 | G95: 0.8018 | H95: 2.66 | I95: 10204.45 | J95: 2.66 | K95: 10204.45 | L95: 2.66 | M95: 10204.45 | N95: 2.66 | O95: 10204.45 | P95: 45702 | Q95: 0.8005 | R95: 0.7982 | S95: 0.7977 | T95: 0.8111 | V95: =IF($A95="", "", CHOOSE( $W$1, AVERAGE(Y95,AB95,AE95,AH95), GEOMEAN(Y95,AB95,AE95,AH95) ) ) -> 2.66 | W95: =IF($A95="", "", CHOOSE( $W$1, AVERAGE(Z95,AC95,AF95,AI95), GEOMEAN(Z95,AC95,AF95,AI95) ) ) -> 10204.45 | X95: =IF($A95="", "", CHOOSE( $W$1, AVERAGE(AA95,AD95,AG95,AJ95), GEOMEAN(AA95,AD95,AG95,AJ95) ) ) -> 0.79935 | Y95: =IF(AND($Y$3,H95<>""), H95, "") -> 2.66 | Z95: =IF(AND($Y$3,I95<>""), I95, "") -> 10204.45 | AA95: =CHOOSE( $A$2, IF(AND($Y$3,Q95<>""), Q95, ""), IF(AND($Y$3,Q95<>""), INDEX($Q:$Q, MATCH($A95,$P:$P, 0)-1), "") ) -> 0.8005 | AB95: =IF(AND($AB$3,J95<>""), J95, "") -> 2.66 | AC95: =IF(AND($AB$3,K95<>""), K95, "") -> 10204.45 | AD95: =CHOOSE( $A$2, IF(AND($AB$3,R95<>""), R95, ""), IF(AND($AB$3,R95<>""), INDEX($R:$R, MATCH($A95,$P:$P, 0)-1), "") ) -> 0.7982 | AE95: =IF(AND($AE$3,L95<>""), L95, "") | AF95: =IF(AND($AE$3,M95<>""), M95, "") | AG95: =CHOOSE( $A$2, IF(AND($AE$3,S95<>""), S95, ""), IF(AND($AE$3,S95<>""), INDEX($S:$S, MATCH($A95,$P:$P, 0)-1), "") ) | AH95: =IF(AND($AH$3,N95<>""), N95, "") | AI95: =IF(AND($AH$3,O95<>""), O95, "") | AJ95: =CHOOSE( $A$2, IF(AND($AH$3,T95<>""), T95, ""), IF(AND($AH$3,T95<>""), INDEX($T:$T, MATCH($A95,$P:$P, 0)-1), "") ) | AM95: 46291 | AN95: 추석
A96: 45701 | B96: 2.671 | C96: 10202.75 | D96: 0.8014 | E96: 2.671 | F96: 10202.78 | G96: 0.8045 | H96: 2.67 | I96: 10202.89 | J96: 2.67 | K96: 10202.89 | L96: 2.675 | M96: 10202.48 | N96: 2.67 | O96: 10202.89 | P96: 45701 | Q96: 0.8031 | R96: 0.8009 | S96: 0.8004 | T96: 0.8138 | V96: =IF($A96="", "", CHOOSE( $W$1, AVERAGE(Y96,AB96,AE96,AH96), GEOMEAN(Y96,AB96,AE96,AH96) ) ) -> 2.67 | W96: =IF($A96="", "", CHOOSE( $W$1, AVERAGE(Z96,AC96,AF96,AI96), GEOMEAN(Z96,AC96,AF96,AI96) ) ) -> 10202.89 | X96: =IF($A96="", "", CHOOSE( $W$1, AVERAGE(AA96,AD96,AG96,AJ96), GEOMEAN(AA96,AD96,AG96,AJ96) ) ) -> 0.802 | Y96: =IF(AND($Y$3,H96<>""), H96, "") -> 2.67 | Z96: =IF(AND($Y$3,I96<>""), I96, "") -> 10202.89 | AA96: =CHOOSE( $A$2, IF(AND($Y$3,Q96<>""), Q96, ""), IF(AND($Y$3,Q96<>""), INDEX($Q:$Q, MATCH($A96,$P:$P, 0)-1), "") ) -> 0.8031 | AB96: =IF(AND($AB$3,J96<>""), J96, "") -> 2.67 | AC96: =IF(AND($AB$3,K96<>""), K96, "") -> 10202.89 | AD96: =CHOOSE( $A$2, IF(AND($AB$3,R96<>""), R96, ""), IF(AND($AB$3,R96<>""), INDEX($R:$R, MATCH($A96,$P:$P, 0)-1), "") ) -> 0.8009 | AE96: =IF(AND($AE$3,L96<>""), L96, "") | AF96: =IF(AND($AE$3,M96<>""), M96, "") | AG96: =CHOOSE( $A$2, IF(AND($AE$3,S96<>""), S96, ""), IF(AND($AE$3,S96<>""), INDEX($S:$S, MATCH($A96,$P:$P, 0)-1), "") ) | AH96: =IF(AND($AH$3,N96<>""), N96, "") | AI96: =IF(AND($AH$3,O96<>""), O96, "") | AJ96: =CHOOSE( $A$2, IF(AND($AH$3,T96<>""), T96, ""), IF(AND($AH$3,T96<>""), INDEX($T:$T, MATCH($A96,$P:$P, 0)-1), "") )
A97: 45700 | B97: 2.668 | C97: 10202.28 | D97: 0.8041 | E97: 2.668 | F97: 10202.25 | G97: 0.8072 | H97: 2.67 | I97: 10202.15 | J97: 2.67 | K97: 10202.15 | L97: 2.665 | M97: 10202.56 | N97: 2.67 | O97: 10202.15 | P97: 45700 | Q97: 0.8058 | R97: 0.8036 | S97: 0.8031 | T97: 0.8165 | V97: =IF($A97="", "", CHOOSE( $W$1, AVERAGE(Y97,AB97,AE97,AH97), GEOMEAN(Y97,AB97,AE97,AH97) ) ) -> 2.67 | W97: =IF($A97="", "", CHOOSE( $W$1, AVERAGE(Z97,AC97,AF97,AI97), GEOMEAN(Z97,AC97,AF97,AI97) ) ) -> 10202.15 | X97: =IF($A97="", "", CHOOSE( $W$1, AVERAGE(AA97,AD97,AG97,AJ97), GEOMEAN(AA97,AD97,AG97,AJ97) ) ) -> 0.8047 | Y97: =IF(AND($Y$3,H97<>""), H97, "") -> 2.67 | Z97: =IF(AND($Y$3,I97<>""), I97, "") -> 10202.15 | AA97: =CHOOSE( $A$2, IF(AND($Y$3,Q97<>""), Q97, ""), IF(AND($Y$3,Q97<>""), INDEX($Q:$Q, MATCH($A97,$P:$P, 0)-1), "") ) -> 0.8058 | AB97: =IF(AND($AB$3,J97<>""), J97, "") -> 2.67 | AC97: =IF(AND($AB$3,K97<>""), K97, "") -> 10202.15 | AD97: =CHOOSE( $A$2, IF(AND($AB$3,R97<>""), R97, ""), IF(AND($AB$3,R97<>""), INDEX($R:$R, MATCH($A97,$P:$P, 0)-1), "") ) -> 0.8036 | AE97: =IF(AND($AE$3,L97<>""), L97, "") | AF97: =IF(AND($AE$3,M97<>""), M97, "") | AG97: =CHOOSE( $A$2, IF(AND($AE$3,S97<>""), S97, ""), IF(AND($AE$3,S97<>""), INDEX($S:$S, MATCH($A97,$P:$P, 0)-1), "") ) | AH97: =IF(AND($AH$3,N97<>""), N97, "") | AI97: =IF(AND($AH$3,O97<>""), O97, "") | AJ97: =CHOOSE( $A$2, IF(AND($AH$3,T97<>""), T97, ""), IF(AND($AH$3,T97<>""), INDEX($T:$T, MATCH($A97,$P:$P, 0)-1), "") )
A98: 45699 | B98: 2.678 | C98: 10200.72 | D98: 0.8068 | E98: 2.678 | F98: 10200.68 | G98: 0.8099 | H98: 2.67 | I98: 10201.41 | J98: 2.68 | K98: 10200.58 | L98: 2.685 | M98: 10200.17 | N98: 2.68 | O98: 10200.58 | P98: 45699 | Q98: 0.8086 | R98: 0.8062 | S98: 0.8058 | T98: 0.8193 | V98: =IF($A98="", "", CHOOSE( $W$1, AVERAGE(Y98,AB98,AE98,AH98), GEOMEAN(Y98,AB98,AE98,AH98) ) ) -> 2.675 | W98: =IF($A98="", "", CHOOSE( $W$1, AVERAGE(Z98,AC98,AF98,AI98), GEOMEAN(Z98,AC98,AF98,AI98) ) ) -> 10200.995 | X98: =IF($A98="", "", CHOOSE( $W$1, AVERAGE(AA98,AD98,AG98,AJ98), GEOMEAN(AA98,AD98,AG98,AJ98) ) ) -> 0.8074 | Y98: =IF(AND($Y$3,H98<>""), H98, "") -> 2.67 | Z98: =IF(AND($Y$3,I98<>""), I98, "") -> 10201.41 | AA98: =CHOOSE( $A$2, IF(AND($Y$3,Q98<>""), Q98, ""), IF(AND($Y$3,Q98<>""), INDEX($Q:$Q, MATCH($A98,$P:$P, 0)-1), "") ) -> 0.8086 | AB98: =IF(AND($AB$3,J98<>""), J98, "") -> 2.68 | AC98: =IF(AND($AB$3,K98<>""), K98, "") -> 10200.58 | AD98: =CHOOSE( $A$2, IF(AND($AB$3,R98<>""), R98, ""), IF(AND($AB$3,R98<>""), INDEX($R:$R, MATCH($A98,$P:$P, 0)-1), "") ) -> 0.8062 | AE98: =IF(AND($AE$3,L98<>""), L98, "") | AF98: =IF(AND($AE$3,M98<>""), M98, "") | AG98: =CHOOSE( $A$2, IF(AND($AE$3,S98<>""), S98, ""), IF(AND($AE$3,S98<>""), INDEX($S:$S, MATCH($A98,$P:$P, 0)-1), "") ) | AH98: =IF(AND($AH$3,N98<>""), N98, "") | AI98: =IF(AND($AH$3,O98<>""), O98, "") | AJ98: =CHOOSE( $A$2, IF(AND($AH$3,T98<>""), T98, ""), IF(AND($AH$3,T98<>""), INDEX($T:$T, MATCH($A98,$P:$P, 0)-1), "") )
A99: 45698 | B99: 2.688 | C99: 10199.15 | D99: 0.8113 | E99: 2.688 | F99: 10199.11 | G99: 0.814 | H99: 2.68 | I99: 10199.84 | J99: 2.695 | K99: 10198.6 | L99: 2.69 | M99: 10199.01 | N99: 2.69 | O99: 10199.01 | P99: 45698 | Q99: 0.8166 | R99: 0.8089 | S99: 0.8085 | T99: 0.822 | V99: =IF($A99="", "", CHOOSE( $W$1, AVERAGE(Y99,AB99,AE99,AH99), GEOMEAN(Y99,AB99,AE99,AH99) ) ) -> 2.6875 | W99: =IF($A99="", "", CHOOSE( $W$1, AVERAGE(Z99,AC99,AF99,AI99), GEOMEAN(Z99,AC99,AF99,AI99) ) ) -> 10199.22 | X99: =IF($A99="", "", CHOOSE( $W$1, AVERAGE(AA99,AD99,AG99,AJ99), GEOMEAN(AA99,AD99,AG99,AJ99) ) ) -> 0.81275 | Y99: =IF(AND($Y$3,H99<>""), H99, "") -> 2.68 | Z99: =IF(AND($Y$3,I99<>""), I99, "") -> 10199.84 | AA99: =CHOOSE( $A$2, IF(AND($Y$3,Q99<>""), Q99, ""), IF(AND($Y$3,Q99<>""), INDEX($Q:$Q, MATCH($A99,$P:$P, 0)-1), "") ) -> 0.8166 | AB99: =IF(AND($AB$3,J99<>""), J99, "") -> 2.695 | AC99: =IF(AND($AB$3,K99<>""), K99, "") -> 10198.6 | AD99: =CHOOSE( $A$2, IF(AND($AB$3,R99<>""), R99, ""), IF(AND($AB$3,R99<>""), INDEX($R:$R, MATCH($A99,$P:$P, 0)-1), "") ) -> 0.8089 | AE99: =IF(AND($AE$3,L99<>""), L99, "") | AF99: =IF(AND($AE$3,M99<>""), M99, "") | AG99: =CHOOSE( $A$2, IF(AND($AE$3,S99<>""), S99, ""), IF(AND($AE$3,S99<>""), INDEX($S:$S, MATCH($A99,$P:$P, 0)-1), "") ) | AH99: =IF(AND($AH$3,N99<>""), N99, "") | AI99: =IF(AND($AH$3,O99<>""), O99, "") | AJ99: =CHOOSE( $A$2, IF(AND($AH$3,T99<>""), T99, ""), IF(AND($AH$3,T99<>""), INDEX($T:$T, MATCH($A99,$P:$P, 0)-1), "") )
A100: 45697 | B100: 2.688 | C100: 10198.4 | D100: 0.8131 | E100: 2.688 | F100: 10198.37 | G100: 0.816 | H100: 2.68 | I100: 10199.1 | J100: 2.695 | K100: 10197.85 | L100: 2.69 | M100: 10198.27 | N100: 2.69 | O100: 10198.27 | P100: 45697 | Q100: 0.8166 | R100: 0.8116 | S100: 0.8112 | T100: 0.8248 | V100: =IF($A100="", "", CHOOSE( $W$1, AVERAGE(Y100,AB100,AE100,AH100), GEOMEAN(Y100,AB100,AE100,AH100) ) ) -> 2.6875 | W100: =IF($A100="", "", CHOOSE( $W$1, AVERAGE(Z100,AC100,AF100,AI100), GEOMEAN(Z100,AC100,AF100,AI100) ) ) -> 10198.475 | X100: =IF($A100="", "", CHOOSE( $W$1, AVERAGE(AA100,AD100,AG100,AJ100), GEOMEAN(AA100,AD100,AG100,AJ100) ) ) -> 0.8141 | Y100: =IF(AND($Y$3,H100<>""), H100, "") -> 2.68 | Z100: =IF(AND($Y$3,I100<>""), I100, "") -> 10199.1 | AA100: =CHOOSE( $A$2, IF(AND($Y$3,Q100<>""), Q100, ""), IF(AND($Y$3,Q100<>""), INDEX($Q:$Q, MATCH($A100,$P:$P, 0)-1), "") ) -> 0.8166 | AB100: =IF(AND($AB$3,J100<>""), J100, "") -> 2.695 | AC100: =IF(AND($AB$3,K100<>""), K100, "") -> 10197.85 | AD100: =CHOOSE( $A$2, IF(AND($AB$3,R100<>""), R100, ""), IF(AND($AB$3,R100<>""), INDEX($R:$R, MATCH($A100,$P:$P, 0)-1), "") ) -> 0.8116 | AE100: =IF(AND($AE$3,L100<>""), L100, "") | AF100: =IF(AND($AE$3,M100<>""), M100, "") | AG100: =CHOOSE( $A$2, IF(AND($AE$3,S100<>""), S100, ""), IF(AND($AE$3,S100<>""), INDEX($S:$S, MATCH($A100,$P:$P, 0)-1), "") ) | AH100: =IF(AND($AH$3,N100<>""), N100, "") | AI100: =IF(AND($AH$3,O100<>""), O100, "") | AJ100: =CHOOSE( $A$2, IF(AND($AH$3,T100<>""), T100, ""), IF(AND($AH$3,T100<>""), INDEX($T:$T, MATCH($A100,$P:$P, 0)-1), "") )
A101: 45696 | B101: 2.688 | C101: 10197.65 | D101: 0.8149 | E101: 2.688 | F101: 10197.62 | G101: 0.818 | H101: 2.68 | I101: 10198.35 | J101: 2.695 | K101: 10197.1 | L101: 2.69 | M101: 10197.52 | N101: 2.69 | O101: 10197.52 | P101: 45696 | Q101: 0.8166 | R101: 0.8143 | S101: 0.8139 | T101: 0.8275 | V101: =IF($A101="", "", CHOOSE( $W$1, AVERAGE(Y101,AB101,AE101,AH101), GEOMEAN(Y101,AB101,AE101,AH101) ) ) -> 2.6875 | W101: =IF($A101="", "", CHOOSE( $W$1, AVERAGE(Z101,AC101,AF101,AI101), GEOMEAN(Z101,AC101,AF101,AI101) ) ) -> 10197.725 | X101: =IF($A101="", "", CHOOSE( $W$1, AVERAGE(AA101,AD101,AG101,AJ101), GEOMEAN(AA101,AD101,AG101,AJ101) ) ) -> 0.81545 | Y101: =IF(AND($Y$3,H101<>""), H101, "") -> 2.68 | Z101: =IF(AND($Y$3,I101<>""), I101, "") -> 10198.35 | AA101: =CHOOSE( $A$2, IF(AND($Y$3,Q101<>""), Q101, ""), IF(AND($Y$3,Q101<>""), INDEX($Q:$Q, MATCH($A101,$P:$P, 0)-1), "") ) -> 0.8166 | AB101: =IF(AND($AB$3,J101<>""), J101, "") -> 2.695 | AC101: =IF(AND($AB$3,K101<>""), K101, "") -> 10197.1 | AD101: =CHOOSE( $A$2, IF(AND($AB$3,R101<>""), R101, ""), IF(AND($AB$3,R101<>""), INDEX($R:$R, MATCH($A101,$P:$P, 0)-1), "") ) -> 0.8143 | AE101: =IF(AND($AE$3,L101<>""), L101, "") | AF101: =IF(AND($AE$3,M101<>""), M101, "") | AG101: =CHOOSE( $A$2, IF(AND($AE$3,S101<>""), S101, ""), IF(AND($AE$3,S101<>""), INDEX($S:$S, MATCH($A101,$P:$P, 0)-1), "") ) | AH101: =IF(AND($AH$3,N101<>""), N101, "") | AI101: =IF(AND($AH$3,O101<>""), O101, "") | AJ101: =CHOOSE( $A$2, IF(AND($AH$3,T101<>""), T101, ""), IF(AND($AH$3,T101<>""), INDEX($T:$T, MATCH($A101,$P:$P, 0)-1), "") )
A102: 45695 | B102: 2.684 | C102: 10197.27 | D102: 0.8176 | E102: 2.684 | F102: 10197.25 | G102: 0.8208 | H102: 2.68 | I102: 10197.61 | J102: 2.685 | K102: 10197.19 | L102: 2.687 | M102: 10197.02 | N102: 2.685 | O102: 10197.19 | P102: 45695 | Q102: 0.8194 | R102: 0.817 | S102: 0.8166 | T102: 0.8303 | V102: =IF($A102="", "", CHOOSE( $W$1, AVERAGE(Y102,AB102,AE102,AH102), GEOMEAN(Y102,AB102,AE102,AH102) ) ) -> 2.6825 | W102: =IF($A102="", "", CHOOSE( $W$1, AVERAGE(Z102,AC102,AF102,AI102), GEOMEAN(Z102,AC102,AF102,AI102) ) ) -> 10197.4 | X102: =IF($A102="", "", CHOOSE( $W$1, AVERAGE(AA102,AD102,AG102,AJ102), GEOMEAN(AA102,AD102,AG102,AJ102) ) ) -> 0.8182 | Y102: =IF(AND($Y$3,H102<>""), H102, "") -> 2.68 | Z102: =IF(AND($Y$3,I102<>""), I102, "") -> 10197.61 | AA102: =CHOOSE( $A$2, IF(AND($Y$3,Q102<>""), Q102, ""), IF(AND($Y$3,Q102<>""), INDEX($Q:$Q, MATCH($A102,$P:$P, 0)-1), "") ) -> 0.8194 | AB102: =IF(AND($AB$3,J102<>""), J102, "") -> 2.685 | AC102: =IF(AND($AB$3,K102<>""), K102, "") -> 10197.19 | AD102: =CHOOSE( $A$2, IF(AND($AB$3,R102<>""), R102, ""), IF(AND($AB$3,R102<>""), INDEX($R:$R, MATCH($A102,$P:$P, 0)-1), "") ) -> 0.817 | AE102: =IF(AND($AE$3,L102<>""), L102, "") | AF102: =IF(AND($AE$3,M102<>""), M102, "") | AG102: =CHOOSE( $A$2, IF(AND($AE$3,S102<>""), S102, ""), IF(AND($AE$3,S102<>""), INDEX($S:$S, MATCH($A102,$P:$P, 0)-1), "") ) | AH102: =IF(AND($AH$3,N102<>""), N102, "") | AI102: =IF(AND($AH$3,O102<>""), O102, "") | AJ102: =CHOOSE( $A$2, IF(AND($AH$3,T102<>""), T102, ""), IF(AND($AH$3,T102<>""), INDEX($T:$T, MATCH($A102,$P:$P, 0)-1), "") )
A103: 45694 | B103: 2.683 | C103: 10196.58 | D103: 0.8203 | E103: 2.683 | F103: 10196.54 | G103: 0.8235 | H103: 2.68 | I103: 10196.86 | J103: 2.685 | K103: 10196.44 | L103: 2.685 | M103: 10196.44 | N103: 2.685 | O103: 10196.44 | P103: 45694 | Q103: 0.8221 | R103: 0.8197 | S103: 0.8193 | T103: 0.833 | V103: =IF($A103="", "", CHOOSE( $W$1, AVERAGE(Y103,AB103,AE103,AH103), GEOMEAN(Y103,AB103,AE103,AH103) ) ) -> 2.6825 | W103: =IF($A103="", "", CHOOSE( $W$1, AVERAGE(Z103,AC103,AF103,AI103), GEOMEAN(Z103,AC103,AF103,AI103) ) ) -> 10196.65 | X103: =IF($A103="", "", CHOOSE( $W$1, AVERAGE(AA103,AD103,AG103,AJ103), GEOMEAN(AA103,AD103,AG103,AJ103) ) ) -> 0.8209 | Y103: =IF(AND($Y$3,H103<>""), H103, "") -> 2.68 | Z103: =IF(AND($Y$3,I103<>""), I103, "") -> 10196.86 | AA103: =CHOOSE( $A$2, IF(AND($Y$3,Q103<>""), Q103, ""), IF(AND($Y$3,Q103<>""), INDEX($Q:$Q, MATCH($A103,$P:$P, 0)-1), "") ) -> 0.8221 | AB103: =IF(AND($AB$3,J103<>""), J103, "") -> 2.685 | AC103: =IF(AND($AB$3,K103<>""), K103, "") -> 10196.44 | AD103: =CHOOSE( $A$2, IF(AND($AB$3,R103<>""), R103, ""), IF(AND($AB$3,R103<>""), INDEX($R:$R, MATCH($A103,$P:$P, 0)-1), "") ) -> 0.8197 | AE103: =IF(AND($AE$3,L103<>""), L103, "") | AF103: =IF(AND($AE$3,M103<>""), M103, "") | AG103: =CHOOSE( $A$2, IF(AND($AE$3,S103<>""), S103, ""), IF(AND($AE$3,S103<>""), INDEX($S:$S, MATCH($A103,$P:$P, 0)-1), "") ) | AH103: =IF(AND($AH$3,N103<>""), N103, "") | AI103: =IF(AND($AH$3,O103<>""), O103, "") | AJ103: =CHOOSE( $A$2, IF(AND($AH$3,T103<>""), T103, ""), IF(AND($AH$3,T103<>""), INDEX($T:$T, MATCH($A103,$P:$P, 0)-1), "") )
A104: 45693 | B104: 2.676 | C104: 10196.4 | D104: 0.8231 | E104: 2.675 | F104: 10196.54 | G104: 0.8263 | H104: 2.68 | I104: 10196.12 | J104: 2.67 | K104: 10196.96 | L104: 2.68 | M104: 10196.12 | N104: 2.67 | O104: 10196.96 | P104: 45693 | Q104: 0.8248 | R104: 0.8225 | S104: 0.8221 | T104: 0.8358 | V104: =IF($A104="", "", CHOOSE( $W$1, AVERAGE(Y104,AB104,AE104,AH104), GEOMEAN(Y104,AB104,AE104,AH104) ) ) -> 2.675 | W104: =IF($A104="", "", CHOOSE( $W$1, AVERAGE(Z104,AC104,AF104,AI104), GEOMEAN(Z104,AC104,AF104,AI104) ) ) -> 10196.54 | X104: =IF($A104="", "", CHOOSE( $W$1, AVERAGE(AA104,AD104,AG104,AJ104), GEOMEAN(AA104,AD104,AG104,AJ104) ) ) -> 0.82365 | Y104: =IF(AND($Y$3,H104<>""), H104, "") -> 2.68 | Z104: =IF(AND($Y$3,I104<>""), I104, "") -> 10196.12 | AA104: =CHOOSE( $A$2, IF(AND($Y$3,Q104<>""), Q104, ""), IF(AND($Y$3,Q104<>""), INDEX($Q:$Q, MATCH($A104,$P:$P, 0)-1), "") ) -> 0.8248 | AB104: =IF(AND($AB$3,J104<>""), J104, "") -> 2.67 | AC104: =IF(AND($AB$3,K104<>""), K104, "") -> 10196.96 | AD104: =CHOOSE( $A$2, IF(AND($AB$3,R104<>""), R104, ""), IF(AND($AB$3,R104<>""), INDEX($R:$R, MATCH($A104,$P:$P, 0)-1), "") ) -> 0.8225 | AE104: =IF(AND($AE$3,L104<>""), L104, "") | AF104: =IF(AND($AE$3,M104<>""), M104, "") | AG104: =CHOOSE( $A$2, IF(AND($AE$3,S104<>""), S104, ""), IF(AND($AE$3,S104<>""), INDEX($S:$S, MATCH($A104,$P:$P, 0)-1), "") ) | AH104: =IF(AND($AH$3,N104<>""), N104, "") | AI104: =IF(AND($AH$3,O104<>""), O104, "") | AJ104: =CHOOSE( $A$2, IF(AND($AH$3,T104<>""), T104, ""), IF(AND($AH$3,T104<>""), INDEX($T:$T, MATCH($A104,$P:$P, 0)-1), "") )
A105: 45692 | B105: 2.66 | C105: 10197.06 | D105: 0.8259 | E105: 2.658 | F105: 10197.16 | G105: 0.829 | H105: 2.66 | I105: 10197.06 | J105: 2.655 | K105: 10197.48 | L105: 2.665 | M105: 10196.64 | N105: 2.655 | O105: 10197.48 | P105: 45692 | Q105: 0.8276 | R105: 0.8253 | S105: 0.8248 | T105: 0.8385 | V105: =IF($A105="", "", CHOOSE( $W$1, AVERAGE(Y105,AB105,AE105,AH105), GEOMEAN(Y105,AB105,AE105,AH105) ) ) -> 2.6575 | W105: =IF($A105="", "", CHOOSE( $W$1, AVERAGE(Z105,AC105,AF105,AI105), GEOMEAN(Z105,AC105,AF105,AI105) ) ) -> 10197.27 | X105: =IF($A105="", "", CHOOSE( $W$1, AVERAGE(AA105,AD105,AG105,AJ105), GEOMEAN(AA105,AD105,AG105,AJ105) ) ) -> 0.82645 | Y105: =IF(AND($Y$3,H105<>""), H105, "") -> 2.66 | Z105: =IF(AND($Y$3,I105<>""), I105, "") -> 10197.06 | AA105: =CHOOSE( $A$2, IF(AND($Y$3,Q105<>""), Q105, ""), IF(AND($Y$3,Q105<>""), INDEX($Q:$Q, MATCH($A105,$P:$P, 0)-1), "") ) -> 0.8276 | AB105: =IF(AND($AB$3,J105<>""), J105, "") -> 2.655 | AC105: =IF(AND($AB$3,K105<>""), K105, "") -> 10197.48 | AD105: =CHOOSE( $A$2, IF(AND($AB$3,R105<>""), R105, ""), IF(AND($AB$3,R105<>""), INDEX($R:$R, MATCH($A105,$P:$P, 0)-1), "") ) -> 0.8253 | AE105: =IF(AND($AE$3,L105<>""), L105, "") | AF105: =IF(AND($AE$3,M105<>""), M105, "") | AG105: =CHOOSE( $A$2, IF(AND($AE$3,S105<>""), S105, ""), IF(AND($AE$3,S105<>""), INDEX($S:$S, MATCH($A105,$P:$P, 0)-1), "") ) | AH105: =IF(AND($AH$3,N105<>""), N105, "") | AI105: =IF(AND($AH$3,O105<>""), O105, "") | AJ105: =CHOOSE( $A$2, IF(AND($AH$3,T105<>""), T105, ""), IF(AND($AH$3,T105<>""), INDEX($T:$T, MATCH($A105,$P:$P, 0)-1), "") )
P106: 45691 | Q106: 0.8357 | R106: 0.828 | S106: 0.8276 | T106: 0.8413
P107: 45690 | Q107: 0.8357 | R107: 0.8307 | S107: 0.8303 | T107: 0.844
P108: 45689 | Q108: 0.8357 | R108: 0.8334 | S108: 0.833 | T108: 0.8468
P109: 45688 | Q109: 0.8547 | R109: 0.8361 | S109: 0.8357 | T109: 0.8495
P110: 45687 | Q110: 0.8547 | R110: 0.8388 | S110: 0.8384 | T110: 0.8523
P111: 45686 | Q111: 0.8547 | R111: 0.8415 | S111: 0.8411 | T111: 0.855
P112: 45685 | Q112: 0.8547 | R112: 0.8442 | S112: 0.8438 | T112: 0.8578
