Workbook

Sheet 스프레드
B2: 국채 지표-비지표 스프레드
B4: =TODAY() -> 45653 | D4: * 당일 체결 없는 경우 및 과거일자는 민평으로 계산 | G4: * 2021-03-11 이전 2Y 조회시 통안 데이터.
D6: =IF(D$11="", "", $C11&"-"&D11) -> (24-9)-(24-3) | E6: =IF(E$11="", "", $C11&"-"&E11) -> (24-9)-(23-8) | F6: =IF(F$11="", "", $C11&"-"&F11) -> (24-9)-(23-3) | G6: =IF(G$11="", "", $C11&"-"&G11) -> (24-9)-(22-15) | H6: =IF(H$11="", "", $C11&"-"&H11) -> (24-9)-(22-10) | I6: =IF(I$11="", "", $C11&"-"&I11) -> (24-9)-(22-7) | J6: =IF(J$11="", "", $C11&"-"&J11) -> (24-9)-(22-3) | K6: =IF(K$11="", "", $C11&"-"&K11) -> (24-9)-(21-12)
C7: 현재 스프레드 | D7: =IFERROR( D12, "") -> 3.2 | E7: =IFERROR( E12, "") -> 8 | F7: =IFERROR( F12, "") -> -7 | G7: =IFERROR( G12, "") -> -9 | H7: =IFERROR( H12, "") -> -40 | I7: =IFERROR( I12, "") -> -58.2 | J7: =IFERROR( J12, "") -> -66 | K7: =IFERROR( K12, "") -> -51
C8: 전일 스프레드 | D8: =IFERROR(data!P16, "") -> 3.6 | E8: =IFERROR(data!Q16, "") -> 8.4 | F8: =IFERROR(data!R16, "") -> -6.6 | G8: =IFERROR(data!S16, "") | H8: =IFERROR(data!T16, "") | I8: =IFERROR(data!U16, "") | J8: =IFERROR(data!V16, "") | K8: =IFERROR(data!W16, "")
C9: 대비 | D9: =IFERROR( D7-D8, "") -> -0.4 | E9: =IFERROR( E7-E8, "") -> -0.4 | F9: =IFERROR( F7-F8, "") -> -0.4 | G9: =IFERROR( G7-G8, "") | H9: =IFERROR( H7-H8, "") | I9: =IFERROR( I7-I8, "") | J9: =IFERROR( J7-J8, "") | K9: =IFERROR( K7-K8, "")
C11: =data!F$13 -> (24-9) | D11: =data!G$13 -> (24-3) | E11: =data!H$13 -> (23-8) | F11: =data!I$13 -> (23-3) | G11: =data!J$13 -> (22-15) | H11: =data!K$13 -> (22-10) | I11: =data!L$13 -> (22-7) | J11: =data!M$13 -> (22-3) | K11: =data!N$13 -> (21-12) | L11: 현재가 | M11: 민평3사
B12: =IF( data!E16= "", "", data!E16) -> KR103503GE96 | C12: →현재 | D12: =IFERROR( ( $L12 - OFFSET($L$11, MATCH(D$11, $C$11:$K$11, 0 ), 0) ) *100, "") -> 3.2 | E12: =IFERROR( ( $L12 - OFFSET($L$11, MATCH(E$11, $C$11:$K$11, 0 ), 0) ) *100, "") -> 8 | F12: =IFERROR( ( $L12 - OFFSET($L$11, MATCH(F$11, $C$11:$K$11, 0 ), 0) ) *100, "") -> -7 | G12: =IFERROR( ( $L12 - OFFSET($L$11, MATCH(G$11, $C$11:$K$11, 0 ), 0) ) *100, "") -> -9 | H12: =IFERROR( ( $L12 - OFFSET($L$11, MATCH(H$11, $C$11:$K$11, 0 ), 0) ) *100, "") -> -40 | I12: =IFERROR( ( $L12 - OFFSET($L$11, MATCH(I$11, $C$11:$K$11, 0 ), 0) ) *100, "") -> -58.2 | J12: =IFERROR( ( $L12 - OFFSET($L$11, MATCH(J$11, $C$11:$K$11, 0 ), 0) ) *100, "") -> -66 | K12: =IFERROR( ( $L12 - OFFSET($L$11, MATCH(K$11, $C$11:$K$11, 0 ), 0) ) *100, "") -> -51 | L12: =data!L16 -> 2.793 | M12: =data!F16 -> 2.797
B13: =IF( data!E17= "", "", data!E17) -> KR103503GE39 | C13: =IFERROR( OFFSET($C$12, MATCH(C$11, $C$11:$K$11, 0)-1, MATCH($B13, $B$12:$B$20, 0)-1 ) - OFFSET(data!$O$16, MATCH(C$11, $C$11:$K$11, 0)-1, MATCH($B13, $B$12:$B$20, 0)-1 ), "") -> -0.4 | D13: ↓대비 | E13: =IFERROR( ( $L13 - OFFSET($L$11, MATCH(E$11, $C$11:$K$11, 0 ), 0) ) *100, "") -> 4.8 | F13: =IFERROR( ( $L13 - OFFSET($L$11, MATCH(F$11, $C$11:$K$11, 0 ), 0) ) *100, "") -> -10.2 | G13: =IFERROR( ( $L13 - OFFSET($L$11, MATCH(G$11, $C$11:$K$11, 0 ), 0) ) *100, "") -> -12.2 | H13: =IFERROR( ( $L13 - OFFSET($L$11, MATCH(H$11, $C$11:$K$11, 0 ), 0) ) *100, "") -> -43.2 | I13: =IFERROR( ( $L13 - OFFSET($L$11, MATCH(I$11, $C$11:$K$11, 0 ), 0) ) *100, "") -> -61.4 | J13: =IFERROR( ( $L13 - OFFSET($L$11, MATCH(J$11, $C$11:$K$11, 0 ), 0) ) *100, "") -> -69.2 | K13: =IFERROR( ( $L13 - OFFSET($L$11, MATCH(K$11, $C$11:$K$11, 0 ), 0) ) *100, "") -> -54.2 | L13: =data!L17 -> 2.761 | M13: =data!F17 -> 2.761
B14: =IF( data!E18= "", "", data!E18) -> KR103503GD97 | C14: =IFERROR( OFFSET($C$12, MATCH(C$11, $C$11:$K$11, 0)-1, MATCH($B14, $B$12:$B$20, 0)-1 ) - OFFSET(data!$O$16, MATCH(C$11, $C$11:$K$11, 0)-1, MATCH($B14, $B$12:$B$20, 0)-1 ), "") -> -0.4 | D14: =IFERROR( OFFSET($C$12, MATCH(D$11, $C$11:$K$11, 0)-1, MATCH($B14, $B$12:$B$20, 0)-1 ) - OFFSET(data!$O$16, MATCH(D$11, $C$11:$K$11, 0)-1, MATCH($B14, $B$12:$B$20, 0)-1 ), "") -> 0 | F14: =IFERROR( ( $L14 - OFFSET($L$11, MATCH(F$11, $C$11:$K$11, 0 ), 0) ) *100, "") -> -15 | G14: =IFERROR( ( $L14 - OFFSET($L$11, MATCH(G$11, $C$11:$K$11, 0 ), 0) ) *100, "") -> -17 | H14: =IFERROR( ( $L14 - OFFSET($L$11, MATCH(H$11, $C$11:$K$11, 0 ), 0) ) *100, "") -> -48 | I14: =IFERROR( ( $L14 - OFFSET($L$11, MATCH(I$11, $C$11:$K$11, 0 ), 0) ) *100, "") -> -66.2 | J14: =IFERROR( ( $L14 - OFFSET($L$11, MATCH(J$11, $C$11:$K$11, 0 ), 0) ) *100, "") -> -74 | K14: =IFERROR( ( $L14 - OFFSET($L$11, MATCH(K$11, $C$11:$K$11, 0 ), 0) ) *100, "") -> -59 | L14: =data!L18 -> 2.713 | M14: =data!F18 -> 2.713
B15: =IF( data!E19= "", "", data!E19) -> KR103503GD30 | C15: =IFERROR( OFFSET($C$12, MATCH(C$11, $C$11:$K$11, 0)-1, MATCH($B15, $B$12:$B$20, 0)-1 ) - OFFSET(data!$O$16, MATCH(C$11, $C$11:$K$11, 0)-1, MATCH($B15, $B$12:$B$20, 0)-1 ), "") -> -0.4 | D15: =IFERROR( OFFSET($C$12, MATCH(D$11, $C$11:$K$11, 0)-1, MATCH($B15, $B$12:$B$20, 0)-1 ) - OFFSET(data!$O$16, MATCH(D$11, $C$11:$K$11, 0)-1, MATCH($B15, $B$12:$B$20, 0)-1 ), "") -> 0 | E15: =IFERROR( OFFSET($C$12, MATCH(E$11, $C$11:$K$11, 0)-1, MATCH($B15, $B$12:$B$20, 0)-1 ) - OFFSET(data!$O$16, MATCH(E$11, $C$11:$K$11, 0)-1, MATCH($B15, $B$12:$B$20, 0)-1 ), "") -> 0 | G15: =IFERROR( ( $L15 - OFFSET($L$11, MATCH(G$11, $C$11:$K$11, 0 ), 0) ) *100, "") -> -2 | H15: =IFERROR( ( $L15 - OFFSET($L$11, MATCH(H$11, $C$11:$K$11, 0 ), 0) ) *100, "") -> -33 | I15: =IFERROR( ( $L15 - OFFSET($L$11, MATCH(I$11, $C$11:$K$11, 0 ), 0) ) *100, "") -> -51.2 | J15: =IFERROR( ( $L15 - OFFSET($L$11, MATCH(J$11, $C$11:$K$11, 0 ), 0) ) *100, "") -> -59 | K15: =IFERROR( ( $L15 - OFFSET($L$11, MATCH(K$11, $C$11:$K$11, 0 ), 0) ) *100, "") -> -44 | L15: =data!L19 -> 2.863 | M15: =data!F19 -> 2.863
B16: =IF( data!E20= "", "", data!E20) -> KR103503GCC6 | C16: =IFERROR( OFFSET($C$12, MATCH(C$11, $C$11:$K$11, 0)-1, MATCH($B16, $B$12:$B$20, 0)-1 ) - OFFSET(data!$O$16, MATCH(C$11, $C$11:$K$11, 0)-1, MATCH($B16, $B$12:$B$20, 0)-1 ), "") | D16: =IFERROR( OFFSET($C$12, MATCH(D$11, $C$11:$K$11, 0)-1, MATCH($B16, $B$12:$B$20, 0)-1 ) - OFFSET(data!$O$16, MATCH(D$11, $C$11:$K$11, 0)-1, MATCH($B16, $B$12:$B$20, 0)-1 ), "") | E16: =IFERROR( OFFSET($C$12, MATCH(E$11, $C$11:$K$11, 0)-1, MATCH($B16, $B$12:$B$20, 0)-1 ) - OFFSET(data!$O$16, MATCH(E$11, $C$11:$K$11, 0)-1, MATCH($B16, $B$12:$B$20, 0)-1 ), "") | F16: =IFERROR( OFFSET($C$12, MATCH(F$11, $C$11:$K$11, 0)-1, MATCH($B16, $B$12:$B$20, 0)-1 ) - OFFSET(data!$O$16, MATCH(F$11, $C$11:$K$11, 0)-1, MATCH($B16, $B$12:$B$20, 0)-1 ), "") | H16: =IFERROR( ( $L16 - OFFSET($L$11, MATCH(H$11, $C$11:$K$11, 0 ), 0) ) *100, "") -> -31 | I16: =IFERROR( ( $L16 - OFFSET($L$11, MATCH(I$11, $C$11:$K$11, 0 ), 0) ) *100, "") -> -49.2 | J16: =IFERROR( ( $L16 - OFFSET($L$11, MATCH(J$11, $C$11:$K$11, 0 ), 0) ) *100, "") -> -57 | K16: =IFERROR( ( $L16 - OFFSET($L$11, MATCH(K$11, $C$11:$K$11, 0 ), 0) ) *100, "") -> -42 | L16: =data!L20 -> 2.883 | M16: =data!F20 -> 2.883
B17: =IF( data!E21= "", "", data!E21) -> KR103503GC98 | C17: =IFERROR( OFFSET($C$12, MATCH(C$11, $C$11:$K$11, 0)-1, MATCH($B17, $B$12:$B$20, 0)-1 ) - OFFSET(data!$O$16, MATCH(C$11, $C$11:$K$11, 0)-1, MATCH($B17, $B$12:$B$20, 0)-1 ), "") | D17: =IFERROR( OFFSET($C$12, MATCH(D$11, $C$11:$K$11, 0)-1, MATCH($B17, $B$12:$B$20, 0)-1 ) - OFFSET(data!$O$16, MATCH(D$11, $C$11:$K$11, 0)-1, MATCH($B17, $B$12:$B$20, 0)-1 ), "") | E17: =IFERROR( OFFSET($C$12, MATCH(E$11, $C$11:$K$11, 0)-1, MATCH($B17, $B$12:$B$20, 0)-1 ) - OFFSET(data!$O$16, MATCH(E$11, $C$11:$K$11, 0)-1, MATCH($B17, $B$12:$B$20, 0)-1 ), "") | F17: =IFERROR( OFFSET($C$12, MATCH(F$11, $C$11:$K$11, 0)-1, MATCH($B17, $B$12:$B$20, 0)-1 ) - OFFSET(data!$O$16, MATCH(F$11, $C$11:$K$11, 0)-1, MATCH($B17, $B$12:$B$20, 0)-1 ), "") | G17: =IFERROR( OFFSET($C$12, MATCH(G$11, $C$11:$K$11, 0)-1, MATCH($B17, $B$12:$B$20, 0)-1 ) - OFFSET(data!$O$16, MATCH(G$11, $C$11:$K$11, 0)-1, MATCH($B17, $B$12:$B$20, 0)-1 ), "") | I17: =IFERROR( ( $L17 - OFFSET($L$11, MATCH(I$11, $C$11:$K$11, 0 ), 0) ) *100, "") -> -18.2 | J17: =IFERROR( ( $L17 - OFFSET($L$11, MATCH(J$11, $C$11:$K$11, 0 ), 0) ) *100, "") -> -26 | K17: =IFERROR( ( $L17 - OFFSET($L$11, MATCH(K$11, $C$11:$K$11, 0 ), 0) ) *100, "") -> -11 | L17: =data!L21 -> 3.193 | M17: =data!F21 -> 3.193
B18: =IF( data!E22= "", "", data!E22) -> KR103504GC63 | C18: =IFERROR( OFFSET($C$12, MATCH(C$11, $C$11:$K$11, 0)-1, MATCH($B18, $B$12:$B$20, 0)-1 ) - OFFSET(data!$O$16, MATCH(C$11, $C$11:$K$11, 0)-1, MATCH($B18, $B$12:$B$20, 0)-1 ), "") | D18: =IFERROR( OFFSET($C$12, MATCH(D$11, $C$11:$K$11, 0)-1, MATCH($B18, $B$12:$B$20, 0)-1 ) - OFFSET(data!$O$16, MATCH(D$11, $C$11:$K$11, 0)-1, MATCH($B18, $B$12:$B$20, 0)-1 ), "") | E18: =IFERROR( OFFSET($C$12, MATCH(E$11, $C$11:$K$11, 0)-1, MATCH($B18, $B$12:$B$20, 0)-1 ) - OFFSET(data!$O$16, MATCH(E$11, $C$11:$K$11, 0)-1, MATCH($B18, $B$12:$B$20, 0)-1 ), "") | F18: =IFERROR( OFFSET($C$12, MATCH(F$11, $C$11:$K$11, 0)-1, MATCH($B18, $B$12:$B$20, 0)-1 ) - OFFSET(data!$O$16, MATCH(F$11, $C$11:$K$11, 0)-1, MATCH($B18, $B$12:$B$20, 0)-1 ), "") | G18: =IFERROR( OFFSET($C$12, MATCH(G$11, $C$11:$K$11, 0)-1, MATCH($B18, $B$12:$B$20, 0)-1 ) - OFFSET(data!$O$16, MATCH(G$11, $C$11:$K$11, 0)-1, MATCH($B18, $B$12:$B$20, 0)-1 ), "") | H18: =IFERROR( OFFSET($C$12, MATCH(H$11, $C$11:$K$11, 0)-1, MATCH($B18, $B$12:$B$20, 0)-1 ) - OFFSET(data!$O$16, MATCH(H$11, $C$11:$K$11, 0)-1, MATCH($B18, $B$12:$B$20, 0)-1 ), "") | J18: =IFERROR( ( $L18 - OFFSET($L$11, MATCH(J$11, $C$11:$K$11, 0 ), 0) ) *100, "") -> -7.8 | K18: =IFERROR( ( $L18 - OFFSET($L$11, MATCH(K$11, $C$11:$K$11, 0 ), 0) ) *100, "") -> 7.2 | L18: =data!L22 -> 3.375 | M18: =data!F22 -> 3.375
B19: =IF( data!E23= "", "", data!E23) -> KR103503GC31 | C19: =IFERROR( OFFSET($C$12, MATCH(C$11, $C$11:$K$11, 0)-1, MATCH($B19, $B$12:$B$20, 0)-1 ) - OFFSET(data!$O$16, MATCH(C$11, $C$11:$K$11, 0)-1, MATCH($B19, $B$12:$B$20, 0)-1 ), "") | D19: =IFERROR( OFFSET($C$12, MATCH(D$11, $C$11:$K$11, 0)-1, MATCH($B19, $B$12:$B$20, 0)-1 ) - OFFSET(data!$O$16, MATCH(D$11, $C$11:$K$11, 0)-1, MATCH($B19, $B$12:$B$20, 0)-1 ), "") | E19: =IFERROR( OFFSET($C$12, MATCH(E$11, $C$11:$K$11, 0)-1, MATCH($B19, $B$12:$B$20, 0)-1 ) - OFFSET(data!$O$16, MATCH(E$11, $C$11:$K$11, 0)-1, MATCH($B19, $B$12:$B$20, 0)-1 ), "") | F19: =IFERROR( OFFSET($C$12, MATCH(F$11, $C$11:$K$11, 0)-1, MATCH($B19, $B$12:$B$20, 0)-1 ) - OFFSET(data!$O$16, MATCH(F$11, $C$11:$K$11, 0)-1, MATCH($B19, $B$12:$B$20, 0)-1 ), "") | G19: =IFERROR( OFFSET($C$12, MATCH(G$11, $C$11:$K$11, 0)-1, MATCH($B19, $B$12:$B$20, 0)-1 ) - OFFSET(data!$O$16, MATCH(G$11, $C$11:$K$11, 0)-1, MATCH($B19, $B$12:$B$20, 0)-1 ), "") | H19: =IFERROR( OFFSET($C$12, MATCH(H$11, $C$11:$K$11, 0)-1, MATCH($B19, $B$12:$B$20, 0)-1 ) - OFFSET(data!$O$16, MATCH(H$11, $C$11:$K$11, 0)-1, MATCH($B19, $B$12:$B$20, 0)-1 ), "") | I19: =IFERROR( OFFSET($C$12, MATCH(I$11, $C$11:$K$11, 0)-1, MATCH($B19, $B$12:$B$20, 0)-1 ) - OFFSET(data!$O$16, MATCH(I$11, $C$11:$K$11, 0)-1, MATCH($B19, $B$12:$B$20, 0)-1 ), "") | K19: =IFERROR( ( $L19 - OFFSET($L$11, MATCH(K$11, $C$11:$K$11, 0 ), 0) ) *100, "") -> 15 | L19: =data!L23 -> 3.453 | M19: =data!F23 -> 3.453
B20: =IF( data!E24= "", "", data!E24) -> KR103503GBC8 | C20: =IFERROR( OFFSET($C$12, MATCH(C$11, $C$11:$K$11, 0)-1, MATCH($B20, $B$12:$B$20, 0)-1 ) - OFFSET(data!$O$16, MATCH(C$11, $C$11:$K$11, 0)-1, MATCH($B20, $B$12:$B$20, 0)-1 ), "") | D20: =IFERROR( OFFSET($C$12, MATCH(D$11, $C$11:$K$11, 0)-1, MATCH($B20, $B$12:$B$20, 0)-1 ) - OFFSET(data!$O$16, MATCH(D$11, $C$11:$K$11, 0)-1, MATCH($B20, $B$12:$B$20, 0)-1 ), "") | E20: =IFERROR( OFFSET($C$12, MATCH(E$11, $C$11:$K$11, 0)-1, MATCH($B20, $B$12:$B$20, 0)-1 ) - OFFSET(data!$O$16, MATCH(E$11, $C$11:$K$11, 0)-1, MATCH($B20, $B$12:$B$20, 0)-1 ), "") | F20: =IFERROR( OFFSET($C$12, MATCH(F$11, $C$11:$K$11, 0)-1, MATCH($B20, $B$12:$B$20, 0)-1 ) - OFFSET(data!$O$16, MATCH(F$11, $C$11:$K$11, 0)-1, MATCH($B20, $B$12:$B$20, 0)-1 ), "") | G20: =IFERROR( OFFSET($C$12, MATCH(G$11, $C$11:$K$11, 0)-1, MATCH($B20, $B$12:$B$20, 0)-1 ) - OFFSET(data!$O$16, MATCH(G$11, $C$11:$K$11, 0)-1, MATCH($B20, $B$12:$B$20, 0)-1 ), "") | H20: =IFERROR( OFFSET($C$12, MATCH(H$11, $C$11:$K$11, 0)-1, MATCH($B20, $B$12:$B$20, 0)-1 ) - OFFSET(data!$O$16, MATCH(H$11, $C$11:$K$11, 0)-1, MATCH($B20, $B$12:$B$20, 0)-1 ), "") | I20: =IFERROR( OFFSET($C$12, MATCH(I$11, $C$11:$K$11, 0)-1, MATCH($B20, $B$12:$B$20, 0)-1 ) - OFFSET(data!$O$16, MATCH(I$11, $C$11:$K$11, 0)-1, MATCH($B20, $B$12:$B$20, 0)-1 ), "") | J20: =IFERROR( OFFSET($C$12, MATCH(J$11, $C$11:$K$11, 0)-1, MATCH($B20, $B$12:$B$20, 0)-1 ) - OFFSET(data!$O$16, MATCH(J$11, $C$11:$K$11, 0)-1, MATCH($B20, $B$12:$B$20, 0)-1 ), "") | L20: =data!L24 -> 3.303 | M20: =data!F24 -> 3.303

Sheet data
A1: 1 | E1: =스프레드!$B$4=TODAY() -> TRUE | O1: {=INDEX($P$3:$P$12, $O$2)} -> 45652 | P1: {=_xll.IMDH("BND", $B$6, $P$2:$Q$2, 스프레드!$B$4-30, 스프레드!$B$4, 10, "DtFmt=1, Per=일, sort=A, Bizday=0, Pos=20, Orient=V")} -> 조회[KR1035G00010] | X1: 1 | Y1: 2 | AA1: {=_xll.IMDH("BND", $Y$2, $AA$2:$AB$2, $Y$9, 스프레드!$B$4, 99999,"Per=일, Sort=D, Bizday=0, DtFmt=1, Quote=종가, Pos=02, Orient=V")} -> 조회[KR103503GE96] | AB1: {=_xll.IMDH("BND", $Y$3, $AB$2:$AB$2, $Y$9, 스프레드!$B$4, 99999,"Per=일, Sort=D, Bizday=0, DtFmt=1, Quote=종가, Pos=03, Orient=V")} -> 조회[KR103503GE39] | AC1: 45652 | AD1: 2.797 | AE1: 2.761 | AG1: =IF($AC1="",NA(),AC1) -> 45652 | AH1: =IF($AK$1, AN1, NA()) -> 2.797 | AI1: =IF($AL$1, AN1, NA()) -> 2.797 | AJ1: =(AN1-AO1)*100 -> 3.6 | AK1: TRUE | AL1: TRUE | AN1: =IF($AC1="",NA(),AD1) -> 2.797 | AO1: =IF($AC1="",NA(),AE1) -> 2.761
E2: {=IF($E$11, data!$B$11, INDEX($B$3:$B$10, $A$1) )} -> KR1035G00002 | O2: =MATCH(스프레드!$B$4-1, data!$P$3:$P$12, 1) -> 10 | P2: 일자 | Q2: 민평3사 수익률(산출일) 당일 | W2: 5 | X2: =F13 -> (24-9) | Y2: {=INDEX($F$11:$N$11, 0, $X$1)} -> KR103503GE96 | Z2: {=INDEX($X$2:$X$10, $X$1)} -> (24-9) | AA2: 일자 | AB2: 민평3사 수익률(산출일) 당일 | AC2: 45650 | AD2: 2.765 | AE2: 2.73 | AG2: =IF($AC2="",NA(),AC2) -> 45650 | AH2: =IF($AK$1, AN2, NA()) -> 2.765 | AI2: =IF($AL$1, AN2, NA()) -> 2.765 | AJ2: =(AN2-AO2)*100 -> 3.5 | AN2: =IF($AC2="",NA(),AD2) -> 2.765 | AO2: =IF($AC2="",NA(),AE2) -> 2.73
A3: 2Y | B3: KR1035G00002 | C3: BNDSTA1200002 | P3: 45638 | Q3: 2.7 | V3: 3 | W3: 3M | X3: =G13 -> (24-3) | Y3: {=INDEX($F$11:$N$11, 0, $Y$1)} -> KR103503GE39 | Z3: {=INDEX($X$2:$X$10, $Y$1)} -> (24-3) | AC3: 45649 | AD3: 2.735 | AE3: 2.711 | AG3: =IF($AC3="",NA(),AC3) -> 45649 | AH3: =IF($AK$1, AN3, NA()) -> 2.735 | AI3: =IF($AL$1, AN3, NA()) -> 2.735 | AJ3: =(AN3-AO3)*100 -> 2.4 | AN3: =IF($AC3="",NA(),AD3) -> 2.735 | AO3: =IF($AC3="",NA(),AE3) -> 2.711
A4: 3Y | B4: KR1035G00003 | C4: BNDSTA1200003 | P4: 45639 | Q4: 2.675 | V4: 6 | W4: 6M | X4: =H13 -> (23-8) | AC4: 45646 | AD4: 2.73 | AE4: 2.718 | AG4: =IF($AC4="",NA(),AC4) -> 45646 | AH4: =IF($AK$1, AN4, NA()) -> 2.73 | AI4: =IF($AL$1, AN4, NA()) -> 2.73 | AJ4: =(AN4-AO4)*100 -> 1.2 | AN4: =IF($AC4="",NA(),AD4) -> 2.73 | AO4: =IF($AC4="",NA(),AE4) -> 2.718
A5: 5Y | B5: KR1035G00005 | C5: BNDSTA1200005 | P5: 45642 | Q5: 2.712 | V5: 12 | W5: 1Y | X5: =I13 -> (23-3) | Y5: {=_xll.IMDP("BND", $Y$2, "발행일",,"DtFmt=1")} -> 45545 | AC5: 45645 | AD5: 2.7 | AE5: 2.708 | AG5: =IF($AC5="",NA(),AC5) -> 45645 | AH5: =IF($AK$1, AN5, NA()) -> 2.7 | AI5: =IF($AL$1, AN5, NA()) -> 2.7 | AJ5: =(AN5-AO5)*100 -> -0.8 | AN5: =IF($AC5="",NA(),AD5) -> 2.7 | AO5: =IF($AC5="",NA(),AE5) -> 2.708
A6: 10Y | B6: KR1035G00010 | C6: BNDSTA1200010 | P6: 45643 | Q6: 2.79 | V6: 36 | W6: 3Y | X6: =J13 -> (22-15) | Y6: {=_xll.IMDP("BND", $Y$3, "발행일",,"DtFmt=1")} -> 45361 | AC6: 45644 | AD6: 2.638 | AE6: 2.678 | AG6: =IF($AC6="",NA(),AC6) -> 45644 | AH6: =IF($AK$1, AN6, NA()) -> 2.638 | AI6: =IF($AL$1, AN6, NA()) -> 2.638 | AJ6: =(AN6-AO6)*100 -> -4 | AN6: =IF($AC6="",NA(),AD6) -> 2.638 | AO6: =IF($AC6="",NA(),AE6) -> 2.678
A7: 20Y | B7: KR1035G00020 | C7: BNDSTA1200020 | P7: 45644 | Q7: 2.735 | W7: MAX | X7: =K13 -> (22-10) | Y7: {=EDATE( 스프레드!$B$4, -INDEX($V$3:$V$6, $W$2,0))} -> #REF! | AC7: 45643 | AD7: 2.714 | AE7: 2.715 | AG7: =IF($AC7="",NA(),AC7) -> 45643 | AH7: =IF($AK$1, AN7, NA()) -> 2.714 | AI7: =IF($AL$1, AN7, NA()) -> 2.714 | AJ7: =(AN7-AO7)*100 -> -0.1 | AN7: =IF($AC7="",NA(),AD7) -> 2.714 | AO7: =IF($AC7="",NA(),AE7) -> 2.715
A8: 30Y | B8: KR1035G00030 | C8: BNDSTA1200030 | P8: 45645 | Q8: 2.81 | X8: =L13 -> (22-7) | AC8: 45642 | AD8: 2.661 | AE8: 2.693 | AG8: =IF($AC8="",NA(),AC8) -> 45642 | AH8: =IF($AK$1, AN8, NA()) -> 2.661 | AI8: =IF($AL$1, AN8, NA()) -> 2.661 | AJ8: =(AN8-AO8)*100 -> -3.2 | AN8: =IF($AC8="",NA(),AD8) -> 2.661 | AO8: =IF($AC8="",NA(),AE8) -> 2.693
A9: 50Y | B9: KR1035G00050 | C9: BNDSTA1200050 | P9: 45646 | Q9: 2.86 | X9: =M13 -> (22-3) | Y9: =IF($W$2=5, MAX($Y$5:$Y$6), MAX($Y$5:$Y$7)) -> 45545 | AC9: 45639 | AD9: 2.653 | AE9: 2.69 | AG9: =IF($AC9="",NA(),AC9) -> 45639 | AH9: =IF($AK$1, AN9, NA()) -> 2.653 | AI9: =IF($AL$1, AN9, NA()) -> 2.653 | AJ9: =(AN9-AO9)*100 -> -3.7 | AN9: =IF($AC9="",NA(),AD9) -> 2.653 | AO9: =IF($AC9="",NA(),AE9) -> 2.69
A10: 물가 | B10: KR1035M00200 | C10: BNDSTA1200801 | P10: 45649 | Q10: 2.845 | X10: =N13 -> (21-12) | AC10: 45638 | AD10: 2.665 | AE10: 2.7 | AG10: =IF($AC10="",NA(),AC10) -> 45638 | AH10: =IF($AK$1, AN10, NA()) -> 2.665 | AI10: =IF($AL$1, AN10, NA()) -> 2.665 | AJ10: =(AN10-AO10)*100 -> -3.5 | AN10: =IF($AC10="",NA(),AD10) -> 2.665 | AO10: =IF($AC10="",NA(),AE10) -> 2.7
A11: 통안 2Y | B11: KR3101000100 | C11: BNDSTA4200004 | D11: =$A$1=1 -> TRUE | E11: =AND($D$11,스프레드!$B$4<=44265) -> FALSE | F11: =$E$16 -> KR103503GE96 | G11: =$E$17 -> KR103503GE39 | H11: =$E$18 -> KR103503GD97 | I11: =$E$19 -> KR103503GD30 | J11: =$E$20 -> KR103503GCC6 | K11: =$E$21 -> KR103503GC98 | L11: =$E$22 -> KR103504GC63 | M11: =$E$23 -> KR103503GC31 | N11: =$E$24 -> KR103503GBC8 | P11: 45650 | Q11: 2.884 | AC11: 45637 | AD11: 2.658 | AE11: 2.701 | AG11: =IF($AC11="",NA(),AC11) -> 45637 | AH11: =IF($AK$1, AN11, NA()) -> 2.658 | AI11: =IF($AL$1, AN11, NA()) -> 2.658 | AJ11: =(AN11-AO11)*100 -> -4.3 | AN11: =IF($AC11="",NA(),AD11) -> 2.658 | AO11: =IF($AC11="",NA(),AE11) -> 2.701
F12: {=_xll.IMDP("BND", F$11, "한글종목명")} -> 국고02875-2609(24-9) | G12: {=_xll.IMDP("BND", G$11, "한글종목명")} -> 국고03250-2603(24-3) | H12: {=_xll.IMDP("BND", H$11, "한글종목명")} -> 국고03625-2509(23-8) | I12: {=_xll.IMDP("BND", I$11, "한글종목명")} -> 국고03375-2503(23-3) | J12: {=_xll.IMDP("BND", J$11, "한글종목명")} -> 국고04250-2412(22-15) | K12: {=_xll.IMDP("BND", K$11, "한글종목명")} -> 국고03125-2409(22-10) | L12: {=_xll.IMDP("BND", L$11, "한글종목명")} -> 국고02875-2406(22-7) | M12: {=_xll.IMDP("BND", M$11, "한글종목명")} -> 국고02125-2403(22-3) | N12: {=_xll.IMDP("BND", N$11, "한글종목명")} -> 국고01750-2312(21-12) | P12: 45652 | Q12: 2.914 | AC12: 45636 | AD12: 2.636 | AE12: 2.697 | AG12: =IF($AC12="",NA(),AC12) -> 45636 | AH12: =IF($AK$1, AN12, NA()) -> 2.636 | AI12: =IF($AL$1, AN12, NA()) -> 2.636 | AJ12: =(AN12-AO12)*100 -> -6.1 | AN12: =IF($AC12="",NA(),AD12) -> 2.636 | AO12: =IF($AC12="",NA(),AE12) -> 2.697
A13: {=IF($E$11, data!$C$11, INDEX($C$3:$C$10, $A$1) )} -> BNDSTA1200002 | F13: =IFERROR( RIGHT(F$12, LEN(F$12)-FIND("(", F$12)+1), MID(F$12, 9, 4) ) -> (24-9) | G13: =IFERROR( RIGHT(G$12, LEN(G$12)-FIND("(", G$12)+1), MID(G$12, 9, 4) ) -> (24-3) | H13: =IFERROR( RIGHT(H$12, LEN(H$12)-FIND("(", H$12)+1), MID(H$12, 9, 4) ) -> (23-8) | I13: =IFERROR( RIGHT(I$12, LEN(I$12)-FIND("(", I$12)+1), MID(I$12, 9, 4) ) -> (23-3) | J13: =IFERROR( RIGHT(J$12, LEN(J$12)-FIND("(", J$12)+1), MID(J$12, 9, 4) ) -> (22-15) | K13: =IFERROR( RIGHT(K$12, LEN(K$12)-FIND("(", K$12)+1), MID(K$12, 9, 4) ) -> (22-10) | L13: =IFERROR( RIGHT(L$12, LEN(L$12)-FIND("(", L$12)+1), MID(L$12, 9, 4) ) -> (22-7) | M13: =IFERROR( RIGHT(M$12, LEN(M$12)-FIND("(", M$12)+1), MID(M$12, 9, 4) ) -> (22-3) | N13: =IFERROR( RIGHT(N$12, LEN(N$12)-FIND("(", N$12)+1), MID(N$12, 9, 4) ) -> (21-12) | AC13: 45635 | AD13: 2.628 | AE13: 2.69 | AG13: =IF($AC13="",NA(),AC13) -> 45635 | AH13: =IF($AK$1, AN13, NA()) -> 2.628 | AI13: =IF($AL$1, AN13, NA()) -> 2.628 | AJ13: =(AN13-AO13)*100 -> -6.2 | AN13: =IF($AC13="",NA(),AD13) -> 2.628 | AO13: =IF($AC13="",NA(),AE13) -> 2.69
A14: {=_xll.IMDT("채권발행", $A$13, $A$15:$D$15, 9, $C$14, "발행일", "발행일", "sort=D, 만기일=FALSE, DtFmt=1, TmFmt=1, Pos=20, Orient=V")} -> 조회[BNDSTA1200002] | C14: ="1980-01-01~"&TEXT(스프레드!$B$4, "YYYY-MM-DD") -> 1980-01-01~2024-12-27 | H14: TRUE | J14: TRUE | AC14: 45632 | AD14: 2.67 | AE14: 2.711 | AG14: =IF($AC14="",NA(),AC14) -> 45632 | AH14: =IF($AK$1, AN14, NA()) -> 2.67 | AI14: =IF($AL$1, AN14, NA()) -> 2.67 | AJ14: =(AN14-AO14)*100 -> -4.1 | AN14: =IF($AC14="",NA(),AD14) -> 2.67 | AO14: =IF($AC14="",NA(),AE14) -> 2.711
A15: 표준코드 | B15: 종목명 | C15: 발행일 | D15: 만기일 | F15: 민평3사 수익률(산출일) | G15: 장내국채-시간 | H15: 장내국채-현재수익률 | I15: 장외-시간 | J15: 장외-현재수익률 | L15: D-0 | N15: D-1 | O15: =F13 -> (24-9) | P15: =G13 -> (24-3) | Q15: =H13 -> (23-8) | R15: =I13 -> (23-3) | S15: =J13 -> (22-15) | T15: =K13 -> (22-10) | U15: =L13 -> (22-7) | V15: =M13 -> (22-3) | W15: =N13 -> (21-12) | AC15: 45631 | AD15: 2.65 | AE15: 2.695 | AG15: =IF($AC15="",NA(),AC15) -> 45631 | AH15: =IF($AK$1, AN15, NA()) -> 2.65 | AI15: =IF($AL$1, AN15, NA()) -> 2.65 | AJ15: =(AN15-AO15)*100 -> -4.5 | AN15: =IF($AC15="",NA(),AD15) -> 2.65 | AO15: =IF($AC15="",NA(),AE15) -> 2.695
A16: KR103503GE96 | B16: 국고02875-2609(24-9) | C16: 45545 | D16: 46275 | E16: =IF( AND($D$11, $E$11=FALSE, $C16<44265), $A30, IF($A16="", "", $A16)) -> KR103503GE96 | F16: {=IF($E16="", "", _xll.IMDP("BND", $E16, IF($E$1, F$15, $Q$2), 스프레드!$B$4, "TmFmt=1"))} -> 2.797 | G16: {=IF($H$14, _xll.IMDP("BND", $E16, G$15, 스프레드!$B$4, "TmFmt=1"), "")} -> 0.38002315 | H16: {=IF($H$14, _xll.IMDP("BND", $E16, H$15, 스프레드!$B$4, "TmFmt=1"), "")} -> 2.793 | I16: {=IF($J$14, _xll.IMDP("BND", $E16, I$15, 스프레드!$B$4, "TmFmt=1"), "")} | J16: {=IF($J$14, _xll.IMDP("BND", $E16, J$15, 스프레드!$B$4, "TmFmt=1"), "")} | L16: {=IF($E16="","", IF( OR($E$1=FALSE, AND($H16="", $J16="")), $F16, INDEX($G16:$J16, 0, MATCH(MAX($G16,$I16),$G16:$J16,0)+1) ) )} -> 2.793 | N16: {=IF($E16="", "", _xll.IMDP("BND", $E16, $Q$2, $O$1, "TmFmt=1") )} -> 2.797 | P16: =( $N16 - OFFSET($N16, MATCH(P$15, $P$15:$W$15, 0), 0) ) * 100 -> 3.6 | Q16: =( $N16 - OFFSET($N16, MATCH(Q$15, $P$15:$W$15, 0), 0) ) * 100 -> 8.4 | R16: =( $N16 - OFFSET($N16, MATCH(R$15, $P$15:$W$15, 0), 0) ) * 100 -> -6.6 | S16: =( $N16 - OFFSET($N16, MATCH(S$15, $P$15:$W$15, 0), 0) ) * 100 -> #VALUE! | T16: =( $N16 - OFFSET($N16, MATCH(T$15, $P$15:$W$15, 0), 0) ) * 100 -> #VALUE! | U16: =( $N16 - OFFSET($N16, MATCH(U$15, $P$15:$W$15, 0), 0) ) * 100 -> #VALUE! | V16: =( $N16 - OFFSET($N16, MATCH(V$15, $P$15:$W$15, 0), 0) ) * 100 -> #VALUE! | W16: =( $N16 - OFFSET($N16, MATCH(W$15, $P$15:$W$15, 0), 0) ) * 100 -> #VALUE! | AC16: 45630 | AD16: 2.678 | AE16: 2.708 | AG16: =IF($AC16="",NA(),AC16) -> 45630 | AH16: =IF($AK$1, AN16, NA()) -> 2.678 | AI16: =IF($AL$1, AN16, NA()) -> 2.678 | AJ16: =(AN16-AO16)*100 -> -3 | AN16: =IF($AC16="",NA(),AD16) -> 2.678 | AO16: =IF($AC16="",NA(),AE16) -> 2.708
A17: KR103503GE39 | B17: 국고03250-2603(24-3) | C17: 45361 | D17: 46091 | E17: =IF( AND($D$11, $E$11=FALSE, $C17<44265), $A31, IF($A17="", "", $A17)) -> KR103503GE39 | F17: {=IF($E17="", "", _xll.IMDP("BND", $E17, IF($E$1, F$15, $Q$2), 스프레드!$B$4, "TmFmt=1"))} -> 2.761 | G17: {=IF($H$14, _xll.IMDP("BND", $E17, G$15, 스프레드!$B$4, "TmFmt=1"), "")} | H17: {=IF($H$14, _xll.IMDP("BND", $E17, H$15, 스프레드!$B$4, "TmFmt=1"), "")} | I17: {=IF($J$14, _xll.IMDP("BND", $E17, I$15, 스프레드!$B$4, "TmFmt=1"), "")} | J17: {=IF($J$14, _xll.IMDP("BND", $E17, J$15, 스프레드!$B$4, "TmFmt=1"), "")} | L17: {=IF($E17="","", IF( OR($E$1=FALSE, AND($H17="", $J17="")), $F17, INDEX($G17:$J17, 0, MATCH(MAX($G17,$I17),$G17:$J17,0)+1) ) )} -> 2.761 | N17: {=IF($E17="", "", _xll.IMDP("BND", $E17, $Q$2, $O$1, "TmFmt=1") )} -> 2.761 | Q17: =( $N17 - OFFSET($N17, MATCH(Q$15, $Q$15:$W$15, 0), 0) ) * 100 -> 4.8 | R17: =( $N17 - OFFSET($N17, MATCH(R$15, $Q$15:$W$15, 0), 0) ) * 100 -> -10.2 | S17: =( $N17 - OFFSET($N17, MATCH(S$15, $Q$15:$W$15, 0), 0) ) * 100 -> #VALUE! | T17: =( $N17 - OFFSET($N17, MATCH(T$15, $Q$15:$W$15, 0), 0) ) * 100 -> #VALUE! | U17: =( $N17 - OFFSET($N17, MATCH(U$15, $Q$15:$W$15, 0), 0) ) * 100 -> #VALUE! | V17: =( $N17 - OFFSET($N17, MATCH(V$15, $Q$15:$W$15, 0), 0) ) * 100 -> #VALUE! | W17: =( $N17 - OFFSET($N17, MATCH(W$15, $Q$15:$W$15, 0), 0) ) * 100 -> #VALUE! | AC17: 45629 | AD17: 2.64 | AE17: 2.706 | AG17: =IF($AC17="",NA(),AC17) -> 45629 | AH17: =IF($AK$1, AN17, NA()) -> 2.64 | AI17: =IF($AL$1, AN17, NA()) -> 2.64 | AJ17: =(AN17-AO17)*100 -> -6.6 | AN17: =IF($AC17="",NA(),AD17) -> 2.64 | AO17: =IF($AC17="",NA(),AE17) -> 2.706
A18: KR103503GD97 | B18: 국고03625-2509(23-8) | C18: 45179 | D18: 45910 | E18: =IF( AND($D$11, $E$11=FALSE, $C18<44265), $A32, IF($A18="", "", $A18)) -> KR103503GD97 | F18: {=IF($E18="", "", _xll.IMDP("BND", $E18, IF($E$1, F$15, $Q$2), 스프레드!$B$4, "TmFmt=1"))} -> 2.713 | G18: {=IF($H$14, _xll.IMDP("BND", $E18, G$15, 스프레드!$B$4, "TmFmt=1"), "")} | H18: {=IF($H$14, _xll.IMDP("BND", $E18, H$15, 스프레드!$B$4, "TmFmt=1"), "")} | I18: {=IF($J$14, _xll.IMDP("BND", $E18, I$15, 스프레드!$B$4, "TmFmt=1"), "")} | J18: {=IF($J$14, _xll.IMDP("BND", $E18, J$15, 스프레드!$B$4, "TmFmt=1"), "")} | L18: {=IF($E18="","", IF( OR($E$1=FALSE, AND($H18="", $J18="")), $F18, INDEX($G18:$J18, 0, MATCH(MAX($G18,$I18),$G18:$J18,0)+1) ) )} -> 2.713 | N18: {=IF($E18="", "", _xll.IMDP("BND", $E18, $Q$2, $O$1, "TmFmt=1") )} -> 2.713 | R18: =( $N18 - OFFSET($N18, MATCH(R$15, $R$15:$W$15, 0), 0) ) * 100 -> -15 | S18: =( $N18 - OFFSET($N18, MATCH(S$15, $R$15:$W$15, 0), 0) ) * 100 -> #VALUE! | T18: =( $N18 - OFFSET($N18, MATCH(T$15, $R$15:$W$15, 0), 0) ) * 100 -> #VALUE! | U18: =( $N18 - OFFSET($N18, MATCH(U$15, $R$15:$W$15, 0), 0) ) * 100 -> #VALUE! | V18: =( $N18 - OFFSET($N18, MATCH(V$15, $R$15:$W$15, 0), 0) ) * 100 -> #VALUE! | W18: =( $N18 - OFFSET($N18, MATCH(W$15, $R$15:$W$15, 0), 0) ) * 100 -> #VALUE! | AC18: 45628 | AD18: 2.623 | AE18: 2.707 | AG18: =IF($AC18="",NA(),AC18) -> 45628 | AH18: =IF($AK$1, AN18, NA()) -> 2.623 | AI18: =IF($AL$1, AN18, NA()) -> 2.623 | AJ18: =(AN18-AO18)*100 -> -8.4 | AN18: =IF($AC18="",NA(),AD18) -> 2.623 | AO18: =IF($AC18="",NA(),AE18) -> 2.707
A19: KR103503GD30 | B19: 국고03375-2503(23-3) | C19: 44995 | D19: 45726 | E19: =IF( AND($D$11, $E$11=FALSE, $C19<44265), $A33, IF($A19="", "", $A19)) -> KR103503GD30 | F19: {=IF($E19="", "", _xll.IMDP("BND", $E19, IF($E$1, F$15, $Q$2), 스프레드!$B$4, "TmFmt=1"))} -> 2.863 | G19: {=IF($H$14, _xll.IMDP("BND", $E19, G$15, 스프레드!$B$4, "TmFmt=1"), "")} | H19: {=IF($H$14, _xll.IMDP("BND", $E19, H$15, 스프레드!$B$4, "TmFmt=1"), "")} | I19: {=IF($J$14, _xll.IMDP("BND", $E19, I$15, 스프레드!$B$4, "TmFmt=1"), "")} | J19: {=IF($J$14, _xll.IMDP("BND", $E19, J$15, 스프레드!$B$4, "TmFmt=1"), "")} | L19: {=IF($E19="","", IF( OR($E$1=FALSE, AND($H19="", $J19="")), $F19, INDEX($G19:$J19, 0, MATCH(MAX($G19,$I19),$G19:$J19,0)+1) ) )} -> 2.863 | N19: {=IF($E19="", "", _xll.IMDP("BND", $E19, $Q$2, $O$1, "TmFmt=1") )} -> 2.863 | S19: =( $N19 - OFFSET($N19, MATCH(S$15, $S$15:$W$15, 0), 0) ) * 100 -> #VALUE! | T19: =( $N19 - OFFSET($N19, MATCH(T$15, $S$15:$W$15, 0), 0) ) * 100 -> #VALUE! | U19: =( $N19 - OFFSET($N19, MATCH(U$15, $S$15:$W$15, 0), 0) ) * 100 -> #VALUE! | V19: =( $N19 - OFFSET($N19, MATCH(V$15, $S$15:$W$15, 0), 0) ) * 100 -> #VALUE! | W19: =( $N19 - OFFSET($N19, MATCH(W$15, $S$15:$W$15, 0), 0) ) * 100 -> #VALUE! | AC19: 45625 | AD19: 2.669 | AE19: 2.733 | AG19: =IF($AC19="",NA(),AC19) -> 45625 | AH19: =IF($AK$1, AN19, NA()) -> 2.669 | AI19: =IF($AL$1, AN19, NA()) -> 2.669 | AJ19: =(AN19-AO19)*100 -> -6.4 | AN19: =IF($AC19="",NA(),AD19) -> 2.669 | AO19: =IF($AC19="",NA(),AE19) -> 2.733
A20: KR103503GCC6 | B20: 국고04250-2412(22-15) | C20: 44905 | D20: 45636 | E20: =IF( AND($D$11, $E$11=FALSE, $C20<44265), $A34, IF($A20="", "", $A20)) -> KR103503GCC6 | F20: {=IF($E20="", "", _xll.IMDP("BND", $E20, IF($E$1, F$15, $Q$2), 스프레드!$B$4, "TmFmt=1"))} -> 2.883 | G20: {=IF($H$14, _xll.IMDP("BND", $E20, G$15, 스프레드!$B$4, "TmFmt=1"), "")} | H20: {=IF($H$14, _xll.IMDP("BND", $E20, H$15, 스프레드!$B$4, "TmFmt=1"), "")} | I20: {=IF($J$14, _xll.IMDP("BND", $E20, I$15, 스프레드!$B$4, "TmFmt=1"), "")} | J20: {=IF($J$14, _xll.IMDP("BND", $E20, J$15, 스프레드!$B$4, "TmFmt=1"), "")} | L20: {=IF($E20="","", IF( OR($E$1=FALSE, AND($H20="", $J20="")), $F20, INDEX($G20:$J20, 0, MATCH(MAX($G20,$I20),$G20:$J20,0)+1) ) )} -> 2.883 | N20: {=IF($E20="", "", _xll.IMDP("BND", $E20, $Q$2, $O$1, "TmFmt=1") )} | T20: =( $N20 - OFFSET($N20, MATCH(T$15, $T$15:$W$15, 0), 0) ) * 100 -> #VALUE! | U20: =( $N20 - OFFSET($N20, MATCH(U$15, $T$15:$W$15, 0), 0) ) * 100 -> #VALUE! | V20: =( $N20 - OFFSET($N20, MATCH(V$15, $T$15:$W$15, 0), 0) ) * 100 -> #VALUE! | W20: =( $N20 - OFFSET($N20, MATCH(W$15, $T$15:$W$15, 0), 0) ) * 100 -> #VALUE! | AC20: 45624 | AD20: 2.696 | AE20: 2.761 | AG20: =IF($AC20="",NA(),AC20) -> 45624 | AH20: =IF($AK$1, AN20, NA()) -> 2.696 | AI20: =IF($AL$1, AN20, NA()) -> 2.696 | AJ20: =(AN20-AO20)*100 -> -6.5 | AN20: =IF($AC20="",NA(),AD20) -> 2.696 | AO20: =IF($AC20="",NA(),AE20) -> 2.761
A21: KR103503GC98 | B21: 국고03125-2409(22-10) | C21: 44814 | D21: 45545 | E21: =IF( AND($D$11, $E$11=FALSE, $C21<44265), $A35, IF($A21="", "", $A21)) -> KR103503GC98 | F21: {=IF($E21="", "", _xll.IMDP("BND", $E21, IF($E$1, F$15, $Q$2), 스프레드!$B$4, "TmFmt=1"))} -> 3.193 | G21: {=IF($H$14, _xll.IMDP("BND", $E21, G$15, 스프레드!$B$4, "TmFmt=1"), "")} | H21: {=IF($H$14, _xll.IMDP("BND", $E21, H$15, 스프레드!$B$4, "TmFmt=1"), "")} | I21: {=IF($J$14, _xll.IMDP("BND", $E21, I$15, 스프레드!$B$4, "TmFmt=1"), "")} | J21: {=IF($J$14, _xll.IMDP("BND", $E21, J$15, 스프레드!$B$4, "TmFmt=1"), "")} | L21: {=IF($E21="","", IF( OR($E$1=FALSE, AND($H21="", $J21="")), $F21, INDEX($G21:$J21, 0, MATCH(MAX($G21,$I21),$G21:$J21,0)+1) ) )} -> 3.193 | N21: {=IF($E21="", "", _xll.IMDP("BND", $E21, $Q$2, $O$1, "TmFmt=1") )} | U21: =( $N21 - OFFSET($N21, MATCH(U$15, $U$15:$W$15, 0), 0) ) * 100 -> #VALUE! | V21: =( $N21 - OFFSET($N21, MATCH(V$15, $U$15:$W$15, 0), 0) ) * 100 -> #VALUE! | W21: =( $N21 - OFFSET($N21, MATCH(W$15, $U$15:$W$15, 0), 0) ) * 100 -> #VALUE! | AC21: 45623 | AD21: 2.8 | AE21: 2.82 | AG21: =IF($AC21="",NA(),AC21) -> 45623 | AH21: =IF($AK$1, AN21, NA()) -> 2.8 | AI21: =IF($AL$1, AN21, NA()) -> 2.8 | AJ21: =(AN21-AO21)*100 -> -2 | AN21: =IF($AC21="",NA(),AD21) -> 2.8 | AO21: =IF($AC21="",NA(),AE21) -> 2.82
A22: KR103504GC63 | B22: 국고02875-2406(22-7) | C22: 44722 | D22: 45453 | E22: =IF( AND($D$11, $E$11=FALSE, $C22<44265), $A36, IF($A22="", "", $A22)) -> KR103504GC63 | F22: {=IF($E22="", "", _xll.IMDP("BND", $E22, IF($E$1, F$15, $Q$2), 스프레드!$B$4, "TmFmt=1"))} -> 3.375 | G22: {=IF($H$14, _xll.IMDP("BND", $E22, G$15, 스프레드!$B$4, "TmFmt=1"), "")} | H22: {=IF($H$14, _xll.IMDP("BND", $E22, H$15, 스프레드!$B$4, "TmFmt=1"), "")} | I22: {=IF($J$14, _xll.IMDP("BND", $E22, I$15, 스프레드!$B$4, "TmFmt=1"), "")} | J22: {=IF($J$14, _xll.IMDP("BND", $E22, J$15, 스프레드!$B$4, "TmFmt=1"), "")} | L22: {=IF($E22="","", IF( OR($E$1=FALSE, AND($H22="", $J22="")), $F22, INDEX($G22:$J22, 0, MATCH(MAX($G22,$I22),$G22:$J22,0)+1) ) )} -> 3.375 | N22: {=IF($E22="", "", _xll.IMDP("BND", $E22, $Q$2, $O$1, "TmFmt=1") )} | V22: =( $N22 - OFFSET($N22, MATCH(V$15, $V$15:$W$15, 0), 0) ) * 100 -> #VALUE! | W22: =( $N22 - OFFSET($N22, MATCH(W$15, $V$15:$W$15, 0), 0) ) * 100 -> #VALUE! | AC22: 45622 | AD22: 2.824 | AE22: 2.835 | AG22: =IF($AC22="",NA(),AC22) -> 45622 | AH22: =IF($AK$1, AN22, NA()) -> 2.824 | AI22: =IF($AL$1, AN22, NA()) -> 2.824 | AJ22: =(AN22-AO22)*100 -> -1.1 | AN22: =IF($AC22="",NA(),AD22) -> 2.824 | AO22: =IF($AC22="",NA(),AE22) -> 2.835
A23: KR103503GC31 | B23: 국고02125-2403(22-3) | C23: 44630 | D23: 45361 | E23: =IF( AND($D$11, $E$11=FALSE, $C23<44265), $A37, IF($A23="", "", $A23)) -> KR103503GC31 | F23: {=IF($E23="", "", _xll.IMDP("BND", $E23, IF($E$1, F$15, $Q$2), 스프레드!$B$4, "TmFmt=1"))} -> 3.453 | G23: {=IF($H$14, _xll.IMDP("BND", $E23, G$15, 스프레드!$B$4, "TmFmt=1"), "")} | H23: {=IF($H$14, _xll.IMDP("BND", $E23, H$15, 스프레드!$B$4, "TmFmt=1"), "")} | I23: {=IF($J$14, _xll.IMDP("BND", $E23, I$15, 스프레드!$B$4, "TmFmt=1"), "")} | J23: {=IF($J$14, _xll.IMDP("BND", $E23, J$15, 스프레드!$B$4, "TmFmt=1"), "")} | L23: {=IF($E23="","", IF( OR($E$1=FALSE, AND($H23="", $J23="")), $F23, INDEX($G23:$J23, 0, MATCH(MAX($G23,$I23),$G23:$J23,0)+1) ) )} -> 3.453 | N23: {=IF($E23="", "", _xll.IMDP("BND", $E23, $Q$2, $O$1, "TmFmt=1") )} | W23: =( $N23 - OFFSET($N23, MATCH(W$15, $W$15:$W$15, 0), 0) ) * 100 -> #VALUE! | AC23: 45621 | AD23: 2.83 | AE23: 2.838 | AG23: =IF($AC23="",NA(),AC23) -> 45621 | AH23: =IF($AK$1, AN23, NA()) -> 2.83 | AI23: =IF($AL$1, AN23, NA()) -> 2.83 | AJ23: =(AN23-AO23)*100 -> -0.8 | AN23: =IF($AC23="",NA(),AD23) -> 2.83 | AO23: =IF($AC23="",NA(),AE23) -> 2.838
A24: KR103503GBC8 | B24: 국고01750-2312(21-12) | C24: 44540 | D24: 45270 | E24: =IF( AND($D$11, $E$11=FALSE, $C24<44265), $A38, IF($A24="", "", $A24)) -> KR103503GBC8 | F24: {=IF($E24="", "", _xll.IMDP("BND", $E24, IF($E$1, F$15, $Q$2), 스프레드!$B$4, "TmFmt=1"))} -> 3.303 | G24: {=IF($H$14, _xll.IMDP("BND", $E24, G$15, 스프레드!$B$4, "TmFmt=1"), "")} | H24: {=IF($H$14, _xll.IMDP("BND", $E24, H$15, 스프레드!$B$4, "TmFmt=1"), "")} | I24: {=IF($J$14, _xll.IMDP("BND", $E24, I$15, 스프레드!$B$4, "TmFmt=1"), "")} | J24: {=IF($J$14, _xll.IMDP("BND", $E24, J$15, 스프레드!$B$4, "TmFmt=1"), "")} | L24: {=IF($E24="","", IF( OR($E$1=FALSE, AND($H24="", $J24="")), $F24, INDEX($G24:$J24, 0, MATCH(MAX($G24,$I24),$G24:$J24,0)+1) ) )} -> 3.303 | N24: {=IF($E24="", "", _xll.IMDP("BND", $E24, $Q$2, $O$1, "TmFmt=1") )} | AC24: 45618 | AD24: 2.87 | AE24: 2.863 | AG24: =IF($AC24="",NA(),AC24) -> 45618 | AH24: =IF($AK$1, AN24, NA()) -> 2.87 | AI24: =IF($AL$1, AN24, NA()) -> 2.87 | AJ24: =(AN24-AO24)*100 -> 0.7 | AN24: =IF($AC24="",NA(),AD24) -> 2.87 | AO24: =IF($AC24="",NA(),AE24) -> 2.863
AC25: 45617 | AD25: 2.893 | AE25: 2.865 | AG25: =IF($AC25="",NA(),AC25) -> 45617 | AH25: =IF($AK$1, AN25, NA()) -> 2.893 | AI25: =IF($AL$1, AN25, NA()) -> 2.893 | AJ25: =(AN25-AO25)*100 -> 2.8 | AN25: =IF($AC25="",NA(),AD25) -> 2.893 | AO25: =IF($AC25="",NA(),AE25) -> 2.865
A26: 통안 | AC26: 45616 | AD26: 2.929 | AE26: 2.89 | AG26: =IF($AC26="",NA(),AC26) -> 45616 | AH26: =IF($AK$1, AN26, NA()) -> 2.929 | AI26: =IF($AL$1, AN26, NA()) -> 2.929 | AJ26: =(AN26-AO26)*100 -> 3.9 | AN26: =IF($AC26="",NA(),AD26) -> 2.929 | AO26: =IF($AC26="",NA(),AE26) -> 2.89
A27: BNDSTA4200004 | AC27: 45615 | AD27: 2.938 | AE27: 2.896 | AG27: =IF($AC27="",NA(),AC27) -> 45615 | AH27: =IF($AK$1, AN27, NA()) -> 2.938 | AI27: =IF($AL$1, AN27, NA()) -> 2.938 | AJ27: =(AN27-AO27)*100 -> 4.2 | AN27: =IF($AC27="",NA(),AD27) -> 2.938 | AO27: =IF($AC27="",NA(),AE27) -> 2.896
A28: {=_xll.IMDT("채권발행", $A$27, $A$15:$D$15, 9, $C$14, "발행일", "발행일", "sort=D, 만기일=FALSE, DtFmt=1, TmFmt=1, Pos=20, Orient=V")} -> 조회[BNDSTA4200004] | C28: ="1980-01-01~"&TEXT(스프레드!$B$4, "YYYY-MM-DD") -> 1980-01-01~2024-12-27 | AC28: 45614 | AD28: 2.962 | AE28: 2.908 | AG28: =IF($AC28="",NA(),AC28) -> 45614 | AH28: =IF($AK$1, AN28, NA()) -> 2.962 | AI28: =IF($AL$1, AN28, NA()) -> 2.962 | AJ28: =(AN28-AO28)*100 -> 5.4 | AN28: =IF($AC28="",NA(),AD28) -> 2.962 | AO28: =IF($AC28="",NA(),AE28) -> 2.908
A29: 표준코드 | B29: 종목명 | C29: 발행일 | D29: 만기일 | AC29: 45611 | AD29: 2.975 | AE29: 2.921 | AG29: =IF($AC29="",NA(),AC29) -> 45611 | AH29: =IF($AK$1, AN29, NA()) -> 2.975 | AI29: =IF($AL$1, AN29, NA()) -> 2.975 | AJ29: =(AN29-AO29)*100 -> 5.4 | AN29: =IF($AC29="",NA(),AD29) -> 2.975 | AO29: =IF($AC29="",NA(),AE29) -> 2.921
A30: KR310101GEA8 | B30: 통안02800-2610-02 | C30: 45567 | D30: 46297 | AC30: 45610 | AD30: 2.955 | AE30: 2.91 | AG30: =IF($AC30="",NA(),AC30) -> 45610 | AH30: =IF($AK$1, AN30, NA()) -> 2.955 | AI30: =IF($AL$1, AN30, NA()) -> 2.955 | AJ30: =(AN30-AO30)*100 -> 4.5 | AN30: =IF($AC30="",NA(),AD30) -> 2.955 | AO30: =IF($AC30="",NA(),AE30) -> 2.91
A31: KR310101GE77 | B31: 통안03200-2607-02 | C31: 45475 | D31: 46205 | AC31: 45609 | AD31: 2.98 | AE31: 2.93 | AG31: =IF($AC31="",NA(),AC31) -> 45609 | AH31: =IF($AK$1, AN31, NA()) -> 2.98 | AI31: =IF($AL$1, AN31, NA()) -> 2.98 | AJ31: =(AN31-AO31)*100 -> 5 | AN31: =IF($AC31="",NA(),AD31) -> 2.98 | AO31: =IF($AC31="",NA(),AE31) -> 2.93
A32: KR310101GE44 | B32: 통안03365-2604-02 | C32: 45384 | D32: 46114 | AC32: 45608 | AD32: 2.937 | AE32: 2.91 | AG32: =IF($AC32="",NA(),AC32) -> 45608 | AH32: =IF($AK$1, AN32, NA()) -> 2.937 | AI32: =IF($AL$1, AN32, NA()) -> 2.937 | AJ32: =(AN32-AO32)*100 -> 2.7 | AN32: =IF($AC32="",NA(),AD32) -> 2.937 | AO32: =IF($AC32="",NA(),AE32) -> 2.91
A33: KR310101GE10 | B33: 통안03340-2601-02 | C33: 45293 | D33: 46024 | AC33: 45607 | AD33: 2.93 | AE33: 2.906 | AG33: =IF($AC33="",NA(),AC33) -> 45607 | AH33: =IF($AK$1, AN33, NA()) -> 2.93 | AI33: =IF($AL$1, AN33, NA()) -> 2.93 | AJ33: =(AN33-AO33)*100 -> 2.4 | AN33: =IF($AC33="",NA(),AD33) -> 2.93 | AO33: =IF($AC33="",NA(),AE33) -> 2.906
A34: KR310101GDA0 | B34: 통안04020-2510-02 | C34: 45201 | D34: 45932 | AC34: 45604 | AD34: 2.915 | AE34: 2.901 | AG34: =IF($AC34="",NA(),AC34) -> 45604 | AH34: =IF($AK$1, AN34, NA()) -> 2.915 | AI34: =IF($AL$1, AN34, NA()) -> 2.915 | AJ34: =(AN34-AO34)*100 -> 1.4 | AN34: =IF($AC34="",NA(),AD34) -> 2.915 | AO34: =IF($AC34="",NA(),AE34) -> 2.901
A35: KR310101GD78 | B35: 통안03670-2507-02 | C35: 45109 | D35: 45840 | AC35: 45603 | AD35: 2.949 | AE35: 2.928 | AG35: =IF($AC35="",NA(),AC35) -> 45603 | AH35: =IF($AK$1, AN35, NA()) -> 2.949 | AI35: =IF($AL$1, AN35, NA()) -> 2.949 | AJ35: =(AN35-AO35)*100 -> 2.1 | AN35: =IF($AC35="",NA(),AD35) -> 2.949 | AO35: =IF($AC35="",NA(),AE35) -> 2.928
A36: KR310101GD45 | B36: 통안03280-2504-02 | C36: 45018 | D36: 45749 | AC36: 45602 | AD36: 2.975 | AE36: 2.955 | AG36: =IF($AC36="",NA(),AC36) -> 45602 | AH36: =IF($AK$1, AN36, NA()) -> 2.975 | AI36: =IF($AL$1, AN36, NA()) -> 2.975 | AJ36: =(AN36-AO36)*100 -> 2 | AN36: =IF($AC36="",NA(),AD36) -> 2.975 | AO36: =IF($AC36="",NA(),AE36) -> 2.955
A37: KR310101GD11 | B37: 통안03680-2501-02 | C37: 44928 | D37: 45659 | AC37: 45601 | AD37: 2.937 | AE37: 2.936 | AG37: =IF($AC37="",NA(),AC37) -> 45601 | AH37: =IF($AK$1, AN37, NA()) -> 2.937 | AI37: =IF($AL$1, AN37, NA()) -> 2.937 | AJ37: =(AN37-AO37)*100 -> 0.1 | AN37: =IF($AC37="",NA(),AD37) -> 2.937 | AO37: =IF($AC37="",NA(),AE37) -> 2.936
A38: KR310101GCA2 | B38: 통안04120-2410-02 | C38: 44836 | D38: 45567 | AC38: 45600 | AD38: 2.952 | AE38: 2.948 | AG38: =IF($AC38="",NA(),AC38) -> 45600 | AH38: =IF($AK$1, AN38, NA()) -> 2.952 | AI38: =IF($AL$1, AN38, NA()) -> 2.952 | AJ38: =(AN38-AO38)*100 -> 0.4 | AN38: =IF($AC38="",NA(),AD38) -> 2.952 | AO38: =IF($AC38="",NA(),AE38) -> 2.948
AC39: 45597 | AD39: 2.96 | AE39: 2.96 | AG39: =IF($AC39="",NA(),AC39) -> 45597 | AH39: =IF($AK$1, AN39, NA()) -> 2.96 | AI39: =IF($AL$1, AN39, NA()) -> 2.96 | AJ39: =(AN39-AO39)*100 -> 0 | AN39: =IF($AC39="",NA(),AD39) -> 2.96 | AO39: =IF($AC39="",NA(),AE39) -> 2.96
AC40: 45596 | AD40: 2.971 | AE40: 2.964 | AG40: =IF($AC40="",NA(),AC40) -> 45596 | AH40: =IF($AK$1, AN40, NA()) -> 2.971 | AI40: =IF($AL$1, AN40, NA()) -> 2.971 | AJ40: =(AN40-AO40)*100 -> 0.7 | AN40: =IF($AC40="",NA(),AD40) -> 2.971 | AO40: =IF($AC40="",NA(),AE40) -> 2.964
...
