Workbook

Sheet 시가평가Matrix
B2: 시가평가 Matrix
D3: 1 | E3: 3월이하(국고대비) | F3: 6월이하(국고대비) | G3: 9월이하(국고대비) | H3: 1년이하(국고대비) | I3: 1.5년이하(국고대비) | J3: 2년이하(국고대비) | K3: 2.5년이하(국고대비) | L3: 3년이하(국고대비) | M3: 4년이하(국고대비) | N3: 5년이하(국고대비) | O3: 7년이하(국고대비) | P3: 10년이하(국고대비) | Q3: 15년이하(국고대비) | R3: 20년이하(국고대비) | S3: 30년이하(국고대비) | T3: 50년이하(국고대비) | AA3: 1 | AB3: 3사평균 | AC3: 수익률
D4: 1 | E4: 3월이하(전일대비) | F4: 6월이하(전일대비) | G4: 9월이하(전일대비) | H4: 1년이하(전일대비) | I4: 1.5년이하(전일대비) | J4: 2년이하(전일대비) | K4: 2.5년이하(전일대비) | L4: 3년이하(전일대비) | M4: 4년이하(전일대비) | N4: 5년이하(전일대비) | O4: 7년이하(전일대비) | P4: 10년이하(전일대비) | Q4: 15년이하(전일대비) | R4: 20년이하(전일대비) | S4: 30년이하(전일대비) | T4: 50년이하(전일대비) | AA4: 2 | AB4: 4사평균 | AC4: 전일대비(bp)
E5: 3월이하(당일) | F5: 6월이하(당일) | G5: 9월이하(당일) | H5: 1년이하(당일) | I5: 1.5년이하(당일) | J5: 2년이하(당일) | K5: 2.5년이하(당일) | L5: 3년이하(당일) | M5: 4년이하(당일) | N5: 5년이하(당일) | O5: 7년이하(당일) | P5: 10년이하(당일) | Q5: 15년이하(당일) | R5: 20년이하(당일) | S5: 30년이하(당일) | T5: 50년이하(당일) | AA5: 3 | AB5: KAP | AC5: 국고대비(bp)
E6: =IF($D$4=1,E$5,IF($D$4=2,E$4,E$3)) -> 3월이하(당일) | F6: =IF($D$4=1,F$5,IF($D$4=2,F$4,F$3)) -> 6월이하(당일) | G6: =IF($D$4=1,G$5,IF($D$4=2,G$4,G$3)) -> 9월이하(당일) | H6: =IF($D$4=1,H$5,IF($D$4=2,H$4,H$3)) -> 1년이하(당일) | I6: =IF($D$4=1,I$5,IF($D$4=2,I$4,I$3)) -> 1.5년이하(당일) | J6: =IF($D$4=1,J$5,IF($D$4=2,J$4,J$3)) -> 2년이하(당일) | K6: =IF($D$4=1,K$5,IF($D$4=2,K$4,K$3)) -> 2.5년이하(당일) | L6: =IF($D$4=1,L$5,IF($D$4=2,L$4,L$3)) -> 3년이하(당일) | ... T6: =IF($D$4=1,T$5,IF($D$4=2,T$4,T$3)) -> 50년이하(당일) | AA6: 4 | AB6: KIS
AA7: 5 | AB7: NICE
B8: 일자 | C8: =WORKDAY(TODAY(),-1) -> 45520 | AA8: 6 | AB8: FN
AA9: 7 | AB9: KOFIA
B10: 대분류 | C10: 중분류 | D10: 소분류 | E10: 3M | F10: 6M | G10: 9M | H10: 1Y | I10: 1.5Y | J10: 2Y | K10: 2.5Y | L10: 3Y | M10: 4Y | N10: 5Y | O10: 7Y | P10: 10Y | Q10: 15Y | R10: 20Y | S10: 30Y | T10: 50Y | Z10: row | AB10: 3M | AC10: 6M | AD10: 9M | AE10: 1Y | AF10: 1.5Y | AG10: 2Y | AH10: 2.5Y | AI10: 3Y | AJ10: 4Y | AK10: 5Y | AL10: 7Y | AM10: 10Y | AN10: 15Y | AO10: 20Y | AP10: 30Y | AQ10: 50Y
B11: 국채 | C11: 국고채 | D11: 양곡,외평,재정 | E11: =IFERROR( IF( $D$4=2, AB11*100, AB11), "") -> 3.338 | F11: =IFERROR( IF( $D$4=2, AC11*100, AC11), "") -> 3.203 | G11: =IFERROR( IF( $D$4=2, AD11*100, AD11), "") -> 3.112 | H11: =IFERROR( IF( $D$4=2, AE11*100, AE11), "") -> 3.052 | I11: =IFERROR( IF( $D$4=2, AF11*100, AF11), "") -> 3.055 | J11: =IFERROR( IF( $D$4=2, AG11*100, AG11), "") -> 3.03 | K11: =IFERROR( IF( $D$4=2, AH11*100, AH11), "") -> 2.944 | L11: =IFERROR( IF( $D$4=2, AI11*100, AI11), "") -> 2.922 | ... T11: =IFERROR( IF( $D$4=2, AQ11*100, AQ11), "") -> 2.763 | Z11: =ROWS($Z$11:Z11) -> 1 | AA11: {=INDEX(code!$E$2:$K$72,시가평가Matrix!$Z11,$D$3)} -> BONDAVG01 | AB11: {=IF( OR($AA11=0,AS11=0), "", _xll.IMDP("IR",$AA11,E$6,$C$8) )} -> 3.338 | AC11: {=IF( OR($AA11=0,AT11=0), "", _xll.IMDP("IR",$AA11,F$6,$C$8) )} -> 3.203 | AD11: {=IF( OR($AA11=0,AU11=0), "", _xll.IMDP("IR",$AA11,G$6,$C$8) )} -> 3.112 | AE11: {=IF( OR($AA11=0,AV11=0), "", _xll.IMDP("IR",$AA11,H$6,$C$8) )} -> 3.052 | AF11: {=IF( OR($AA11=0,AW11=0), "", _xll.IMDP("IR",$AA11,I$6,$C$8) )} -> 3.055 | AG11: {=IF( OR($AA11=0,AX11=0), "", _xll.IMDP("IR",$AA11,J$6,$C$8) )} -> 3.03 | AH11: {=IF( OR($AA11=0,AY11=0), "", _xll.IMDP("IR",$AA11,K$6,$C$8) )} -> 2.944 | AI11: {=IF( OR($AA11=0,AZ11=0), "", _xll.IMDP("IR",$AA11,L$6,$C$8) )} -> 2.922 | ... AQ11: {=IF( OR($AA11=0,BH11=0), "", _xll.IMDP("IR",$AA11,T$6,$C$8) )} -> 2.763 | AS11: {=_xll.IMDP("IR",$AA11,E$5,$C$8)} -> 3.338 | AT11: {=_xll.IMDP("IR",$AA11,F$5,$C$8)} -> 3.203 | AU11: {=_xll.IMDP("IR",$AA11,G$5,$C$8)} -> 3.112 | AV11: {=_xll.IMDP("IR",$AA11,H$5,$C$8)} -> 3.052 | AW11: {=_xll.IMDP("IR",$AA11,I$5,$C$8)} -> 3.055 | AX11: {=_xll.IMDP("IR",$AA11,J$5,$C$8)} -> 3.03 | AY11: {=_xll.IMDP("IR",$AA11,K$5,$C$8)} -> 2.944 | AZ11: {=_xll.IMDP("IR",$AA11,L$5,$C$8)} -> 2.922 | ... BH11: {=_xll.IMDP("IR",$AA11,T$5,$C$8)} -> 2.763
C12: 국민주택1종 | D12: 복리채 | E12: =IFERROR( IF( $D$4=2, AB12*100, AB12), "") -> 3.346 | F12: =IFERROR( IF( $D$4=2, AC12*100, AC12), "") -> 3.254 | G12: =IFERROR( IF( $D$4=2, AD12*100, AD12), "") -> 3.172 | H12: =IFERROR( IF( $D$4=2, AE12*100, AE12), "") -> 3.089 | I12: =IFERROR( IF( $D$4=2, AF12*100, AF12), "") -> 3.077 | J12: =IFERROR( IF( $D$4=2, AG12*100, AG12), "") -> 3.054 | K12: =IFERROR( IF( $D$4=2, AH12*100, AH12), "") -> 3.012 | L12: =IFERROR( IF( $D$4=2, AI12*100, AI12), "") -> 3.01 | ... T12: =IFERROR( IF( $D$4=2, AQ12*100, AQ12), "") | Z12: =ROWS($Z$11:Z12) -> 2 | AA12: {=INDEX(code!$E$2:$K$72,시가평가Matrix!$Z12,$D$3)} -> BONDAVG02 | AB12: {=IF( OR($AA12=0,AS12=0), "", _xll.IMDP("IR",$AA12,E$6,$C$8) )} -> 3.346 | AC12: {=IF( OR($AA12=0,AT12=0), "", _xll.IMDP("IR",$AA12,F$6,$C$8) )} -> 3.254 | AD12: {=IF( OR($AA12=0,AU12=0), "", _xll.IMDP("IR",$AA12,G$6,$C$8) )} -> 3.172 | AE12: {=IF( OR($AA12=0,AV12=0), "", _xll.IMDP("IR",$AA12,H$6,$C$8) )} -> 3.089 | AF12: {=IF( OR($AA12=0,AW12=0), "", _xll.IMDP("IR",$AA12,I$6,$C$8) )} -> 3.077 | AG12: {=IF( OR($AA12=0,AX12=0), "", _xll.IMDP("IR",$AA12,J$6,$C$8) )} -> 3.054 | AH12: {=IF( OR($AA12=0,AY12=0), "", _xll.IMDP("IR",$AA12,K$6,$C$8) )} -> 3.012 | AI12: {=IF( OR($AA12=0,AZ12=0), "", _xll.IMDP("IR",$AA12,L$6,$C$8) )} -> 3.01 | ... AQ12: {=IF( OR($AA12=0,BH12=0), "", _xll.IMDP("IR",$AA12,T$6,$C$8) )} | AS12: {=_xll.IMDP("IR",$AA12,E$5,$C$8)} -> 3.346 | AT12: {=_xll.IMDP("IR",$AA12,F$5,$C$8)} -> 3.254 | AU12: {=_xll.IMDP("IR",$AA12,G$5,$C$8)} -> 3.172 | AV12: {=_xll.IMDP("IR",$AA12,H$5,$C$8)} -> 3.089 | AW12: {=_xll.IMDP("IR",$AA12,I$5,$C$8)} -> 3.077 | AX12: {=_xll.IMDP("IR",$AA12,J$5,$C$8)} -> 3.054 | AY12: {=_xll.IMDP("IR",$AA12,K$5,$C$8)} -> 3.012 | AZ12: {=_xll.IMDP("IR",$AA12,L$5,$C$8)} -> 3.01 | ... BH12: {=_xll.IMDP("IR",$AA12,T$5,$C$8)} -> 0
C13: 국민주택2종 | D13: 복리채 | E13: =IFERROR( IF( $D$4=2, AB13*100, AB13), "") -> 3.129 | F13: =IFERROR( IF( $D$4=2, AC13*100, AC13), "") -> 3.046 | G13: =IFERROR( IF( $D$4=2, AD13*100, AD13), "") -> 2.976 | H13: =IFERROR( IF( $D$4=2, AE13*100, AE13), "") -> 2.886 | I13: =IFERROR( IF( $D$4=2, AF13*100, AF13), "") -> 2.876 | J13: =IFERROR( IF( $D$4=2, AG13*100, AG13), "") -> 2.852 | K13: =IFERROR( IF( $D$4=2, AH13*100, AH13), "") -> 2.81 | L13: =IFERROR( IF( $D$4=2, AI13*100, AI13), "") -> 2.822 | ... T13: =IFERROR( IF( $D$4=2, AQ13*100, AQ13), "") | Z13: =ROWS($Z$11:Z13) -> 3 | AA13: {=INDEX(code!$E$2:$K$72,시가평가Matrix!$Z13,$D$3)} -> BONDAVG03 | AB13: {=IF( OR($AA13=0,AS13=0), "", _xll.IMDP("IR",$AA13,E$6,$C$8) )} -> 3.129 | AC13: {=IF( OR($AA13=0,AT13=0), "", _xll.IMDP("IR",$AA13,F$6,$C$8) )} -> 3.046 | AD13: {=IF( OR($AA13=0,AU13=0), "", _xll.IMDP("IR",$AA13,G$6,$C$8) )} -> 2.976 | AE13: {=IF( OR($AA13=0,AV13=0), "", _xll.IMDP("IR",$AA13,H$6,$C$8) )} -> 2.886 | AF13: {=IF( OR($AA13=0,AW13=0), "", _xll.IMDP("IR",$AA13,I$6,$C$8) )} -> 2.876 | AG13: {=IF( OR($AA13=0,AX13=0), "", _xll.IMDP("IR",$AA13,J$6,$C$8) )} -> 2.852 | AH13: {=IF( OR($AA13=0,AY13=0), "", _xll.IMDP("IR",$AA13,K$6,$C$8) )} -> 2.81 | AI13: {=IF( OR($AA13=0,AZ13=0), "", _xll.IMDP("IR",$AA13,L$6,$C$8) )} -> 2.822 | ... AQ13: {=IF( OR($AA13=0,BH13=0), "", _xll.IMDP("IR",$AA13,T$6,$C$8) )} | AS13: {=_xll.IMDP("IR",$AA13,E$5,$C$8)} -> 3.129 | AT13: {=_xll.IMDP("IR",$AA13,F$5,$C$8)} -> 3.046 | AU13: {=_xll.IMDP("IR",$AA13,G$5,$C$8)} -> 2.976 | AV13: {=_xll.IMDP("IR",$AA13,H$5,$C$8)} -> 2.886 | AW13: {=_xll.IMDP("IR",$AA13,I$5,$C$8)} -> 2.876 | AX13: {=_xll.IMDP("IR",$AA13,J$5,$C$8)} -> 2.852 | AY13: {=_xll.IMDP("IR",$AA13,K$5,$C$8)} -> 2.81 | AZ13: {=_xll.IMDP("IR",$AA13,L$5,$C$8)} -> 2.822 | ... BH13: {=_xll.IMDP("IR",$AA13,T$5,$C$8)} -> 0
C14: 국민주택3종 | D14: 복리채 | E14: =IFERROR( IF( $D$4=2, AB14*100, AB14), "") -> 2.875 | F14: =IFERROR( IF( $D$4=2, AC14*100, AC14), "") -> 2.785 | G14: =IFERROR( IF( $D$4=2, AD14*100, AD14), "") -> 2.695 | H14: =IFERROR( IF( $D$4=2, AE14*100, AE14), "") -> 2.597 | I14: =IFERROR( IF( $D$4=2, AF14*100, AF14), "") -> 2.607 | J14: =IFERROR( IF( $D$4=2, AG14*100, AG14), "") -> 2.577 | K14: =IFERROR( IF( $D$4=2, AH14*100, AH14), "") -> 2.517 | L14: =IFERROR( IF( $D$4=2, AI14*100, AI14), "") -> 2.54 | ... T14: =IFERROR( IF( $D$4=2, AQ14*100, AQ14), "") | Z14: =ROWS($Z$11:Z14) -> 4 | AA14: {=INDEX(code!$E$2:$K$72,시가평가Matrix!$Z14,$D$3)} -> BONDAVG04 | AB14: {=IF( OR($AA14=0,AS14=0), "", _xll.IMDP("IR",$AA14,E$6,$C$8) )} -> 2.875 | AC14: {=IF( OR($AA14=0,AT14=0), "", _xll.IMDP("IR",$AA14,F$6,$C$8) )} -> 2.785 | AD14: {=IF( OR($AA14=0,AU14=0), "", _xll.IMDP("IR",$AA14,G$6,$C$8) )} -> 2.695 | AE14: {=IF( OR($AA14=0,AV14=0), "", _xll.IMDP("IR",$AA14,H$6,$C$8) )} -> 2.597 | AF14: {=IF( OR($AA14=0,AW14=0), "", _xll.IMDP("IR",$AA14,I$6,$C$8) )} -> 2.607 | AG14: {=IF( OR($AA14=0,AX14=0), "", _xll.IMDP("IR",$AA14,J$6,$C$8) )} -> 2.577 | AH14: {=IF( OR($AA14=0,AY14=0), "", _xll.IMDP("IR",$AA14,K$6,$C$8) )} -> 2.517 | AI14: {=IF( OR($AA14=0,AZ14=0), "", _xll.IMDP("IR",$AA14,L$6,$C$8) )} -> 2.54 | ... AQ14: {=IF( OR($AA14=0,BH14=0), "", _xll.IMDP("IR",$AA14,T$6,$C$8) )} | AS14: {=_xll.IMDP("IR",$AA14,E$5,$C$8)} -> 2.875 | AT14: {=_xll.IMDP("IR",$AA14,F$5,$C$8)} -> 2.785 | AU14: {=_xll.IMDP("IR",$AA14,G$5,$C$8)} -> 2.695 | AV14: {=_xll.IMDP("IR",$AA14,H$5,$C$8)} -> 2.597 | AW14: {=_xll.IMDP("IR",$AA14,I$5,$C$8)} -> 2.607 | AX14: {=_xll.IMDP("IR",$AA14,J$5,$C$8)} -> 2.577 | AY14: {=_xll.IMDP("IR",$AA14,K$5,$C$8)} -> 2.517 | AZ14: {=_xll.IMDP("IR",$AA14,L$5,$C$8)} -> 2.54 | ... BH14: {=_xll.IMDP("IR",$AA14,T$5,$C$8)} -> 0
B15: 지방채 | C15: 서울도시철도 | D15: 분할거치 | E15: =IFERROR( IF( $D$4=2, AB15*100, AB15), "") -> 3.413 | F15: =IFERROR( IF( $D$4=2, AC15*100, AC15), "") -> 3.341 | G15: =IFERROR( IF( $D$4=2, AD15*100, AD15), "") -> 3.256 | H15: =IFERROR( IF( $D$4=2, AE15*100, AE15), "") -> 3.17 | I15: =IFERROR( IF( $D$4=2, AF15*100, AF15), "") -> 3.168 | J15: =IFERROR( IF( $D$4=2, AG15*100, AG15), "") -> 3.147 | K15: =IFERROR( IF( $D$4=2, AH15*100, AH15), "") -> 3.113 | L15: =IFERROR( IF( $D$4=2, AI15*100, AI15), "") -> 3.126 | ... T15: =IFERROR( IF( $D$4=2, AQ15*100, AQ15), "") | Z15: =ROWS($Z$11:Z15) -> 5 | AA15: {=INDEX(code!$E$2:$K$72,시가평가Matrix!$Z15,$D$3)} -> BONDAVG05 | AB15: {=IF( OR($AA15=0,AS15=0), "", _xll.IMDP("IR",$AA15,E$6,$C$8) )} -> 3.413 | AC15: {=IF( OR($AA15=0,AT15=0), "", _xll.IMDP("IR",$AA15,F$6,$C$8) )} -> 3.341 | AD15: {=IF( OR($AA15=0,AU15=0), "", _xll.IMDP("IR",$AA15,G$6,$C$8) )} -> 3.256 | AE15: {=IF( OR($AA15=0,AV15=0), "", _xll.IMDP("IR",$AA15,H$6,$C$8) )} -> 3.17 | AF15: {=IF( OR($AA15=0,AW15=0), "", _xll.IMDP("IR",$AA15,I$6,$C$8) )} -> 3.168 | AG15: {=IF( OR($AA15=0,AX15=0), "", _xll.IMDP("IR",$AA15,J$6,$C$8) )} -> 3.147 | AH15: {=IF( OR($AA15=0,AY15=0), "", _xll.IMDP("IR",$AA15,K$6,$C$8) )} -> 3.113 | AI15: {=IF( OR($AA15=0,AZ15=0), "", _xll.IMDP("IR",$AA15,L$6,$C$8) )} -> 3.126 | ... AQ15: {=IF( OR($AA15=0,BH15=0), "", _xll.IMDP("IR",$AA15,T$6,$C$8) )} | AS15: {=_xll.IMDP("IR",$AA15,E$5,$C$8)} -> 3.413 | AT15: {=_xll.IMDP("IR",$AA15,F$5,$C$8)} -> 3.341 | AU15: {=_xll.IMDP("IR",$AA15,G$5,$C$8)} -> 3.256 | AV15: {=_xll.IMDP("IR",$AA15,H$5,$C$8)} -> 3.17 | AW15: {=_xll.IMDP("IR",$AA15,I$5,$C$8)} -> 3.168 | AX15: {=_xll.IMDP("IR",$AA15,J$5,$C$8)} -> 3.147 | AY15: {=_xll.IMDP("IR",$AA15,K$5,$C$8)} -> 3.113 | AZ15: {=_xll.IMDP("IR",$AA15,L$5,$C$8)} -> 3.126 | ... BH15: {=_xll.IMDP("IR",$AA15,T$5,$C$8)} -> 0
C16: 지역개발채 | D16: 복리채 | E16: =IFERROR( IF( $D$4=2, AB16*100, AB16), "") -> 3.413 | F16: =IFERROR( IF( $D$4=2, AC16*100, AC16), "") -> 3.341 | G16: =IFERROR( IF( $D$4=2, AD16*100, AD16), "") -> 3.256 | H16: =IFERROR( IF( $D$4=2, AE16*100, AE16), "") -> 3.17 | I16: =IFERROR( IF( $D$4=2, AF16*100, AF16), "") -> 3.168 | J16: =IFERROR( IF( $D$4=2, AG16*100, AG16), "") -> 3.149 | K16: =IFERROR( IF( $D$4=2, AH16*100, AH16), "") -> 3.113 | L16: =IFERROR( IF( $D$4=2, AI16*100, AI16), "") -> 3.126 | ... T16: =IFERROR( IF( $D$4=2, AQ16*100, AQ16), "") | Z16: =ROWS($Z$11:Z16) -> 6 | AA16: {=INDEX(code!$E$2:$K$72,시가평가Matrix!$Z16,$D$3)} -> BONDAVG06 | AB16: {=IF( OR($AA16=0,AS16=0), "", _xll.IMDP("IR",$AA16,E$6,$C$8) )} -> 3.413 | AC16: {=IF( OR($AA16=0,AT16=0), "", _xll.IMDP("IR",$AA16,F$6,$C$8) )} -> 3.341 | AD16: {=IF( OR($AA16=0,AU16=0), "", _xll.IMDP("IR",$AA16,G$6,$C$8) )} -> 3.256 | AE16: {=IF( OR($AA16=0,AV16=0), "", _xll.IMDP("IR",$AA16,H$6,$C$8) )} -> 3.17 | AF16: {=IF( OR($AA16=0,AW16=0), "", _xll.IMDP("IR",$AA16,I$6,$C$8) )} -> 3.168 | AG16: {=IF( OR($AA16=0,AX16=0), "", _xll.IMDP("IR",$AA16,J$6,$C$8) )} -> 3.149 | AH16: {=IF( OR($AA16=0,AY16=0), "", _xll.IMDP("IR",$AA16,K$6,$C$8) )} -> 3.113 | AI16: {=IF( OR($AA16=0,AZ16=0), "", _xll.IMDP("IR",$AA16,L$6,$C$8) )} -> 3.126 | ... AQ16: {=IF( OR($AA16=0,BH16=0), "", _xll.IMDP("IR",$AA16,T$6,$C$8) )} | AS16: {=_xll.IMDP("IR",$AA16,E$5,$C$8)} -> 3.413 | AT16: {=_xll.IMDP("IR",$AA16,F$5,$C$8)} -> 3.341 | AU16: {=_xll.IMDP("IR",$AA16,G$5,$C$8)} -> 3.256 | AV16: {=_xll.IMDP("IR",$AA16,H$5,$C$8)} -> 3.17 | AW16: {=_xll.IMDP("IR",$AA16,I$5,$C$8)} -> 3.168 | AX16: {=_xll.IMDP("IR",$AA16,J$5,$C$8)} -> 3.149 | AY16: {=_xll.IMDP("IR",$AA16,K$5,$C$8)} -> 3.113 | AZ16: {=_xll.IMDP("IR",$AA16,L$5,$C$8)} -> 3.126 | ... BH16: {=_xll.IMDP("IR",$AA16,T$5,$C$8)} -> 0
B17: 공사/공단채 | C17: 공사/공단채 | D17: 정부보증 | E17: =IFERROR( IF( $D$4=2, AB17*100, AB17), "") -> 3.388 | F17: =IFERROR( IF( $D$4=2, AC17*100, AC17), "") -> 3.313 | G17: =IFERROR( IF( $D$4=2, AD17*100, AD17), "") -> 3.233 | H17: =IFERROR( IF( $D$4=2, AE17*100, AE17), "") -> 3.182 | I17: =IFERROR( IF( $D$4=2, AF17*100, AF17), "") -> 3.135 | J17: =IFERROR( IF( $D$4=2, AG17*100, AG17), "") -> 3.121 | K17: =IFERROR( IF( $D$4=2, AH17*100, AH17), "") -> 3.087 | L17: =IFERROR( IF( $D$4=2, AI17*100, AI17), "") -> 3.07 | ... T17: =IFERROR( IF( $D$4=2, AQ17*100, AQ17), "") | Z17: =ROWS($Z$11:Z17) -> 7 | AA17: {=INDEX(code!$E$2:$K$72,시가평가Matrix!$Z17,$D$3)} -> BONDAVG13 | AB17: {=IF( OR($AA17=0,AS17=0), "", _xll.IMDP("IR",$AA17,E$6,$C$8) )} -> 3.388 | AC17: {=IF( OR($AA17=0,AT17=0), "", _xll.IMDP("IR",$AA17,F$6,$C$8) )} -> 3.313 | AD17: {=IF( OR($AA17=0,AU17=0), "", _xll.IMDP("IR",$AA17,G$6,$C$8) )} -> 3.233 | AE17: {=IF( OR($AA17=0,AV17=0), "", _xll.IMDP("IR",$AA17,H$6,$C$8) )} -> 3.182 | AF17: {=IF( OR($AA17=0,AW17=0), "", _xll.IMDP("IR",$AA17,I$6,$C$8) )} -> 3.135 | AG17: {=IF( OR($AA17=0,AX17=0), "", _xll.IMDP("IR",$AA17,J$6,$C$8) )} -> 3.121 | AH17: {=IF( OR($AA17=0,AY17=0), "", _xll.IMDP("IR",$AA17,K$6,$C$8) )} -> 3.087 | AI17: {=IF( OR($AA17=0,AZ17=0), "", _xll.IMDP("IR",$AA17,L$6,$C$8) )} -> 3.07 | ... AQ17: {=IF( OR($AA17=0,BH17=0), "", _xll.IMDP("IR",$AA17,T$6,$C$8) )} | AS17: {=_xll.IMDP("IR",$AA17,E$5,$C$8)} -> 3.388 | AT17: {=_xll.IMDP("IR",$AA17,F$5,$C$8)} -> 3.313 | AU17: {=_xll.IMDP("IR",$AA17,G$5,$C$8)} -> 3.233 | AV17: {=_xll.IMDP("IR",$AA17,H$5,$C$8)} -> 3.182 | AW17: {=_xll.IMDP("IR",$AA17,I$5,$C$8)} -> 3.135 | AX17: {=_xll.IMDP("IR",$AA17,J$5,$C$8)} -> 3.121 | AY17: {=_xll.IMDP("IR",$AA17,K$5,$C$8)} -> 3.087 | AZ17: {=_xll.IMDP("IR",$AA17,L$5,$C$8)} -> 3.07 | ... BH17: {=_xll.IMDP("IR",$AA17,T$5,$C$8)} -> 0
D18: AAA | E18: =IFERROR( IF( $D$4=2, AB18*100, AB18), "") -> 3.393 | F18: =IFERROR( IF( $D$4=2, AC18*100, AC18), "") -> 3.361 | G18: =IFERROR( IF( $D$4=2, AD18*100, AD18), "") -> 3.298 | H18: =IFERROR( IF( $D$4=2, AE18*100, AE18), "") -> 3.259 | I18: =IFERROR( IF( $D$4=2, AF18*100, AF18), "") -> 3.197 | J18: =IFERROR( IF( $D$4=2, AG18*100, AG18), "") -> 3.186 | K18: =IFERROR( IF( $D$4=2, AH18*100, AH18), "") -> 3.156 | L18: =IFERROR( IF( $D$4=2, AI18*100, AI18), "") -> 3.154 | ... T18: =IFERROR( IF( $D$4=2, AQ18*100, AQ18), "") | Z18: =ROWS($Z$11:Z18) -> 8 | AA18: {=INDEX(code!$E$2:$K$72,시가평가Matrix!$Z18,$D$3)} -> BONDAVG09 | AB18: {=IF( OR($AA18=0,AS18=0), "", _xll.IMDP("IR",$AA18,E$6,$C$8) )} -> 3.393 | AC18: {=IF( OR($AA18=0,AT18=0), "", _xll.IMDP("IR",$AA18,F$6,$C$8) )} -> 3.361 | AD18: {=IF( OR($AA18=0,AU18=0), "", _xll.IMDP("IR",$AA18,G$6,$C$8) )} -> 3.298 | AE18: {=IF( OR($AA18=0,AV18=0), "", _xll.IMDP("IR",$AA18,H$6,$C$8) )} -> 3.259 | AF18: {=IF( OR($AA18=0,AW18=0), "", _xll.IMDP("IR",$AA18,I$6,$C$8) )} -> 3.197 | AG18: {=IF( OR($AA18=0,AX18=0), "", _xll.IMDP("IR",$AA18,J$6,$C$8) )} -> 3.186 | AH18: {=IF( OR($AA18=0,AY18=0), "", _xll.IMDP("IR",$AA18,K$6,$C$8) )} -> 3.156 | AI18: {=IF( OR($AA18=0,AZ18=0), "", _xll.IMDP("IR",$AA18,L$6,$C$8) )} -> 3.154 | ... AQ18: {=IF( OR($AA18=0,BH18=0), "", _xll.IMDP("IR",$AA18,T$6,$C$8) )} | AS18: {=_xll.IMDP("IR",$AA18,E$5,$C$8)} -> 3.393 | AT18: {=_xll.IMDP("IR",$AA18,F$5,$C$8)} -> 3.361 | AU18: {=_xll.IMDP("IR",$AA18,G$5,$C$8)} -> 3.298 | AV18: {=_xll.IMDP("IR",$AA18,H$5,$C$8)} -> 3.259 | AW18: {=_xll.IMDP("IR",$AA18,I$5,$C$8)} -> 3.197 | AX18: {=_xll.IMDP("IR",$AA18,J$5,$C$8)} -> 3.186 | AY18: {=_xll.IMDP("IR",$AA18,K$5,$C$8)} -> 3.156 | AZ18: {=_xll.IMDP("IR",$AA18,L$5,$C$8)} -> 3.154 | ... BH18: {=_xll.IMDP("IR",$AA18,T$5,$C$8)} -> 0
D19: AA+ | E19: =IFERROR( IF( $D$4=2, AB19*100, AB19), "") -> 3.418 | F19: =IFERROR( IF( $D$4=2, AC19*100, AC19), "") -> 3.408 | G19: =IFERROR( IF( $D$4=2, AD19*100, AD19), "") -> 3.356 | H19: =IFERROR( IF( $D$4=2, AE19*100, AE19), "") -> 3.309 | I19: =IFERROR( IF( $D$4=2, AF19*100, AF19), "") -> 3.279 | J19: =IFERROR( IF( $D$4=2, AG19*100, AG19), "") -> 3.287 | K19: =IFERROR( IF( $D$4=2, AH19*100, AH19), "") -> 3.255 | L19: =IFERROR( IF( $D$4=2, AI19*100, AI19), "") -> 3.246 | ... T19: =IFERROR( IF( $D$4=2, AQ19*100, AQ19), "") | Z19: =ROWS($Z$11:Z19) -> 9 | AA19: {=INDEX(code!$E$2:$K$72,시가평가Matrix!$Z19,$D$3)} -> BONDAVG10 | AB19: {=IF( OR($AA19=0,AS19=0), "", _xll.IMDP("IR",$AA19,E$6,$C$8) )} -> 3.418 | AC19: {=IF( OR($AA19=0,AT19=0), "", _xll.IMDP("IR",$AA19,F$6,$C$8) )} -> 3.408 | AD19: {=IF( OR($AA19=0,AU19=0), "", _xll.IMDP("IR",$AA19,G$6,$C$8) )} -> 3.356 | AE19: {=IF( OR($AA19=0,AV19=0), "", _xll.IMDP("IR",$AA19,H$6,$C$8) )} -> 3.309 | AF19: {=IF( OR($AA19=0,AW19=0), "", _xll.IMDP("IR",$AA19,I$6,$C$8) )} -> 3.279 | AG19: {=IF( OR($AA19=0,AX19=0), "", _xll.IMDP("IR",$AA19,J$6,$C$8) )} -> 3.287 | AH19: {=IF( OR($AA19=0,AY19=0), "", _xll.IMDP("IR",$AA19,K$6,$C$8) )} -> 3.255 | AI19: {=IF( OR($AA19=0,AZ19=0), "", _xll.IMDP("IR",$AA19,L$6,$C$8) )} -> 3.246 | ... AQ19: {=IF( OR($AA19=0,BH19=0), "", _xll.IMDP("IR",$AA19,T$6,$C$8) )} | AS19: {=_xll.IMDP("IR",$AA19,E$5,$C$8)} -> 3.418 | AT19: {=_xll.IMDP("IR",$AA19,F$5,$C$8)} -> 3.408 | AU19: {=_xll.IMDP("IR",$AA19,G$5,$C$8)} -> 3.356 | AV19: {=_xll.IMDP("IR",$AA19,H$5,$C$8)} -> 3.309 | AW19: {=_xll.IMDP("IR",$AA19,I$5,$C$8)} -> 3.279 | AX19: {=_xll.IMDP("IR",$AA19,J$5,$C$8)} -> 3.287 | AY19: {=_xll.IMDP("IR",$AA19,K$5,$C$8)} -> 3.255 | AZ19: {=_xll.IMDP("IR",$AA19,L$5,$C$8)} -> 3.246 | ... BH19: {=_xll.IMDP("IR",$AA19,T$5,$C$8)} -> 0
D20: AA0 | E20: =IFERROR( IF( $D$4=2, AB20*100, AB20), "") -> 3.467 | F20: =IFERROR( IF( $D$4=2, AC20*100, AC20), "") -> 3.477 | G20: =IFERROR( IF( $D$4=2, AD20*100, AD20), "") -> 3.441 | H20: =IFERROR( IF( $D$4=2, AE20*100, AE20), "") -> 3.41 | I20: =IFERROR( IF( $D$4=2, AF20*100, AF20), "") -> 3.404 | J20: =IFERROR( IF( $D$4=2, AG20*100, AG20), "") -> 3.412 | K20: =IFERROR( IF( $D$4=2, AH20*100, AH20), "") -> 3.389 | L20: =IFERROR( IF( $D$4=2, AI20*100, AI20), "") -> 3.398 | ... T20: =IFERROR( IF( $D$4=2, AQ20*100, AQ20), "") | Z20: =ROWS($Z$11:Z20) -> 10 | AA20: {=INDEX(code!$E$2:$K$72,시가평가Matrix!$Z20,$D$3)} -> BONDAVG11 | AB20: {=IF( OR($AA20=0,AS20=0), "", _xll.IMDP("IR",$AA20,E$6,$C$8) )} -> 3.467 | AC20: {=IF( OR($AA20=0,AT20=0), "", _xll.IMDP("IR",$AA20,F$6,$C$8) )} -> 3.477 | AD20: {=IF( OR($AA20=0,AU20=0), "", _xll.IMDP("IR",$AA20,G$6,$C$8) )} -> 3.441 | AE20: {=IF( OR($AA20=0,AV20=0), "", _xll.IMDP("IR",$AA20,H$6,$C$8) )} -> 3.41 | AF20: {=IF( OR($AA20=0,AW20=0), "", _xll.IMDP("IR",$AA20,I$6,$C$8) )} -> 3.404 | AG20: {=IF( OR($AA20=0,AX20=0), "", _xll.IMDP("IR",$AA20,J$6,$C$8) )} -> 3.412 | AH20: {=IF( OR($AA20=0,AY20=0), "", _xll.IMDP("IR",$AA20,K$6,$C$8) )} -> 3.389 | AI20: {=IF( OR($AA20=0,AZ20=0), "", _xll.IMDP("IR",$AA20,L$6,$C$8) )} -> 3.398 | ... AQ20: {=IF( OR($AA20=0,BH20=0), "", _xll.IMDP("IR",$AA20,T$6,$C$8) )} | AS20: {=_xll.IMDP("IR",$AA20,E$5,$C$8)} -> 3.467 | AT20: {=_xll.IMDP("IR",$AA20,F$5,$C$8)} -> 3.477 | AU20: {=_xll.IMDP("IR",$AA20,G$5,$C$8)} -> 3.441 | AV20: {=_xll.IMDP("IR",$AA20,H$5,$C$8)} -> 3.41 | AW20: {=_xll.IMDP("IR",$AA20,I$5,$C$8)} -> 3.404 | AX20: {=_xll.IMDP("IR",$AA20,J$5,$C$8)} -> 3.412 | AY20: {=_xll.IMDP("IR",$AA20,K$5,$C$8)} -> 3.389 | AZ20: {=_xll.IMDP("IR",$AA20,L$5,$C$8)} -> 3.398 | ... BH20: {=_xll.IMDP("IR",$AA20,T$5,$C$8)} -> 0
D21: AA- | E21: =IFERROR( IF( $D$4=2, AB21*100, AB21), "") -> 3.582 | F21: =IFERROR( IF( $D$4=2, AC21*100, AC21), "") -> 3.599 | G21: =IFERROR( IF( $D$4=2, AD21*100, AD21), "") -> 3.574 | H21: =IFERROR( IF( $D$4=2, AE21*100, AE21), "") -> 3.569 | I21: =IFERROR( IF( $D$4=2, AF21*100, AF21), "") -> 3.544 | J21: =IFERROR( IF( $D$4=2, AG21*100, AG21), "") -> 3.553 | K21: =IFERROR( IF( $D$4=2, AH21*100, AH21), "") -> 3.527 | L21: =IFERROR( IF( $D$4=2, AI21*100, AI21), "") -> 3.534 | ... T21: =IFERROR( IF( $D$4=2, AQ21*100, AQ21), "") | Z21: =ROWS($Z$11:Z21) -> 11 | AA21: {=INDEX(code!$E$2:$K$72,시가평가Matrix!$Z21,$D$3)} -> BONDAVG12 | AB21: {=IF( OR($AA21=0,AS21=0), "", _xll.IMDP("IR",$AA21,E$6,$C$8) )} -> 3.582 | AC21: {=IF( OR($AA21=0,AT21=0), "", _xll.IMDP("IR",$AA21,F$6,$C$8) )} -> 3.599 | AD21: {=IF( OR($AA21=0,AU21=0), "", _xll.IMDP("IR",$AA21,G$6,$C$8) )} -> 3.574 | AE21: {=IF( OR($AA21=0,AV21=0), "", _xll.IMDP("IR",$AA21,H$6,$C$8) )} -> 3.569 | AF21: {=IF( OR($AA21=0,AW21=0), "", _xll.IMDP("IR",$AA21,I$6,$C$8) )} -> 3.544 | AG21: {=IF( OR($AA21=0,AX21=0), "", _xll.IMDP("IR",$AA21,J$6,$C$8) )} -> 3.553 | AH21: {=IF( OR($AA21=0,AY21=0), "", _xll.IMDP("IR",$AA21,K$6,$C$8) )} -> 3.527 | AI21: {=IF( OR($AA21=0,AZ21=0), "", _xll.IMDP("IR",$AA21,L$6,$C$8) )} -> 3.534 | ... AQ21: {=IF( OR($AA21=0,BH21=0), "", _xll.IMDP("IR",$AA21,T$6,$C$8) )} | AS21: {=_xll.IMDP("IR",$AA21,E$5,$C$8)} -> 3.582 | AT21: {=_xll.IMDP("IR",$AA21,F$5,$C$8)} -> 3.599 | AU21: {=_xll.IMDP("IR",$AA21,G$5,$C$8)} -> 3.574 | AV21: {=_xll.IMDP("IR",$AA21,H$5,$C$8)} -> 3.569 | AW21: {=_xll.IMDP("IR",$AA21,I$5,$C$8)} -> 3.544 | AX21: {=_xll.IMDP("IR",$AA21,J$5,$C$8)} -> 3.553 | AY21: {=_xll.IMDP("IR",$AA21,K$5,$C$8)} -> 3.527 | AZ21: {=_xll.IMDP("IR",$AA21,L$5,$C$8)} -> 3.534 | ... BH21: {=_xll.IMDP("IR",$AA21,T$5,$C$8)} -> 0
B22: 통안증권 | C22: 통안증권 | D22: 이표채 | E22: =IFERROR( IF( $D$4=2, AB22*100, AB22), "") -> 3.271 | F22: =IFERROR( IF( $D$4=2, AC22*100, AC22), "") -> 3.169 | G22: =IFERROR( IF( $D$4=2, AD22*100, AD22), "") -> 3.097 | H22: =IFERROR( IF( $D$4=2, AE22*100, AE22), "") -> 3.025 | I22: =IFERROR( IF( $D$4=2, AF22*100, AF22), "") -> 3.043 | J22: =IFERROR( IF( $D$4=2, AG22*100, AG22), "") -> 2.987 | K22: =IFERROR( IF( $D$4=2, AH22*100, AH22), "") -> 2.993 | L22: =IFERROR( IF( $D$4=2, AI22*100, AI22), "") -> 2.994 | ... T22: =IFERROR( IF( $D$4=2, AQ22*100, AQ22), "") | Z22: =ROWS($Z$11:Z22) -> 12 | AA22: {=INDEX(code!$E$2:$K$72,시가평가Matrix!$Z22,$D$3)} -> BONDAVG14 | AB22: {=IF( OR($AA22=0,AS22=0), "", _xll.IMDP("IR",$AA22,E$6,$C$8) )} -> 3.271 | AC22: {=IF( OR($AA22=0,AT22=0), "", _xll.IMDP("IR",$AA22,F$6,$C$8) )} -> 3.169 | AD22: {=IF( OR($AA22=0,AU22=0), "", _xll.IMDP("IR",$AA22,G$6,$C$8) )} -> 3.097 | AE22: {=IF( OR($AA22=0,AV22=0), "", _xll.IMDP("IR",$AA22,H$6,$C$8) )} -> 3.025 | AF22: {=IF( OR($AA22=0,AW22=0), "", _xll.IMDP("IR",$AA22,I$6,$C$8) )} -> 3.043 | AG22: {=IF( OR($AA22=0,AX22=0), "", _xll.IMDP("IR",$AA22,J$6,$C$8) )} -> 2.987 | AH22: {=IF( OR($AA22=0,AY22=0), "", _xll.IMDP("IR",$AA22,K$6,$C$8) )} -> 2.993 | AI22: {=IF( OR($AA22=0,AZ22=0), "", _xll.IMDP("IR",$AA22,L$6,$C$8) )} -> 2.994 | ... AQ22: {=IF( OR($AA22=0,BH22=0), "", _xll.IMDP("IR",$AA22,T$6,$C$8) )} | AS22: {=_xll.IMDP("IR",$AA22,E$5,$C$8)} -> 3.271 | AT22: {=_xll.IMDP("IR",$AA22,F$5,$C$8)} -> 3.169 | AU22: {=_xll.IMDP("IR",$AA22,G$5,$C$8)} -> 3.097 | AV22: {=_xll.IMDP("IR",$AA22,H$5,$C$8)} -> 3.025 | AW22: {=_xll.IMDP("IR",$AA22,I$5,$C$8)} -> 3.043 | AX22: {=_xll.IMDP("IR",$AA22,J$5,$C$8)} -> 2.987 | AY22: {=_xll.IMDP("IR",$AA22,K$5,$C$8)} -> 2.993 | AZ22: {=_xll.IMDP("IR",$AA22,L$5,$C$8)} -> 2.994 | ... BH22: {=_xll.IMDP("IR",$AA22,T$5,$C$8)} -> 0
D23: 할인채 | E23: =IFERROR( IF( $D$4=2, AB23*100, AB23), "") -> 3.287 | F23: =IFERROR( IF( $D$4=2, AC23*100, AC23), "") -> 3.183 | G23: =IFERROR( IF( $D$4=2, AD23*100, AD23), "") -> 3.111 | H23: =IFERROR( IF( $D$4=2, AE23*100, AE23), "") -> 3.022 | I23: =IFERROR( IF( $D$4=2, AF23*100, AF23), "") -> 3.048 | J23: =IFERROR( IF( $D$4=2, AG23*100, AG23), "") -> 2.994 | K23: =IFERROR( IF( $D$4=2, AH23*100, AH23), "") -> 3.002 | L23: =IFERROR( IF( $D$4=2, AI23*100, AI23), "") -> 3.003 | ... T23: =IFERROR( IF( $D$4=2, AQ23*100, AQ23), "") | Z23: =ROWS($Z$11:Z23) -> 13 | AA23: {=INDEX(code!$E$2:$K$72,시가평가Matrix!$Z23,$D$3)} -> BONDAVG15 | AB23: {=IF( OR($AA23=0,AS23=0), "", _xll.IMDP("IR",$AA23,E$6,$C$8) )} -> 3.287 | AC23: {=IF( OR($AA23=0,AT23=0), "", _xll.IMDP("IR",$AA23,F$6,$C$8) )} -> 3.183 | AD23: {=IF( OR($AA23=0,AU23=0), "", _xll.IMDP("IR",$AA23,G$6,$C$8) )} -> 3.111 | AE23: {=IF( OR($AA23=0,AV23=0), "", _xll.IMDP("IR",$AA23,H$6,$C$8) )} -> 3.022 | AF23: {=IF( OR($AA23=0,AW23=0), "", _xll.IMDP("IR",$AA23,I$6,$C$8) )} -> 3.048 | AG23: {=IF( OR($AA23=0,AX23=0), "", _xll.IMDP("IR",$AA23,J$6,$C$8) )} -> 2.994 | AH23: {=IF( OR($AA23=0,AY23=0), "", _xll.IMDP("IR",$AA23,K$6,$C$8) )} -> 3.002 | AI23: {=IF( OR($AA23=0,AZ23=0), "", _xll.IMDP("IR",$AA23,L$6,$C$8) )} -> 3.003 | ... AQ23: {=IF( OR($AA23=0,BH23=0), "", _xll.IMDP("IR",$AA23,T$6,$C$8) )} | AS23: {=_xll.IMDP("IR",$AA23,E$5,$C$8)} -> 3.287 | AT23: {=_xll.IMDP("IR",$AA23,F$5,$C$8)} -> 3.183 | AU23: {=_xll.IMDP("IR",$AA23,G$5,$C$8)} -> 3.111 | AV23: {=_xll.IMDP("IR",$AA23,H$5,$C$8)} -> 3.022 | AW23: {=_xll.IMDP("IR",$AA23,I$5,$C$8)} -> 3.048 | AX23: {=_xll.IMDP("IR",$AA23,J$5,$C$8)} -> 2.994 | AY23: {=_xll.IMDP("IR",$AA23,K$5,$C$8)} -> 3.002 | AZ23: {=_xll.IMDP("IR",$AA23,L$5,$C$8)} -> 3.003 | ... BH23: {=_xll.IMDP("IR",$AA23,T$5,$C$8)} -> 0
B24: 커버드본드 | C24: 커버드본드 | D24: AAA | E24: =IFERROR( IF( $D$4=2, AB24*100, AB24), "") -> 3.425 | F24: =IFERROR( IF( $D$4=2, AC24*100, AC24), "") -> 3.406 | G24: =IFERROR( IF( $D$4=2, AD24*100, AD24), "") -> 3.335 | H24: =IFERROR( IF( $D$4=2, AE24*100, AE24), "") -> 3.294 | I24: =IFERROR( IF( $D$4=2, AF24*100, AF24), "") -> 3.252 | J24: =IFERROR( IF( $D$4=2, AG24*100, AG24), "") -> 3.213 | K24: =IFERROR( IF( $D$4=2, AH24*100, AH24), "") -> 3.186 | L24: =IFERROR( IF( $D$4=2, AI24*100, AI24), "") -> 3.165 | ... T24: =IFERROR( IF( $D$4=2, AQ24*100, AQ24), "") | Z24: =ROWS($Z$11:Z24) -> 14 | AA24: {=INDEX(code!$E$2:$K$72,시가평가Matrix!$Z24,$D$3)} -> BONDAVG84 | AB24: {=IF( OR($AA24=0,AS24=0), "", _xll.IMDP("IR",$AA24,E$6,$C$8) )} -> 3.425 | AC24: {=IF( OR($AA24=0,AT24=0), "", _xll.IMDP("IR",$AA24,F$6,$C$8) )} -> 3.406 | AD24: {=IF( OR($AA24=0,AU24=0), "", _xll.IMDP("IR",$AA24,G$6,$C$8) )} -> 3.335 | AE24: {=IF( OR($AA24=0,AV24=0), "", _xll.IMDP("IR",$AA24,H$6,$C$8) )} -> 3.294 | AF24: {=IF( OR($AA24=0,AW24=0), "", _xll.IMDP("IR",$AA24,I$6,$C$8) )} -> 3.252 | AG24: {=IF( OR($AA24=0,AX24=0), "", _xll.IMDP("IR",$AA24,J$6,$C$8) )} -> 3.213 | AH24: {=IF( OR($AA24=0,AY24=0), "", _xll.IMDP("IR",$AA24,K$6,$C$8) )} -> 3.186 | AI24: {=IF( OR($AA24=0,AZ24=0), "", _xll.IMDP("IR",$AA24,L$6,$C$8) )} -> 3.165 | ... AQ24: {=IF( OR($AA24=0,BH24=0), "", _xll.IMDP("IR",$AA24,T$6,$C$8) )} | AS24: {=_xll.IMDP("IR",$AA24,E$5,$C$8)} -> 3.425 | AT24: {=_xll.IMDP("IR",$AA24,F$5,$C$8)} -> 3.406 | AU24: {=_xll.IMDP("IR",$AA24,G$5,$C$8)} -> 3.335 | AV24: {=_xll.IMDP("IR",$AA24,H$5,$C$8)} -> 3.294 | AW24: {=_xll.IMDP("IR",$AA24,I$5,$C$8)} -> 3.252 | AX24: {=_xll.IMDP("IR",$AA24,J$5,$C$8)} -> 3.213 | AY24: {=_xll.IMDP("IR",$AA24,K$5,$C$8)} -> 3.186 | AZ24: {=_xll.IMDP("IR",$AA24,L$5,$C$8)} -> 3.165 | ... BH24: {=_xll.IMDP("IR",$AA24,T$5,$C$8)} -> 0
B25: 금융채 | C25: 은행채 | D25: AAA(산금-이표) | E25: =IFERROR( IF( $D$4=2, AB25*100, AB25), "") -> 3.418 | F25: =IFERROR( IF( $D$4=2, AC25*100, AC25), "") -> 3.393 | G25: =IFERROR( IF( $D$4=2, AD25*100, AD25), "") -> 3.323 | H25: =IFERROR( IF( $D$4=2, AE25*100, AE25), "") -> 3.284 | I25: =IFERROR( IF( $D$4=2, AF25*100, AF25), "") -> 3.236 | J25: =IFERROR( IF( $D$4=2, AG25*100, AG25), "") -> 3.185 | K25: =IFERROR( IF( $D$4=2, AH25*100, AH25), "") -> 3.127 | L25: =IFERROR( IF( $D$4=2, AI25*100, AI25), "") -> 3.093 | ... T25: =IFERROR( IF( $D$4=2, AQ25*100, AQ25), "") | Z25: =ROWS($Z$11:Z25) -> 15 | AA25: {=INDEX(code!$E$2:$K$72,시가평가Matrix!$Z25,$D$3)} -> BONDAVG16 | AB25: {=IF( OR($AA25=0,AS25=0), "", _xll.IMDP("IR",$AA25,E$6,$C$8) )} -> 3.418 | AC25: {=IF( OR($AA25=0,AT25=0), "", _xll.IMDP("IR",$AA25,F$6,$C$8) )} -> 3.393 | AD25: {=IF( OR($AA25=0,AU25=0), "", _xll.IMDP("IR",$AA25,G$6,$C$8) )} -> 3.323 | AE25: {=IF( OR($AA25=0,AV25=0), "", _xll.IMDP("IR",$AA25,H$6,$C$8) )} -> 3.284 | AF25: {=IF( OR($AA25=0,AW25=0), "", _xll.IMDP("IR",$AA25,I$6,$C$8) )} -> 3.236 | AG25: {=IF( OR($AA25=0,AX25=0), "", _xll.IMDP("IR",$AA25,J$6,$C$8) )} -> 3.185 | AH25: {=IF( OR($AA25=0,AY25=0), "", _xll.IMDP("IR",$AA25,K$6,$C$8) )} -> 3.127 | AI25: {=IF( OR($AA25=0,AZ25=0), "", _xll.IMDP("IR",$AA25,L$6,$C$8) )} -> 3.093 | ... AQ25: {=IF( OR($AA25=0,BH25=0), "", _xll.IMDP("IR",$AA25,T$6,$C$8) )} | AS25: {=_xll.IMDP("IR",$AA25,E$5,$C$8)} -> 3.418 | AT25: {=_xll.IMDP("IR",$AA25,F$5,$C$8)} -> 3.393 | AU25: {=_xll.IMDP("IR",$AA25,G$5,$C$8)} -> 3.323 | AV25: {=_xll.IMDP("IR",$AA25,H$5,$C$8)} -> 3.284 | AW25: {=_xll.IMDP("IR",$AA25,I$5,$C$8)} -> 3.236 | AX25: {=_xll.IMDP("IR",$AA25,J$5,$C$8)} -> 3.185 | AY25: {=_xll.IMDP("IR",$AA25,K$5,$C$8)} -> 3.127 | AZ25: {=_xll.IMDP("IR",$AA25,L$5,$C$8)} -> 3.093 | ... BH25: {=_xll.IMDP("IR",$AA25,T$5,$C$8)} -> 0
D26: AAA(산금-할인) | E26: =IFERROR( IF( $D$4=2, AB26*100, AB26), "") -> 3.411 | F26: =IFERROR( IF( $D$4=2, AC26*100, AC26), "") -> 3.394 | G26: =IFERROR( IF( $D$4=2, AD26*100, AD26), "") -> 3.316 | H26: =IFERROR( IF( $D$4=2, AE26*100, AE26), "") -> 3.274 | I26: =IFERROR( IF( $D$4=2, AF26*100, AF26), "") -> 3.24 | J26: =IFERROR( IF( $D$4=2, AG26*100, AG26), "") -> 3.198 | K26: =IFERROR( IF( $D$4=2, AH26*100, AH26), "") -> 3.152 | L26: =IFERROR( IF( $D$4=2, AI26*100, AI26), "") -> 3.128 | ... T26: =IFERROR( IF( $D$4=2, AQ26*100, AQ26), "") | Z26: =ROWS($Z$11:Z26) -> 16 | AA26: {=INDEX(code!$E$2:$K$72,시가평가Matrix!$Z26,$D$3)} -> BONDAVG17 | AB26: {=IF( OR($AA26=0,AS26=0), "", _xll.IMDP("IR",$AA26,E$6,$C$8) )} -> 3.411 | AC26: {=IF( OR($AA26=0,AT26=0), "", _xll.IMDP("IR",$AA26,F$6,$C$8) )} -> 3.394 | AD26: {=IF( OR($AA26=0,AU26=0), "", _xll.IMDP("IR",$AA26,G$6,$C$8) )} -> 3.316 | AE26: {=IF( OR($AA26=0,AV26=0), "", _xll.IMDP("IR",$AA26,H$6,$C$8) )} -> 3.274 | AF26: {=IF( OR($AA26=0,AW26=0), "", _xll.IMDP("IR",$AA26,I$6,$C$8) )} -> 3.24 | AG26: {=IF( OR($AA26=0,AX26=0), "", _xll.IMDP("IR",$AA26,J$6,$C$8) )} -> 3.198 | AH26: {=IF( OR($AA26=0,AY26=0), "", _xll.IMDP("IR",$AA26,K$6,$C$8) )} -> 3.152 | AI26: {=IF( OR($AA26=0,AZ26=0), "", _xll.IMDP("IR",$AA26,L$6,$C$8) )} -> 3.128 | ... AQ26: {=IF( OR($AA26=0,BH26=0), "", _xll.IMDP("IR",$AA26,T$6,$C$8) )} | AS26: {=_xll.IMDP("IR",$AA26,E$5,$C$8)} -> 3.411 | AT26: {=_xll.IMDP("IR",$AA26,F$5,$C$8)} -> 3.394 | AU26: {=_xll.IMDP("IR",$AA26,G$5,$C$8)} -> 3.316 | AV26: {=_xll.IMDP("IR",$AA26,H$5,$C$8)} -> 3.274 | AW26: {=_xll.IMDP("IR",$AA26,I$5,$C$8)} -> 3.24 | AX26: {=_xll.IMDP("IR",$AA26,J$5,$C$8)} -> 3.198 | AY26: {=_xll.IMDP("IR",$AA26,K$5,$C$8)} -> 3.152 | AZ26: {=_xll.IMDP("IR",$AA26,L$5,$C$8)} -> 3.128 | ... BH26: {=_xll.IMDP("IR",$AA26,T$5,$C$8)} -> 0
D27: AAA(중금_이표) | E27: =IFERROR( IF( $D$4=2, AB27*100, AB27), "") -> 3.418 | F27: =IFERROR( IF( $D$4=2, AC27*100, AC27), "") -> 3.393 | G27: =IFERROR( IF( $D$4=2, AD27*100, AD27), "") -> 3.323 | H27: =IFERROR( IF( $D$4=2, AE27*100, AE27), "") -> 3.284 | I27: =IFERROR( IF( $D$4=2, AF27*100, AF27), "") -> 3.236 | J27: =IFERROR( IF( $D$4=2, AG27*100, AG27), "") -> 3.185 | K27: =IFERROR( IF( $D$4=2, AH27*100, AH27), "") -> 3.127 | L27: =IFERROR( IF( $D$4=2, AI27*100, AI27), "") -> 3.093 | ... T27: =IFERROR( IF( $D$4=2, AQ27*100, AQ27), "") | Z27: =ROWS($Z$11:Z27) -> 17 | AA27: {=INDEX(code!$E$2:$K$72,시가평가Matrix!$Z27,$D$3)} -> BONDAVG18 | AB27: {=IF( OR($AA27=0,AS27=0), "", _xll.IMDP("IR",$AA27,E$6,$C$8) )} -> 3.418 | AC27: {=IF( OR($AA27=0,AT27=0), "", _xll.IMDP("IR",$AA27,F$6,$C$8) )} -> 3.393 | AD27: {=IF( OR($AA27=0,AU27=0), "", _xll.IMDP("IR",$AA27,G$6,$C$8) )} -> 3.323 | AE27: {=IF( OR($AA27=0,AV27=0), "", _xll.IMDP("IR",$AA27,H$6,$C$8) )} -> 3.284 | AF27: {=IF( OR($AA27=0,AW27=0), "", _xll.IMDP("IR",$AA27,I$6,$C$8) )} -> 3.236 | AG27: {=IF( OR($AA27=0,AX27=0), "", _xll.IMDP("IR",$AA27,J$6,$C$8) )} -> 3.185 | AH27: {=IF( OR($AA27=0,AY27=0), "", _xll.IMDP("IR",$AA27,K$6,$C$8) )} -> 3.127 | AI27: {=IF( OR($AA27=0,AZ27=0), "", _xll.IMDP("IR",$AA27,L$6,$C$8) )} -> 3.093 | ... AQ27: {=IF( OR($AA27=0,BH27=0), "", _xll.IMDP("IR",$AA27,T$6,$C$8) )} | AS27: {=_xll.IMDP("IR",$AA27,E$5,$C$8)} -> 3.418 | AT27: {=_xll.IMDP("IR",$AA27,F$5,$C$8)} -> 3.393 | AU27: {=_xll.IMDP("IR",$AA27,G$5,$C$8)} -> 3.323 | AV27: {=_xll.IMDP("IR",$AA27,H$5,$C$8)} -> 3.284 | AW27: {=_xll.IMDP("IR",$AA27,I$5,$C$8)} -> 3.236 | AX27: {=_xll.IMDP("IR",$AA27,J$5,$C$8)} -> 3.185 | AY27: {=_xll.IMDP("IR",$AA27,K$5,$C$8)} -> 3.127 | AZ27: {=_xll.IMDP("IR",$AA27,L$5,$C$8)} -> 3.093 | ... BH27: {=_xll.IMDP("IR",$AA27,T$5,$C$8)} -> 0
D28: AAA(중금-할인) | E28: =IFERROR( IF( $D$4=2, AB28*100, AB28), "") -> 3.411 | F28: =IFERROR( IF( $D$4=2, AC28*100, AC28), "") -> 3.394 | G28: =IFERROR( IF( $D$4=2, AD28*100, AD28), "") -> 3.316 | H28: =IFERROR( IF( $D$4=2, AE28*100, AE28), "") -> 3.274 | I28: =IFERROR( IF( $D$4=2, AF28*100, AF28), "") -> 3.24 | J28: =IFERROR( IF( $D$4=2, AG28*100, AG28), "") -> 3.198 | K28: =IFERROR( IF( $D$4=2, AH28*100, AH28), "") -> 3.152 | L28: =IFERROR( IF( $D$4=2, AI28*100, AI28), "") -> 3.128 | ... T28: =IFERROR( IF( $D$4=2, AQ28*100, AQ28), "") | Z28: =ROWS($Z$11:Z28) -> 18 | AA28: {=INDEX(code!$E$2:$K$72,시가평가Matrix!$Z28,$D$3)} -> BONDAVG19 | AB28: {=IF( OR($AA28=0,AS28=0), "", _xll.IMDP("IR",$AA28,E$6,$C$8) )} -> 3.411 | AC28: {=IF( OR($AA28=0,AT28=0), "", _xll.IMDP("IR",$AA28,F$6,$C$8) )} -> 3.394 | AD28: {=IF( OR($AA28=0,AU28=0), "", _xll.IMDP("IR",$AA28,G$6,$C$8) )} -> 3.316 | AE28: {=IF( OR($AA28=0,AV28=0), "", _xll.IMDP("IR",$AA28,H$6,$C$8) )} -> 3.274 | AF28: {=IF( OR($AA28=0,AW28=0), "", _xll.IMDP("IR",$AA28,I$6,$C$8) )} -> 3.24 | AG28: {=IF( OR($AA28=0,AX28=0), "", _xll.IMDP("IR",$AA28,J$6,$C$8) )} -> 3.198 | AH28: {=IF( OR($AA28=0,AY28=0), "", _xll.IMDP("IR",$AA28,K$6,$C$8) )} -> 3.152 | AI28: {=IF( OR($AA28=0,AZ28=0), "", _xll.IMDP("IR",$AA28,L$6,$C$8) )} -> 3.128 | ... AQ28: {=IF( OR($AA28=0,BH28=0), "", _xll.IMDP("IR",$AA28,T$6,$C$8) )} | AS28: {=_xll.IMDP("IR",$AA28,E$5,$C$8)} -> 3.411 | AT28: {=_xll.IMDP("IR",$AA28,F$5,$C$8)} -> 3.394 | AU28: {=_xll.IMDP("IR",$AA28,G$5,$C$8)} -> 3.316 | AV28: {=_xll.IMDP("IR",$AA28,H$5,$C$8)} -> 3.274 | AW28: {=_xll.IMDP("IR",$AA28,I$5,$C$8)} -> 3.24 | AX28: {=_xll.IMDP("IR",$AA28,J$5,$C$8)} -> 3.198 | AY28: {=_xll.IMDP("IR",$AA28,K$5,$C$8)} -> 3.152 | AZ28: {=_xll.IMDP("IR",$AA28,L$5,$C$8)} -> 3.128 | ... BH28: {=_xll.IMDP("IR",$AA28,T$5,$C$8)} -> 0
D29: AAA | E29: =IFERROR( IF( $D$4=2, AB29*100, AB29), "") -> 3.436 | F29: =IFERROR( IF( $D$4=2, AC29*100, AC29), "") -> 3.42 | G29: =IFERROR( IF( $D$4=2, AD29*100, AD29), "") -> 3.35 | H29: =IFERROR( IF( $D$4=2, AE29*100, AE29), "") -> 3.311 | I29: =IFERROR( IF( $D$4=2, AF29*100, AF29), "") -> 3.259 | J29: =IFERROR( IF( $D$4=2, AG29*100, AG29), "") -> 3.227 | K29: =IFERROR( IF( $D$4=2, AH29*100, AH29), "") -> 3.211 | L29: =IFERROR( IF( $D$4=2, AI29*100, AI29), "") -> 3.211 | ... T29: =IFERROR( IF( $D$4=2, AQ29*100, AQ29), "") | Z29: =ROWS($Z$11:Z29) -> 19 | AA29: {=INDEX(code!$E$2:$K$72,시가평가Matrix!$Z29,$D$3)} -> BONDAVG20 | AB29: {=IF( OR($AA29=0,AS29=0), "", _xll.IMDP("IR",$AA29,E$6,$C$8) )} -> 3.436 | AC29: {=IF( OR($AA29=0,AT29=0), "", _xll.IMDP("IR",$AA29,F$6,$C$8) )} -> 3.42 | AD29: {=IF( OR($AA29=0,AU29=0), "", _xll.IMDP("IR",$AA29,G$6,$C$8) )} -> 3.35 | AE29: {=IF( OR($AA29=0,AV29=0), "", _xll.IMDP("IR",$AA29,H$6,$C$8) )} -> 3.311 | AF29: {=IF( OR($AA29=0,AW29=0), "", _xll.IMDP("IR",$AA29,I$6,$C$8) )} -> 3.259 | AG29: {=IF( OR($AA29=0,AX29=0), "", _xll.IMDP("IR",$AA29,J$6,$C$8) )} -> 3.227 | AH29: {=IF( OR($AA29=0,AY29=0), "", _xll.IMDP("IR",$AA29,K$6,$C$8) )} -> 3.211 | AI29: {=IF( OR($AA29=0,AZ29=0), "", _xll.IMDP("IR",$AA29,L$6,$C$8) )} -> 3.211 | ... AQ29: {=IF( OR($AA29=0,BH29=0), "", _xll.IMDP("IR",$AA29,T$6,$C$8) )} | AS29: {=_xll.IMDP("IR",$AA29,E$5,$C$8)} -> 3.436 | AT29: {=_xll.IMDP("IR",$AA29,F$5,$C$8)} -> 3.42 | AU29: {=_xll.IMDP("IR",$AA29,G$5,$C$8)} -> 3.35 | AV29: {=_xll.IMDP("IR",$AA29,H$5,$C$8)} -> 3.311 | AW29: {=_xll.IMDP("IR",$AA29,I$5,$C$8)} -> 3.259 | AX29: {=_xll.IMDP("IR",$AA29,J$5,$C$8)} -> 3.227 | AY29: {=_xll.IMDP("IR",$AA29,K$5,$C$8)} -> 3.211 | AZ29: {=_xll.IMDP("IR",$AA29,L$5,$C$8)} -> 3.211 | ... BH29: {=_xll.IMDP("IR",$AA29,T$5,$C$8)} -> 0
D30: AA+ | E30: =IFERROR( IF( $D$4=2, AB30*100, AB30), "") -> 3.452 | F30: =IFERROR( IF( $D$4=2, AC30*100, AC30), "") -> 3.439 | G30: =IFERROR( IF( $D$4=2, AD30*100, AD30), "") -> 3.392 | H30: =IFERROR( IF( $D$4=2, AE30*100, AE30), "") -> 3.374 | I30: =IFERROR( IF( $D$4=2, AF30*100, AF30), "") -> 3.36 | J30: =IFERROR( IF( $D$4=2, AG30*100, AG30), "") -> 3.328 | K30: =IFERROR( IF( $D$4=2, AH30*100, AH30), "") -> 3.31 | L30: =IFERROR( IF( $D$4=2, AI30*100, AI30), "") -> 3.303 | ... T30: =IFERROR( IF( $D$4=2, AQ30*100, AQ30), "") | Z30: =ROWS($Z$11:Z30) -> 20 | AA30: {=INDEX(code!$E$2:$K$72,시가평가Matrix!$Z30,$D$3)} -> BONDAVG21 | AB30: {=IF( OR($AA30=0,AS30=0), "", _xll.IMDP("IR",$AA30,E$6,$C$8) )} -> 3.452 | AC30: {=IF( OR($AA30=0,AT30=0), "", _xll.IMDP("IR",$AA30,F$6,$C$8) )} -> 3.439 | AD30: {=IF( OR($AA30=0,AU30=0), "", _xll.IMDP("IR",$AA30,G$6,$C$8) )} -> 3.392 | AE30: {=IF( OR($AA30=0,AV30=0), "", _xll.IMDP("IR",$AA30,H$6,$C$8) )} -> 3.374 | AF30: {=IF( OR($AA30=0,AW30=0), "", _xll.IMDP("IR",$AA30,I$6,$C$8) )} -> 3.36 | AG30: {=IF( OR($AA30=0,AX30=0), "", _xll.IMDP("IR",$AA30,J$6,$C$8) )} -> 3.328 | AH30: {=IF( OR($AA30=0,AY30=0), "", _xll.IMDP("IR",$AA30,K$6,$C$8) )} -> 3.31 | AI30: {=IF( OR($AA30=0,AZ30=0), "", _xll.IMDP("IR",$AA30,L$6,$C$8) )} -> 3.303 | ... AQ30: {=IF( OR($AA30=0,BH30=0), "", _xll.IMDP("IR",$AA30,T$6,$C$8) )} | AS30: {=_xll.IMDP("IR",$AA30,E$5,$C$8)} -> 3.452 | AT30: {=_xll.IMDP("IR",$AA30,F$5,$C$8)} -> 3.439 | AU30: {=_xll.IMDP("IR",$AA30,G$5,$C$8)} -> 3.392 | AV30: {=_xll.IMDP("IR",$AA30,H$5,$C$8)} -> 3.374 | AW30: {=_xll.IMDP("IR",$AA30,I$5,$C$8)} -> 3.36 | AX30: {=_xll.IMDP("IR",$AA30,J$5,$C$8)} -> 3.328 | AY30: {=_xll.IMDP("IR",$AA30,K$5,$C$8)} -> 3.31 | AZ30: {=_xll.IMDP("IR",$AA30,L$5,$C$8)} -> 3.303 | ... BH30: {=_xll.IMDP("IR",$AA30,T$5,$C$8)} -> 0
D31: AA0 | E31: =IFERROR( IF( $D$4=2, AB31*100, AB31), "") -> 3.624 | F31: =IFERROR( IF( $D$4=2, AC31*100, AC31), "") -> 3.621 | G31: =IFERROR( IF( $D$4=2, AD31*100, AD31), "") -> 3.567 | H31: =IFERROR( IF( $D$4=2, AE31*100, AE31), "") -> 3.56 | I31: =IFERROR( IF( $D$4=2, AF31*100, AF31), "") -> 3.555 | J31: =IFERROR( IF( $D$4=2, AG31*100, AG31), "") -> 3.553 | K31: =IFERROR( IF( $D$4=2, AH31*100, AH31), "") -> 3.557 | L31: =IFERROR( IF( $D$4=2, AI31*100, AI31), "") -> 3.552 | ... T31: =IFERROR( IF( $D$4=2, AQ31*100, AQ31), "") | Z31: =ROWS($Z$11:Z31) -> 21 | AA31: {=INDEX(code!$E$2:$K$72,시가평가Matrix!$Z31,$D$3)} -> BONDAVG22 | AB31: {=IF( OR($AA31=0,AS31=0), "", _xll.IMDP("IR",$AA31,E$6,$C$8) )} -> 3.624 | AC31: {=IF( OR($AA31=0,AT31=0), "", _xll.IMDP("IR",$AA31,F$6,$C$8) )} -> 3.621 | AD31: {=IF( OR($AA31=0,AU31=0), "", _xll.IMDP("IR",$AA31,G$6,$C$8) )} -> 3.567 | AE31: {=IF( OR($AA31=0,AV31=0), "", _xll.IMDP("IR",$AA31,H$6,$C$8) )} -> 3.56 | AF31: {=IF( OR($AA31=0,AW31=0), "", _xll.IMDP("IR",$AA31,I$6,$C$8) )} -> 3.555 | AG31: {=IF( OR($AA31=0,AX31=0), "", _xll.IMDP("IR",$AA31,J$6,$C$8) )} -> 3.553 | AH31: {=IF( OR($AA31=0,AY31=0), "", _xll.IMDP("IR",$AA31,K$6,$C$8) )} -> 3.557 | AI31: {=IF( OR($AA31=0,AZ31=0), "", _xll.IMDP("IR",$AA31,L$6,$C$8) )} -> 3.552 | ... AQ31: {=IF( OR($AA31=0,BH31=0), "", _xll.IMDP("IR",$AA31,T$6,$C$8) )} | AS31: {=_xll.IMDP("IR",$AA31,E$5,$C$8)} -> 3.624 | AT31: {=_xll.IMDP("IR",$AA31,F$5,$C$8)} -> 3.621 | AU31: {=_xll.IMDP("IR",$AA31,G$5,$C$8)} -> 3.567 | AV31: {=_xll.IMDP("IR",$AA31,H$5,$C$8)} -> 3.56 | AW31: {=_xll.IMDP("IR",$AA31,I$5,$C$8)} -> 3.555 | AX31: {=_xll.IMDP("IR",$AA31,J$5,$C$8)} -> 3.553 | AY31: {=_xll.IMDP("IR",$AA31,K$5,$C$8)} -> 3.557 | AZ31: {=_xll.IMDP("IR",$AA31,L$5,$C$8)} -> 3.552 | ... BH31: {=_xll.IMDP("IR",$AA31,T$5,$C$8)} -> 0
D32: AA- | E32: =IFERROR( IF( $D$4=2, AB32*100, AB32), "") -> 3.747 | F32: =IFERROR( IF( $D$4=2, AC32*100, AC32), "") -> 3.828 | G32: =IFERROR( IF( $D$4=2, AD32*100, AD32), "") -> 3.812 | H32: =IFERROR( IF( $D$4=2, AE32*100, AE32), "") -> 3.818 | I32: =IFERROR( IF( $D$4=2, AF32*100, AF32), "") -> 3.811 | J32: =IFERROR( IF( $D$4=2, AG32*100, AG32), "") -> 3.805 | K32: =IFERROR( IF( $D$4=2, AH32*100, AH32), "") -> 3.799 | L32: =IFERROR( IF( $D$4=2, AI32*100, AI32), "") -> 3.793 | ... T32: =IFERROR( IF( $D$4=2, AQ32*100, AQ32), "") | Z32: =ROWS($Z$11:Z32) -> 22 | AA32: {=INDEX(code!$E$2:$K$72,시가평가Matrix!$Z32,$D$3)} -> BONDAVG23 | AB32: {=IF( OR($AA32=0,AS32=0), "", _xll.IMDP("IR",$AA32,E$6,$C$8) )} -> 3.747 | AC32: {=IF( OR($AA32=0,AT32=0), "", _xll.IMDP("IR",$AA32,F$6,$C$8) )} -> 3.828 | AD32: {=IF( OR($AA32=0,AU32=0), "", _xll.IMDP("IR",$AA32,G$6,$C$8) )} -> 3.812 | AE32: {=IF( OR($AA32=0,AV32=0), "", _xll.IMDP("IR",$AA32,H$6,$C$8) )} -> 3.818 | AF32: {=IF( OR($AA32=0,AW32=0), "", _xll.IMDP("IR",$AA32,I$6,$C$8) )} -> 3.811 | AG32: {=IF( OR($AA32=0,AX32=0), "", _xll.IMDP("IR",$AA32,J$6,$C$8) )} -> 3.805 | AH32: {=IF( OR($AA32=0,AY32=0), "", _xll.IMDP("IR",$AA32,K$6,$C$8) )} -> 3.799 | AI32: {=IF( OR($AA32=0,AZ32=0), "", _xll.IMDP("IR",$AA32,L$6,$C$8) )} -> 3.793 | ... AQ32: {=IF( OR($AA32=0,BH32=0), "", _xll.IMDP("IR",$AA32,T$6,$C$8) )} | AS32: {=_xll.IMDP("IR",$AA32,E$5,$C$8)} -> 3.747 | AT32: {=_xll.IMDP("IR",$AA32,F$5,$C$8)} -> 3.828 | AU32: {=_xll.IMDP("IR",$AA32,G$5,$C$8)} -> 3.812 | AV32: {=_xll.IMDP("IR",$AA32,H$5,$C$8)} -> 3.818 | AW32: {=_xll.IMDP("IR",$AA32,I$5,$C$8)} -> 3.811 | AX32: {=_xll.IMDP("IR",$AA32,J$5,$C$8)} -> 3.805 | AY32: {=_xll.IMDP("IR",$AA32,K$5,$C$8)} -> 3.799 | AZ32: {=_xll.IMDP("IR",$AA32,L$5,$C$8)} -> 3.793 | ... BH32: {=_xll.IMDP("IR",$AA32,T$5,$C$8)} -> 0
D33: A+ | E33: =IFERROR( IF( $D$4=2, AB33*100, AB33), "") -> 3.864 | F33: =IFERROR( IF( $D$4=2, AC33*100, AC33), "") -> 3.919 | G33: =IFERROR( IF( $D$4=2, AD33*100, AD33), "") -> 3.903 | H33: =IFERROR( IF( $D$4=2, AE33*100, AE33), "") -> 3.914 | I33: =IFERROR( IF( $D$4=2, AF33*100, AF33), "") -> 3.922 | J33: =IFERROR( IF( $D$4=2, AG33*100, AG33), "") -> 3.922 | K33: =IFERROR( IF( $D$4=2, AH33*100, AH33), "") -> 3.92 | L33: =IFERROR( IF( $D$4=2, AI33*100, AI33), "") -> 3.917 | ... T33: =IFERROR( IF( $D$4=2, AQ33*100, AQ33), "") | Z33: =ROWS($Z$11:Z33) -> 23 | AA33: {=INDEX(code!$E$2:$K$72,시가평가Matrix!$Z33,$D$3)} -> BONDAVG24 | AB33: {=IF( OR($AA33=0,AS33=0), "", _xll.IMDP("IR",$AA33,E$6,$C$8) )} -> 3.864 | AC33: {=IF( OR($AA33=0,AT33=0), "", _xll.IMDP("IR",$AA33,F$6,$C$8) )} -> 3.919 | AD33: {=IF( OR($AA33=0,AU33=0), "", _xll.IMDP("IR",$AA33,G$6,$C$8) )} -> 3.903 | AE33: {=IF( OR($AA33=0,AV33=0), "", _xll.IMDP("IR",$AA33,H$6,$C$8) )} -> 3.914 | AF33: {=IF( OR($AA33=0,AW33=0), "", _xll.IMDP("IR",$AA33,I$6,$C$8) )} -> 3.922 | AG33: {=IF( OR($AA33=0,AX33=0), "", _xll.IMDP("IR",$AA33,J$6,$C$8) )} -> 3.922 | AH33: {=IF( OR($AA33=0,AY33=0), "", _xll.IMDP("IR",$AA33,K$6,$C$8) )} -> 3.92 | AI33: {=IF( OR($AA33=0,AZ33=0), "", _xll.IMDP("IR",$AA33,L$6,$C$8) )} -> 3.917 | ... AQ33: {=IF( OR($AA33=0,BH33=0), "", _xll.IMDP("IR",$AA33,T$6,$C$8) )} | AS33: {=_xll.IMDP("IR",$AA33,E$5,$C$8)} -> 3.864 | AT33: {=_xll.IMDP("IR",$AA33,F$5,$C$8)} -> 3.919 | AU33: {=_xll.IMDP("IR",$AA33,G$5,$C$8)} -> 3.903 | AV33: {=_xll.IMDP("IR",$AA33,H$5,$C$8)} -> 3.914 | AW33: {=_xll.IMDP("IR",$AA33,I$5,$C$8)} -> 3.922 | AX33: {=_xll.IMDP("IR",$AA33,J$5,$C$8)} -> 3.922 | AY33: {=_xll.IMDP("IR",$AA33,K$5,$C$8)} -> 3.92 | AZ33: {=_xll.IMDP("IR",$AA33,L$5,$C$8)} -> 3.917 | ... BH33: {=_xll.IMDP("IR",$AA33,T$5,$C$8)} -> 0
D34: A0 | E34: =IFERROR( IF( $D$4=2, AB34*100, AB34), "") -> 3.952 | F34: =IFERROR( IF( $D$4=2, AC34*100, AC34), "") -> 3.99 | G34: =IFERROR( IF( $D$4=2, AD34*100, AD34), "") -> 3.991 | H34: =IFERROR( IF( $D$4=2, AE34*100, AE34), "") -> 4.005 | I34: =IFERROR( IF( $D$4=2, AF34*100, AF34), "") -> 4.012 | J34: =IFERROR( IF( $D$4=2, AG34*100, AG34), "") -> 4.021 | K34: =IFERROR( IF( $D$4=2, AH34*100, AH34), "") -> 4.02 | L34: =IFERROR( IF( $D$4=2, AI34*100, AI34), "") -> 4.019 | ... T34: =IFERROR( IF( $D$4=2, AQ34*100, AQ34), "") | Z34: =ROWS($Z$11:Z34) -> 24 | AA34: {=INDEX(code!$E$2:$K$72,시가평가Matrix!$Z34,$D$3)} -> BONDAVG25 | AB34: {=IF( OR($AA34=0,AS34=0), "", _xll.IMDP("IR",$AA34,E$6,$C$8) )} -> 3.952 | AC34: {=IF( OR($AA34=0,AT34=0), "", _xll.IMDP("IR",$AA34,F$6,$C$8) )} -> 3.99 | AD34: {=IF( OR($AA34=0,AU34=0), "", _xll.IMDP("IR",$AA34,G$6,$C$8) )} -> 3.991 | AE34: {=IF( OR($AA34=0,AV34=0), "", _xll.IMDP("IR",$AA34,H$6,$C$8) )} -> 4.005 | AF34: {=IF( OR($AA34=0,AW34=0), "", _xll.IMDP("IR",$AA34,I$6,$C$8) )} -> 4.012 | AG34: {=IF( OR($AA34=0,AX34=0), "", _xll.IMDP("IR",$AA34,J$6,$C$8) )} -> 4.021 | AH34: {=IF( OR($AA34=0,AY34=0), "", _xll.IMDP("IR",$AA34,K$6,$C$8) )} -> 4.02 | AI34: {=IF( OR($AA34=0,AZ34=0), "", _xll.IMDP("IR",$AA34,L$6,$C$8) )} -> 4.019 | ... AQ34: {=IF( OR($AA34=0,BH34=0), "", _xll.IMDP("IR",$AA34,T$6,$C$8) )} | AS34: {=_xll.IMDP("IR",$AA34,E$5,$C$8)} -> 3.952 | AT34: {=_xll.IMDP("IR",$AA34,F$5,$C$8)} -> 3.99 | AU34: {=_xll.IMDP("IR",$AA34,G$5,$C$8)} -> 3.991 | AV34: {=_xll.IMDP("IR",$AA34,H$5,$C$8)} -> 4.005 | AW34: {=_xll.IMDP("IR",$AA34,I$5,$C$8)} -> 4.012 | AX34: {=_xll.IMDP("IR",$AA34,J$5,$C$8)} -> 4.021 | AY34: {=_xll.IMDP("IR",$AA34,K$5,$C$8)} -> 4.02 | AZ34: {=_xll.IMDP("IR",$AA34,L$5,$C$8)} -> 4.019 | ... BH34: {=_xll.IMDP("IR",$AA34,T$5,$C$8)} -> 0
D35: A- | E35: =IFERROR( IF( $D$4=2, AB35*100, AB35), "") -> 4.037 | F35: =IFERROR( IF( $D$4=2, AC35*100, AC35), "") -> 4.079 | G35: =IFERROR( IF( $D$4=2, AD35*100, AD35), "") -> 4.079 | H35: =IFERROR( IF( $D$4=2, AE35*100, AE35), "") -> 4.095 | I35: =IFERROR( IF( $D$4=2, AF35*100, AF35), "") -> 4.099 | J35: =IFERROR( IF( $D$4=2, AG35*100, AG35), "") -> 4.111 | K35: =IFERROR( IF( $D$4=2, AH35*100, AH35), "") -> 4.113 | L35: =IFERROR( IF( $D$4=2, AI35*100, AI35), "") -> 4.111 | ... T35: =IFERROR( IF( $D$4=2, AQ35*100, AQ35), "") | Z35: =ROWS($Z$11:Z35) -> 25 | AA35: {=INDEX(code!$E$2:$K$72,시가평가Matrix!$Z35,$D$3)} -> BONDAVG26 | AB35: {=IF( OR($AA35=0,AS35=0), "", _xll.IMDP("IR",$AA35,E$6,$C$8) )} -> 4.037 | AC35: {=IF( OR($AA35=0,AT35=0), "", _xll.IMDP("IR",$AA35,F$6,$C$8) )} -> 4.079 | AD35: {=IF( OR($AA35=0,AU35=0), "", _xll.IMDP("IR",$AA35,G$6,$C$8) )} -> 4.079 | AE35: {=IF( OR($AA35=0,AV35=0), "", _xll.IMDP("IR",$AA35,H$6,$C$8) )} -> 4.095 | AF35: {=IF( OR($AA35=0,AW35=0), "", _xll.IMDP("IR",$AA35,I$6,$C$8) )} -> 4.099 | AG35: {=IF( OR($AA35=0,AX35=0), "", _xll.IMDP("IR",$AA35,J$6,$C$8) )} -> 4.111 | AH35: {=IF( OR($AA35=0,AY35=0), "", _xll.IMDP("IR",$AA35,K$6,$C$8) )} -> 4.113 | AI35: {=IF( OR($AA35=0,AZ35=0), "", _xll.IMDP("IR",$AA35,L$6,$C$8) )} -> 4.111 | ... AQ35: {=IF( OR($AA35=0,BH35=0), "", _xll.IMDP("IR",$AA35,T$6,$C$8) )} | AS35: {=_xll.IMDP("IR",$AA35,E$5,$C$8)} -> 4.037 | AT35: {=_xll.IMDP("IR",$AA35,F$5,$C$8)} -> 4.079 | AU35: {=_xll.IMDP("IR",$AA35,G$5,$C$8)} -> 4.079 | AV35: {=_xll.IMDP("IR",$AA35,H$5,$C$8)} -> 4.095 | AW35: {=_xll.IMDP("IR",$AA35,I$5,$C$8)} -> 4.099 | AX35: {=_xll.IMDP("IR",$AA35,J$5,$C$8)} -> 4.111 | AY35: {=_xll.IMDP("IR",$AA35,K$5,$C$8)} -> 4.113 | AZ35: {=_xll.IMDP("IR",$AA35,L$5,$C$8)} -> 4.111 | ... BH35: {=_xll.IMDP("IR",$AA35,T$5,$C$8)} -> 0
C36: 카드채 | D36: AA+ | E36: =IFERROR( IF( $D$4=2, AB36*100, AB36), "") -> 3.433 | F36: =IFERROR( IF( $D$4=2, AC36*100, AC36), "") -> 3.42 | G36: =IFERROR( IF( $D$4=2, AD36*100, AD36), "") -> 3.386 | H36: =IFERROR( IF( $D$4=2, AE36*100, AE36), "") -> 3.396 | I36: =IFERROR( IF( $D$4=2, AF36*100, AF36), "") -> 3.447 | J36: =IFERROR( IF( $D$4=2, AG36*100, AG36), "") -> 3.418 | K36: =IFERROR( IF( $D$4=2, AH36*100, AH36), "") -> 3.375 | L36: =IFERROR( IF( $D$4=2, AI36*100, AI36), "") -> 3.361 | ... T36: =IFERROR( IF( $D$4=2, AQ36*100, AQ36), "") | Z36: =ROWS($Z$11:Z36) -> 26 | AA36: {=INDEX(code!$E$2:$K$72,시가평가Matrix!$Z36,$D$3)} -> BONDAVG81 | AB36: {=IF( OR($AA36=0,AS36=0), "", _xll.IMDP("IR",$AA36,E$6,$C$8) )} -> 3.433 | AC36: {=IF( OR($AA36=0,AT36=0), "", _xll.IMDP("IR",$AA36,F$6,$C$8) )} -> 3.42 | AD36: {=IF( OR($AA36=0,AU36=0), "", _xll.IMDP("IR",$AA36,G$6,$C$8) )} -> 3.386 | AE36: {=IF( OR($AA36=0,AV36=0), "", _xll.IMDP("IR",$AA36,H$6,$C$8) )} -> 3.396 | AF36: {=IF( OR($AA36=0,AW36=0), "", _xll.IMDP("IR",$AA36,I$6,$C$8) )} -> 3.447 | AG36: {=IF( OR($AA36=0,AX36=0), "", _xll.IMDP("IR",$AA36,J$6,$C$8) )} -> 3.418 | AH36: {=IF( OR($AA36=0,AY36=0), "", _xll.IMDP("IR",$AA36,K$6,$C$8) )} -> 3.375 | AI36: {=IF( OR($AA36=0,AZ36=0), "", _xll.IMDP("IR",$AA36,L$6,$C$8) )} -> 3.361 | ... AQ36: {=IF( OR($AA36=0,BH36=0), "", _xll.IMDP("IR",$AA36,T$6,$C$8) )} | AS36: {=_xll.IMDP("IR",$AA36,E$5,$C$8)} -> 3.433 | AT36: {=_xll.IMDP("IR",$AA36,F$5,$C$8)} -> 3.42 | AU36: {=_xll.IMDP("IR",$AA36,G$5,$C$8)} -> 3.386 | AV36: {=_xll.IMDP("IR",$AA36,H$5,$C$8)} -> 3.396 | AW36: {=_xll.IMDP("IR",$AA36,I$5,$C$8)} -> 3.447 | AX36: {=_xll.IMDP("IR",$AA36,J$5,$C$8)} -> 3.418 | AY36: {=_xll.IMDP("IR",$AA36,K$5,$C$8)} -> 3.375 | AZ36: {=_xll.IMDP("IR",$AA36,L$5,$C$8)} -> 3.361 | ... BH36: {=_xll.IMDP("IR",$AA36,T$5,$C$8)} -> 0
D37: AA0 | E37: =IFERROR( IF( $D$4=2, AB37*100, AB37), "") -> 3.462 | F37: =IFERROR( IF( $D$4=2, AC37*100, AC37), "") -> 3.445 | G37: =IFERROR( IF( $D$4=2, AD37*100, AD37), "") -> 3.413 | H37: =IFERROR( IF( $D$4=2, AE37*100, AE37), "") -> 3.429 | I37: =IFERROR( IF( $D$4=2, AF37*100, AF37), "") -> 3.488 | J37: =IFERROR( IF( $D$4=2, AG37*100, AG37), "") -> 3.461 | K37: =IFERROR( IF( $D$4=2, AH37*100, AH37), "") -> 3.43 | L37: =IFERROR( IF( $D$4=2, AI37*100, AI37), "") -> 3.426 | ... T37: =IFERROR( IF( $D$4=2, AQ37*100, AQ37), "") | Z37: =ROWS($Z$11:Z37) -> 27 | AA37: {=INDEX(code!$E$2:$K$72,시가평가Matrix!$Z37,$D$3)} -> BONDAVG27 | AB37: {=IF( OR($AA37=0,AS37=0), "", _xll.IMDP("IR",$AA37,E$6,$C$8) )} -> 3.462 | AC37: {=IF( OR($AA37=0,AT37=0), "", _xll.IMDP("IR",$AA37,F$6,$C$8) )} -> 3.445 | AD37: {=IF( OR($AA37=0,AU37=0), "", _xll.IMDP("IR",$AA37,G$6,$C$8) )} -> 3.413 | AE37: {=IF( OR($AA37=0,AV37=0), "", _xll.IMDP("IR",$AA37,H$6,$C$8) )} -> 3.429 | AF37: {=IF( OR($AA37=0,AW37=0), "", _xll.IMDP("IR",$AA37,I$6,$C$8) )} -> 3.488 | AG37: {=IF( OR($AA37=0,AX37=0), "", _xll.IMDP("IR",$AA37,J$6,$C$8) )} -> 3.461 | AH37: {=IF( OR($AA37=0,AY37=0), "", _xll.IMDP("IR",$AA37,K$6,$C$8) )} -> 3.43 | AI37: {=IF( OR($AA37=0,AZ37=0), "", _xll.IMDP("IR",$AA37,L$6,$C$8) )} -> 3.426 | ... AQ37: {=IF( OR($AA37=0,BH37=0), "", _xll.IMDP("IR",$AA37,T$6,$C$8) )} | AS37: {=_xll.IMDP("IR",$AA37,E$5,$C$8)} -> 3.462 | AT37: {=_xll.IMDP("IR",$AA37,F$5,$C$8)} -> 3.445 | AU37: {=_xll.IMDP("IR",$AA37,G$5,$C$8)} -> 3.413 | AV37: {=_xll.IMDP("IR",$AA37,H$5,$C$8)} -> 3.429 | AW37: {=_xll.IMDP("IR",$AA37,I$5,$C$8)} -> 3.488 | AX37: {=_xll.IMDP("IR",$AA37,J$5,$C$8)} -> 3.461 | AY37: {=_xll.IMDP("IR",$AA37,K$5,$C$8)} -> 3.43 | AZ37: {=_xll.IMDP("IR",$AA37,L$5,$C$8)} -> 3.426 | ... BH37: {=_xll.IMDP("IR",$AA37,T$5,$C$8)} -> 0
D38: AA- | E38: =IFERROR( IF( $D$4=2, AB38*100, AB38), "") -> 3.486 | F38: =IFERROR( IF( $D$4=2, AC38*100, AC38), "") -> 3.476 | G38: =IFERROR( IF( $D$4=2, AD38*100, AD38), "") -> 3.468 | H38: =IFERROR( IF( $D$4=2, AE38*100, AE38), "") -> 3.5 | I38: =IFERROR( IF( $D$4=2, AF38*100, AF38), "") -> 3.554 | J38: =IFERROR( IF( $D$4=2, AG38*100, AG38), "") -> 3.555 | K38: =IFERROR( IF( $D$4=2, AH38*100, AH38), "") -> 3.546 | L38: =IFERROR( IF( $D$4=2, AI38*100, AI38), "") -> 3.544 | ... T38: =IFERROR( IF( $D$4=2, AQ38*100, AQ38), "") | Z38: =ROWS($Z$11:Z38) -> 28 | AA38: {=INDEX(code!$E$2:$K$72,시가평가Matrix!$Z38,$D$3)} -> BONDAVG28 | AB38: {=IF( OR($AA38=0,AS38=0), "", _xll.IMDP("IR",$AA38,E$6,$C$8) )} -> 3.486 | AC38: {=IF( OR($AA38=0,AT38=0), "", _xll.IMDP("IR",$AA38,F$6,$C$8) )} -> 3.476 | AD38: {=IF( OR($AA38=0,AU38=0), "", _xll.IMDP("IR",$AA38,G$6,$C$8) )} -> 3.468 | AE38: {=IF( OR($AA38=0,AV38=0), "", _xll.IMDP("IR",$AA38,H$6,$C$8) )} -> 3.5 | AF38: {=IF( OR($AA38=0,AW38=0), "", _xll.IMDP("IR",$AA38,I$6,$C$8) )} -> 3.554 | AG38: {=IF( OR($AA38=0,AX38=0), "", _xll.IMDP("IR",$AA38,J$6,$C$8) )} -> 3.555 | AH38: {=IF( OR($AA38=0,AY38=0), "", _xll.IMDP("IR",$AA38,K$6,$C$8) )} -> 3.546 | AI38: {=IF( OR($AA38=0,AZ38=0), "", _xll.IMDP("IR",$AA38,L$6,$C$8) )} -> 3.544 | ... AQ38: {=IF( OR($AA38=0,BH38=0), "", _xll.IMDP("IR",$AA38,T$6,$C$8) )} | AS38: {=_xll.IMDP("IR",$AA38,E$5,$C$8)} -> 3.486 | AT38: {=_xll.IMDP("IR",$AA38,F$5,$C$8)} -> 3.476 | AU38: {=_xll.IMDP("IR",$AA38,G$5,$C$8)} -> 3.468 | AV38: {=_xll.IMDP("IR",$AA38,H$5,$C$8)} -> 3.5 | AW38: {=_xll.IMDP("IR",$AA38,I$5,$C$8)} -> 3.554 | AX38: {=_xll.IMDP("IR",$AA38,J$5,$C$8)} -> 3.555 | AY38: {=_xll.IMDP("IR",$AA38,K$5,$C$8)} -> 3.546 | AZ38: {=_xll.IMDP("IR",$AA38,L$5,$C$8)} -> 3.544 | ... BH38: {=_xll.IMDP("IR",$AA38,T$5,$C$8)} -> 0
D39: A+ | E39: =IFERROR( IF( $D$4=2, AB39*100, AB39), "") -> 4.008 | F39: =IFERROR( IF( $D$4=2, AC39*100, AC39), "") -> 4.276 | G39: =IFERROR( IF( $D$4=2, AD39*100, AD39), "") -> 4.364 | H39: =IFERROR( IF( $D$4=2, AE39*100, AE39), "") -> 4.389 | I39: =IFERROR( IF( $D$4=2, AF39*100, AF39), "") -> 4.427 | J39: =IFERROR( IF( $D$4=2, AG39*100, AG39), "") -> 4.434 | K39: =IFERROR( IF( $D$4=2, AH39*100, AH39), "") -> 4.493 | L39: =IFERROR( IF( $D$4=2, AI39*100, AI39), "") -> 4.566 | ... T39: =IFERROR( IF( $D$4=2, AQ39*100, AQ39), "") | Z39: =ROWS($Z$11:Z39) -> 29 | AA39: {=INDEX(code!$E$2:$K$72,시가평가Matrix!$Z39,$D$3)} -> BONDAVG29 | AB39: {=IF( OR($AA39=0,AS39=0), "", _xll.IMDP("IR",$AA39,E$6,$C$8) )} -> 4.008 | AC39: {=IF( OR($AA39=0,AT39=0), "", _xll.IMDP("IR",$AA39,F$6,$C$8) )} -> 4.276 | AD39: {=IF( OR($AA39=0,AU39=0), "", _xll.IMDP("IR",$AA39,G$6,$C$8) )} -> 4.364 | AE39: {=IF( OR($AA39=0,AV39=0), "", _xll.IMDP("IR",$AA39,H$6,$C$8) )} -> 4.389 | AF39: {=IF( OR($AA39=0,AW39=0), "", _xll.IMDP("IR",$AA39,I$6,$C$8) )} -> 4.427 | AG39: {=IF( OR($AA39=0,AX39=0), "", _xll.IMDP("IR",$AA39,J$6,$C$8) )} -> 4.434 | AH39: {=IF( OR($AA39=0,AY39=0), "", _xll.IMDP("IR",$AA39,K$6,$C$8) )} -> 4.493 | AI39: {=IF( OR($AA39=0,AZ39=0), "", _xll.IMDP("IR",$AA39,L$6,$C$8) )} -> 4.566 | ... AQ39: {=IF( OR($AA39=0,BH39=0), "", _xll.IMDP("IR",$AA39,T$6,$C$8) )} | AS39: {=_xll.IMDP("IR",$AA39,E$5,$C$8)} -> 4.008 | AT39: {=_xll.IMDP("IR",$AA39,F$5,$C$8)} -> 4.276 | AU39: {=_xll.IMDP("IR",$AA39,G$5,$C$8)} -> 4.364 | AV39: {=_xll.IMDP("IR",$AA39,H$5,$C$8)} -> 4.389 | AW39: {=_xll.IMDP("IR",$AA39,I$5,$C$8)} -> 4.427 | AX39: {=_xll.IMDP("IR",$AA39,J$5,$C$8)} -> 4.434 | AY39: {=_xll.IMDP("IR",$AA39,K$5,$C$8)} -> 4.493 | AZ39: {=_xll.IMDP("IR",$AA39,L$5,$C$8)} -> 4.566 | ... BH39: {=_xll.IMDP("IR",$AA39,T$5,$C$8)} -> 0
D40: A0 | E40: =IFERROR( IF( $D$4=2, AB40*100, AB40), "") -> 4.567 | F40: =IFERROR( IF( $D$4=2, AC40*100, AC40), "") -> 4.888 | G40: =IFERROR( IF( $D$4=2, AD40*100, AD40), "") -> 5.031 | H40: =IFERROR( IF( $D$4=2, AE40*100, AE40), "") -> 5.133 | I40: =IFERROR( IF( $D$4=2, AF40*100, AF40), "") -> 5.21 | J40: =IFERROR( IF( $D$4=2, AG40*100, AG40), "") -> 5.259 | K40: =IFERROR( IF( $D$4=2, AH40*100, AH40), "") -> 5.279 | L40: =IFERROR( IF( $D$4=2, AI40*100, AI40), "") -> 5.347 | ... T40: =IFERROR( IF( $D$4=2, AQ40*100, AQ40), "") | Z40: =ROWS($Z$11:Z40) -> 30 | AA40: {=INDEX(code!$E$2:$K$72,시가평가Matrix!$Z40,$D$3)} -> BONDAVG30 | AB40: {=IF( OR($AA40=0,AS40=0), "", _xll.IMDP("IR",$AA40,E$6,$C$8) )} -> 4.567 | AC40: {=IF( OR($AA40=0,AT40=0), "", _xll.IMDP("IR",$AA40,F$6,$C$8) )} -> 4.888 | AD40: {=IF( OR($AA40=0,AU40=0), "", _xll.IMDP("IR",$AA40,G$6,$C$8) )} -> 5.031 | AE40: {=IF( OR($AA40=0,AV40=0), "", _xll.IMDP("IR",$AA40,H$6,$C$8) )} -> 5.133 | AF40: {=IF( OR($AA40=0,AW40=0), "", _xll.IMDP("IR",$AA40,I$6,$C$8) )} -> 5.21 | AG40: {=IF( OR($AA40=0,AX40=0), "", _xll.IMDP("IR",$AA40,J$6,$C$8) )} -> 5.259 | AH40: {=IF( OR($AA40=0,AY40=0), "", _xll.IMDP("IR",$AA40,K$6,$C$8) )} -> 5.279 | AI40: {=IF( OR($AA40=0,AZ40=0), "", _xll.IMDP("IR",$AA40,L$6,$C$8) )} -> 5.347 | ... AQ40: {=IF( OR($AA40=0,BH40=0), "", _xll.IMDP("IR",$AA40,T$6,$C$8) )} | AS40: {=_xll.IMDP("IR",$AA40,E$5,$C$8)} -> 4.567 | AT40: {=_xll.IMDP("IR",$AA40,F$5,$C$8)} -> 4.888 | AU40: {=_xll.IMDP("IR",$AA40,G$5,$C$8)} -> 5.031 | AV40: {=_xll.IMDP("IR",$AA40,H$5,$C$8)} -> 5.133 | AW40: {=_xll.IMDP("IR",$AA40,I$5,$C$8)} -> 5.21 | AX40: {=_xll.IMDP("IR",$AA40,J$5,$C$8)} -> 5.259 | AY40: {=_xll.IMDP("IR",$AA40,K$5,$C$8)} -> 5.279 | AZ40: {=_xll.IMDP("IR",$AA40,L$5,$C$8)} -> 5.347 | ... BH40: {=_xll.IMDP("IR",$AA40,T$5,$C$8)} -> 0
D41: A- | E41: =IFERROR( IF( $D$4=2, AB41*100, AB41), "") -> 5.09 | F41: =IFERROR( IF( $D$4=2, AC41*100, AC41), "") -> 5.521 | G41: =IFERROR( IF( $D$4=2, AD41*100, AD41), "") -> 5.647 | H41: =IFERROR( IF( $D$4=2, AE41*100, AE41), "") -> 5.69 | I41: =IFERROR( IF( $D$4=2, AF41*100, AF41), "") -> 5.763 | J41: =IFERROR( IF( $D$4=2, AG41*100, AG41), "") -> 5.843 | K41: =IFERROR( IF( $D$4=2, AH41*100, AH41), "") -> 5.936 | L41: =IFERROR( IF( $D$4=2, AI41*100, AI41), "") -> 6.024 | ... T41: =IFERROR( IF( $D$4=2, AQ41*100, AQ41), "") | Z41: =ROWS($Z$11:Z41) -> 31 | AA41: {=INDEX(code!$E$2:$K$72,시가평가Matrix!$Z41,$D$3)} -> BONDAVG31 | AB41: {=IF( OR($AA41=0,AS41=0), "", _xll.IMDP("IR",$AA41,E$6,$C$8) )} -> 5.09 | AC41: {=IF( OR($AA41=0,AT41=0), "", _xll.IMDP("IR",$AA41,F$6,$C$8) )} -> 5.521 | AD41: {=IF( OR($AA41=0,AU41=0), "", _xll.IMDP("IR",$AA41,G$6,$C$8) )} -> 5.647 | AE41: {=IF( OR($AA41=0,AV41=0), "", _xll.IMDP("IR",$AA41,H$6,$C$8) )} -> 5.69 | AF41: {=IF( OR($AA41=0,AW41=0), "", _xll.IMDP("IR",$AA41,I$6,$C$8) )} -> 5.763 | AG41: {=IF( OR($AA41=0,AX41=0), "", _xll.IMDP("IR",$AA41,J$6,$C$8) )} -> 5.843 | AH41: {=IF( OR($AA41=0,AY41=0), "", _xll.IMDP("IR",$AA41,K$6,$C$8) )} -> 5.936 | AI41: {=IF( OR($AA41=0,AZ41=0), "", _xll.IMDP("IR",$AA41,L$6,$C$8) )} -> 6.024 | ... AQ41: {=IF( OR($AA41=0,BH41=0), "", _xll.IMDP("IR",$AA41,T$6,$C$8) )} | AS41: {=_xll.IMDP("IR",$AA41,E$5,$C$8)} -> 5.09 | AT41: {=_xll.IMDP("IR",$AA41,F$5,$C$8)} -> 5.521 | AU41: {=_xll.IMDP("IR",$AA41,G$5,$C$8)} -> 5.647 | AV41: {=_xll.IMDP("IR",$AA41,H$5,$C$8)} -> 5.69 | AW41: {=_xll.IMDP("IR",$AA41,I$5,$C$8)} -> 5.763 | AX41: {=_xll.IMDP("IR",$AA41,J$5,$C$8)} -> 5.843 | AY41: {=_xll.IMDP("IR",$AA41,K$5,$C$8)} -> 5.936 | AZ41: {=_xll.IMDP("IR",$AA41,L$5,$C$8)} -> 6.024 | ... BH41: {=_xll.IMDP("IR",$AA41,T$5,$C$8)} -> 0
...

Sheet Yield Curve
B2: Yield Curve
B4: 일자 | C4: =WORKDAY(TODAY(),-1) -> 45520 | D4: 1
C6: 기준 | I6: 상대 | V6: 기준 | AB6: 상대
C7: 3M | D7: 6M | E7: 9M | F7: 1Y | G7: 1.5Y | H7: 2Y | I7: 2.5Y | J7: 3Y | K7: 4Y | L7: 5Y | M7: 7Y | N7: 10Y | O7: 15Y | P7: 20Y | Q7: 30Y | R7: 50Y | V7: 3M | W7: 6M | X7: 9M | Y7: 1Y | Z7: 1.5Y | AA7: 2Y | AB7: 2.5Y | AC7: 3Y | AD7: 4Y | AE7: 5Y | AF7: 7Y | AG7: 10Y | AH7: 15Y | AI7: 20Y | AJ7: 30Y | AK7: 50Y
