Workbook

Sheet 발행사 Term Structure
C2: 발행사 Term structure
D4: 1 | F4: 1
C5: 3사평균 | D5: BONDAVG | E5: 당일 | F5: (당일)
C6: 4사평균 | D6: BONDAV4 | E6: 전일 | F6: (전일)
C7: KAP | D7: BONDKBP | E7: 전일대비 | F7: (전일대비)
C8: KIS | D8: BONDKIS | E8: 국고대비 | F8: (당일)
C9: NICE | D9: BONDNIC | H9: 3월이하(당일) | I9: 6월이하(당일) | J9: 9월이하(당일) | K9: 1년이하(당일) | L9: 1.5년이하(당일) | M9: 2년이하(당일) | N9: 2.5년이하(당일) | O9: 3년이하(당일) | P9: 4년이하(당일) | Q9: 5년이하(당일) | R9: 7년이하(당일) | S9: 10년이하(당일) | T9: 15년이하(당일) | U9: 20년이하(당일) | V9: 30년이하(당일)
C10: FN | D10: BONDFNP | H10: =H$12&INDEX($F$5:$F$8,$F$4,1) -> 3월이하(당일) | I10: =I$12&INDEX($F$5:$F$8,$F$4,1) -> 6월이하(당일) | J10: =J$12&INDEX($F$5:$F$8,$F$4,1) -> 9월이하(당일) | K10: =K$12&INDEX($F$5:$F$8,$F$4,1) -> 1년이하(당일) | L10: =L$12&INDEX($F$5:$F$8,$F$4,1) -> 1.5년이하(당일) | M10: =M$12&INDEX($F$5:$F$8,$F$4,1) -> 2년이하(당일) | N10: =N$12&INDEX($F$5:$F$8,$F$4,1) -> 2.5년이하(당일) | O10: =O$12&INDEX($F$5:$F$8,$F$4,1) -> 3년이하(당일) | ... V10: =V$12&INDEX($F$5:$F$8,$F$4,1) -> 30년이하(당일)
C12: 발행기관코드 | D12: 발행기관명 | E12: 종목코드 | F12: 채권그룹 | G12: =IF($F$4=2, "날짜(전일)", "날짜(당일)") -> 날짜(당일) | H12: 3월이하 | I12: 6월이하 | J12: 9월이하 | K12: 1년이하 | L12: 1.5년이하 | M12: 2년이하 | N12: 2.5년이하 | O12: 3년이하 | P12: 4년이하 | Q12: 5년이하 | R12: 7년이하 | S12: 10년이하 | T12: 15년이하 | U12: 20년이하 | V12: 30년이하
C13: 01 | D13: 국고채권 | E13: =INDEX($D$5:$D$10,$D$4,1)&$C13 -> BONDAVG01 | F13: 국고채권 | G13: =_xll.IMDP("IR",$E13,G$12) -> 20240830 | H13: =_xll.IMDP("IR",$E13,H$9) -> 3.353 | I13: =_xll.IMDP("IR",$E13,I$9) -> 3.216 | J13: =_xll.IMDP("IR",$E13,J$9) -> 3.106 | K13: =_xll.IMDP("IR",$E13,K$9) -> 3.051 | L13: =_xll.IMDP("IR",$E13,L$9) -> 3.064 | M13: =_xll.IMDP("IR",$E13,M$9) -> 3.068 | N13: =_xll.IMDP("IR",$E13,N$9) -> 2.983 | O13: =_xll.IMDP("IR",$E13,O$9) -> 2.955 | ... V13: =_xll.IMDP("IR",$E13,V$9) -> 2.982
B14: 1 | C14: =IFERROR( VLOOKUP( $B14, Sheet1!$M$2:$O$10001, 2,0),"") -> 00001 | D14: =IFERROR( VLOOKUP( $B14, Sheet1!$M$2:$O$10001, 3,0),"") -> 신한은행 | E14: =INDEX($D$5:$D$10,$D$4,1)&$C14 -> BONDAVG00001 | F14: =_xll.IMDP("IR",$E14,F$12) -> 은행채AAA | G14: =_xll.IMDP("IR",$E14,G$12) -> 20240830 | H14: =IFERROR(IF($F$4=4,_xll.IMDP("IR",$E14,H$9)-H$13,_xll.IMDP("IR",$E14,H$10)),"") -> 3.483 | I14: =IFERROR(IF($F$4=4,_xll.IMDP("IR",$E14,I$9)-I$13,_xll.IMDP("IR",$E14,I$10)),"") -> 3.457 | J14: =IFERROR(IF($F$4=4,_xll.IMDP("IR",$E14,J$9)-J$13,_xll.IMDP("IR",$E14,J$10)),"") -> 3.389 | K14: =IFERROR(IF($F$4=4,_xll.IMDP("IR",$E14,K$9)-K$13,_xll.IMDP("IR",$E14,K$10)),"") -> 3.363 | L14: =IFERROR(IF($F$4=4,_xll.IMDP("IR",$E14,L$9)-L$13,_xll.IMDP("IR",$E14,L$10)),"") -> 3.329 | M14: =IFERROR(IF($F$4=4,_xll.IMDP("IR",$E14,M$9)-M$13,_xll.IMDP("IR",$E14,M$10)),"") -> 3.292 | N14: =IFERROR(IF($F$4=4,_xll.IMDP("IR",$E14,N$9)-N$13,_xll.IMDP("IR",$E14,N$10)),"") -> 3.267 | O14: =IFERROR(IF($F$4=4,_xll.IMDP("IR",$E14,O$9)-O$13,_xll.IMDP("IR",$E14,O$10)),"") -> 3.251 | ... V14: =IFERROR(IF($F$4=4,_xll.IMDP("IR",$E14,V$9)-V$13,_xll.IMDP("IR",$E14,V$10)),"")
B15: 2 | C15: =IFERROR( VLOOKUP( $B15, Sheet1!$M$2:$O$10001, 2,0),"") -> 00007 | D15: =IFERROR( VLOOKUP( $B15, Sheet1!$M$2:$O$10001, 3,0),"") -> 삼양홀딩스 | E15: =INDEX($D$5:$D$10,$D$4,1)&$C15 -> BONDAVG00007 | F15: =_xll.IMDP("IR",$E15,F$12) -> 공모/무보증AA- | G15: =_xll.IMDP("IR",$E15,G$12) -> 20240830 | H15: =IFERROR(IF($F$4=4,_xll.IMDP("IR",$E15,H$9)-H$13,_xll.IMDP("IR",$E15,H$10)),"") -> 3.451 | I15: =IFERROR(IF($F$4=4,_xll.IMDP("IR",$E15,I$9)-I$13,_xll.IMDP("IR",$E15,I$10)),"") -> 3.45 | J15: =IFERROR(IF($F$4=4,_xll.IMDP("IR",$E15,J$9)-J$13,_xll.IMDP("IR",$E15,J$10)),"") -> 3.388 | K15: =IFERROR(IF($F$4=4,_xll.IMDP("IR",$E15,K$9)-K$13,_xll.IMDP("IR",$E15,K$10)),"") -> 3.358 | L15: =IFERROR(IF($F$4=4,_xll.IMDP("IR",$E15,L$9)-L$13,_xll.IMDP("IR",$E15,L$10)),"") -> 3.38 | M15: =IFERROR(IF($F$4=4,_xll.IMDP("IR",$E15,M$9)-M$13,_xll.IMDP("IR",$E15,M$10)),"") -> 3.4 | N15: =IFERROR(IF($F$4=4,_xll.IMDP("IR",$E15,N$9)-N$13,_xll.IMDP("IR",$E15,N$10)),"") -> 3.424 | O15: =IFERROR(IF($F$4=4,_xll.IMDP("IR",$E15,O$9)-O$13,_xll.IMDP("IR",$E15,O$10)),"") -> 3.44 | ... V15: =IFERROR(IF($F$4=4,_xll.IMDP("IR",$E15,V$9)-V$13,_xll.IMDP("IR",$E15,V$10)),"")
B16: 3 | C16: =IFERROR( VLOOKUP( $B16, Sheet1!$M$2:$O$10001, 2,0),"") -> 00008 | D16: =IFERROR( VLOOKUP( $B16, Sheet1!$M$2:$O$10001, 3,0),"") -> 하이트진로 | E16: =INDEX($D$5:$D$10,$D$4,1)&$C16 -> BONDAVG00008 | F16: =_xll.IMDP("IR",$E16,F$12) -> 공모/무보증A+ | G16: =_xll.IMDP("IR",$E16,G$12) -> 20240830 | H16: =IFERROR(IF($F$4=4,_xll.IMDP("IR",$E16,H$9)-H$13,_xll.IMDP("IR",$E16,H$10)),"") -> 3.423 | I16: =IFERROR(IF($F$4=4,_xll.IMDP("IR",$E16,I$9)-I$13,_xll.IMDP("IR",$E16,I$10)),"") -> 3.478 | J16: =IFERROR(IF($F$4=4,_xll.IMDP("IR",$E16,J$9)-J$13,_xll.IMDP("IR",$E16,J$10)),"") -> 3.481 | K16: =IFERROR(IF($F$4=4,_xll.IMDP("IR",$E16,K$9)-K$13,_xll.IMDP("IR",$E16,K$10)),"") -> 3.489 | L16: =IFERROR(IF($F$4=4,_xll.IMDP("IR",$E16,L$9)-L$13,_xll.IMDP("IR",$E16,L$10)),"") -> 3.54 | M16: =IFERROR(IF($F$4=4,_xll.IMDP("IR",$E16,M$9)-M$13,_xll.IMDP("IR",$E16,M$10)),"") -> 3.574 | N16: =IFERROR(IF($F$4=4,_xll.IMDP("IR",$E16,N$9)-N$13,_xll.IMDP("IR",$E16,N$10)),"") -> 3.602 | O16: =IFERROR(IF($F$4=4,_xll.IMDP("IR",$E16,O$9)-O$13,_xll.IMDP("IR",$E16,O$10)),"") -> 3.659 | ... V16: =IFERROR(IF($F$4=4,_xll.IMDP("IR",$E16,V$9)-V$13,_xll.IMDP("IR",$E16,V$10)),"")
B17: 4 | C17: =IFERROR( VLOOKUP( $B17, Sheet1!$M$2:$O$10001, 2,0),"") -> 00011 | D17: =IFERROR( VLOOKUP( $B17, Sheet1!$M$2:$O$10001, 3,0),"") -> 스탠다드차타드은행 | E17: =INDEX($D$5:$D$10,$D$4,1)&$C17 -> BONDAVG00011 | F17: =_xll.IMDP("IR",$E17,F$12) -> 은행채AAA | G17: =_xll.IMDP("IR",$E17,G$12) -> 20240830 | H17: =IFERROR(IF($F$4=4,_xll.IMDP("IR",$E17,H$9)-H$13,_xll.IMDP("IR",$E17,H$10)),"") -> 3.495 | I17: =IFERROR(IF($F$4=4,_xll.IMDP("IR",$E17,I$9)-I$13,_xll.IMDP("IR",$E17,I$10)),"") -> 3.471 | J17: =IFERROR(IF($F$4=4,_xll.IMDP("IR",$E17,J$9)-J$13,_xll.IMDP("IR",$E17,J$10)),"") -> 3.405 | K17: =IFERROR(IF($F$4=4,_xll.IMDP("IR",$E17,K$9)-K$13,_xll.IMDP("IR",$E17,K$10)),"") -> 3.38 | L17: =IFERROR(IF($F$4=4,_xll.IMDP("IR",$E17,L$9)-L$13,_xll.IMDP("IR",$E17,L$10)),"") -> 3.347 | M17: =IFERROR(IF($F$4=4,_xll.IMDP("IR",$E17,M$9)-M$13,_xll.IMDP("IR",$E17,M$10)),"") -> 3.309 | N17: =IFERROR(IF($F$4=4,_xll.IMDP("IR",$E17,N$9)-N$13,_xll.IMDP("IR",$E17,N$10)),"") -> 3.285 | O17: =IFERROR(IF($F$4=4,_xll.IMDP("IR",$E17,O$9)-O$13,_xll.IMDP("IR",$E17,O$10)),"") -> 3.268 | ... V17: =IFERROR(IF($F$4=4,_xll.IMDP("IR",$E17,V$9)-V$13,_xll.IMDP("IR",$E17,V$10)),"")
B18: 5 | C18: =IFERROR( VLOOKUP( $B18, Sheet1!$M$2:$O$10001, 2,0),"") -> 00012 | D18: =IFERROR( VLOOKUP( $B18, Sheet1!$M$2:$O$10001, 3,0),"") -> CJ대한통운 | E18: =INDEX($D$5:$D$10,$D$4,1)&$C18 -> BONDAVG00012 | F18: =_xll.IMDP("IR",$E18,F$12) -> 공모/무보증AA- | G18: =_xll.IMDP("IR",$E18,G$12) -> 20240830 | H18: =IFERROR(IF($F$4=4,_xll.IMDP("IR",$E18,H$9)-H$13,_xll.IMDP("IR",$E18,H$10)),"") -> 3.4 | I18: =IFERROR(IF($F$4=4,_xll.IMDP("IR",$E18,I$9)-I$13,_xll.IMDP("IR",$E18,I$10)),"") -> 3.398 | J18: =IFERROR(IF($F$4=4,_xll.IMDP("IR",$E18,J$9)-J$13,_xll.IMDP("IR",$E18,J$10)),"") -> 3.333 | K18: =IFERROR(IF($F$4=4,_xll.IMDP("IR",$E18,K$9)-K$13,_xll.IMDP("IR",$E18,K$10)),"") -> 3.301 | L18: =IFERROR(IF($F$4=4,_xll.IMDP("IR",$E18,L$9)-L$13,_xll.IMDP("IR",$E18,L$10)),"") -> 3.319 | M18: =IFERROR(IF($F$4=4,_xll.IMDP("IR",$E18,M$9)-M$13,_xll.IMDP("IR",$E18,M$10)),"") -> 3.34 | N18: =IFERROR(IF($F$4=4,_xll.IMDP("IR",$E18,N$9)-N$13,_xll.IMDP("IR",$E18,N$10)),"") -> 3.361 | O18: =IFERROR(IF($F$4=4,_xll.IMDP("IR",$E18,O$9)-O$13,_xll.IMDP("IR",$E18,O$10)),"") -> 3.376 | ... V18: =IFERROR(IF($F$4=4,_xll.IMDP("IR",$E18,V$9)-V$13,_xll.IMDP("IR",$E18,V$10)),"")
B19: 6 | C19: =IFERROR( VLOOKUP( $B19, Sheet1!$M$2:$O$10001, 2,0),"") -> 00014 | D19: =IFERROR( VLOOKUP( $B19, Sheet1!$M$2:$O$10001, 3,0),"") -> 하이트진로홀딩스 | E19: =INDEX($D$5:$D$10,$D$4,1)&$C19 -> BONDAVG00014 | F19: =_xll.IMDP("IR",$E19,F$12) -> 공모/무보증A0 | G19: =_xll.IMDP("IR",$E19,G$12) -> 20240830 | H19: =IFERROR(IF($F$4=4,_xll.IMDP("IR",$E19,H$9)-H$13,_xll.IMDP("IR",$E19,H$10)),"") -> 3.723 | I19: =IFERROR(IF($F$4=4,_xll.IMDP("IR",$E19,I$9)-I$13,_xll.IMDP("IR",$E19,I$10)),"") -> 3.805 | J19: =IFERROR(IF($F$4=4,_xll.IMDP("IR",$E19,J$9)-J$13,_xll.IMDP("IR",$E19,J$10)),"") -> 3.831 | K19: =IFERROR(IF($F$4=4,_xll.IMDP("IR",$E19,K$9)-K$13,_xll.IMDP("IR",$E19,K$10)),"") -> 3.861 | L19: =IFERROR(IF($F$4=4,_xll.IMDP("IR",$E19,L$9)-L$13,_xll.IMDP("IR",$E19,L$10)),"") -> 3.941 | M19: =IFERROR(IF($F$4=4,_xll.IMDP("IR",$E19,M$9)-M$13,_xll.IMDP("IR",$E19,M$10)),"") -> 4.009 | N19: =IFERROR(IF($F$4=4,_xll.IMDP("IR",$E19,N$9)-N$13,_xll.IMDP("IR",$E19,N$10)),"") -> 4.131 | O19: =IFERROR(IF($F$4=4,_xll.IMDP("IR",$E19,O$9)-O$13,_xll.IMDP("IR",$E19,O$10)),"") -> 4.222 | ... V19: =IFERROR(IF($F$4=4,_xll.IMDP("IR",$E19,V$9)-V$13,_xll.IMDP("IR",$E19,V$10)),"")
B20: 7 | C20: =IFERROR( VLOOKUP( $B20, Sheet1!$M$2:$O$10001, 2,0),"") -> 00015 | D20: =IFERROR( VLOOKUP( $B20, Sheet1!$M$2:$O$10001, 3,0),"") -> 두산 | E20: =INDEX($D$5:$D$10,$D$4,1)&$C20 -> BONDAVG00015 | F20: =_xll.IMDP("IR",$E20,F$12) -> 공모/무보증BBB0 | G20: =_xll.IMDP("IR",$E20,G$12) -> 20240830 | H20: =IFERROR(IF($F$4=4,_xll.IMDP("IR",$E20,H$9)-H$13,_xll.IMDP("IR",$E20,H$10)),"") -> 3.546 | I20: =IFERROR(IF($F$4=4,_xll.IMDP("IR",$E20,I$9)-I$13,_xll.IMDP("IR",$E20,I$10)),"") -> 4.029 | J20: =IFERROR(IF($F$4=4,_xll.IMDP("IR",$E20,J$9)-J$13,_xll.IMDP("IR",$E20,J$10)),"") -> 4.169 | K20: =IFERROR(IF($F$4=4,_xll.IMDP("IR",$E20,K$9)-K$13,_xll.IMDP("IR",$E20,K$10)),"") -> 4.202 | L20: =IFERROR(IF($F$4=4,_xll.IMDP("IR",$E20,L$9)-L$13,_xll.IMDP("IR",$E20,L$10)),"") -> 4.302 | M20: =IFERROR(IF($F$4=4,_xll.IMDP("IR",$E20,M$9)-M$13,_xll.IMDP("IR",$E20,M$10)),"") -> 4.482 | N20: =IFERROR(IF($F$4=4,_xll.IMDP("IR",$E20,N$9)-N$13,_xll.IMDP("IR",$E20,N$10)),"") -> 4.867 | O20: =IFERROR(IF($F$4=4,_xll.IMDP("IR",$E20,O$9)-O$13,_xll.IMDP("IR",$E20,O$10)),"") -> 4.986 | ... V20: =IFERROR(IF($F$4=4,_xll.IMDP("IR",$E20,V$9)-V$13,_xll.IMDP("IR",$E20,V$10)),"")
B21: 8 | C21: =IFERROR( VLOOKUP( $B21, Sheet1!$M$2:$O$10001, 2,0),"") -> 00021 | D21: =IFERROR( VLOOKUP( $B21, Sheet1!$M$2:$O$10001, 3,0),"") -> DL | E21: =INDEX($D$5:$D$10,$D$4,1)&$C21 -> BONDAVG00021 | F21: =_xll.IMDP("IR",$E21,F$12) -> 공모/무보증A+ | G21: =_xll.IMDP("IR",$E21,G$12) -> 20240830 | H21: =IFERROR(IF($F$4=4,_xll.IMDP("IR",$E21,H$9)-H$13,_xll.IMDP("IR",$E21,H$10)),"") -> 3.791 | I21: =IFERROR(IF($F$4=4,_xll.IMDP("IR",$E21,I$9)-I$13,_xll.IMDP("IR",$E21,I$10)),"") -> 3.847 | J21: =IFERROR(IF($F$4=4,_xll.IMDP("IR",$E21,J$9)-J$13,_xll.IMDP("IR",$E21,J$10)),"") -> 3.863 | K21: =IFERROR(IF($F$4=4,_xll.IMDP("IR",$E21,K$9)-K$13,_xll.IMDP("IR",$E21,K$10)),"") -> 3.885 | L21: =IFERROR(IF($F$4=4,_xll.IMDP("IR",$E21,L$9)-L$13,_xll.IMDP("IR",$E21,L$10)),"") -> 3.956 | M21: =IFERROR(IF($F$4=4,_xll.IMDP("IR",$E21,M$9)-M$13,_xll.IMDP("IR",$E21,M$10)),"") -> 4.003 | N21: =IFERROR(IF($F$4=4,_xll.IMDP("IR",$E21,N$9)-N$13,_xll.IMDP("IR",$E21,N$10)),"") -> 4.07 | O21: =IFERROR(IF($F$4=4,_xll.IMDP("IR",$E21,O$9)-O$13,_xll.IMDP("IR",$E21,O$10)),"") -> 4.114 | ... V21: =IFERROR(IF($F$4=4,_xll.IMDP("IR",$E21,V$9)-V$13,_xll.IMDP("IR",$E21,V$10)),"")
B22: 9 | C22: =IFERROR( VLOOKUP( $B22, Sheet1!$M$2:$O$10001, 2,0),"") -> 00027 | D22: =IFERROR( VLOOKUP( $B22, Sheet1!$M$2:$O$10001, 3,0),"") -> 기아 | E22: =INDEX($D$5:$D$10,$D$4,1)&$C22 -> BONDAVG00027 | F22: =_xll.IMDP("IR",$E22,F$12) -> 공모/무보증AA+ | G22: =_xll.IMDP("IR",$E22,G$12) -> 20240830 | H22: =IFERROR(IF($F$4=4,_xll.IMDP("IR",$E22,H$9)-H$13,_xll.IMDP("IR",$E22,H$10)),"") -> 3.464 | I22: =IFERROR(IF($F$4=4,_xll.IMDP("IR",$E22,I$9)-I$13,_xll.IMDP("IR",$E22,I$10)),"") -> 3.458 | J22: =IFERROR(IF($F$4=4,_xll.IMDP("IR",$E22,J$9)-J$13,_xll.IMDP("IR",$E22,J$10)),"") -> 3.395 | K22: =IFERROR(IF($F$4=4,_xll.IMDP("IR",$E22,K$9)-K$13,_xll.IMDP("IR",$E22,K$10)),"") -> 3.362 | L22: =IFERROR(IF($F$4=4,_xll.IMDP("IR",$E22,L$9)-L$13,_xll.IMDP("IR",$E22,L$10)),"") -> 3.386 | M22: =IFERROR(IF($F$4=4,_xll.IMDP("IR",$E22,M$9)-M$13,_xll.IMDP("IR",$E22,M$10)),"") -> 3.395 | N22: =IFERROR(IF($F$4=4,_xll.IMDP("IR",$E22,N$9)-N$13,_xll.IMDP("IR",$E22,N$10)),"") -> 3.42 | O22: =IFERROR(IF($F$4=4,_xll.IMDP("IR",$E22,O$9)-O$13,_xll.IMDP("IR",$E22,O$10)),"") -> 3.427 | ... V22: =IFERROR(IF($F$4=4,_xll.IMDP("IR",$E22,V$9)-V$13,_xll.IMDP("IR",$E22,V$10)),"")
B23: 10 | C23: =IFERROR( VLOOKUP( $B23, Sheet1!$M$2:$O$10001, 2,0),"") -> 00064 | D23: =IFERROR( VLOOKUP( $B23, Sheet1!$M$2:$O$10001, 3,0),"") -> 동아쏘시오홀딩스 | E23: =INDEX($D$5:$D$10,$D$4,1)&$C23 -> BONDAVG00064 | F23: =_xll.IMDP("IR",$E23,F$12) -> 공모/무보증A0 | G23: =_xll.IMDP("IR",$E23,G$12) -> 20240830 | H23: =IFERROR(IF($F$4=4,_xll.IMDP("IR",$E23,H$9)-H$13,_xll.IMDP("IR",$E23,H$10)),"") -> 3.756 | I23: =IFERROR(IF($F$4=4,_xll.IMDP("IR",$E23,I$9)-I$13,_xll.IMDP("IR",$E23,I$10)),"") -> 3.788 | J23: =IFERROR(IF($F$4=4,_xll.IMDP("IR",$E23,J$9)-J$13,_xll.IMDP("IR",$E23,J$10)),"") -> 3.793 | K23: =IFERROR(IF($F$4=4,_xll.IMDP("IR",$E23,K$9)-K$13,_xll.IMDP("IR",$E23,K$10)),"") -> 3.814 | L23: =IFERROR(IF($F$4=4,_xll.IMDP("IR",$E23,L$9)-L$13,_xll.IMDP("IR",$E23,L$10)),"") -> 3.856 | M23: =IFERROR(IF($F$4=4,_xll.IMDP("IR",$E23,M$9)-M$13,_xll.IMDP("IR",$E23,M$10)),"") -> 3.885 | N23: =IFERROR(IF($F$4=4,_xll.IMDP("IR",$E23,N$9)-N$13,_xll.IMDP("IR",$E23,N$10)),"") -> 3.981 | O23: =IFERROR(IF($F$4=4,_xll.IMDP("IR",$E23,O$9)-O$13,_xll.IMDP("IR",$E23,O$10)),"") -> 4.149 | ... V23: =IFERROR(IF($F$4=4,_xll.IMDP("IR",$E23,V$9)-V$13,_xll.IMDP("IR",$E23,V$10)),"")
B24: 11 | C24: =IFERROR( VLOOKUP( $B24, Sheet1!$M$2:$O$10001, 2,0),"") -> 00066 | D24: =IFERROR( VLOOKUP( $B24, Sheet1!$M$2:$O$10001, 3,0),"") -> SK하이닉스 | E24: =INDEX($D$5:$D$10,$D$4,1)&$C24 -> BONDAVG00066 | F24: =_xll.IMDP("IR",$E24,F$12) -> 공모/무보증AA0 | G24: =_xll.IMDP("IR",$E24,G$12) -> 20240830 | H24: =IFERROR(IF($F$4=4,_xll.IMDP("IR",$E24,H$9)-H$13,_xll.IMDP("IR",$E24,H$10)),"") -> 3.4 | I24: =IFERROR(IF($F$4=4,_xll.IMDP("IR",$E24,I$9)-I$13,_xll.IMDP("IR",$E24,I$10)),"") -> 3.393 | J24: =IFERROR(IF($F$4=4,_xll.IMDP("IR",$E24,J$9)-J$13,_xll.IMDP("IR",$E24,J$10)),"") -> 3.328 | K24: =IFERROR(IF($F$4=4,_xll.IMDP("IR",$E24,K$9)-K$13,_xll.IMDP("IR",$E24,K$10)),"") -> 3.292 | L24: =IFERROR(IF($F$4=4,_xll.IMDP("IR",$E24,L$9)-L$13,_xll.IMDP("IR",$E24,L$10)),"") -> 3.312 | M24: =IFERROR(IF($F$4=4,_xll.IMDP("IR",$E24,M$9)-M$13,_xll.IMDP("IR",$E24,M$10)),"") -> 3.321 | N24: =IFERROR(IF($F$4=4,_xll.IMDP("IR",$E24,N$9)-N$13,_xll.IMDP("IR",$E24,N$10)),"") -> 3.339 | O24: =IFERROR(IF($F$4=4,_xll.IMDP("IR",$E24,O$9)-O$13,_xll.IMDP("IR",$E24,O$10)),"") -> 3.336 | ... V24: =IFERROR(IF($F$4=4,_xll.IMDP("IR",$E24,V$9)-V$13,_xll.IMDP("IR",$E24,V$10)),"")
B25: 12 | C25: =IFERROR( VLOOKUP( $B25, Sheet1!$M$2:$O$10001, 2,0),"") -> 00072 | D25: =IFERROR( VLOOKUP( $B25, Sheet1!$M$2:$O$10001, 3,0),"") -> 현대건설 | E25: =INDEX($D$5:$D$10,$D$4,1)&$C25 -> BONDAVG00072 | F25: =_xll.IMDP("IR",$E25,F$12) -> 공모/무보증AA- | G25: =_xll.IMDP("IR",$E25,G$12) -> 20240830 | H25: =IFERROR(IF($F$4=4,_xll.IMDP("IR",$E25,H$9)-H$13,_xll.IMDP("IR",$E25,H$10)),"") -> 3.585 | I25: =IFERROR(IF($F$4=4,_xll.IMDP("IR",$E25,I$9)-I$13,_xll.IMDP("IR",$E25,I$10)),"") -> 3.578 | J25: =IFERROR(IF($F$4=4,_xll.IMDP("IR",$E25,J$9)-J$13,_xll.IMDP("IR",$E25,J$10)),"") -> 3.523 | K25: =IFERROR(IF($F$4=4,_xll.IMDP("IR",$E25,K$9)-K$13,_xll.IMDP("IR",$E25,K$10)),"") -> 3.496 | L25: =IFERROR(IF($F$4=4,_xll.IMDP("IR",$E25,L$9)-L$13,_xll.IMDP("IR",$E25,L$10)),"") -> 3.542 | M25: =IFERROR(IF($F$4=4,_xll.IMDP("IR",$E25,M$9)-M$13,_xll.IMDP("IR",$E25,M$10)),"") -> 3.585 | N25: =IFERROR(IF($F$4=4,_xll.IMDP("IR",$E25,N$9)-N$13,_xll.IMDP("IR",$E25,N$10)),"") -> 3.615 | O25: =IFERROR(IF($F$4=4,_xll.IMDP("IR",$E25,O$9)-O$13,_xll.IMDP("IR",$E25,O$10)),"") -> 3.632 | ... V25: =IFERROR(IF($F$4=4,_xll.IMDP("IR",$E25,V$9)-V$13,_xll.IMDP("IR",$E25,V$10)),"")
... B513: 500 | C513: =IFERROR( VLOOKUP( $B513, Sheet1!$M$2:$O$10001, 2,0),"") | D513: =IFERROR( VLOOKUP( $B513, Sheet1!$M$2:$O$10001, 3,0),"") | E513: =INDEX($D$5:$D$10,$D$4,1)&$C513 -> BONDAVG | F513: =_xll.IMDP("IR",$E513,F$12) | G513: =_xll.IMDP("IR",$E513,G$12) | H513: =IFERROR(IF($F$4=4,_xll.IMDP("IR",$E513,H$9)-H$13,_xll.IMDP("IR",$E513,H$10)),"") | I513: =IFERROR(IF($F$4=4,_xll.IMDP("IR",$E513,I$9)-I$13,_xll.IMDP("IR",$E513,I$10)),"") | J513: =IFERROR(IF($F$4=4,_xll.IMDP("IR",$E513,J$9)-J$13,_xll.IMDP("IR",$E513,J$10)),"") | K513: =IFERROR(IF($F$4=4,_xll.IMDP("IR",$E513,K$9)-K$13,_xll.IMDP("IR",$E513,K$10)),"") | L513: =IFERROR(IF($F$4=4,_xll.IMDP("IR",$E513,L$9)-L$13,_xll.IMDP("IR",$E513,L$10)),"") | M513: =IFERROR(IF($F$4=4,_xll.IMDP("IR",$E513,M$9)-M$13,_xll.IMDP("IR",$E513,M$10)),"") | N513: =IFERROR(IF($F$4=4,_xll.IMDP("IR",$E513,N$9)-N$13,_xll.IMDP("IR",$E513,N$10)),"") | O513: =IFERROR(IF($F$4=4,_xll.IMDP("IR",$E513,O$9)-O$13,_xll.IMDP("IR",$E513,O$10)),"") | ... V513: =IFERROR(IF($F$4=4,_xll.IMDP("IR",$E513,V$9)-V$13,_xll.IMDP("IR",$E513,V$10)),"")

Sheet Sheet1
A1: 코드 | B1: CRDLIST010000 | C1: 코드 | D1: CRDLIST020000 | E1: 코드 | F1: CRDLIST030000 | G1: =TEXT( EOMONTH(TODAY(), -19)+1, "YYYYMMDD") & "~" & TEXT( EOMONTH(TODAY(),0), "YYYYMMDD") -> 20230301~20240930 | I1: ROW | J1: Unique Count | M1: Display | Q1: Select | U1: 1
A2: 조회건수 | B2: 9999 | C2: 조회건수 | D2: 9999 | E2: 조회건수 | F2: 9999 | G2: =$B$7 -> 4725 | I2: =ROW()-1 -> 1 | J2: =IF( $I2>$G$4, NA(), IF($I2>$G$3, $I2-$G$3, IF($I2>$G$2, $I2-$G$2, $I2 ) ) ) -> 1 | K2: =IF( $I2>$G$4, NA(), IF($I2>$G$3, 5, IF($I2>$G$2, 3, 1 ) ) ) -> 1 | L2: =COUNTIF($N$2:N2, N2)=1 -> TRUE | M2: =IF( $Q2, MAX($M$1:M1)+1, 0) -> 1 | N2: {=INDEX($A$9:$F$1048576, $J2, $K2 )} -> 00001 | O2: {=INDEX($B$9:$F$1048576, $J2, $K2 )} -> 신한은행 | P2: {=IF( $L2, TRIM(_xll.IMDP("IR", $G$5&$N2, $G$6)), "" )} -> 은행채AAA | Q2: {=IF( $U$1=1, AND($P2<>"", $P2<>"...", $P2<>"입력오류"), IF( $U$18=1, AND($P2<>"", $P2<>"...", $P2<>"입력오류", ISNUMBER(FIND(INDEX($T$2:$T$7,$U$1),$P2))), IF( $U$17="기타", AND($P2<>"", $P2<>"...", $P2<>"입력오류", NOT(ISNUMBER(FIND($T$21:$T$34,$P2)))), AND($P2<>"", $P2<>"...", $P2<>"입력오류", $T$19=$P2) ) ) )} -> TRUE | S2: {=SUM( IFERROR(FIND($AA$6:$AA$11, $P2), 0) )} -> 0 | U2: 전체 | W2: 공사/공단채정부보증 | X2: 은행채AAA(산금-이표) | Y2: 카드채AAA | Z2: 기타금융채AAA | AA2: 공모/무보증AAA
A3: 일자 | B3: =$G$1 -> 20230301~20240930 | C3: 일자 | D3: =$G$1 -> 20230301~20240930 | E3: 일자 | F3: =$G$1 -> 20230301~20240930 | G3: =$G$2+$D$7 -> 6584 | I3: =ROW()-1 -> 2 | J3: =IF( $I3>$G$4, NA(), IF($I3>$G$3, $I3-$G$3, IF($I3>$G$2, $I3-$G$2, $I3 ) ) ) -> 2 | K3: =IF( $I3>$G$4, NA(), IF($I3>$G$3, 5, IF($I3>$G$2, 3, 1 ) ) ) -> 1 | L3: =COUNTIF($N$2:N3, N3)=1 -> TRUE | M3: =IF( $Q3, MAX($M$1:M2)+1, 0) -> 2 | N3: {=INDEX($A$9:$F$1048576, $J3, $K3 )} -> 00007 | O3: {=INDEX($B$9:$F$1048576, $J3, $K3 )} -> 삼양홀딩스 | P3: {=IF( $L3, TRIM(_xll.IMDP("IR", $G$5&$N3, $G$6)), "" )} -> 공모/무보증AA- | Q3: {=IF( $U$1=1, AND($P3<>"", $P3<>"...", $P3<>"입력오류"), IF( $U$18=1, AND($P3<>"", $P3<>"...", $P3<>"입력오류", ISNUMBER(FIND(INDEX($T$2:$T$7,$U$1),$P3))), IF( $U$17="기타", AND($P3<>"", $P3<>"...", $P3<>"입력오류", NOT(ISNUMBER(FIND($T$21:$T$34,$P3)))), AND($P3<>"", $P3<>"...", $P3<>"입력오류", $T$19=$P3) ) ) )} -> TRUE | S3: {=SUM( IFERROR(FIND($AA$6:$AA$11, $P3), 0) )} -> 0 | T3: 공사/공단채 | U3: 공사공단채 | W3: 공사/공단채AAA | X3: 은행채AAA(산금-할인) | Y3: 카드채AA+ | Z3: 기타금융채AA+ | AA3: 공모/무보증AA+
A4: 조회기준 | B4: 전체 | C4: 조회기준 | D4: 전체 | E4: 조회기준 | F4: 전체 | G4: =$G$3+F7 -> 6880 | I4: =ROW()-1 -> 3 | J4: =IF( $I4>$G$4, NA(), IF($I4>$G$3, $I4-$G$3, IF($I4>$G$2, $I4-$G$2, $I4 ) ) ) -> 3 | K4: =IF( $I4>$G$4, NA(), IF($I4>$G$3, 5, IF($I4>$G$2, 3, 1 ) ) ) -> 1 | L4: =COUNTIF($N$2:N4, N4)=1 -> TRUE | M4: =IF( $Q4, MAX($M$1:M3)+1, 0) -> 3 | N4: {=INDEX($A$9:$F$1048576, $J4, $K4 )} -> 00008 | O4: {=INDEX($B$9:$F$1048576, $J4, $K4 )} -> 하이트진로 | P4: {=IF( $L4, TRIM(_xll.IMDP("IR", $G$5&$N4, $G$6)), "" )} -> 공모/무보증A+ | Q4: {=IF( $U$1=1, AND($P4<>"", $P4<>"...", $P4<>"입력오류"), IF( $U$18=1, AND($P4<>"", $P4<>"...", $P4<>"입력오류", ISNUMBER(FIND(INDEX($T$2:$T$7,$U$1),$P4))), IF( $U$17="기타", AND($P4<>"", $P4<>"...", $P4<>"입력오류", NOT(ISNUMBER(FIND($T$21:$T$34,$P4)))), AND($P4<>"", $P4<>"...", $P4<>"입력오류", $T$19=$P4) ) ) )} -> TRUE | S4: {=SUM( IFERROR(FIND($AA$6:$AA$11, $P4), 0) )} -> 1 | T4: 은행채 | U4: 은행채 | W4: 공사/공단채AA+ | X4: 은행채AAA(중금-이표) | Y4: 카드채AA0 | Z4: 기타금융채AA0 | AA4: 공모/무보증AA0
A5: 정렬기준 | B5: 채권코드 | C5: 정렬기준 | D5: 채권코드 | E5: 정렬기준 | F5: 채권코드 | G5: {=INDEX('발행사 Term Structure'!$D$5:$D$10,'발행사 Term Structure'!$D$4,1)} -> BONDAVG | I5: =ROW()-1 -> 4 | J5: =IF( $I5>$G$4, NA(), IF($I5>$G$3, $I5-$G$3, IF($I5>$G$2, $I5-$G$2, $I5 ) ) ) -> 4 | K5: =IF( $I5>$G$4, NA(), IF($I5>$G$3, 5, IF($I5>$G$2, 3, 1 ) ) ) -> 1 | L5: =COUNTIF($N$2:N5, N5)=1 -> TRUE | M5: =IF( $Q5, MAX($M$1:M4)+1, 0) -> 4 | N5: {=INDEX($A$9:$F$1048576, $J5, $K5 )} -> 00011 | O5: {=INDEX($B$9:$F$1048576, $J5, $K5 )} -> 스탠다드차타드은행 | P5: {=IF( $L5, TRIM(_xll.IMDP("IR", $G$5&$N5, $G$6)), "" )} -> 은행채AAA | Q5: {=IF( $U$1=1, AND($P5<>"", $P5<>"...", $P5<>"입력오류"), IF( $U$18=1, AND($P5<>"", $P5<>"...", $P5<>"입력오류", ISNUMBER(FIND(INDEX($T$2:$T$7,$U$1),$P5))), IF( $U$17="기타", AND($P5<>"", $P5<>"...", $P5<>"입력오류", NOT(ISNUMBER(FIND($T$21:$T$34,$P5)))), AND($P5<>"", $P5<>"...", $P5<>"입력오류", $T$19=$P5) ) ) )} -> TRUE | T5: 카드채 | U5: 카드채 | W5: 공사/공단채AA0 | X5: 은행채AAA(중금-할인) | Y5: 카드채AA- | Z5: 기타금융채AA- | AA5: 공모/무보증AA-
A6: 정렬 | B6: A | C6: 정렬 | D6: A | E6: 정렬 | F6: A | G6: 채권그룹 | I6: =ROW()-1 -> 5 | J6: =IF( $I6>$G$4, NA(), IF($I6>$G$3, $I6-$G$3, IF($I6>$G$2, $I6-$G$2, $I6 ) ) ) -> 5 | K6: =IF( $I6>$G$4, NA(), IF($I6>$G$3, 5, IF($I6>$G$2, 3, 1 ) ) ) -> 1 | L6: =COUNTIF($N$2:N6, N6)=1 -> TRUE | M6: =IF( $Q6, MAX($M$1:M5)+1, 0) -> 5 | N6: {=INDEX($A$9:$F$1048576, $J6, $K6 )} -> 00012 | O6: {=INDEX($B$9:$F$1048576, $J6, $K6 )} -> CJ대한통운 | P6: {=IF( $L6, TRIM(_xll.IMDP("IR", $G$5&$N6, $G$6)), "" )} -> 공모/무보증AA- | Q6: {=IF( $U$1=1, AND($P6<>"", $P6<>"...", $P6<>"입력오류"), IF( $U$18=1, AND($P6<>"", $P6<>"...", $P6<>"입력오류", ISNUMBER(FIND(INDEX($T$2:$T$7,$U$1),$P6))), IF( $U$17="기타", AND($P6<>"", $P6<>"...", $P6<>"입력오류", NOT(ISNUMBER(FIND($T$21:$T$34,$P6)))), AND($P6<>"", $P6<>"...", $P6<>"입력오류", $T$19=$P6) ) ) )} -> TRUE | T6: 기타금융채 | U6: 기타금융채 | W6: 공사/공단채AA- | X6: 은행채AAA | Y6: 카드채A+ | Z6: 기타금융채A+ | AA6: 공모/무보증A+
A7: =_xll.IMDT("등급별기업",B1,A8:B8,B2,B3,B4,B5,"sort="&B6&",DtFmt=1,TmFmt=1,Pos=20,Orient=V,Title=채권") -> 채권 | B7: =COUNTA(B$9:B$1048576) -> 4725 | C7: =_xll.IMDT("등급별기업",D1,C8:D8,D2,D3,D4,D5,"sort="&D6&",DtFmt=1,TmFmt=1,Pos=20,Orient=V,Title=CP") -> CP | D7: =COUNTA(D$9:D$1048576) -> 1859 | E7: =_xll.IMDT("등급별기업",F1,E8:F8,F2,F3,F4,F5,"sort="&F6&",DtFmt=1,TmFmt=1,Pos=20,Orient=V,Title=기업") -> 기업 | F7: =COUNTA(F$9:F$1048576) -> 296 | I7: =ROW()-1 -> 6 | J7: =IF( $I7>$G$4, NA(), IF($I7>$G$3, $I7-$G$3, IF($I7>$G$2, $I7-$G$2, $I7 ) ) ) -> 6 | K7: =IF( $I7>$G$4, NA(), IF($I7>$G$3, 5, IF($I7>$G$2, 3, 1 ) ) ) -> 1 | L7: =COUNTIF($N$2:N7, N7)=1 -> TRUE | M7: =IF( $Q7, MAX($M$1:M6)+1, 0) -> 6 | N7: {=INDEX($A$9:$F$1048576, $J7, $K7 )} -> 00014 | O7: {=INDEX($B$9:$F$1048576, $J7, $K7 )} -> 하이트진로홀딩스 | P7: {=IF( $L7, TRIM(_xll.IMDP("IR", $G$5&$N7, $G$6)), "" )} -> 공모/무보증A0 | Q7: {=IF( $U$1=1, AND($P7<>"", $P7<>"...", $P7<>"입력오류"), IF( $U$18=1, AND($P7<>"", $P7<>"...", $P7<>"입력오류", ISNUMBER(FIND(INDEX($T$2:$T$7,$U$1),$P7))), IF( $U$17="기타", AND($P7<>"", $P7<>"...", $P7<>"입력오류", NOT(ISNUMBER(FIND($T$21:$T$34,$P7)))), AND($P7<>"", $P7<>"...", $P7<>"입력오류", $T$19=$P7) ) ) )} -> TRUE | T7: 공모/무보증 | U7: 회사채 | X7: 은행채AA+ | Y7: 카드채A0 | Z7: 기타금융채A0 | AA7: 공모/무보증A0
A8: 채권코드 | B8: 회사명 | C8: 채권코드 | D8: 회사명 | E8: 채권코드 | F8: 회사명 | I8: =ROW()-1 -> 7 | J8: =IF( $I8>$G$4, NA(), IF($I8>$G$3, $I8-$G$3, IF($I8>$G$2, $I8-$G$2, $I8 ) ) ) -> 7 | K8: =IF( $I8>$G$4, NA(), IF($I8>$G$3, 5, IF($I8>$G$2, 3, 1 ) ) ) -> 1 | L8: =COUNTIF($N$2:N8, N8)=1 -> TRUE | M8: =IF( $Q8, MAX($M$1:M7)+1, 0) -> 7 | N8: {=INDEX($A$9:$F$1048576, $J8, $K8 )} -> 00015 | O8: {=INDEX($B$9:$F$1048576, $J8, $K8 )} -> 두산 | P8: {=IF( $L8, TRIM(_xll.IMDP("IR", $G$5&$N8, $G$6)), "" )} -> 공모/무보증BBB0 | Q8: {=IF( $U$1=1, AND($P8<>"", $P8<>"...", $P8<>"입력오류"), IF( $U$18=1, AND($P8<>"", $P8<>"...", $P8<>"입력오류", ISNUMBER(FIND(INDEX($T$2:$T$7,$U$1),$P8))), IF( $U$17="기타", AND($P8<>"", $P8<>"...", $P8<>"입력오류", NOT(ISNUMBER(FIND($T$21:$T$34,$P8)))), AND($P8<>"", $P8<>"...", $P8<>"입력오류", $T$19=$P8) ) ) )} -> TRUE | X8: 은행채AA0 | Y8: 카드채A- | Z8: 기타금융채A- | AA8: 공모/무보증A-
A9: 00001 | B9: 신한은행 | C9: 00008 | D9: 하이트진로 | E9: 00001 | F9: 신한은행 | I9: =ROW()-1 -> 8 | J9: =IF( $I9>$G$4, NA(), IF($I9>$G$3, $I9-$G$3, IF($I9>$G$2, $I9-$G$2, $I9 ) ) ) -> 8 | K9: =IF( $I9>$G$4, NA(), IF($I9>$G$3, 5, IF($I9>$G$2, 3, 1 ) ) ) -> 1 | L9: =COUNTIF($N$2:N9, N9)=1 -> TRUE | M9: =IF( $Q9, MAX($M$1:M8)+1, 0) -> 8 | N9: {=INDEX($A$9:$F$1048576, $J9, $K9 )} -> 00021 | O9: {=INDEX($B$9:$F$1048576, $J9, $K9 )} -> DL | P9: {=IF( $L9, TRIM(_xll.IMDP("IR", $G$5&$N9, $G$6)), "" )} -> 공모/무보증A+ | Q9: {=IF( $U$1=1, AND($P9<>"", $P9<>"...", $P9<>"입력오류"), IF( $U$18=1, AND($P9<>"", $P9<>"...", $P9<>"입력오류", ISNUMBER(FIND(INDEX($T$2:$T$7,$U$1),$P9))), IF( $U$17="기타", AND($P9<>"", $P9<>"...", $P9<>"입력오류", NOT(ISNUMBER(FIND($T$21:$T$34,$P9)))), AND($P9<>"", $P9<>"...", $P9<>"입력오류", $T$19=$P9) ) ) )} -> TRUE | X9: 은행채AA- | Y9: 카드채BBB+ | Z9: 기타금융채BBB+ | AA9: 공모/무보증BBB+
A10: 00007 | B10: 삼양홀딩스 | C10: 0000E | D10: 사조오양(신한은행 보증) | E10: 00011 | F10: 스탠다드차타드은행 | I10: =ROW()-1 -> 9 | J10: =IF( $I10>$G$4, NA(), IF($I10>$G$3, $I10-$G$3, IF($I10>$G$2, $I10-$G$2, $I10 ) ) ) -> 9 | K10: =IF( $I10>$G$4, NA(), IF($I10>$G$3, 5, IF($I10>$G$2, 3, 1 ) ) ) -> 1 | L10: =COUNTIF($N$2:N10, N10)=1 -> TRUE | M10: =IF( $Q10, MAX($M$1:M9)+1, 0) -> 9 | N10: {=INDEX($A$9:$F$1048576, $J10, $K10 )} -> 00027 | O10: {=INDEX($B$9:$F$1048576, $J10, $K10 )} -> 기아 | P10: {=IF( $L10, TRIM(_xll.IMDP("IR", $G$5&$N10, $G$6)), "" )} -> 공모/무보증AA+ | Q10: {=IF( $U$1=1, AND($P10<>"", $P10<>"...", $P10<>"입력오류"), IF( $U$18=1, AND($P10<>"", $P10<>"...", $P10<>"입력오류", ISNUMBER(FIND(INDEX($T$2:$T$7,$U$1),$P10))), IF( $U$17="기타", AND($P10<>"", $P10<>"...", $P10<>"입력오류", NOT(ISNUMBER(FIND($T$21:$T$34,$P10)))), AND($P10<>"", $P10<>"...", $P10<>"입력오류", $T$19=$P10) ) ) )} -> TRUE | X10: 은행채A+ | Y10: 카드채BBB0 | Z10: 기타금융채BBB0 | AA10: 공모/무보증BBB0
A11: 00008 | B11: 하이트진로 | C11: 0000L | D11: 해태아이스크림(신한은행보증) | E11: 00012 | F11: CJ대한통운 | I11: =ROW()-1 -> 10 | J11: =IF( $I11>$G$4, NA(), IF($I11>$G$3, $I11-$G$3, IF($I11>$G$2, $I11-$G$2, $I11 ) ) ) -> 10 | K11: =IF( $I11>$G$4, NA(), IF($I11>$G$3, 5, IF($I11>$G$2, 3, 1 ) ) ) -> 1 | L11: =COUNTIF($N$2:N11, N11)=1 -> TRUE | M11: =IF( $Q11, MAX($M$1:M10)+1, 0) -> 0 | N11: {=INDEX($A$9:$F$1048576, $J11, $K11 )} -> 00030 | O11: {=INDEX($B$9:$F$1048576, $J11, $K11 )} -> 대유플러스 | P11: {=IF( $L11, TRIM(_xll.IMDP("IR", $G$5&$N11, $G$6)), "" )} | Q11: {=IF( $U$1=1, AND($P11<>"", $P11<>"...", $P11<>"입력오류"), IF( $U$18=1, AND($P11<>"", $P11<>"...", $P11<>"입력오류", ISNUMBER(FIND(INDEX($T$2:$T$7,$U$1),$P11))), IF( $U$17="기타", AND($P11<>"", $P11<>"...", $P11<>"입력오류", NOT(ISNUMBER(FIND($T$21:$T$34,$P11)))), AND($P11<>"", $P11<>"...", $P11<>"입력오류", $T$19=$P11) ) ) )} -> FALSE | X11: 은행채A0 | Y11: 카드채BBB- | Z11: 기타금융채BBB- | AA11: 공모/무보증BBB-
A12: 00011 | B12: 스탠다드차타드은행 | C12: 0000M | D12: 유경산업(신한은행보증) | E12: 00027 | F12: 기아 | I12: =ROW()-1 -> 11 | J12: =IF( $I12>$G$4, NA(), IF($I12>$G$3, $I12-$G$3, IF($I12>$G$2, $I12-$G$2, $I12 ) ) ) -> 11 | K12: =IF( $I12>$G$4, NA(), IF($I12>$G$3, 5, IF($I12>$G$2, 3, 1 ) ) ) -> 1 | L12: =COUNTIF($N$2:N12, N12)=1 -> TRUE | M12: =IF( $Q12, MAX($M$1:M11)+1, 0) -> 0 | N12: {=INDEX($A$9:$F$1048576, $J12, $K12 )} -> 00049 | O12: {=INDEX($B$9:$F$1048576, $J12, $K12 )} -> 대동 | P12: {=IF( $L12, TRIM(_xll.IMDP("IR", $G$5&$N12, $G$6)), "" )} | Q12: {=IF( $U$1=1, AND($P12<>"", $P12<>"...", $P12<>"입력오류"), IF( $U$18=1, AND($P12<>"", $P12<>"...", $P12<>"입력오류", ISNUMBER(FIND(INDEX($T$2:$T$7,$U$1),$P12))), IF( $U$17="기타", AND($P12<>"", $P12<>"...", $P12<>"입력오류", NOT(ISNUMBER(FIND($T$21:$T$34,$P12)))), AND($P12<>"", $P12<>"...", $P12<>"입력오류", $T$19=$P12) ) ) )} -> FALSE | X12: 은행채A- | AA12: 공모/무보증BB+
A13: 00012 | B13: CJ대한통운 | C13: 0000N | D13: 어프로티움(신한은행보증) | E13: 00049 | F13: 대동 | I13: =ROW()-1 -> 12 | J13: =IF( $I13>$G$4, NA(), IF($I13>$G$3, $I13-$G$3, IF($I13>$G$2, $I13-$G$2, $I13 ) ) ) -> 12 | K13: =IF( $I13>$G$4, NA(), IF($I13>$G$3, 5, IF($I13>$G$2, 3, 1 ) ) ) -> 1 | L13: =COUNTIF($N$2:N13, N13)=1 -> TRUE | M13: =IF( $Q13, MAX($M$1:M12)+1, 0) -> 10 | N13: {=INDEX($A$9:$F$1048576, $J13, $K13 )} -> 00064 | O13: {=INDEX($B$9:$F$1048576, $J13, $K13 )} -> 동아쏘시오홀딩스 | P13: {=IF( $L13, TRIM(_xll.IMDP("IR", $G$5&$N13, $G$6)), "" )} -> 공모/무보증A0 | Q13: {=IF( $U$1=1, AND($P13<>"", $P13<>"...", $P13<>"입력오류"), IF( $U$18=1, AND($P13<>"", $P13<>"...", $P13<>"입력오류", ISNUMBER(FIND(INDEX($T$2:$T$7,$U$1),$P13))), IF( $U$17="기타", AND($P13<>"", $P13<>"...", $P13<>"입력오류", NOT(ISNUMBER(FIND($T$21:$T$34,$P13)))), AND($P13<>"", $P13<>"...", $P13<>"입력오류", $T$19=$P13) ) ) )} -> TRUE | AA13: 공모/무보증BB0
A14: 00014 | B14: 하이트진로홀딩스 | C14: 0000P | D14: 테크로스(신한은행보증) | E14: 00068 | F14: LS네트웍스 | I14: =ROW()-1 -> 13 | J14: =IF( $I14>$G$4, NA(), IF($I14>$G$3, $I14-$G$3, IF($I14>$G$2, $I14-$G$2, $I14 ) ) ) -> 13 | K14: =IF( $I14>$G$4, NA(), IF($I14>$G$3, 5, IF($I14>$G$2, 3, 1 ) ) ) -> 1 | L14: =COUNTIF($N$2:N14, N14)=1 -> TRUE | M14: =IF( $Q14, MAX($M$1:M13)+1, 0) -> 11 | N14: {=INDEX($A$9:$F$1048576, $J14, $K14 )} -> 00066 | O14: {=INDEX($B$9:$F$1048576, $J14, $K14 )} -> SK하이닉스 | P14: {=IF( $L14, TRIM(_xll.IMDP("IR", $G$5&$N14, $G$6)), "" )} -> 공모/무보증AA0 | Q14: {=IF( $U$1=1, AND($P14<>"", $P14<>"...", $P14<>"입력오류"), IF( $U$18=1, AND($P14<>"", $P14<>"...", $P14<>"입력오류", ISNUMBER(FIND(INDEX($T$2:$T$7,$U$1),$P14))), IF( $U$17="기타", AND($P14<>"", $P14<>"...", $P14<>"입력오류", NOT(ISNUMBER(FIND($T$21:$T$34,$P14)))), AND($P14<>"", $P14<>"...", $P14<>"입력오류", $T$19=$P14) ) ) )} -> TRUE | AA14: 공모/무보증BB-
A15: 00015 | B15: 두산 | C15: 0000Q | D15: 의료법인송은의료재단(보증) | E15: 00072 | F15: 현대건설 | I15: =ROW()-1 -> 14 | J15: =IF( $I15>$G$4, NA(), IF($I15>$G$3, $I15-$G$3, IF($I15>$G$2, $I15-$G$2, $I15 ) ) ) -> 14 | K15: =IF( $I15>$G$4, NA(), IF($I15>$G$3, 5, IF($I15>$G$2, 3, 1 ) ) ) -> 1 | L15: =COUNTIF($N$2:N15, N15)=1 -> TRUE | M15: =IF( $Q15, MAX($M$1:M14)+1, 0) -> 12 | N15: {=INDEX($A$9:$F$1048576, $J15, $K15 )} -> 00072 | O15: {=INDEX($B$9:$F$1048576, $J15, $K15 )} -> 현대건설 | P15: {=IF( $L15, TRIM(_xll.IMDP("IR", $G$5&$N15, $G$6)), "" )} -> 공모/무보증AA- | Q15: {=IF( $U$1=1, AND($P15<>"", $P15<>"...", $P15<>"입력오류"), IF( $U$18=1, AND($P15<>"", $P15<>"...", $P15<>"입력오류", ISNUMBER(FIND(INDEX($T$2:$T$7,$U$1),$P15))), IF( $U$17="기타", AND($P15<>"", $P15<>"...", $P15<>"입력오류", NOT(ISNUMBER(FIND($T$21:$T$34,$P15)))), AND($P15<>"", $P15<>"...", $P15<>"입력오류", $T$19=$P15) ) ) )} -> TRUE | AA15: 공모/무보증B0
A16: 00021 | B16: DL | C16: 0000R | D16: 위드인천에너지(신한은행보증) | E16: 00086 | F16: 건설화학공업 | I16: =ROW()-1 -> 15 | J16: =IF( $I16>$G$4, NA(), IF($I16>$G$3, $I16-$G$3, IF($I16>$G$2, $I16-$G$2, $I16 ) ) ) -> 15 | K16: =IF( $I16>$G$4, NA(), IF($I16>$G$3, 5, IF($I16>$G$2, 3, 1 ) ) ) -> 1 | L16: =COUNTIF($N$2:N16, N16)=1 -> TRUE | M16: =IF( $Q16, MAX($M$1:M15)+1, 0) -> 13 | N16: {=INDEX($A$9:$F$1048576, $J16, $K16 )} -> 00082 | O16: {=INDEX($B$9:$F$1048576, $J16, $K16 )} -> 롯데건설 | P16: {=IF( $L16, TRIM(_xll.IMDP("IR", $G$5&$N16, $G$6)), "" )} -> 공모/무보증A+ | Q16: {=IF( $U$1=1, AND($P16<>"", $P16<>"...", $P16<>"입력오류"), IF( $U$18=1, AND($P16<>"", $P16<>"...", $P16<>"입력오류", ISNUMBER(FIND(INDEX($T$2:$T$7,$U$1),$P16))), IF( $U$17="기타", AND($P16<>"", $P16<>"...", $P16<>"입력오류", NOT(ISNUMBER(FIND($T$21:$T$34,$P16)))), AND($P16<>"", $P16<>"...", $P16<>"입력오류", $T$19=$P16) ) ) )} -> TRUE
A17: 00027 | B17: 기아 | C17: 0000S | D17: 미래(신한은행보증) | E17: 00088 | F17: 한화 | I17: =ROW()-1 -> 16 | J17: =IF( $I17>$G$4, NA(), IF($I17>$G$3, $I17-$G$3, IF($I17>$G$2, $I17-$G$2, $I17 ) ) ) -> 16 | K17: =IF( $I17>$G$4, NA(), IF($I17>$G$3, 5, IF($I17>$G$2, 3, 1 ) ) ) -> 1 | L17: =COUNTIF($N$2:N17, N17)=1 -> TRUE | M17: =IF( $Q17, MAX($M$1:M16)+1, 0) -> 14 | N17: {=INDEX($A$9:$F$1048576, $J17, $K17 )} -> 00088 | O17: {=INDEX($B$9:$F$1048576, $J17, $K17 )} -> 한화 | P17: {=IF( $L17, TRIM(_xll.IMDP("IR", $G$5&$N17, $G$6)), "" )} -> 공모/무보증A+ | Q17: {=IF( $U$1=1, AND($P17<>"", $P17<>"...", $P17<>"입력오류"), IF( $U$18=1, AND($P17<>"", $P17<>"...", $P17<>"입력오류", ISNUMBER(FIND(INDEX($T$2:$T$7,$U$1),$P17))), IF( $U$17="기타", AND($P17<>"", $P17<>"...", $P17<>"입력오류", NOT(ISNUMBER(FIND($T$21:$T$34,$P17)))), AND($P17<>"", $P17<>"...", $P17<>"입력오류", $T$19=$P17) ) ) )} -> TRUE | U17: {=INDEX($U$19:$U$34, $U$18)} -> 전체
A18: 00030 | B18: 대유플러스 | C18: 00012 | D18: CJ대한통운 | E18: 00099 | F18: DB하이텍 | I18: =ROW()-1 -> 17 | J18: =IF( $I18>$G$4, NA(), IF($I18>$G$3, $I18-$G$3, IF($I18>$G$2, $I18-$G$2, $I18 ) ) ) -> 17 | K18: =IF( $I18>$G$4, NA(), IF($I18>$G$3, 5, IF($I18>$G$2, 3, 1 ) ) ) -> 1 | L18: =COUNTIF($N$2:N18, N18)=1 -> TRUE | M18: =IF( $Q18, MAX($M$1:M17)+1, 0) -> 15 | N18: {=INDEX($A$9:$F$1048576, $J18, $K18 )} -> 00104 | O18: {=INDEX($B$9:$F$1048576, $J18, $K18 )} -> CJ | P18: {=IF( $L18, TRIM(_xll.IMDP("IR", $G$5&$N18, $G$6)), "" )} -> 공모/무보증AA- | Q18: {=IF( $U$1=1, AND($P18<>"", $P18<>"...", $P18<>"입력오류"), IF( $U$18=1, AND($P18<>"", $P18<>"...", $P18<>"입력오류", ISNUMBER(FIND(INDEX($T$2:$T$7,$U$1),$P18))), IF( $U$17="기타", AND($P18<>"", $P18<>"...", $P18<>"입력오류", NOT(ISNUMBER(FIND($T$21:$T$34,$P18)))), AND($P18<>"", $P18<>"...", $P18<>"입력오류", $T$19=$P18) ) ) )} -> TRUE | U18: 1
A19: 00049 | B19: 대동 | C19: 00014 | D19: 하이트진로홀딩스 | E19: 00106 | F19: JW중외제약 | I19: =ROW()-1 -> 18 | J19: =IF( $I19>$G$4, NA(), IF($I19>$G$3, $I19-$G$3, IF($I19>$G$2, $I19-$G$2, $I19 ) ) ) -> 18 | K19: =IF( $I19>$G$4, NA(), IF($I19>$G$3, 5, IF($I19>$G$2, 3, 1 ) ) ) -> 1 | L19: =COUNTIF($N$2:N19, N19)=1 -> TRUE | M19: =IF( $Q19, MAX($M$1:M18)+1, 0) -> 16 | N19: {=INDEX($A$9:$F$1048576, $J19, $K19 )} -> 00112 | O19: {=INDEX($B$9:$F$1048576, $J19, $K19 )} -> LX인터내셔널 | P19: {=IF( $L19, TRIM(_xll.IMDP("IR", $G$5&$N19, $G$6)), "" )} -> 공모/무보증AA- | Q19: {=IF( $U$1=1, AND($P19<>"", $P19<>"...", $P19<>"입력오류"), IF( $U$18=1, AND($P19<>"", $P19<>"...", $P19<>"입력오류", ISNUMBER(FIND(INDEX($T$2:$T$7,$U$1),$P19))), IF( $U$17="기타", AND($P19<>"", $P19<>"...", $P19<>"입력오류", NOT(ISNUMBER(FIND($T$21:$T$34,$P19)))), AND($P19<>"", $P19<>"...", $P19<>"입력오류", $T$19=$P19) ) ) )} -> TRUE | T19: {=INDEX($W$1:$AA$15, $U$18, $U$1-1)} -> #VALUE! | U19: {=IF( $U$1=1, "전체", IFERROR( INDEX($W$19:$AA$34, ROW()-ROW(U$18), $U$1-1),"") )} -> 전체 | W19: 전체 | X19: 전체 | Y19: 전체 | Z19: 전체 | AA19: 전체
A20: 00064 | B20: 동아쏘시오홀딩스 | C20: 00015 | D20: 두산 | E20: 00123 | F20: 동국제강 | I20: =ROW()-1 -> 19 | J20: =IF( $I20>$G$4, NA(), IF($I20>$G$3, $I20-$G$3, IF($I20>$G$2, $I20-$G$2, $I20 ) ) ) -> 19 | K20: =IF( $I20>$G$4, NA(), IF($I20>$G$3, 5, IF($I20>$G$2, 3, 1 ) ) ) -> 1 | L20: =COUNTIF($N$2:N20, N20)=1 -> TRUE | M20: =IF( $Q20, MAX($M$1:M19)+1, 0) -> 0 | N20: {=INDEX($A$9:$F$1048576, $J20, $K20 )} -> 00120 | O20: {=INDEX($B$9:$F$1048576, $J20, $K20 )} -> 유진증권 | P20: {=IF( $L20, TRIM(_xll.IMDP("IR", $G$5&$N20, $G$6)), "" )} | Q20: {=IF( $U$1=1, AND($P20<>"", $P20<>"...", $P20<>"입력오류"), IF( $U$18=1, AND($P20<>"", $P20<>"...", $P20<>"입력오류", ISNUMBER(FIND(INDEX($T$2:$T$7,$U$1),$P20))), IF( $U$17="기타", AND($P20<>"", $P20<>"...", $P20<>"입력오류", NOT(ISNUMBER(FIND($T$21:$T$34,$P20)))), AND($P20<>"", $P20<>"...", $P20<>"입력오류", $T$19=$P20) ) ) )} -> FALSE | U20: {=IF( $U$1=1, "", IFERROR( INDEX($W$19:$AA$34, ROW()-ROW(U$18), $U$1-1),"") )} | W20: 정부보증 | X20: AAA(산금-이표) | Y20: AAA | Z20: AAA | AA20: 공모/무보증 AAA
A21: 00066 | B21: SK하이닉스 | C21: 00043 | D21: 대원강업 | E21: 00129 | F21: 상상인증권 | I21: =ROW()-1 -> 20 | J21: =IF( $I21>$G$4, NA(), IF($I21>$G$3, $I21-$G$3, IF($I21>$G$2, $I21-$G$2, $I21 ) ) ) -> 20 | K21: =IF( $I21>$G$4, NA(), IF($I21>$G$3, 5, IF($I21>$G$2, 3, 1 ) ) ) -> 1 | L21: =COUNTIF($N$2:N21, N21)=1 -> TRUE | M21: =IF( $Q21, MAX($M$1:M20)+1, 0) -> 17 | N21: {=INDEX($A$9:$F$1048576, $J21, $K21 )} -> 00125 | O21: {=INDEX($B$9:$F$1048576, $J21, $K21 )} -> GS글로벌 | P21: {=IF( $L21, TRIM(_xll.IMDP("IR", $G$5&$N21, $G$6)), "" )} -> 공모/무보증A0 | Q21: {=IF( $U$1=1, AND($P21<>"", $P21<>"...", $P21<>"입력오류"), IF( $U$18=1, AND($P21<>"", $P21<>"...", $P21<>"입력오류", ISNUMBER(FIND(INDEX($T$2:$T$7,$U$1),$P21))), IF( $U$17="기타", AND($P21<>"", $P21<>"...", $P21<>"입력오류", NOT(ISNUMBER(FIND($T$21:$T$34,$P21)))), AND($P21<>"", $P21<>"...", $P21<>"입력오류", $T$19=$P21) ) ) )} -> TRUE | T21: =IF( CHOOSE($U$1-1, $W2,$X2,$Y2,$Z2,$AA2)=0, "", CHOOSE($U$1-1, $W2,$X2,$Y2,$Z2,$AA2) ) -> #VALUE! | U21: {=IF( $U$1=1, "", IFERROR( INDEX($W$19:$AA$34, ROW()-ROW(U$18), $U$1-1),"") )} | W21: AAA | X21: AAA(산금-할인) | Y21: AA+ | Z21: AA+ | AA21: 공모/무보증 AA+
A22: 00072 | B22: 현대건설 | C22: 00049 | D22: 대동 | E22: 00144 | F22: 대한전선 | I22: =ROW()-1 -> 21 | J22: =IF( $I22>$G$4, NA(), IF($I22>$G$3, $I22-$G$3, IF($I22>$G$2, $I22-$G$2, $I22 ) ) ) -> 21 | K22: =IF( $I22>$G$4, NA(), IF($I22>$G$3, 5, IF($I22>$G$2, 3, 1 ) ) ) -> 1 | L22: =COUNTIF($N$2:N22, N22)=1 -> TRUE | M22: =IF( $Q22, MAX($M$1:M21)+1, 0) -> 0 | N22: {=INDEX($A$9:$F$1048576, $J22, $K22 )} -> 00129 | O22: {=INDEX($B$9:$F$1048576, $J22, $K22 )} -> 상상인증권 | P22: {=IF( $L22, TRIM(_xll.IMDP("IR", $G$5&$N22, $G$6)), "" )} | Q22: {=IF( $U$1=1, AND($P22<>"", $P22<>"...", $P22<>"입력오류"), IF( $U$18=1, AND($P22<>"", $P22<>"...", $P22<>"입력오류", ISNUMBER(FIND(INDEX($T$2:$T$7,$U$1),$P22))), IF( $U$17="기타", AND($P22<>"", $P22<>"...", $P22<>"입력오류", NOT(ISNUMBER(FIND($T$21:$T$34,$P22)))), AND($P22<>"", $P22<>"...", $P22<>"입력오류", $T$19=$P22) ) ) )} -> FALSE | T22: =IF( CHOOSE($U$1-1, $W3,$X3,$Y3,$Z3,$AA3)=0, "", CHOOSE($U$1-1, $W3,$X3,$Y3,$Z3,$AA3) ) -> #VALUE! | U22: {=IF( $U$1=1, "", IFERROR( INDEX($W$19:$AA$34, ROW()-ROW(U$18), $U$1-1),"") )} | W22: AA+ | X22: AAA(중금-이표) | Y22: AA | Z22: AA | AA22: 공모/무보증 AA
A23: 00082 | B23: 롯데건설 | C23: 00050 | D23: 가온전선 | E23: 00150 | F23: 현대차증권 | I23: =ROW()-1 -> 22 | J23: =IF( $I23>$G$4, NA(), IF($I23>$G$3, $I23-$G$3, IF($I23>$G$2, $I23-$G$2, $I23 ) ) ) -> 22 | K23: =IF( $I23>$G$4, NA(), IF($I23>$G$3, 5, IF($I23>$G$2, 3, 1 ) ) ) -> 1 | L23: =COUNTIF($N$2:N23, N23)=1 -> TRUE | M23: =IF( $Q23, MAX($M$1:M22)+1, 0) -> 0 | N23: {=INDEX($A$9:$F$1048576, $J23, $K23 )} -> 00132 | O23: {=INDEX($B$9:$F$1048576, $J23, $K23 )} -> 흥아 | P23: {=IF( $L23, TRIM(_xll.IMDP("IR", $G$5&$N23, $G$6)), "" )} | Q23: {=IF( $U$1=1, AND($P23<>"", $P23<>"...", $P23<>"입력오류"), IF( $U$18=1, AND($P23<>"", $P23<>"...", $P23<>"입력오류", ISNUMBER(FIND(INDEX($T$2:$T$7,$U$1),$P23))), IF( $U$17="기타", AND($P23<>"", $P23<>"...", $P23<>"입력오류", NOT(ISNUMBER(FIND($T$21:$T$34,$P23)))), AND($P23<>"", $P23<>"...", $P23<>"입력오류", $T$19=$P23) ) ) )} -> FALSE | T23: =IF( CHOOSE($U$1-1, $W4,$X4,$Y4,$Z4,$AA4)=0, "", CHOOSE($U$1-1, $W4,$X4,$Y4,$Z4,$AA4) ) -> #VALUE! | U23: {=IF( $U$1=1, "", IFERROR( INDEX($W$19:$AA$34, ROW()-ROW(U$18), $U$1-1),"") )} | W23: AA | X23: AAA(중금-할인) | Y23: AA- | Z23: AA- | AA23: 공모/무보증 AA-
A24: 00088 | B24: 한화 | C24: 00066 | D24: SK하이닉스 | E24: 00151 | F24: SK증권 | I24: =ROW()-1 -> 23 | J24: =IF( $I24>$G$4, NA(), IF($I24>$G$3, $I24-$G$3, IF($I24>$G$2, $I24-$G$2, $I24 ) ) ) -> 23 | K24: =IF( $I24>$G$4, NA(), IF($I24>$G$3, 5, IF($I24>$G$2, 3, 1 ) ) ) -> 1 | L24: =COUNTIF($N$2:N24, N24)=1 -> TRUE | M24: =IF( $Q24, MAX($M$1:M23)+1, 0) -> 18 | N24: {=INDEX($A$9:$F$1048576, $J24, $K24 )} -> 00150 | O24: {=INDEX($B$9:$F$1048576, $J24, $K24 )} -> 현대차증권 | P24: {=IF( $L24, TRIM(_xll.IMDP("IR", $G$5&$N24, $G$6)), "" )} -> 공모/무보증AA- | Q24: {=IF( $U$1=1, AND($P24<>"", $P24<>"...", $P24<>"입력오류"), IF( $U$18=1, AND($P24<>"", $P24<>"...", $P24<>"입력오류", ISNUMBER(FIND(INDEX($T$2:$T$7,$U$1),$P24))), IF( $U$17="기타", AND($P24<>"", $P24<>"...", $P24<>"입력오류", NOT(ISNUMBER(FIND($T$21:$T$34,$P24)))), AND($P24<>"", $P24<>"...", $P24<>"입력오류", $T$19=$P24) ) ) )} -> TRUE | T24: =IF( CHOOSE($U$1-1, $W5,$X5,$Y5,$Z5,$AA5)=0, "", CHOOSE($U$1-1, $W5,$X5,$Y5,$Z5,$AA5) ) -> #VALUE! | U24: {=IF( $U$1=1, "", IFERROR( INDEX($W$19:$AA$34, ROW()-ROW(U$18), $U$1-1),"") )} | W24: AA- | X24: AAA | Y24: A+ | Z24: A+ | AA24: 공모/무보증 A+
A25: 00104 | B25: CJ | C25: 00082 | D25: 롯데건설 | E25: 00172 | F25: 신영증권 | I25: =ROW()-1 -> 24 | J25: =IF( $I25>$G$4, NA(), IF($I25>$G$3, $I25-$G$3, IF($I25>$G$2, $I25-$G$2, $I25 ) ) ) -> 24 | K25: =IF( $I25>$G$4, NA(), IF($I25>$G$3, 5, IF($I25>$G$2, 3, 1 ) ) ) -> 1 | L25: =COUNTIF($N$2:N25, N25)=1 -> TRUE | M25: =IF( $Q25, MAX($M$1:M24)+1, 0) -> 0 | N25: {=INDEX($A$9:$F$1048576, $J25, $K25 )} -> 00151 | O25: {=INDEX($B$9:$F$1048576, $J25, $K25 )} -> SK증권 | P25: {=IF( $L25, TRIM(_xll.IMDP("IR", $G$5&$N25, $G$6)), "" )} | Q25: {=IF( $U$1=1, AND($P25<>"", $P25<>"...", $P25<>"입력오류"), IF( $U$18=1, AND($P25<>"", $P25<>"...", $P25<>"입력오류", ISNUMBER(FIND(INDEX($T$2:$T$7,$U$1),$P25))), IF( $U$17="기타", AND($P25<>"", $P25<>"...", $P25<>"입력오류", NOT(ISNUMBER(FIND($T$21:$T$34,$P25)))), AND($P25<>"", $P25<>"...", $P25<>"입력오류", $T$19=$P25) ) ) )} -> FALSE | T25: =IF( CHOOSE($U$1-1, $W6,$X6,$Y6,$Z6,$AA6)=0, "", CHOOSE($U$1-1, $W6,$X6,$Y6,$Z6,$AA6) ) -> #VALUE! | U25: {=IF( $U$1=1, "", IFERROR( INDEX($W$19:$AA$34, ROW()-ROW(U$18), $U$1-1),"") )} | W25: 기타 | X25: AA+ | Y25: A | Z25: A | AA25: 공모/무보증 A
A26: 00112 | B26: LX인터내셔널 | C26: 00088 | D26: 한화 | E26: 00174 | F26: SK네트웍스 | I26: =ROW()-1 -> 25 | J26: =IF( $I26>$G$4, NA(), IF($I26>$G$3, $I26-$G$3, IF($I26>$G$2, $I26-$G$2, $I26 ) ) ) -> 25 | K26: =IF( $I26>$G$4, NA(), IF($I26>$G$3, 5, IF($I26>$G$2, 3, 1 ) ) ) -> 1 | L26: =COUNTIF($N$2:N26, N26)=1 -> TRUE | M26: =IF( $Q26, MAX($M$1:M25)+1, 0) -> 0 | N26: {=INDEX($A$9:$F$1048576, $J26, $K26 )} -> 00157 | O26: {=INDEX($B$9:$F$1048576, $J26, $K26 )} -> 금양 | P26: {=IF( $L26, TRIM(_xll.IMDP("IR", $G$5&$N26, $G$6)), "" )} | Q26: {=IF( $U$1=1, AND($P26<>"", $P26<>"...", $P26<>"입력오류"), IF( $U$18=1, AND($P26<>"", $P26<>"...", $P26<>"입력오류", ISNUMBER(FIND(INDEX($T$2:$T$7,$U$1),$P26))), IF( $U$17="기타", AND($P26<>"", $P26<>"...", $P26<>"입력오류", NOT(ISNUMBER(FIND($T$21:$T$34,$P26)))), AND($P26<>"", $P26<>"...", $P26<>"입력오류", $T$19=$P26) ) ) )} -> FALSE | T26: =IF( CHOOSE($U$1-1, $W7,$X7,$Y7,$Z7,$AA7)=0, "", CHOOSE($U$1-1, $W7,$X7,$Y7,$Z7,$AA7) ) -> #VALUE! | U26: {=IF( $U$1=1, "", IFERROR( INDEX($W$19:$AA$34, ROW()-ROW(U$18), $U$1-1),"") )} | W26: #N/A | X26: AA | Y26: A- | Z26: A- | AA26: 공모/무보증 A-
A27: 00120 | B27: 유진증권 | C27: 00104 | D27: CJ | E27: 00175 | F27: 한양증권 | I27: =ROW()-1 -> 26 | J27: =IF( $I27>$G$4, NA(), IF($I27>$G$3, $I27-$G$3, IF($I27>$G$2, $I27-$G$2, $I27 ) ) ) -> 26 | K27: =IF( $I27>$G$4, NA(), IF($I27>$G$3, 5, IF($I27>$G$2, 3, 1 ) ) ) -> 1 | L27: =COUNTIF($N$2:N27, N27)=1 -> TRUE | M27: =IF( $Q27, MAX($M$1:M26)+1, 0) -> 0 | N27: {=INDEX($A$9:$F$1048576, $J27, $K27 )} -> 00162 | O27: {=INDEX($B$9:$F$1048576, $J27, $K27 )} -> 케이비아이동국실업 | P27: {=IF( $L27, TRIM(_xll.IMDP("IR", $G$5&$N27, $G$6)), "" )} | Q27: {=IF( $U$1=1, AND($P27<>"", $P27<>"...", $P27<>"입력오류"), IF( $U$18=1, AND($P27<>"", $P27<>"...", $P27<>"입력오류", ISNUMBER(FIND(INDEX($T$2:$T$7,$U$1),$P27))), IF( $U$17="기타", AND($P27<>"", $P27<>"...", $P27<>"입력오류", NOT(ISNUMBER(FIND($T$21:$T$34,$P27)))), AND($P27<>"", $P27<>"...", $P27<>"입력오류", $T$19=$P27) ) ) )} -> FALSE | T27: =IF( CHOOSE($U$1-1, $W8,$X8,$Y8,$Z8,$AA8)=0, "", CHOOSE($U$1-1, $W8,$X8,$Y8,$Z8,$AA8) ) -> #VALUE! | U27: {=IF( $U$1=1, "", IFERROR( INDEX($W$19:$AA$34, ROW()-ROW(U$18), $U$1-1),"") )} | W27: #N/A | X27: AA- | Y27: BBB+ | Z27: BBB+ | AA27: 공모/무보증 BBB+
A28: 00125 | B28: GS글로벌 | C28: 00120 | D28: 유진증권 | E28: 00178 | F28: 알루코 | I28: =ROW()-1 -> 27 | J28: =IF( $I28>$G$4, NA(), IF($I28>$G$3, $I28-$G$3, IF($I28>$G$2, $I28-$G$2, $I28 ) ) ) -> 27 | K28: =IF( $I28>$G$4, NA(), IF($I28>$G$3, 5, IF($I28>$G$2, 3, 1 ) ) ) -> 1 | L28: =COUNTIF($N$2:N28, N28)=1 -> TRUE | M28: =IF( $Q28, MAX($M$1:M27)+1, 0) -> 19 | N28: {=INDEX($A$9:$F$1048576, $J28, $K28 )} -> 00163 | O28: {=INDEX($B$9:$F$1048576, $J28, $K28 )} -> 종근당홀딩스 | P28: {=IF( $L28, TRIM(_xll.IMDP("IR", $G$5&$N28, $G$6)), "" )} -> 공모/무보증A+ | Q28: {=IF( $U$1=1, AND($P28<>"", $P28<>"...", $P28<>"입력오류"), IF( $U$18=1, AND($P28<>"", $P28<>"...", $P28<>"입력오류", ISNUMBER(FIND(INDEX($T$2:$T$7,$U$1),$P28))), IF( $U$17="기타", AND($P28<>"", $P28<>"...", $P28<>"입력오류", NOT(ISNUMBER(FIND($T$21:$T$34,$P28)))), AND($P28<>"", $P28<>"...", $P28<>"입력오류", $T$19=$P28) ) ) )} -> TRUE | T28: =IF( CHOOSE($U$1-1, $W9,$X9,$Y9,$Z9,$AA9)=0, "", CHOOSE($U$1-1, $W9,$X9,$Y9,$Z9,$AA9) ) -> #VALUE! | U28: {=IF( $U$1=1, "", IFERROR( INDEX($W$19:$AA$34, ROW()-ROW(U$18), $U$1-1),"") )} | W28: #N/A | X28: A+ | Y28: BBB | Z28: BBB | AA28: 공모/무보증 BBB
A29: 00129 | B29: 상상인증권 | C29: 00127 | D29: 부국증권 | E29: 00188 | F29: DL건설 | I29: =ROW()-1 -> 28 | J29: =IF( $I29>$G$4, NA(), IF($I29>$G$3, $I29-$G$3, IF($I29>$G$2, $I29-$G$2, $I29 ) ) ) -> 28 | K29: =IF( $I29>$G$4, NA(), IF($I29>$G$3, 5, IF($I29>$G$2, 3, 1 ) ) ) -> 1 | L29: =COUNTIF($N$2:N29, N29)=1 -> TRUE | M29: =IF( $Q29, MAX($M$1:M28)+1, 0) -> 20 | N29: {=INDEX($A$9:$F$1048576, $J29, $K29 )} -> 00168 | O29: {=INDEX($B$9:$F$1048576, $J29, $K29 )} -> 대상 | P29: {=IF( $L29, TRIM(_xll.IMDP("IR", $G$5&$N29, $G$6)), "" )} -> 공모/무보증AA- | Q29: {=IF( $U$1=1, AND($P29<>"", $P29<>"...", $P29<>"입력오류"), IF( $U$18=1, AND($P29<>"", $P29<>"...", $P29<>"입력오류", ISNUMBER(FIND(INDEX($T$2:$T$7,$U$1),$P29))), IF( $U$17="기타", AND($P29<>"", $P29<>"...", $P29<>"입력오류", NOT(ISNUMBER(FIND($T$21:$T$34,$P29)))), AND($P29<>"", $P29<>"...", $P29<>"입력오류", $T$19=$P29) ) ) )} -> TRUE | T29: =IF( CHOOSE($U$1-1, $W10,$X10,$Y10,$Z10,$AA10)=0, "", CHOOSE($U$1-1, $W10,$X10,$Y10,$Z10,$AA10) ) -> #VALUE! | U29: {=IF( $U$1=1, "", IFERROR( INDEX($W$19:$AA$34, ROW()-ROW(U$18), $U$1-1),"") )} | W29: #N/A | X29: A | Y29: BBB- | Z29: BBB- | AA29: 공모/무보증 BBB-
A30: 00132 | B30: 흥아 | C30: 00129 | D30: 상상인증권 | E30: 00235 | F30: 넥센타이어 | I30: =ROW()-1 -> 29 | J30: =IF( $I30>$G$4, NA(), IF($I30>$G$3, $I30-$G$3, IF($I30>$G$2, $I30-$G$2, $I30 ) ) ) -> 29 | K30: =IF( $I30>$G$4, NA(), IF($I30>$G$3, 5, IF($I30>$G$2, 3, 1 ) ) ) -> 1 | L30: =COUNTIF($N$2:N30, N30)=1 -> TRUE | M30: =IF( $Q30, MAX($M$1:M29)+1, 0) -> 0 | N30: {=INDEX($A$9:$F$1048576, $J30, $K30 )} -> 00172 | O30: {=INDEX($B$9:$F$1048576, $J30, $K30 )} -> 신영증권 | P30: {=IF( $L30, TRIM(_xll.IMDP("IR", $G$5&$N30, $G$6)), "" )} | Q30: {=IF( $U$1=1, AND($P30<>"", $P30<>"...", $P30<>"입력오류"), IF( $U$18=1, AND($P30<>"", $P30<>"...", $P30<>"입력오류", ISNUMBER(FIND(INDEX($T$2:$T$7,$U$1),$P30))), IF( $U$17="기타", AND($P30<>"", $P30<>"...", $P30<>"입력오류", NOT(ISNUMBER(FIND($T$21:$T$34,$P30)))), AND($P30<>"", $P30<>"...", $P30<>"입력오류", $T$19=$P30) ) ) )} -> FALSE | T30: =IF( CHOOSE($U$1-1, $W11,$X11,$Y11,$Z11,$AA11)=0, "", CHOOSE($U$1-1, $W11,$X11,$Y11,$Z11,$AA11) ) -> #VALUE! | U30: {=IF( $U$1=1, "", IFERROR( INDEX($W$19:$AA$34, ROW()-ROW(U$18), $U$1-1),"") )} | W30: #N/A | X30: A- | Y30: 기타 | Z30: 기타 | AA30: 공모/무보증 BB+
A31: 00150 | B31: 현대차증권 | C31: 00143 | D31: 세아베스틸지주 | E31: 00238 | F31: 케이씨씨 | I31: =ROW()-1 -> 30 | J31: =IF( $I31>$G$4, NA(), IF($I31>$G$3, $I31-$G$3, IF($I31>$G$2, $I31-$G$2, $I31 ) ) ) -> 30 | K31: =IF( $I31>$G$4, NA(), IF($I31>$G$3, 5, IF($I31>$G$2, 3, 1 ) ) ) -> 1 | L31: =COUNTIF($N$2:N31, N31)=1 -> TRUE | M31: =IF( $Q31, MAX($M$1:M30)+1, 0) -> 21 | N31: {=INDEX($A$9:$F$1048576, $J31, $K31 )} -> 00174 | O31: {=INDEX($B$9:$F$1048576, $J31, $K31 )} -> SK네트웍스 | P31: {=IF( $L31, TRIM(_xll.IMDP("IR", $G$5&$N31, $G$6)), "" )} -> 공모/무보증AA- | Q31: {=IF( $U$1=1, AND($P31<>"", $P31<>"...", $P31<>"입력오류"), IF( $U$18=1, AND($P31<>"", $P31<>"...", $P31<>"입력오류", ISNUMBER(FIND(INDEX($T$2:$T$7,$U$1),$P31))), IF( $U$17="기타", AND($P31<>"", $P31<>"...", $P31<>"입력오류", NOT(ISNUMBER(FIND($T$21:$T$34,$P31)))), AND($P31<>"", $P31<>"...", $P31<>"입력오류", $T$19=$P31) ) ) )} -> TRUE | T31: =IF( CHOOSE($U$1-1, $W12,$X12,$Y12,$Z12,$AA12)=0, "", CHOOSE($U$1-1, $W12,$X12,$Y12,$Z12,$AA12) ) -> #VALUE! | U31: {=IF( $U$1=1, "", IFERROR( INDEX($W$19:$AA$34, ROW()-ROW(U$18), $U$1-1),"") )} | W31: #N/A | X31: 기타 | Y31: #N/A | Z31: #N/A | AA31: 공모/무보증 BB
A32: 00151 | B32: SK증권 | C32: 00150 | D32: 현대차증권 | E32: 00255 | F32: KB손해보험 | I32: =ROW()-1 -> 31 | J32: =IF( $I32>$G$4, NA(), IF($I32>$G$3, $I32-$G$3, IF($I32>$G$2, $I32-$G$2, $I32 ) ) ) -> 31 | K32: =IF( $I32>$G$4, NA(), IF($I32>$G$3, 5, IF($I32>$G$2, 3, 1 ) ) ) -> 1 | L32: =COUNTIF($N$2:N32, N32)=1 -> TRUE | M32: =IF( $Q32, MAX($M$1:M31)+1, 0) -> 0 | N32: {=INDEX($A$9:$F$1048576, $J32, $K32 )} -> 00178 | O32: {=INDEX($B$9:$F$1048576, $J32, $K32 )} -> 알루코 | P32: {=IF( $L32, TRIM(_xll.IMDP("IR", $G$5&$N32, $G$6)), "" )} | Q32: {=IF( $U$1=1, AND($P32<>"", $P32<>"...", $P32<>"입력오류"), IF( $U$18=1, AND($P32<>"", $P32<>"...", $P32<>"입력오류", ISNUMBER(FIND(INDEX($T$2:$T$7,$U$1),$P32))), IF( $U$17="기타", AND($P32<>"", $P32<>"...", $P32<>"입력오류", NOT(ISNUMBER(FIND($T$21:$T$34,$P32)))), AND($P32<>"", $P32<>"...", $P32<>"입력오류", $T$19=$P32) ) ) )} -> FALSE | T32: =IF( CHOOSE($U$1-1, $W13,$X13,$Y13,$Z13,$AA13)=0, "", CHOOSE($U$1-1, $W13,$X13,$Y13,$Z13,$AA13) ) -> #VALUE! | U32: {=IF( $U$1=1, "", IFERROR( INDEX($W$19:$AA$34, ROW()-ROW(U$18), $U$1-1),"") )} | W32: #N/A | X32: #N/A | Y32: #N/A | Z32: #N/A | AA32: 공모/무보증 BB-
A33: 00157 | B33: 금양 | C33: 00151 | D33: SK증권 | E33: 00278 | F33: 진흥기업 | I33: =ROW()-1 -> 32 | J33: =IF( $I33>$G$4, NA(), IF($I33>$G$3, $I33-$G$3, IF($I33>$G$2, $I33-$G$2, $I33 ) ) ) -> 32 | K33: =IF( $I33>$G$4, NA(), IF($I33>$G$3, 5, IF($I33>$G$2, 3, 1 ) ) ) -> 1 | L33: =COUNTIF($N$2:N33, N33)=1 -> TRUE | M33: =IF( $Q33, MAX($M$1:M32)+1, 0) -> 22 | N33: {=INDEX($A$9:$F$1048576, $J33, $K33 )} -> 00179 | O33: {=INDEX($B$9:$F$1048576, $J33, $K33 )} -> 대한제당 | P33: {=IF( $L33, TRIM(_xll.IMDP("IR", $G$5&$N33, $G$6)), "" )} -> 공모/무보증A- | Q33: {=IF( $U$1=1, AND($P33<>"", $P33<>"...", $P33<>"입력오류"), IF( $U$18=1, AND($P33<>"", $P33<>"...", $P33<>"입력오류", ISNUMBER(FIND(INDEX($T$2:$T$7,$U$1),$P33))), IF( $U$17="기타", AND($P33<>"", $P33<>"...", $P33<>"입력오류", NOT(ISNUMBER(FIND($T$21:$T$34,$P33)))), AND($P33<>"", $P33<>"...", $P33<>"입력오류", $T$19=$P33) ) ) )} -> TRUE | T33: =IF( CHOOSE($U$1-1, $W14,$X14,$Y14,$Z14,$AA14)=0, "", CHOOSE($U$1-1, $W14,$X14,$Y14,$Z14,$AA14) ) -> #VALUE! | U33: {=IF( $U$1=1, "", IFERROR( INDEX($W$19:$AA$34, ROW()-ROW(U$18), $U$1-1),"") )} | W33: #N/A | X33: #N/A | Y33: #N/A | Z33: #N/A | AA33: 공모/무보증 B
A34: 00162 | B34: 케이비아이동국실업 | C34: 00172 | D34: 신영증권 | E34: 00290 | F34: TYM | I34: =ROW()-1 -> 33 | J34: =IF( $I34>$G$4, NA(), IF($I34>$G$3, $I34-$G$3, IF($I34>$G$2, $I34-$G$2, $I34 ) ) ) -> 33 | K34: =IF( $I34>$G$4, NA(), IF($I34>$G$3, 5, IF($I34>$G$2, 3, 1 ) ) ) -> 1 | L34: =COUNTIF($N$2:N34, N34)=1 -> TRUE | M34: =IF( $Q34, MAX($M$1:M33)+1, 0) -> 23 | N34: {=INDEX($A$9:$F$1048576, $J34, $K34 )} -> 00188 | O34: {=INDEX($B$9:$F$1048576, $J34, $K34 )} -> DL건설 | P34: {=IF( $L34, TRIM(_xll.IMDP("IR", $G$5&$N34, $G$6)), "" )} -> 공모/무보증A- | Q34: {=IF( $U$1=1, AND($P34<>"", $P34<>"...", $P34<>"입력오류"), IF( $U$18=1, AND($P34<>"", $P34<>"...", $P34<>"입력오류", ISNUMBER(FIND(INDEX($T$2:$T$7,$U$1),$P34))), IF( $U$17="기타", AND($P34<>"", $P34<>"...", $P34<>"입력오류", NOT(ISNUMBER(FIND($T$21:$T$34,$P34)))), AND($P34<>"", $P34<>"...", $P34<>"입력오류", $T$19=$P34) ) ) )} -> TRUE | T34: =IF( CHOOSE($U$1-1, $W15,$X15,$Y15,$Z15,$AA15)=0, "", CHOOSE($U$1-1, $W15,$X15,$Y15,$Z15,$AA15) ) -> #VALUE! | U34: {=IF( $U$1=1, "", IFERROR( INDEX($W$19:$AA$34, ROW()-ROW(U$18), $U$1-1),"") )} | W34: #N/A | X34: #N/A | Y34: #N/A | Z34: #N/A | AA34: 기타
A35: 00163 | B35: 종근당홀딩스 | C35: 00174 | D35: SK네트웍스 | E35: 00299 | F35: 금호건설 | I35: =ROW()-1 -> 34 | J35: =IF( $I35>$G$4, NA(), IF($I35>$G$3, $I35-$G$3, IF($I35>$G$2, $I35-$G$2, $I35 ) ) ) -> 34 | K35: =IF( $I35>$G$4, NA(), IF($I35>$G$3, 5, IF($I35>$G$2, 3, 1 ) ) ) -> 1 | L35: =COUNTIF($N$2:N35, N35)=1 -> TRUE | M35: =IF( $Q35, MAX($M$1:M34)+1, 0) -> 0 | N35: {=INDEX($A$9:$F$1048576, $J35, $K35 )} -> 00202 | O35: {=INDEX($B$9:$F$1048576, $J35, $K35 )} -> 코오롱 | P35: {=IF( $L35, TRIM(_xll.IMDP("IR", $G$5&$N35, $G$6)), "" )} | Q35: {=IF( $U$1=1, AND($P35<>"", $P35<>"...", $P35<>"입력오류"), IF( $U$18=1, AND($P35<>"", $P35<>"...", $P35<>"입력오류", ISNUMBER(FIND(INDEX($T$2:$T$7,$U$1),$P35))), IF( $U$17="기타", AND($P35<>"", $P35<>"...", $P35<>"입력오류", NOT(ISNUMBER(FIND($T$21:$T$34,$P35)))), AND($P35<>"", $P35<>"...", $P35<>"입력오류", $T$19=$P35) ) ) )} -> FALSE
A36: 00168 | B36: 대상 | C36: 00175 | D36: 한양증권 | E36: 00338 | F36: 하림지주 | I36: =ROW()-1 -> 35 | J36: =IF( $I36>$G$4, NA(), IF($I36>$G$3, $I36-$G$3, IF($I36>$G$2, $I36-$G$2, $I36 ) ) ) -> 35 | K36: =IF( $I36>$G$4, NA(), IF($I36>$G$3, 5, IF($I36>$G$2, 3, 1 ) ) ) -> 1 | L36: =COUNTIF($N$2:N36, N36)=1 -> TRUE | M36: =IF( $Q36, MAX($M$1:M35)+1, 0) -> 24 | N36: {=INDEX($A$9:$F$1048576, $J36, $K36 )} -> 00232 | O36: {=INDEX($B$9:$F$1048576, $J36, $K36 )} -> 한진 | P36: {=IF( $L36, TRIM(_xll.IMDP("IR", $G$5&$N36, $G$6)), "" )} -> 공모/무보증BBB+ | Q36: {=IF( $U$1=1, AND($P36<>"", $P36<>"...", $P36<>"입력오류"), IF( $U$18=1, AND($P36<>"", $P36<>"...", $P36<>"입력오류", ISNUMBER(FIND(INDEX($T$2:$T$7,$U$1),$P36))), IF( $U$17="기타", AND($P36<>"", $P36<>"...", $P36<>"입력오류", NOT(ISNUMBER(FIND($T$21:$T$34,$P36)))), AND($P36<>"", $P36<>"...", $P36<>"입력오류", $T$19=$P36) ) ) )} -> TRUE
A37: 00172 | B37: 신영증권 | C37: 00180 | D37: 오리온홀딩스 | E37: 00347 | F37: 유안타증권 | I37: =ROW()-1 -> 36 | J37: =IF( $I37>$G$4, NA(), IF($I37>$G$3, $I37-$G$3, IF($I37>$G$2, $I37-$G$2, $I37 ) ) ) -> 36 | K37: =IF( $I37>$G$4, NA(), IF($I37>$G$3, 5, IF($I37>$G$2, 3, 1 ) ) ) -> 1 | L37: =COUNTIF($N$2:N37, N37)=1 -> TRUE | M37: =IF( $Q37, MAX($M$1:M36)+1, 0) -> 25 | N37: {=INDEX($A$9:$F$1048576, $J37, $K37 )} -> 00235 | O37: {=INDEX($B$9:$F$1048576, $J37, $K37 )} -> 넥센타이어 | P37: {=IF( $L37, TRIM(_xll.IMDP("IR", $G$5&$N37, $G$6)), "" )} -> 공모/무보증A0 | Q37: {=IF( $U$1=1, AND($P37<>"", $P37<>"...", $P37<>"입력오류"), IF( $U$18=1, AND($P37<>"", $P37<>"...", $P37<>"입력오류", ISNUMBER(FIND(INDEX($T$2:$T$7,$U$1),$P37))), IF( $U$17="기타", AND($P37<>"", $P37<>"...", $P37<>"입력오류", NOT(ISNUMBER(FIND($T$21:$T$34,$P37)))), AND($P37<>"", $P37<>"...", $P37<>"입력오류", $T$19=$P37) ) ) )} -> TRUE
A38: 00174 | B38: SK네트웍스 | C38: 00188 | D38: DL건설 | E38: 00353 | F38: 한화투자증권 | I38: =ROW()-1 -> 37 | J38: =IF( $I38>$G$4, NA(), IF($I38>$G$3, $I38-$G$3, IF($I38>$G$2, $I38-$G$2, $I38 ) ) ) -> 37 | K38: =IF( $I38>$G$4, NA(), IF($I38>$G$3, 5, IF($I38>$G$2, 3, 1 ) ) ) -> 1 | L38: =COUNTIF($N$2:N38, N38)=1 -> TRUE | M38: =IF( $Q38, MAX($M$1:M37)+1, 0) -> 26 | N38: {=INDEX($A$9:$F$1048576, $J38, $K38 )} -> 00238 | O38: {=INDEX($B$9:$F$1048576, $J38, $K38 )} -> 케이씨씨 | P38: {=IF( $L38, TRIM(_xll.IMDP("IR", $G$5&$N38, $G$6)), "" )} -> 공모/무보증AA- | Q38: {=IF( $U$1=1, AND($P38<>"", $P38<>"...", $P38<>"입력오류"), IF( $U$18=1, AND($P38<>"", $P38<>"...", $P38<>"입력오류", ISNUMBER(FIND(INDEX($T$2:$T$7,$U$1),$P38))), IF( $U$17="기타", AND($P38<>"", $P38<>"...", $P38<>"입력오류", NOT(ISNUMBER(FIND($T$21:$T$34,$P38)))), AND($P38<>"", $P38<>"...", $P38<>"입력오류", $T$19=$P38) ) ) )} -> TRUE
A39: 00178 | B39: 알루코 | C39: 00235 | D39: 넥센타이어 | E39: 00385 | F39: 보령 | I39: =ROW()-1 -> 38 | J39: =IF( $I39>$G$4, NA(), IF($I39>$G$3, $I39-$G$3, IF($I39>$G$2, $I39-$G$2, $I39 ) ) ) -> 38 | K39: =IF( $I39>$G$4, NA(), IF($I39>$G$3, 5, IF($I39>$G$2, 3, 1 ) ) ) -> 1 | L39: =COUNTIF($N$2:N39, N39)=1 -> TRUE | M39: =IF( $Q39, MAX($M$1:M38)+1, 0) -> 0 | N39: {=INDEX($A$9:$F$1048576, $J39, $K39 )} -> 00239 | O39: {=INDEX($B$9:$F$1048576, $J39, $K39 )} -> 한독 | P39: {=IF( $L39, TRIM(_xll.IMDP("IR", $G$5&$N39, $G$6)), "" )} | Q39: {=IF( $U$1=1, AND($P39<>"", $P39<>"...", $P39<>"입력오류"), IF( $U$18=1, AND($P39<>"", $P39<>"...", $P39<>"입력오류", ISNUMBER(FIND(INDEX($T$2:$T$7,$U$1),$P39))), IF( $U$17="기타", AND($P39<>"", $P39<>"...", $P39<>"입력오류", NOT(ISNUMBER(FIND($T$21:$T$34,$P39)))), AND($P39<>"", $P39<>"...", $P39<>"입력오류", $T$19=$P39) ) ) )} -> FALSE
A40: 00179 | B40: 대한제당 | C40: 00238 | D40: 케이씨씨 | E40: 00402 | F40: 현대제철 | I40: =ROW()-1 -> 39 | J40: =IF( $I40>$G$4, NA(), IF($I40>$G$3, $I40-$G$3, IF($I40>$G$2, $I40-$G$2, $I40 ) ) ) -> 39 | K40: =IF( $I40>$G$4, NA(), IF($I40>$G$3, 5, IF($I40>$G$2, 3, 1 ) ) ) -> 1 | L40: =COUNTIF($N$2:N40, N40)=1 -> TRUE | M40: =IF( $Q40, MAX($M$1:M39)+1, 0) -> 0 | N40: {=INDEX($A$9:$F$1048576, $J40, $K40 )} -> 00243 | O40: {=INDEX($B$9:$F$1048576, $J40, $K40 )} -> 동광건설 | P40: {=IF( $L40, TRIM(_xll.IMDP("IR", $G$5&$N40, $G$6)), "" )} | Q40: {=IF( $U$1=1, AND($P40<>"", $P40<>"...", $P40<>"입력오류"), IF( $U$18=1, AND($P40<>"", $P40<>"...", $P40<>"입력오류", ISNUMBER(FIND(INDEX($T$2:$T$7,$U$1),$P40))), IF( $U$17="기타", AND($P40<>"", $P40<>"...", $P40<>"입력오류", NOT(ISNUMBER(FIND($T$21:$T$34,$P40)))), AND($P40<>"", $P40<>"...", $P40<>"입력오류", $T$19=$P40) ) ) )} -> FALSE
...
