Workbook

Sheet Hist
C2: 시가평가 Spread 분석
J5: =IF( hist_data!$B$4="#N/A", " 없는 그룹입니다. 다른 채권이나 중개사를 선택하세요", IF(OFFSET(hist_data!$B$7, 0, hist_data!$D$3)=0, " 없는 기물입니다. 다른 기물을 선택하세요", ""))
J10: =IF( hist_data!$S$4="#N/A", " 없는 그룹입니다. 다른 채권이나 중개사를 선택하세요", "" )
E13: =hist_data!$B7 -> 45520 | F13: =hist_data!$B8 -> 45518 | G13: =hist_data!$B9 -> 45517 | H13: =hist_data!$B10 -> 45516 | I13: =hist_data!$B11 -> 45513 | J13: =hist_data!$B12 -> 45512 | K13: =hist_data!$B13 -> 45511 | L13: =hist_data!$B14 -> 45510 | M13: =hist_data!$B15 -> 45509 | N13: =hist_data!$B16 -> 45506 | O13: =hist_data!$B17 -> 45505 | P13: =hist_data!$B18 -> 45504 | R13: 20 | S13: 20 | T13: 20 | U13: 60 | V13: 60 | W13: 60 | X13: 120 | Y13: 120 | Z13: 120 | AA13: 250 | AB13: 250 | AC13: 250
C14: 기준 - 비교 | E14: =TEXT(E$13, "YYYY") -> 2024 | F14: =TEXT(F$13, "YYYY") -> 2024 | G14: =TEXT(G$13, "YYYY") -> 2024 | H14: =TEXT(H$13, "YYYY") -> 2024 | I14: =TEXT(I$13, "YYYY") -> 2024 | J14: =TEXT(J$13, "YYYY") -> 2024 | K14: =TEXT(K$13, "YYYY") -> 2024 | L14: =TEXT(L$13, "YYYY") -> 2024 | ... P14: =TEXT(P$13, "YYYY") -> 2024 | R14: 20D | U14: 60D | X14: 120D | AA14: 250D
E15: =TEXT(E$13, "MM-DD") -> 08-16 | F15: =TEXT(F$13, "MM-DD") -> 08-14 | G15: =TEXT(G$13, "MM-DD") -> 08-13 | H15: =TEXT(H$13, "MM-DD") -> 08-12 | I15: =TEXT(I$13, "MM-DD") -> 08-09 | J15: =TEXT(J$13, "MM-DD") -> 08-08 | K15: =TEXT(K$13, "MM-DD") -> 08-07 | L15: =TEXT(L$13, "MM-DD") -> 08-06 | ... P15: =TEXT(P$13, "MM-DD") -> 07-31 | R15: Avg. | S15: Max. | T15: Min. | U15: Avg. | V15: Max. | W15: Min. | X15: Avg. | Y15: Max. | Z15: Min. | AA15: Avg. | AB15: Max. | AC15: Min.
C16: 비교 | D16: 기준 | E16: {=IF( INDEX( hist_data!$B$6:$R$256, MATCH(E$13, hist_data!$B$6:$B$256, 0), hist_data!$D$3+1)=0, "", INDEX( hist_data!$B$6:$R$256, MATCH(E$13, hist_data!$B$6:$B$256, 0), hist_data!$D$3+1))} -> 2.922 | F16: {=IF( INDEX( hist_data!$B$6:$R$256, MATCH(F$13, hist_data!$B$6:$B$256, 0), hist_data!$D$3+1)=0, "", INDEX( hist_data!$B$6:$R$256, MATCH(F$13, hist_data!$B$6:$B$256, 0), hist_data!$D$3+1))} -> 2.887 | G16: {=IF( INDEX( hist_data!$B$6:$R$256, MATCH(G$13, hist_data!$B$6:$B$256, 0), hist_data!$D$3+1)=0, "", INDEX( hist_data!$B$6:$R$256, MATCH(G$13, hist_data!$B$6:$B$256, 0), hist_data!$D$3+1))} -> 2.915 | H16: {=IF( INDEX( hist_data!$B$6:$R$256, MATCH(H$13, hist_data!$B$6:$B$256, 0), hist_data!$D$3+1)=0, "", INDEX( hist_data!$B$6:$R$256, MATCH(H$13, hist_data!$B$6:$B$256, 0), hist_data!$D$3+1))} -> 2.945 | I16: {=IF( INDEX( hist_data!$B$6:$R$256, MATCH(I$13, hist_data!$B$6:$B$256, 0), hist_data!$D$3+1)=0, "", INDEX( hist_data!$B$6:$R$256, MATCH(I$13, hist_data!$B$6:$B$256, 0), hist_data!$D$3+1))} -> 2.94 | J16: {=IF( INDEX( hist_data!$B$6:$R$256, MATCH(J$13, hist_data!$B$6:$B$256, 0), hist_data!$D$3+1)=0, "", INDEX( hist_data!$B$6:$R$256, MATCH(J$13, hist_data!$B$6:$B$256, 0), hist_data!$D$3+1))} -> 2.919 | K16: {=IF( INDEX( hist_data!$B$6:$R$256, MATCH(K$13, hist_data!$B$6:$B$256, 0), hist_data!$D$3+1)=0, "", INDEX( hist_data!$B$6:$R$256, MATCH(K$13, hist_data!$B$6:$B$256, 0), hist_data!$D$3+1))} -> 2.931 | L16: {=IF( INDEX( hist_data!$B$6:$R$256, MATCH(L$13, hist_data!$B$6:$B$256, 0), hist_data!$D$3+1)=0, "", INDEX( hist_data!$B$6:$R$256, MATCH(L$13, hist_data!$B$6:$B$256, 0), hist_data!$D$3+1))} -> 2.94 | ... P16: {=IF( INDEX( hist_data!$B$6:$R$256, MATCH(P$13, hist_data!$B$6:$B$256, 0), hist_data!$D$3+1)=0, "", INDEX( hist_data!$B$6:$R$256, MATCH(P$13, hist_data!$B$6:$B$256, 0), hist_data!$D$3+1))} -> 3 | R16: =IF( $E16="", "", AVERAGE( OFFSET( hist_data!$B$7, 0, hist_data!$D$3, R$13) ) ) -> 2.97005 | S16: =IF( $E16="", "", MAX( OFFSET( hist_data!$B$7, 0, hist_data!$D$3, S$13) ) ) -> 3.087 | T16: =IF( $E16="", "", MIN( OFFSET( hist_data!$B$7, 0, hist_data!$D$3, T$13) ) ) -> 2.815 | U16: =IF( $E16="", "", AVERAGE( OFFSET( hist_data!$B$7, 0, hist_data!$D$3, U$13) ) ) -> 3.1466333 | V16: =IF( $E16="", "", MAX( OFFSET( hist_data!$B$7, 0, hist_data!$D$3, V$13) ) ) -> 3.452 | W16: =IF( $E16="", "", MIN( OFFSET( hist_data!$B$7, 0, hist_data!$D$3, W$13) ) ) -> 2.815 | X16: =IF( $E16="", "", AVERAGE( OFFSET( hist_data!$B$7, 0, hist_data!$D$3, X$13) ) ) -> 3.2661917 | Y16: =IF( $E16="", "", MAX( OFFSET( hist_data!$B$7, 0, hist_data!$D$3, Y$13) ) ) -> 3.54 | Z16: =IF( $E16="", "", MIN( OFFSET( hist_data!$B$7, 0, hist_data!$D$3, Z$13) ) ) -> 2.815 | AA16: =IF( $E16="", "", AVERAGE( OFFSET( hist_data!$B$7, 0, hist_data!$D$3, AA$13) ) ) -> 3.450952 | AB16: =IF( $E16="", "", MAX( OFFSET( hist_data!$B$7, 0, hist_data!$D$3, AB$13) ) ) -> 4.14 | AC16: =IF( $E16="", "", MIN( OFFSET( hist_data!$B$7, 0, hist_data!$D$3, AC$13) ) ) -> 2.815
A17: 1 | C17: {=INDEX(hist_data!$A$6:$A$21, Hist!$A17)} -> 03M | E17: {=IF( INDEX(hist_data!$S$6:$AI$256, MATCH(E$13, hist_data!$S$6:$S$256, 0), MATCH($C17, hist_data!$A$6:$A$21, 0)+1)=0, "", INDEX(hist_data!$S$6:$AI$256, MATCH(E$13, hist_data!$S$6:$S$256, 0), MATCH($C17, hist_data!$A$6:$A$21, 0)+1) )} -> 3.393 | F17: {=IF( INDEX(hist_data!$S$6:$AI$256, MATCH(F$13, hist_data!$S$6:$S$256, 0), MATCH($C17, hist_data!$A$6:$A$21, 0)+1)=0, "", INDEX(hist_data!$S$6:$AI$256, MATCH(F$13, hist_data!$S$6:$S$256, 0), MATCH($C17, hist_data!$A$6:$A$21, 0)+1) )} -> 3.388 | G17: {=IF( INDEX(hist_data!$S$6:$AI$256, MATCH(G$13, hist_data!$S$6:$S$256, 0), MATCH($C17, hist_data!$A$6:$A$21, 0)+1)=0, "", INDEX(hist_data!$S$6:$AI$256, MATCH(G$13, hist_data!$S$6:$S$256, 0), MATCH($C17, hist_data!$A$6:$A$21, 0)+1) )} -> 3.386 | H17: {=IF( INDEX(hist_data!$S$6:$AI$256, MATCH(H$13, hist_data!$S$6:$S$256, 0), MATCH($C17, hist_data!$A$6:$A$21, 0)+1)=0, "", INDEX(hist_data!$S$6:$AI$256, MATCH(H$13, hist_data!$S$6:$S$256, 0), MATCH($C17, hist_data!$A$6:$A$21, 0)+1) )} -> 3.386 | I17: {=IF( INDEX(hist_data!$S$6:$AI$256, MATCH(I$13, hist_data!$S$6:$S$256, 0), MATCH($C17, hist_data!$A$6:$A$21, 0)+1)=0, "", INDEX(hist_data!$S$6:$AI$256, MATCH(I$13, hist_data!$S$6:$S$256, 0), MATCH($C17, hist_data!$A$6:$A$21, 0)+1) )} -> 3.383 | J17: {=IF( INDEX(hist_data!$S$6:$AI$256, MATCH(J$13, hist_data!$S$6:$S$256, 0), MATCH($C17, hist_data!$A$6:$A$21, 0)+1)=0, "", INDEX(hist_data!$S$6:$AI$256, MATCH(J$13, hist_data!$S$6:$S$256, 0), MATCH($C17, hist_data!$A$6:$A$21, 0)+1) )} -> 3.38 | K17: {=IF( INDEX(hist_data!$S$6:$AI$256, MATCH(K$13, hist_data!$S$6:$S$256, 0), MATCH($C17, hist_data!$A$6:$A$21, 0)+1)=0, "", INDEX(hist_data!$S$6:$AI$256, MATCH(K$13, hist_data!$S$6:$S$256, 0), MATCH($C17, hist_data!$A$6:$A$21, 0)+1) )} -> 3.376 | L17: {=IF( INDEX(hist_data!$S$6:$AI$256, MATCH(L$13, hist_data!$S$6:$S$256, 0), MATCH($C17, hist_data!$A$6:$A$21, 0)+1)=0, "", INDEX(hist_data!$S$6:$AI$256, MATCH(L$13, hist_data!$S$6:$S$256, 0), MATCH($C17, hist_data!$A$6:$A$21, 0)+1) )} -> 3.361 | ... P17: {=IF( INDEX(hist_data!$S$6:$AI$256, MATCH(P$13, hist_data!$S$6:$S$256, 0), MATCH($C17, hist_data!$A$6:$A$21, 0)+1)=0, "", INDEX(hist_data!$S$6:$AI$256, MATCH(P$13, hist_data!$S$6:$S$256, 0), MATCH($C17, hist_data!$A$6:$A$21, 0)+1) )} -> 3.393 | R17: =IF($E17="", "", AVERAGE( OFFSET( hist_data!$S$7, 0, MATCH($C17, hist_data!$A$6:$A$21, 0), R$13 ) )) -> 3.3868 | S17: =IF($E17="","",MAX(OFFSET(hist_data!$S$7,0,MATCH($C17,hist_data!$A$6:$A$21,0),S$13))) -> 3.398 | T17: =IF($E17="","",MIN(OFFSET(hist_data!$S$7,0,MATCH($C17,hist_data!$A$6:$A$21,0),T$13))) -> 3.351 | U17: =IF($E17="", "", AVERAGE( OFFSET( hist_data!$S$7, 0, MATCH($C17, hist_data!$A$6:$A$21, 0), U$13 ) )) -> 3.4558333 | V17: =IF($E17="","",MAX(OFFSET(hist_data!$S$7,0,MATCH($C17,hist_data!$A$6:$A$21,0),V$13))) -> 3.534 | W17: =IF($E17="","",MIN(OFFSET(hist_data!$S$7,0,MATCH($C17,hist_data!$A$6:$A$21,0),W$13))) -> 3.351 | X17: =IF($E17="", "", AVERAGE( OFFSET( hist_data!$S$7, 0, MATCH($C17, hist_data!$A$6:$A$21, 0), X$13 ) )) -> 3.5080167 | Y17: =IF($E17="","",MAX(OFFSET(hist_data!$S$7,0,MATCH($C17,hist_data!$A$6:$A$21,0),Y$13))) -> 3.634 | Z17: =IF($E17="","",MIN(OFFSET(hist_data!$S$7,0,MATCH($C17,hist_data!$A$6:$A$21,0),Z$13))) -> 3.351 | AA17: =IF($E17="", "", AVERAGE( OFFSET( hist_data!$S$7, 0, MATCH($C17, hist_data!$A$6:$A$21, 0), AA$13 ) )) -> 3.641748 | AB17: =IF($E17="","",MAX(OFFSET(hist_data!$S$7,0,MATCH($C17,hist_data!$A$6:$A$21,0),AB$13))) -> 3.912 | AC17: =IF($E17="","",MIN(OFFSET(hist_data!$S$7,0,MATCH($C17,hist_data!$A$6:$A$21,0),AC$13))) -> 3.351
C18: SP(bp) | E18: =IFERROR( (E$16-E17)*100, "") -> -47.1 | F18: =IFERROR( (F$16-F17)*100, "") -> -50.1 | G18: =IFERROR( (G$16-G17)*100, "") -> -47.1 | H18: =IFERROR( (H$16-H17)*100, "") -> -44.1 | I18: =IFERROR( (I$16-I17)*100, "") -> -44.3 | J18: =IFERROR( (J$16-J17)*100, "") -> -46.1 | K18: =IFERROR( (K$16-K17)*100, "") -> -44.5 | L18: =IFERROR( (L$16-L17)*100, "") -> -42.1 | ... P18: =IFERROR( (P$16-P17)*100, "") -> -39.3 | R18: =IFERROR( (R$16-R17)*100, "") -> -41.675 | S18: =IFERROR( (S$16-S17)*100, "") -> -31.1 | T18: =IFERROR( (T$16-T17)*100, "") -> -53.6 | U18: =IFERROR( (U$16-U17)*100, "") -> -30.92 | V18: =IFERROR( (V$16-V17)*100, "") -> -8.2 | W18: =IFERROR( (W$16-W17)*100, "") -> -53.6 | X18: =IFERROR( (X$16-X17)*100, "") -> -24.1825 | Y18: =IFERROR( (Y$16-Y17)*100, "") -> -9.4 | ... AC18: =IFERROR( (AC$16-AC17)*100, "") -> -53.6
A19: 2 | C19: {=INDEX(hist_data!$A$6:$A$21, Hist!$A19)} -> 06M | E19: {=IF( INDEX(hist_data!$S$6:$AI$256, MATCH(E$13, hist_data!$S$6:$S$256, 0), MATCH($C19, hist_data!$A$6:$A$21, 0)+1)=0, "", INDEX(hist_data!$S$6:$AI$256, MATCH(E$13, hist_data!$S$6:$S$256, 0), MATCH($C19, hist_data!$A$6:$A$21, 0)+1) )} -> 3.361 | F19: {=IF( INDEX(hist_data!$S$6:$AI$256, MATCH(F$13, hist_data!$S$6:$S$256, 0), MATCH($C19, hist_data!$A$6:$A$21, 0)+1)=0, "", INDEX(hist_data!$S$6:$AI$256, MATCH(F$13, hist_data!$S$6:$S$256, 0), MATCH($C19, hist_data!$A$6:$A$21, 0)+1) )} -> 3.348 | G19: {=IF( INDEX(hist_data!$S$6:$AI$256, MATCH(G$13, hist_data!$S$6:$S$256, 0), MATCH($C19, hist_data!$A$6:$A$21, 0)+1)=0, "", INDEX(hist_data!$S$6:$AI$256, MATCH(G$13, hist_data!$S$6:$S$256, 0), MATCH($C19, hist_data!$A$6:$A$21, 0)+1) )} -> 3.348 | H19: {=IF( INDEX(hist_data!$S$6:$AI$256, MATCH(H$13, hist_data!$S$6:$S$256, 0), MATCH($C19, hist_data!$A$6:$A$21, 0)+1)=0, "", INDEX(hist_data!$S$6:$AI$256, MATCH(H$13, hist_data!$S$6:$S$256, 0), MATCH($C19, hist_data!$A$6:$A$21, 0)+1) )} -> 3.348 | I19: {=IF( INDEX(hist_data!$S$6:$AI$256, MATCH(I$13, hist_data!$S$6:$S$256, 0), MATCH($C19, hist_data!$A$6:$A$21, 0)+1)=0, "", INDEX(hist_data!$S$6:$AI$256, MATCH(I$13, hist_data!$S$6:$S$256, 0), MATCH($C19, hist_data!$A$6:$A$21, 0)+1) )} -> 3.342 | J19: {=IF( INDEX(hist_data!$S$6:$AI$256, MATCH(J$13, hist_data!$S$6:$S$256, 0), MATCH($C19, hist_data!$A$6:$A$21, 0)+1)=0, "", INDEX(hist_data!$S$6:$AI$256, MATCH(J$13, hist_data!$S$6:$S$256, 0), MATCH($C19, hist_data!$A$6:$A$21, 0)+1) )} -> 3.342 | K19: {=IF( INDEX(hist_data!$S$6:$AI$256, MATCH(K$13, hist_data!$S$6:$S$256, 0), MATCH($C19, hist_data!$A$6:$A$21, 0)+1)=0, "", INDEX(hist_data!$S$6:$AI$256, MATCH(K$13, hist_data!$S$6:$S$256, 0), MATCH($C19, hist_data!$A$6:$A$21, 0)+1) )} -> 3.343 | L19: {=IF( INDEX(hist_data!$S$6:$AI$256, MATCH(L$13, hist_data!$S$6:$S$256, 0), MATCH($C19, hist_data!$A$6:$A$21, 0)+1)=0, "", INDEX(hist_data!$S$6:$AI$256, MATCH(L$13, hist_data!$S$6:$S$256, 0), MATCH($C19, hist_data!$A$6:$A$21, 0)+1) )} -> 3.344 | ... P19: {=IF( INDEX(hist_data!$S$6:$AI$256, MATCH(P$13, hist_data!$S$6:$S$256, 0), MATCH($C19, hist_data!$A$6:$A$21, 0)+1)=0, "", INDEX(hist_data!$S$6:$AI$256, MATCH(P$13, hist_data!$S$6:$S$256, 0), MATCH($C19, hist_data!$A$6:$A$21, 0)+1) )} -> 3.391 | R19: =IF($E19="", "", AVERAGE( OFFSET( hist_data!$S$7, 0, MATCH($C19, hist_data!$A$6:$A$21, 0), R$13 ) )) -> 3.37225 | S19: =IF($E19="","",MAX(OFFSET(hist_data!$S$7,0,MATCH($C19,hist_data!$A$6:$A$21,0),S$13))) -> 3.411 | T19: =IF($E19="","",MIN(OFFSET(hist_data!$S$7,0,MATCH($C19,hist_data!$A$6:$A$21,0),T$13))) -> 3.328 | U19: =IF($E19="", "", AVERAGE( OFFSET( hist_data!$S$7, 0, MATCH($C19, hist_data!$A$6:$A$21, 0), U$13 ) )) -> 3.4641167 | V19: =IF($E19="","",MAX(OFFSET(hist_data!$S$7,0,MATCH($C19,hist_data!$A$6:$A$21,0),V$13))) -> 3.583 | W19: =IF($E19="","",MIN(OFFSET(hist_data!$S$7,0,MATCH($C19,hist_data!$A$6:$A$21,0),W$13))) -> 3.328 | X19: =IF($E19="", "", AVERAGE( OFFSET( hist_data!$S$7, 0, MATCH($C19, hist_data!$A$6:$A$21, 0), X$13 ) )) -> 3.522125 | Y19: =IF($E19="","",MAX(OFFSET(hist_data!$S$7,0,MATCH($C19,hist_data!$A$6:$A$21,0),Y$13))) -> 3.651 | Z19: =IF($E19="","",MIN(OFFSET(hist_data!$S$7,0,MATCH($C19,hist_data!$A$6:$A$21,0),Z$13))) -> 3.328 | AA19: =IF($E19="", "", AVERAGE( OFFSET( hist_data!$S$7, 0, MATCH($C19, hist_data!$A$6:$A$21, 0), AA$13 ) )) -> 3.679744 | AB19: =IF($E19="","",MAX(OFFSET(hist_data!$S$7,0,MATCH($C19,hist_data!$A$6:$A$21,0),AB$13))) -> 4.025 | AC19: =IF($E19="","",MIN(OFFSET(hist_data!$S$7,0,MATCH($C19,hist_data!$A$6:$A$21,0),AC$13))) -> 3.328
C20: SP(bp) | E20: =IFERROR( (E$16-E19)*100, "") -> -43.9 | F20: =IFERROR( (F$16-F19)*100, "") -> -46.1 | G20: =IFERROR( (G$16-G19)*100, "") -> -43.3 | H20: =IFERROR( (H$16-H19)*100, "") -> -40.3 | I20: =IFERROR( (I$16-I19)*100, "") -> -40.2 | J20: =IFERROR( (J$16-J19)*100, "") -> -42.3 | K20: =IFERROR( (K$16-K19)*100, "") -> -41.2 | L20: =IFERROR( (L$16-L19)*100, "") -> -40.4 | ... P20: =IFERROR( (P$16-P19)*100, "") -> -39.1 | R20: =IFERROR( (R$16-R19)*100, "") -> -40.22 | S20: =IFERROR( (S$16-S19)*100, "") -> -32.4 | T20: =IFERROR( (T$16-T19)*100, "") -> -51.3 | U20: =IFERROR( (U$16-U19)*100, "") -> -31.748333 | V20: =IFERROR( (V$16-V19)*100, "") -> -13.1 | W20: =IFERROR( (W$16-W19)*100, "") -> -51.3 | X20: =IFERROR( (X$16-X19)*100, "") -> -25.593333 | Y20: =IFERROR( (Y$16-Y19)*100, "") -> -11.1 | ... AC20: =IFERROR( (AC$16-AC19)*100, "") -> -51.3
A21: 3 | C21: {=INDEX(hist_data!$A$6:$A$21, Hist!$A21)} -> 09M | E21: {=IF( INDEX(hist_data!$S$6:$AI$256, MATCH(E$13, hist_data!$S$6:$S$256, 0), MATCH($C21, hist_data!$A$6:$A$21, 0)+1)=0, "", INDEX(hist_data!$S$6:$AI$256, MATCH(E$13, hist_data!$S$6:$S$256, 0), MATCH($C21, hist_data!$A$6:$A$21, 0)+1) )} -> 3.298 | F21: {=IF( INDEX(hist_data!$S$6:$AI$256, MATCH(F$13, hist_data!$S$6:$S$256, 0), MATCH($C21, hist_data!$A$6:$A$21, 0)+1)=0, "", INDEX(hist_data!$S$6:$AI$256, MATCH(F$13, hist_data!$S$6:$S$256, 0), MATCH($C21, hist_data!$A$6:$A$21, 0)+1) )} -> 3.283 | G21: {=IF( INDEX(hist_data!$S$6:$AI$256, MATCH(G$13, hist_data!$S$6:$S$256, 0), MATCH($C21, hist_data!$A$6:$A$21, 0)+1)=0, "", INDEX(hist_data!$S$6:$AI$256, MATCH(G$13, hist_data!$S$6:$S$256, 0), MATCH($C21, hist_data!$A$6:$A$21, 0)+1) )} -> 3.284 | H21: {=IF( INDEX(hist_data!$S$6:$AI$256, MATCH(H$13, hist_data!$S$6:$S$256, 0), MATCH($C21, hist_data!$A$6:$A$21, 0)+1)=0, "", INDEX(hist_data!$S$6:$AI$256, MATCH(H$13, hist_data!$S$6:$S$256, 0), MATCH($C21, hist_data!$A$6:$A$21, 0)+1) )} -> 3.287 | I21: {=IF( INDEX(hist_data!$S$6:$AI$256, MATCH(I$13, hist_data!$S$6:$S$256, 0), MATCH($C21, hist_data!$A$6:$A$21, 0)+1)=0, "", INDEX(hist_data!$S$6:$AI$256, MATCH(I$13, hist_data!$S$6:$S$256, 0), MATCH($C21, hist_data!$A$6:$A$21, 0)+1) )} -> 3.281 | J21: {=IF( INDEX(hist_data!$S$6:$AI$256, MATCH(J$13, hist_data!$S$6:$S$256, 0), MATCH($C21, hist_data!$A$6:$A$21, 0)+1)=0, "", INDEX(hist_data!$S$6:$AI$256, MATCH(J$13, hist_data!$S$6:$S$256, 0), MATCH($C21, hist_data!$A$6:$A$21, 0)+1) )} -> 3.279 | K21: {=IF( INDEX(hist_data!$S$6:$AI$256, MATCH(K$13, hist_data!$S$6:$S$256, 0), MATCH($C21, hist_data!$A$6:$A$21, 0)+1)=0, "", INDEX(hist_data!$S$6:$AI$256, MATCH(K$13, hist_data!$S$6:$S$256, 0), MATCH($C21, hist_data!$A$6:$A$21, 0)+1) )} -> 3.28 | L21: {=IF( INDEX(hist_data!$S$6:$AI$256, MATCH(L$13, hist_data!$S$6:$S$256, 0), MATCH($C21, hist_data!$A$6:$A$21, 0)+1)=0, "", INDEX(hist_data!$S$6:$AI$256, MATCH(L$13, hist_data!$S$6:$S$256, 0), MATCH($C21, hist_data!$A$6:$A$21, 0)+1) )} -> 3.278 | ... P21: {=IF( INDEX(hist_data!$S$6:$AI$256, MATCH(P$13, hist_data!$S$6:$S$256, 0), MATCH($C21, hist_data!$A$6:$A$21, 0)+1)=0, "", INDEX(hist_data!$S$6:$AI$256, MATCH(P$13, hist_data!$S$6:$S$256, 0), MATCH($C21, hist_data!$A$6:$A$21, 0)+1) )} -> 3.332 | R21: =IF($E21="", "", AVERAGE( OFFSET( hist_data!$S$7, 0, MATCH($C21, hist_data!$A$6:$A$21, 0), R$13 ) )) -> 3.313 | S21: =IF($E21="","",MAX(OFFSET(hist_data!$S$7,0,MATCH($C21,hist_data!$A$6:$A$21,0),S$13))) -> 3.37 | T21: =IF($E21="","",MIN(OFFSET(hist_data!$S$7,0,MATCH($C21,hist_data!$A$6:$A$21,0),T$13))) -> 3.253 | U21: =IF($E21="", "", AVERAGE( OFFSET( hist_data!$S$7, 0, MATCH($C21, hist_data!$A$6:$A$21, 0), U$13 ) )) -> 3.4355167 | V21: =IF($E21="","",MAX(OFFSET(hist_data!$S$7,0,MATCH($C21,hist_data!$A$6:$A$21,0),V$13))) -> 3.591 | W21: =IF($E21="","",MIN(OFFSET(hist_data!$S$7,0,MATCH($C21,hist_data!$A$6:$A$21,0),W$13))) -> 3.253 | X21: =IF($E21="", "", AVERAGE( OFFSET( hist_data!$S$7, 0, MATCH($C21, hist_data!$A$6:$A$21, 0), X$13 ) )) -> 3.5186417 | Y21: =IF($E21="","",MAX(OFFSET(hist_data!$S$7,0,MATCH($C21,hist_data!$A$6:$A$21,0),Y$13))) -> 3.673 | Z21: =IF($E21="","",MIN(OFFSET(hist_data!$S$7,0,MATCH($C21,hist_data!$A$6:$A$21,0),Z$13))) -> 3.253 | AA21: =IF($E21="", "", AVERAGE( OFFSET( hist_data!$S$7, 0, MATCH($C21, hist_data!$A$6:$A$21, 0), AA$13 ) )) -> 3.683244 | AB21: =IF($E21="","",MAX(OFFSET(hist_data!$S$7,0,MATCH($C21,hist_data!$A$6:$A$21,0),AB$13))) -> 4.06 | AC21: =IF($E21="","",MIN(OFFSET(hist_data!$S$7,0,MATCH($C21,hist_data!$A$6:$A$21,0),AC$13))) -> 3.253
C22: SP(bp) | E22: =IFERROR( (E$16-E21)*100, "") -> -37.6 | F22: =IFERROR( (F$16-F21)*100, "") -> -39.6 | G22: =IFERROR( (G$16-G21)*100, "") -> -36.9 | H22: =IFERROR( (H$16-H21)*100, "") -> -34.2 | I22: =IFERROR( (I$16-I21)*100, "") -> -34.1 | J22: =IFERROR( (J$16-J21)*100, "") -> -36 | K22: =IFERROR( (K$16-K21)*100, "") -> -34.9 | L22: =IFERROR( (L$16-L21)*100, "") -> -33.8 | ... P22: =IFERROR( (P$16-P21)*100, "") -> -33.2 | R22: =IFERROR( (R$16-R21)*100, "") -> -34.295 | S22: =IFERROR( (S$16-S21)*100, "") -> -28.3 | T22: =IFERROR( (T$16-T21)*100, "") -> -43.8 | U22: =IFERROR( (U$16-U21)*100, "") -> -28.888333 | V22: =IFERROR( (V$16-V21)*100, "") -> -13.9 | W22: =IFERROR( (W$16-W21)*100, "") -> -43.8 | X22: =IFERROR( (X$16-X21)*100, "") -> -25.245 | Y22: =IFERROR( (Y$16-Y21)*100, "") -> -13.3 | ... AC22: =IFERROR( (AC$16-AC21)*100, "") -> -43.8
A23: 4 | C23: {=INDEX(hist_data!$A$6:$A$21, Hist!$A23)} -> 01Y | E23: {=IF( INDEX(hist_data!$S$6:$AI$256, MATCH(E$13, hist_data!$S$6:$S$256, 0), MATCH($C23, hist_data!$A$6:$A$21, 0)+1)=0, "", INDEX(hist_data!$S$6:$AI$256, MATCH(E$13, hist_data!$S$6:$S$256, 0), MATCH($C23, hist_data!$A$6:$A$21, 0)+1) )} -> 3.259 | F23: {=IF( INDEX(hist_data!$S$6:$AI$256, MATCH(F$13, hist_data!$S$6:$S$256, 0), MATCH($C23, hist_data!$A$6:$A$21, 0)+1)=0, "", INDEX(hist_data!$S$6:$AI$256, MATCH(F$13, hist_data!$S$6:$S$256, 0), MATCH($C23, hist_data!$A$6:$A$21, 0)+1) )} -> 3.246 | G23: {=IF( INDEX(hist_data!$S$6:$AI$256, MATCH(G$13, hist_data!$S$6:$S$256, 0), MATCH($C23, hist_data!$A$6:$A$21, 0)+1)=0, "", INDEX(hist_data!$S$6:$AI$256, MATCH(G$13, hist_data!$S$6:$S$256, 0), MATCH($C23, hist_data!$A$6:$A$21, 0)+1) )} -> 3.243 | H23: {=IF( INDEX(hist_data!$S$6:$AI$256, MATCH(H$13, hist_data!$S$6:$S$256, 0), MATCH($C23, hist_data!$A$6:$A$21, 0)+1)=0, "", INDEX(hist_data!$S$6:$AI$256, MATCH(H$13, hist_data!$S$6:$S$256, 0), MATCH($C23, hist_data!$A$6:$A$21, 0)+1) )} -> 3.244 | I23: {=IF( INDEX(hist_data!$S$6:$AI$256, MATCH(I$13, hist_data!$S$6:$S$256, 0), MATCH($C23, hist_data!$A$6:$A$21, 0)+1)=0, "", INDEX(hist_data!$S$6:$AI$256, MATCH(I$13, hist_data!$S$6:$S$256, 0), MATCH($C23, hist_data!$A$6:$A$21, 0)+1) )} -> 3.238 | J23: {=IF( INDEX(hist_data!$S$6:$AI$256, MATCH(J$13, hist_data!$S$6:$S$256, 0), MATCH($C23, hist_data!$A$6:$A$21, 0)+1)=0, "", INDEX(hist_data!$S$6:$AI$256, MATCH(J$13, hist_data!$S$6:$S$256, 0), MATCH($C23, hist_data!$A$6:$A$21, 0)+1) )} -> 3.236 | K23: {=IF( INDEX(hist_data!$S$6:$AI$256, MATCH(K$13, hist_data!$S$6:$S$256, 0), MATCH($C23, hist_data!$A$6:$A$21, 0)+1)=0, "", INDEX(hist_data!$S$6:$AI$256, MATCH(K$13, hist_data!$S$6:$S$256, 0), MATCH($C23, hist_data!$A$6:$A$21, 0)+1) )} -> 3.247 | L23: {=IF( INDEX(hist_data!$S$6:$AI$256, MATCH(L$13, hist_data!$S$6:$S$256, 0), MATCH($C23, hist_data!$A$6:$A$21, 0)+1)=0, "", INDEX(hist_data!$S$6:$AI$256, MATCH(L$13, hist_data!$S$6:$S$256, 0), MATCH($C23, hist_data!$A$6:$A$21, 0)+1) )} -> 3.244 | ... P23: {=IF( INDEX(hist_data!$S$6:$AI$256, MATCH(P$13, hist_data!$S$6:$S$256, 0), MATCH($C23, hist_data!$A$6:$A$21, 0)+1)=0, "", INDEX(hist_data!$S$6:$AI$256, MATCH(P$13, hist_data!$S$6:$S$256, 0), MATCH($C23, hist_data!$A$6:$A$21, 0)+1) )} -> 3.296 | R23: =IF($E23="", "", AVERAGE( OFFSET( hist_data!$S$7, 0, MATCH($C23, hist_data!$A$6:$A$21, 0), R$13 ) )) -> 3.28125 | S23: =IF($E23="","",MAX(OFFSET(hist_data!$S$7,0,MATCH($C23,hist_data!$A$6:$A$21,0),S$13))) -> 3.361 | T23: =IF($E23="","",MIN(OFFSET(hist_data!$S$7,0,MATCH($C23,hist_data!$A$6:$A$21,0),T$13))) -> 3.205 | U23: =IF($E23="", "", AVERAGE( OFFSET( hist_data!$S$7, 0, MATCH($C23, hist_data!$A$6:$A$21, 0), U$13 ) )) -> 3.4165833 | V23: =IF($E23="","",MAX(OFFSET(hist_data!$S$7,0,MATCH($C23,hist_data!$A$6:$A$21,0),V$13))) -> 3.592 | W23: =IF($E23="","",MIN(OFFSET(hist_data!$S$7,0,MATCH($C23,hist_data!$A$6:$A$21,0),W$13))) -> 3.205 | X23: =IF($E23="", "", AVERAGE( OFFSET( hist_data!$S$7, 0, MATCH($C23, hist_data!$A$6:$A$21, 0), X$13 ) )) -> 3.5050917 | Y23: =IF($E23="","",MAX(OFFSET(hist_data!$S$7,0,MATCH($C23,hist_data!$A$6:$A$21,0),Y$13))) -> 3.672 | Z23: =IF($E23="","",MIN(OFFSET(hist_data!$S$7,0,MATCH($C23,hist_data!$A$6:$A$21,0),Z$13))) -> 3.205 | AA23: =IF($E23="", "", AVERAGE( OFFSET( hist_data!$S$7, 0, MATCH($C23, hist_data!$A$6:$A$21, 0), AA$13 ) )) -> 3.678644 | AB23: =IF($E23="","",MAX(OFFSET(hist_data!$S$7,0,MATCH($C23,hist_data!$A$6:$A$21,0),AB$13))) -> 4.105 | AC23: =IF($E23="","",MIN(OFFSET(hist_data!$S$7,0,MATCH($C23,hist_data!$A$6:$A$21,0),AC$13))) -> 3.205
C24: SP(bp) | E24: =IFERROR( (E$16-E23)*100, "") -> -33.7 | F24: =IFERROR( (F$16-F23)*100, "") -> -35.9 | G24: =IFERROR( (G$16-G23)*100, "") -> -32.8 | H24: =IFERROR( (H$16-H23)*100, "") -> -29.9 | I24: =IFERROR( (I$16-I23)*100, "") -> -29.8 | J24: =IFERROR( (J$16-J23)*100, "") -> -31.7 | K24: =IFERROR( (K$16-K23)*100, "") -> -31.6 | L24: =IFERROR( (L$16-L23)*100, "") -> -30.4 | ... P24: =IFERROR( (P$16-P23)*100, "") -> -29.6 | R24: =IFERROR( (R$16-R23)*100, "") -> -31.12 | S24: =IFERROR( (S$16-S23)*100, "") -> -27.4 | T24: =IFERROR( (T$16-T23)*100, "") -> -39 | U24: =IFERROR( (U$16-U23)*100, "") -> -26.995 | V24: =IFERROR( (V$16-V23)*100, "") -> -14 | W24: =IFERROR( (W$16-W23)*100, "") -> -39 | X24: =IFERROR( (X$16-X23)*100, "") -> -23.89 | Y24: =IFERROR( (Y$16-Y23)*100, "") -> -13.2 | ... AC24: =IFERROR( (AC$16-AC23)*100, "") -> -39
A25: 5 | C25: {=INDEX(hist_data!$A$6:$A$21, Hist!$A25)} -> 1.5Y | E25: {=IF( INDEX(hist_data!$S$6:$AI$256, MATCH(E$13, hist_data!$S$6:$S$256, 0), MATCH($C25, hist_data!$A$6:$A$21, 0)+1)=0, "", INDEX(hist_data!$S$6:$AI$256, MATCH(E$13, hist_data!$S$6:$S$256, 0), MATCH($C25, hist_data!$A$6:$A$21, 0)+1) )} -> 3.197 | F25: {=IF( INDEX(hist_data!$S$6:$AI$256, MATCH(F$13, hist_data!$S$6:$S$256, 0), MATCH($C25, hist_data!$A$6:$A$21, 0)+1)=0, "", INDEX(hist_data!$S$6:$AI$256, MATCH(F$13, hist_data!$S$6:$S$256, 0), MATCH($C25, hist_data!$A$6:$A$21, 0)+1) )} -> 3.16 | G25: {=IF( INDEX(hist_data!$S$6:$AI$256, MATCH(G$13, hist_data!$S$6:$S$256, 0), MATCH($C25, hist_data!$A$6:$A$21, 0)+1)=0, "", INDEX(hist_data!$S$6:$AI$256, MATCH(G$13, hist_data!$S$6:$S$256, 0), MATCH($C25, hist_data!$A$6:$A$21, 0)+1) )} -> 3.161 | H25: {=IF( INDEX(hist_data!$S$6:$AI$256, MATCH(H$13, hist_data!$S$6:$S$256, 0), MATCH($C25, hist_data!$A$6:$A$21, 0)+1)=0, "", INDEX(hist_data!$S$6:$AI$256, MATCH(H$13, hist_data!$S$6:$S$256, 0), MATCH($C25, hist_data!$A$6:$A$21, 0)+1) )} -> 3.171 | I25: {=IF( INDEX(hist_data!$S$6:$AI$256, MATCH(I$13, hist_data!$S$6:$S$256, 0), MATCH($C25, hist_data!$A$6:$A$21, 0)+1)=0, "", INDEX(hist_data!$S$6:$AI$256, MATCH(I$13, hist_data!$S$6:$S$256, 0), MATCH($C25, hist_data!$A$6:$A$21, 0)+1) )} -> 3.168 | J25: {=IF( INDEX(hist_data!$S$6:$AI$256, MATCH(J$13, hist_data!$S$6:$S$256, 0), MATCH($C25, hist_data!$A$6:$A$21, 0)+1)=0, "", INDEX(hist_data!$S$6:$AI$256, MATCH(J$13, hist_data!$S$6:$S$256, 0), MATCH($C25, hist_data!$A$6:$A$21, 0)+1) )} -> 3.163 | K25: {=IF( INDEX(hist_data!$S$6:$AI$256, MATCH(K$13, hist_data!$S$6:$S$256, 0), MATCH($C25, hist_data!$A$6:$A$21, 0)+1)=0, "", INDEX(hist_data!$S$6:$AI$256, MATCH(K$13, hist_data!$S$6:$S$256, 0), MATCH($C25, hist_data!$A$6:$A$21, 0)+1) )} -> 3.179 | L25: {=IF( INDEX(hist_data!$S$6:$AI$256, MATCH(L$13, hist_data!$S$6:$S$256, 0), MATCH($C25, hist_data!$A$6:$A$21, 0)+1)=0, "", INDEX(hist_data!$S$6:$AI$256, MATCH(L$13, hist_data!$S$6:$S$256, 0), MATCH($C25, hist_data!$A$6:$A$21, 0)+1) )} -> 3.179 | ... P25: {=IF( INDEX(hist_data!$S$6:$AI$256, MATCH(P$13, hist_data!$S$6:$S$256, 0), MATCH($C25, hist_data!$A$6:$A$21, 0)+1)=0, "", INDEX(hist_data!$S$6:$AI$256, MATCH(P$13, hist_data!$S$6:$S$256, 0), MATCH($C25, hist_data!$A$6:$A$21, 0)+1) )} -> 3.233 | R25: =IF($E25="", "", AVERAGE( OFFSET( hist_data!$S$7, 0, MATCH($C25, hist_data!$A$6:$A$21, 0), R$13 ) )) -> 3.20445 | S25: =IF($E25="","",MAX(OFFSET(hist_data!$S$7,0,MATCH($C25,hist_data!$A$6:$A$21,0),S$13))) -> 3.27 | T25: =IF($E25="","",MIN(OFFSET(hist_data!$S$7,0,MATCH($C25,hist_data!$A$6:$A$21,0),T$13))) -> 3.108 | U25: =IF($E25="", "", AVERAGE( OFFSET( hist_data!$S$7, 0, MATCH($C25, hist_data!$A$6:$A$21, 0), U$13 ) )) -> 3.3509667 | V25: =IF($E25="","",MAX(OFFSET(hist_data!$S$7,0,MATCH($C25,hist_data!$A$6:$A$21,0),V$13))) -> 3.6 | W25: =IF($E25="","",MIN(OFFSET(hist_data!$S$7,0,MATCH($C25,hist_data!$A$6:$A$21,0),W$13))) -> 3.108 | X25: =IF($E25="", "", AVERAGE( OFFSET( hist_data!$S$7, 0, MATCH($C25, hist_data!$A$6:$A$21, 0), X$13 ) )) -> 3.4648833 | Y25: =IF($E25="","",MAX(OFFSET(hist_data!$S$7,0,MATCH($C25,hist_data!$A$6:$A$21,0),Y$13))) -> 3.647 | Z25: =IF($E25="","",MIN(OFFSET(hist_data!$S$7,0,MATCH($C25,hist_data!$A$6:$A$21,0),Z$13))) -> 3.108 | AA25: =IF($E25="", "", AVERAGE( OFFSET( hist_data!$S$7, 0, MATCH($C25, hist_data!$A$6:$A$21, 0), AA$13 ) )) -> 3.697732 | AB25: =IF($E25="","",MAX(OFFSET(hist_data!$S$7,0,MATCH($C25,hist_data!$A$6:$A$21,0),AB$13))) -> 4.314 | AC25: =IF($E25="","",MIN(OFFSET(hist_data!$S$7,0,MATCH($C25,hist_data!$A$6:$A$21,0),AC$13))) -> 3.108
C26: SP(bp) | E26: =IFERROR( (E$16-E25)*100, "") -> -27.5 | F26: =IFERROR( (F$16-F25)*100, "") -> -27.3 | G26: =IFERROR( (G$16-G25)*100, "") -> -24.6 | H26: =IFERROR( (H$16-H25)*100, "") -> -22.6 | I26: =IFERROR( (I$16-I25)*100, "") -> -22.8 | J26: =IFERROR( (J$16-J25)*100, "") -> -24.4 | K26: =IFERROR( (K$16-K25)*100, "") -> -24.8 | L26: =IFERROR( (L$16-L25)*100, "") -> -23.9 | ... P26: =IFERROR( (P$16-P25)*100, "") -> -23.3 | R26: =IFERROR( (R$16-R25)*100, "") -> -23.44 | S26: =IFERROR( (S$16-S25)*100, "") -> -18.3 | T26: =IFERROR( (T$16-T25)*100, "") -> -29.3 | U26: =IFERROR( (U$16-U25)*100, "") -> -20.433333 | V26: =IFERROR( (V$16-V25)*100, "") -> -14.8 | W26: =IFERROR( (W$16-W25)*100, "") -> -29.3 | X26: =IFERROR( (X$16-X25)*100, "") -> -19.869167 | Y26: =IFERROR( (Y$16-Y25)*100, "") -> -10.7 | ... AC26: =IFERROR( (AC$16-AC25)*100, "") -> -29.3
A27: 6 | C27: {=INDEX(hist_data!$A$6:$A$21, Hist!$A27)} -> 02Y | E27: {=IF( INDEX(hist_data!$S$6:$AI$256, MATCH(E$13, hist_data!$S$6:$S$256, 0), MATCH($C27, hist_data!$A$6:$A$21, 0)+1)=0, "", INDEX(hist_data!$S$6:$AI$256, MATCH(E$13, hist_data!$S$6:$S$256, 0), MATCH($C27, hist_data!$A$6:$A$21, 0)+1) )} -> 3.186 | F27: {=IF( INDEX(hist_data!$S$6:$AI$256, MATCH(F$13, hist_data!$S$6:$S$256, 0), MATCH($C27, hist_data!$A$6:$A$21, 0)+1)=0, "", INDEX(hist_data!$S$6:$AI$256, MATCH(F$13, hist_data!$S$6:$S$256, 0), MATCH($C27, hist_data!$A$6:$A$21, 0)+1) )} -> 3.144 | G27: {=IF( INDEX(hist_data!$S$6:$AI$256, MATCH(G$13, hist_data!$S$6:$S$256, 0), MATCH($C27, hist_data!$A$6:$A$21, 0)+1)=0, "", INDEX(hist_data!$S$6:$AI$256, MATCH(G$13, hist_data!$S$6:$S$256, 0), MATCH($C27, hist_data!$A$6:$A$21, 0)+1) )} -> 3.143 | H27: {=IF( INDEX(hist_data!$S$6:$AI$256, MATCH(H$13, hist_data!$S$6:$S$256, 0), MATCH($C27, hist_data!$A$6:$A$21, 0)+1)=0, "", INDEX(hist_data!$S$6:$AI$256, MATCH(H$13, hist_data!$S$6:$S$256, 0), MATCH($C27, hist_data!$A$6:$A$21, 0)+1) )} -> 3.154 | I27: {=IF( INDEX(hist_data!$S$6:$AI$256, MATCH(I$13, hist_data!$S$6:$S$256, 0), MATCH($C27, hist_data!$A$6:$A$21, 0)+1)=0, "", INDEX(hist_data!$S$6:$AI$256, MATCH(I$13, hist_data!$S$6:$S$256, 0), MATCH($C27, hist_data!$A$6:$A$21, 0)+1) )} -> 3.143 | J27: {=IF( INDEX(hist_data!$S$6:$AI$256, MATCH(J$13, hist_data!$S$6:$S$256, 0), MATCH($C27, hist_data!$A$6:$A$21, 0)+1)=0, "", INDEX(hist_data!$S$6:$AI$256, MATCH(J$13, hist_data!$S$6:$S$256, 0), MATCH($C27, hist_data!$A$6:$A$21, 0)+1) )} -> 3.123 | K27: {=IF( INDEX(hist_data!$S$6:$AI$256, MATCH(K$13, hist_data!$S$6:$S$256, 0), MATCH($C27, hist_data!$A$6:$A$21, 0)+1)=0, "", INDEX(hist_data!$S$6:$AI$256, MATCH(K$13, hist_data!$S$6:$S$256, 0), MATCH($C27, hist_data!$A$6:$A$21, 0)+1) )} -> 3.14 | L27: {=IF( INDEX(hist_data!$S$6:$AI$256, MATCH(L$13, hist_data!$S$6:$S$256, 0), MATCH($C27, hist_data!$A$6:$A$21, 0)+1)=0, "", INDEX(hist_data!$S$6:$AI$256, MATCH(L$13, hist_data!$S$6:$S$256, 0), MATCH($C27, hist_data!$A$6:$A$21, 0)+1) )} -> 3.154 | ... P27: {=IF( INDEX(hist_data!$S$6:$AI$256, MATCH(P$13, hist_data!$S$6:$S$256, 0), MATCH($C27, hist_data!$A$6:$A$21, 0)+1)=0, "", INDEX(hist_data!$S$6:$AI$256, MATCH(P$13, hist_data!$S$6:$S$256, 0), MATCH($C27, hist_data!$A$6:$A$21, 0)+1) )} -> 3.2 | R27: =IF($E27="", "", AVERAGE( OFFSET( hist_data!$S$7, 0, MATCH($C27, hist_data!$A$6:$A$21, 0), R$13 ) )) -> 3.17265 | S27: =IF($E27="","",MAX(OFFSET(hist_data!$S$7,0,MATCH($C27,hist_data!$A$6:$A$21,0),S$13))) -> 3.24 | T27: =IF($E27="","",MIN(OFFSET(hist_data!$S$7,0,MATCH($C27,hist_data!$A$6:$A$21,0),T$13))) -> 3.049 | U27: =IF($E27="", "", AVERAGE( OFFSET( hist_data!$S$7, 0, MATCH($C27, hist_data!$A$6:$A$21, 0), U$13 ) )) -> 3.3297167 | V27: =IF($E27="","",MAX(OFFSET(hist_data!$S$7,0,MATCH($C27,hist_data!$A$6:$A$21,0),V$13))) -> 3.589 | W27: =IF($E27="","",MIN(OFFSET(hist_data!$S$7,0,MATCH($C27,hist_data!$A$6:$A$21,0),W$13))) -> 3.049 | X27: =IF($E27="", "", AVERAGE( OFFSET( hist_data!$S$7, 0, MATCH($C27, hist_data!$A$6:$A$21, 0), X$13 ) )) -> 3.4565417 | Y27: =IF($E27="","",MAX(OFFSET(hist_data!$S$7,0,MATCH($C27,hist_data!$A$6:$A$21,0),Y$13))) -> 3.673 | Z27: =IF($E27="","",MIN(OFFSET(hist_data!$S$7,0,MATCH($C27,hist_data!$A$6:$A$21,0),Z$13))) -> 3.049 | AA27: =IF($E27="", "", AVERAGE( OFFSET( hist_data!$S$7, 0, MATCH($C27, hist_data!$A$6:$A$21, 0), AA$13 ) )) -> 3.71822 | AB27: =IF($E27="","",MAX(OFFSET(hist_data!$S$7,0,MATCH($C27,hist_data!$A$6:$A$21,0),AB$13))) -> 4.447 | AC27: =IF($E27="","",MIN(OFFSET(hist_data!$S$7,0,MATCH($C27,hist_data!$A$6:$A$21,0),AC$13))) -> 3.049
C28: SP(bp) | E28: =IFERROR( (E$16-E27)*100, "") -> -26.4 | F28: =IFERROR( (F$16-F27)*100, "") -> -25.7 | G28: =IFERROR( (G$16-G27)*100, "") -> -22.8 | H28: =IFERROR( (H$16-H27)*100, "") -> -20.9 | I28: =IFERROR( (I$16-I27)*100, "") -> -20.3 | J28: =IFERROR( (J$16-J27)*100, "") -> -20.4 | K28: =IFERROR( (K$16-K27)*100, "") -> -20.9 | L28: =IFERROR( (L$16-L27)*100, "") -> -21.4 | ... P28: =IFERROR( (P$16-P27)*100, "") -> -20 | R28: =IFERROR( (R$16-R27)*100, "") -> -20.26 | S28: =IFERROR( (S$16-S27)*100, "") -> -15.3 | T28: =IFERROR( (T$16-T27)*100, "") -> -23.4 | U28: =IFERROR( (U$16-U27)*100, "") -> -18.308333 | V28: =IFERROR( (V$16-V27)*100, "") -> -13.7 | W28: =IFERROR( (W$16-W27)*100, "") -> -23.4 | X28: =IFERROR( (X$16-X27)*100, "") -> -19.035 | Y28: =IFERROR( (Y$16-Y27)*100, "") -> -13.3 | ... AC28: =IFERROR( (AC$16-AC27)*100, "") -> -23.4
A29: 7 | C29: {=INDEX(hist_data!$A$6:$A$21, Hist!$A29)} -> 2.5Y | E29: {=IF( INDEX(hist_data!$S$6:$AI$256, MATCH(E$13, hist_data!$S$6:$S$256, 0), MATCH($C29, hist_data!$A$6:$A$21, 0)+1)=0, "", INDEX(hist_data!$S$6:$AI$256, MATCH(E$13, hist_data!$S$6:$S$256, 0), MATCH($C29, hist_data!$A$6:$A$21, 0)+1) )} -> 3.156 | F29: {=IF( INDEX(hist_data!$S$6:$AI$256, MATCH(F$13, hist_data!$S$6:$S$256, 0), MATCH($C29, hist_data!$A$6:$A$21, 0)+1)=0, "", INDEX(hist_data!$S$6:$AI$256, MATCH(F$13, hist_data!$S$6:$S$256, 0), MATCH($C29, hist_data!$A$6:$A$21, 0)+1) )} -> 3.116 | G29: {=IF( INDEX(hist_data!$S$6:$AI$256, MATCH(G$13, hist_data!$S$6:$S$256, 0), MATCH($C29, hist_data!$A$6:$A$21, 0)+1)=0, "", INDEX(hist_data!$S$6:$AI$256, MATCH(G$13, hist_data!$S$6:$S$256, 0), MATCH($C29, hist_data!$A$6:$A$21, 0)+1) )} -> 3.127 | H29: {=IF( INDEX(hist_data!$S$6:$AI$256, MATCH(H$13, hist_data!$S$6:$S$256, 0), MATCH($C29, hist_data!$A$6:$A$21, 0)+1)=0, "", INDEX(hist_data!$S$6:$AI$256, MATCH(H$13, hist_data!$S$6:$S$256, 0), MATCH($C29, hist_data!$A$6:$A$21, 0)+1) )} -> 3.146 | I29: {=IF( INDEX(hist_data!$S$6:$AI$256, MATCH(I$13, hist_data!$S$6:$S$256, 0), MATCH($C29, hist_data!$A$6:$A$21, 0)+1)=0, "", INDEX(hist_data!$S$6:$AI$256, MATCH(I$13, hist_data!$S$6:$S$256, 0), MATCH($C29, hist_data!$A$6:$A$21, 0)+1) )} -> 3.134 | J29: {=IF( INDEX(hist_data!$S$6:$AI$256, MATCH(J$13, hist_data!$S$6:$S$256, 0), MATCH($C29, hist_data!$A$6:$A$21, 0)+1)=0, "", INDEX(hist_data!$S$6:$AI$256, MATCH(J$13, hist_data!$S$6:$S$256, 0), MATCH($C29, hist_data!$A$6:$A$21, 0)+1) )} -> 3.11 | K29: {=IF( INDEX(hist_data!$S$6:$AI$256, MATCH(K$13, hist_data!$S$6:$S$256, 0), MATCH($C29, hist_data!$A$6:$A$21, 0)+1)=0, "", INDEX(hist_data!$S$6:$AI$256, MATCH(K$13, hist_data!$S$6:$S$256, 0), MATCH($C29, hist_data!$A$6:$A$21, 0)+1) )} -> 3.126 | L29: {=IF( INDEX(hist_data!$S$6:$AI$256, MATCH(L$13, hist_data!$S$6:$S$256, 0), MATCH($C29, hist_data!$A$6:$A$21, 0)+1)=0, "", INDEX(hist_data!$S$6:$AI$256, MATCH(L$13, hist_data!$S$6:$S$256, 0), MATCH($C29, hist_data!$A$6:$A$21, 0)+1) )} -> 3.134 | ... P29: {=IF( INDEX(hist_data!$S$6:$AI$256, MATCH(P$13, hist_data!$S$6:$S$256, 0), MATCH($C29, hist_data!$A$6:$A$21, 0)+1)=0, "", INDEX(hist_data!$S$6:$AI$256, MATCH(P$13, hist_data!$S$6:$S$256, 0), MATCH($C29, hist_data!$A$6:$A$21, 0)+1) )} -> 3.195 | R29: =IF($E29="", "", AVERAGE( OFFSET( hist_data!$S$7, 0, MATCH($C29, hist_data!$A$6:$A$21, 0), R$13 ) )) -> 3.1602 | S29: =IF($E29="","",MAX(OFFSET(hist_data!$S$7,0,MATCH($C29,hist_data!$A$6:$A$21,0),S$13))) -> 3.238 | T29: =IF($E29="","",MIN(OFFSET(hist_data!$S$7,0,MATCH($C29,hist_data!$A$6:$A$21,0),T$13))) -> 3.02 | U29: =IF($E29="", "", AVERAGE( OFFSET( hist_data!$S$7, 0, MATCH($C29, hist_data!$A$6:$A$21, 0), U$13 ) )) -> 3.3249167 | V29: =IF($E29="","",MAX(OFFSET(hist_data!$S$7,0,MATCH($C29,hist_data!$A$6:$A$21,0),V$13))) -> 3.604 | W29: =IF($E29="","",MIN(OFFSET(hist_data!$S$7,0,MATCH($C29,hist_data!$A$6:$A$21,0),W$13))) -> 3.02 | X29: =IF($E29="", "", AVERAGE( OFFSET( hist_data!$S$7, 0, MATCH($C29, hist_data!$A$6:$A$21, 0), X$13 ) )) -> 3.4554917 | Y29: =IF($E29="","",MAX(OFFSET(hist_data!$S$7,0,MATCH($C29,hist_data!$A$6:$A$21,0),Y$13))) -> 3.68 | Z29: =IF($E29="","",MIN(OFFSET(hist_data!$S$7,0,MATCH($C29,hist_data!$A$6:$A$21,0),Z$13))) -> 3.02 | AA29: =IF($E29="", "", AVERAGE( OFFSET( hist_data!$S$7, 0, MATCH($C29, hist_data!$A$6:$A$21, 0), AA$13 ) )) -> 3.723716 | AB29: =IF($E29="","",MAX(OFFSET(hist_data!$S$7,0,MATCH($C29,hist_data!$A$6:$A$21,0),AB$13))) -> 4.498 | AC29: =IF($E29="","",MIN(OFFSET(hist_data!$S$7,0,MATCH($C29,hist_data!$A$6:$A$21,0),AC$13))) -> 3.02
C30: SP(bp) | E30: =IFERROR( (E$16-E29)*100, "") -> -23.4 | F30: =IFERROR( (F$16-F29)*100, "") -> -22.9 | G30: =IFERROR( (G$16-G29)*100, "") -> -21.2 | H30: =IFERROR( (H$16-H29)*100, "") -> -20.1 | I30: =IFERROR( (I$16-I29)*100, "") -> -19.4 | J30: =IFERROR( (J$16-J29)*100, "") -> -19.1 | K30: =IFERROR( (K$16-K29)*100, "") -> -19.5 | L30: =IFERROR( (L$16-L29)*100, "") -> -19.4 | ... P30: =IFERROR( (P$16-P29)*100, "") -> -19.5 | R30: =IFERROR( (R$16-R29)*100, "") -> -19.015 | S30: =IFERROR( (S$16-S29)*100, "") -> -15.1 | T30: =IFERROR( (T$16-T29)*100, "") -> -20.5 | U30: =IFERROR( (U$16-U29)*100, "") -> -17.828333 | V30: =IFERROR( (V$16-V29)*100, "") -> -15.2 | W30: =IFERROR( (W$16-W29)*100, "") -> -20.5 | X30: =IFERROR( (X$16-X29)*100, "") -> -18.93 | Y30: =IFERROR( (Y$16-Y29)*100, "") -> -14 | ... AC30: =IFERROR( (AC$16-AC29)*100, "") -> -20.5
A31: 8 | C31: {=INDEX(hist_data!$A$6:$A$21, Hist!$A31)} -> 03Y | E31: {=IF( INDEX(hist_data!$S$6:$AI$256, MATCH(E$13, hist_data!$S$6:$S$256, 0), MATCH($C31, hist_data!$A$6:$A$21, 0)+1)=0, "", INDEX(hist_data!$S$6:$AI$256, MATCH(E$13, hist_data!$S$6:$S$256, 0), MATCH($C31, hist_data!$A$6:$A$21, 0)+1) )} -> 3.154 | F31: {=IF( INDEX(hist_data!$S$6:$AI$256, MATCH(F$13, hist_data!$S$6:$S$256, 0), MATCH($C31, hist_data!$A$6:$A$21, 0)+1)=0, "", INDEX(hist_data!$S$6:$AI$256, MATCH(F$13, hist_data!$S$6:$S$256, 0), MATCH($C31, hist_data!$A$6:$A$21, 0)+1) )} -> 3.109 | G31: {=IF( INDEX(hist_data!$S$6:$AI$256, MATCH(G$13, hist_data!$S$6:$S$256, 0), MATCH($C31, hist_data!$A$6:$A$21, 0)+1)=0, "", INDEX(hist_data!$S$6:$AI$256, MATCH(G$13, hist_data!$S$6:$S$256, 0), MATCH($C31, hist_data!$A$6:$A$21, 0)+1) )} -> 3.127 | H31: {=IF( INDEX(hist_data!$S$6:$AI$256, MATCH(H$13, hist_data!$S$6:$S$256, 0), MATCH($C31, hist_data!$A$6:$A$21, 0)+1)=0, "", INDEX(hist_data!$S$6:$AI$256, MATCH(H$13, hist_data!$S$6:$S$256, 0), MATCH($C31, hist_data!$A$6:$A$21, 0)+1) )} -> 3.145 | I31: {=IF( INDEX(hist_data!$S$6:$AI$256, MATCH(I$13, hist_data!$S$6:$S$256, 0), MATCH($C31, hist_data!$A$6:$A$21, 0)+1)=0, "", INDEX(hist_data!$S$6:$AI$256, MATCH(I$13, hist_data!$S$6:$S$256, 0), MATCH($C31, hist_data!$A$6:$A$21, 0)+1) )} -> 3.139 | J31: {=IF( INDEX(hist_data!$S$6:$AI$256, MATCH(J$13, hist_data!$S$6:$S$256, 0), MATCH($C31, hist_data!$A$6:$A$21, 0)+1)=0, "", INDEX(hist_data!$S$6:$AI$256, MATCH(J$13, hist_data!$S$6:$S$256, 0), MATCH($C31, hist_data!$A$6:$A$21, 0)+1) )} -> 3.119 | K31: {=IF( INDEX(hist_data!$S$6:$AI$256, MATCH(K$13, hist_data!$S$6:$S$256, 0), MATCH($C31, hist_data!$A$6:$A$21, 0)+1)=0, "", INDEX(hist_data!$S$6:$AI$256, MATCH(K$13, hist_data!$S$6:$S$256, 0), MATCH($C31, hist_data!$A$6:$A$21, 0)+1) )} -> 3.133 | L31: {=IF( INDEX(hist_data!$S$6:$AI$256, MATCH(L$13, hist_data!$S$6:$S$256, 0), MATCH($C31, hist_data!$A$6:$A$21, 0)+1)=0, "", INDEX(hist_data!$S$6:$AI$256, MATCH(L$13, hist_data!$S$6:$S$256, 0), MATCH($C31, hist_data!$A$6:$A$21, 0)+1) )} -> 3.145 | ... P31: {=IF( INDEX(hist_data!$S$6:$AI$256, MATCH(P$13, hist_data!$S$6:$S$256, 0), MATCH($C31, hist_data!$A$6:$A$21, 0)+1)=0, "", INDEX(hist_data!$S$6:$AI$256, MATCH(P$13, hist_data!$S$6:$S$256, 0), MATCH($C31, hist_data!$A$6:$A$21, 0)+1) )} -> 3.193 | R31: =IF($E31="", "", AVERAGE( OFFSET( hist_data!$S$7, 0, MATCH($C31, hist_data!$A$6:$A$21, 0), R$13 ) )) -> 3.16245 | S31: =IF($E31="","",MAX(OFFSET(hist_data!$S$7,0,MATCH($C31,hist_data!$A$6:$A$21,0),S$13))) -> 3.242 | T31: =IF($E31="","",MIN(OFFSET(hist_data!$S$7,0,MATCH($C31,hist_data!$A$6:$A$21,0),T$13))) -> 3.024 | U31: =IF($E31="", "", AVERAGE( OFFSET( hist_data!$S$7, 0, MATCH($C31, hist_data!$A$6:$A$21, 0), U$13 ) )) -> 3.32485 | V31: =IF($E31="","",MAX(OFFSET(hist_data!$S$7,0,MATCH($C31,hist_data!$A$6:$A$21,0),V$13))) -> 3.61 | W31: =IF($E31="","",MIN(OFFSET(hist_data!$S$7,0,MATCH($C31,hist_data!$A$6:$A$21,0),W$13))) -> 3.024 | X31: =IF($E31="", "", AVERAGE( OFFSET( hist_data!$S$7, 0, MATCH($C31, hist_data!$A$6:$A$21, 0), X$13 ) )) -> 3.45665 | Y31: =IF($E31="","",MAX(OFFSET(hist_data!$S$7,0,MATCH($C31,hist_data!$A$6:$A$21,0),Y$13))) -> 3.705 | Z31: =IF($E31="","",MIN(OFFSET(hist_data!$S$7,0,MATCH($C31,hist_data!$A$6:$A$21,0),Z$13))) -> 3.024 | AA31: =IF($E31="", "", AVERAGE( OFFSET( hist_data!$S$7, 0, MATCH($C31, hist_data!$A$6:$A$21, 0), AA$13 ) )) -> 3.73316 | AB31: =IF($E31="","",MAX(OFFSET(hist_data!$S$7,0,MATCH($C31,hist_data!$A$6:$A$21,0),AB$13))) -> 4.58 | AC31: =IF($E31="","",MIN(OFFSET(hist_data!$S$7,0,MATCH($C31,hist_data!$A$6:$A$21,0),AC$13))) -> 3.024
C32: SP(bp) | E32: =IFERROR( (E$16-E31)*100, "") -> -23.2 | F32: =IFERROR( (F$16-F31)*100, "") -> -22.2 | G32: =IFERROR( (G$16-G31)*100, "") -> -21.2 | H32: =IFERROR( (H$16-H31)*100, "") -> -20 | I32: =IFERROR( (I$16-I31)*100, "") -> -19.9 | J32: =IFERROR( (J$16-J31)*100, "") -> -20 | K32: =IFERROR( (K$16-K31)*100, "") -> -20.2 | L32: =IFERROR( (L$16-L31)*100, "") -> -20.5 | ... P32: =IFERROR( (P$16-P31)*100, "") -> -19.3 | R32: =IFERROR( (R$16-R31)*100, "") -> -19.24 | S32: =IFERROR( (S$16-S31)*100, "") -> -15.5 | T32: =IFERROR( (T$16-T31)*100, "") -> -20.9 | U32: =IFERROR( (U$16-U31)*100, "") -> -17.821667 | V32: =IFERROR( (V$16-V31)*100, "") -> -15.8 | W32: =IFERROR( (W$16-W31)*100, "") -> -20.9 | X32: =IFERROR( (X$16-X31)*100, "") -> -19.045833 | Y32: =IFERROR( (Y$16-Y31)*100, "") -> -16.5 | ... AC32: =IFERROR( (AC$16-AC31)*100, "") -> -20.9
A33: 9 | C33: {=INDEX(hist_data!$A$6:$A$21, Hist!$A33)} -> 04Y | E33: {=IF( INDEX(hist_data!$S$6:$AI$256, MATCH(E$13, hist_data!$S$6:$S$256, 0), MATCH($C33, hist_data!$A$6:$A$21, 0)+1)=0, "", INDEX(hist_data!$S$6:$AI$256, MATCH(E$13, hist_data!$S$6:$S$256, 0), MATCH($C33, hist_data!$A$6:$A$21, 0)+1) )} -> 3.146 | F33: {=IF( INDEX(hist_data!$S$6:$AI$256, MATCH(F$13, hist_data!$S$6:$S$256, 0), MATCH($C33, hist_data!$A$6:$A$21, 0)+1)=0, "", INDEX(hist_data!$S$6:$AI$256, MATCH(F$13, hist_data!$S$6:$S$256, 0), MATCH($C33, hist_data!$A$6:$A$21, 0)+1) )} -> 3.112 | G33: {=IF( INDEX(hist_data!$S$6:$AI$256, MATCH(G$13, hist_data!$S$6:$S$256, 0), MATCH($C33, hist_data!$A$6:$A$21, 0)+1)=0, "", INDEX(hist_data!$S$6:$AI$256, MATCH(G$13, hist_data!$S$6:$S$256, 0), MATCH($C33, hist_data!$A$6:$A$21, 0)+1) )} -> 3.136 | H33: {=IF( INDEX(hist_data!$S$6:$AI$256, MATCH(H$13, hist_data!$S$6:$S$256, 0), MATCH($C33, hist_data!$A$6:$A$21, 0)+1)=0, "", INDEX(hist_data!$S$6:$AI$256, MATCH(H$13, hist_data!$S$6:$S$256, 0), MATCH($C33, hist_data!$A$6:$A$21, 0)+1) )} -> 3.154 | I33: {=IF( INDEX(hist_data!$S$6:$AI$256, MATCH(I$13, hist_data!$S$6:$S$256, 0), MATCH($C33, hist_data!$A$6:$A$21, 0)+1)=0, "", INDEX(hist_data!$S$6:$AI$256, MATCH(I$13, hist_data!$S$6:$S$256, 0), MATCH($C33, hist_data!$A$6:$A$21, 0)+1) )} -> 3.15 | J33: {=IF( INDEX(hist_data!$S$6:$AI$256, MATCH(J$13, hist_data!$S$6:$S$256, 0), MATCH($C33, hist_data!$A$6:$A$21, 0)+1)=0, "", INDEX(hist_data!$S$6:$AI$256, MATCH(J$13, hist_data!$S$6:$S$256, 0), MATCH($C33, hist_data!$A$6:$A$21, 0)+1) )} -> 3.125 | K33: {=IF( INDEX(hist_data!$S$6:$AI$256, MATCH(K$13, hist_data!$S$6:$S$256, 0), MATCH($C33, hist_data!$A$6:$A$21, 0)+1)=0, "", INDEX(hist_data!$S$6:$AI$256, MATCH(K$13, hist_data!$S$6:$S$256, 0), MATCH($C33, hist_data!$A$6:$A$21, 0)+1) )} -> 3.139 | L33: {=IF( INDEX(hist_data!$S$6:$AI$256, MATCH(L$13, hist_data!$S$6:$S$256, 0), MATCH($C33, hist_data!$A$6:$A$21, 0)+1)=0, "", INDEX(hist_data!$S$6:$AI$256, MATCH(L$13, hist_data!$S$6:$S$256, 0), MATCH($C33, hist_data!$A$6:$A$21, 0)+1) )} -> 3.141 | ... P33: {=IF( INDEX(hist_data!$S$6:$AI$256, MATCH(P$13, hist_data!$S$6:$S$256, 0), MATCH($C33, hist_data!$A$6:$A$21, 0)+1)=0, "", INDEX(hist_data!$S$6:$AI$256, MATCH(P$13, hist_data!$S$6:$S$256, 0), MATCH($C33, hist_data!$A$6:$A$21, 0)+1) )} -> 3.196 | R33: =IF($E33="", "", AVERAGE( OFFSET( hist_data!$S$7, 0, MATCH($C33, hist_data!$A$6:$A$21, 0), R$13 ) )) -> 3.16905 | S33: =IF($E33="","",MAX(OFFSET(hist_data!$S$7,0,MATCH($C33,hist_data!$A$6:$A$21,0),S$13))) -> 3.268 | T33: =IF($E33="","",MIN(OFFSET(hist_data!$S$7,0,MATCH($C33,hist_data!$A$6:$A$21,0),T$13))) -> 3.016 | U33: =IF($E33="", "", AVERAGE( OFFSET( hist_data!$S$7, 0, MATCH($C33, hist_data!$A$6:$A$21, 0), U$13 ) )) -> 3.32925 | V33: =IF($E33="","",MAX(OFFSET(hist_data!$S$7,0,MATCH($C33,hist_data!$A$6:$A$21,0),V$13))) -> 3.624 | W33: =IF($E33="","",MIN(OFFSET(hist_data!$S$7,0,MATCH($C33,hist_data!$A$6:$A$21,0),W$13))) -> 3.016 | X33: =IF($E33="", "", AVERAGE( OFFSET( hist_data!$S$7, 0, MATCH($C33, hist_data!$A$6:$A$21, 0), X$13 ) )) -> 3.4600833 | Y33: =IF($E33="","",MAX(OFFSET(hist_data!$S$7,0,MATCH($C33,hist_data!$A$6:$A$21,0),Y$13))) -> 3.723 | Z33: =IF($E33="","",MIN(OFFSET(hist_data!$S$7,0,MATCH($C33,hist_data!$A$6:$A$21,0),Z$13))) -> 3.016 | AA33: =IF($E33="", "", AVERAGE( OFFSET( hist_data!$S$7, 0, MATCH($C33, hist_data!$A$6:$A$21, 0), AA$13 ) )) -> 3.74464 | AB33: =IF($E33="","",MAX(OFFSET(hist_data!$S$7,0,MATCH($C33,hist_data!$A$6:$A$21,0),AB$13))) -> 4.628 | AC33: =IF($E33="","",MIN(OFFSET(hist_data!$S$7,0,MATCH($C33,hist_data!$A$6:$A$21,0),AC$13))) -> 3.016
C34: SP(bp) | E34: =IFERROR( (E$16-E33)*100, "") -> -22.4 | F34: =IFERROR( (F$16-F33)*100, "") -> -22.5 | G34: =IFERROR( (G$16-G33)*100, "") -> -22.1 | H34: =IFERROR( (H$16-H33)*100, "") -> -20.9 | I34: =IFERROR( (I$16-I33)*100, "") -> -21 | J34: =IFERROR( (J$16-J33)*100, "") -> -20.6 | K34: =IFERROR( (K$16-K33)*100, "") -> -20.8 | L34: =IFERROR( (L$16-L33)*100, "") -> -20.1 | ... P34: =IFERROR( (P$16-P33)*100, "") -> -19.6 | R34: =IFERROR( (R$16-R33)*100, "") -> -19.9 | S34: =IFERROR( (S$16-S33)*100, "") -> -18.1 | T34: =IFERROR( (T$16-T33)*100, "") -> -20.1 | U34: =IFERROR( (U$16-U33)*100, "") -> -18.261667 | V34: =IFERROR( (V$16-V33)*100, "") -> -17.2 | W34: =IFERROR( (W$16-W33)*100, "") -> -20.1 | X34: =IFERROR( (X$16-X33)*100, "") -> -19.389167 | Y34: =IFERROR( (Y$16-Y33)*100, "") -> -18.3 | ... AC34: =IFERROR( (AC$16-AC33)*100, "") -> -20.1
A35: 10 | C35: {=INDEX(hist_data!$A$6:$A$21, Hist!$A35)} -> 05Y | E35: {=IF( INDEX(hist_data!$S$6:$AI$256, MATCH(E$13, hist_data!$S$6:$S$256, 0), MATCH($C35, hist_data!$A$6:$A$21, 0)+1)=0, "", INDEX(hist_data!$S$6:$AI$256, MATCH(E$13, hist_data!$S$6:$S$256, 0), MATCH($C35, hist_data!$A$6:$A$21, 0)+1) )} -> 3.146 | F35: {=IF( INDEX(hist_data!$S$6:$AI$256, MATCH(F$13, hist_data!$S$6:$S$256, 0), MATCH($C35, hist_data!$A$6:$A$21, 0)+1)=0, "", INDEX(hist_data!$S$6:$AI$256, MATCH(F$13, hist_data!$S$6:$S$256, 0), MATCH($C35, hist_data!$A$6:$A$21, 0)+1) )} -> 3.114 | G35: {=IF( INDEX(hist_data!$S$6:$AI$256, MATCH(G$13, hist_data!$S$6:$S$256, 0), MATCH($C35, hist_data!$A$6:$A$21, 0)+1)=0, "", INDEX(hist_data!$S$6:$AI$256, MATCH(G$13, hist_data!$S$6:$S$256, 0), MATCH($C35, hist_data!$A$6:$A$21, 0)+1) )} -> 3.139 | H35: {=IF( INDEX(hist_data!$S$6:$AI$256, MATCH(H$13, hist_data!$S$6:$S$256, 0), MATCH($C35, hist_data!$A$6:$A$21, 0)+1)=0, "", INDEX(hist_data!$S$6:$AI$256, MATCH(H$13, hist_data!$S$6:$S$256, 0), MATCH($C35, hist_data!$A$6:$A$21, 0)+1) )} -> 3.154 | I35: {=IF( INDEX(hist_data!$S$6:$AI$256, MATCH(I$13, hist_data!$S$6:$S$256, 0), MATCH($C35, hist_data!$A$6:$A$21, 0)+1)=0, "", INDEX(hist_data!$S$6:$AI$256, MATCH(I$13, hist_data!$S$6:$S$256, 0), MATCH($C35, hist_data!$A$6:$A$21, 0)+1) )} -> 3.152 | J35: {=IF( INDEX(hist_data!$S$6:$AI$256, MATCH(J$13, hist_data!$S$6:$S$256, 0), MATCH($C35, hist_data!$A$6:$A$21, 0)+1)=0, "", INDEX(hist_data!$S$6:$AI$256, MATCH(J$13, hist_data!$S$6:$S$256, 0), MATCH($C35, hist_data!$A$6:$A$21, 0)+1) )} -> 3.131 | K35: {=IF( INDEX(hist_data!$S$6:$AI$256, MATCH(K$13, hist_data!$S$6:$S$256, 0), MATCH($C35, hist_data!$A$6:$A$21, 0)+1)=0, "", INDEX(hist_data!$S$6:$AI$256, MATCH(K$13, hist_data!$S$6:$S$256, 0), MATCH($C35, hist_data!$A$6:$A$21, 0)+1) )} -> 3.143 | L35: {=IF( INDEX(hist_data!$S$6:$AI$256, MATCH(L$13, hist_data!$S$6:$S$256, 0), MATCH($C35, hist_data!$A$6:$A$21, 0)+1)=0, "", INDEX(hist_data!$S$6:$AI$256, MATCH(L$13, hist_data!$S$6:$S$256, 0), MATCH($C35, hist_data!$A$6:$A$21, 0)+1) )} -> 3.147 | ... P35: {=IF( INDEX(hist_data!$S$6:$AI$256, MATCH(P$13, hist_data!$S$6:$S$256, 0), MATCH($C35, hist_data!$A$6:$A$21, 0)+1)=0, "", INDEX(hist_data!$S$6:$AI$256, MATCH(P$13, hist_data!$S$6:$S$256, 0), MATCH($C35, hist_data!$A$6:$A$21, 0)+1) )} -> 3.2 | R35: =IF($E35="", "", AVERAGE( OFFSET( hist_data!$S$7, 0, MATCH($C35, hist_data!$A$6:$A$21, 0), R$13 ) )) -> 3.1718 | S35: =IF($E35="","",MAX(OFFSET(hist_data!$S$7,0,MATCH($C35,hist_data!$A$6:$A$21,0),S$13))) -> 3.273 | T35: =IF($E35="","",MIN(OFFSET(hist_data!$S$7,0,MATCH($C35,hist_data!$A$6:$A$21,0),T$13))) -> 3.023 | U35: =IF($E35="", "", AVERAGE( OFFSET( hist_data!$S$7, 0, MATCH($C35, hist_data!$A$6:$A$21, 0), U$13 ) )) -> 3.3332 | V35: =IF($E35="","",MAX(OFFSET(hist_data!$S$7,0,MATCH($C35,hist_data!$A$6:$A$21,0),V$13))) -> 3.641 | W35: =IF($E35="","",MIN(OFFSET(hist_data!$S$7,0,MATCH($C35,hist_data!$A$6:$A$21,0),W$13))) -> 3.023 | X35: =IF($E35="", "", AVERAGE( OFFSET( hist_data!$S$7, 0, MATCH($C35, hist_data!$A$6:$A$21, 0), X$13 ) )) -> 3.4700583 | Y35: =IF($E35="","",MAX(OFFSET(hist_data!$S$7,0,MATCH($C35,hist_data!$A$6:$A$21,0),Y$13))) -> 3.754 | Z35: =IF($E35="","",MIN(OFFSET(hist_data!$S$7,0,MATCH($C35,hist_data!$A$6:$A$21,0),Z$13))) -> 3.023 | AA35: =IF($E35="", "", AVERAGE( OFFSET( hist_data!$S$7, 0, MATCH($C35, hist_data!$A$6:$A$21, 0), AA$13 ) )) -> 3.753092 | AB35: =IF($E35="","",MAX(OFFSET(hist_data!$S$7,0,MATCH($C35,hist_data!$A$6:$A$21,0),AB$13))) -> 4.673 | AC35: =IF($E35="","",MIN(OFFSET(hist_data!$S$7,0,MATCH($C35,hist_data!$A$6:$A$21,0),AC$13))) -> 3.023
C36: SP(bp) | E36: =IFERROR( (E$16-E35)*100, "") -> -22.4 | F36: =IFERROR( (F$16-F35)*100, "") -> -22.7 | G36: =IFERROR( (G$16-G35)*100, "") -> -22.4 | H36: =IFERROR( (H$16-H35)*100, "") -> -20.9 | I36: =IFERROR( (I$16-I35)*100, "") -> -21.2 | J36: =IFERROR( (J$16-J35)*100, "") -> -21.2 | K36: =IFERROR( (K$16-K35)*100, "") -> -21.2 | L36: =IFERROR( (L$16-L35)*100, "") -> -20.7 | ... P36: =IFERROR( (P$16-P35)*100, "") -> -20 | R36: =IFERROR( (R$16-R35)*100, "") -> -20.175 | S36: =IFERROR( (S$16-S35)*100, "") -> -18.6 | T36: =IFERROR( (T$16-T35)*100, "") -> -20.8 | U36: =IFERROR( (U$16-U35)*100, "") -> -18.656667 | V36: =IFERROR( (V$16-V35)*100, "") -> -18.9 | W36: =IFERROR( (W$16-W35)*100, "") -> -20.8 | X36: =IFERROR( (X$16-X35)*100, "") -> -20.386667 | Y36: =IFERROR( (Y$16-Y35)*100, "") -> -21.4 | ... AC36: =IFERROR( (AC$16-AC35)*100, "") -> -20.8
A37: 11 | C37: {=INDEX(hist_data!$A$6:$A$21, Hist!$A37)} -> 07Y | E37: {=IF( INDEX(hist_data!$S$6:$AI$256, MATCH(E$13, hist_data!$S$6:$S$256, 0), MATCH($C37, hist_data!$A$6:$A$21, 0)+1)=0, "", INDEX(hist_data!$S$6:$AI$256, MATCH(E$13, hist_data!$S$6:$S$256, 0), MATCH($C37, hist_data!$A$6:$A$21, 0)+1) )} -> 3.143 | F37: {=IF( INDEX(hist_data!$S$6:$AI$256, MATCH(F$13, hist_data!$S$6:$S$256, 0), MATCH($C37, hist_data!$A$6:$A$21, 0)+1)=0, "", INDEX(hist_data!$S$6:$AI$256, MATCH(F$13, hist_data!$S$6:$S$256, 0), MATCH($C37, hist_data!$A$6:$A$21, 0)+1) )} -> 3.11 | G37: {=IF( INDEX(hist_data!$S$6:$AI$256, MATCH(G$13, hist_data!$S$6:$S$256, 0), MATCH($C37, hist_data!$A$6:$A$21, 0)+1)=0, "", INDEX(hist_data!$S$6:$AI$256, MATCH(G$13, hist_data!$S$6:$S$256, 0), MATCH($C37, hist_data!$A$6:$A$21, 0)+1) )} -> 3.137 | H37: {=IF( INDEX(hist_data!$S$6:$AI$256, MATCH(H$13, hist_data!$S$6:$S$256, 0), MATCH($C37, hist_data!$A$6:$A$21, 0)+1)=0, "", INDEX(hist_data!$S$6:$AI$256, MATCH(H$13, hist_data!$S$6:$S$256, 0), MATCH($C37, hist_data!$A$6:$A$21, 0)+1) )} -> 3.156 | I37: {=IF( INDEX(hist_data!$S$6:$AI$256, MATCH(I$13, hist_data!$S$6:$S$256, 0), MATCH($C37, hist_data!$A$6:$A$21, 0)+1)=0, "", INDEX(hist_data!$S$6:$AI$256, MATCH(I$13, hist_data!$S$6:$S$256, 0), MATCH($C37, hist_data!$A$6:$A$21, 0)+1) )} -> 3.157 | J37: {=IF( INDEX(hist_data!$S$6:$AI$256, MATCH(J$13, hist_data!$S$6:$S$256, 0), MATCH($C37, hist_data!$A$6:$A$21, 0)+1)=0, "", INDEX(hist_data!$S$6:$AI$256, MATCH(J$13, hist_data!$S$6:$S$256, 0), MATCH($C37, hist_data!$A$6:$A$21, 0)+1) )} -> 3.142 | K37: {=IF( INDEX(hist_data!$S$6:$AI$256, MATCH(K$13, hist_data!$S$6:$S$256, 0), MATCH($C37, hist_data!$A$6:$A$21, 0)+1)=0, "", INDEX(hist_data!$S$6:$AI$256, MATCH(K$13, hist_data!$S$6:$S$256, 0), MATCH($C37, hist_data!$A$6:$A$21, 0)+1) )} -> 3.151 | L37: {=IF( INDEX(hist_data!$S$6:$AI$256, MATCH(L$13, hist_data!$S$6:$S$256, 0), MATCH($C37, hist_data!$A$6:$A$21, 0)+1)=0, "", INDEX(hist_data!$S$6:$AI$256, MATCH(L$13, hist_data!$S$6:$S$256, 0), MATCH($C37, hist_data!$A$6:$A$21, 0)+1) )} -> 3.15 | ... P37: {=IF( INDEX(hist_data!$S$6:$AI$256, MATCH(P$13, hist_data!$S$6:$S$256, 0), MATCH($C37, hist_data!$A$6:$A$21, 0)+1)=0, "", INDEX(hist_data!$S$6:$AI$256, MATCH(P$13, hist_data!$S$6:$S$256, 0), MATCH($C37, hist_data!$A$6:$A$21, 0)+1) )} -> 3.191 | R37: =IF($E37="", "", AVERAGE( OFFSET( hist_data!$S$7, 0, MATCH($C37, hist_data!$A$6:$A$21, 0), R$13 ) )) -> 3.17435 | S37: =IF($E37="","",MAX(OFFSET(hist_data!$S$7,0,MATCH($C37,hist_data!$A$6:$A$21,0),S$13))) -> 3.285 | T37: =IF($E37="","",MIN(OFFSET(hist_data!$S$7,0,MATCH($C37,hist_data!$A$6:$A$21,0),T$13))) -> 3.034 | U37: =IF($E37="", "", AVERAGE( OFFSET( hist_data!$S$7, 0, MATCH($C37, hist_data!$A$6:$A$21, 0), U$13 ) )) -> 3.34265 | V37: =IF($E37="","",MAX(OFFSET(hist_data!$S$7,0,MATCH($C37,hist_data!$A$6:$A$21,0),V$13))) -> 3.654 | W37: =IF($E37="","",MIN(OFFSET(hist_data!$S$7,0,MATCH($C37,hist_data!$A$6:$A$21,0),W$13))) -> 3.034 | X37: =IF($E37="", "", AVERAGE( OFFSET( hist_data!$S$7, 0, MATCH($C37, hist_data!$A$6:$A$21, 0), X$13 ) )) -> 3.4918 | Y37: =IF($E37="","",MAX(OFFSET(hist_data!$S$7,0,MATCH($C37,hist_data!$A$6:$A$21,0),Y$13))) -> 3.791 | Z37: =IF($E37="","",MIN(OFFSET(hist_data!$S$7,0,MATCH($C37,hist_data!$A$6:$A$21,0),Z$13))) -> 3.034 | AA37: =IF($E37="", "", AVERAGE( OFFSET( hist_data!$S$7, 0, MATCH($C37, hist_data!$A$6:$A$21, 0), AA$13 ) )) -> 3.776788 | AB37: =IF($E37="","",MAX(OFFSET(hist_data!$S$7,0,MATCH($C37,hist_data!$A$6:$A$21,0),AB$13))) -> 4.692 | AC37: =IF($E37="","",MIN(OFFSET(hist_data!$S$7,0,MATCH($C37,hist_data!$A$6:$A$21,0),AC$13))) -> 3.034
C38: SP(bp) | E38: =IFERROR( (E$16-E37)*100, "") -> -22.1 | F38: =IFERROR( (F$16-F37)*100, "") -> -22.3 | G38: =IFERROR( (G$16-G37)*100, "") -> -22.2 | H38: =IFERROR( (H$16-H37)*100, "") -> -21.1 | I38: =IFERROR( (I$16-I37)*100, "") -> -21.7 | J38: =IFERROR( (J$16-J37)*100, "") -> -22.3 | K38: =IFERROR( (K$16-K37)*100, "") -> -22 | L38: =IFERROR( (L$16-L37)*100, "") -> -21 | ... P38: =IFERROR( (P$16-P37)*100, "") -> -19.1 | R38: =IFERROR( (R$16-R37)*100, "") -> -20.43 | S38: =IFERROR( (S$16-S37)*100, "") -> -19.8 | T38: =IFERROR( (T$16-T37)*100, "") -> -21.9 | U38: =IFERROR( (U$16-U37)*100, "") -> -19.601667 | V38: =IFERROR( (V$16-V37)*100, "") -> -20.2 | W38: =IFERROR( (W$16-W37)*100, "") -> -21.9 | X38: =IFERROR( (X$16-X37)*100, "") -> -22.560833 | Y38: =IFERROR( (Y$16-Y37)*100, "") -> -25.1 | ... AC38: =IFERROR( (AC$16-AC37)*100, "") -> -21.9
A39: 12 | C39: {=INDEX(hist_data!$A$6:$A$21, Hist!$A39)} -> 10Y | E39: {=IF( INDEX(hist_data!$S$6:$AI$256, MATCH(E$13, hist_data!$S$6:$S$256, 0), MATCH($C39, hist_data!$A$6:$A$21, 0)+1)=0, "", INDEX(hist_data!$S$6:$AI$256, MATCH(E$13, hist_data!$S$6:$S$256, 0), MATCH($C39, hist_data!$A$6:$A$21, 0)+1) )} -> 3.158 | F39: {=IF( INDEX(hist_data!$S$6:$AI$256, MATCH(F$13, hist_data!$S$6:$S$256, 0), MATCH($C39, hist_data!$A$6:$A$21, 0)+1)=0, "", INDEX(hist_data!$S$6:$AI$256, MATCH(F$13, hist_data!$S$6:$S$256, 0), MATCH($C39, hist_data!$A$6:$A$21, 0)+1) )} -> 3.124 | G39: {=IF( INDEX(hist_data!$S$6:$AI$256, MATCH(G$13, hist_data!$S$6:$S$256, 0), MATCH($C39, hist_data!$A$6:$A$21, 0)+1)=0, "", INDEX(hist_data!$S$6:$AI$256, MATCH(G$13, hist_data!$S$6:$S$256, 0), MATCH($C39, hist_data!$A$6:$A$21, 0)+1) )} -> 3.155 | H39: {=IF( INDEX(hist_data!$S$6:$AI$256, MATCH(H$13, hist_data!$S$6:$S$256, 0), MATCH($C39, hist_data!$A$6:$A$21, 0)+1)=0, "", INDEX(hist_data!$S$6:$AI$256, MATCH(H$13, hist_data!$S$6:$S$256, 0), MATCH($C39, hist_data!$A$6:$A$21, 0)+1) )} -> 3.182 | I39: {=IF( INDEX(hist_data!$S$6:$AI$256, MATCH(I$13, hist_data!$S$6:$S$256, 0), MATCH($C39, hist_data!$A$6:$A$21, 0)+1)=0, "", INDEX(hist_data!$S$6:$AI$256, MATCH(I$13, hist_data!$S$6:$S$256, 0), MATCH($C39, hist_data!$A$6:$A$21, 0)+1) )} -> 3.192 | J39: {=IF( INDEX(hist_data!$S$6:$AI$256, MATCH(J$13, hist_data!$S$6:$S$256, 0), MATCH($C39, hist_data!$A$6:$A$21, 0)+1)=0, "", INDEX(hist_data!$S$6:$AI$256, MATCH(J$13, hist_data!$S$6:$S$256, 0), MATCH($C39, hist_data!$A$6:$A$21, 0)+1) )} -> 3.18 | K39: {=IF( INDEX(hist_data!$S$6:$AI$256, MATCH(K$13, hist_data!$S$6:$S$256, 0), MATCH($C39, hist_data!$A$6:$A$21, 0)+1)=0, "", INDEX(hist_data!$S$6:$AI$256, MATCH(K$13, hist_data!$S$6:$S$256, 0), MATCH($C39, hist_data!$A$6:$A$21, 0)+1) )} -> 3.183 | L39: {=IF( INDEX(hist_data!$S$6:$AI$256, MATCH(L$13, hist_data!$S$6:$S$256, 0), MATCH($C39, hist_data!$A$6:$A$21, 0)+1)=0, "", INDEX(hist_data!$S$6:$AI$256, MATCH(L$13, hist_data!$S$6:$S$256, 0), MATCH($C39, hist_data!$A$6:$A$21, 0)+1) )} -> 3.174 | ... P39: {=IF( INDEX(hist_data!$S$6:$AI$256, MATCH(P$13, hist_data!$S$6:$S$256, 0), MATCH($C39, hist_data!$A$6:$A$21, 0)+1)=0, "", INDEX(hist_data!$S$6:$AI$256, MATCH(P$13, hist_data!$S$6:$S$256, 0), MATCH($C39, hist_data!$A$6:$A$21, 0)+1) )} -> 3.215 | R39: =IF($E39="", "", AVERAGE( OFFSET( hist_data!$S$7, 0, MATCH($C39, hist_data!$A$6:$A$21, 0), R$13 ) )) -> 3.20695 | S39: =IF($E39="","",MAX(OFFSET(hist_data!$S$7,0,MATCH($C39,hist_data!$A$6:$A$21,0),S$13))) -> 3.333 | T39: =IF($E39="","",MIN(OFFSET(hist_data!$S$7,0,MATCH($C39,hist_data!$A$6:$A$21,0),T$13))) -> 3.066 | U39: =IF($E39="", "", AVERAGE( OFFSET( hist_data!$S$7, 0, MATCH($C39, hist_data!$A$6:$A$21, 0), U$13 ) )) -> 3.3913667 | V39: =IF($E39="","",MAX(OFFSET(hist_data!$S$7,0,MATCH($C39,hist_data!$A$6:$A$21,0),V$13))) -> 3.722 | W39: =IF($E39="","",MIN(OFFSET(hist_data!$S$7,0,MATCH($C39,hist_data!$A$6:$A$21,0),W$13))) -> 3.066 | X39: =IF($E39="", "", AVERAGE( OFFSET( hist_data!$S$7, 0, MATCH($C39, hist_data!$A$6:$A$21, 0), X$13 ) )) -> 3.5394083 | Y39: =IF($E39="","",MAX(OFFSET(hist_data!$S$7,0,MATCH($C39,hist_data!$A$6:$A$21,0),Y$13))) -> 3.857 | Z39: =IF($E39="","",MIN(OFFSET(hist_data!$S$7,0,MATCH($C39,hist_data!$A$6:$A$21,0),Z$13))) -> 3.066 | AA39: =IF($E39="", "", AVERAGE( OFFSET( hist_data!$S$7, 0, MATCH($C39, hist_data!$A$6:$A$21, 0), AA$13 ) )) -> 3.811656 | AB39: =IF($E39="","",MAX(OFFSET(hist_data!$S$7,0,MATCH($C39,hist_data!$A$6:$A$21,0),AB$13))) -> 4.741 | AC39: =IF($E39="","",MIN(OFFSET(hist_data!$S$7,0,MATCH($C39,hist_data!$A$6:$A$21,0),AC$13))) -> 3.066
C40: SP(bp) | E40: =IFERROR( (E$16-E39)*100, "") -> -23.6 | F40: =IFERROR( (F$16-F39)*100, "") -> -23.7 | G40: =IFERROR( (G$16-G39)*100, "") -> -24 | H40: =IFERROR( (H$16-H39)*100, "") -> -23.7 | I40: =IFERROR( (I$16-I39)*100, "") -> -25.2 | J40: =IFERROR( (J$16-J39)*100, "") -> -26.1 | K40: =IFERROR( (K$16-K39)*100, "") -> -25.2 | L40: =IFERROR( (L$16-L39)*100, "") -> -23.4 | ... P40: =IFERROR( (P$16-P39)*100, "") -> -21.5 | R40: =IFERROR( (R$16-R39)*100, "") -> -23.69 | S40: =IFERROR( (S$16-S39)*100, "") -> -24.6 | T40: =IFERROR( (T$16-T39)*100, "") -> -25.1 | U40: =IFERROR( (U$16-U39)*100, "") -> -24.473333 | V40: =IFERROR( (V$16-V39)*100, "") -> -27 | W40: =IFERROR( (W$16-W39)*100, "") -> -25.1 | X40: =IFERROR( (X$16-X39)*100, "") -> -27.321667 | Y40: =IFERROR( (Y$16-Y39)*100, "") -> -31.7 | ... AC40: =IFERROR( (AC$16-AC39)*100, "") -> -25.1
