Workbook

Sheet Matrix
B2: 시가평가 평균 산출
D6: =TODAY() -> 45523
B7: 대분류 | C7: 중분류 | D7: 소분류 | E7: 3M | F7: 6M | G7: 9M | H7: 1Y | I7: 1.5Y | J7: 2Y | K7: 2.5Y | L7: 3Y | M7: 4Y | N7: 5Y | O7: 7Y | P7: 10Y | Q7: 15Y | R7: 20Y | S7: 30Y | T7: 50Y
B8: 국채 | C8: 국고채 | D8: 양곡,외평,재정 | E8: {=IFERROR( CHOOSE( data!$B$7, IF(_xll.IMDP("IR", data!$B9, data!M$8, $D$6)=0,"",_xll.IMDP("IR", data!$B9, data!M$8, $D$6)), IF(_xll.IMDP("IR", data!$C9, data!M$8, $D$6)=0,"",_xll.IMDP("IR", data!$C9, data!M$8, $D$6)), data!M9 ), "")} -> 3.338 | F8: {=IFERROR( CHOOSE( data!$B$7, IF(_xll.IMDP("IR", data!$B9, data!N$8, $D$6)=0,"",_xll.IMDP("IR", data!$B9, data!N$8, $D$6)), IF(_xll.IMDP("IR", data!$C9, data!N$8, $D$6)=0,"",_xll.IMDP("IR", data!$C9, data!N$8, $D$6)), data!N9 ), "")} -> 3.202 | G8: {=IFERROR( CHOOSE( data!$B$7, IF(_xll.IMDP("IR", data!$B9, data!O$8, $D$6)=0,"",_xll.IMDP("IR", data!$B9, data!O$8, $D$6)), IF(_xll.IMDP("IR", data!$C9, data!O$8, $D$6)=0,"",_xll.IMDP("IR", data!$C9, data!O$8, $D$6)), data!O9 ), "")} -> 3.114 | H8: {=IFERROR( CHOOSE( data!$B$7, IF(_xll.IMDP("IR", data!$B9, data!P$8, $D$6)=0,"",_xll.IMDP("IR", data!$B9, data!P$8, $D$6)), IF(_xll.IMDP("IR", data!$C9, data!P$8, $D$6)=0,"",_xll.IMDP("IR", data!$C9, data!P$8, $D$6)), data!P9 ), "")} -> 3.053 | I8: {=IFERROR( CHOOSE( data!$B$7, IF(_xll.IMDP("IR", data!$B9, data!Q$8, $D$6)=0,"",_xll.IMDP("IR", data!$B9, data!Q$8, $D$6)), IF(_xll.IMDP("IR", data!$C9, data!Q$8, $D$6)=0,"",_xll.IMDP("IR", data!$C9, data!Q$8, $D$6)), data!Q9 ), "")} -> 3.056 | J8: {=IFERROR( CHOOSE( data!$B$7, IF(_xll.IMDP("IR", data!$B9, data!R$8, $D$6)=0,"",_xll.IMDP("IR", data!$B9, data!R$8, $D$6)), IF(_xll.IMDP("IR", data!$C9, data!R$8, $D$6)=0,"",_xll.IMDP("IR", data!$C9, data!R$8, $D$6)), data!R9 ), "")} -> 3.03 | K8: {=IFERROR( CHOOSE( data!$B$7, IF(_xll.IMDP("IR", data!$B9, data!S$8, $D$6)=0,"",_xll.IMDP("IR", data!$B9, data!S$8, $D$6)), IF(_xll.IMDP("IR", data!$C9, data!S$8, $D$6)=0,"",_xll.IMDP("IR", data!$C9, data!S$8, $D$6)), data!S9 ), "")} -> 2.943 | L8: {=IFERROR( CHOOSE( data!$B$7, IF(_xll.IMDP("IR", data!$B9, data!T$8, $D$6)=0,"",_xll.IMDP("IR", data!$B9, data!T$8, $D$6)), IF(_xll.IMDP("IR", data!$C9, data!T$8, $D$6)=0,"",_xll.IMDP("IR", data!$C9, data!T$8, $D$6)), data!T9 ), "")} -> 2.922 | ... T8: {=IFERROR( CHOOSE( data!$B$7, IF(_xll.IMDP("IR", data!$B9, data!AB$8, $D$6)=0,"",_xll.IMDP("IR", data!$B9, data!AB$8, $D$6)), IF(_xll.IMDP("IR", data!$C9, data!AB$8, $D$6)=0,"",_xll.IMDP("IR", data!$C9, data!AB$8, $D$6)), data!AB9 ), "")} -> 2.762
C9: 국민주택1종 | D9: 복리채 | E9: {=IFERROR( CHOOSE( data!$B$7, IF(_xll.IMDP("IR", data!$B10, data!M$8, $D$6)=0,"",_xll.IMDP("IR", data!$B10, data!M$8, $D$6)), IF(_xll.IMDP("IR", data!$C10, data!M$8, $D$6)=0,"",_xll.IMDP("IR", data!$C10, data!M$8, $D$6)), data!M10 ), "")} -> 3.344 | F9: {=IFERROR( CHOOSE( data!$B$7, IF(_xll.IMDP("IR", data!$B10, data!N$8, $D$6)=0,"",_xll.IMDP("IR", data!$B10, data!N$8, $D$6)), IF(_xll.IMDP("IR", data!$C10, data!N$8, $D$6)=0,"",_xll.IMDP("IR", data!$C10, data!N$8, $D$6)), data!N10 ), "")} -> 3.25 | G9: {=IFERROR( CHOOSE( data!$B$7, IF(_xll.IMDP("IR", data!$B10, data!O$8, $D$6)=0,"",_xll.IMDP("IR", data!$B10, data!O$8, $D$6)), IF(_xll.IMDP("IR", data!$C10, data!O$8, $D$6)=0,"",_xll.IMDP("IR", data!$C10, data!O$8, $D$6)), data!O10 ), "")} -> 3.172 | H9: {=IFERROR( CHOOSE( data!$B$7, IF(_xll.IMDP("IR", data!$B10, data!P$8, $D$6)=0,"",_xll.IMDP("IR", data!$B10, data!P$8, $D$6)), IF(_xll.IMDP("IR", data!$C10, data!P$8, $D$6)=0,"",_xll.IMDP("IR", data!$C10, data!P$8, $D$6)), data!P10 ), "")} -> 3.089 | I9: {=IFERROR( CHOOSE( data!$B$7, IF(_xll.IMDP("IR", data!$B10, data!Q$8, $D$6)=0,"",_xll.IMDP("IR", data!$B10, data!Q$8, $D$6)), IF(_xll.IMDP("IR", data!$C10, data!Q$8, $D$6)=0,"",_xll.IMDP("IR", data!$C10, data!Q$8, $D$6)), data!Q10 ), "")} -> 3.074 | J9: {=IFERROR( CHOOSE( data!$B$7, IF(_xll.IMDP("IR", data!$B10, data!R$8, $D$6)=0,"",_xll.IMDP("IR", data!$B10, data!R$8, $D$6)), IF(_xll.IMDP("IR", data!$C10, data!R$8, $D$6)=0,"",_xll.IMDP("IR", data!$C10, data!R$8, $D$6)), data!R10 ), "")} -> 3.054 | K9: {=IFERROR( CHOOSE( data!$B$7, IF(_xll.IMDP("IR", data!$B10, data!S$8, $D$6)=0,"",_xll.IMDP("IR", data!$B10, data!S$8, $D$6)), IF(_xll.IMDP("IR", data!$C10, data!S$8, $D$6)=0,"",_xll.IMDP("IR", data!$C10, data!S$8, $D$6)), data!S10 ), "")} -> 3.011 | L9: {=IFERROR( CHOOSE( data!$B$7, IF(_xll.IMDP("IR", data!$B10, data!T$8, $D$6)=0,"",_xll.IMDP("IR", data!$B10, data!T$8, $D$6)), IF(_xll.IMDP("IR", data!$C10, data!T$8, $D$6)=0,"",_xll.IMDP("IR", data!$C10, data!T$8, $D$6)), data!T10 ), "")} -> 3.01 | ... T9: {=IFERROR( CHOOSE( data!$B$7, IF(_xll.IMDP("IR", data!$B10, data!AB$8, $D$6)=0,"",_xll.IMDP("IR", data!$B10, data!AB$8, $D$6)), IF(_xll.IMDP("IR", data!$C10, data!AB$8, $D$6)=0,"",_xll.IMDP("IR", data!$C10, data!AB$8, $D$6)), data!AB10 ), "")}
C10: 국민주택2종 | D10: 복리채 | E10: {=IFERROR( CHOOSE( data!$B$7, IF(_xll.IMDP("IR", data!$B11, data!M$8, $D$6)=0,"",_xll.IMDP("IR", data!$B11, data!M$8, $D$6)), IF(_xll.IMDP("IR", data!$C11, data!M$8, $D$6)=0,"",_xll.IMDP("IR", data!$C11, data!M$8, $D$6)), data!M11 ), "")} -> 3.128 | F10: {=IFERROR( CHOOSE( data!$B$7, IF(_xll.IMDP("IR", data!$B11, data!N$8, $D$6)=0,"",_xll.IMDP("IR", data!$B11, data!N$8, $D$6)), IF(_xll.IMDP("IR", data!$C11, data!N$8, $D$6)=0,"",_xll.IMDP("IR", data!$C11, data!N$8, $D$6)), data!N11 ), "")} -> 3.04 | G10: {=IFERROR( CHOOSE( data!$B$7, IF(_xll.IMDP("IR", data!$B11, data!O$8, $D$6)=0,"",_xll.IMDP("IR", data!$B11, data!O$8, $D$6)), IF(_xll.IMDP("IR", data!$C11, data!O$8, $D$6)=0,"",_xll.IMDP("IR", data!$C11, data!O$8, $D$6)), data!O11 ), "")} -> 2.973 | H10: {=IFERROR( CHOOSE( data!$B$7, IF(_xll.IMDP("IR", data!$B11, data!P$8, $D$6)=0,"",_xll.IMDP("IR", data!$B11, data!P$8, $D$6)), IF(_xll.IMDP("IR", data!$C11, data!P$8, $D$6)=0,"",_xll.IMDP("IR", data!$C11, data!P$8, $D$6)), data!P11 ), "")} -> 2.885 | I10: {=IFERROR( CHOOSE( data!$B$7, IF(_xll.IMDP("IR", data!$B11, data!Q$8, $D$6)=0,"",_xll.IMDP("IR", data!$B11, data!Q$8, $D$6)), IF(_xll.IMDP("IR", data!$C11, data!Q$8, $D$6)=0,"",_xll.IMDP("IR", data!$C11, data!Q$8, $D$6)), data!Q11 ), "")} -> 2.871 | J10: {=IFERROR( CHOOSE( data!$B$7, IF(_xll.IMDP("IR", data!$B11, data!R$8, $D$6)=0,"",_xll.IMDP("IR", data!$B11, data!R$8, $D$6)), IF(_xll.IMDP("IR", data!$C11, data!R$8, $D$6)=0,"",_xll.IMDP("IR", data!$C11, data!R$8, $D$6)), data!R11 ), "")} -> 2.851 | K10: {=IFERROR( CHOOSE( data!$B$7, IF(_xll.IMDP("IR", data!$B11, data!S$8, $D$6)=0,"",_xll.IMDP("IR", data!$B11, data!S$8, $D$6)), IF(_xll.IMDP("IR", data!$C11, data!S$8, $D$6)=0,"",_xll.IMDP("IR", data!$C11, data!S$8, $D$6)), data!S11 ), "")} -> 2.811 | L10: {=IFERROR( CHOOSE( data!$B$7, IF(_xll.IMDP("IR", data!$B11, data!T$8, $D$6)=0,"",_xll.IMDP("IR", data!$B11, data!T$8, $D$6)), IF(_xll.IMDP("IR", data!$C11, data!T$8, $D$6)=0,"",_xll.IMDP("IR", data!$C11, data!T$8, $D$6)), data!T11 ), "")} -> 2.818 | ... T10: {=IFERROR( CHOOSE( data!$B$7, IF(_xll.IMDP("IR", data!$B11, data!AB$8, $D$6)=0,"",_xll.IMDP("IR", data!$B11, data!AB$8, $D$6)), IF(_xll.IMDP("IR", data!$C11, data!AB$8, $D$6)=0,"",_xll.IMDP("IR", data!$C11, data!AB$8, $D$6)), data!AB11 ), "")}
C11: 국민주택3종 | D11: 복리채 | E11: {=IFERROR( CHOOSE( data!$B$7, IF(_xll.IMDP("IR", data!$B12, data!M$8, $D$6)=0,"",_xll.IMDP("IR", data!$B12, data!M$8, $D$6)), IF(_xll.IMDP("IR", data!$C12, data!M$8, $D$6)=0,"",_xll.IMDP("IR", data!$C12, data!M$8, $D$6)), data!M12 ), "")} -> 2.875 | F11: {=IFERROR( CHOOSE( data!$B$7, IF(_xll.IMDP("IR", data!$B12, data!N$8, $D$6)=0,"",_xll.IMDP("IR", data!$B12, data!N$8, $D$6)), IF(_xll.IMDP("IR", data!$C12, data!N$8, $D$6)=0,"",_xll.IMDP("IR", data!$C12, data!N$8, $D$6)), data!N12 ), "")} -> 2.785 | G11: {=IFERROR( CHOOSE( data!$B$7, IF(_xll.IMDP("IR", data!$B12, data!O$8, $D$6)=0,"",_xll.IMDP("IR", data!$B12, data!O$8, $D$6)), IF(_xll.IMDP("IR", data!$C12, data!O$8, $D$6)=0,"",_xll.IMDP("IR", data!$C12, data!O$8, $D$6)), data!O12 ), "")} -> 2.695 | H11: {=IFERROR( CHOOSE( data!$B$7, IF(_xll.IMDP("IR", data!$B12, data!P$8, $D$6)=0,"",_xll.IMDP("IR", data!$B12, data!P$8, $D$6)), IF(_xll.IMDP("IR", data!$C12, data!P$8, $D$6)=0,"",_xll.IMDP("IR", data!$C12, data!P$8, $D$6)), data!P12 ), "")} -> 2.597 | I11: {=IFERROR( CHOOSE( data!$B$7, IF(_xll.IMDP("IR", data!$B12, data!Q$8, $D$6)=0,"",_xll.IMDP("IR", data!$B12, data!Q$8, $D$6)), IF(_xll.IMDP("IR", data!$C12, data!Q$8, $D$6)=0,"",_xll.IMDP("IR", data!$C12, data!Q$8, $D$6)), data!Q12 ), "")} -> 2.607 | J11: {=IFERROR( CHOOSE( data!$B$7, IF(_xll.IMDP("IR", data!$B12, data!R$8, $D$6)=0,"",_xll.IMDP("IR", data!$B12, data!R$8, $D$6)), IF(_xll.IMDP("IR", data!$C12, data!R$8, $D$6)=0,"",_xll.IMDP("IR", data!$C12, data!R$8, $D$6)), data!R12 ), "")} -> 2.577 | K11: {=IFERROR( CHOOSE( data!$B$7, IF(_xll.IMDP("IR", data!$B12, data!S$8, $D$6)=0,"",_xll.IMDP("IR", data!$B12, data!S$8, $D$6)), IF(_xll.IMDP("IR", data!$C12, data!S$8, $D$6)=0,"",_xll.IMDP("IR", data!$C12, data!S$8, $D$6)), data!S12 ), "")} -> 2.517 | L11: {=IFERROR( CHOOSE( data!$B$7, IF(_xll.IMDP("IR", data!$B12, data!T$8, $D$6)=0,"",_xll.IMDP("IR", data!$B12, data!T$8, $D$6)), IF(_xll.IMDP("IR", data!$C12, data!T$8, $D$6)=0,"",_xll.IMDP("IR", data!$C12, data!T$8, $D$6)), data!T12 ), "")} -> 2.54 | ... T11: {=IFERROR( CHOOSE( data!$B$7, IF(_xll.IMDP("IR", data!$B12, data!AB$8, $D$6)=0,"",_xll.IMDP("IR", data!$B12, data!AB$8, $D$6)), IF(_xll.IMDP("IR", data!$C12, data!AB$8, $D$6)=0,"",_xll.IMDP("IR", data!$C12, data!AB$8, $D$6)), data!AB12 ), "")}
B12: 지방채 | C12: 서울도시철도 | D12: 분할거치 | E12: {=IFERROR( CHOOSE( data!$B$7, IF(_xll.IMDP("IR", data!$B13, data!M$8, $D$6)=0,"",_xll.IMDP("IR", data!$B13, data!M$8, $D$6)), IF(_xll.IMDP("IR", data!$C13, data!M$8, $D$6)=0,"",_xll.IMDP("IR", data!$C13, data!M$8, $D$6)), data!M13 ), "")} -> 3.41 | F12: {=IFERROR( CHOOSE( data!$B$7, IF(_xll.IMDP("IR", data!$B13, data!N$8, $D$6)=0,"",_xll.IMDP("IR", data!$B13, data!N$8, $D$6)), IF(_xll.IMDP("IR", data!$C13, data!N$8, $D$6)=0,"",_xll.IMDP("IR", data!$C13, data!N$8, $D$6)), data!N13 ), "")} -> 3.335 | G12: {=IFERROR( CHOOSE( data!$B$7, IF(_xll.IMDP("IR", data!$B13, data!O$8, $D$6)=0,"",_xll.IMDP("IR", data!$B13, data!O$8, $D$6)), IF(_xll.IMDP("IR", data!$C13, data!O$8, $D$6)=0,"",_xll.IMDP("IR", data!$C13, data!O$8, $D$6)), data!O13 ), "")} -> 3.255 | H12: {=IFERROR( CHOOSE( data!$B$7, IF(_xll.IMDP("IR", data!$B13, data!P$8, $D$6)=0,"",_xll.IMDP("IR", data!$B13, data!P$8, $D$6)), IF(_xll.IMDP("IR", data!$C13, data!P$8, $D$6)=0,"",_xll.IMDP("IR", data!$C13, data!P$8, $D$6)), data!P13 ), "")} -> 3.172 | I12: {=IFERROR( CHOOSE( data!$B$7, IF(_xll.IMDP("IR", data!$B13, data!Q$8, $D$6)=0,"",_xll.IMDP("IR", data!$B13, data!Q$8, $D$6)), IF(_xll.IMDP("IR", data!$C13, data!Q$8, $D$6)=0,"",_xll.IMDP("IR", data!$C13, data!Q$8, $D$6)), data!Q13 ), "")} -> 3.163 | J12: {=IFERROR( CHOOSE( data!$B$7, IF(_xll.IMDP("IR", data!$B13, data!R$8, $D$6)=0,"",_xll.IMDP("IR", data!$B13, data!R$8, $D$6)), IF(_xll.IMDP("IR", data!$C13, data!R$8, $D$6)=0,"",_xll.IMDP("IR", data!$C13, data!R$8, $D$6)), data!R13 ), "")} -> 3.147 | K12: {=IFERROR( CHOOSE( data!$B$7, IF(_xll.IMDP("IR", data!$B13, data!S$8, $D$6)=0,"",_xll.IMDP("IR", data!$B13, data!S$8, $D$6)), IF(_xll.IMDP("IR", data!$C13, data!S$8, $D$6)=0,"",_xll.IMDP("IR", data!$C13, data!S$8, $D$6)), data!S13 ), "")} -> 3.115 | L12: {=IFERROR( CHOOSE( data!$B$7, IF(_xll.IMDP("IR", data!$B13, data!T$8, $D$6)=0,"",_xll.IMDP("IR", data!$B13, data!T$8, $D$6)), IF(_xll.IMDP("IR", data!$C13, data!T$8, $D$6)=0,"",_xll.IMDP("IR", data!$C13, data!T$8, $D$6)), data!T13 ), "")} -> 3.127 | ... T12: {=IFERROR( CHOOSE( data!$B$7, IF(_xll.IMDP("IR", data!$B13, data!AB$8, $D$6)=0,"",_xll.IMDP("IR", data!$B13, data!AB$8, $D$6)), IF(_xll.IMDP("IR", data!$C13, data!AB$8, $D$6)=0,"",_xll.IMDP("IR", data!$C13, data!AB$8, $D$6)), data!AB13 ), "")}
C13: 지역개발채 | D13: 복리채 | E13: {=IFERROR( CHOOSE( data!$B$7, IF(_xll.IMDP("IR", data!$B14, data!M$8, $D$6)=0,"",_xll.IMDP("IR", data!$B14, data!M$8, $D$6)), IF(_xll.IMDP("IR", data!$C14, data!M$8, $D$6)=0,"",_xll.IMDP("IR", data!$C14, data!M$8, $D$6)), data!M14 ), "")} -> 3.41 | F13: {=IFERROR( CHOOSE( data!$B$7, IF(_xll.IMDP("IR", data!$B14, data!N$8, $D$6)=0,"",_xll.IMDP("IR", data!$B14, data!N$8, $D$6)), IF(_xll.IMDP("IR", data!$C14, data!N$8, $D$6)=0,"",_xll.IMDP("IR", data!$C14, data!N$8, $D$6)), data!N14 ), "")} -> 3.335 | G13: {=IFERROR( CHOOSE( data!$B$7, IF(_xll.IMDP("IR", data!$B14, data!O$8, $D$6)=0,"",_xll.IMDP("IR", data!$B14, data!O$8, $D$6)), IF(_xll.IMDP("IR", data!$C14, data!O$8, $D$6)=0,"",_xll.IMDP("IR", data!$C14, data!O$8, $D$6)), data!O14 ), "")} -> 3.255 | H13: {=IFERROR( CHOOSE( data!$B$7, IF(_xll.IMDP("IR", data!$B14, data!P$8, $D$6)=0,"",_xll.IMDP("IR", data!$B14, data!P$8, $D$6)), IF(_xll.IMDP("IR", data!$C14, data!P$8, $D$6)=0,"",_xll.IMDP("IR", data!$C14, data!P$8, $D$6)), data!P14 ), "")} -> 3.172 | I13: {=IFERROR( CHOOSE( data!$B$7, IF(_xll.IMDP("IR", data!$B14, data!Q$8, $D$6)=0,"",_xll.IMDP("IR", data!$B14, data!Q$8, $D$6)), IF(_xll.IMDP("IR", data!$C14, data!Q$8, $D$6)=0,"",_xll.IMDP("IR", data!$C14, data!Q$8, $D$6)), data!Q14 ), "")} -> 3.163 | J13: {=IFERROR( CHOOSE( data!$B$7, IF(_xll.IMDP("IR", data!$B14, data!R$8, $D$6)=0,"",_xll.IMDP("IR", data!$B14, data!R$8, $D$6)), IF(_xll.IMDP("IR", data!$C14, data!R$8, $D$6)=0,"",_xll.IMDP("IR", data!$C14, data!R$8, $D$6)), data!R14 ), "")} -> 3.148 | K13: {=IFERROR( CHOOSE( data!$B$7, IF(_xll.IMDP("IR", data!$B14, data!S$8, $D$6)=0,"",_xll.IMDP("IR", data!$B14, data!S$8, $D$6)), IF(_xll.IMDP("IR", data!$C14, data!S$8, $D$6)=0,"",_xll.IMDP("IR", data!$C14, data!S$8, $D$6)), data!S14 ), "")} -> 3.115 | L13: {=IFERROR( CHOOSE( data!$B$7, IF(_xll.IMDP("IR", data!$B14, data!T$8, $D$6)=0,"",_xll.IMDP("IR", data!$B14, data!T$8, $D$6)), IF(_xll.IMDP("IR", data!$C14, data!T$8, $D$6)=0,"",_xll.IMDP("IR", data!$C14, data!T$8, $D$6)), data!T14 ), "")} -> 3.127 | ... T13: {=IFERROR( CHOOSE( data!$B$7, IF(_xll.IMDP("IR", data!$B14, data!AB$8, $D$6)=0,"",_xll.IMDP("IR", data!$B14, data!AB$8, $D$6)), IF(_xll.IMDP("IR", data!$C14, data!AB$8, $D$6)=0,"",_xll.IMDP("IR", data!$C14, data!AB$8, $D$6)), data!AB14 ), "")}
B14: 공사 | C14: 공사/공단채 | D14: 정부보증 | E14: {=IFERROR( CHOOSE( data!$B$7, IF(_xll.IMDP("IR", data!$B15, data!M$8, $D$6)=0,"",_xll.IMDP("IR", data!$B15, data!M$8, $D$6)), IF(_xll.IMDP("IR", data!$C15, data!M$8, $D$6)=0,"",_xll.IMDP("IR", data!$C15, data!M$8, $D$6)), data!M15 ), "")} -> 3.387 | F14: {=IFERROR( CHOOSE( data!$B$7, IF(_xll.IMDP("IR", data!$B15, data!N$8, $D$6)=0,"",_xll.IMDP("IR", data!$B15, data!N$8, $D$6)), IF(_xll.IMDP("IR", data!$C15, data!N$8, $D$6)=0,"",_xll.IMDP("IR", data!$C15, data!N$8, $D$6)), data!N15 ), "")} -> 3.311 | G14: {=IFERROR( CHOOSE( data!$B$7, IF(_xll.IMDP("IR", data!$B15, data!O$8, $D$6)=0,"",_xll.IMDP("IR", data!$B15, data!O$8, $D$6)), IF(_xll.IMDP("IR", data!$C15, data!O$8, $D$6)=0,"",_xll.IMDP("IR", data!$C15, data!O$8, $D$6)), data!O15 ), "")} -> 3.233 | H14: {=IFERROR( CHOOSE( data!$B$7, IF(_xll.IMDP("IR", data!$B15, data!P$8, $D$6)=0,"",_xll.IMDP("IR", data!$B15, data!P$8, $D$6)), IF(_xll.IMDP("IR", data!$C15, data!P$8, $D$6)=0,"",_xll.IMDP("IR", data!$C15, data!P$8, $D$6)), data!P15 ), "")} -> 3.18 | I14: {=IFERROR( CHOOSE( data!$B$7, IF(_xll.IMDP("IR", data!$B15, data!Q$8, $D$6)=0,"",_xll.IMDP("IR", data!$B15, data!Q$8, $D$6)), IF(_xll.IMDP("IR", data!$C15, data!Q$8, $D$6)=0,"",_xll.IMDP("IR", data!$C15, data!Q$8, $D$6)), data!Q15 ), "")} -> 3.137 | J14: {=IFERROR( CHOOSE( data!$B$7, IF(_xll.IMDP("IR", data!$B15, data!R$8, $D$6)=0,"",_xll.IMDP("IR", data!$B15, data!R$8, $D$6)), IF(_xll.IMDP("IR", data!$C15, data!R$8, $D$6)=0,"",_xll.IMDP("IR", data!$C15, data!R$8, $D$6)), data!R15 ), "")} -> 3.12 | K14: {=IFERROR( CHOOSE( data!$B$7, IF(_xll.IMDP("IR", data!$B15, data!S$8, $D$6)=0,"",_xll.IMDP("IR", data!$B15, data!S$8, $D$6)), IF(_xll.IMDP("IR", data!$C15, data!S$8, $D$6)=0,"",_xll.IMDP("IR", data!$C15, data!S$8, $D$6)), data!S15 ), "")} -> 3.085 | L14: {=IFERROR( CHOOSE( data!$B$7, IF(_xll.IMDP("IR", data!$B15, data!T$8, $D$6)=0,"",_xll.IMDP("IR", data!$B15, data!T$8, $D$6)), IF(_xll.IMDP("IR", data!$C15, data!T$8, $D$6)=0,"",_xll.IMDP("IR", data!$C15, data!T$8, $D$6)), data!T15 ), "")} -> 3.074 | ... T14: {=IFERROR( CHOOSE( data!$B$7, IF(_xll.IMDP("IR", data!$B15, data!AB$8, $D$6)=0,"",_xll.IMDP("IR", data!$B15, data!AB$8, $D$6)), IF(_xll.IMDP("IR", data!$C15, data!AB$8, $D$6)=0,"",_xll.IMDP("IR", data!$C15, data!AB$8, $D$6)), data!AB15 ), "")}
B15: 공단채 | D15: AAA | E15: {=IFERROR( CHOOSE( data!$B$7, IF(_xll.IMDP("IR", data!$B16, data!M$8, $D$6)=0,"",_xll.IMDP("IR", data!$B16, data!M$8, $D$6)), IF(_xll.IMDP("IR", data!$C16, data!M$8, $D$6)=0,"",_xll.IMDP("IR", data!$C16, data!M$8, $D$6)), data!M16 ), "")} -> 3.392 | F15: {=IFERROR( CHOOSE( data!$B$7, IF(_xll.IMDP("IR", data!$B16, data!N$8, $D$6)=0,"",_xll.IMDP("IR", data!$B16, data!N$8, $D$6)), IF(_xll.IMDP("IR", data!$C16, data!N$8, $D$6)=0,"",_xll.IMDP("IR", data!$C16, data!N$8, $D$6)), data!N16 ), "")} -> 3.357 | G15: {=IFERROR( CHOOSE( data!$B$7, IF(_xll.IMDP("IR", data!$B16, data!O$8, $D$6)=0,"",_xll.IMDP("IR", data!$B16, data!O$8, $D$6)), IF(_xll.IMDP("IR", data!$C16, data!O$8, $D$6)=0,"",_xll.IMDP("IR", data!$C16, data!O$8, $D$6)), data!O16 ), "")} -> 3.299 | H15: {=IFERROR( CHOOSE( data!$B$7, IF(_xll.IMDP("IR", data!$B16, data!P$8, $D$6)=0,"",_xll.IMDP("IR", data!$B16, data!P$8, $D$6)), IF(_xll.IMDP("IR", data!$C16, data!P$8, $D$6)=0,"",_xll.IMDP("IR", data!$C16, data!P$8, $D$6)), data!P16 ), "")} -> 3.257 | I15: {=IFERROR( CHOOSE( data!$B$7, IF(_xll.IMDP("IR", data!$B16, data!Q$8, $D$6)=0,"",_xll.IMDP("IR", data!$B16, data!Q$8, $D$6)), IF(_xll.IMDP("IR", data!$C16, data!Q$8, $D$6)=0,"",_xll.IMDP("IR", data!$C16, data!Q$8, $D$6)), data!Q16 ), "")} -> 3.198 | J15: {=IFERROR( CHOOSE( data!$B$7, IF(_xll.IMDP("IR", data!$B16, data!R$8, $D$6)=0,"",_xll.IMDP("IR", data!$B16, data!R$8, $D$6)), IF(_xll.IMDP("IR", data!$C16, data!R$8, $D$6)=0,"",_xll.IMDP("IR", data!$C16, data!R$8, $D$6)), data!R16 ), "")} -> 3.184 | K15: {=IFERROR( CHOOSE( data!$B$7, IF(_xll.IMDP("IR", data!$B16, data!S$8, $D$6)=0,"",_xll.IMDP("IR", data!$B16, data!S$8, $D$6)), IF(_xll.IMDP("IR", data!$C16, data!S$8, $D$6)=0,"",_xll.IMDP("IR", data!$C16, data!S$8, $D$6)), data!S16 ), "")} -> 3.153 | L15: {=IFERROR( CHOOSE( data!$B$7, IF(_xll.IMDP("IR", data!$B16, data!T$8, $D$6)=0,"",_xll.IMDP("IR", data!$B16, data!T$8, $D$6)), IF(_xll.IMDP("IR", data!$C16, data!T$8, $D$6)=0,"",_xll.IMDP("IR", data!$C16, data!T$8, $D$6)), data!T16 ), "")} -> 3.153 | ... T15: {=IFERROR( CHOOSE( data!$B$7, IF(_xll.IMDP("IR", data!$B16, data!AB$8, $D$6)=0,"",_xll.IMDP("IR", data!$B16, data!AB$8, $D$6)), IF(_xll.IMDP("IR", data!$C16, data!AB$8, $D$6)=0,"",_xll.IMDP("IR", data!$C16, data!AB$8, $D$6)), data!AB16 ), "")}
D16: AA+ | E16: {=IFERROR( CHOOSE( data!$B$7, IF(_xll.IMDP("IR", data!$B17, data!M$8, $D$6)=0,"",_xll.IMDP("IR", data!$B17, data!M$8, $D$6)), IF(_xll.IMDP("IR", data!$C17, data!M$8, $D$6)=0,"",_xll.IMDP("IR", data!$C17, data!M$8, $D$6)), data!M17 ), "")} -> 3.417 | F16: {=IFERROR( CHOOSE( data!$B$7, IF(_xll.IMDP("IR", data!$B17, data!N$8, $D$6)=0,"",_xll.IMDP("IR", data!$B17, data!N$8, $D$6)), IF(_xll.IMDP("IR", data!$C17, data!N$8, $D$6)=0,"",_xll.IMDP("IR", data!$C17, data!N$8, $D$6)), data!N17 ), "")} -> 3.405 | G16: {=IFERROR( CHOOSE( data!$B$7, IF(_xll.IMDP("IR", data!$B17, data!O$8, $D$6)=0,"",_xll.IMDP("IR", data!$B17, data!O$8, $D$6)), IF(_xll.IMDP("IR", data!$C17, data!O$8, $D$6)=0,"",_xll.IMDP("IR", data!$C17, data!O$8, $D$6)), data!O17 ), "")} -> 3.356 | H16: {=IFERROR( CHOOSE( data!$B$7, IF(_xll.IMDP("IR", data!$B17, data!P$8, $D$6)=0,"",_xll.IMDP("IR", data!$B17, data!P$8, $D$6)), IF(_xll.IMDP("IR", data!$C17, data!P$8, $D$6)=0,"",_xll.IMDP("IR", data!$C17, data!P$8, $D$6)), data!P17 ), "")} -> 3.306 | I16: {=IFERROR( CHOOSE( data!$B$7, IF(_xll.IMDP("IR", data!$B17, data!Q$8, $D$6)=0,"",_xll.IMDP("IR", data!$B17, data!Q$8, $D$6)), IF(_xll.IMDP("IR", data!$C17, data!Q$8, $D$6)=0,"",_xll.IMDP("IR", data!$C17, data!Q$8, $D$6)), data!Q17 ), "")} -> 3.284 | J16: {=IFERROR( CHOOSE( data!$B$7, IF(_xll.IMDP("IR", data!$B17, data!R$8, $D$6)=0,"",_xll.IMDP("IR", data!$B17, data!R$8, $D$6)), IF(_xll.IMDP("IR", data!$C17, data!R$8, $D$6)=0,"",_xll.IMDP("IR", data!$C17, data!R$8, $D$6)), data!R17 ), "")} -> 3.284 | K16: {=IFERROR( CHOOSE( data!$B$7, IF(_xll.IMDP("IR", data!$B17, data!S$8, $D$6)=0,"",_xll.IMDP("IR", data!$B17, data!S$8, $D$6)), IF(_xll.IMDP("IR", data!$C17, data!S$8, $D$6)=0,"",_xll.IMDP("IR", data!$C17, data!S$8, $D$6)), data!S17 ), "")} -> 3.252 | L16: {=IFERROR( CHOOSE( data!$B$7, IF(_xll.IMDP("IR", data!$B17, data!T$8, $D$6)=0,"",_xll.IMDP("IR", data!$B17, data!T$8, $D$6)), IF(_xll.IMDP("IR", data!$C17, data!T$8, $D$6)=0,"",_xll.IMDP("IR", data!$C17, data!T$8, $D$6)), data!T17 ), "")} -> 3.249 | ... T16: {=IFERROR( CHOOSE( data!$B$7, IF(_xll.IMDP("IR", data!$B17, data!AB$8, $D$6)=0,"",_xll.IMDP("IR", data!$B17, data!AB$8, $D$6)), IF(_xll.IMDP("IR", data!$C17, data!AB$8, $D$6)=0,"",_xll.IMDP("IR", data!$C17, data!AB$8, $D$6)), data!AB17 ), "")}
D17: AA0 | E17: {=IFERROR( CHOOSE( data!$B$7, IF(_xll.IMDP("IR", data!$B18, data!M$8, $D$6)=0,"",_xll.IMDP("IR", data!$B18, data!M$8, $D$6)), IF(_xll.IMDP("IR", data!$C18, data!M$8, $D$6)=0,"",_xll.IMDP("IR", data!$C18, data!M$8, $D$6)), data!M18 ), "")} -> 3.471 | F17: {=IFERROR( CHOOSE( data!$B$7, IF(_xll.IMDP("IR", data!$B18, data!N$8, $D$6)=0,"",_xll.IMDP("IR", data!$B18, data!N$8, $D$6)), IF(_xll.IMDP("IR", data!$C18, data!N$8, $D$6)=0,"",_xll.IMDP("IR", data!$C18, data!N$8, $D$6)), data!N18 ), "")} -> 3.478 | G17: {=IFERROR( CHOOSE( data!$B$7, IF(_xll.IMDP("IR", data!$B18, data!O$8, $D$6)=0,"",_xll.IMDP("IR", data!$B18, data!O$8, $D$6)), IF(_xll.IMDP("IR", data!$C18, data!O$8, $D$6)=0,"",_xll.IMDP("IR", data!$C18, data!O$8, $D$6)), data!O18 ), "")} -> 3.442 | H17: {=IFERROR( CHOOSE( data!$B$7, IF(_xll.IMDP("IR", data!$B18, data!P$8, $D$6)=0,"",_xll.IMDP("IR", data!$B18, data!P$8, $D$6)), IF(_xll.IMDP("IR", data!$C18, data!P$8, $D$6)=0,"",_xll.IMDP("IR", data!$C18, data!P$8, $D$6)), data!P18 ), "")} -> 3.41 | I17: {=IFERROR( CHOOSE( data!$B$7, IF(_xll.IMDP("IR", data!$B18, data!Q$8, $D$6)=0,"",_xll.IMDP("IR", data!$B18, data!Q$8, $D$6)), IF(_xll.IMDP("IR", data!$C18, data!Q$8, $D$6)=0,"",_xll.IMDP("IR", data!$C18, data!Q$8, $D$6)), data!Q18 ), "")} -> 3.409 | J17: {=IFERROR( CHOOSE( data!$B$7, IF(_xll.IMDP("IR", data!$B18, data!R$8, $D$6)=0,"",_xll.IMDP("IR", data!$B18, data!R$8, $D$6)), IF(_xll.IMDP("IR", data!$C18, data!R$8, $D$6)=0,"",_xll.IMDP("IR", data!$C18, data!R$8, $D$6)), data!R18 ), "")} -> 3.413 | K17: {=IFERROR( CHOOSE( data!$B$7, IF(_xll.IMDP("IR", data!$B18, data!S$8, $D$6)=0,"",_xll.IMDP("IR", data!$B18, data!S$8, $D$6)), IF(_xll.IMDP("IR", data!$C18, data!S$8, $D$6)=0,"",_xll.IMDP("IR", data!$C18, data!S$8, $D$6)), data!S18 ), "")} -> 3.389 | L17: {=IFERROR( CHOOSE( data!$B$7, IF(_xll.IMDP("IR", data!$B18, data!T$8, $D$6)=0,"",_xll.IMDP("IR", data!$B18, data!T$8, $D$6)), IF(_xll.IMDP("IR", data!$C18, data!T$8, $D$6)=0,"",_xll.IMDP("IR", data!$C18, data!T$8, $D$6)), data!T18 ), "")} -> 3.398 | ... T17: {=IFERROR( CHOOSE( data!$B$7, IF(_xll.IMDP("IR", data!$B18, data!AB$8, $D$6)=0,"",_xll.IMDP("IR", data!$B18, data!AB$8, $D$6)), IF(_xll.IMDP("IR", data!$C18, data!AB$8, $D$6)=0,"",_xll.IMDP("IR", data!$C18, data!AB$8, $D$6)), data!AB18 ), "")}
D18: AA- | E18: {=IFERROR( CHOOSE( data!$B$7, IF(_xll.IMDP("IR", data!$B19, data!M$8, $D$6)=0,"",_xll.IMDP("IR", data!$B19, data!M$8, $D$6)), IF(_xll.IMDP("IR", data!$C19, data!M$8, $D$6)=0,"",_xll.IMDP("IR", data!$C19, data!M$8, $D$6)), data!M19 ), "")} -> 3.587 | F18: {=IFERROR( CHOOSE( data!$B$7, IF(_xll.IMDP("IR", data!$B19, data!N$8, $D$6)=0,"",_xll.IMDP("IR", data!$B19, data!N$8, $D$6)), IF(_xll.IMDP("IR", data!$C19, data!N$8, $D$6)=0,"",_xll.IMDP("IR", data!$C19, data!N$8, $D$6)), data!N19 ), "")} -> 3.6 | G18: {=IFERROR( CHOOSE( data!$B$7, IF(_xll.IMDP("IR", data!$B19, data!O$8, $D$6)=0,"",_xll.IMDP("IR", data!$B19, data!O$8, $D$6)), IF(_xll.IMDP("IR", data!$C19, data!O$8, $D$6)=0,"",_xll.IMDP("IR", data!$C19, data!O$8, $D$6)), data!O19 ), "")} -> 3.576 | H18: {=IFERROR( CHOOSE( data!$B$7, IF(_xll.IMDP("IR", data!$B19, data!P$8, $D$6)=0,"",_xll.IMDP("IR", data!$B19, data!P$8, $D$6)), IF(_xll.IMDP("IR", data!$C19, data!P$8, $D$6)=0,"",_xll.IMDP("IR", data!$C19, data!P$8, $D$6)), data!P19 ), "")} -> 3.569 | I18: {=IFERROR( CHOOSE( data!$B$7, IF(_xll.IMDP("IR", data!$B19, data!Q$8, $D$6)=0,"",_xll.IMDP("IR", data!$B19, data!Q$8, $D$6)), IF(_xll.IMDP("IR", data!$C19, data!Q$8, $D$6)=0,"",_xll.IMDP("IR", data!$C19, data!Q$8, $D$6)), data!Q19 ), "")} -> 3.549 | J18: {=IFERROR( CHOOSE( data!$B$7, IF(_xll.IMDP("IR", data!$B19, data!R$8, $D$6)=0,"",_xll.IMDP("IR", data!$B19, data!R$8, $D$6)), IF(_xll.IMDP("IR", data!$C19, data!R$8, $D$6)=0,"",_xll.IMDP("IR", data!$C19, data!R$8, $D$6)), data!R19 ), "")} -> 3.555 | K18: {=IFERROR( CHOOSE( data!$B$7, IF(_xll.IMDP("IR", data!$B19, data!S$8, $D$6)=0,"",_xll.IMDP("IR", data!$B19, data!S$8, $D$6)), IF(_xll.IMDP("IR", data!$C19, data!S$8, $D$6)=0,"",_xll.IMDP("IR", data!$C19, data!S$8, $D$6)), data!S19 ), "")} -> 3.529 | L18: {=IFERROR( CHOOSE( data!$B$7, IF(_xll.IMDP("IR", data!$B19, data!T$8, $D$6)=0,"",_xll.IMDP("IR", data!$B19, data!T$8, $D$6)), IF(_xll.IMDP("IR", data!$C19, data!T$8, $D$6)=0,"",_xll.IMDP("IR", data!$C19, data!T$8, $D$6)), data!T19 ), "")} -> 3.536 | ... T18: {=IFERROR( CHOOSE( data!$B$7, IF(_xll.IMDP("IR", data!$B19, data!AB$8, $D$6)=0,"",_xll.IMDP("IR", data!$B19, data!AB$8, $D$6)), IF(_xll.IMDP("IR", data!$C19, data!AB$8, $D$6)=0,"",_xll.IMDP("IR", data!$C19, data!AB$8, $D$6)), data!AB19 ), "")}
B19: 통안증권 | C19: 통안증권 | D19: 이표채 | E19: {=IFERROR( CHOOSE( data!$B$7, IF(_xll.IMDP("IR", data!$B20, data!M$8, $D$6)=0,"",_xll.IMDP("IR", data!$B20, data!M$8, $D$6)), IF(_xll.IMDP("IR", data!$C20, data!M$8, $D$6)=0,"",_xll.IMDP("IR", data!$C20, data!M$8, $D$6)), data!M20 ), "")} -> 3.271 | F19: {=IFERROR( CHOOSE( data!$B$7, IF(_xll.IMDP("IR", data!$B20, data!N$8, $D$6)=0,"",_xll.IMDP("IR", data!$B20, data!N$8, $D$6)), IF(_xll.IMDP("IR", data!$C20, data!N$8, $D$6)=0,"",_xll.IMDP("IR", data!$C20, data!N$8, $D$6)), data!N20 ), "")} -> 3.166 | G19: {=IFERROR( CHOOSE( data!$B$7, IF(_xll.IMDP("IR", data!$B20, data!O$8, $D$6)=0,"",_xll.IMDP("IR", data!$B20, data!O$8, $D$6)), IF(_xll.IMDP("IR", data!$C20, data!O$8, $D$6)=0,"",_xll.IMDP("IR", data!$C20, data!O$8, $D$6)), data!O20 ), "")} -> 3.1 | H19: {=IFERROR( CHOOSE( data!$B$7, IF(_xll.IMDP("IR", data!$B20, data!P$8, $D$6)=0,"",_xll.IMDP("IR", data!$B20, data!P$8, $D$6)), IF(_xll.IMDP("IR", data!$C20, data!P$8, $D$6)=0,"",_xll.IMDP("IR", data!$C20, data!P$8, $D$6)), data!P20 ), "")} -> 3.026 | I19: {=IFERROR( CHOOSE( data!$B$7, IF(_xll.IMDP("IR", data!$B20, data!Q$8, $D$6)=0,"",_xll.IMDP("IR", data!$B20, data!Q$8, $D$6)), IF(_xll.IMDP("IR", data!$C20, data!Q$8, $D$6)=0,"",_xll.IMDP("IR", data!$C20, data!Q$8, $D$6)), data!Q20 ), "")} -> 3.042 | J19: {=IFERROR( CHOOSE( data!$B$7, IF(_xll.IMDP("IR", data!$B20, data!R$8, $D$6)=0,"",_xll.IMDP("IR", data!$B20, data!R$8, $D$6)), IF(_xll.IMDP("IR", data!$C20, data!R$8, $D$6)=0,"",_xll.IMDP("IR", data!$C20, data!R$8, $D$6)), data!R20 ), "")} -> 2.987 | K19: {=IFERROR( CHOOSE( data!$B$7, IF(_xll.IMDP("IR", data!$B20, data!S$8, $D$6)=0,"",_xll.IMDP("IR", data!$B20, data!S$8, $D$6)), IF(_xll.IMDP("IR", data!$C20, data!S$8, $D$6)=0,"",_xll.IMDP("IR", data!$C20, data!S$8, $D$6)), data!S20 ), "")} -> 2.993 | L19: {=IFERROR( CHOOSE( data!$B$7, IF(_xll.IMDP("IR", data!$B20, data!T$8, $D$6)=0,"",_xll.IMDP("IR", data!$B20, data!T$8, $D$6)), IF(_xll.IMDP("IR", data!$C20, data!T$8, $D$6)=0,"",_xll.IMDP("IR", data!$C20, data!T$8, $D$6)), data!T20 ), "")} -> 2.994 | ... T19: {=IFERROR( CHOOSE( data!$B$7, IF(_xll.IMDP("IR", data!$B20, data!AB$8, $D$6)=0,"",_xll.IMDP("IR", data!$B20, data!AB$8, $D$6)), IF(_xll.IMDP("IR", data!$C20, data!AB$8, $D$6)=0,"",_xll.IMDP("IR", data!$C20, data!AB$8, $D$6)), data!AB20 ), "")}
D20: 할인채 | E20: {=IFERROR( CHOOSE( data!$B$7, IF(_xll.IMDP("IR", data!$B21, data!M$8, $D$6)=0,"",_xll.IMDP("IR", data!$B21, data!M$8, $D$6)), IF(_xll.IMDP("IR", data!$C21, data!M$8, $D$6)=0,"",_xll.IMDP("IR", data!$C21, data!M$8, $D$6)), data!M21 ), "")} -> 3.287 | F20: {=IFERROR( CHOOSE( data!$B$7, IF(_xll.IMDP("IR", data!$B21, data!N$8, $D$6)=0,"",_xll.IMDP("IR", data!$B21, data!N$8, $D$6)), IF(_xll.IMDP("IR", data!$C21, data!N$8, $D$6)=0,"",_xll.IMDP("IR", data!$C21, data!N$8, $D$6)), data!N21 ), "")} -> 3.183 | G20: {=IFERROR( CHOOSE( data!$B$7, IF(_xll.IMDP("IR", data!$B21, data!O$8, $D$6)=0,"",_xll.IMDP("IR", data!$B21, data!O$8, $D$6)), IF(_xll.IMDP("IR", data!$C21, data!O$8, $D$6)=0,"",_xll.IMDP("IR", data!$C21, data!O$8, $D$6)), data!O21 ), "")} -> 3.111 | H20: {=IFERROR( CHOOSE( data!$B$7, IF(_xll.IMDP("IR", data!$B21, data!P$8, $D$6)=0,"",_xll.IMDP("IR", data!$B21, data!P$8, $D$6)), IF(_xll.IMDP("IR", data!$C21, data!P$8, $D$6)=0,"",_xll.IMDP("IR", data!$C21, data!P$8, $D$6)), data!P21 ), "")} -> 3.022 | I20: {=IFERROR( CHOOSE( data!$B$7, IF(_xll.IMDP("IR", data!$B21, data!Q$8, $D$6)=0,"",_xll.IMDP("IR", data!$B21, data!Q$8, $D$6)), IF(_xll.IMDP("IR", data!$C21, data!Q$8, $D$6)=0,"",_xll.IMDP("IR", data!$C21, data!Q$8, $D$6)), data!Q21 ), "")} -> 3.048 | J20: {=IFERROR( CHOOSE( data!$B$7, IF(_xll.IMDP("IR", data!$B21, data!R$8, $D$6)=0,"",_xll.IMDP("IR", data!$B21, data!R$8, $D$6)), IF(_xll.IMDP("IR", data!$C21, data!R$8, $D$6)=0,"",_xll.IMDP("IR", data!$C21, data!R$8, $D$6)), data!R21 ), "")} -> 2.994 | K20: {=IFERROR( CHOOSE( data!$B$7, IF(_xll.IMDP("IR", data!$B21, data!S$8, $D$6)=0,"",_xll.IMDP("IR", data!$B21, data!S$8, $D$6)), IF(_xll.IMDP("IR", data!$C21, data!S$8, $D$6)=0,"",_xll.IMDP("IR", data!$C21, data!S$8, $D$6)), data!S21 ), "")} -> 3.002 | L20: {=IFERROR( CHOOSE( data!$B$7, IF(_xll.IMDP("IR", data!$B21, data!T$8, $D$6)=0,"",_xll.IMDP("IR", data!$B21, data!T$8, $D$6)), IF(_xll.IMDP("IR", data!$C21, data!T$8, $D$6)=0,"",_xll.IMDP("IR", data!$C21, data!T$8, $D$6)), data!T21 ), "")} -> 3.003 | ... T20: {=IFERROR( CHOOSE( data!$B$7, IF(_xll.IMDP("IR", data!$B21, data!AB$8, $D$6)=0,"",_xll.IMDP("IR", data!$B21, data!AB$8, $D$6)), IF(_xll.IMDP("IR", data!$C21, data!AB$8, $D$6)=0,"",_xll.IMDP("IR", data!$C21, data!AB$8, $D$6)), data!AB21 ), "")}
B21: 커버드본드 | C21: 커버드본드 | D21: AAA | E21: {=IFERROR( CHOOSE( data!$B$7, IF(_xll.IMDP("IR", data!$B22, data!M$8, $D$6)=0,"",_xll.IMDP("IR", data!$B22, data!M$8, $D$6)), IF(_xll.IMDP("IR", data!$C22, data!M$8, $D$6)=0,"",_xll.IMDP("IR", data!$C22, data!M$8, $D$6)), data!M22 ), "")} -> 3.423 | F21: {=IFERROR( CHOOSE( data!$B$7, IF(_xll.IMDP("IR", data!$B22, data!N$8, $D$6)=0,"",_xll.IMDP("IR", data!$B22, data!N$8, $D$6)), IF(_xll.IMDP("IR", data!$C22, data!N$8, $D$6)=0,"",_xll.IMDP("IR", data!$C22, data!N$8, $D$6)), data!N22 ), "")} -> 3.4 | G21: {=IFERROR( CHOOSE( data!$B$7, IF(_xll.IMDP("IR", data!$B22, data!O$8, $D$6)=0,"",_xll.IMDP("IR", data!$B22, data!O$8, $D$6)), IF(_xll.IMDP("IR", data!$C22, data!O$8, $D$6)=0,"",_xll.IMDP("IR", data!$C22, data!O$8, $D$6)), data!O22 ), "")} -> 3.33 | H21: {=IFERROR( CHOOSE( data!$B$7, IF(_xll.IMDP("IR", data!$B22, data!P$8, $D$6)=0,"",_xll.IMDP("IR", data!$B22, data!P$8, $D$6)), IF(_xll.IMDP("IR", data!$C22, data!P$8, $D$6)=0,"",_xll.IMDP("IR", data!$C22, data!P$8, $D$6)), data!P22 ), "")} -> 3.288 | I21: {=IFERROR( CHOOSE( data!$B$7, IF(_xll.IMDP("IR", data!$B22, data!Q$8, $D$6)=0,"",_xll.IMDP("IR", data!$B22, data!Q$8, $D$6)), IF(_xll.IMDP("IR", data!$C22, data!Q$8, $D$6)=0,"",_xll.IMDP("IR", data!$C22, data!Q$8, $D$6)), data!Q22 ), "")} -> 3.244 | J21: {=IFERROR( CHOOSE( data!$B$7, IF(_xll.IMDP("IR", data!$B22, data!R$8, $D$6)=0,"",_xll.IMDP("IR", data!$B22, data!R$8, $D$6)), IF(_xll.IMDP("IR", data!$C22, data!R$8, $D$6)=0,"",_xll.IMDP("IR", data!$C22, data!R$8, $D$6)), data!R22 ), "")} -> 3.207 | K21: {=IFERROR( CHOOSE( data!$B$7, IF(_xll.IMDP("IR", data!$B22, data!S$8, $D$6)=0,"",_xll.IMDP("IR", data!$B22, data!S$8, $D$6)), IF(_xll.IMDP("IR", data!$C22, data!S$8, $D$6)=0,"",_xll.IMDP("IR", data!$C22, data!S$8, $D$6)), data!S22 ), "")} -> 3.182 | L21: {=IFERROR( CHOOSE( data!$B$7, IF(_xll.IMDP("IR", data!$B22, data!T$8, $D$6)=0,"",_xll.IMDP("IR", data!$B22, data!T$8, $D$6)), IF(_xll.IMDP("IR", data!$C22, data!T$8, $D$6)=0,"",_xll.IMDP("IR", data!$C22, data!T$8, $D$6)), data!T22 ), "")} -> 3.166 | ... T21: {=IFERROR( CHOOSE( data!$B$7, IF(_xll.IMDP("IR", data!$B22, data!AB$8, $D$6)=0,"",_xll.IMDP("IR", data!$B22, data!AB$8, $D$6)), IF(_xll.IMDP("IR", data!$C22, data!AB$8, $D$6)=0,"",_xll.IMDP("IR", data!$C22, data!AB$8, $D$6)), data!AB22 ), "")}
B22: 금융채 | C22: 은행채 | D22: AAA(산금-이표) | E22: {=IFERROR( CHOOSE( data!$B$7, IF(_xll.IMDP("IR", data!$B23, data!M$8, $D$6)=0,"",_xll.IMDP("IR", data!$B23, data!M$8, $D$6)), IF(_xll.IMDP("IR", data!$C23, data!M$8, $D$6)=0,"",_xll.IMDP("IR", data!$C23, data!M$8, $D$6)), data!M23 ), "")} -> 3.416 | F22: {=IFERROR( CHOOSE( data!$B$7, IF(_xll.IMDP("IR", data!$B23, data!N$8, $D$6)=0,"",_xll.IMDP("IR", data!$B23, data!N$8, $D$6)), IF(_xll.IMDP("IR", data!$C23, data!N$8, $D$6)=0,"",_xll.IMDP("IR", data!$C23, data!N$8, $D$6)), data!N23 ), "")} -> 3.389 | G22: {=IFERROR( CHOOSE( data!$B$7, IF(_xll.IMDP("IR", data!$B23, data!O$8, $D$6)=0,"",_xll.IMDP("IR", data!$B23, data!O$8, $D$6)), IF(_xll.IMDP("IR", data!$C23, data!O$8, $D$6)=0,"",_xll.IMDP("IR", data!$C23, data!O$8, $D$6)), data!O23 ), "")} -> 3.32 | H22: {=IFERROR( CHOOSE( data!$B$7, IF(_xll.IMDP("IR", data!$B23, data!P$8, $D$6)=0,"",_xll.IMDP("IR", data!$B23, data!P$8, $D$6)), IF(_xll.IMDP("IR", data!$C23, data!P$8, $D$6)=0,"",_xll.IMDP("IR", data!$C23, data!P$8, $D$6)), data!P23 ), "")} -> 3.28 | I22: {=IFERROR( CHOOSE( data!$B$7, IF(_xll.IMDP("IR", data!$B23, data!Q$8, $D$6)=0,"",_xll.IMDP("IR", data!$B23, data!Q$8, $D$6)), IF(_xll.IMDP("IR", data!$C23, data!Q$8, $D$6)=0,"",_xll.IMDP("IR", data!$C23, data!Q$8, $D$6)), data!Q23 ), "")} -> 3.232 | J22: {=IFERROR( CHOOSE( data!$B$7, IF(_xll.IMDP("IR", data!$B23, data!R$8, $D$6)=0,"",_xll.IMDP("IR", data!$B23, data!R$8, $D$6)), IF(_xll.IMDP("IR", data!$C23, data!R$8, $D$6)=0,"",_xll.IMDP("IR", data!$C23, data!R$8, $D$6)), data!R23 ), "")} -> 3.181 | K22: {=IFERROR( CHOOSE( data!$B$7, IF(_xll.IMDP("IR", data!$B23, data!S$8, $D$6)=0,"",_xll.IMDP("IR", data!$B23, data!S$8, $D$6)), IF(_xll.IMDP("IR", data!$C23, data!S$8, $D$6)=0,"",_xll.IMDP("IR", data!$C23, data!S$8, $D$6)), data!S23 ), "")} -> 3.126 | L22: {=IFERROR( CHOOSE( data!$B$7, IF(_xll.IMDP("IR", data!$B23, data!T$8, $D$6)=0,"",_xll.IMDP("IR", data!$B23, data!T$8, $D$6)), IF(_xll.IMDP("IR", data!$C23, data!T$8, $D$6)=0,"",_xll.IMDP("IR", data!$C23, data!T$8, $D$6)), data!T23 ), "")} -> 3.093 | ... T22: {=IFERROR( CHOOSE( data!$B$7, IF(_xll.IMDP("IR", data!$B23, data!AB$8, $D$6)=0,"",_xll.IMDP("IR", data!$B23, data!AB$8, $D$6)), IF(_xll.IMDP("IR", data!$C23, data!AB$8, $D$6)=0,"",_xll.IMDP("IR", data!$C23, data!AB$8, $D$6)), data!AB23 ), "")}
D23: AAA(산금-할인) | E23: {=IFERROR( CHOOSE( data!$B$7, IF(_xll.IMDP("IR", data!$B24, data!M$8, $D$6)=0,"",_xll.IMDP("IR", data!$B24, data!M$8, $D$6)), IF(_xll.IMDP("IR", data!$C24, data!M$8, $D$6)=0,"",_xll.IMDP("IR", data!$C24, data!M$8, $D$6)), data!M24 ), "")} -> 3.411 | F23: {=IFERROR( CHOOSE( data!$B$7, IF(_xll.IMDP("IR", data!$B24, data!N$8, $D$6)=0,"",_xll.IMDP("IR", data!$B24, data!N$8, $D$6)), IF(_xll.IMDP("IR", data!$C24, data!N$8, $D$6)=0,"",_xll.IMDP("IR", data!$C24, data!N$8, $D$6)), data!N24 ), "")} -> 3.394 | G23: {=IFERROR( CHOOSE( data!$B$7, IF(_xll.IMDP("IR", data!$B24, data!O$8, $D$6)=0,"",_xll.IMDP("IR", data!$B24, data!O$8, $D$6)), IF(_xll.IMDP("IR", data!$C24, data!O$8, $D$6)=0,"",_xll.IMDP("IR", data!$C24, data!O$8, $D$6)), data!O24 ), "")} -> 3.316 | H23: {=IFERROR( CHOOSE( data!$B$7, IF(_xll.IMDP("IR", data!$B24, data!P$8, $D$6)=0,"",_xll.IMDP("IR", data!$B24, data!P$8, $D$6)), IF(_xll.IMDP("IR", data!$C24, data!P$8, $D$6)=0,"",_xll.IMDP("IR", data!$C24, data!P$8, $D$6)), data!P24 ), "")} -> 3.274 | I23: {=IFERROR( CHOOSE( data!$B$7, IF(_xll.IMDP("IR", data!$B24, data!Q$8, $D$6)=0,"",_xll.IMDP("IR", data!$B24, data!Q$8, $D$6)), IF(_xll.IMDP("IR", data!$C24, data!Q$8, $D$6)=0,"",_xll.IMDP("IR", data!$C24, data!Q$8, $D$6)), data!Q24 ), "")} -> 3.24 | J23: {=IFERROR( CHOOSE( data!$B$7, IF(_xll.IMDP("IR", data!$B24, data!R$8, $D$6)=0,"",_xll.IMDP("IR", data!$B24, data!R$8, $D$6)), IF(_xll.IMDP("IR", data!$C24, data!R$8, $D$6)=0,"",_xll.IMDP("IR", data!$C24, data!R$8, $D$6)), data!R24 ), "")} -> 3.198 | K23: {=IFERROR( CHOOSE( data!$B$7, IF(_xll.IMDP("IR", data!$B24, data!S$8, $D$6)=0,"",_xll.IMDP("IR", data!$B24, data!S$8, $D$6)), IF(_xll.IMDP("IR", data!$C24, data!S$8, $D$6)=0,"",_xll.IMDP("IR", data!$C24, data!S$8, $D$6)), data!S24 ), "")} -> 3.152 | L23: {=IFERROR( CHOOSE( data!$B$7, IF(_xll.IMDP("IR", data!$B24, data!T$8, $D$6)=0,"",_xll.IMDP("IR", data!$B24, data!T$8, $D$6)), IF(_xll.IMDP("IR", data!$C24, data!T$8, $D$6)=0,"",_xll.IMDP("IR", data!$C24, data!T$8, $D$6)), data!T24 ), "")} -> 3.128 | ... T23: {=IFERROR( CHOOSE( data!$B$7, IF(_xll.IMDP("IR", data!$B24, data!AB$8, $D$6)=0,"",_xll.IMDP("IR", data!$B24, data!AB$8, $D$6)), IF(_xll.IMDP("IR", data!$C24, data!AB$8, $D$6)=0,"",_xll.IMDP("IR", data!$C24, data!AB$8, $D$6)), data!AB24 ), "")}
D24: AAA(중금-이표) | E24: {=IFERROR( CHOOSE( data!$B$7, IF(_xll.IMDP("IR", data!$B25, data!M$8, $D$6)=0,"",_xll.IMDP("IR", data!$B25, data!M$8, $D$6)), IF(_xll.IMDP("IR", data!$C25, data!M$8, $D$6)=0,"",_xll.IMDP("IR", data!$C25, data!M$8, $D$6)), data!M25 ), "")} -> 3.416 | F24: {=IFERROR( CHOOSE( data!$B$7, IF(_xll.IMDP("IR", data!$B25, data!N$8, $D$6)=0,"",_xll.IMDP("IR", data!$B25, data!N$8, $D$6)), IF(_xll.IMDP("IR", data!$C25, data!N$8, $D$6)=0,"",_xll.IMDP("IR", data!$C25, data!N$8, $D$6)), data!N25 ), "")} -> 3.389 | G24: {=IFERROR( CHOOSE( data!$B$7, IF(_xll.IMDP("IR", data!$B25, data!O$8, $D$6)=0,"",_xll.IMDP("IR", data!$B25, data!O$8, $D$6)), IF(_xll.IMDP("IR", data!$C25, data!O$8, $D$6)=0,"",_xll.IMDP("IR", data!$C25, data!O$8, $D$6)), data!O25 ), "")} -> 3.32 | H24: {=IFERROR( CHOOSE( data!$B$7, IF(_xll.IMDP("IR", data!$B25, data!P$8, $D$6)=0,"",_xll.IMDP("IR", data!$B25, data!P$8, $D$6)), IF(_xll.IMDP("IR", data!$C25, data!P$8, $D$6)=0,"",_xll.IMDP("IR", data!$C25, data!P$8, $D$6)), data!P25 ), "")} -> 3.28 | I24: {=IFERROR( CHOOSE( data!$B$7, IF(_xll.IMDP("IR", data!$B25, data!Q$8, $D$6)=0,"",_xll.IMDP("IR", data!$B25, data!Q$8, $D$6)), IF(_xll.IMDP("IR", data!$C25, data!Q$8, $D$6)=0,"",_xll.IMDP("IR", data!$C25, data!Q$8, $D$6)), data!Q25 ), "")} -> 3.232 | J24: {=IFERROR( CHOOSE( data!$B$7, IF(_xll.IMDP("IR", data!$B25, data!R$8, $D$6)=0,"",_xll.IMDP("IR", data!$B25, data!R$8, $D$6)), IF(_xll.IMDP("IR", data!$C25, data!R$8, $D$6)=0,"",_xll.IMDP("IR", data!$C25, data!R$8, $D$6)), data!R25 ), "")} -> 3.181 | K24: {=IFERROR( CHOOSE( data!$B$7, IF(_xll.IMDP("IR", data!$B25, data!S$8, $D$6)=0,"",_xll.IMDP("IR", data!$B25, data!S$8, $D$6)), IF(_xll.IMDP("IR", data!$C25, data!S$8, $D$6)=0,"",_xll.IMDP("IR", data!$C25, data!S$8, $D$6)), data!S25 ), "")} -> 3.126 | L24: {=IFERROR( CHOOSE( data!$B$7, IF(_xll.IMDP("IR", data!$B25, data!T$8, $D$6)=0,"",_xll.IMDP("IR", data!$B25, data!T$8, $D$6)), IF(_xll.IMDP("IR", data!$C25, data!T$8, $D$6)=0,"",_xll.IMDP("IR", data!$C25, data!T$8, $D$6)), data!T25 ), "")} -> 3.093 | ... T24: {=IFERROR( CHOOSE( data!$B$7, IF(_xll.IMDP("IR", data!$B25, data!AB$8, $D$6)=0,"",_xll.IMDP("IR", data!$B25, data!AB$8, $D$6)), IF(_xll.IMDP("IR", data!$C25, data!AB$8, $D$6)=0,"",_xll.IMDP("IR", data!$C25, data!AB$8, $D$6)), data!AB25 ), "")}
D25: AAA(중금-할인) | E25: {=IFERROR( CHOOSE( data!$B$7, IF(_xll.IMDP("IR", data!$B26, data!M$8, $D$6)=0,"",_xll.IMDP("IR", data!$B26, data!M$8, $D$6)), IF(_xll.IMDP("IR", data!$C26, data!M$8, $D$6)=0,"",_xll.IMDP("IR", data!$C26, data!M$8, $D$6)), data!M26 ), "")} -> 3.411 | F25: {=IFERROR( CHOOSE( data!$B$7, IF(_xll.IMDP("IR", data!$B26, data!N$8, $D$6)=0,"",_xll.IMDP("IR", data!$B26, data!N$8, $D$6)), IF(_xll.IMDP("IR", data!$C26, data!N$8, $D$6)=0,"",_xll.IMDP("IR", data!$C26, data!N$8, $D$6)), data!N26 ), "")} -> 3.394 | G25: {=IFERROR( CHOOSE( data!$B$7, IF(_xll.IMDP("IR", data!$B26, data!O$8, $D$6)=0,"",_xll.IMDP("IR", data!$B26, data!O$8, $D$6)), IF(_xll.IMDP("IR", data!$C26, data!O$8, $D$6)=0,"",_xll.IMDP("IR", data!$C26, data!O$8, $D$6)), data!O26 ), "")} -> 3.316 | H25: {=IFERROR( CHOOSE( data!$B$7, IF(_xll.IMDP("IR", data!$B26, data!P$8, $D$6)=0,"",_xll.IMDP("IR", data!$B26, data!P$8, $D$6)), IF(_xll.IMDP("IR", data!$C26, data!P$8, $D$6)=0,"",_xll.IMDP("IR", data!$C26, data!P$8, $D$6)), data!P26 ), "")} -> 3.274 | I25: {=IFERROR( CHOOSE( data!$B$7, IF(_xll.IMDP("IR", data!$B26, data!Q$8, $D$6)=0,"",_xll.IMDP("IR", data!$B26, data!Q$8, $D$6)), IF(_xll.IMDP("IR", data!$C26, data!Q$8, $D$6)=0,"",_xll.IMDP("IR", data!$C26, data!Q$8, $D$6)), data!Q26 ), "")} -> 3.24 | J25: {=IFERROR( CHOOSE( data!$B$7, IF(_xll.IMDP("IR", data!$B26, data!R$8, $D$6)=0,"",_xll.IMDP("IR", data!$B26, data!R$8, $D$6)), IF(_xll.IMDP("IR", data!$C26, data!R$8, $D$6)=0,"",_xll.IMDP("IR", data!$C26, data!R$8, $D$6)), data!R26 ), "")} -> 3.198 | K25: {=IFERROR( CHOOSE( data!$B$7, IF(_xll.IMDP("IR", data!$B26, data!S$8, $D$6)=0,"",_xll.IMDP("IR", data!$B26, data!S$8, $D$6)), IF(_xll.IMDP("IR", data!$C26, data!S$8, $D$6)=0,"",_xll.IMDP("IR", data!$C26, data!S$8, $D$6)), data!S26 ), "")} -> 3.152 | L25: {=IFERROR( CHOOSE( data!$B$7, IF(_xll.IMDP("IR", data!$B26, data!T$8, $D$6)=0,"",_xll.IMDP("IR", data!$B26, data!T$8, $D$6)), IF(_xll.IMDP("IR", data!$C26, data!T$8, $D$6)=0,"",_xll.IMDP("IR", data!$C26, data!T$8, $D$6)), data!T26 ), "")} -> 3.128 | ... T25: {=IFERROR( CHOOSE( data!$B$7, IF(_xll.IMDP("IR", data!$B26, data!AB$8, $D$6)=0,"",_xll.IMDP("IR", data!$B26, data!AB$8, $D$6)), IF(_xll.IMDP("IR", data!$C26, data!AB$8, $D$6)=0,"",_xll.IMDP("IR", data!$C26, data!AB$8, $D$6)), data!AB26 ), "")}
D26: AAA | E26: {=IFERROR( CHOOSE( data!$B$7, IF(_xll.IMDP("IR", data!$B27, data!M$8, $D$6)=0,"",_xll.IMDP("IR", data!$B27, data!M$8, $D$6)), IF(_xll.IMDP("IR", data!$C27, data!M$8, $D$6)=0,"",_xll.IMDP("IR", data!$C27, data!M$8, $D$6)), data!M27 ), "")} -> 3.434 | F26: {=IFERROR( CHOOSE( data!$B$7, IF(_xll.IMDP("IR", data!$B27, data!N$8, $D$6)=0,"",_xll.IMDP("IR", data!$B27, data!N$8, $D$6)), IF(_xll.IMDP("IR", data!$C27, data!N$8, $D$6)=0,"",_xll.IMDP("IR", data!$C27, data!N$8, $D$6)), data!N27 ), "")} -> 3.417 | G26: {=IFERROR( CHOOSE( data!$B$7, IF(_xll.IMDP("IR", data!$B27, data!O$8, $D$6)=0,"",_xll.IMDP("IR", data!$B27, data!O$8, $D$6)), IF(_xll.IMDP("IR", data!$C27, data!O$8, $D$6)=0,"",_xll.IMDP("IR", data!$C27, data!O$8, $D$6)), data!O27 ), "")} -> 3.348 | H26: {=IFERROR( CHOOSE( data!$B$7, IF(_xll.IMDP("IR", data!$B27, data!P$8, $D$6)=0,"",_xll.IMDP("IR", data!$B27, data!P$8, $D$6)), IF(_xll.IMDP("IR", data!$C27, data!P$8, $D$6)=0,"",_xll.IMDP("IR", data!$C27, data!P$8, $D$6)), data!P27 ), "")} -> 3.308 | I26: {=IFERROR( CHOOSE( data!$B$7, IF(_xll.IMDP("IR", data!$B27, data!Q$8, $D$6)=0,"",_xll.IMDP("IR", data!$B27, data!Q$8, $D$6)), IF(_xll.IMDP("IR", data!$C27, data!Q$8, $D$6)=0,"",_xll.IMDP("IR", data!$C27, data!Q$8, $D$6)), data!Q27 ), "")} -> 3.256 | J26: {=IFERROR( CHOOSE( data!$B$7, IF(_xll.IMDP("IR", data!$B27, data!R$8, $D$6)=0,"",_xll.IMDP("IR", data!$B27, data!R$8, $D$6)), IF(_xll.IMDP("IR", data!$C27, data!R$8, $D$6)=0,"",_xll.IMDP("IR", data!$C27, data!R$8, $D$6)), data!R27 ), "")} -> 3.224 | K26: {=IFERROR( CHOOSE( data!$B$7, IF(_xll.IMDP("IR", data!$B27, data!S$8, $D$6)=0,"",_xll.IMDP("IR", data!$B27, data!S$8, $D$6)), IF(_xll.IMDP("IR", data!$C27, data!S$8, $D$6)=0,"",_xll.IMDP("IR", data!$C27, data!S$8, $D$6)), data!S27 ), "")} -> 3.208 | L26: {=IFERROR( CHOOSE( data!$B$7, IF(_xll.IMDP("IR", data!$B27, data!T$8, $D$6)=0,"",_xll.IMDP("IR", data!$B27, data!T$8, $D$6)), IF(_xll.IMDP("IR", data!$C27, data!T$8, $D$6)=0,"",_xll.IMDP("IR", data!$C27, data!T$8, $D$6)), data!T27 ), "")} -> 3.211 | ... T26: {=IFERROR( CHOOSE( data!$B$7, IF(_xll.IMDP("IR", data!$B27, data!AB$8, $D$6)=0,"",_xll.IMDP("IR", data!$B27, data!AB$8, $D$6)), IF(_xll.IMDP("IR", data!$C27, data!AB$8, $D$6)=0,"",_xll.IMDP("IR", data!$C27, data!AB$8, $D$6)), data!AB27 ), "")}
D27: AA+ | E27: {=IFERROR( CHOOSE( data!$B$7, IF(_xll.IMDP("IR", data!$B28, data!M$8, $D$6)=0,"",_xll.IMDP("IR", data!$B28, data!M$8, $D$6)), IF(_xll.IMDP("IR", data!$C28, data!M$8, $D$6)=0,"",_xll.IMDP("IR", data!$C28, data!M$8, $D$6)), data!M28 ), "")} -> 3.453 | F27: {=IFERROR( CHOOSE( data!$B$7, IF(_xll.IMDP("IR", data!$B28, data!N$8, $D$6)=0,"",_xll.IMDP("IR", data!$B28, data!N$8, $D$6)), IF(_xll.IMDP("IR", data!$C28, data!N$8, $D$6)=0,"",_xll.IMDP("IR", data!$C28, data!N$8, $D$6)), data!N28 ), "")} -> 3.439 | G27: {=IFERROR( CHOOSE( data!$B$7, IF(_xll.IMDP("IR", data!$B28, data!O$8, $D$6)=0,"",_xll.IMDP("IR", data!$B28, data!O$8, $D$6)), IF(_xll.IMDP("IR", data!$C28, data!O$8, $D$6)=0,"",_xll.IMDP("IR", data!$C28, data!O$8, $D$6)), data!O28 ), "")} -> 3.392 | H27: {=IFERROR( CHOOSE( data!$B$7, IF(_xll.IMDP("IR", data!$B28, data!P$8, $D$6)=0,"",_xll.IMDP("IR", data!$B28, data!P$8, $D$6)), IF(_xll.IMDP("IR", data!$C28, data!P$8, $D$6)=0,"",_xll.IMDP("IR", data!$C28, data!P$8, $D$6)), data!P28 ), "")} -> 3.373 | I27: {=IFERROR( CHOOSE( data!$B$7, IF(_xll.IMDP("IR", data!$B28, data!Q$8, $D$6)=0,"",_xll.IMDP("IR", data!$B28, data!Q$8, $D$6)), IF(_xll.IMDP("IR", data!$C28, data!Q$8, $D$6)=0,"",_xll.IMDP("IR", data!$C28, data!Q$8, $D$6)), data!Q28 ), "")} -> 3.358 | J27: {=IFERROR( CHOOSE( data!$B$7, IF(_xll.IMDP("IR", data!$B28, data!R$8, $D$6)=0,"",_xll.IMDP("IR", data!$B28, data!R$8, $D$6)), IF(_xll.IMDP("IR", data!$C28, data!R$8, $D$6)=0,"",_xll.IMDP("IR", data!$C28, data!R$8, $D$6)), data!R28 ), "")} -> 3.327 | K27: {=IFERROR( CHOOSE( data!$B$7, IF(_xll.IMDP("IR", data!$B28, data!S$8, $D$6)=0,"",_xll.IMDP("IR", data!$B28, data!S$8, $D$6)), IF(_xll.IMDP("IR", data!$C28, data!S$8, $D$6)=0,"",_xll.IMDP("IR", data!$C28, data!S$8, $D$6)), data!S28 ), "")} -> 3.31 | L27: {=IFERROR( CHOOSE( data!$B$7, IF(_xll.IMDP("IR", data!$B28, data!T$8, $D$6)=0,"",_xll.IMDP("IR", data!$B28, data!T$8, $D$6)), IF(_xll.IMDP("IR", data!$C28, data!T$8, $D$6)=0,"",_xll.IMDP("IR", data!$C28, data!T$8, $D$6)), data!T28 ), "")} -> 3.304 | ... T27: {=IFERROR( CHOOSE( data!$B$7, IF(_xll.IMDP("IR", data!$B28, data!AB$8, $D$6)=0,"",_xll.IMDP("IR", data!$B28, data!AB$8, $D$6)), IF(_xll.IMDP("IR", data!$C28, data!AB$8, $D$6)=0,"",_xll.IMDP("IR", data!$C28, data!AB$8, $D$6)), data!AB28 ), "")}
D28: AA0 | E28: {=IFERROR( CHOOSE( data!$B$7, IF(_xll.IMDP("IR", data!$B29, data!M$8, $D$6)=0,"",_xll.IMDP("IR", data!$B29, data!M$8, $D$6)), IF(_xll.IMDP("IR", data!$C29, data!M$8, $D$6)=0,"",_xll.IMDP("IR", data!$C29, data!M$8, $D$6)), data!M29 ), "")} -> 3.625 | F28: {=IFERROR( CHOOSE( data!$B$7, IF(_xll.IMDP("IR", data!$B29, data!N$8, $D$6)=0,"",_xll.IMDP("IR", data!$B29, data!N$8, $D$6)), IF(_xll.IMDP("IR", data!$C29, data!N$8, $D$6)=0,"",_xll.IMDP("IR", data!$C29, data!N$8, $D$6)), data!N29 ), "")} -> 3.618 | G28: {=IFERROR( CHOOSE( data!$B$7, IF(_xll.IMDP("IR", data!$B29, data!O$8, $D$6)=0,"",_xll.IMDP("IR", data!$B29, data!O$8, $D$6)), IF(_xll.IMDP("IR", data!$C29, data!O$8, $D$6)=0,"",_xll.IMDP("IR", data!$C29, data!O$8, $D$6)), data!O29 ), "")} -> 3.565 | H28: {=IFERROR( CHOOSE( data!$B$7, IF(_xll.IMDP("IR", data!$B29, data!P$8, $D$6)=0,"",_xll.IMDP("IR", data!$B29, data!P$8, $D$6)), IF(_xll.IMDP("IR", data!$C29, data!P$8, $D$6)=0,"",_xll.IMDP("IR", data!$C29, data!P$8, $D$6)), data!P29 ), "")} -> 3.558 | I28: {=IFERROR( CHOOSE( data!$B$7, IF(_xll.IMDP("IR", data!$B29, data!Q$8, $D$6)=0,"",_xll.IMDP("IR", data!$B29, data!Q$8, $D$6)), IF(_xll.IMDP("IR", data!$C29, data!Q$8, $D$6)=0,"",_xll.IMDP("IR", data!$C29, data!Q$8, $D$6)), data!Q29 ), "")} -> 3.552 | J28: {=IFERROR( CHOOSE( data!$B$7, IF(_xll.IMDP("IR", data!$B29, data!R$8, $D$6)=0,"",_xll.IMDP("IR", data!$B29, data!R$8, $D$6)), IF(_xll.IMDP("IR", data!$C29, data!R$8, $D$6)=0,"",_xll.IMDP("IR", data!$C29, data!R$8, $D$6)), data!R29 ), "")} -> 3.548 | K28: {=IFERROR( CHOOSE( data!$B$7, IF(_xll.IMDP("IR", data!$B29, data!S$8, $D$6)=0,"",_xll.IMDP("IR", data!$B29, data!S$8, $D$6)), IF(_xll.IMDP("IR", data!$C29, data!S$8, $D$6)=0,"",_xll.IMDP("IR", data!$C29, data!S$8, $D$6)), data!S29 ), "")} -> 3.555 | L28: {=IFERROR( CHOOSE( data!$B$7, IF(_xll.IMDP("IR", data!$B29, data!T$8, $D$6)=0,"",_xll.IMDP("IR", data!$B29, data!T$8, $D$6)), IF(_xll.IMDP("IR", data!$C29, data!T$8, $D$6)=0,"",_xll.IMDP("IR", data!$C29, data!T$8, $D$6)), data!T29 ), "")} -> 3.553 | ... T28: {=IFERROR( CHOOSE( data!$B$7, IF(_xll.IMDP("IR", data!$B29, data!AB$8, $D$6)=0,"",_xll.IMDP("IR", data!$B29, data!AB$8, $D$6)), IF(_xll.IMDP("IR", data!$C29, data!AB$8, $D$6)=0,"",_xll.IMDP("IR", data!$C29, data!AB$8, $D$6)), data!AB29 ), "")}
D29: AA- | E29: {=IFERROR( CHOOSE( data!$B$7, IF(_xll.IMDP("IR", data!$B30, data!M$8, $D$6)=0,"",_xll.IMDP("IR", data!$B30, data!M$8, $D$6)), IF(_xll.IMDP("IR", data!$C30, data!M$8, $D$6)=0,"",_xll.IMDP("IR", data!$C30, data!M$8, $D$6)), data!M30 ), "")} -> 3.756 | F29: {=IFERROR( CHOOSE( data!$B$7, IF(_xll.IMDP("IR", data!$B30, data!N$8, $D$6)=0,"",_xll.IMDP("IR", data!$B30, data!N$8, $D$6)), IF(_xll.IMDP("IR", data!$C30, data!N$8, $D$6)=0,"",_xll.IMDP("IR", data!$C30, data!N$8, $D$6)), data!N30 ), "")} -> 3.833 | G29: {=IFERROR( CHOOSE( data!$B$7, IF(_xll.IMDP("IR", data!$B30, data!O$8, $D$6)=0,"",_xll.IMDP("IR", data!$B30, data!O$8, $D$6)), IF(_xll.IMDP("IR", data!$C30, data!O$8, $D$6)=0,"",_xll.IMDP("IR", data!$C30, data!O$8, $D$6)), data!O30 ), "")} -> 3.815 | H29: {=IFERROR( CHOOSE( data!$B$7, IF(_xll.IMDP("IR", data!$B30, data!P$8, $D$6)=0,"",_xll.IMDP("IR", data!$B30, data!P$8, $D$6)), IF(_xll.IMDP("IR", data!$C30, data!P$8, $D$6)=0,"",_xll.IMDP("IR", data!$C30, data!P$8, $D$6)), data!P30 ), "")} -> 3.818 | I29: {=IFERROR( CHOOSE( data!$B$7, IF(_xll.IMDP("IR", data!$B30, data!Q$8, $D$6)=0,"",_xll.IMDP("IR", data!$B30, data!Q$8, $D$6)), IF(_xll.IMDP("IR", data!$C30, data!Q$8, $D$6)=0,"",_xll.IMDP("IR", data!$C30, data!Q$8, $D$6)), data!Q30 ), "")} -> 3.81 | J29: {=IFERROR( CHOOSE( data!$B$7, IF(_xll.IMDP("IR", data!$B30, data!R$8, $D$6)=0,"",_xll.IMDP("IR", data!$B30, data!R$8, $D$6)), IF(_xll.IMDP("IR", data!$C30, data!R$8, $D$6)=0,"",_xll.IMDP("IR", data!$C30, data!R$8, $D$6)), data!R30 ), "")} -> 3.802 | K29: {=IFERROR( CHOOSE( data!$B$7, IF(_xll.IMDP("IR", data!$B30, data!S$8, $D$6)=0,"",_xll.IMDP("IR", data!$B30, data!S$8, $D$6)), IF(_xll.IMDP("IR", data!$C30, data!S$8, $D$6)=0,"",_xll.IMDP("IR", data!$C30, data!S$8, $D$6)), data!S30 ), "")} -> 3.8 | L29: {=IFERROR( CHOOSE( data!$B$7, IF(_xll.IMDP("IR", data!$B30, data!T$8, $D$6)=0,"",_xll.IMDP("IR", data!$B30, data!T$8, $D$6)), IF(_xll.IMDP("IR", data!$C30, data!T$8, $D$6)=0,"",_xll.IMDP("IR", data!$C30, data!T$8, $D$6)), data!T30 ), "")} -> 3.797 | ... T29: {=IFERROR( CHOOSE( data!$B$7, IF(_xll.IMDP("IR", data!$B30, data!AB$8, $D$6)=0,"",_xll.IMDP("IR", data!$B30, data!AB$8, $D$6)), IF(_xll.IMDP("IR", data!$C30, data!AB$8, $D$6)=0,"",_xll.IMDP("IR", data!$C30, data!AB$8, $D$6)), data!AB30 ), "")}
D30: A+ | E30: {=IFERROR( CHOOSE( data!$B$7, IF(_xll.IMDP("IR", data!$B31, data!M$8, $D$6)=0,"",_xll.IMDP("IR", data!$B31, data!M$8, $D$6)), IF(_xll.IMDP("IR", data!$C31, data!M$8, $D$6)=0,"",_xll.IMDP("IR", data!$C31, data!M$8, $D$6)), data!M31 ), "")} -> 3.865 | F30: {=IFERROR( CHOOSE( data!$B$7, IF(_xll.IMDP("IR", data!$B31, data!N$8, $D$6)=0,"",_xll.IMDP("IR", data!$B31, data!N$8, $D$6)), IF(_xll.IMDP("IR", data!$C31, data!N$8, $D$6)=0,"",_xll.IMDP("IR", data!$C31, data!N$8, $D$6)), data!N31 ), "")} -> 3.922 | G30: {=IFERROR( CHOOSE( data!$B$7, IF(_xll.IMDP("IR", data!$B31, data!O$8, $D$6)=0,"",_xll.IMDP("IR", data!$B31, data!O$8, $D$6)), IF(_xll.IMDP("IR", data!$C31, data!O$8, $D$6)=0,"",_xll.IMDP("IR", data!$C31, data!O$8, $D$6)), data!O31 ), "")} -> 3.902 | H30: {=IFERROR( CHOOSE( data!$B$7, IF(_xll.IMDP("IR", data!$B31, data!P$8, $D$6)=0,"",_xll.IMDP("IR", data!$B31, data!P$8, $D$6)), IF(_xll.IMDP("IR", data!$C31, data!P$8, $D$6)=0,"",_xll.IMDP("IR", data!$C31, data!P$8, $D$6)), data!P31 ), "")} -> 3.912 | I30: {=IFERROR( CHOOSE( data!$B$7, IF(_xll.IMDP("IR", data!$B31, data!Q$8, $D$6)=0,"",_xll.IMDP("IR", data!$B31, data!Q$8, $D$6)), IF(_xll.IMDP("IR", data!$C31, data!Q$8, $D$6)=0,"",_xll.IMDP("IR", data!$C31, data!Q$8, $D$6)), data!Q31 ), "")} -> 3.919 | J30: {=IFERROR( CHOOSE( data!$B$7, IF(_xll.IMDP("IR", data!$B31, data!R$8, $D$6)=0,"",_xll.IMDP("IR", data!$B31, data!R$8, $D$6)), IF(_xll.IMDP("IR", data!$C31, data!R$8, $D$6)=0,"",_xll.IMDP("IR", data!$C31, data!R$8, $D$6)), data!R31 ), "")} -> 3.917 | K30: {=IFERROR( CHOOSE( data!$B$7, IF(_xll.IMDP("IR", data!$B31, data!S$8, $D$6)=0,"",_xll.IMDP("IR", data!$B31, data!S$8, $D$6)), IF(_xll.IMDP("IR", data!$C31, data!S$8, $D$6)=0,"",_xll.IMDP("IR", data!$C31, data!S$8, $D$6)), data!S31 ), "")} -> 3.92 | L30: {=IFERROR( CHOOSE( data!$B$7, IF(_xll.IMDP("IR", data!$B31, data!T$8, $D$6)=0,"",_xll.IMDP("IR", data!$B31, data!T$8, $D$6)), IF(_xll.IMDP("IR", data!$C31, data!T$8, $D$6)=0,"",_xll.IMDP("IR", data!$C31, data!T$8, $D$6)), data!T31 ), "")} -> 3.921 | ... T30: {=IFERROR( CHOOSE( data!$B$7, IF(_xll.IMDP("IR", data!$B31, data!AB$8, $D$6)=0,"",_xll.IMDP("IR", data!$B31, data!AB$8, $D$6)), IF(_xll.IMDP("IR", data!$C31, data!AB$8, $D$6)=0,"",_xll.IMDP("IR", data!$C31, data!AB$8, $D$6)), data!AB31 ), "")}
D31: A0 | E31: {=IFERROR( CHOOSE( data!$B$7, IF(_xll.IMDP("IR", data!$B32, data!M$8, $D$6)=0,"",_xll.IMDP("IR", data!$B32, data!M$8, $D$6)), IF(_xll.IMDP("IR", data!$C32, data!M$8, $D$6)=0,"",_xll.IMDP("IR", data!$C32, data!M$8, $D$6)), data!M32 ), "")} -> 3.956 | F31: {=IFERROR( CHOOSE( data!$B$7, IF(_xll.IMDP("IR", data!$B32, data!N$8, $D$6)=0,"",_xll.IMDP("IR", data!$B32, data!N$8, $D$6)), IF(_xll.IMDP("IR", data!$C32, data!N$8, $D$6)=0,"",_xll.IMDP("IR", data!$C32, data!N$8, $D$6)), data!N32 ), "")} -> 3.997 | G31: {=IFERROR( CHOOSE( data!$B$7, IF(_xll.IMDP("IR", data!$B32, data!O$8, $D$6)=0,"",_xll.IMDP("IR", data!$B32, data!O$8, $D$6)), IF(_xll.IMDP("IR", data!$C32, data!O$8, $D$6)=0,"",_xll.IMDP("IR", data!$C32, data!O$8, $D$6)), data!O32 ), "")} -> 3.986 | H31: {=IFERROR( CHOOSE( data!$B$7, IF(_xll.IMDP("IR", data!$B32, data!P$8, $D$6)=0,"",_xll.IMDP("IR", data!$B32, data!P$8, $D$6)), IF(_xll.IMDP("IR", data!$C32, data!P$8, $D$6)=0,"",_xll.IMDP("IR", data!$C32, data!P$8, $D$6)), data!P32 ), "")} -> 4.003 | I31: {=IFERROR( CHOOSE( data!$B$7, IF(_xll.IMDP("IR", data!$B32, data!Q$8, $D$6)=0,"",_xll.IMDP("IR", data!$B32, data!Q$8, $D$6)), IF(_xll.IMDP("IR", data!$C32, data!Q$8, $D$6)=0,"",_xll.IMDP("IR", data!$C32, data!Q$8, $D$6)), data!Q32 ), "")} -> 4.01 | J31: {=IFERROR( CHOOSE( data!$B$7, IF(_xll.IMDP("IR", data!$B32, data!R$8, $D$6)=0,"",_xll.IMDP("IR", data!$B32, data!R$8, $D$6)), IF(_xll.IMDP("IR", data!$C32, data!R$8, $D$6)=0,"",_xll.IMDP("IR", data!$C32, data!R$8, $D$6)), data!R32 ), "")} -> 4.015 | K31: {=IFERROR( CHOOSE( data!$B$7, IF(_xll.IMDP("IR", data!$B32, data!S$8, $D$6)=0,"",_xll.IMDP("IR", data!$B32, data!S$8, $D$6)), IF(_xll.IMDP("IR", data!$C32, data!S$8, $D$6)=0,"",_xll.IMDP("IR", data!$C32, data!S$8, $D$6)), data!S32 ), "")} -> 4.019 | L31: {=IFERROR( CHOOSE( data!$B$7, IF(_xll.IMDP("IR", data!$B32, data!T$8, $D$6)=0,"",_xll.IMDP("IR", data!$B32, data!T$8, $D$6)), IF(_xll.IMDP("IR", data!$C32, data!T$8, $D$6)=0,"",_xll.IMDP("IR", data!$C32, data!T$8, $D$6)), data!T32 ), "")} -> 4.024 | ... T31: {=IFERROR( CHOOSE( data!$B$7, IF(_xll.IMDP("IR", data!$B32, data!AB$8, $D$6)=0,"",_xll.IMDP("IR", data!$B32, data!AB$8, $D$6)), IF(_xll.IMDP("IR", data!$C32, data!AB$8, $D$6)=0,"",_xll.IMDP("IR", data!$C32, data!AB$8, $D$6)), data!AB32 ), "")}
D32: A- | E32: {=IFERROR( CHOOSE( data!$B$7, IF(_xll.IMDP("IR", data!$B33, data!M$8, $D$6)=0,"",_xll.IMDP("IR", data!$B33, data!M$8, $D$6)), IF(_xll.IMDP("IR", data!$C33, data!M$8, $D$6)=0,"",_xll.IMDP("IR", data!$C33, data!M$8, $D$6)), data!M33 ), "")} -> 4.043 | F32: {=IFERROR( CHOOSE( data!$B$7, IF(_xll.IMDP("IR", data!$B33, data!N$8, $D$6)=0,"",_xll.IMDP("IR", data!$B33, data!N$8, $D$6)), IF(_xll.IMDP("IR", data!$C33, data!N$8, $D$6)=0,"",_xll.IMDP("IR", data!$C33, data!N$8, $D$6)), data!N33 ), "")} -> 4.086 | G32: {=IFERROR( CHOOSE( data!$B$7, IF(_xll.IMDP("IR", data!$B33, data!O$8, $D$6)=0,"",_xll.IMDP("IR", data!$B33, data!O$8, $D$6)), IF(_xll.IMDP("IR", data!$C33, data!O$8, $D$6)=0,"",_xll.IMDP("IR", data!$C33, data!O$8, $D$6)), data!O33 ), "")} -> 4.071 | H32: {=IFERROR( CHOOSE( data!$B$7, IF(_xll.IMDP("IR", data!$B33, data!P$8, $D$6)=0,"",_xll.IMDP("IR", data!$B33, data!P$8, $D$6)), IF(_xll.IMDP("IR", data!$C33, data!P$8, $D$6)=0,"",_xll.IMDP("IR", data!$C33, data!P$8, $D$6)), data!P33 ), "")} -> 4.097 | I32: {=IFERROR( CHOOSE( data!$B$7, IF(_xll.IMDP("IR", data!$B33, data!Q$8, $D$6)=0,"",_xll.IMDP("IR", data!$B33, data!Q$8, $D$6)), IF(_xll.IMDP("IR", data!$C33, data!Q$8, $D$6)=0,"",_xll.IMDP("IR", data!$C33, data!Q$8, $D$6)), data!Q33 ), "")} -> 4.102 | J32: {=IFERROR( CHOOSE( data!$B$7, IF(_xll.IMDP("IR", data!$B33, data!R$8, $D$6)=0,"",_xll.IMDP("IR", data!$B33, data!R$8, $D$6)), IF(_xll.IMDP("IR", data!$C33, data!R$8, $D$6)=0,"",_xll.IMDP("IR", data!$C33, data!R$8, $D$6)), data!R33 ), "")} -> 4.108 | K32: {=IFERROR( CHOOSE( data!$B$7, IF(_xll.IMDP("IR", data!$B33, data!S$8, $D$6)=0,"",_xll.IMDP("IR", data!$B33, data!S$8, $D$6)), IF(_xll.IMDP("IR", data!$C33, data!S$8, $D$6)=0,"",_xll.IMDP("IR", data!$C33, data!S$8, $D$6)), data!S33 ), "")} -> 4.115 | L32: {=IFERROR( CHOOSE( data!$B$7, IF(_xll.IMDP("IR", data!$B33, data!T$8, $D$6)=0,"",_xll.IMDP("IR", data!$B33, data!T$8, $D$6)), IF(_xll.IMDP("IR", data!$C33, data!T$8, $D$6)=0,"",_xll.IMDP("IR", data!$C33, data!T$8, $D$6)), data!T33 ), "")} -> 4.119 | ... T32: {=IFERROR( CHOOSE( data!$B$7, IF(_xll.IMDP("IR", data!$B33, data!AB$8, $D$6)=0,"",_xll.IMDP("IR", data!$B33, data!AB$8, $D$6)), IF(_xll.IMDP("IR", data!$C33, data!AB$8, $D$6)=0,"",_xll.IMDP("IR", data!$C33, data!AB$8, $D$6)), data!AB33 ), "")}
