Workbook

Sheet 재무비율
J2: 재무비율 및 재무제표 분석
N4: =_xll.IMDP("STK",$N$5,"한글종목명") -> 삼성전자 | O4: 기준시점 | P4: 연결기준 | Q4: 재무제표 보기
M5: 수정 가능한 영역 표시 | N5: 005930 | O5: =K96 -> 45199 | P5: 연결
J89: 재무제표
F90: 천원 | G90: 1 | H90: 3
F91: 백만원 | G91: 1000 | H91: =INDEX($G$90:$G$93, $H$90) -> 100000 | J91: 그래프 보기 | K91: =O4 -> 기준시점 | L91: 시작일 | M91: 누적기준 | N91: 분기 | O91: =P4 -> 연결기준 | Q91: 연결 | R91: 누적 | S91: 연속
F92: 억원 | G92: 100000 | K92: =K96 -> 45199 | L92: =EOMONTH(TODAY(),-26) -> 44469 | M92: 누적 | N92: 연속 | O92: =P5 -> 연결 | Q92: 개별 | R92: 순 | S92: 1
F93: 십억원 | G93: 1000000 | J93: =$N$4 -> 삼성전자 | S93: 2
J94: 단위: | S94: 3
S95: 4
B96: 1 | D96: 재무상태표 | E96: 포괄손익계산서 | F96: 현금흐름표 | G96: 자본변동표 | H96: 재무비율 | J96: 일자 | K96: =IF(Sheet1!D4="", "", Sheet1!D4) -> 45199 | L96: =IF(Sheet1!E4="", "", Sheet1!E4) -> 45107 | M96: =IF(Sheet1!F4="", "", Sheet1!F4) -> 45016 | N96: =IF(Sheet1!G4="", "", Sheet1!G4) -> 44926 | O96: =IF(Sheet1!H4="", "", Sheet1!H4) -> 44834 | P96: =IF(Sheet1!I4="", "", Sheet1!I4) -> 44742 | Q96: =IF(Sheet1!J4="", "", Sheet1!J4) -> 44651 | R96: =IF(Sheet1!K4="", "", Sheet1!K4) -> 44561 | ... AS96: =IF(Sheet1!AL4="", "", Sheet1!AL4)
B97: 재무상태표 | C97: 1 | D97: 자산 | E97: 매출액(영업수익) | F97: 영업활동으로인한현금흐름 | G97: 기말자본금 | H97: 총자산증가율 | J97: =IF(INDEX($D$97:$H$135,$C97,$B$96)=0,"",INDEX($D$97:$H$135,$C97,$B$96)) -> 자산 | K97: =IF(Sheet1!D5="", "", Sheet1!D5/$H$91) -> 4544664.5 | L97: =IF(Sheet1!E5="", "", Sheet1!E5/$H$91) -> 4480005.5 | M97: =IF(Sheet1!F5="", "", Sheet1!F5/$H$91) -> 4540917.8 | N97: =IF(Sheet1!G5="", "", Sheet1!G5/$H$91) -> 4484245.1 | O97: =IF(Sheet1!H5="", "", Sheet1!H5/$H$91) -> 4702784.1 | P97: =IF(Sheet1!I5="", "", Sheet1!I5/$H$91) -> 4480406.5 | Q97: =IF(Sheet1!J5="", "", Sheet1!J5/$H$91) -> 4393269.6 | R97: =IF(Sheet1!K5="", "", Sheet1!K5/$H$91) -> 4266211.6 | ... AS97: =IF(Sheet1!AL5="", "", Sheet1!AL5/$H$91)
B98: 포괄손익계산서 | C98: 2 | D98: 현금및현금성자산 | E98: 매출원가(영업비용) | F98: 당기순손익 | G98: 기초자본금 | H98: 유형자산증가율 | J98: =IF(INDEX($D$97:$H$135,$C98,$B$96)=0,"",INDEX($D$97:$H$135,$C98,$B$96)) -> 현금및현금성자산 | K98: =IF(Sheet1!D6="", "", Sheet1!D6/$H$91) -> 751442.84 | L98: =IF(Sheet1!E6="", "", Sheet1!E6/$H$91) -> 799197.75 | M98: =IF(Sheet1!F6="", "", Sheet1!F6/$H$91) -> 729493.77 | N98: =IF(Sheet1!G6="", "", Sheet1!G6/$H$91) -> 496807.1 | O98: =IF(Sheet1!H6="", "", Sheet1!H6/$H$91) -> 445154.21 | P98: =IF(Sheet1!I6="", "", Sheet1!I6/$H$91) -> 395831.41 | Q98: =IF(Sheet1!J6="", "", Sheet1!J6/$H$91) -> 489449.82 | R98: =IF(Sheet1!K6="", "", Sheet1!K6/$H$91) -> 390314.15 | ... AS98: =IF(Sheet1!AL6="", "", Sheet1!AL6/$H$91)
B99: 현금흐름표 | C99: 3 | D99: 금융자산 | E99: 매출총이익 | F99: 현금유출이없는비용등가산 | G99: 유상증자 | H99: 부채총계증가율 | J99: =IF(INDEX($D$97:$H$135,$C99,$B$96)=0,"",INDEX($D$97:$H$135,$C99,$B$96)) -> 금융자산 | K99: =IF(Sheet1!D7="", "", Sheet1!D7/$H$91) -> 179272.66 | L99: =IF(Sheet1!E7="", "", Sheet1!E7/$H$91) -> 171801.3 | M99: =IF(Sheet1!F7="", "", Sheet1!F7/$H$91) -> 352001.84 | N99: =IF(Sheet1!G7="", "", Sheet1!G7/$H$91) -> 651028.86 | O99: =IF(Sheet1!H7="", "", Sheet1!H7/$H$91) -> 836468.07 | P99: =IF(Sheet1!I7="", "", Sheet1!I7/$H$91) -> 844288.22 | Q99: =IF(Sheet1!J7="", "", Sheet1!J7/$H$91) -> 751214.26 | R99: =IF(Sheet1!K7="", "", Sheet1!K7/$H$91) -> 817089.86 | ... AS99: =IF(Sheet1!AL7="", "", Sheet1!AL7/$H$91)
B100: 자본변동표 | C100: 4 | D100: 파생상품자산 | E100: 판매비와 관리비 | F100: 감가상각비(현금흐름표) | G100: 무상증자 | H100: 차입금증가율 | J100: =IF(INDEX($D$97:$H$135,$C100,$B$96)=0,"",INDEX($D$97:$H$135,$C100,$B$96)) -> 파생상품자산 | K100: =IF(Sheet1!D8="", "", Sheet1!D8/$H$91) | L100: =IF(Sheet1!E8="", "", Sheet1!E8/$H$91) | M100: =IF(Sheet1!F8="", "", Sheet1!F8/$H$91) | N100: =IF(Sheet1!G8="", "", Sheet1!G8/$H$91) | O100: =IF(Sheet1!H8="", "", Sheet1!H8/$H$91) | P100: =IF(Sheet1!I8="", "", Sheet1!I8/$H$91) | Q100: =IF(Sheet1!J8="", "", Sheet1!J8/$H$91) | R100: =IF(Sheet1!K8="", "", Sheet1!K8/$H$91) | ... AS100: =IF(Sheet1!AL8="", "", Sheet1!AL8/$H$91)
B101: 재무비율 | C101: 5 | D101: 대출채권 | E101: 급여 | F101: 기타무형자산상각비(현금흐름표) | G101: 주식매수선택권 | H101: 자기자본증가율 | J101: =IF(INDEX($D$97:$H$135,$C101,$B$96)=0,"",INDEX($D$97:$H$135,$C101,$B$96)) -> 대출채권 | K101: =IF(Sheet1!D9="", "", Sheet1!D9/$H$91) | L101: =IF(Sheet1!E9="", "", Sheet1!E9/$H$91) | M101: =IF(Sheet1!F9="", "", Sheet1!F9/$H$91) | N101: =IF(Sheet1!G9="", "", Sheet1!G9/$H$91) | O101: =IF(Sheet1!H9="", "", Sheet1!H9/$H$91) | P101: =IF(Sheet1!I9="", "", Sheet1!I9/$H$91) | Q101: =IF(Sheet1!J9="", "", Sheet1!J9/$H$91) | R101: =IF(Sheet1!K9="", "", Sheet1!K9/$H$91) | ... AS101: =IF(Sheet1!AL9="", "", Sheet1!AL9/$H$91)
C102: 6 | D102: 기타자산 | E102: 감가상각비(포괄손익계산서) | F102: 외환거래손실(현금흐름표) | G102: 전환사채 | H102: 매출액(영업수익)증가율 | J102: =IF(INDEX($D$97:$H$135,$C102,$B$96)=0,"",INDEX($D$97:$H$135,$C102,$B$96)) -> 기타자산 | K102: =IF(Sheet1!D10="", "", Sheet1!D10/$H$91) -> 238584.34 | L102: =IF(Sheet1!E10="", "", Sheet1!E10/$H$91) -> 233997.91 | M102: =IF(Sheet1!F10="", "", Sheet1!F10/$H$91) -> 226843.43 | N102: =IF(Sheet1!G10="", "", Sheet1!G10/$H$91) -> 210493 | O102: =IF(Sheet1!H10="", "", Sheet1!H10/$H$91) -> 197927.57 | P102: =IF(Sheet1!I10="", "", Sheet1!I10/$H$91) -> 180694.77 | Q102: =IF(Sheet1!J10="", "", Sheet1!J10/$H$91) -> 183971.54 | R102: =IF(Sheet1!K10="", "", Sheet1!K10/$H$91) -> 157986.06 | ... AS102: =IF(Sheet1!AL10="", "", Sheet1!AL10/$H$91)
C103: 7 | D103: 유형자산 | E103: 기타무형자산상각비(포괄손익계산서) | F103: 자산처분손실 | G103: 신주인수권부사채 | H103: 매출원가(영업비용)증가율 | J103: =IF(INDEX($D$97:$H$135,$C103,$B$96)=0,"",INDEX($D$97:$H$135,$C103,$B$96)) -> 유형자산 | K103: =IF(Sheet1!D11="", "", Sheet1!D11/$H$91) -> 1808059.6 | L103: =IF(Sheet1!E11="", "", Sheet1!E11/$H$91) -> 1778699.4 | M103: =IF(Sheet1!F11="", "", Sheet1!F11/$H$91) -> 1718575.2 | N103: =IF(Sheet1!G11="", "", Sheet1!G11/$H$91) -> 1680453.9 | O103: =IF(Sheet1!H11="", "", Sheet1!H11/$H$91) -> 1603435.7 | P103: =IF(Sheet1!I11="", "", Sheet1!I11/$H$91) -> 1542545.8 | Q103: =IF(Sheet1!J11="", "", Sheet1!J11/$H$91) -> 1496180.2 | R103: =IF(Sheet1!K11="", "", Sheet1!K11/$H$91) -> 1499285.4 | ... AS103: =IF(Sheet1!AL11="", "", Sheet1!AL11/$H$91)
C104: 8 | D104: 투자부동산 | E104: 연구개발비 | F104: (현금유입이없는수익등차감) | G104: 기말자본잉여금 | H104: 영업이익증가율(보고서기재) | J104: =IF(INDEX($D$97:$H$135,$C104,$B$96)=0,"",INDEX($D$97:$H$135,$C104,$B$96)) -> 투자부동산 | K104: =IF(Sheet1!D12="", "", Sheet1!D12/$H$91) | L104: =IF(Sheet1!E12="", "", Sheet1!E12/$H$91) | M104: =IF(Sheet1!F12="", "", Sheet1!F12/$H$91) | N104: =IF(Sheet1!G12="", "", Sheet1!G12/$H$91) | O104: =IF(Sheet1!H12="", "", Sheet1!H12/$H$91) | P104: =IF(Sheet1!I12="", "", Sheet1!I12/$H$91) | Q104: =IF(Sheet1!J12="", "", Sheet1!J12/$H$91) | R104: =IF(Sheet1!K12="", "", Sheet1!K12/$H$91) | ... AS104: =IF(Sheet1!AL12="", "", Sheet1!AL12/$H$91)
C105: 9 | D105: 비업무용자산 | E105: 영업이익 | F105: 외환거래이익(현금흐름표) | G105: 기말기타자본 | H105: 순이익증가율 | J105: =IF(INDEX($D$97:$H$135,$C105,$B$96)=0,"",INDEX($D$97:$H$135,$C105,$B$96)) -> 비업무용자산 | K105: =IF(Sheet1!D13="", "", Sheet1!D13/$H$91) | L105: =IF(Sheet1!E13="", "", Sheet1!E13/$H$91) | M105: =IF(Sheet1!F13="", "", Sheet1!F13/$H$91) | N105: =IF(Sheet1!G13="", "", Sheet1!G13/$H$91) | O105: =IF(Sheet1!H13="", "", Sheet1!H13/$H$91) | P105: =IF(Sheet1!I13="", "", Sheet1!I13/$H$91) | Q105: =IF(Sheet1!J13="", "", Sheet1!J13/$H$91) | R105: =IF(Sheet1!K13="", "", Sheet1!K13/$H$91) | ... AS105: =IF(Sheet1!AL13="", "", Sheet1!AL13/$H$91)
C106: 10 | D106: 영업권 | E106: 이자수익 | F106: 자산처분이익 | G106: 기말기타포괄손익누계액 | H106: EPS증가율 | J106: =IF(INDEX($D$97:$H$135,$C106,$B$96)=0,"",INDEX($D$97:$H$135,$C106,$B$96)) -> 영업권 | K106: =IF(Sheet1!D14="", "", Sheet1!D14/$H$91) | L106: =IF(Sheet1!E14="", "", Sheet1!E14/$H$91) | M106: =IF(Sheet1!F14="", "", Sheet1!F14/$H$91) | N106: =IF(Sheet1!G14="", "", Sheet1!G14/$H$91) -> 60144.22 | O106: =IF(Sheet1!H14="", "", Sheet1!H14/$H$91) | P106: =IF(Sheet1!I14="", "", Sheet1!I14/$H$91) | Q106: =IF(Sheet1!J14="", "", Sheet1!J14/$H$91) | R106: =IF(Sheet1!K14="", "", Sheet1!K14/$H$91) -> 58442.59 | ... AS106: =IF(Sheet1!AL14="", "", Sheet1!AL14/$H$91)
C107: 11 | D107: 무형자산 | E107: 배당금수익 | F107: 영업활동으로인한자산부채변동 | G107: 기말이익잉여금 | H107: 희석EPS증가율 | J107: =IF(INDEX($D$97:$H$135,$C107,$B$96)=0,"",INDEX($D$97:$H$135,$C107,$B$96)) -> 무형자산 | K107: =IF(Sheet1!D15="", "", Sheet1!D15/$H$91) -> 231370 | L107: =IF(Sheet1!E15="", "", Sheet1!E15/$H$91) -> 234302.34 | M107: =IF(Sheet1!F15="", "", Sheet1!F15/$H$91) -> 236177.03 | N107: =IF(Sheet1!G15="", "", Sheet1!G15/$H$91) -> 142033.32 | O107: =IF(Sheet1!H15="", "", Sheet1!H15/$H$91) -> 214848.57 | P107: =IF(Sheet1!I15="", "", Sheet1!I15/$H$91) -> 200969.26 | Q107: =IF(Sheet1!J15="", "", Sheet1!J15/$H$91) -> 200106.94 | R107: =IF(Sheet1!K15="", "", Sheet1!K15/$H$91) -> 143919.85 | ... AS107: =IF(Sheet1!AL15="", "", Sheet1!AL15/$H$91)
C108: 12 | D108: 이연법인세자산 | E108: 외환거래이익(포괄손익계산서) | F108: 자산의감소 | G108: 처분후이익잉여금 | H108: 영업활동으로인한현금흐름증가율 | J108: =IF(INDEX($D$97:$H$135,$C108,$B$96)=0,"",INDEX($D$97:$H$135,$C108,$B$96)) -> 이연법인세자산 | K108: =IF(Sheet1!D16="", "", Sheet1!D16/$H$91) -> 65354.42 | L108: =IF(Sheet1!E16="", "", Sheet1!E16/$H$91) -> 55273.77 | M108: =IF(Sheet1!F16="", "", Sheet1!F16/$H$91) -> 51034.74 | N108: =IF(Sheet1!G16="", "", Sheet1!G16/$H$91) -> 51013.18 | O108: =IF(Sheet1!H16="", "", Sheet1!H16/$H$91) -> 54881.63 | P108: =IF(Sheet1!I16="", "", Sheet1!I16/$H$91) -> 51143.32 | Q108: =IF(Sheet1!J16="", "", Sheet1!J16/$H$91) -> 41789.84 | R108: =IF(Sheet1!K16="", "", Sheet1!K16/$H$91) -> 42612.14 | ... AS108: =IF(Sheet1!AL16="", "", Sheet1!AL16/$H$91)
C109: 13 | D109: 당기법인세자산 | E109: 금융자산처분이익 | F109: 부채의증가 | G109: (중간배당) | H109: 투자활동으로인한현금흐름증가율 | J109: =IF(INDEX($D$97:$H$135,$C109,$B$96)=0,"",INDEX($D$97:$H$135,$C109,$B$96)) -> 당기법인세자산 | K109: =IF(Sheet1!D17="", "", Sheet1!D17/$H$91) | L109: =IF(Sheet1!E17="", "", Sheet1!E17/$H$91) | M109: =IF(Sheet1!F17="", "", Sheet1!F17/$H$91) | N109: =IF(Sheet1!G17="", "", Sheet1!G17/$H$91) | O109: =IF(Sheet1!H17="", "", Sheet1!H17/$H$91) | P109: =IF(Sheet1!I17="", "", Sheet1!I17/$H$91) | Q109: =IF(Sheet1!J17="", "", Sheet1!J17/$H$91) | R109: =IF(Sheet1!K17="", "", Sheet1!K17/$H$91) | ... AS109: =IF(Sheet1!AL17="", "", Sheet1!AL17/$H$91)
C110: 14 | D110: 기타금융업자산 | E110: 금융자산평가이익 | F110: 영업활동으로인한현금흐름(간접법) | G110: 기타포괄손익(자본변동표) | H110: 재무활동으로인한현금흐름증가율 | J110: =IF(INDEX($D$97:$H$135,$C110,$B$96)=0,"",INDEX($D$97:$H$135,$C110,$B$96)) -> 기타금융업자산 | K110: =IF(Sheet1!D18="", "", Sheet1!D18/$H$91) | L110: =IF(Sheet1!E18="", "", Sheet1!E18/$H$91) | M110: =IF(Sheet1!F18="", "", Sheet1!F18/$H$91) | N110: =IF(Sheet1!G18="", "", Sheet1!G18/$H$91) | O110: =IF(Sheet1!H18="", "", Sheet1!H18/$H$91) | P110: =IF(Sheet1!I18="", "", Sheet1!I18/$H$91) | Q110: =IF(Sheet1!J18="", "", Sheet1!J18/$H$91) | R110: =IF(Sheet1!K18="", "", Sheet1!K18/$H$91) | ... AS110: =IF(Sheet1!AL18="", "", Sheet1!AL18/$H$91)
C111: 15 | D111: 자본 | E111: 파생상품이익 | F111: 영업에서창출된현금흐름 | G111: 당기순이익(자본변동표) | H111: 기말현금증가율 | J111: =IF(INDEX($D$97:$H$135,$C111,$B$96)=0,"",INDEX($D$97:$H$135,$C111,$B$96)) -> 자본 | K111: =IF(Sheet1!D19="", "", Sheet1!D19/$H$91) -> 3638926.4 | L111: =IF(Sheet1!E19="", "", Sheet1!E19/$H$91) -> 3589756.3 | M111: =IF(Sheet1!F19="", "", Sheet1!F19/$H$91) -> 3597994.2 | N111: =IF(Sheet1!G19="", "", Sheet1!G19/$H$91) -> 3547496 | O111: =IF(Sheet1!H19="", "", Sheet1!H19/$H$91) -> 3449068.9 | P111: =IF(Sheet1!I19="", "", Sheet1!I19/$H$91) -> 3279066.6 | Q111: =IF(Sheet1!J19="", "", Sheet1!J19/$H$91) -> 3152909.2 | R111: =IF(Sheet1!K19="", "", Sheet1!K19/$H$91) -> 3048999.3 | ... AS111: =IF(Sheet1!AL19="", "", Sheet1!AL19/$H$91)
C112: 16 | D112: 상장자본금 | E112: 이자비용 | F112: 이자수입 | G112: 기말비지배주주지분 | H112: ROE | J112: =IF(INDEX($D$97:$H$135,$C112,$B$96)=0,"",INDEX($D$97:$H$135,$C112,$B$96)) -> 상장자본금 | K112: =IF(Sheet1!D20="", "", Sheet1!D20/$H$91) -> 8975.14 | L112: =IF(Sheet1!E20="", "", Sheet1!E20/$H$91) -> 8975.14 | M112: =IF(Sheet1!F20="", "", Sheet1!F20/$H$91) -> 8975.14 | N112: =IF(Sheet1!G20="", "", Sheet1!G20/$H$91) -> 8975.14 | O112: =IF(Sheet1!H20="", "", Sheet1!H20/$H$91) -> 8975.14 | P112: =IF(Sheet1!I20="", "", Sheet1!I20/$H$91) -> 8975.14 | Q112: =IF(Sheet1!J20="", "", Sheet1!J20/$H$91) -> 8975.14 | R112: =IF(Sheet1!K20="", "", Sheet1!K20/$H$91) -> 8975.14 | ... AS112: =IF(Sheet1!AL20="", "", Sheet1!AL20/$H$91)
C113: 17 | D113: 신종자본증권 | E113: 외환거래손실(포괄손익계산서) | F113: 이자지급(-) | G113: 합계(자본변동표) | H113: ROA | J113: =IF(INDEX($D$97:$H$135,$C113,$B$96)=0,"",INDEX($D$97:$H$135,$C113,$B$96)) -> 신종자본증권 | K113: =IF(Sheet1!D21="", "", Sheet1!D21/$H$91) | L113: =IF(Sheet1!E21="", "", Sheet1!E21/$H$91) | M113: =IF(Sheet1!F21="", "", Sheet1!F21/$H$91) | N113: =IF(Sheet1!G21="", "", Sheet1!G21/$H$91) | O113: =IF(Sheet1!H21="", "", Sheet1!H21/$H$91) | P113: =IF(Sheet1!I21="", "", Sheet1!I21/$H$91) | Q113: =IF(Sheet1!J21="", "", Sheet1!J21/$H$91) | R113: =IF(Sheet1!K21="", "", Sheet1!K21/$H$91) | ... AS113: =IF(Sheet1!AL21="", "", Sheet1!AL21/$H$91)
C114: 18 | D114: 자본잉여금 | E114: 금융자산처분손실 | F114: 배당금수입 | H114: 총자산영업이익률 | J114: =IF(INDEX($D$97:$H$135,$C114,$B$96)=0,"",INDEX($D$97:$H$135,$C114,$B$96)) -> 자본잉여금 | K114: =IF(Sheet1!D22="", "", Sheet1!D22/$H$91) -> 44038.93 | L114: =IF(Sheet1!E22="", "", Sheet1!E22/$H$91) -> 44038.93 | M114: =IF(Sheet1!F22="", "", Sheet1!F22/$H$91) -> 44038.93 | N114: =IF(Sheet1!G22="", "", Sheet1!G22/$H$91) -> 44038.93 | O114: =IF(Sheet1!H22="", "", Sheet1!H22/$H$91) -> 44038.93 | P114: =IF(Sheet1!I22="", "", Sheet1!I22/$H$91) -> 44038.93 | Q114: =IF(Sheet1!J22="", "", Sheet1!J22/$H$91) -> 44038.93 | R114: =IF(Sheet1!K22="", "", Sheet1!K22/$H$91) -> 44038.93 | ... AS114: =IF(Sheet1!AL22="", "", Sheet1!AL22/$H$91)
C115: 19 | D115: 기타자본 | E115: 금융자산평가손실 | F115: 영업활동배당금지급(-) | H115: 자기자본영업이익률 | J115: =IF(INDEX($D$97:$H$135,$C115,$B$96)=0,"",INDEX($D$97:$H$135,$C115,$B$96)) -> 기타자본 | K115: =IF(Sheet1!D23="", "", Sheet1!D23/$H$91) -> 860.67 | L115: =IF(Sheet1!E23="", "", Sheet1!E23/$H$91) -> 994.52 | M115: =IF(Sheet1!F23="", "", Sheet1!F23/$H$91) -> 947.53 | N115: =IF(Sheet1!G23="", "", Sheet1!G23/$H$91) -> 866.45 | O115: =IF(Sheet1!H23="", "", Sheet1!H23/$H$91) -> 876.49 | P115: =IF(Sheet1!I23="", "", Sheet1!I23/$H$91) -> 946.72 | Q115: =IF(Sheet1!J23="", "", Sheet1!J23/$H$91) -> 931.05 | R115: =IF(Sheet1!K23="", "", Sheet1!K23/$H$91) -> 867.63 | ... AS115: =IF(Sheet1!AL23="", "", Sheet1!AL23/$H$91)
C116: 20 | D116: 기타포괄손익누계액 | E116: 파생상품손실 | F116: 법인세환입 | H116: 자본금영업이익률 | J116: =IF(INDEX($D$97:$H$135,$C116,$B$96)=0,"",INDEX($D$97:$H$135,$C116,$B$96)) -> 기타포괄손익누계액 | K116: =IF(Sheet1!D24="", "", Sheet1!D24/$H$91) -> 61672.93 | L116: =IF(Sheet1!E24="", "", Sheet1!E24/$H$91) -> 53308.99 | M116: =IF(Sheet1!F24="", "", Sheet1!F24/$H$91) -> 77419.16 | N116: =IF(Sheet1!G24="", "", Sheet1!G24/$H$91) -> 18516.83 | O116: =IF(Sheet1!H24="", "", Sheet1!H24/$H$91) -> 131908.48 | P116: =IF(Sheet1!I24="", "", Sheet1!I24/$H$91) -> 32177.48 | Q116: =IF(Sheet1!J24="", "", Sheet1!J24/$H$91) -> -7457.94 | R116: =IF(Sheet1!K24="", "", Sheet1!K24/$H$91) -> -22152.36 | ... AS116: =IF(Sheet1!AL24="", "", Sheet1!AL24/$H$91)
C117: 21 | D117: 이익잉여금(결손금) | E117: 종속기업공동지배기업관계기업손익 | F117: 법인세납부(-) | H117: 자본금순이익률 | J117: =IF(INDEX($D$97:$H$135,$C117,$B$96)=0,"",INDEX($D$97:$H$135,$C117,$B$96)) -> 이익잉여금(결손금) | K117: =IF(Sheet1!D25="", "", Sheet1!D25/$H$91) -> 3421254.2 | L117: =IF(Sheet1!E25="", "", Sheet1!E25/$H$91) -> 3383106.5 | M117: =IF(Sheet1!F25="", "", Sheet1!F25/$H$91) -> 3368818.5 | N117: =IF(Sheet1!G25="", "", Sheet1!G25/$H$91) -> 3379464.1 | O117: =IF(Sheet1!H25="", "", Sheet1!H25/$H$91) -> 3168902.7 | P117: =IF(Sheet1!I25="", "", Sheet1!I25/$H$91) -> 3102167.9 | Q117: =IF(Sheet1!J25="", "", Sheet1!J25/$H$91) -> 3017431.5 | R117: =IF(Sheet1!K25="", "", Sheet1!K25/$H$91) -> 2930647.6 | ... AS117: =IF(Sheet1!AL25="", "", Sheet1!AL25/$H$91)
C118: 22 | D118: 부채 | E118: 법인세비용차감전순이익 | F118: 투자활동으로인한현금흐름 | H118: 영업이익률 | J118: =IF(INDEX($D$97:$H$135,$C118,$B$96)=0,"",INDEX($D$97:$H$135,$C118,$B$96)) -> 부채 | K118: =IF(Sheet1!D26="", "", Sheet1!D26/$H$91) -> 905738.04 | L118: =IF(Sheet1!E26="", "", Sheet1!E26/$H$91) -> 890249.26 | M118: =IF(Sheet1!F26="", "", Sheet1!F26/$H$91) -> 942923.61 | N118: =IF(Sheet1!G26="", "", Sheet1!G26/$H$91) -> 936749.03 | O118: =IF(Sheet1!H26="", "", Sheet1!H26/$H$91) -> 1253715.2 | P118: =IF(Sheet1!I26="", "", Sheet1!I26/$H$91) -> 1201339.9 | Q118: =IF(Sheet1!J26="", "", Sheet1!J26/$H$91) -> 1240360.4 | R118: =IF(Sheet1!K26="", "", Sheet1!K26/$H$91) -> 1217212.3 | ... AS118: =IF(Sheet1!AL26="", "", Sheet1!AL26/$H$91)
C119: 23 | D119: 비예수부채 | E119: 법인세비용 | F119: 투자활동으로인한현금유입액 | H119: 적립금비율 | J119: =IF(INDEX($D$97:$H$135,$C119,$B$96)=0,"",INDEX($D$97:$H$135,$C119,$B$96)) -> 비예수부채 | K119: =IF(Sheet1!D27="", "", Sheet1!D27/$H$91) -> 15488.78 | L119: =IF(Sheet1!E27="", "", Sheet1!E27/$H$91) -> -52674.35 | M119: =IF(Sheet1!F27="", "", Sheet1!F27/$H$91) -> 6174.58 | N119: =IF(Sheet1!G27="", "", Sheet1!G27/$H$91) -> -52674.35 | O119: =IF(Sheet1!H27="", "", Sheet1!H27/$H$91) -> 15488.78 | P119: =IF(Sheet1!I27="", "", Sheet1!I27/$H$91) -> -52674.35 | Q119: =IF(Sheet1!J27="", "", Sheet1!J27/$H$91) -> 6174.58 | R119: =IF(Sheet1!K27="", "", Sheet1!K27/$H$91) -> -52674.35 | ... AS119: =IF(Sheet1!AL27="", "", Sheet1!AL27/$H$91)
C120: 24 | D120: 금융부채 | E120: 계속영업이익 | F120: 유형자산의감소 | H120: 유형자산구성비율 | J120: =IF(INDEX($D$97:$H$135,$C120,$B$96)=0,"",INDEX($D$97:$H$135,$C120,$B$96)) -> 금융부채 | K120: =IF(Sheet1!D28="", "", Sheet1!D28/$H$91) -> 38305.07 | L120: =IF(Sheet1!E28="", "", Sheet1!E28/$H$91) -> 46941.77 | M120: =IF(Sheet1!F28="", "", Sheet1!F28/$H$91) -> 36925.95 | N120: =IF(Sheet1!G28="", "", Sheet1!G28/$H$91) -> 35268.26 | O120: =IF(Sheet1!H28="", "", Sheet1!H28/$H$91) -> 31674.48 | P120: =IF(Sheet1!I28="", "", Sheet1!I28/$H$91) -> 29347.08 | Q120: =IF(Sheet1!J28="", "", Sheet1!J28/$H$91) -> 27782.07 | R120: =IF(Sheet1!K28="", "", Sheet1!K28/$H$91) -> 28646.56 | ... AS120: =IF(Sheet1!AL28="", "", Sheet1!AL28/$H$91)
C121: 25 | D121: 파생상품부채 | E121: 당기순이익(포괄손익계산서) | F121: 무형자산의감소 | H121: 타인자본구성비율 | J121: =IF(INDEX($D$97:$H$135,$C121,$B$96)=0,"",INDEX($D$97:$H$135,$C121,$B$96)) -> 파생상품부채 | K121: =IF(Sheet1!D29="", "", Sheet1!D29/$H$91) | L121: =IF(Sheet1!E29="", "", Sheet1!E29/$H$91) | M121: =IF(Sheet1!F29="", "", Sheet1!F29/$H$91) | N121: =IF(Sheet1!G29="", "", Sheet1!G29/$H$91) | O121: =IF(Sheet1!H29="", "", Sheet1!H29/$H$91) | P121: =IF(Sheet1!I29="", "", Sheet1!I29/$H$91) | Q121: =IF(Sheet1!J29="", "", Sheet1!J29/$H$91) | R121: =IF(Sheet1!K29="", "", Sheet1!K29/$H$91) | ... AS121: =IF(Sheet1!AL29="", "", Sheet1!AL29/$H$91)
C122: 26 | D122: 차입금 | E122: 당기순이익지배기업주주지분 | F122: (투자활동으로인한현금유출액) | H122: 자기자본비율 | J122: =IF(INDEX($D$97:$H$135,$C122,$B$96)=0,"",INDEX($D$97:$H$135,$C122,$B$96)) -> 차입금 | K122: =IF(Sheet1!D30="", "", Sheet1!D30/$H$91) -> 43765.79 | L122: =IF(Sheet1!E30="", "", Sheet1!E30/$H$91) -> 35911.16 | M122: =IF(Sheet1!F30="", "", Sheet1!F30/$H$91) -> 45006.89 | N122: =IF(Sheet1!G30="", "", Sheet1!G30/$H$91) -> 51811.61 | O122: =IF(Sheet1!H30="", "", Sheet1!H30/$H$91) -> 76246.43 | P122: =IF(Sheet1!I30="", "", Sheet1!I30/$H$91) -> 129976.88 | Q122: =IF(Sheet1!J30="", "", Sheet1!J30/$H$91) -> 138883.89 | R122: =IF(Sheet1!K30="", "", Sheet1!K30/$H$91) -> 136892.93 | ... AS122: =IF(Sheet1!AL30="", "", Sheet1!AL30/$H$91)
C123: 27 | D123: 사채 | E123: 기타포괄손익(포괄손익계산서) | F123: 유형자산의증가 | H123: 차입금비율 | J123: =IF(INDEX($D$97:$H$135,$C123,$B$96)=0,"",INDEX($D$97:$H$135,$C123,$B$96)) -> 사채 | K123: =IF(Sheet1!D31="", "", Sheet1!D31/$H$91) -> 5648.16 | L123: =IF(Sheet1!E31="", "", Sheet1!E31/$H$91) -> 5546.25 | M123: =IF(Sheet1!F31="", "", Sheet1!F31/$H$91) -> 5511.72 | N123: =IF(Sheet1!G31="", "", Sheet1!G31/$H$91) -> 5360.93 | O123: =IF(Sheet1!H31="", "", Sheet1!H31/$H$91) -> 6097.9 | P123: =IF(Sheet1!I31="", "", Sheet1!I31/$H$91) -> 5537.83 | Q123: =IF(Sheet1!J31="", "", Sheet1!J31/$H$91) -> 5188.56 | R123: =IF(Sheet1!K31="", "", Sheet1!K31/$H$91) -> 5082.32 | ... AS123: =IF(Sheet1!AL31="", "", Sheet1!AL31/$H$91)
C124: 28 | D124: 기타금융업부채 | E124: 총포괄손익 | F124: 무형자산의증가 | H124: 차입금의존도 | J124: =IF(INDEX($D$97:$H$135,$C124,$B$96)=0,"",INDEX($D$97:$H$135,$C124,$B$96)) -> 기타금융업부채 | K124: =IF(Sheet1!D32="", "", Sheet1!D32/$H$91) | L124: =IF(Sheet1!E32="", "", Sheet1!E32/$H$91) | M124: =IF(Sheet1!F32="", "", Sheet1!F32/$H$91) | N124: =IF(Sheet1!G32="", "", Sheet1!G32/$H$91) | O124: =IF(Sheet1!H32="", "", Sheet1!H32/$H$91) | P124: =IF(Sheet1!I32="", "", Sheet1!I32/$H$91) | Q124: =IF(Sheet1!J32="", "", Sheet1!J32/$H$91) | R124: =IF(Sheet1!K32="", "", Sheet1!K32/$H$91) | ... AS124: =IF(Sheet1!AL32="", "", Sheet1!AL32/$H$91)
C125: 29 | D125: 기타충당부채 | E125: 총포괄손익지배기업주주지분 | F125: 재무활동으로인한현금흐름 | H125: 유보율 | J125: =IF(INDEX($D$97:$H$135,$C125,$B$96)=0,"",INDEX($D$97:$H$135,$C125,$B$96)) -> 기타충당부채 | K125: =IF(Sheet1!D33="", "", Sheet1!D33/$H$91) -> 97487.63 | L125: =IF(Sheet1!E33="", "", Sheet1!E33/$H$91) -> 91330.21 | M125: =IF(Sheet1!F33="", "", Sheet1!F33/$H$91) -> 91922.9 | N125: =IF(Sheet1!G33="", "", Sheet1!G33/$H$91) -> 77734.25 | O125: =IF(Sheet1!H33="", "", Sheet1!H33/$H$91) -> 83331.36 | P125: =IF(Sheet1!I33="", "", Sheet1!I33/$H$91) -> 82740.21 | Q125: =IF(Sheet1!J33="", "", Sheet1!J33/$H$91) -> 81604.27 | R125: =IF(Sheet1!K33="", "", Sheet1!K33/$H$91) -> 76798.66 | ... AS125: =IF(Sheet1!AL33="", "", Sheet1!AL33/$H$91)
...

Sheet Sheet1
A1: =_xll.IMDH("STK",재무비율!$N$5,재무비율!$J$96:$J$135,재무비율!$L$92,TODAY(),9999,"Per=분기,sort=D,real=true,Bizday=0,Quote=종가,Pos=33,Orient=H,Cons="&재무비율!$P$5&",Comp="&재무비율!$M$92&",Trai="&재무비율!$N$92&",DtFmt=1,TmFmt=1,unit=true,title="&재무비율!$N$5&"") -> 005930
D4: 45199 | E4: 45107 | F4: 45016 | G4: 44926 | H4: 44834 | I4: 44742 | J4: 44651 | K4: 44561 | L4: 44469
D5: 454466447000 | E5: 448000552000 | F5: 454091777000 | G5: 448424507000 | H5: 470278409000 | I5: 448040650000 | J5: 439326959000 | K5: 426621158000 | L5: 410420718000
D6: 75144284000 | E6: 79919775000 | F6: 72949377000 | G6: 49680710000 | H6: 44515421000 | I6: 39583141000 | J6: 48944982000 | K6: 39031415000 | L6: 32675040000
D7: 17927266000 | E7: 17180130000 | F7: 35200184000 | G7: 65102886000 | H7: 83646807000 | I7: 84428822000 | J7: 75121426000 | K7: 81708986000 | L7: 85077401000
D10: 23858434000 | E10: 23399791000 | F10: 22684343000 | G10: 21049300000 | H10: 19792757000 | I10: 18069477000 | J10: 18397154000 | K10: 15798606000 | L10: 14388455000
D11: 180805963000 | E11: 177869942000 | F11: 171857516000 | G11: 168045388000 | H11: 160343568000 | I11: 154254576000 | J11: 149618019000 | K11: 149928539000 | L11: 143029384000
G14: 6014422000 | K14: 5844259000
D15: 23137000000 | E15: 23430234000 | F15: 23617703000 | G15: 14203332000 | H15: 21484857000 | I15: 20096926000 | J15: 20010694000 | K15: 14391985000 | L15: 20753637000
D16: 6535442000 | E16: 5527377000 | F16: 5103474000 | G16: 5101318000 | H16: 5488163000 | I16: 5114332000 | J16: 4178984000 | K16: 4261214000 | L16: 3928050000
D19: 363892643000 | E19: 358975626000 | F19: 359799416000 | G19: 354749604000 | H19: 344906889000 | I19: 327906664000 | J19: 315290919000 | K19: 304899931000 | L19: 296766118000
D20: 897514000 | E20: 897514000 | F20: 897514000 | G20: 897514000 | H20: 897514000 | I20: 897514000 | J20: 897514000 | K20: 897514000 | L20: 897514000
D22: 4403893000 | E22: 4403893000 | F22: 4403893000 | G22: 4403893000 | H22: 4403893000 | I22: 4403893000 | J22: 4403893000 | K22: 4403893000 | L22: 4403893000
D23: 86067000 | E23: 99452000 | F23: 94753000 | G23: 86645000 | H23: 87649000 | I23: 94672000 | J23: 93105000 | K23: 86763000 | L23: 68543000
D24: 6167293000 | E24: 5330899000 | F24: 7741916000 | G24: 1851683000 | H24: 13190848000 | I24: 3217748000 | J24: -745794000 | K24: -2215236000 | L24: -1865734000
D25: 342125419000 | E25: 338310655000 | F25: 336881852000 | G25: 337946407000 | H25: 316890272000 | I25: 310216785000 | J25: 301743152000 | K25: 293064763000 | L25: 284826992000
D26: 90573804000 | E26: 89024926000 | F26: 94292361000 | G26: 93674903000 | H26: 125371520000 | I26: 120133986000 | J26: 124036040000 | K26: 121721227000 | L26: 113654600000
D27: 1548878000 | E27: -5267435000 | F27: 617458000 | G27: -5267435000 | H27: 1548878000 | I27: -5267435000 | J27: 617458000 | K27: -5267435000 | L27: -5267435000
D28: 3830507000 | E28: 4694177000 | F28: 3692595000 | G28: 3526826000 | H28: 3167448000 | I28: 2934708000 | J28: 2778207000 | K28: 2864656000 | L28: 2166741000
D30: 4376579000 | E30: 3591116000 | F30: 4500689000 | G30: 5181161000 | H30: 7624643000 | I30: 12997688000 | J30: 13888389000 | K30: 13689293000 | L30: 17283881000
... D38: -2414751000 | E38: -1149340000 | F38: -476640000 | G38: -1149340000 | H38: -2414751000 | I38: -1149340000 | J38: -476640000 | K38: -1149340000 | L38: -1149340000
