Workbook

Sheet 재무상태표
B2: 종목코드 | C2: 000660 | E2: 시작일 | F2: =TODAY()-3650 -> 39970 | H2: 연결기준 | I2: 연결 | K2: 연결 | L2: 누적 | M2: 연속
B3: 종목명 | C3: =_xll.IMDP("STK",$C$2,"한글종목명") -> SK하이닉스 | E3: 종료일 | F3: =EOMONTH(TODAY(),-1) -> 43616 | H3: 누적기준 | I3: 누적 | K3: 개별 | L3: 순 | M3: 1
H4: 분기 | I4: 연속 | M4: 2
M5: 3
B6: =_xll.IMDH("STK",$C$2,B7:B41,$F$2,$F$3,9999,"Per=일,sort=D,real=true,Bizday=0,Quote=종가,Pos=11,Orient=H,Cons="&$I$2&",Comp="&$I$3&",Trai="&I4&",Title="&$C$3&",DtFmt=1,TmFmt=1,unit=true") -> SK하이닉스 | M6: 4
B7: 일자 | C7: 43555 | D7: 43465 | E7: 43373 | F7: 43281 | G7: 43190 | H7: 43100 | I7: 43008 | J7: 42916 | K7: 42825 | L7: 42735 | M7: 42643 | N7: 42551 | O7: 42460 | P7: 42369 | Q7: 42277 | R7: 42185 | S7: 42094 | T7: 42004 | U7: 41912 | V7: 41820 | W7: 41729 | X7: 41639 | Y7: 41547 | Z7: 41455 | AA7: 41364 | AB7: 41274 | AC7: 41182 | AD7: 41090 | AE7: 40999 | AF7: 40908 | AG7: 40816 | AH7: 40724 | AI7: 40633 | AJ7: 40543 | AK7: 40178
B8: 자산 | C8: 65131501000 | D8: 63658335000 | E8: 57377252000 | F8: 53257080000 | G8: 49125123000 | H8: 45418464000 | I8: 40730453000 | J8: 37501577000 | K8: 34319500000 | L8: 32216026000 | M8: 29166995000 | N8: 29329452000 | O8: 29797655000 | P8: 29677906000 | Q8: 29342140000 | R8: 28463705000 | S8: 27392913000 | T8: 26883278000 | U8: 24081215000 | V8: 22556707000 | W8: 22065739000 | X8: 20797298000 | Y8: 20537290000 | Z8: 20275395000 | AA8: 19058214000 | AB8: 18648693000 | AC8: 19221984000 | AD8: 19835172000 | AE8: 19264360000 | AF8: 17238148000 | AG8: 18041596000 | AH8: 17515937000 | AI8: 17376877000 | AJ8: 17412117000 | AK8: 16303533398
B9: 현금및현금성자산 | C9: 1152257000 | D9: 2349319000 | E9: 2340357000 | F9: 1187928000 | G9: 3477358000 | H9: 2949991000 | I9: 1123119000 | J9: 1326003000 | K9: 2162786000 | L9: 613786000 | M9: 1214703000 | N9: 987448000 | O9: 946946000 | P9: 1175719000 | Q9: 510632000 | R9: 650081000 | S9: 342269000 | T9: 436761000 | U9: 377645000 | V9: 591243000 | W9: 319961000 | X9: 631867000 | Y9: 600784000 | Z9: 504748000 | AA9: 741111000 | AB9: 658387000 | AC9: 605655000 | AD9: 1719419000 | AE9: 2691104000 | AF9: 1243788000 | AG9: 1407276000 | AH9: 747956000 | AI9: 1416033000 | AJ9: 1253226000 | AK9: 1209110638
B10: 금융자산 | C10: 1004681000 | D10: 556787000 | E10: 7370835000 | F10: 7311680000 | G10: 4859383000 | H10: 5662146000 | I10: 5260235000 | J10: 3962952000 | K10: 2867025000 | L10: 3679248000 | M10: 2530612000 | N10: 2596811000 | O10: 3457593000 | P10: 3757228000 | Q10: 3736305000 | R10: 3695968000 | S10: 4043550000 | T10: 3756354000 | U10: 3487021000 | V10: 2693737000 | W10: 3021128000 | X10: 2570451000 | Y10: 2552837000 | Z10: 2005280000 | AA10: 1280850000 | AB10: 1179504000 | AC10: 1252349000 | AD10: 1332527000 | AE10: 780419000 | AF10: 693851000 | AG10: 641256000 | AH10: 1093167000 | AI10: 750659000 | AJ10: 1020382000 | AK10: 342552198
B11: 파생상품자산 | W11: 157000 | X11: 272000 | Z11: 300000 | AB11: 198000 | AD11: 487000 | AF11: 3114000 | AG11: 603000 | AH11: 4953000 | AI11: 7914000 | AJ11: 7695000
B12: 대출채권
B13: 기타자산 | C13: 2480415000 | D13: 1347949000 | E13: 1279524000 | F13: 1251006000 | G13: 1392787000 | H13: 1273743000 | I13: 1087742000 | J13: 1007978000 | K13: 973803000 | L13: 969755000 | M13: 844257000 | N13: 960537000 | O13: 945906000 | P13: 919459000 | Q13: 822660000 | R13: 813782000 | S13: 856173000 | T13: 865907000 | U13: 536166000 | V13: 552994000 | W13: 555436000 | X13: 507205000 | Y13: 433516000 | Z13: 293513000 | AA13: 316027000 | AB13: 324368000 | AC13: 387301000 | AD13: 324005000 | AE13: 354418000 | AF13: 249164000 | AG13: 303432000 | AH13: 280464000 | AI13: 242727000 | AJ13: 226479000 | AK13: 571473670
B14: 유형자산 | C14: 36385101000 | D14: 34952617000 | E14: 31259492000 | F14: 29311297000 | G14: 27364769000 | H14: 24062601000 | I14: 21977158000 | J14: 21395285000 | K14: 19856004000 | L14: 18777402000 | M14: 17888583000 | N14: 17936788000 | O14: 17666499000 | P14: 16966252000 | Q14: 16819082000 | R14: 16084135000 | S14: 15147835000 | T14: 14090334000 | U14: 13536397000 | V14: 13262740000 | W14: 12854615000 | X14: 12129797000 | Y14: 11950509000 | Z14: 11899593000 | AA14: 11598526000 | AB14: 11586192000 | AC14: 12112035000 | AD14: 12008981000 | AE14: 11224263000 | AF14: 10899308000 | AG14: 11163051000 | AH14: 10872414000 | AI14: 10623721000 | AJ14: 10590580000 | AK14: 10143005769
B15: 투자부동산 | C15: 1384000 | D15: 1400000 | E15: 1416000 | F15: 2415000 | G15: 2442000 | H15: 2468000 | I15: 2494000 | J15: 2521000 | K15: 2547000 | L15: 2573000 | M15: 2600000 | N15: 2626000 | O15: 2653000 | P15: 2679000 | Q15: 2705000 | R15: 27795000 | S15: 28126000 | T15: 28456000 | U15: 26295000 | V15: 26602000 | W15: 26909000 | X15: 28609000 | Y15: 28929000 | Z15: 29249000 | AA15: 29568000 | AB15: 29888000 | AC15: 30208000 | AD15: 30528000 | AE15: 30848000 | AF15: 31168000 | AG15: 36116000 | AH15: 36445000 | AI15: 36858000 | AJ15: 37186000 | AK15: 162415720
B16: 비업무용자산 | C16: -16000 | D16: -16000 | E16: -999000 | F16: -27000 | G16: -16000 | H16: -16000 | I16: -27000 | J16: -27000 | K16: -26000 | L16: -26000 | M16: -27000 | N16: -26000 | O16: -26000 | P16: -27000 | Q16: -27000 | R16: -27000 | S16: -27000
B17: 영업권 | D17: 709811000 | H17: 695073000 | L17: 730204000 | P17: 720755000 | T17: 704185000 | X17: 632311000 | AB17: 633170000 | AF17: 386450000 | AG17: 386450000 | AH17: 386450000 | AI17: 386450000 | AJ17: 386450000 | AK17: 2083467423
B18: 무형자산 | C18: 2611595000 | D18: 1968959000 | E18: 2469187000 | F18: 2408291000 | G18: 2304852000 | H18: 1552217000 | I18: 2236944000 | J18: 2162731000 | K18: 2002619000 | L18: 1185387000 | M18: 1805666000 | N18: 1760564000 | O18: 1735514000 | P18: 984141000 | Q18: 1618504000 | R18: 1519467000 | S18: 1401266000 | T18: 632495000 | U18: 1255777000 | V18: 1205087000 | W18: 1124984000 | X18: 478092000 | Y18: 1055582000 | Z18: 1051617000 | AA18: 1017329000 | AB18: 350460000 | AC18: 999169000 | AD18: 712028000 | AE18: 702410000 | AF18: 321198000 | AG18: 321640000 | AH18: 289966000 | AI18: 242898000 | AJ18: 217203000 | AK18: 75507773
B19: 이연법인세자산 | C19: 552484000 | D19: 544016000 | E19: 637326000 | F19: 638571000 | G19: 610667000 | H19: 599783000 | I19: 781408000 | J19: 777879000 | K19: 773398000 | L19: 792368000 | M19: 385394000 | N19: 397852000 | O19: 359385000 | P19: 361204000 | Q19: 305156000 | R19: 291223000 | S19: 279923000 | T19: 272102000 | U19: 223738000 | V19: 210797000 | W19: 203016000 | X19: 198570000 | Y19: 227747000 | Z19: 302011000 | AA19: 360312000 | AB19: 378366000 | AC19: 315355000 | AD19: 317072000 | AE19: 316970000 | AF19: 315718000 | AG19: 446909000 | AH19: 439140000 | AI19: 441544000 | AJ19: 388773000 | AK19: 258837717
B20: 당기법인세자산 | C20: 8926000 | D20: 22252000 | E20: 1663000 | F20: 515000 | G20: 421000 | H20: 1305000 | I20: 1665000 | J20: 885000 | K20: 611000 | L20: 489000 | M20: 1015000 | N20: 536000 | O20: 361000 | P20: 1394000 | Q20: 1717000 | R20: 1453000 | S20: 1524000 | T20: 1629000 | U20: 1824000 | V20: 1342000 | W20: 1521000 | X20: 9242000 | Y20: 18695000 | Z20: 4834000 | AA20: 1271000 | AB20: 12719000 | AF20: 10642000
B21: 기타금융업자산
B22: 자본 | C22: 47166007000 | D22: 46852331000 | E22: 43488826000 | F22: 40777676000 | G22: 36378486000 | H22: 33820919000 | I22: 30904498000 | J22: 27763784000 | K22: 25168919000 | L22: 24023530000 | M22: 22004580000 | N22: 21700822000 | O22: 21464689000 | P22: 21387703000 | Q22: 20766327000 | R22: 20295553000 | S22: 19125736000 | T22: 18036303000 | U22: 16290275000 | V22: 14609986000 | W22: 13852376000 | X22: 13066859000 | Y22: 12313704000 | Z22: 11157690000 | AA22: 10043546000 | AB22: 9739442000 | AC22: 9786442000 | AD22: 9859602000 | AE22: 9898248000 | AF22: 7875271000 | AG22: 8266462000 | AH22: 8558728000 | AI22: 8099989000 | AJ22: 7907576000 | AK22: 5919278463
B23: 상장자본금 | C23: 3657652000 | D23: 3657652000 | E23: 3657652000 | F23: 3657652000 | G23: 3657652000 | H23: 3657652000 | I23: 3657652000 | J23: 3657652000 | K23: 3657652000 | L23: 3657652000 | M23: 3657652000 | N23: 3657652000 | O23: 3657652000 | P23: 3657652000 | Q23: 3657652000 | R23: 3657652000 | S23: 3657652000 | T23: 3657652000 | U23: 3649675000 | V23: 3598249000 | W23: 3568645000 | X23: 3568645000 | Y23: 3568645000 | Z23: 3491225000 | AA23: 3488467000 | AB23: 3488419000 | AC23: 3488252000 | AD23: 3488252000 | AE23: 3487768000 | AF23: 2978498000 | AG23: 2978498000 | AH23: 2978498000 | AI23: 2971195000 | AJ23: 2969023000 | AK23: 2965833030
B24: 신종자본증권
B25: 자본잉여금 | C25: 4143736000 | D25: 4143736000 | E25: 4143736000 | F25: 4143736000 | G25: 4143736000 | H25: 4143736000 | I25: 4143736000 | J25: 4143736000 | K25: 4143736000 | L25: 4143736000 | M25: 4143736000 | N25: 4143736000 | O25: 4143736000 | P25: 4143736000 | Q25: 4143736000 | R25: 4143736000 | S25: 4143736000 | T25: 4143736000 | U25: 4081272000 | V25: 3646702000 | W25: 3406083000 | X25: 3406083000 | Y25: 3406148000 | Z25: 3066076000 | AA25: 3054075000 | AB25: 3053874000 | AC25: 3049173000 | AD25: 3049248000 | AE25: 3045857000 | AF25: 1229052000 | AG25: 1230979000 | AH25: 1230979000 | AI25: 1203046000 | AJ25: 1193100000 | AK25: 1303527701
B26: 기타자본 | C26: -2506133000 | D26: -2506451000 | E26: -2506748000 | F26: -770531000 | G26: -770825000 | H26: -771100000 | I26: -771365000 | J26: -771629000 | K26: -771890000 | L26: -771913000 | M26: -771913000 | N26: -771913000 | O26: -771913000 | P26: -771913000 | Q26: -753647000 | R26: -24000 | S26: -24000 | T26: -24000 | U26: -24000 | V26: -24000 | AC26: 4100000 | AD26: 4101000 | AE26: 5762000 | AF26: 5762000 | AG26: 5762000 | AH26: 5762000 | AI26: 5762000 | AJ26: 5762000 | AK26: 5768977
B27: 기타포괄손익누계액 | C27: -239859000 | D27: -482819000 | E27: -503817000 | F27: -265781000 | G27: -342468000 | H27: -502264000 | I27: -184564000 | J27: -273810000 | K27: -403951000 | L27: -79103000 | M27: -355501000 | N27: -64363000 | O27: -16611000 | P27: -1600000 | Q27: 212891000 | R27: 35334000 | S27: -27757000 | T27: -41815000 | U27: -212561000 | V27: -311877000 | W27: -125534000 | X27: -108807000 | Y27: -57240000 | Z27: 162184000 | AA27: 9642000 | AB27: -115402000 | AC27: 13086000 | AD27: 87763000 | AE27: 75355000 | AF27: 107107000 | AG27: 128474000 | AH27: -141242000 | AI27: -93749000 | AJ27: -23261000 | AK27: 171315813
B28: 이익잉여금(결손금) | C28: 42104440000 | D28: 42033601000 | E28: 38693194000 | F28: 34006624000 | G28: 29683733000 | H28: 27287256000 | I28: 24051224000 | J28: 21001186000 | K28: 18536781000 | L28: 17066583000 | M28: 15326660000 | N28: 14732047000 | O28: 14448057000 | P28: 14358988000 | Q28: 13505758000 | R28: 12459056000 | S28: 11352618000 | T28: 10276904000 | U28: 8772307000 | V28: 7677012000 | W28: 7003836000 | X28: 6201322000 | Y28: 5396824000 | Z28: 4438631000 | AA28: 3491844000 | AB28: 3313265000 | AC28: 3232602000 | AD28: 3230970000 | AE28: 3284131000 | AF28: 3555323000 | AG28: 3923160000 | AH28: 4484268000 | AI28: 4013194000 | AJ28: 3761299000 | AK28: 1005936494
B29: 부채 | C29: 17965494000 | D29: 16806004000 | E29: 13888426000 | F29: 12479404000 | G29: 12746637000 | H29: 11597545000 | I29: 9825955000 | J29: 9737793000 | K29: 9150581000 | L29: 8192496000 | M29: 7162415000 | N29: 7628630000 | O29: 8332966000 | P29: 8290203000 | Q29: 8575813000 | R29: 8168152000 | S29: 8267177000 | T29: 8846975000 | U29: 7790940000 | V29: 7946721000 | W29: 8213363000 | X29: 7730439000 | Y29: 8223586000 | Z29: 9117705000 | AA29: 9014668000 | AB29: 8909251000 | AC29: 9435542000 | AD29: 9975570000 | AE29: 9366112000 | AF29: 9362877000 | AG29: 9775134000 | AH29: 8957209000 | AI29: 9276888000 | AJ29: 9504541000 | AK29: 10384254935
B30: 비예수부채 | C30: 1159490000 | D30: 2917578000 | E30: 1409022000 | F30: -267233000 | G30: 1159490000 | H30: 2917578000 | I30: 88162000 | J30: -267233000 | K30: 1149092000 | L30: 1771590000 | M30: 88162000 | N30: 587212000 | O30: 958085000 | P30: 1030081000 | Q30: 1030081000 | R30: 1030081000 | S30: 1030081000
B31: 금융부채 | C31: 1153848000 | J31: 100000 | K31: 189000 | L31: 288000 | M31: 435000 | N31: 564000 | O31: 624000 | P31: 683000 | Q31: 854000 | R31: 855000 | S31: 956000 | T31: 738000 | U31: 24831000 | V31: 212896000 | W31: 91534000 | X31: 109288000 | Y31: 47314000 | Z31: 51240000 | AA31: 44632000 | AB31: 18635000 | AC31: 11087000 | AD31: 14000000 | AE31: 81832000 | AF31: 46474000 | AG31: 58381000 | AH31: 88203000 | AI31: 121581000 | AJ31: 59768000 | AK31: 96198115
B32: 파생상품부채 | J32: 100000 | K32: 189000 | L32: 288000 | N32: 564000 | O32: 624000 | P32: 683000 | R32: 855000 | S32: 956000 | T32: 738000 | U32: 24831000 | V32: 212896000 | W32: 91534000 | X32: 109288000 | Y32: 47314000 | Z32: 51240000 | AA32: 44632000 | AB32: 18635000 | AC32: 11087000 | AD32: 14000000 | AE32: 81832000 | AF32: 46474000 | AG32: 58381000 | AH32: 88203000 | AI32: 121581000 | AJ32: 59768000 | AK32: 33309115
B33: 차입금 | C33: 3537650000 | D33: 2747354000 | E33: 2420553000 | F33: 3280040000 | G33: 3343293000 | H33: 2273019000 | I33: 2466932000 | J33: 2534132000 | K33: 2200378000 | L33: 2095737000 | M33: 1936416000 | N33: 2092149000 | O33: 3554149000 | P33: 1659951000 | Q33: 2109905000 | R33: 2997889000 | S33: 2746106000 | T33: 1996937000 | U33: 2001156000 | V33: 1571455000 | W33: 1992748000 | X33: 1868162000 | Y33: 2587034000 | Z33: 2880668000 | AA33: 3153573000 | AB33: 3322416000 | AC33: 3338377000 | AD33: 3201301000 | AE33: 2569761000 | AF33: 2898982000 | AG33: 3011092000 | AH33: 2142449000 | AI33: 2538750000 | AJ33: 2283665000 | AK33: 3570599152
B34: 사채 | C34: 1506366000 | D34: 1506068000 | E34: 1505770000 | F34: 1166912000 | H34: 1317157000 | I34: 1386757000 | J34: 1386447000 | K34: 1465935000 | L34: 1535381000 | M34: 1534980000 | N34: 1734349000 | P34: 1293220000 | Q34: 1116049000 | R34: 760316000 | T34: 1156967000 | U34: 1151849000 | V34: 1147971000 | W34: 1763072000 | X34: 1983180000 | Y34: 1955857000 | Z34: 1992245000 | AA34: 1455415000 | AB34: 1457110000 | AC34: 1455380000 | AD34: 2040125000 | AE34: 2458812000 | AF34: 2463215000 | AG34: 2576480000 | AH34: 2101121000 | AI34: 1877179000 | AJ34: 1704706000 | AK34: 1931176000
B35: 기타금융업부채
B36: 기타충당부채 | C36: 3115000 | D36: 9873000 | E36: 43152000 | F36: 3611000 | G36: 63540000 | H36: 43939000 | I36: 66622000 | J36: 50872000 | K36: 59082000 | L36: 42822000 | M36: 33425000 | N36: 29047000 | O36: 27851000 | P36: 25276000 | Q36: 31520000 | R36: 30714000 | S36: 26637000 | T36: 25932000 | U36: 23582000 | V36: 25056000 | W36: 46926000 | X36: 52584000 | Y36: 97067000 | Z36: 42582000 | AA36: 346985000 | AB36: 330615000 | AC36: 382118000 | AD36: 414184000 | AE36: 380702000 | AF36: 353467000 | AG36: 412102000 | AH36: 367666000 | AI36: 487875000 | AJ36: 532123000
B37: 당기법인세부채 | C37: 2906381000 | D37: 4555670000 | E37: 3377828000 | F37: 2751896000 | G37: 2508545000 | H37: 2385876000 | I37: 1620360000 | J37: 1054780000 | K37: 685800000 | L37: 374666000 | M37: 81437000 | N37: 237084000 | O37: 476896000 | P37: 627260000 | Q37: 466194000 | R37: 565970000 | S37: 671356000 | T37: 583529000 | U37: 262846000 | V37: 362752000 | W37: 175607000 | X37: 12084000 | Y37: 7426000 | Z37: 10541000 | AA37: 21509000 | AB37: 13368000 | AC37: 9109000 | AD37: 13347000 | AE37: 9868000 | AF37: 11170000 | AG37: 16155000 | AH37: 4969000 | AI37: 14106000 | AJ37: 8588000 | AK37: 4417663
B38: 종업원급여충당부채 | C38: 139763000 | D38: 79790000 | E38: 214321000 | F38: 164582000 | G38: 114089000 | H38: 70056000 | I38: 504147000 | J38: 452266000 | K38: 416061000 | L38: 368371000 | M38: 670875000 | N38: 632332000 | O38: 589647000 | P38: 546126000 | Q38: 644100000 | R38: 605301000 | S38: 566263000 | T38: 524814000 | U38: 778304000 | V38: 748543000 | W38: 716230000 | X38: 687020000 | Y38: 689263000 | Z38: 661563000 | AA38: 633883000 | AB38: 615431000 | AC38: 511563000 | AD38: 503486000 | AE38: 505914000 | AF38: 493268000 | AG38: 423553000 | AH38: 412257000 | AI38: 396051000 | AJ38: 386369000 | AK38: 351844804
B39: 기타부채 | C39: 16797000 | D39: 21559000 | E39: 97627000 | F39: 114333000 | G39: 66223000 | H39: 15825000 | I39: 10864000 | J39: 9037000 | K39: 9354000 | L39: 6337000 | M39: 7472000 | N39: 6832000 | O39: 5693000 | P39: 7249000 | Q39: 5712000 | R39: 2453000 | S39: 2119000 | T39: 3167000 | U39: 5447000 | V39: 3209000 | W39: 4275000 | X39: 5284000 | Y39: 8615000 | Z39: 9033000 | AA39: 11756000 | AB39: 5197000 | AC39: 17845000 | AD39: 18701000 | AE39: 40070000 | AF39: 18956000 | AG39: 67593000 | AH39: 95592000 | AI39: 156472000 | AJ39: 293134000 | AK39: 559123552
B40: 이연법인세부채 | C40: 6224000 | D40: 6597000 | E40: 2229000 | F40: 2548000 | G40: 2708000 | H40: 5554000 | I40: 5156000 | J40: 3806000 | K40: 4034000 | L40: 4732000 | M40: 5146000 | N40: 6110000 | O40: 6946000 | P40: 7582000 | Q40: 2754000 | R40: 1915000 | S40: 2212000 | T40: 3463000 | U40: 2784000 | V40: 3009000
B41: 예수부채 | C41: -373000 | D41: 4368000 | E41: -319000 | F41: -160000 | G41: -373000 | H41: 4368000 | I41: 1350000 | J41: -160000 | K41: -2846000 | L41: 398000 | M41: 1350000 | N41: -228000 | O41: -698000 | P41: -414000 | Q41: -414000 | R41: -414000 | S41: -414000

Sheet 포괄손익계산서
B2: 종목코드 | C2: =재무상태표!C2 -> 000660 | E2: 시작일 | F2: =재무상태표!F2 -> 39970 | H2: 연결기준 | I2: =재무상태표!I2 -> 연결
B3: 종목명 | C3: =재무상태표!C3 -> SK하이닉스 | E3: 종료일 | F3: =재무상태표!F3 -> 43616 | H3: 누적기준 | I3: =재무상태표!I3 -> 누적
H4: 분기 | I4: =재무상태표!I4 -> 연속
B7: =_xll.IMDH("STK",$C$2,B8:B39,$F$2,$F$3,9999,"Per=일,sort=D,real=true,Bizday=0,Quote=종가,Pos=11,Orient=H,Cons="&$I$2&",Comp="&$I$3&",Trai="&I4&",Title="&$C$3&",DtFmt=1,TmFmt=1,unit=true") -> SK하이닉스
B8: 일자 | C8: 43555 | D8: 43465 | E8: 43373 | F8: 43281 | G8: 43190 | H8: 43100 | I8: 43008 | J8: 42916 | K8: 42825 | L8: 42735 | M8: 42643 | N8: 42551 | O8: 42460 | P8: 42369 | Q8: 42277 | R8: 42185 | S8: 42094 | T8: 42004 | U8: 41912 | V8: 41820 | W8: 41729 | X8: 41639 | Y8: 41547 | Z8: 41455 | AA8: 41364 | AB8: 41274 | AC8: 41182 | AD8: 41090 | AE8: 40999 | AF8: 40908 | AG8: 40816 | AH8: 40724 | AI8: 40633 | AJ8: 40543 | AK8: 40451 | AL8: 40359 | AM8: 40268 | AN8: 40178
B9: 매출액(영업수익) | C9: 6772655000 | D9: 40445066000 | E9: 30506985000 | F9: 19090197000 | G9: 8719691000 | H9: 30109434000 | I9: 21081881000 | J9: 12981796000 | K9: 6289518000 | L9: 17197975000 | M9: 11840289000 | N9: 7596644000 | O9: 3655717000 | P9: 18797998000 | Q9: 14381954000 | R9: 9456920000 | S9: 4818341000 | T9: 17125566000 | U9: 11977634000 | V9: 7665565000 | W9: 3742690000 | X9: 14165102000 | Y9: 10797415000 | Z9: 6713794000 | AA9: 2781147000 | AB9: 10162210000 | AC9: 7443823000 | AD9: 5020341000 | AE9: 2388389000 | AF9: 10395811000 | AG9: 7842652000 | AH9: 5551547000 | AI9: 2793185000 | AJ9: 12106090000 | AK9: 9355422000 | AL9: 6103829000 | AM9: 2823913000 | AN9: 7906350018
B10: 매출원가(영업비용) | C10: 4092455000 | D10: 15180838000 | E10: 11017081000 | F10: 7145457000 | G10: 3383214000 | H10: 12701843000 | I10: 9241783000 | J10: 5843626000 | K10: 2984822000 | L10: 10787139000 | M10: 7819077000 | N10: 5026789000 | O10: 2337672000 | P10: 10515353000 | Q10: 7848686000 | R10: 5052677000 | S10: 2529949000 | T10: 9461725000 | U10: 6733182000 | V10: 4356467000 | W10: 2110422000 | X10: 8864587000 | Y10: 6848384000 | Z10: 4469109000 | AA10: 2018229000 | AB10: 8550989000 | AC10: 6347051000 | AD10: 4332796000 | AE10: 2178386000 | AF10: 8704921000 | AG10: 6422073000 | AH10: 4239394000 | AI10: 2112379000 | AJ10: 7643517000 | AK10: 5544659000 | AL10: 3606564000 | AM10: 1708758000 | AN10: 6279821110
B11: 매출총이익 | C11: 2680200000 | D11: 25264228000 | E11: 19489904000 | F11: 11944740000 | G11: 5336477000 | H11: 17407591000 | I11: 11840098000 | J11: 7138170000 | K11: 3304696000 | L11: 6410836000 | M11: 4021212000 | N11: 2569855000 | O11: 1318045000 | P11: 8282645000 | Q11: 6533268000 | R11: 4404243000 | S11: 2288392000 | T11: 7663841000 | U11: 5244452000 | V11: 3309098000 | W11: 1632268000 | X11: 5300515000 | Y11: 3949031000 | Z11: 2244685000 | AA11: 762918000 | AB11: 1611221000 | AC11: 1096772000 | AD11: 687545000 | AE11: 210003000 | AF11: 1690890000 | AG11: 1420579000 | AH11: 1312153000 | AI11: 680806000 | AJ11: 4462573000 | AK11: 3810763000 | AL11: 2497265000 | AM11: 1115155000 | AN11: 1626528908
B12: 판매비와 관리비 | C12: 1313710000 | D12: 4420478000 | E12: 3076229000 | F12: 2003485000 | G12: 969139000 | H12: 3686265000 | I12: 2584606000 | J12: 1619871000 | K12: 837097000 | L12: 3134090000 | M12: 2280605000 | N12: 1555204000 | O12: 756247000 | P12: 2946545000 | Q12: 2186043000 | R12: 1440233000 | S12: 699862000 | T12: 2554375000 | U12: 1802145000 | V12: 1167965000 | W12: 575002000 | X12: 1920730000 | Y12: 1353997000 | Z12: 814131000 | AA12: 445967000 | AB12: 1838570000 | AC12: 1379093000 | AD12: 945843000 | AE12: 473548000 | AF12: 1321795000 | AG12: 1122919000 | AH12: 722667000 | AI12: 348469000 | AJ12: 1461172000 | AK12: 1133122000 | AL12: 749018000 | AM12: 355290000 | AN12: 1434559682
B13: 급여 | C13: 147407000 | D13: 564923000 | E13: 383647000 | F13: 256711000 | G13: 135533000 | H13: 467824000 | I13: 345671000 | J13: 221020000 | K13: 126021000 | L13: 348571000 | M13: 245218000 | N13: 155149000 | O13: 82993000 | P13: 385281000 | Q13: 304253000 | R13: 205351000 | S13: 99591000 | T13: 351318000 | U13: 248108000 | V13: 159348000 | W13: 78174000 | X13: 265137000 | Y13: 194324000 | Z13: 129179000 | AA13: 51017000 | AB13: 211210000 | AC13: 155307000 | AD13: 110209000 | AE13: 57801000 | AF13: 178193000 | AG13: 131511000 | AH13: 87027000 | AI13: 37731000 | AJ13: 196587000 | AK13: 142484000 | AL13: 91271000 | AM13: 34852000 | AN13: 125954134
B14: 감가상각비(포괄손익계산서) | C14: 43714000 | D14: 130229000 | E14: 90695000 | F14: 57887000 | G14: 28749000 | H14: 96153000 | I14: 70119000 | J14: 45945000 | K14: 22498000 | L14: 82461000 | M14: 60505000 | N14: 41273000 | O14: 22695000 | P14: 89879000 | Q14: 64331000 | R14: 41043000 | S14: 19995000 | T14: 58608000 | U14: 41067000 | V14: 25829000 | W14: 14087000 | X14: 51240000 | Y14: 38953000 | Z14: 25662000 | AA14: 12825000 | AB14: 55602000 | AC14: 42248000 | AD14: 28234000 | AE14: 12987000 | AF14: 55528000 | AG14: 42095000 | AH14: 28291000 | AI14: 14206000 | AJ14: 56435000 | AK14: 42193000 | AL14: 29014000 | AM14: 14322000 | AN14: 57877094
B15: 기타무형자산상각비(포괄손익계산서) | C15: 196784000 | D15: 442389000 | E15: 330949000 | F15: 220922000 | G15: 110962000 | H15: 348519000 | I15: 237846000 | J15: 132949000 | K15: 66105000 | L15: 282392000 | M15: 217758000 | N15: 167854000 | O15: 85239000 | P15: 239227000 | Q15: 158013000 | R15: 99041000 | S15: 57991000 | T15: 169844000 | U15: 124152000 | V15: 85064000 | W15: 48933000 | X15: 155313000 | Y15: 105267000 | Z15: 75152000 | AA15: 44756000 | AB15: 145154000 | AC15: 93253000 | AD15: 57769000 | AE15: 30556000 | AF15: 65018000 | AG15: 34551000 | AH15: 18294000 | AI15: 9138000 | AJ15: 18503000 | AK15: 11164000 | AL15: 7346000 | AM15: 3545000 | AN15: 52996583
B16: 연구개발비 | C16: 653973000 | D16: 2284000000 | E16: 1589573000 | F16: 1031360000 | G16: 512389000 | H16: 1975386000 | I16: 1389797000 | J16: 866977000 | K16: 451231000 | L16: 1744711000 | M16: 1279160000 | N16: 871602000 | O16: 420742000 | P16: 1620324000 | Q16: 1208131000 | R16: 798279000 | S16: 392067000 | T16: 1409530000 | U16: 1008129000 | V16: 650662000 | W16: 314244000 | X16: 968804000 | Y16: 669962000 | Z16: 351827000 | AA16: 234317000 | AB16: 975057000 | AC16: 751829000 | AD16: 520491000 | AE16: 263823000 | AF16: 609729000 | AG16: 617349000 | AH16: 395566000 | AI16: 191963000 | AJ16: 801627000 | AK16: 642724000 | AL16: 417661000 | AM16: 194643000 | AN16: 798701565
B17: 영업이익 | C17: 1366490000 | D17: 20843750000 | E17: 16413675000 | F17: 9941255000 | G17: 4367338000 | H17: 13721326000 | I17: 9255492000 | J17: 5518299000 | K17: 2467599000 | L17: 3276746000 | M17: 1740607000 | N17: 1014651000 | O17: 561798000 | P17: 5336100000 | Q17: 4347225000 | R17: 2964010000 | S17: 1588530000 | T17: 5109466000 | U17: 3442307000 | V17: 2141133000 | W17: 1057266000 | X17: 3379785000 | Y17: 2595034000 | Z17: 1430554000 | AA17: 316951000 | AB17: -227349000 | AC17: -282321000 | AD17: -258298000 | AE17: -263545000 | AF17: 369095000 | AG17: 492959000 | AH17: 769718000 | AI17: 322829000 | AJ17: 2975271000 | AK17: 2681586000 | AL17: 1757724000 | AM17: 741762000 | AN17: 191969226
B18: 이자수익 | C18: 11306000 | D18: 62478000 | E18: 53791000 | F18: 43193000 | G18: 27282000 | H18: 54275000 | I18: 33983000 | J18: 19352000 | K18: 9513000 | L18: 34174000 | M18: 26185000 | N18: 19198000 | O18: 11605000 | P18: 40715000 | Q18: 29554000 | R18: 17687000 | S18: 8964000 | T18: 52122000 | U18: 39808000 | V18: 27996000 | W18: 16273000 | X18: 66410000 | Y18: 45659000 | Z18: 25538000 | AA18: 12528000 | AB18: 80154000 | AC18: 68136000 | AD18: 48061000 | AE18: 21957000 | AF18: 56470000 | AG18: 42465000 | AH18: 28475000 | AI18: 13400000 | AJ18: 67708000 | AK18: 49648000 | AL18: 31903000 | AM18: 12016000 | AN18: 29977103
B19: 배당금수익
B20: 외환거래이익(포괄손익계산서) | C20: 320219000 | D20: 1386287000 | E20: 1091720000 | F20: 945807000 | G20: 207561000 | H20: 893047000 | I20: 672703000 | J20: 470406000 | K20: 364869000 | L20: 762747000 | M20: 584337000 | N20: 358349000 | O20: 282096000 | P20: 766981000 | Q20: 616575000 | R20: 316041000 | S20: 176172000 | T20: 576577000 | U20: 357656000 | V20: 239419000 | W20: 92986000 | X20: 485411000 | Y20: 370146000 | Z20: 270794000 | AA20: 127893000 | AB20: 598986000 | AC20: 375645000 | AD20: 227404000 | AE20: 159837000 | AF20: 532684000 | AG20: 471867000 | AH20: 349958000 | AI20: 186129000 | AJ20: 716815000 | AK20: 597312000 | AL20: 392370000 | AM20: 249074000 | AN20: 892699611
B21: 금융자산처분이익 | C21: 6042000 | D21: 41853000 | E21: 19122000 | F21: 7548000 | G21: 3842000 | H21: 46832000 | I21: 39572000 | J21: 5261000 | K21: 2731000 | L21: 15348000 | M21: 11532000 | N21: 9265000 | O21: 4792000 | P21: 33814000 | Q21: 28365000 | R21: 20522000 | S21: 13424000 | T21: 38547000 | U21: 27482000 | V21: 10444000 | W21: 220000 | X21: 205000 | Y21: 205000 | AA21: 86000 | AB21: 5944000 | AC21: 5875000 | AE21: 5872000 | AJ21: 617000 | AN21: 413140
B22: 금융자산평가이익 | C22: 20737000 | D22: 199201000 | E22: 9578000 | F22: 4828000 | G22: 1104000 | H22: 1399000 | I22: 2937000 | J22: 1735000 | K22: 434000 | L22: 1133000 | M22: 690000 | N22: 932000 | O22: 1862000 | P22: 2280000 | Q22: 3404000 | R22: 4694000 | S22: 487000 | T22: 6921000 | U22: 4725000 | V22: 2899000 | W22: 6082000
B23: 파생상품이익 | H23: 902000 | I23: 902000 | J23: 598000 | K23: 302000 | L23: 1472000 | M23: 1124000 | N23: 704000 | O23: 346000 | P23: 1697000 | Q23: 1376000 | R23: 989000 | S23: 560000 | T23: 3170000 | U23: 2529000 | V23: 1517000 | W23: 16149000 | X23: 6163000 | Y23: 5556000 | Z23: 1880000 | AA23: 1124000 | AB23: 4409000 | AC23: 4744000 | AD23: 2704000 | AE23: 8704000 | AF23: 41111000 | AG23: 39870000 | AH23: 20820000 | AI23: 9804000 | AJ23: 80695000 | AK23: 78076000 | AL23: 40421000 | AM23: 13226000 | AN23: 19738000
B24: 이자비용 | C24: 41070000 | D24: 94635000 | E24: 65781000 | F24: 42377000 | G24: 24891000 | H24: 123918000 | I24: 96330000 | J24: 64026000 | K24: 29575000 | L24: 120122000 | M24: 96836000 | N24: 64741000 | O24: 33669000 | P24: 118505000 | Q24: 85931000 | R24: 52917000 | S24: 26011000 | T24: 170363000 | U24: 142552000 | V24: 102903000 | W24: 53340000 | X24: 256623000 | Y24: 200558000 | Z24: 136894000 | AA24: 67880000 | AB24: 317926000 | AC24: 242345000 | AD24: 162415000 | AE24: 81528000 | AF24: 310397000 | AG24: 229930000 | AH24: 161081000 | AI24: 79865000 | AJ24: 346377000 | AK24: 264573000 | AL24: 180650000 | AM24: 87594000 | AN24: 433576400
B25: 외환거래손실(포괄손익계산서) | C25: 206772000 | D25: 1046217000 | E25: 863835000 | F25: 635241000 | G25: 288387000 | H25: 1124628000 | I25: 642441000 | J25: 515514000 | K25: 437366000 | L25: 724681000 | M25: 592097000 | N25: 381624000 | O25: 258389000 | P25: 709350000 | Q25: 598769000 | R25: 267588000 | S25: 152226000 | T25: 448060000 | U25: 283795000 | V25: 227612000 | W25: 102765000 | X25: 391071000 | Y25: 335362000 | Z25: 334147000 | AA25: 162079000 | AB25: 335468000 | AC25: 245869000 | AD25: 178437000 | AE25: 83947000 | AF25: 551750000 | AG25: 579625000 | AH25: 208078000 | AI25: 107734000 | AJ25: 654166000 | AK25: 544746000 | AL25: 473067000 | AM25: 114603000
B26: 금융자산처분손실 | H26: 158000 | I26: 1000 | T26: 3500000 | U26: 3500000
B27: 금융자산평가손실 | C27: 13000 | D27: 1282000
B28: 파생상품손실 | H28: 913000 | I28: 913000 | J28: 609000 | K28: 308000 | L28: 1525000 | M28: 1218000 | N28: 812000 | O28: 406000 | P28: 2058000 | Q28: 1797000 | R28: 1291000 | S28: 885000 | T28: 174924000 | U28: 174523000 | V28: 187861000 | W28: 352000 | X28: 99635000 | Y28: 36924000 | Z28: 39353000 | AA28: 28255000 | AB28: 18730000 | AC28: 11214000 | AD28: 7002000 | AE28: 37864000 | AF28: 19714000 | AG28: 31160000 | AH28: 40374000 | AI28: 65666000 | AJ28: 5385000 | AK28: 5920000 | AL28: 7929000 | AM28: 749000 | AN28: 14257094
B29: 종속기업공동지배기업관계기업손익 | C29: 4426000 | D29: 13007000 | E29: 11451000 | F29: 8472000 | G29: 4526000 | H29: 12367000 | I29: 8027000 | J29: 4503000 | K29: -227000 | L29: 22752000 | M29: 16600000 | N29: 14181000 | O29: 3071000 | P29: 24642000 | Q29: 18510000 | R29: 10270000 | S29: 5695000 | T29: 23145000 | U29: 15967000 | V29: 13710000 | W29: 388000 | X29: 19256000 | Y29: 13369000 | Z29: 7703000 | AA29: 3614000 | AB29: 16713000 | AC29: 11036000 | AD29: 6959000 | AE29: 6543000 | AF29: 10533000 | AG29: 7274000 | AH29: 5802000 | AI29: 2519000 | AJ29: 2120000 | AK29: 2460000 | AL29: 78000 | AM29: 1052000 | AN29: 6101643
B30: 법인세비용차감전순이익 | C30: 1479547000 | D30: 21341030000 | E30: 16629519000 | F30: 10194284000 | G30: 4290810000 | H30: 13439566000 | I30: 9282319000 | J30: 5439462000 | K30: 2370143000 | L30: 3216454000 | M30: 1645362000 | N30: 941198000 | O30: 557990000 | P30: 5269121000 | Q30: 4291991000 | R30: 2980329000 | S30: 1602080000 | T30: 5047670000 | U30: 3142405000 | V30: 1827480000 | W30: 969489000 | X30: 3074925000 | Y30: 2240765000 | Z30: 1221018000 | AA30: 208217000 | AB30: -199301000 | AC30: -309719000 | AD30: -314903000 | AE30: -271028000 | AF30: 45147000 | AG30: 202373000 | AH30: 753893000 | AI30: 281418000 | AJ30: 2666382000 | AK30: 2567881000 | AL30: 1534388000 | AM30: 814802000 | AN30: -370820974
B31: 법인세비용 | C31: 377417000 | D31: 5801046000 | E31: 4487454000 | F31: 2744413000 | G31: 1169481000 | H31: 2797347000 | I31: 1859600000 | J31: 1072273000 | K31: 471465000 | L31: 255971000 | M31: 313453000 | N31: 207040000 | O31: 109964000 | P31: 945526000 | Q31: 839763000 | R31: 576463000 | S31: 306624000 | T31: 852501000 | U31: 571320000 | V31: 351476000 | W31: 167235000 | X31: 202068000 | Y31: 157055000 | Z31: 95545000 | AA31: 29504000 | AB31: -40506000 | AC31: 12770000 | AD31: 9627000 | AE31: 195000 | AF31: 101118000 | AG31: 18456000 | AH31: 7356000 | AI31: 7878000 | AJ31: 68807000 | AK31: 308000 | AL31: 7612000 | AM31: 6703000 | AN31: -38176877
B32: 계속영업이익 | C32: 1102130000 | D32: 15539984000 | E32: 12142065000 | F32: 7449871000 | G32: 3121329000 | H32: 10642219000 | I32: 7422719000 | J32: 4367189000 | K32: 1898678000 | L32: 2960483000 | M32: 1331909000 | N32: 734158000 | O32: 448026000 | P32: 4323595000 | Q32: 3452228000 | R32: 2403866000 | S32: 1295456000 | T32: 4195169000 | U32: 2571085000 | V32: 1476004000 | W32: 802254000 | X32: 2872857000 | Y32: 2083710000 | Z32: 1125473000 | AA32: 178713000 | AB32: -158795000 | AC32: -322489000 | AD32: -324530000 | AE32: -271223000 | AF32: -55971000 | AG32: 183917000 | AH32: 746537000 | AI32: 273540000 | AJ32: 2597575000 | AK32: 2567573000 | AL32: 1526776000 | AM32: 808099000 | AN32: -332644097
B33: 당기순이익(포괄손익계산서) | C33: 1102130000 | D33: 15539984000 | E33: 12142065000 | F33: 7449871000 | G33: 3121329000 | H33: 10642219000 | I33: 7422719000 | J33: 4367189000 | K33: 1898678000 | L33: 2960483000 | M33: 1331909000 | N33: 734158000 | O33: 448026000 | P33: 4323595000 | Q33: 3452228000 | R33: 2403866000 | S33: 1295456000 | T33: 4195169000 | U33: 2571085000 | V33: 1476004000 | W33: 802254000 | X33: 2872857000 | Y33: 2083710000 | Z33: 1125473000 | AA33: 178713000 | AB33: -158795000 | AC33: -322489000 | AD33: -324530000 | AE33: -271223000 | AF33: -55971000 | AG33: 183917000 | AH33: 746537000 | AI33: 273540000 | AJ33: 2597575000 | AK33: 2567573000 | AL33: 1526776000 | AM33: 808099000 | AN33: -332644097
B34: 당기순이익지배기업주주지분 | C34: 1102753000 | D34: 15540111000 | E34: 12143821000 | F34: 7450200000 | G34: 3120254000 | H34: 10641512000 | I34: 7420763000 | J34: 4366515000 | K34: 1897969000 | L34: 2953774000 | M34: 1327109000 | N34: 730335000 | O34: 444194000 | P34: 4322356000 | Q34: 3452106000 | R34: 2403799000 | S34: 1295730000 | T34: 4195456000 | U34: 2571059000 | V34: 1475739000 | W34: 802538000 | X34: 2872470000 | Y34: 2083680000 | Z34: 1125401000 | AA34: 178595000 | AB34: -158886000 | AC34: -322392000 | AD34: -324278000 | AE34: -271119000 | AF34: -56641000 | AG34: 183252000 | AH34: 744352000 | AI34: 273264000 | AJ34: 2620962000 | AK34: 2601945000 | AL34: 1547697000 | AM34: 819633000
B35: 기타포괄손익(포괄손익계산서) | C35: 237231000 | D35: -67219000 | E35: -32508000 | F35: 212319000 | G35: 141965000 | H35: -422042000 | I35: -118698000 | J35: -203618000 | K35: -329711000 | L35: 28844000 | M35: -361532000 | N35: -67539000 | O35: -17589000 | P35: 18095000 | Q35: 249820000 | R35: 73785000 | S35: 12377000 | T35: -52361000 | U35: -103864000 | V35: -203076000 | W35: -16737000 | X35: 22125000 | Y35: 58122000 | Z35: 277767000 | AA35: 125142000 | AB35: -305601000 | AC35: -94379000 | AD35: -19358000 | AE35: -31799000 | AF35: 68850000 | AG35: 149969000 | AH35: -121057000 | AI35: -71727000 | AJ35: -103395000 | AK35: -48846000 | AL35: 77598000 | AM35: -96931000
B36: 총포괄손익 | C36: 1339361000 | D36: 15472765000 | E36: 12109557000 | F36: 7662190000 | G36: 3263294000 | H36: 10220177000 | I36: 7304021000 | J36: 4163571000 | K36: 1568967000 | L36: 2989327000 | M36: 970377000 | N36: 666619000 | O36: 430437000 | P36: 4341690000 | Q36: 3702048000 | R36: 2477651000 | S36: 1307833000 | T36: 4142808000 | U36: 2467221000 | V36: 1272928000 | W36: 785517000 | X36: 2894982000 | Y36: 2141832000 | Z36: 1403240000 | AA36: 303855000 | AB36: -464396000 | AC36: -416868000 | AD36: -343888000 | AE36: -303022000 | AF36: 12879000 | AG36: 333886000 | AH36: 625480000 | AI36: 201813000 | AJ36: 2494180000 | AK36: 2518727000 | AL36: 1604374000 | AM36: 711168000
B37: 총포괄손익지배기업주주지분 | C37: 1339802000 | D37: 15471792000 | E37: 12110387000 | F37: 7661853000 | G37: 3262275000 | H37: 10221113000 | I37: 7302781000 | J37: 4163497000 | K37: 1568951000 | L37: 2982703000 | M37: 966382000 | N37: 662907000 | O37: 426669000 | P37: 4340700000 | Q37: 3701961000 | R37: 2477702000 | S37: 1308172000 | T37: 4142574000 | U37: 2467231000 | V37: 1272620000 | W37: 785787000 | X37: 2894652000 | Y37: 2141791000 | Z37: 1402952000 | AA37: 303623000 | AB37: -464267000 | AC37: -416673000 | AD37: -343627000 | AE37: -302868000 | AF37: 12947000 | AG37: 333895000 | AH37: 626670000 | AI37: 202926000 | AJ37: 2524853000 | AK37: 2551598000 | AL37: 1611765000 | AM37: 737275000
B38: 주당순손익 | C38: 1612 | D38: 22255 | E38: 17272 | F38: 10553 | G38: 4420 | H38: 15073 | I38: 10511 | J38: 6185 | K38: 2688 | L38: 4184 | M38: 1880 | N38: 1034 | O38: 629 | P38: 6002 | Q38: 4762 | R38: 3302 | S38: 1780 | T38: 5842 | U38: 3596 | V38: 2063 | W38: 1130 | X38: 4045 | Y38: 2934 | Z38: 1620 | AA38: 257 | AB38: -233 | AC38: -476 | AD38: -484 | AE38: -420 | AF38: -96 | AG38: 309 | AH38: 1257 | AI38: 463 | AJ38: 4440 | AL38: 2622 | AM38: 1390
B39: 희석주당순손익 | D39: 22252 | E39: 17270 | F39: 10551 | G39: 4419 | H39: 15072 | W39: 1104 | Z39: 1606 | AH39: 1246 | AI39: 462 | AJ39: 4171 | AL39: 2500 | AM39: 1305

Sheet 현금흐름표
B2: 종목코드 | C2: =재무상태표!C2 -> 000660 | E2: 시작일 | F2: =재무상태표!F2 -> 39970 | H2: 연결기준 | I2: =재무상태표!I2 -> 연결
B3: 종목명 | C3: =재무상태표!C3 -> SK하이닉스 | E3: 종료일 | F3: =재무상태표!F3 -> 43616 | H3: 누적기준 | I3: =재무상태표!I3 -> 누적
H4: 분기 | I4: =재무상태표!I4 -> 연속
B7: =_xll.IMDH("STK",$C$2,B8:B47,$F$2,$F$3,9999,"Per=일,sort=D,real=true,Bizday=0,Quote=종가,Pos=11,Orient=H,Cons="&$I$2&",Comp="&$I$3&",Trai="&I4&",Title="&$C$3&",DtFmt=1,TmFmt=1,unit=true") -> SK하이닉스
B8: 일자 | C8: 43555 | D8: 43465 | E8: 43373 | F8: 43281 | G8: 43190 | H8: 43100 | I8: 43008 | J8: 42916 | K8: 42825 | L8: 42735 | M8: 42643 | N8: 42551 | O8: 42460 | P8: 42369 | Q8: 42277 | R8: 42185 | S8: 42094 | T8: 42004 | U8: 41912 | V8: 41820 | W8: 41729 | X8: 41639 | Y8: 41547 | Z8: 41455 | AA8: 41364 | AB8: 41274 | AC8: 41182 | AD8: 41090 | AE8: 40999 | AF8: 40908 | AG8: 40816 | AH8: 40724 | AI8: 40633 | AJ8: 40543 | AK8: 40451 | AL8: 40359 | AM8: 40268 | AN8: 40178
B9: 영업활동으로인한현금흐름 | C9: 2630762000 | D9: 22227199000 | E9: 15256517000 | F9: 8168263000 | G9: 4523576000 | H9: 14690614000 | I9: 9904080000 | J9: 6104122000 | K9: 2820020000 | L9: 5548922000 | M9: 3569159000 | N9: 1932535000 | O9: 649699000 | P9: 9319520000 | Q9: 6876195000 | R9: 4686390000 | S9: 2537650000 | T9: 5866691000 | U9: 4645022000 | V9: 3019859000 | W9: 1210525000 | X9: 6372056000 | Y9: 4652778000 | Z9: 2468869000 | AA9: 945760000 | AB9: 2211651000 | AC9: 1598458000 | AD9: 1229771000 | AE9: 743813000 | AF9: 2855960000 | AG9: 2120218000 | AH9: 1513460000 | AI9: 593830000 | AJ9: 5883541000 | AK9: 4775081000 | AL9: 2758648000 | AM9: 1559511000 | AN9: 1340381596
B10: 당기순손익 | C10: 1102130000 | D10: 15539984000 | E10: 12142065000 | F10: 7449871000 | G10: 3121329000 | H10: 10642219000 | I10: 7422719000 | J10: 4367189000 | K10: 1898678000 | L10: 2960483000 | M10: 1331909000 | N10: 734158000 | O10: 448026000 | P10: 4323595000 | Q10: 3452228000 | R10: 2403866000 | S10: 1295456000 | T10: 4195169000 | U10: 2571085000 | V10: 1476004000 | W10: 802254000 | X10: 2872857000 | Y10: 2083710000 | AA10: 178713000 | AJ10: 2656476000 | AN10: -332644097
B11: 현금유출이없는비용등가산 | C11: 2601834000 | D11: 12765682000 | E11: 9614998000 | F11: 6233342000 | G11: 2789866000 | H11: 8382948000 | I11: 5823638000 | J11: 3665343000 | K11: 1858327000 | L11: 5178758000 | M11: 3943425000 | N11: 2640049000 | O11: 1393412000 | P11: 5343635000 | Q11: 4196466000 | R11: 2668200000 | S11: 1360873000 | T11: 4911828000 | U11: 3643135000 | V11: 2461057000 | W11: 1149647000 | X11: 3897330000 | Y11: 2947829000 | Z11: 1956706000 | AA11: 1039480000 | AB11: 3690178000 | AC11: 2761886000 | AD11: 1868571000 | AE11: 986446000 | AF11: 3981991000 | AG11: 3183581000 | AH11: 1961983000 | AI11: 1043929000 | AJ11: 3857362000 | AK11: 2791720000 | AL11: 1925281000 | AM11: 901118000 | AN11: 3607740348
B12: 감가상각비(현금흐름표) | C12: 1816877000 | D12: 5904240000 | E12: 4285230000 | F12: 2763874000 | G12: 1318856000 | H12: 4618881000 | I12: 3408766000 | J12: 2220348000 | K12: 1086730000 | L12: 4133886000 | M12: 3065956000 | N12: 2018478000 | O12: 984498000 | P12: 3695158000 | Q12: 2726911000 | R12: 1785228000 | S12: 880494000 | T12: 3269705000 | U12: 2406024000 | V12: 1572095000 | W12: 774622000 | X12: 2922245000 | Y12: 2185037000 | Z12: 1454323000 | AA12: 727324000 | AB12: 3057856000 | AC12: 2306118000 | AD12: 1550971000 | AE12: 808376000 | AF12: 3401222000 | AG12: 2570616000 | AH12: 1687353000 | AI12: 837497000 | AJ12: 3128028000 | AK12: 2295490000 | AL12: 1445910000 | AM12: 736376000 | AN12: 2654166260
B13: 기타무형자산상각비(현금흐름표) | C13: 221098000 | D13: 524095000 | E13: 389993000 | F13: 259590000 | G13: 129801000 | H13: 407354000 | I13: 279087000 | J13: 158692000 | K13: 78408000 | L13: 322569000 | M13: 247027000 | N13: 186600000 | O13: 94168000 | P13: 258078000 | Q13: 170803000 | R13: 107007000 | S13: 61682000 | T13: 174275000 | U13: 126186000 | V13: 85882000 | W13: 49864000 | X13: 156276000 | Y13: 105989000 | Z13: 75636000 | AA13: 45002000 | AB13: 145698000 | AC13: 93710000 | AD13: 58066000 | AE13: 30703000 | AF13: 65692000 | AG13: 35075000 | AH13: 18671000 | AI13: 9331000 | AJ13: 21195000 | AK13: 11883000 | AL13: 8405000 | AM13: 4101000 | AN13: 53146467
B14: 외환거래손실(현금흐름표) | C14: 85781000 | D14: 181210000 | E14: 188233000 | F14: 276398000 | G14: 94235000 | H14: 246316000 | I14: 40526000 | J14: 55474000 | K14: 141582000 | L14: 116500000 | M14: 77408000 | N14: 63359000 | O14: 128106000 | P14: 143768000 | Q14: 210792000 | R14: 61878000 | S14: 46997000 | T14: 116726000 | U14: 64045000 | V14: 49287000 | W14: 43412000 | X14: 24415000 | Y14: 60091000 | Z14: 184342000 | AA14: 111265000 | AB14: 24597000 | AC14: 26329000 | AD14: 30532000 | AE14: 9749000 | AF14: 75810000 | AG14: 280777000 | AH14: 27332000 | AI14: 32419000 | AJ14: 51059000 | AK14: 94346000 | AL14: 209677000 | AM14: 26447000 | AN14: 34626817
B15: 자산처분손실 | C15: 3675000 | D15: 65283000 | E15: 62173000 | F15: 56097000 | G15: 4542000 | H15: 15101000 | I15: 10210000 | J15: 8525000 | K15: 6482000 | L15: 11784000 | M15: 9180000 | N15: 6555000 | Q15: 21697000 | R15: 6163000 | U15: 12755000 | V15: 9353000 | AD15: 4490000 | AE15: 2217000 | AF15: 15343000 | AG15: 12703000 | AH15: 1596000 | AI15: 856000 | AJ15: 47970000 | AK15: 40008000 | AL15: 37476000 | AM15: 25038000 | AN15: 39947782
B16: (현금유입이없는수익등차감) | C16: 192514000 | D16: 483731000 | E16: 193980000 | F16: 520281000 | G16: 87475000 | H16: 461770000 | I16: 326977000 | J16: 243567000 | K16: 239649000 | L16: 193414000 | M16: 247526000 | N16: 106800000 | O16: 133297000 | P16: 142246000 | Q16: 174508000 | R16: 136270000 | S16: 77551000 | T16: 144306000 | U16: 206290000 | V16: 142915000 | W16: 49885000 | X16: 179841000 | Y16: 140687000 | Z16: 105816000 | AA16: 67122000 | AB16: 308212000 | AC16: 183196000 | AD16: 89762000 | AE16: 103476000 | AF16: 134815000 | AG16: 193947000 | AH16: 199104000 | AI16: 137954000 | AJ16: 339832000 | AK16: 339340000 | AL16: 168617000 | AM16: 208390000 | AN16: 1041075277
B17: 외환거래이익(현금흐름표) | C17: 149801000 | D17: 126094000 | E17: 69563000 | F17: 442996000 | G17: 44953000 | H17: 310978000 | I17: 213079000 | J17: 203227000 | K17: 224970000 | L17: 106840000 | M17: 188256000 | N17: 61045000 | O17: 117009000 | P17: 58658000 | Q17: 80959000 | R17: 78682000 | S17: 51535000 | T17: 79678000 | U17: 115348000 | V17: 86339000 | W17: 17427000 | X17: 94175000 | Y17: 81659000 | Z17: 72575000 | AA17: 50390000 | AB17: 211345000 | AC17: 104024000 | AD17: 34742000 | AE17: 71741000 | AF17: 46380000 | AG17: 132381000 | AH17: 164244000 | AI17: 121218000 | AJ17: 127834000 | AK17: 146480000 | AL17: 70807000 | AM17: 164896000 | AN17: 287521342
B18: 자산처분이익 | C18: 202000 | D18: 44907000 | E18: 30723000 | F18: 13492000 | G18: 6016000 | H18: 66997000 | I18: 29379000 | J18: 9489000 | K18: 2000000 | L18: 13167000 | M18: 4263000 | N18: 2179000 | Q18: 13716000 | R18: 4415000 | U18: 2960000 | V18: 1527000 | AD18: 1265000 | AE18: 131000 | AF18: 24445000 | AG18: 16613000 | AH18: 6385000 | AI18: 3336000 | AJ18: 39043000 | AK18: 36523000 | AL18: 30990000 | AM18: 16501000 | AN18: 129583874
B19: 영업활동으로인한자산부채변동 | C19: -832216000 | D19: -1996918000 | E19: -3310899000 | F19: -2611903000 | G19: -248040000 | H19: -3190136000 | I19: -2347248000 | J19: -1260689000 | K19: -509710000 | L19: -1459046000 | M19: -515493000 | N19: -678112000 | O19: -778993000 | P19: 832283000 | Q19: 419760000 | R19: 379753000 | S19: 187822000 | T19: -2657462000 | U19: -1128097000 | V19: -725836000 | W19: -673732000 | X19: -68793000 | Y19: -125447000 | Z19: -532336000 | AA19: -161015000 | AB19: -761771000 | AC19: -507249000 | AD19: -132933000 | AE19: 164300000 | AF19: -812458000 | AG19: -929065000 | AH19: -907768000 | AI19: -574074000 | AJ19: -30163000 | AK19: -63280000 | AL19: -405882000 | AM19: 93558000 | AN19: -893639378
B20: 자산의감소 | C20: 387023000 | D20: -2390169000 | E20: -3107089000 | F20: -1901734000 | G20: -590246000 | H20: -3938403000 | I20: -2762952000 | J20: -1649330000 | K20: -617012000 | L20: -574563000 | M20: 140629000 | N20: 76960000 | O20: -1663000 | P20: 1392175000 | Q20: 972293000 | R20: 890428000 | S20: 810217000 | T20: -2706700000 | U20: -1102339000 | V20: -617534000 | W20: -378143000 | X20: -399216000 | Y20: -251216000 | Z20: -584438000 | AA20: -101276000 | AB20: -588168000 | AC20: -465548000 | AD20: -302951000 | AE20: -162838000 | AF20: 237267000 | AG20: 171509000 | AH20: -188819000 | AI20: -41486000 | AJ20: -274355000 | AK20: -590697000 | AL20: -503007000 | AM20: -138167000 | AN20: -769210632
B21: 부채의증가 | C21: -1219239000 | D21: 393251000 | E21: -203810000 | F21: -710169000 | G21: 342206000 | H21: 748267000 | I21: 415704000 | J21: 388641000 | K21: 107302000 | L21: -884483000 | M21: -656122000 | N21: -755072000 | O21: -777330000 | P21: -559892000 | Q21: -552533000 | R21: -510675000 | S21: -622395000 | T21: 49238000 | U21: -25758000 | V21: -108302000 | W21: -295589000 | X21: 330423000 | Y21: 221807000 | Z21: 11227000 | AA21: -68560000 | AB21: -98234000 | AC21: 45222000 | AD21: 185871000 | AE21: 320346000 | AF21: -899824000 | AG21: -680185000 | AH21: -718949000 | AI21: -532588000 | AJ21: 206133000 | AK21: 527417000 | AL21: 97125000 | AM21: 231725000 | AN21: -124428746
B22: 영업활동으로인한현금흐름(간접법) | C22: 2630762000 | D22: 22227199000 | E22: 15256517000 | F22: 8168263000 | G22: 4523576000 | H22: 14690614000 | I22: 9904080000 | J22: 6104122000 | K22: 2820020000 | L22: 5548922000 | M22: 3569159000 | N22: 1932535000 | O22: 649699000 | P22: 9319520000 | Q22: 6876195000 | R22: 4686390000 | S22: 2537650000 | T22: 5866691000 | U22: 4645022000 | V22: 3019859000 | W22: 1210525000 | X22: 6372056000 | Y22: 4652778000 | Z22: 2468869000 | AA22: 945760000 | AB22: 2211651000 | AC22: 1598458000 | AD22: 1229771000 | AE22: 743813000 | AF22: 2855960000 | AG22: 2120218000 | AH22: 1513460000 | AI22: 593830000 | AJ22: 5883541000 | AK22: 4775081000 | AL22: 2758648000 | AM22: 1559511000 | AN22: 1340381596
B23: 영업에서창출된현금흐름 | C23: 2679234000 | D23: 25825017000 | E23: 18252184000 | F23: 10551029000 | G23: 5575680000 | H23: 15373261000 | I23: 10572132000 | J23: 6528276000 | K23: 3007646000 | L23: 6486781000 | M23: 4512315000 | N23: 2589295000 | O23: 929148000 | P23: 10357267000 | Q23: 7893946000 | R23: 5315549000 | S23: 2766600000 | T23: 6305229000 | U23: 4879833000 | V23: 3068310000 | W23: 1228284000 | X23: 6521553000 | Y23: 4765405000 | Z23: 2539572000 | AA23: 990056000 | AB23: 2420894000 | AC23: 1761722000 | AD23: 1330973000 | AE23: 776242000 | AF23: 3079865000 | AG23: 2262942000 | AH23: 1609004000 | AI23: 613319000 | AJ23: 6153749000 | AK23: 4956981000 | AL23: 2885170000 | AM23: 1601088000
B24: 이자수입 | C24: 7158000 | D24: 81323000 | E24: 73561000 | F24: 64078000 | G24: 28192000 | H24: 41680000 | I24: 22329000 | J24: 13112000 | K24: 2619000 | L24: 42895000 | M24: 36356000 | N24: 25494000 | O24: 13147000 | P24: 51610000 | Q24: 43282000 | R24: 30319000 | S24: 27595000 | T24: 35658000 | U24: 32973000 | V24: 22053000 | W24: 17132000 | X24: 58888000 | Y24: 39111000 | Z24: 27068000 | AA24: 7169000 | AB24: 81931000 | AC24: 64086000 | AD24: 44769000 | AE24: 15303000 | AF24: 68107000 | AG24: 49458000 | AH24: 28744000 | AI24: 19174000 | AJ24: 67732000 | AK24: 36557000 | AL24: 22921000 | AM24: 7474000
B25: 이자지급(-) | C25: -39580000 | D25: -126029000 | E25: -90820000 | F25: -58974000 | G25: -30195000 | H25: -120332000 | I25: -92061000 | J25: -60946000 | K25: -29920000 | L25: -125818000 | M25: -97338000 | N25: -64474000 | O25: -30631000 | P25: -124304000 | Q25: -92651000 | R25: -63775000 | S25: -36742000 | T25: -151551000 | U25: -115432000 | V25: -81196000 | W25: -39137000 | X25: -199553000 | Y25: -152043000 | Z25: -103102000 | AA25: -50738000 | AB25: -275169000 | AC25: -219075000 | AD25: -145930000 | AE25: -41311000 | AF25: -275866000 | AG25: -189160000 | AH25: -122061000 | AI25: -36868000 | AJ25: -334144000 | AK25: -217960000 | AL25: -149320000 | AM25: -49142000
B26: 배당금수입 | C26: 42000 | D26: 15258000 | E26: 15099000 | F26: 15099000 | G26: 346000 | H26: 14841000 | J26: 14841000 | L26: 20744000 | M26: 20744000 | N26: 20744000 | O26: 18000 | P26: 17045000 | Q26: 16836000 | R26: 16781000 | S26: 995000 | T26: 17134000 | U26: 17106000 | V26: 15959000 | W26: 4000 | X26: 17414000 | Y26: 17414000 | Z26: 16450000 | AA26: 1362000 | AB26: 12098000 | AC26: 12098000 | AD26: 12098000 | AE26: 1000 | AF26: 8883000 | AG26: 8883000 | AH26: 8883000 | AK26: 687000 | AL26: 187000
B27: 영업활동배당금지급(-) | I27: -613161000
B28: 법인세환입 | I28: 14841000 | W28: 4242000 | AM28: 91000
B29: 법인세납부(-) | C29: -16092000 | D29: -3568370000 | E29: -2993507000 | F29: -2402969000 | G29: -1050447000 | H29: -618836000 | J29: -391161000 | K29: -160325000 | L29: -875680000 | M29: -902918000 | N29: -638524000 | O29: -261983000 | P29: -982098000 | Q29: -985218000 | R29: -612484000 | S29: -220798000 | T29: -339779000 | U29: -169458000 | V29: -5267000 | X29: -26246000 | Y29: -17109000 | Z29: -11119000 | AA29: -2089000 | AB29: -28103000 | AC29: -20373000 | AD29: -12139000 | AE29: -6422000 | AF29: -25029000 | AG29: -11905000 | AH29: -11110000 | AI29: -1795000 | AJ29: -3796000 | AK29: -1184000 | AL29: -310000
B30: 투자활동으로인한현금흐름 | C30: -4655347000 | D30: -21428749000 | E30: -14172714000 | F30: -10364680000 | G30: -3709452000 | H30: -11919162000 | I30: -9048646000 | J30: -5381034000 | K30: -1396667000 | L30: -6230451000 | M30: -3629309000 | N30: -2326760000 | O30: -1470668000 | P30: -7125530000 | Q30: -5786577000 | R30: -3798284000 | S30: -2027076000 | T30: -6087827000 | U30: -4910042000 | V30: -2861433000 | W30: -1713446000 | X30: -4892125000 | Y30: -3919118000 | Z30: -2203539000 | AA30: -648671000 | AB30: -4698379000 | AC30: -4326710000 | AD30: -2689162000 | AE30: -1263249000 | AF30: -3389264000 | AG30: -2660803000 | AH30: -2241514000 | AI30: -713805000 | AJ30: -4683472000 | AK30: -3827594000 | AL30: -2661291000 | AM30: -1145943000 | AN30: -1004420937
B31: 투자활동으로인한현금유입액 | C31: 460481000 | D31: 4355092000 | E31: 4428322000 | F31: 3983569000 | G31: 1310645000 | H31: 934647000 | I31: 4307524000 | J31: 261177000 | K31: 821569000 | L31: 292796000 | M31: 5378915000 | N31: 1192585000 | O31: 320899000 | P31: 304312000 | Q31: 9671496000 | R31: 7297299000 | S31: 4173648000 | T31: 529382000 | U31: 16454063000 | V31: 9209374000 | W31: 3890098000 | X31: 3979936000 | Y31: 2162776000 | Z31: 1202436000 | AA31: 365161000 | AB31: 2817096000 | AC31: 1776568000 | AD31: 1045627000 | AE31: 495213000 | AF31: 2730055000 | AG31: 2198424000 | AH31: 1362864000 | AI31: 910185000 | AJ31: 128129000 | AK31: 186509000 | AL31: 488175000 | AM31: 125499000 | AN31: 315505706
B32: 유형자산의감소 | C32: 323000 | D32: 131754000 | E32: 122757000 | F32: 16696000 | G32: 5971000 | H32: 244897000 | I32: 221136000 | J32: 9757000 | K32: 2125000 | L32: 162120000 | M32: 109806000 | N32: 5437000 | O32: 2436000 | P32: 220097000 | Q32: 161780000 | R32: 62862000 | S32: 3479000 | T32: 198959000 | U32: 136708000 | V32: 74607000 | W32: 26575000 | X32: 15509000 | Y32: 13640000 | Z32: 10954000 | AA32: 9553000 | AB32: 35809000 | AC32: 35006000 | AD32: 25919000 | AE32: 19884000 | AF32: 14371000 | AG32: 4789000 | AH32: 5085000 | AI32: 249000 | AJ32: 127688000 | AK32: 45047000 | AL32: 74010000 | AM32: 13999000 | AN32: 278713718
B33: 무형자산의감소 | C33: 183000 | D33: 2532000 | E33: 2532000 | F33: 2532000 | H33: 3249000 | I33: 985000 | J33: 985000 | L33: 1585000 | M33: 1577000 | N33: 1577000 | O33: 238000 | P33: 7963000 | Q33: 431000 | R33: 406000 | S33: 155000 | T33: 286000 | U33: 185000 | V33: 17000 | X33: 200000 | Y33: 200000 | Z33: 200000 | AA33: 200000 | AB33: 1226000 | AC33: 4000 | AD33: 4000 | AE33: 4000 | AF33: 13946000 | AG33: 13903000 | AH33: 29000 | AI33: 5000 | AK33: 62000 | AL33: 62000 | AN33: 260561
B34: (투자활동으로인한현금유출액) | C34: 5115828000 | D34: 25783841000 | E34: 18601036000 | F34: 14348249000 | G34: 5020097000 | H34: 12853809000 | I34: 13356170000 | J34: 5642211000 | K34: 2218236000 | L34: 6523247000 | M34: 9008224000 | N34: 3519345000 | O34: 1791567000 | P34: 7429842000 | Q34: 15458073000 | R34: 11095583000 | S34: 6200724000 | T34: 6617209000 | U34: 21364105000 | V34: 12070807000 | W34: 5603544000 | X34: 8872061000 | Y34: 6081894000 | Z34: 3405975000 | AA34: 1013832000 | AB34: 7515475000 | AC34: 6103278000 | AD34: 3734789000 | AE34: 1758462000 | AF34: 6119319000 | AG34: 4859227000 | AH34: 3604378000 | AI34: 1623990000 | AJ34: 4811601000 | AK34: 4014103000 | AL34: 3149466000 | AM34: 1271442000 | AN34: 1319926643
B35: 유형자산의증가 | C35: 4349571000 | D35: 16036146000 | E35: 11757688000 | F35: 8458983000 | G35: 4317223000 | H35: 9128303000 | I35: 6852671000 | J35: 4683431000 | K35: 2018470000 | L35: 5956354000 | M35: 4600747000 | N35: 3254017000 | O35: 1649520000 | P35: 6774625000 | Q35: 5591862000 | R35: 3662230000 | S35: 1628365000 | T35: 4800722000 | U35: 3964835000 | V35: 2711828000 | W35: 1230914000 | X35: 3205797000 | Y35: 2370781000 | Z35: 1265973000 | AA35: 497484000 | AB35: 3772879000 | AC35: 3319569000 | AD35: 1919626000 | AE35: 1185377000 | AF35: 3568238000 | AG35: 2915507000 | AH35: 2066038000 | AI35: 937222000 | AJ35: 3391910000 | AK35: 2529220000 | AL35: 1418169000 | AM35: 676377000 | AN35: 1012625674
B36: 무형자산의증가 | C36: 148436000 | D36: 933139000 | E36: 613359000 | F36: 414471000 | G36: 192226000 | H36: 784911000 | I36: 622245000 | J36: 429713000 | K36: 194297000 | L36: 530375000 | M36: 375594000 | N36: 247797000 | O36: 129651000 | P36: 623743000 | Q36: 416664000 | R36: 286945000 | S36: 125580000 | T36: 336291000 | U36: 216349000 | V36: 137628000 | W36: 64887000 | X36: 301496000 | Y36: 189507000 | Z36: 129958000 | AA36: 69513000 | AB36: 159072000 | AC36: 108911000 | AD36: 66404000 | AE36: 27637000 | AF36: 176111000 | AG36: 143599000 | AH36: 93022000 | AI36: 35861000 | AJ36: 151856000 | AK36: 55914000 | AL36: 42143000 | AM36: 16986000 | AN36: 22217143
B37: 재무활동으로인한현금흐름 | C37: 807047000 | D37: -1395317000 | E37: -1691367000 | F37: 410215000 | G37: -301005000 | H37: -351906000 | I37: -362299000 | J37: -22657000 | K37: 177535000 | L37: 116876000 | M37: 135246000 | N37: 211580000 | O37: 615154000 | P37: -1462257000 | Q37: -1033290000 | R37: -681781000 | S37: -607329000 | T37: 28343000 | U37: 14181000 | V37: -185857000 | W37: 189835000 | X37: -1499989000 | Y37: -786490000 | Z37: -428021000 | AA37: -220761000 | AB37: 1917122000 | AC37: 2093463000 | AD37: 1936372000 | AE37: 1969254000 | AF37: 519133000 | AG37: 691654000 | AH37: 235182000 | AI37: 291563000 | AJ37: -1140424000 | AK37: -1258769000 | AL37: -107522000 | AM37: -252906000 | AN37: 354500854
B38: 재무활동으로인한현금유입액 | C38: 983810000 | D38: 3125721000 | E38: 2407194000 | F38: 2063692000 | G38: 298732000 | H38: 782330000 | I38: 752944000 | J38: 697115000 | K38: 344893000 | L38: 2080343000 | M38: 2081562000 | N38: 1881493000 | O38: 1421133000 | P38: 3933056000 | Q38: 3502025000 | R38: 1854550000 | S38: 883054000 | T38: 3848816000 | U38: 2541874000 | V38: 1889955000 | W38: 1347321000 | X38: 3528687000 | Y38: 2801959000 | Z38: 2032139000 | AA38: 1217425000 | AB38: 9294794000 | AC38: 7655902000 | AD38: 5820561000 | AE38: 3418164000 | AF38: 2434510000 | AG38: 2287691000 | AH38: 1376131000 | AI38: 641424000 | AJ38: 1187488000 | AK38: 1147709000 | AL38: 983304000 | AM38: 86136000 | AN38: 1302814713
B39: 사채의증가 | AJ39: 857473000 | AN39: 199161222
B40: 차입금의증가 | C40: 983810000 | D40: 3125721000 | E40: 2407194000 | F40: 2063692000 | G40: 298732000 | H40: 782330000 | I40: 752944000 | J40: 697115000 | K40: 344893000 | L40: 2080343000 | M40: 2081562000 | N40: 1881493000 | O40: 1421133000 | P40: 3933056000 | Q40: 3502025000 | R40: 1854550000 | S40: 883054000 | T40: 3848816000 | U40: 2541874000 | V40: 1889955000 | W40: 1347321000 | X40: 3528687000 | Y40: 2801959000 | Z40: 2032139000 | AA40: 1217425000 | AB40: 6966003000 | AC40: 5327800000 | AD40: 3492459000 | AE40: 1092187000 | AF40: 2434510000 | AG40: 2287691000 | AH40: 1376131000 | AI40: 641424000 | AJ40: 1187488000 | AK40: 1147679000 | AL40: 983274000 | AM40: 86123000 | AN40: 14114000
B41: (재무활동으로인한현금유출액) | C41: 176763000 | D41: 3815036000 | E41: 3392559000 | F41: 947475000 | G41: 599737000 | H41: 710635000 | I41: 691642000 | J41: 296171000 | K41: 167358000 | L41: 1610466000 | M41: 1593315000 | N41: 1316912000 | O41: 805979000 | P41: 5176912000 | Q41: 4316914000 | R41: 2317930000 | S41: 1490383000 | T41: 3820473000 | U41: 2527693000 | V41: 2075812000 | W41: 1157486000 | X41: 5028676000 | Y41: 3588449000 | Z41: 2460160000 | AA41: 1438186000 | AB41: 7377672000 | AC41: 5562439000 | AD41: 3884189000 | AE41: 1448910000 | AF41: 1826836000 | AG41: 1507496000 | AH41: 1052408000 | AI41: 349861000 | AJ41: 2327912000 | AK41: 2406478000 | AL41: 1090826000 | AM41: 339042000 | AN41: 948313859
B42: 사채의감소
B43: 차입금의감소 | C43: 109224000 | D43: 2078522000 | E43: 1656045000 | F43: 947475000 | G43: 599737000 | H43: 710635000 | I43: 691642000 | J43: 296171000 | K43: 167358000 | L43: 1610466000 | M43: 1593315000 | N43: 1316912000 | O43: 805979000 | P43: 4405023000 | Q43: 3563291000 | R43: 2317930000 | S43: 1490383000 | T43: 3820449000 | U43: 2527669000 | V43: 2075788000 | W43: 1157486000 | X43: 5028676000 | Y43: 3588449000 | Z43: 2460160000 | AA43: 1438186000 | AB43: 7377491000 | AC43: 5562258000 | AD43: 3884189000 | AE43: 1448910000 | AF43: 1826595000 | AG43: 1507496000 | AH43: 1052408000 | AI43: 349620000 | AJ43: 3231747000 | AK43: 1899306000 | AL43: 1090826000 | AM43: 339042000 | AN43: 591046217
...

Sheet 자본변동표
B2: 종목코드 | C2: =재무상태표!C2 -> 000660 | E2: 시작일 | F2: =재무상태표!F2 -> 39970 | H2: 연결기준 | I2: =재무상태표!I2 -> 연결
B3: 종목명 | C3: =재무상태표!C3 -> SK하이닉스 | E3: 종료일 | F3: =재무상태표!F3 -> 43616 | H3: 누적기준 | I3: =재무상태표!I3 -> 누적
H4: 분기 | I4: =재무상태표!I4 -> 연속
B7: =_xll.IMDH("STK",$C$2,B8:B25,$F$2,$F$3,9999,"Per=일,sort=D,real=true,Bizday=0,Quote=종가,Pos=11,Orient=H,Cons="&$I$2&",Comp="&$I$3&",Trai="&I4&",Title="&$C$3&",DtFmt=1,TmFmt=1,unit=true") -> SK하이닉스
B8: 일자 | C8: 43555 | D8: 43465 | E8: 43373 | F8: 43281 | G8: 43190 | H8: 43100 | I8: 43008 | J8: 42916 | K8: 42825 | L8: 42735 | M8: 42643 | N8: 42551 | O8: 42460 | P8: 42369 | Q8: 42277 | R8: 42185 | S8: 42094 | T8: 42004 | U8: 41912 | V8: 41820 | W8: 41729 | X8: 41639 | Y8: 41547 | Z8: 41455 | AA8: 41364 | AB8: 41274 | AC8: 41182 | AD8: 41090 | AE8: 40999 | AF8: 40908 | AG8: 40816 | AH8: 40724 | AI8: 40633 | AJ8: 40543 | AK8: 40178
B9: 기말자본금 | C9: 3657652000 | D9: 3657652000 | E9: 3657652000 | F9: 3657652000 | G9: 3657652000 | H9: 3657652000 | I9: 3657652000 | J9: 3657652000 | K9: 3657652000 | L9: 3657652000 | M9: 3657652000 | N9: 3657652000 | O9: 3657652000 | P9: 3657652000 | Q9: 3657652000 | R9: 3657652000 | S9: 3657652000 | T9: 3657652000 | U9: 3649675000 | V9: 3598249000 | W9: 3568645000 | X9: 3568645000 | Y9: 3568645000 | Z9: 3491225000 | AA9: 3488467000 | AB9: 3488419000 | AC9: 3488252000 | AD9: 3488252000 | AE9: 3487768000 | AF9: 2978498000 | AG9: 2978498000 | AH9: 2978498000 | AI9: 2971195000 | AJ9: 2969023000 | AK9: 2965833030
B10: 기초자본금 | C10: 3657652000 | D10: 3657652000 | E10: 3657652000 | F10: 3657652000 | G10: 3657652000 | H10: 3657652000 | I10: 3657652000 | J10: 3657652000 | K10: 3657652000 | L10: 3657652000 | M10: 3657652000 | N10: 3657652000 | O10: 3657652000 | P10: 3657652000 | Q10: 3657652000 | R10: 3657652000 | S10: 3657652000 | T10: 3568645000 | U10: 3568645000 | V10: 3568645000 | W10: 3568645000 | X10: 3488419000 | Y10: 3488419000 | Z10: 3488419000 | AA10: 3488419000 | AB10: 2978498000 | AC10: 2978498000 | AD10: 2978498000 | AE10: 2978498000 | AF10: 2969023000 | AG10: 2969023000 | AH10: 2969023000 | AI10: 2969023000 | AJ10: 2965833000 | AK10: 2315654175
B11: 유상증자 | AB11: 509250000 | AC11: 509250000 | AD11: 509250000 | AE11: 509250000 | AK11: 650000000
B12: 무상증자
B13: 주식매수선택권 | AB13: 619000 | AC13: 468000 | AD13: 468000 | AJ13: 13000 | AK13: 133000
B14: 전환사채 | T14: 82214000 | U14: 74237000 | V14: 22811000 | X14: 80226000 | Y14: 80226000 | Z14: 2806000 | AA14: 48000 | AB14: 52000 | AC14: 36000 | AD14: 36000 | AE14: 20000 | AF14: 9475000 | AG14: 9475000 | AH14: 9475000 | AI14: 2172000 | AJ14: 3177000 | AK14: 45855
B15: 신주인수권부사채
B16: 기말자본잉여금 | C16: 4143736000 | D16: 4143736000 | E16: 4143736000 | F16: 4143736000 | G16: 4143736000 | H16: 4143736000 | I16: 4143736000 | J16: 4143736000 | K16: 4143736000 | L16: 4143736000 | M16: 4143736000 | N16: 4143736000 | O16: 4143736000 | P16: 4143736000 | Q16: 4143736000 | R16: 4143736000 | S16: 4143736000 | T16: 4143736000 | U16: 4081272000 | V16: 3646702000 | W16: 3406083000 | X16: 3406083000 | Y16: 3406148000 | Z16: 3066076000 | AA16: 3054075000 | AB16: 3053874000 | AC16: 3049173000 | AD16: 3049248000 | AE16: 3045857000 | AF16: 1229052000 | AG16: 1230979000 | AH16: 1230979000 | AI16: 1203046000 | AJ16: 1193100000 | AK16: 1303527701
