Workbook

Sheet cal
B2: [2311] 스왑포인트 vs. 내재금리
B4: 일자 | C4: 45624
C6: 결제일 | D6: 일수 | E6: MID | F6: 시장 금리 | G6: 미국 금리 | H6: 내재 금리 | I6: 시장-내재 | M6: 시장 금리 | O6: 미국
B7: SPOT | C7: {=_xll.IMDP("FX", $R7, C$6, $C$4, "DtFmt=1")} -> 45628 | E7: {=IF( $C$4=TODAY(), _xll.IMDP("FX", $R7, "중간값", $C$4, "DtFmt=1"), _xll.IMDP("FX", $R7, "현재가", $C$4, "DtFmt=1") )} -> 1395.6 | L7: ON | M7: {=_xll.IMDP("IR", "CALLALLX00", "최종이율", $C$4)} -> 3.057 | N7: 콜 거래 종합 | R7: {=INDEX(option!$B$14:$B$17, option!$B$2, 0)} -> USDSP_SMBCC | S7: #N/A
B8: =IF(option!$D$13, "TN", "ON") -> TN | C8: {=_xll.IMDP("FX", $R8, C$6, $C$4, "DtFmt=1")} -> 45628 | D8: =IFERROR( C8-IF(option!$D$13, $C$7, $C$4), "") -> 0 | E8: {=_xll.IMDP("FX", $R8, "중간값", $C$4, "DtFmt=1")} -> 13 | F8: =$M$7 -> 3.057 | G8: {=IF(option!$J$11=1, _xll.IMDP("ECO", cal!$S8, "현재가", $C$4, "fill=true"), _xll.IMDP("IR", $S8, "MID", $C$4, "fill=true"))} -> 4.58 | H8: =IFERROR( ( $E8/100/$E$7 * (365/$D8) + $G8/100 ) *100, "") | I8: =IFERROR( (F8-H8) * 100, "") | L8: 3M | M8: {=_xll.IMDP("IR", "BONDKSDCAL08", "대표수익률", $C$4)} -> 3.29 | N8: CD91 (금투협) | R8: =IF(option!$B$2>2, option!$E14, option!$D14) -> USDTN_SMBCC | S8: {=INDEX(option!$J14:$K14, 1, option!$J$11)} -> IRSTA6USD00D
B9: 1W | C9: {=_xll.IMDP("FX", $R9, C$6, $C$4, "DtFmt=1")} -> 45635 | D9: =IFERROR( C9-$C$7, "") -> 7 | E9: {=_xll.IMDP("FX", $R9, "중간값", $C$4, "DtFmt=1")} -> -20 | F9: =IFERROR( FORECAST( $D9, option!$H$14:$H$15, option!$G$14:$G$15), "") -> 3.0725333 | G9: {=IF(ISNA($S9), FORECAST($D9, option!$N$14:$N$15, option!$M$14:$M$15),_xll.IMDP("IR", $S9, "MID", $C$4, "fill=true"))} -> 4.594 | H9: =IFERROR( ( $E9/100/$E$7 * (365/$D9) + $G9/100 ) *100, "") -> 3.8467536 | I9: =IFERROR( (F9-H9) * 100, "") -> -77.422022 | L9: 1Y | M9: {=_xll.IMDP("IR", option!$H$2, "대표수익률", $C$4)} -> 2.756 | R9: =IF(option!$B$2>2, option!$E15, option!$D15) -> USD1W_SMBCC | S9: {=INDEX(option!$J15:$K15, 1, option!$K$11)} -> IRSTA6USD01W
B10: 1M | C10: {=_xll.IMDP("FX", $R10, C$6, $C$4, "DtFmt=1")} -> 45659 | D10: =IFERROR( C10-$C$7, "") -> 31 | E10: {=_xll.IMDP("FX", $R10, "중간값", $C$4, "DtFmt=1")} -> -145 | F10: =IFERROR( FORECAST( $D10, option!$H$14:$H$15, option!$G$14:$G$15), "") -> 3.1346667 | G10: {=_xll.IMDP("IR", $S10, "MID", $C$4, "fill=true")} -> 4.54 | H10: =IFERROR( ( $E10/100/$E$7 * (365/$D10) + $G10/100 ) *100, "") -> 3.3166853 | I10: =IFERROR( (F10-H10) * 100, "") -> -18.201858 | R10: =IF(option!$B$2>2, option!$E16, option!$D16) -> USD1M_SMBCC | S10: {=INDEX(option!$J16:$K16, 1, option!$K$11)} -> IRSTA6USD01M
B11: 2M | C11: {=_xll.IMDP("FX", $R11, C$6, $C$4, "DtFmt=1")} -> 45691 | D11: =IFERROR( C11-$C$7, "") -> 63 | E11: {=_xll.IMDP("FX", $R11, "중간값", $C$4, "DtFmt=1")} -> -335 | F11: =IFERROR( FORECAST( $D11, option!$H$14:$H$15, option!$G$14:$G$15), "") -> 3.2175111 | G11: {=_xll.IMDP("IR", $S11, "MID", $C$4, "fill=true")} -> 4.497 | H11: =IFERROR( ( $E11/100/$E$7 * (365/$D11) + $G11/100 ) *100, "") -> 3.1062913 | I11: =IFERROR( (F11-H11) * 100, "") -> 11.121978 | R11: =IF(option!$B$2>2, option!$E17, option!$D17) -> USD2M_SMBCC | S11: {=INDEX(option!$J17:$K17, 1, option!$K$11)} -> IRSTA6USD02M
B12: 3M | C12: {=_xll.IMDP("FX", $R12, C$6, $C$4, "DtFmt=1")} -> 45720 | D12: =IFERROR( C12-$C$7, "") -> 92 | E12: {=_xll.IMDP("FX", $R12, "중간값", $C$4, "DtFmt=1")} -> -535 | F12: =$M$8 -> 3.29 | G12: {=_xll.IMDP("IR", $S12, "MID", $C$4, "fill=true")} -> 4.469 | H12: =IFERROR( ( $E12/100/$E$7 * (365/$D12) + $G12/100 ) *100, "") -> 2.9481098 | I12: =IFERROR( (F12-H12) * 100, "") -> 34.189019 | R12: =IF(option!$B$2>2, option!$E18, option!$D18) -> USD3M_SMBCC | S12: {=INDEX(option!$J18:$K18, 1, option!$K$11)} -> IRSTA6USD03M
B13: 6M | C13: {=_xll.IMDP("FX", $R13, C$6, $C$4, "DtFmt=1")} -> 45810 | D13: =IFERROR( C13-$C$7, "") -> 182 | E13: {=_xll.IMDP("FX", $R13, "중간값", $C$4, "DtFmt=1")} -> -1240 | F13: =IFERROR( FORECAST( $D13, option!$H$15:$H$16, option!$G$15:$G$16), "") -> 3.1126496 | G13: {=_xll.IMDP("IR", $S13, "MID", $C$4, "fill=true")} -> 4.392 | H13: =IFERROR( ( $E13/100/$E$7 * (365/$D13) + $G13/100 ) *100, "") -> 2.6101046 | I13: =IFERROR( (F13-H13) * 100, "") -> 50.254501 | R13: =IF(option!$B$2>2, option!$E19, option!$D19) -> USD6M_SMBCC | S13: {=INDEX(option!$J19:$K19, 1, option!$K$11)} -> IRSTA6USD06M
B14: 1Y | C14: {=_xll.IMDP("FX", $R14, C$6, $C$4, "DtFmt=1")} -> 45993 | D14: =IFERROR( C14-$C$7, "") -> 365 | E14: {=_xll.IMDP("FX", $R14, "중간값", $C$4, "DtFmt=1")} -> -2590 | F14: =$M$9 -> 2.756 | G14: {=_xll.IMDP("IR", $S14, "MID", $C$4, "fill=true")} -> 4.265 | H14: =IFERROR( ( $E14/100/$E$7 * (365/$D14) + $G14/100 ) *100, "") -> 2.4091674 | I14: =IFERROR( (F14-H14) * 100, "") -> 34.683262 | R14: =IF(option!$B$2>2, option!$E20, option!$D20) -> USD1Y_SMBCC | S14: {=INDEX(option!$J20:$K20, 1, option!$K$11)} -> IRSTA6USD01Y
B16: 일자 | C16: =$E$16-90 -> 45534 | D16: ~ | E16: =$C$4 -> 45624
B18: 일자 | C18: 결제일 | D18: 일수 | E18: MID | F18: 시장 금리 | G18: 미국 금리 | H18: 내재 금리 | I18: 시장-내재
B19: =IF( OR(history!$F7 ="",history!$F7 <$C$16), "", history!$F7 ) -> 45624 | C19: =IF( OR(history!$I7 ="",history!$F7 <$C$16), "", history!$I7 ) -> 45720 | D19: =IF($B19="", "", history!J7) -> 92 | E19: =IF( OR(history!$H7 ="",history!$F7 <$C$16), "", history!$H7 ) -> -535 | F19: =IFERROR( VLOOKUP($B19, history!$F$7:$S$73, 14, 0), "") -> 3.29 | G19: =IFERROR( VLOOKUP($B19, history!$F$7:$W$73, 18, 0), "") -> 4.469 | H19: =IFERROR( ( $E19/100/VLOOKUP($B19, history!$A$7:$C$106, 3, 0) * (365/$D19) + $G19/100 ) * 100, "") -> 2.9481098 | I19: =IFERROR( (F19-H19) * 100, "") -> 34.189019
B20: =IF( OR(history!$F8 ="",history!$F8 <$C$16), "", history!$F8 ) -> 45623 | C20: =IF( OR(history!$I8 ="",history!$F8 <$C$16), "", history!$I8 ) -> 45716 | D20: =IF($B20="", "", history!J8) -> 91 | E20: =IF( OR(history!$H8 ="",history!$F8 <$C$16), "", history!$H8 ) -> -495 | F20: =IFERROR( VLOOKUP($B20, history!$F$7:$S$73, 14, 0), "") -> 3.44 | G20: =IFERROR( VLOOKUP($B20, history!$F$7:$W$73, 18, 0), "") -> 4.469 | H20: =IFERROR( ( $E20/100/VLOOKUP($B20, history!$A$7:$C$106, 3, 0) * (365/$D20) + $G20/100 ) * 100, "") -> 3.0477834 | I20: =IFERROR( (F20-H20) * 100, "") -> 39.221658
B21: =IF( OR(history!$F9 ="",history!$F9 <$C$16), "", history!$F9 ) -> 45622 | C21: =IF( OR(history!$I9 ="",history!$F9 <$C$16), "", history!$I9 ) -> 45716 | D21: =IF($B21="", "", history!J9) -> 91 | E21: =IF( OR(history!$H9 ="",history!$F9 <$C$16), "", history!$H9 ) -> -500 | F21: =IFERROR( VLOOKUP($B21, history!$F$7:$S$73, 14, 0), "") -> 3.44 | G21: =IFERROR( VLOOKUP($B21, history!$F$7:$W$73, 18, 0), "") -> 4.482 | H21: =IFERROR( ( $E21/100/VLOOKUP($B21, history!$A$7:$C$106, 3, 0) * (365/$D21) + $G21/100 ) * 100, "") -> 3.0476598 | I21: =IFERROR( (F21-H21) * 100, "") -> 39.234023
B22: =IF( OR(history!$F10 ="",history!$F10 <$C$16), "", history!$F10 ) -> 45621 | C22: =IF( OR(history!$I10 ="",history!$F10 <$C$16), "", history!$I10 ) -> 45715 | D22: =IF($B22="", "", history!J10) -> 92 | E22: =IF( OR(history!$H10 ="",history!$F10 <$C$16), "", history!$H10 ) -> -535 | F22: =IFERROR( VLOOKUP($B22, history!$F$7:$S$73, 14, 0), "") -> 3.44 | G22: =IFERROR( VLOOKUP($B22, history!$F$7:$W$73, 18, 0), "") -> 4.514 | H22: =IFERROR( ( $E22/100/VLOOKUP($B22, history!$A$7:$C$106, 3, 0) * (365/$D22) + $G22/100 ) * 100, "") -> 3.0002685 | I22: =IFERROR( (F22-H22) * 100, "") -> 43.973153
B23: =IF( OR(history!$F11 ="",history!$F11 <$C$16), "", history!$F11 ) -> 45618 | C23: =IF( OR(history!$I11 ="",history!$F11 <$C$16), "", history!$I11 ) -> 45714 | D23: =IF($B23="", "", history!J11) -> 92 | E23: =IF( OR(history!$H11 ="",history!$F11 <$C$16), "", history!$H11 ) -> -560 | F23: =IFERROR( VLOOKUP($B23, history!$F$7:$S$73, 14, 0), "") -> 3.44 | G23: =IFERROR( VLOOKUP($B23, history!$F$7:$W$73, 18, 0), "") -> 4.527 | H23: =IFERROR( ( $E23/100/VLOOKUP($B23, history!$A$7:$C$106, 3, 0) * (365/$D23) + $G23/100 ) * 100, "") -> 2.9420812 | I23: =IFERROR( (F23-H23) * 100, "") -> 49.791877
B24: =IF( OR(history!$F12 ="",history!$F12 <$C$16), "", history!$F12 ) -> 45617 | C24: =IF( OR(history!$I12 ="",history!$F12 <$C$16), "", history!$I12 ) -> 45713 | D24: =IF($B24="", "", history!J12) -> 92 | E24: =IF( OR(history!$H12 ="",history!$F12 <$C$16), "", history!$H12 ) -> -555 | F24: =IFERROR( VLOOKUP($B24, history!$F$7:$S$73, 14, 0), "") -> 3.44 | G24: =IFERROR( VLOOKUP($B24, history!$F$7:$W$73, 18, 0), "") -> 4.521 | H24: =IFERROR( ( $E24/100/VLOOKUP($B24, history!$A$7:$C$106, 3, 0) * (365/$D24) + $G24/100 ) * 100, "") -> 2.9453992 | I24: =IFERROR( (F24-H24) * 100, "") -> 49.460084
B25: =IF( OR(history!$F13 ="",history!$F13 <$C$16), "", history!$F13 ) -> 45616 | C25: =IF( OR(history!$I13 ="",history!$F13 <$C$16), "", history!$I13 ) -> 45712 | D25: =IF($B25="", "", history!J13) -> 94 | E25: =IF( OR(history!$H13 ="",history!$F13 <$C$16), "", history!$H13 ) -> -560 | F25: =IFERROR( VLOOKUP($B25, history!$F$7:$S$73, 14, 0), "") -> 3.44 | G25: =IFERROR( VLOOKUP($B25, history!$F$7:$W$73, 18, 0), "") -> 4.524 | H25: =IFERROR( ( $E25/100/VLOOKUP($B25, history!$A$7:$C$106, 3, 0) * (365/$D25) + $G25/100 ) * 100, "") -> 2.9606467 | I25: =IFERROR( (F25-H25) * 100, "") -> 47.935329
B26: =IF( OR(history!$F14 ="",history!$F14 <$C$16), "", history!$F14 ) -> 45615 | C26: =IF( OR(history!$I14 ="",history!$F14 <$C$16), "", history!$I14 ) -> 45709 | D26: =IF($B26="", "", history!J14) -> 92 | E26: =IF( OR(history!$H14 ="",history!$F14 <$C$16), "", history!$H14 ) -> -560 | F26: =IFERROR( VLOOKUP($B26, history!$F$7:$S$73, 14, 0), "") -> 3.44 | G26: =IFERROR( VLOOKUP($B26, history!$F$7:$W$73, 18, 0), "") -> 4.521 | H26: =IFERROR( ( $E26/100/VLOOKUP($B26, history!$A$7:$C$106, 3, 0) * (365/$D26) + $G26/100 ) * 100, "") -> 2.9236608 | I26: =IFERROR( (F26-H26) * 100, "") -> 51.633923
B27: =IF( OR(history!$F15 ="",history!$F15 <$C$16), "", history!$F15 ) -> 45614 | C27: =IF( OR(history!$I15 ="",history!$F15 <$C$16), "", history!$I15 ) -> 45708 | D27: =IF($B27="", "", history!J15) -> 92 | E27: =IF( OR(history!$H15 ="",history!$F15 <$C$16), "", history!$H15 ) -> -550 | F27: =IFERROR( VLOOKUP($B27, history!$F$7:$S$73, 14, 0), "") -> 3.44 | G27: =IFERROR( VLOOKUP($B27, history!$F$7:$W$73, 18, 0), "") -> 4.52 | H27: =IFERROR( ( $E27/100/VLOOKUP($B27, history!$A$7:$C$106, 3, 0) * (365/$D27) + $G27/100 ) * 100, "") -> 2.9560198 | I27: =IFERROR( (F27-H27) * 100, "") -> 48.398023
B28: =IF( OR(history!$F16 ="",history!$F16 <$C$16), "", history!$F16 ) -> 45611 | C28: =IF( OR(history!$I16 ="",history!$F16 <$C$16), "", history!$I16 ) -> 45707 | D28: =IF($B28="", "", history!J16) -> 92 | E28: =IF( OR(history!$H16 ="",history!$F16 <$C$16), "", history!$H16 ) -> -535 | F28: =IFERROR( VLOOKUP($B28, history!$F$7:$S$73, 14, 0), "") -> 3.44 | G28: =IFERROR( VLOOKUP($B28, history!$F$7:$W$73, 18, 0), "") -> 4.519 | H28: =IFERROR( ( $E28/100/VLOOKUP($B28, history!$A$7:$C$106, 3, 0) * (365/$D28) + $G28/100 ) * 100, "") -> 3.0015891 | I28: =IFERROR( (F28-H28) * 100, "") -> 43.841089
B29: =IF( OR(history!$F17 ="",history!$F17 <$C$16), "", history!$F17 ) -> 45610 | C29: =IF( OR(history!$I17 ="",history!$F17 <$C$16), "", history!$I17 ) -> 45706 | D29: =IF($B29="", "", history!J17) -> 92 | E29: =IF( OR(history!$H17 ="",history!$F17 <$C$16), "", history!$H17 ) -> -500 | F29: =IFERROR( VLOOKUP($B29, history!$F$7:$S$73, 14, 0), "") -> 3.44 | G29: =IFERROR( VLOOKUP($B29, history!$F$7:$W$73, 18, 0), "") -> 4.519 | H29: =IFERROR( ( $E29/100/VLOOKUP($B29, history!$A$7:$C$106, 3, 0) * (365/$D29) + $G29/100 ) * 100, "") -> 3.1072175 | I29: =IFERROR( (F29-H29) * 100, "") -> 33.278254
B30: =IF( OR(history!$F18 ="",history!$F18 <$C$16), "", history!$F18 ) -> 45609 | C30: =IF( OR(history!$I18 ="",history!$F18 <$C$16), "", history!$I18 ) -> 45706 | D30: =IF($B30="", "", history!J18) -> 95 | E30: =IF( OR(history!$H18 ="",history!$F18 <$C$16), "", history!$H18 ) -> -550 | F30: =IFERROR( VLOOKUP($B30, history!$F$7:$S$73, 14, 0), "") -> 3.44 | G30: =IFERROR( VLOOKUP($B30, history!$F$7:$W$73, 18, 0), "") -> 4.485 | H30: =IFERROR( ( $E30/100/VLOOKUP($B30, history!$A$7:$C$106, 3, 0) * (365/$D30) + $G30/100 ) * 100, "") -> 2.9826839 | I30: =IFERROR( (F30-H30) * 100, "") -> 45.731615
... B118: =IF( OR(history!$F106 ="",history!$F106 <$C$16), "", history!$F106 ) | C118: =IF( OR(history!$I106 ="",history!$F106 <$C$16), "", history!$I106 ) | D118: =IF($B118="", "", history!J106) | E118: =IF( OR(history!$H106 ="",history!$F106 <$C$16), "", history!$H106 ) | F118: =IFERROR( VLOOKUP($B118, history!$F$7:$S$73, 14, 0), "") | G118: =IFERROR( VLOOKUP($B118, history!$F$7:$W$73, 18, 0), "") | H118: =IFERROR( ( $E118/100/VLOOKUP($B118, history!$A$7:$C$106, 3, 0) * (365/$D118) + $G118/100 ) * 100, "") | I118: =IFERROR( (F118-H118) * 100, "")

Sheet option
D1: {=INDEX(cal!$R$8:$R$14, $D$2)} -> USD3M_SMBCC
B2: 1 | D2: 5 | G2: 2 | H2: {=INDEX($H$3:$H$4, $G$2)} -> BONDKSDCAL02
B3: 서울외환 (15:30) | D3: ON | G3: 국고 (금투협) | H3: BONDKSDCAL10
B4: 서울외환 (익일 02:00 | D4: 1W | G4: 통안 (금투협) | H4: BONDKSDCAL02
B5: 한국자금 (15:30) | D5: 1M
B6: 한국자금 (익일 02:00 | D6: 2M | H6: BONDKSDCAL19
D7: 3M | H7: BONDKSDCAL03
D8: 6M | H8: {=INDEX($H$6:$H$7,$G$2)} -> BONDKSDCAL03
D9: 1Y
J11: 2 | K11: 2
J12: SOFR | K12: 유통
D13: {=_xll.IMDP("FX", "USDON_SMBCC", "매수호가", cal!$C$4) =""} -> TRUE | J13: OIS | K13: OIS
B14: USDSP_SMBCC | C14: USDON_SMBCC | D14: =IF( $D$13, "USDTN_SMBCC", "USDON_SMBCC" ) -> USDTN_SMBCC | E14: =$D$14 -> USDTN_SMBCC | G14: 1 | H14: =cal!M7 -> 3.057 | J14: 761212 | K14: =IF( $D$13, "IRSTA6USD00D", "IRSTA6USD01D" ) -> IRSTA6USD00D | M14: =cal!D8 -> 0 | N14: =cal!G8 -> 4.58
B15: USDSP_SMBCC_EXT | C15: =cal!R9 -> USD1W_SMBCC | D15: USD1W_SMBCC | E15: USD1W_KMBCC | G15: 91 | H15: =cal!M8 -> 3.29 | J15: #N/A | K15: IRSTA6USD01W | M15: =cal!D10 -> 31 | N15: =cal!G10 -> 4.54
B16: USDSP_KMBCC | C16: =cal!R10 -> USD1M_SMBCC | D16: USD1M_SMBCC | E16: USD1M_KMBCC | G16: 365 | H16: =cal!M9 -> 2.756 | J16: US01M | K16: IRSTA6USD01M
B17: USDSP_KMBCC_EXT | C17: =cal!R11 -> USD2M_SMBCC | D17: USD2M_SMBCC | E17: USD2M_KMBCC | G17: 730 | H17: {=_xll.IMDP("IR", $H$8, "대표수익률", cal!$C$4)} -> 2.719 | J17: US02M | K17: IRSTA6USD02M
C18: =cal!R12 -> USD3M_SMBCC | D18: USD3M_SMBCC | E18: USD3M_KMBCC | J18: US03M | K18: IRSTA6USD03M
C19: =cal!R13 -> USD6M_SMBCC | D19: USD6M_SMBCC | E19: USD6M_KMBCC | J19: US06M | K19: IRSTA6USD06M
C20: =cal!R14 -> USD1Y_SMBCC | D20: USD1Y_SMBCC | E20: USD1Y_KMBCC | J20: US01Y | K20: IRSTA6USD01Y

Sheet history
A1: 시작 | B1: =MAX( cal!$C$16-10, $A$3) -> 45524 | C1: 종료 | D1: =cal!$E$16 -> 45624 | E1: Data 개수 | F1: =D1-B1+20 -> 120 | G1: 주기 | H1: 일 | I1: 정렬 | J1: D | K1: 영업일 | L1: 0 | M1: 시세산출 | N1: 종가
C2: 스팟 고정 | H2: 선택 | AE2: 국내1 | AF2: 국내2 | AG2: 국내3 | AH2: 국내4 | AI2: 선택 | AJ2: 미국1 | AK2: 미국2
A3: 43831 | C3: FX | H3: FX | Y3: FX | AA3: FX | AE3: IR | AF3: IR | AG3: IR | AH3: IR | AI3: =IF(AND( option!$J$11=1, option!$D$2=1), "ECO", "IR") -> IR | AJ3: =IF( option!$J$11=1, "ECO", "IR") -> IR | AK3: IR
C4: =cal!$R$7 -> USDSP_SMBCC | H4: {=INDEX(option!$C$14:$C$20, option!$D$2, 0)} -> USD3M_SMBCC | Y4: USDON_SMBCC | AA4: USDTN_SMBCC | AE4: CALLALLX00 | AF4: BONDKSDCAL08 | AG4: =option!$H$2 -> BONDKSDCAL02 | AH4: =option!$H$8 -> BONDKSDCAL03 | AI4: {=INDEX(cal!$S$8:$S$14, option!$D$2)} -> IRSTA6USD03M | AJ4: =cal!$S$8 -> IRSTA6USD00D | AK4: =cal!$S$10 -> IRSTA6USD01M
A5: {=_xll.IMDH(C3, C4, A6:C6, $B$1, $D$1, $F$1, "Per="&$H$1&", sort="&$J$1&", real=true, Bizday="&$L$1&", Quote="&$N$1&", Pos=20, Orient=V, DtFmt=1, TmFmt=1, unit=true")} -> 조회[USDSP_SMBCC] | F5: {=_xll.IMDH(H3, H4, F6:H6, $B$1, $D$1, $F$1, "Per="&$H$1&", sort="&$J$1&", real=true, Bizday="&$L$1&", Quote="&$N$1&", Pos=20, Orient=V, DtFmt=1, TmFmt=1, unit=true")} -> 조회[USD3M_SMBCC] | U5: 0 | V5: 30 | W5: =AND(option!$D$2=2, option!$K$11=1) -> FALSE | X5: {=_xll.IMDH(Y3, Y4, X6:Y6, $B$1-20, $D$1, $F$1, "Per="&$H$1&", sort="&$J$1&", real=true, Bizday="&$L$1&", Quote="&$N$1&", Pos=20, Orient=V, DtFmt=1, TmFmt=1, unit=true")} -> 조회[USDON_SMBCC] | Z5: {=_xll.IMDH(AA3, AA4, Z6:AA6, $B$1-20, $D$1, $F$1, "Per="&$H$1&", sort="&$J$1&", real=true, Bizday="&$L$1&", Quote="&$N$1&", Pos=20, Orient=V, DtFmt=1, TmFmt=1, unit=true")} -> 조회[USDTN_SMBCC] | AD5: {=_xll.IMDH(AE3, AE4, AD6:AE6, $B$1-20, $D$1, $F$1, "Per="&$H$1&", sort="&$J$1&", real=true, Bizday=2, Quote="&$N$1&", Pos=20, Orient=V, DtFmt=1, TmFmt=1, unit=true")} -> 조회[CALLALLX00] | AF5: {=_xll.IMDH(AF3, AF4, AF6:AF6, $B$1-20, $D$1, $F$1, "Per="&$H$1&", sort="&$J$1&", real=true, Bizday=2, Quote="&$N$1&", Pos=20, Orient=V, DtFmt=1, TmFmt=1, unit=true")} -> 조회[BONDKSDCAL08] | AG5: {=_xll.IMDH(AG3, AG4, AG6:AG6, $B$1-20, $D$1, $F$1, "Per="&$H$1&", sort="&$J$1&", real=true, Bizday=2, Quote="&$N$1&", Pos=20, Orient=V, DtFmt=1, TmFmt=1, unit=true")} -> 조회[BONDKSDCAL02] | AH5: {=_xll.IMDH(AH3, AH4, AH6:AH6, $B$1-20, $D$1, $F$1, "Per="&$H$1&", sort="&$J$1&", real=true, Bizday=2, Quote="&$N$1&", Pos=20, Orient=V, DtFmt=1, TmFmt=1, unit=true")} -> 조회[BONDKSDCAL03] | AI5: {=_xll.IMDH(AI3, AI4, AI6:AI6, $B$1-20, $D$1, $F$1, "Per="&$H$1&", sort="&$J$1&", real=true, Bizday=2, Quote="&$N$1&", Pos=20, Orient=V, DtFmt=1, TmFmt=1, unit=true")} -> 조회[IRSTA6USD03M] | AJ5: {=_xll.IMDH(AJ3, AJ4, AJ6:AJ6, $B$1-20, $D$1, $F$1, "Per="&$H$1&", sort="&$J$1&", real=true, Bizday=2, Quote="&$N$1&", Pos=20, Orient=V, DtFmt=1, TmFmt=1, unit=true")} -> 조회[IRSTA6USD00D] | AK5: {=_xll.IMDH(AK3, AK4, AK6:AK6, $B$1-20, $D$1, $F$1, "Per="&$H$1&", sort="&$J$1&", real=true, Bizday=2, Quote="&$N$1&", Pos=20, Orient=V, DtFmt=1, TmFmt=1, unit=true")} -> 조회[IRSTA6USD01M]
A6: 일자 | B6: 결제일 | C6: 현재가 | F6: 일자 | G6: 결제일 | H6: 중간값 | I6: 선택 | J6: day | K6: ON_day | O6: 국내1 | P6: 국내2 | Q6: 국내3 | R6: 국내4 | S6: 시장 | T6: 미국 | U6: 미국1 | V6: 미국2 | X6: 일자 | Y6: 결제일 | Z6: 일자 | AA6: 결제일 | AD6: 일자 | AE6: 최종이율 | AF6: 대표수익률 | AG6: 대표수익률 | AH6: 대표수익률 | AI6: =IF(AND( option!$J$11=1, option!$D$2=1), "현재가", "MID") -> MID | AJ6: =IF(option!$J$11=1, "현재가", "MID") -> MID | AK6: MID
A7: 45624 | B7: 20241202 | C7: 1395.6 | D7: =IF(B7="", "", DATE(LEFT(B7,4), MID(B7,5,2), RIGHT(B7,2))) -> 45628 | F7: 45624 | G7: 20250304 | H7: -535 | I7: =IF(G7="", "", DATE(LEFT(G7,4), MID(G7,5,2), RIGHT(G7,2))) -> 45720 | J7: =I7-D7 -> 92 | K7: =IF(AB7="", "", DATE(LEFT(AB7,4), MID(AB7,5,2), RIGHT(AB7,2)))-$F7 -> 4 | L7: 91 | M7: 365 | N7: 730 | O7: =VLOOKUP($F7, $AD$7:$AK$106, 2, 0) -> 3.057 | P7: =VLOOKUP($F7, $AD$7:$AK$106, 3, 0) -> 3.29 | Q7: =VLOOKUP($F7, $AD$7:$AK$106, 4, 0) -> 2.756 | R7: =VLOOKUP($F7, $AD$7:$AK$106, 5, 0) -> 2.719 | S7: =CHOOSE(option!$D$2, history!$O7, FORECAST(history!$J7, history!$O7:$P7, history!$K7:$L7), FORECAST(history!$J7, history!$O7:$P7, history!$K7:$L7), FORECAST(history!$J7, history!$O7:$P7, history!$K7:$L7), history!$P7, history!$Q7 ) -> 3.29 | T7: =VLOOKUP($F7, $AD$7:$AK$126, 6, 0) -> 4.469 | U7: =VLOOKUP($F7, $AD$7:$AK$126, 7, 0) -> 4.58 | V7: =VLOOKUP($F7, $AD$7:$AK$126, 8, 0) -> 4.54 | W7: =IF($W$5, FORECAST($J7,$U7:$V7,$U$5:$V$5), $T7) -> 4.469 | X7: 45623 | Y7: 20241129 | Z7: 45624 | AA7: 20241202 | AB7: =IFERROR( VLOOKUP($F7, $X$7:$Y$106, 2, 0), VLOOKUP($F7, $Z$7:$AA$106, 2, 0)) -> 20241202 | AD7: 45624 | AE7: 3.057 | AF7: 3.29 | AG7: 2.756 | AH7: 2.719 | AI7: 4.469 | AJ7: 4.58 | AK7: 4.54
A8: 45623 | B8: 20241129 | C8: 1397 | D8: =IF(B8="", "", DATE(LEFT(B8,4), MID(B8,5,2), RIGHT(B8,2))) -> 45625 | F8: 45623 | G8: 20250228 | H8: -495 | I8: =IF(G8="", "", DATE(LEFT(G8,4), MID(G8,5,2), RIGHT(G8,2))) -> 45716 | J8: =I8-D8 -> 91 | K8: =IF(AB8="", "", DATE(LEFT(AB8,4), MID(AB8,5,2), RIGHT(AB8,2)))-$F8 -> 2 | L8: 91 | M8: 365 | N8: 730 | O8: =VLOOKUP($F8, $AD$7:$AK$106, 2, 0) -> 3.263 | P8: =VLOOKUP($F8, $AD$7:$AK$106, 3, 0) -> 3.44 | Q8: =VLOOKUP($F8, $AD$7:$AK$106, 4, 0) -> 2.8 | R8: =VLOOKUP($F8, $AD$7:$AK$106, 5, 0) -> 2.817 | S8: =CHOOSE(option!$D$2, history!$O8, FORECAST(history!$J8, history!$O8:$P8, history!$K8:$L8), FORECAST(history!$J8, history!$O8:$P8, history!$K8:$L8), FORECAST(history!$J8, history!$O8:$P8, history!$K8:$L8), history!$P8, history!$Q8 ) -> 3.44 | T8: =VLOOKUP($F8, $AD$7:$AK$126, 6, 0) -> 4.469 | U8: =VLOOKUP($F8, $AD$7:$AK$126, 7, 0) -> 4.58 | V8: =VLOOKUP($F8, $AD$7:$AK$126, 8, 0) -> 4.54 | W8: =IF($W$5, FORECAST($J8,$U8:$V8,$U$5:$V$5), $T8) -> 4.469 | X8: 45622 | Y8: 20241127 | Z8: 45622 | AA8: 20241129 | AB8: =IFERROR( VLOOKUP($F8, $X$7:$Y$106, 2, 0), VLOOKUP($F8, $Z$7:$AA$106, 2, 0)) -> 20241129 | AD8: 45623 | AE8: 3.263 | AF8: 3.44 | AG8: 2.8 | AH8: 2.817 | AI8: 4.469 | AJ8: 4.58 | AK8: 4.54
A9: 45622 | B9: 20241129 | C9: 1398.2 | D9: =IF(B9="", "", DATE(LEFT(B9,4), MID(B9,5,2), RIGHT(B9,2))) -> 45625 | F9: 45622 | G9: 20250228 | H9: -500 | I9: =IF(G9="", "", DATE(LEFT(G9,4), MID(G9,5,2), RIGHT(G9,2))) -> 45716 | J9: =I9-D9 -> 91 | K9: =IF(AB9="", "", DATE(LEFT(AB9,4), MID(AB9,5,2), RIGHT(AB9,2)))-$F9 -> 1 | L9: 91 | M9: 365 | N9: 730 | O9: =VLOOKUP($F9, $AD$7:$AK$106, 2, 0) -> 3.267 | P9: =VLOOKUP($F9, $AD$7:$AK$106, 3, 0) -> 3.44 | Q9: =VLOOKUP($F9, $AD$7:$AK$106, 4, 0) -> 2.803 | R9: =VLOOKUP($F9, $AD$7:$AK$106, 5, 0) -> 2.842 | S9: =CHOOSE(option!$D$2, history!$O9, FORECAST(history!$J9, history!$O9:$P9, history!$K9:$L9), FORECAST(history!$J9, history!$O9:$P9, history!$K9:$L9), FORECAST(history!$J9, history!$O9:$P9, history!$K9:$L9), history!$P9, history!$Q9 ) -> 3.44 | T9: =VLOOKUP($F9, $AD$7:$AK$126, 6, 0) -> 4.482 | U9: =VLOOKUP($F9, $AD$7:$AK$126, 7, 0) -> 4.58 | V9: =VLOOKUP($F9, $AD$7:$AK$126, 8, 0) -> 4.549 | W9: =IF($W$5, FORECAST($J9,$U9:$V9,$U$5:$V$5), $T9) -> 4.482 | X9: 45621 | Y9: 20241126 | Z9: 45621 | AA9: 20241127 | AB9: =IFERROR( VLOOKUP($F9, $X$7:$Y$106, 2, 0), VLOOKUP($F9, $Z$7:$AA$106, 2, 0)) -> 20241127 | AD9: 45622 | AE9: 3.267 | AF9: 3.44 | AG9: 2.803 | AH9: 2.842 | AI9: 4.482 | AJ9: 4.58 | AK9: 4.549
A10: 45621 | B10: 20241127 | C10: 1402.2 | D10: =IF(B10="", "", DATE(LEFT(B10,4), MID(B10,5,2), RIGHT(B10,2))) -> 45623 | F10: 45621 | G10: 20250227 | H10: -535 | I10: =IF(G10="", "", DATE(LEFT(G10,4), MID(G10,5,2), RIGHT(G10,2))) -> 45715 | J10: =I10-D10 -> 92 | K10: =IF(AB10="", "", DATE(LEFT(AB10,4), MID(AB10,5,2), RIGHT(AB10,2)))-$F10 -> 1 | L10: 91 | M10: 365 | N10: 730 | O10: =VLOOKUP($F10, $AD$7:$AK$106, 2, 0) -> 3.29 | P10: =VLOOKUP($F10, $AD$7:$AK$106, 3, 0) -> 3.44 | Q10: =VLOOKUP($F10, $AD$7:$AK$106, 4, 0) -> 2.801 | R10: =VLOOKUP($F10, $AD$7:$AK$106, 5, 0) -> 2.845 | S10: =CHOOSE(option!$D$2, history!$O10, FORECAST(history!$J10, history!$O10:$P10, history!$K10:$L10), FORECAST(history!$J10, history!$O10:$P10, history!$K10:$L10), FORECAST(history!$J10, history!$O10:$P10, history!$K10:$L10), history!$P10, history!$Q10 ) -> 3.44 | T10: =VLOOKUP($F10, $AD$7:$AK$126, 6, 0) -> 4.514 | U10: =VLOOKUP($F10, $AD$7:$AK$126, 7, 0) -> 4.57 | V10: =VLOOKUP($F10, $AD$7:$AK$126, 8, 0) -> 4.572 | W10: =IF($W$5, FORECAST($J10,$U10:$V10,$U$5:$V$5), $T10) -> 4.514 | X10: 45618 | Y10: 20241125 | Z10: 45618 | AA10: 20241126 | AB10: =IFERROR( VLOOKUP($F10, $X$7:$Y$106, 2, 0), VLOOKUP($F10, $Z$7:$AA$106, 2, 0)) -> 20241126 | AD10: 45621 | AE10: 3.29 | AF10: 3.44 | AG10: 2.801 | AH10: 2.845 | AI10: 4.514 | AJ10: 4.57 | AK10: 4.572
A11: 45618 | B11: 20241126 | C11: 1401.8 | D11: =IF(B11="", "", DATE(LEFT(B11,4), MID(B11,5,2), RIGHT(B11,2))) -> 45622 | F11: 45618 | G11: 20250226 | H11: -560 | I11: =IF(G11="", "", DATE(LEFT(G11,4), MID(G11,5,2), RIGHT(G11,2))) -> 45714 | J11: =I11-D11 -> 92 | K11: =IF(AB11="", "", DATE(LEFT(AB11,4), MID(AB11,5,2), RIGHT(AB11,2)))-$F11 -> 3 | L11: 91 | M11: 365 | N11: 730 | O11: =VLOOKUP($F11, $AD$7:$AK$106, 2, 0) -> 3.285 | P11: =VLOOKUP($F11, $AD$7:$AK$106, 3, 0) -> 3.44 | Q11: =VLOOKUP($F11, $AD$7:$AK$106, 4, 0) -> 2.812 | R11: =VLOOKUP($F11, $AD$7:$AK$106, 5, 0) -> 2.88 | S11: =CHOOSE(option!$D$2, history!$O11, FORECAST(history!$J11, history!$O11:$P11, history!$K11:$L11), FORECAST(history!$J11, history!$O11:$P11, history!$K11:$L11), FORECAST(history!$J11, history!$O11:$P11, history!$K11:$L11), history!$P11, history!$Q11 ) -> 3.44 | T11: =VLOOKUP($F11, $AD$7:$AK$126, 6, 0) -> 4.527 | U11: =VLOOKUP($F11, $AD$7:$AK$126, 7, 0) -> 4.57 | V11: =VLOOKUP($F11, $AD$7:$AK$126, 8, 0) -> 4.581 | W11: =IF($W$5, FORECAST($J11,$U11:$V11,$U$5:$V$5), $T11) -> 4.527 | X11: 45617 | Y11: 20241122 | Z11: 45617 | AA11: 20241125 | AB11: =IFERROR( VLOOKUP($F11, $X$7:$Y$106, 2, 0), VLOOKUP($F11, $Z$7:$AA$106, 2, 0)) -> 20241125 | AD11: 45620 | AE11: 3.285 | AF11: 3.44 | AG11: 2.812 | AH11: 2.88 | AI11: 4.527 | AJ11: 4.57 | AK11: 4.581
A12: 45617 | B12: 20241125 | C12: 1397.5 | D12: =IF(B12="", "", DATE(LEFT(B12,4), MID(B12,5,2), RIGHT(B12,2))) -> 45621 | F12: 45617 | G12: 20250225 | H12: -555 | I12: =IF(G12="", "", DATE(LEFT(G12,4), MID(G12,5,2), RIGHT(G12,2))) -> 45713 | J12: =I12-D12 -> 92 | K12: =IF(AB12="", "", DATE(LEFT(AB12,4), MID(AB12,5,2), RIGHT(AB12,2)))-$F12 -> 1 | L12: 91 | M12: 365 | N12: 730 | O12: =VLOOKUP($F12, $AD$7:$AK$106, 2, 0) -> 3.271 | P12: =VLOOKUP($F12, $AD$7:$AK$106, 3, 0) -> 3.44 | Q12: =VLOOKUP($F12, $AD$7:$AK$106, 4, 0) -> 2.817 | R12: =VLOOKUP($F12, $AD$7:$AK$106, 5, 0) -> 2.892 | S12: =CHOOSE(option!$D$2, history!$O12, FORECAST(history!$J12, history!$O12:$P12, history!$K12:$L12), FORECAST(history!$J12, history!$O12:$P12, history!$K12:$L12), FORECAST(history!$J12, history!$O12:$P12, history!$K12:$L12), history!$P12, history!$Q12 ) -> 3.44 | T12: =VLOOKUP($F12, $AD$7:$AK$126, 6, 0) -> 4.521 | U12: =VLOOKUP($F12, $AD$7:$AK$126, 7, 0) -> 4.57 | V12: =VLOOKUP($F12, $AD$7:$AK$126, 8, 0) -> 4.578 | W12: =IF($W$5, FORECAST($J12,$U12:$V12,$U$5:$V$5), $T12) -> 4.521 | X12: 45616 | Y12: 20241121 | Z12: 45616 | AA12: 20241122 | AB12: =IFERROR( VLOOKUP($F12, $X$7:$Y$106, 2, 0), VLOOKUP($F12, $Z$7:$AA$106, 2, 0)) -> 20241122 | AD12: 45619 | AE12: 3.285 | AF12: 3.44 | AG12: 2.812 | AH12: 2.88 | AI12: 4.527 | AJ12: 4.57 | AK12: 4.581
A13: 45616 | B13: 20241122 | C13: 1390.9 | D13: =IF(B13="", "", DATE(LEFT(B13,4), MID(B13,5,2), RIGHT(B13,2))) -> 45618 | F13: 45616 | G13: 20250224 | H13: -560 | I13: =IF(G13="", "", DATE(LEFT(G13,4), MID(G13,5,2), RIGHT(G13,2))) -> 45712 | J13: =I13-D13 -> 94 | K13: =IF(AB13="", "", DATE(LEFT(AB13,4), MID(AB13,5,2), RIGHT(AB13,2)))-$F13 -> 1 | L13: 91 | M13: 365 | N13: 730 | O13: =VLOOKUP($F13, $AD$7:$AK$106, 2, 0) -> 3.266 | P13: =VLOOKUP($F13, $AD$7:$AK$106, 3, 0) -> 3.44 | Q13: =VLOOKUP($F13, $AD$7:$AK$106, 4, 0) -> 2.836 | R13: =VLOOKUP($F13, $AD$7:$AK$106, 5, 0) -> 2.93 | S13: =CHOOSE(option!$D$2, history!$O13, FORECAST(history!$J13, history!$O13:$P13, history!$K13:$L13), FORECAST(history!$J13, history!$O13:$P13, history!$K13:$L13), FORECAST(history!$J13, history!$O13:$P13, history!$K13:$L13), history!$P13, history!$Q13 ) -> 3.44 | T13: =VLOOKUP($F13, $AD$7:$AK$126, 6, 0) -> 4.524 | U13: =VLOOKUP($F13, $AD$7:$AK$126, 7, 0) -> 4.57 | V13: =VLOOKUP($F13, $AD$7:$AK$126, 8, 0) -> 4.589 | W13: =IF($W$5, FORECAST($J13,$U13:$V13,$U$5:$V$5), $T13) -> 4.524 | X13: 45615 | Y13: 20241120 | Z13: 45615 | AA13: 20241121 | AB13: =IFERROR( VLOOKUP($F13, $X$7:$Y$106, 2, 0), VLOOKUP($F13, $Z$7:$AA$106, 2, 0)) -> 20241121 | AD13: 45618 | AE13: 3.285 | AF13: 3.44 | AG13: 2.812 | AH13: 2.88 | AI13: 4.527 | AJ13: 4.57 | AK13: 4.581
A14: 45615 | B14: 20241121 | C14: 1390.9 | D14: =IF(B14="", "", DATE(LEFT(B14,4), MID(B14,5,2), RIGHT(B14,2))) -> 45617 | F14: 45615 | G14: 20250221 | H14: -560 | I14: =IF(G14="", "", DATE(LEFT(G14,4), MID(G14,5,2), RIGHT(G14,2))) -> 45709 | J14: =I14-D14 -> 92 | K14: =IF(AB14="", "", DATE(LEFT(AB14,4), MID(AB14,5,2), RIGHT(AB14,2)))-$F14 -> 1 | L14: 91 | M14: 365 | N14: 730 | O14: =VLOOKUP($F14, $AD$7:$AK$106, 2, 0) -> 3.262 | P14: =VLOOKUP($F14, $AD$7:$AK$106, 3, 0) -> 3.44 | Q14: =VLOOKUP($F14, $AD$7:$AK$106, 4, 0) -> 2.842 | R14: =VLOOKUP($F14, $AD$7:$AK$106, 5, 0) -> 2.941 | S14: =CHOOSE(option!$D$2, history!$O14, FORECAST(history!$J14, history!$O14:$P14, history!$K14:$L14), FORECAST(history!$J14, history!$O14:$P14, history!$K14:$L14), FORECAST(history!$J14, history!$O14:$P14, history!$K14:$L14), history!$P14, history!$Q14 ) -> 3.44 | T14: =VLOOKUP($F14, $AD$7:$AK$126, 6, 0) -> 4.521 | U14: =VLOOKUP($F14, $AD$7:$AK$126, 7, 0) -> 4.58 | V14: =VLOOKUP($F14, $AD$7:$AK$126, 8, 0) -> 4.589 | W14: =IF($W$5, FORECAST($J14,$U14:$V14,$U$5:$V$5), $T14) -> 4.521 | X14: 45614 | Y14: 20241119 | Z14: 45614 | AA14: 20241120 | AB14: =IFERROR( VLOOKUP($F14, $X$7:$Y$106, 2, 0), VLOOKUP($F14, $Z$7:$AA$106, 2, 0)) -> 20241120 | AD14: 45617 | AE14: 3.271 | AF14: 3.44 | AG14: 2.817 | AH14: 2.892 | AI14: 4.521 | AJ14: 4.57 | AK14: 4.578
A15: 45614 | B15: 20241120 | C15: 1395.2 | D15: =IF(B15="", "", DATE(LEFT(B15,4), MID(B15,5,2), RIGHT(B15,2))) -> 45616 | F15: 45614 | G15: 20250220 | H15: -550 | I15: =IF(G15="", "", DATE(LEFT(G15,4), MID(G15,5,2), RIGHT(G15,2))) -> 45708 | J15: =I15-D15 -> 92 | K15: =IF(AB15="", "", DATE(LEFT(AB15,4), MID(AB15,5,2), RIGHT(AB15,2)))-$F15 -> 1 | L15: 91 | M15: 365 | N15: 730 | O15: =VLOOKUP($F15, $AD$7:$AK$106, 2, 0) -> 3.267 | P15: =VLOOKUP($F15, $AD$7:$AK$106, 3, 0) -> 3.44 | Q15: =VLOOKUP($F15, $AD$7:$AK$106, 4, 0) -> 2.851 | R15: =VLOOKUP($F15, $AD$7:$AK$106, 5, 0) -> 2.961 | S15: =CHOOSE(option!$D$2, history!$O15, FORECAST(history!$J15, history!$O15:$P15, history!$K15:$L15), FORECAST(history!$J15, history!$O15:$P15, history!$K15:$L15), FORECAST(history!$J15, history!$O15:$P15, history!$K15:$L15), history!$P15, history!$Q15 ) -> 3.44 | T15: =VLOOKUP($F15, $AD$7:$AK$126, 6, 0) -> 4.52 | U15: =VLOOKUP($F15, $AD$7:$AK$126, 7, 0) -> 4.57 | V15: =VLOOKUP($F15, $AD$7:$AK$126, 8, 0) -> 4.6 | W15: =IF($W$5, FORECAST($J15,$U15:$V15,$U$5:$V$5), $T15) -> 4.52 | X15: 45611 | Y15: 20241118 | Z15: 45611 | AA15: 20241119 | AB15: =IFERROR( VLOOKUP($F15, $X$7:$Y$106, 2, 0), VLOOKUP($F15, $Z$7:$AA$106, 2, 0)) -> 20241119 | AD15: 45616 | AE15: 3.266 | AF15: 3.44 | AG15: 2.836 | AH15: 2.93 | AI15: 4.524 | AJ15: 4.57 | AK15: 4.589
A16: 45611 | B16: 20241119 | C16: 1398.8 | D16: =IF(B16="", "", DATE(LEFT(B16,4), MID(B16,5,2), RIGHT(B16,2))) -> 45615 | F16: 45611 | G16: 20250219 | H16: -535 | I16: =IF(G16="", "", DATE(LEFT(G16,4), MID(G16,5,2), RIGHT(G16,2))) -> 45707 | J16: =I16-D16 -> 92 | K16: =IF(AB16="", "", DATE(LEFT(AB16,4), MID(AB16,5,2), RIGHT(AB16,2)))-$F16 -> 3 | L16: 91 | M16: 365 | N16: 730 | O16: =VLOOKUP($F16, $AD$7:$AK$106, 2, 0) -> 3.264 | P16: =VLOOKUP($F16, $AD$7:$AK$106, 3, 0) -> 3.44 | Q16: =VLOOKUP($F16, $AD$7:$AK$106, 4, 0) -> 2.859 | R16: =VLOOKUP($F16, $AD$7:$AK$106, 5, 0) -> 2.977 | S16: =CHOOSE(option!$D$2, history!$O16, FORECAST(history!$J16, history!$O16:$P16, history!$K16:$L16), FORECAST(history!$J16, history!$O16:$P16, history!$K16:$L16), FORECAST(history!$J16, history!$O16:$P16, history!$K16:$L16), history!$P16, history!$Q16 ) -> 3.44 | T16: =VLOOKUP($F16, $AD$7:$AK$126, 6, 0) -> 4.519 | U16: =VLOOKUP($F16, $AD$7:$AK$126, 7, 0) -> 4.59 | V16: =VLOOKUP($F16, $AD$7:$AK$126, 8, 0) -> 4.603 | W16: =IF($W$5, FORECAST($J16,$U16:$V16,$U$5:$V$5), $T16) -> 4.519 | X16: 45610 | Y16: 20241115 | Z16: 45610 | AA16: 20241118 | AB16: =IFERROR( VLOOKUP($F16, $X$7:$Y$106, 2, 0), VLOOKUP($F16, $Z$7:$AA$106, 2, 0)) -> 20241118 | AD16: 45615 | AE16: 3.262 | AF16: 3.44 | AG16: 2.842 | AH16: 2.941 | AI16: 4.521 | AJ16: 4.58 | AK16: 4.589
A17: 45610 | B17: 20241118 | C17: 1405.1 | D17: =IF(B17="", "", DATE(LEFT(B17,4), MID(B17,5,2), RIGHT(B17,2))) -> 45614 | F17: 45610 | G17: 20250218 | H17: -500 | I17: =IF(G17="", "", DATE(LEFT(G17,4), MID(G17,5,2), RIGHT(G17,2))) -> 45706 | J17: =I17-D17 -> 92 | K17: =IF(AB17="", "", DATE(LEFT(AB17,4), MID(AB17,5,2), RIGHT(AB17,2)))-$F17 -> 1 | L17: 91 | M17: 365 | N17: 730 | O17: =VLOOKUP($F17, $AD$7:$AK$106, 2, 0) -> 3.266 | P17: =VLOOKUP($F17, $AD$7:$AK$106, 3, 0) -> 3.44 | Q17: =VLOOKUP($F17, $AD$7:$AK$106, 4, 0) -> 2.84 | R17: =VLOOKUP($F17, $AD$7:$AK$106, 5, 0) -> 2.965 | S17: =CHOOSE(option!$D$2, history!$O17, FORECAST(history!$J17, history!$O17:$P17, history!$K17:$L17), FORECAST(history!$J17, history!$O17:$P17, history!$K17:$L17), FORECAST(history!$J17, history!$O17:$P17, history!$K17:$L17), history!$P17, history!$Q17 ) -> 3.44 | T17: =VLOOKUP($F17, $AD$7:$AK$126, 6, 0) -> 4.519 | U17: =VLOOKUP($F17, $AD$7:$AK$126, 7, 0) -> 4.59 | V17: =VLOOKUP($F17, $AD$7:$AK$126, 8, 0) -> 4.605 | W17: =IF($W$5, FORECAST($J17,$U17:$V17,$U$5:$V$5), $T17) -> 4.519 | X17: 45609 | Y17: 20241114 | Z17: 45609 | AA17: 20241115 | AB17: =IFERROR( VLOOKUP($F17, $X$7:$Y$106, 2, 0), VLOOKUP($F17, $Z$7:$AA$106, 2, 0)) -> 20241115 | AD17: 45614 | AE17: 3.267 | AF17: 3.44 | AG17: 2.851 | AH17: 2.961 | AI17: 4.52 | AJ17: 4.57 | AK17: 4.6
A18: 45609 | B18: 20241115 | C18: 1406.6 | D18: =IF(B18="", "", DATE(LEFT(B18,4), MID(B18,5,2), RIGHT(B18,2))) -> 45611 | F18: 45609 | G18: 20250218 | H18: -550 | I18: =IF(G18="", "", DATE(LEFT(G18,4), MID(G18,5,2), RIGHT(G18,2))) -> 45706 | J18: =I18-D18 -> 95 | K18: =IF(AB18="", "", DATE(LEFT(AB18,4), MID(AB18,5,2), RIGHT(AB18,2)))-$F18 -> 1 | L18: 91 | M18: 365 | N18: 730 | O18: =VLOOKUP($F18, $AD$7:$AK$106, 2, 0) -> 3.276 | P18: =VLOOKUP($F18, $AD$7:$AK$106, 3, 0) -> 3.44 | Q18: =VLOOKUP($F18, $AD$7:$AK$106, 4, 0) -> 2.845 | R18: =VLOOKUP($F18, $AD$7:$AK$106, 5, 0) -> 2.979 | S18: =CHOOSE(option!$D$2, history!$O18, FORECAST(history!$J18, history!$O18:$P18, history!$K18:$L18), FORECAST(history!$J18, history!$O18:$P18, history!$K18:$L18), FORECAST(history!$J18, history!$O18:$P18, history!$K18:$L18), history!$P18, history!$Q18 ) -> 3.44 | T18: =VLOOKUP($F18, $AD$7:$AK$126, 6, 0) -> 4.485 | U18: =VLOOKUP($F18, $AD$7:$AK$126, 7, 0) -> 4.59 | V18: =VLOOKUP($F18, $AD$7:$AK$126, 8, 0) -> 4.606 | W18: =IF($W$5, FORECAST($J18,$U18:$V18,$U$5:$V$5), $T18) -> 4.485 | X18: 45608 | Y18: 20241113 | Z18: 45608 | AA18: 20241114 | AB18: =IFERROR( VLOOKUP($F18, $X$7:$Y$106, 2, 0), VLOOKUP($F18, $Z$7:$AA$106, 2, 0)) -> 20241114 | AD18: 45613 | AE18: 3.264 | AF18: 3.44 | AG18: 2.859 | AH18: 2.977 | AI18: 4.519 | AJ18: 4.59 | AK18: 4.603
... A73: 45524 | B73: 20240822 | C73: 1333.2 | D73: =IF(B73="", "", DATE(LEFT(B73,4), MID(B73,5,2), RIGHT(B73,2))) -> 45526 | F73: 45524 | G73: 20241122 | H73: -765 | I73: =IF(G73="", "", DATE(LEFT(G73,4), MID(G73,5,2), RIGHT(G73,2))) -> 45618 | J73: =I73-D73 -> 92 | K73: =IF(AB73="", "", DATE(LEFT(AB73,4), MID(AB73,5,2), RIGHT(AB73,2)))-$F73 -> 1 | L73: 91 | M73: 365 | N73: 730 | O73: =VLOOKUP($F73, $AD$7:$AK$106, 2, 0) -> #N/A | P73: =VLOOKUP($F73, $AD$7:$AK$106, 3, 0) -> #N/A | Q73: =VLOOKUP($F73, $AD$7:$AK$106, 4, 0) -> #N/A | R73: =VLOOKUP($F73, $AD$7:$AK$106, 5, 0) -> #N/A | S73: =CHOOSE(option!$D$2, history!$O73, FORECAST(history!$J73, history!$O73:$P73, history!$K73:$L73), FORECAST(history!$J73, history!$O73:$P73, history!$K73:$L73), FORECAST(history!$J73, history!$O73:$P73, history!$K73:$L73), history!$P73, history!$Q73 ) -> #N/A | T73: =VLOOKUP($F73, $AD$7:$AK$126, 6, 0) -> 5.103 | U73: =VLOOKUP($F73, $AD$7:$AK$126, 7, 0) -> 5.33 | V73: =VLOOKUP($F73, $AD$7:$AK$126, 8, 0) -> 5.307 | W73: =IF($W$5, FORECAST($J73,$U73:$V73,$U$5:$V$5), $T73) -> 5.103 | X73: 45517 | Y73: 20240814 | Z73: 45517 | AA73: 20240816 | AB73: =IFERROR( VLOOKUP($F73, $X$7:$Y$106, 2, 0), VLOOKUP($F73, $Z$7:$AA$106, 2, 0)) -> 20240821 | AD73: 45558 | AE73: 3.499 | AF73: 3.53 | AG73: 2.879 | AH73: 2.92 | AI73: 4.655 | AJ73: 4.83 | AK73: 4.857
D74: =IF(B74="", "", DATE(LEFT(B74,4), MID(B74,5,2), RIGHT(B74,2))) | I74: =IF(G74="", "", DATE(LEFT(G74,4), MID(G74,5,2), RIGHT(G74,2))) | J74: =I74-D74 -> #VALUE! | K74: =IF(AB74="", "", DATE(LEFT(AB74,4), MID(AB74,5,2), RIGHT(AB74,2)))-$F74 -> #N/A | L74: 91 | M74: 365 | N74: 730 | O74: =VLOOKUP($F74, $AD$7:$AK$106, 2, 0) -> #N/A | P74: =VLOOKUP($F74, $AD$7:$AK$106, 3, 0) -> #N/A | Q74: =VLOOKUP($F74, $AD$7:$AK$106, 4, 0) -> #N/A | R74: =VLOOKUP($F74, $AD$7:$AK$106, 5, 0) -> #N/A | S74: =CHOOSE(option!$D$2, history!$O74, FORECAST(history!$J74, history!$O74:$P74, history!$K74:$L74), FORECAST(history!$J74, history!$O74:$P74, history!$K74:$L74), FORECAST(history!$J74, history!$O74:$P74, history!$K74:$L74), history!$P74, history!$Q74 ) -> #N/A | T74: =VLOOKUP($F74, $AD$7:$AK$126, 6, 0) -> #N/A | U74: =VLOOKUP($F74, $AD$7:$AK$126, 7, 0) -> #N/A | V74: =VLOOKUP($F74, $AD$7:$AK$126, 8, 0) -> #N/A | W74: =IF($W$5, FORECAST($J74,$U74:$V74,$U$5:$V$5), $T74) -> #N/A | X74: 45516 | Y74: 20240813 | Z74: 45516 | AA74: 20240814 | AB74: =IFERROR( VLOOKUP($F74, $X$7:$Y$106, 2, 0), VLOOKUP($F74, $Z$7:$AA$106, 2, 0)) -> #N/A | AD74: 45557 | AE74: 3.505 | AF74: 3.53 | AG74: 2.879 | AH74: 2.905 | AI74: 4.668 | AJ74: 4.83 | AK74: 4.856
D75: =IF(B75="", "", DATE(LEFT(B75,4), MID(B75,5,2), RIGHT(B75,2))) | I75: =IF(G75="", "", DATE(LEFT(G75,4), MID(G75,5,2), RIGHT(G75,2))) | J75: =I75-D75 -> #VALUE! | K75: =IF(AB75="", "", DATE(LEFT(AB75,4), MID(AB75,5,2), RIGHT(AB75,2)))-$F75 -> #N/A | L75: 91 | M75: 365 | N75: 730 | O75: =VLOOKUP($F75, $AD$7:$AK$106, 2, 0) -> #N/A | P75: =VLOOKUP($F75, $AD$7:$AK$106, 3, 0) -> #N/A | Q75: =VLOOKUP($F75, $AD$7:$AK$106, 4, 0) -> #N/A | R75: =VLOOKUP($F75, $AD$7:$AK$106, 5, 0) -> #N/A | S75: =CHOOSE(option!$D$2, history!$O75, FORECAST(history!$J75, history!$O75:$P75, history!$K75:$L75), FORECAST(history!$J75, history!$O75:$P75, history!$K75:$L75), FORECAST(history!$J75, history!$O75:$P75, history!$K75:$L75), history!$P75, history!$Q75 ) -> #N/A | T75: =VLOOKUP($F75, $AD$7:$AK$126, 6, 0) -> #N/A | U75: =VLOOKUP($F75, $AD$7:$AK$126, 7, 0) -> #N/A | V75: =VLOOKUP($F75, $AD$7:$AK$126, 8, 0) -> #N/A | W75: =IF($W$5, FORECAST($J75,$U75:$V75,$U$5:$V$5), $T75) -> #N/A | X75: 45513 | Y75: 20240812 | Z75: 45513 | AA75: 20240813 | AB75: =IFERROR( VLOOKUP($F75, $X$7:$Y$106, 2, 0), VLOOKUP($F75, $Z$7:$AA$106, 2, 0)) -> #N/A | AD75: 45556 | AE75: 3.505 | AF75: 3.53 | AG75: 2.879 | AH75: 2.905 | AI75: 4.668 | AJ75: 4.83 | AK75: 4.856
D76: =IF(B76="", "", DATE(LEFT(B76,4), MID(B76,5,2), RIGHT(B76,2))) | I76: =IF(G76="", "", DATE(LEFT(G76,4), MID(G76,5,2), RIGHT(G76,2))) | J76: =I76-D76 -> #VALUE! | K76: =IF(AB76="", "", DATE(LEFT(AB76,4), MID(AB76,5,2), RIGHT(AB76,2)))-$F76 -> #N/A | L76: 91 | M76: 365 | N76: 730 | O76: =VLOOKUP($F76, $AD$7:$AK$106, 2, 0) -> #N/A | P76: =VLOOKUP($F76, $AD$7:$AK$106, 3, 0) -> #N/A | Q76: =VLOOKUP($F76, $AD$7:$AK$106, 4, 0) -> #N/A | R76: =VLOOKUP($F76, $AD$7:$AK$106, 5, 0) -> #N/A | S76: =CHOOSE(option!$D$2, history!$O76, FORECAST(history!$J76, history!$O76:$P76, history!$K76:$L76), FORECAST(history!$J76, history!$O76:$P76, history!$K76:$L76), FORECAST(history!$J76, history!$O76:$P76, history!$K76:$L76), history!$P76, history!$Q76 ) -> #N/A | T76: =VLOOKUP($F76, $AD$7:$AK$126, 6, 0) -> #N/A | U76: =VLOOKUP($F76, $AD$7:$AK$126, 7, 0) -> #N/A | V76: =VLOOKUP($F76, $AD$7:$AK$126, 8, 0) -> #N/A | W76: =IF($W$5, FORECAST($J76,$U76:$V76,$U$5:$V$5), $T76) -> #N/A | X76: 45512 | Y76: 20240809 | Z76: 45512 | AA76: 20240812 | AB76: =IFERROR( VLOOKUP($F76, $X$7:$Y$106, 2, 0), VLOOKUP($F76, $Z$7:$AA$106, 2, 0)) -> #N/A | AD76: 45555 | AE76: 3.505 | AF76: 3.53 | AG76: 2.879 | AH76: 2.905 | AI76: 4.668 | AJ76: 4.83 | AK76: 4.856
D77: =IF(B77="", "", DATE(LEFT(B77,4), MID(B77,5,2), RIGHT(B77,2))) | I77: =IF(G77="", "", DATE(LEFT(G77,4), MID(G77,5,2), RIGHT(G77,2))) | J77: =I77-D77 -> #VALUE! | K77: =IF(AB77="", "", DATE(LEFT(AB77,4), MID(AB77,5,2), RIGHT(AB77,2)))-$F77 -> #N/A | L77: 91 | M77: 365 | N77: 730 | O77: =VLOOKUP($F77, $AD$7:$AK$106, 2, 0) -> #N/A | P77: =VLOOKUP($F77, $AD$7:$AK$106, 3, 0) -> #N/A | Q77: =VLOOKUP($F77, $AD$7:$AK$106, 4, 0) -> #N/A | R77: =VLOOKUP($F77, $AD$7:$AK$106, 5, 0) -> #N/A | S77: =CHOOSE(option!$D$2, history!$O77, FORECAST(history!$J77, history!$O77:$P77, history!$K77:$L77), FORECAST(history!$J77, history!$O77:$P77, history!$K77:$L77), FORECAST(history!$J77, history!$O77:$P77, history!$K77:$L77), history!$P77, history!$Q77 ) -> #N/A | T77: =VLOOKUP($F77, $AD$7:$AK$126, 6, 0) -> #N/A | U77: =VLOOKUP($F77, $AD$7:$AK$126, 7, 0) -> #N/A | V77: =VLOOKUP($F77, $AD$7:$AK$126, 8, 0) -> #N/A | W77: =IF($W$5, FORECAST($J77,$U77:$V77,$U$5:$V$5), $T77) -> #N/A | X77: 45511 | Y77: 20240808 | Z77: 45511 | AA77: 20240809 | AB77: =IFERROR( VLOOKUP($F77, $X$7:$Y$106, 2, 0), VLOOKUP($F77, $Z$7:$AA$106, 2, 0)) -> #N/A | AD77: 45554 | AE77: 3.517 | AF77: 3.53 | AG77: 2.887 | AH77: 2.921 | AI77: 4.691 | AJ77: 4.83 | AK77: 4.86
D78: =IF(B78="", "", DATE(LEFT(B78,4), MID(B78,5,2), RIGHT(B78,2))) | I78: =IF(G78="", "", DATE(LEFT(G78,4), MID(G78,5,2), RIGHT(G78,2))) | J78: =I78-D78 -> #VALUE! | K78: =IF(AB78="", "", DATE(LEFT(AB78,4), MID(AB78,5,2), RIGHT(AB78,2)))-$F78 -> #N/A | L78: 91 | M78: 365 | N78: 730 | O78: =VLOOKUP($F78, $AD$7:$AK$106, 2, 0) -> #N/A | P78: =VLOOKUP($F78, $AD$7:$AK$106, 3, 0) -> #N/A | Q78: =VLOOKUP($F78, $AD$7:$AK$106, 4, 0) -> #N/A | R78: =VLOOKUP($F78, $AD$7:$AK$106, 5, 0) -> #N/A | S78: =CHOOSE(option!$D$2, history!$O78, FORECAST(history!$J78, history!$O78:$P78, history!$K78:$L78), FORECAST(history!$J78, history!$O78:$P78, history!$K78:$L78), FORECAST(history!$J78, history!$O78:$P78, history!$K78:$L78), history!$P78, history!$Q78 ) -> #N/A | T78: =VLOOKUP($F78, $AD$7:$AK$126, 6, 0) -> #N/A | U78: =VLOOKUP($F78, $AD$7:$AK$126, 7, 0) -> #N/A | V78: =VLOOKUP($F78, $AD$7:$AK$126, 8, 0) -> #N/A | W78: =IF($W$5, FORECAST($J78,$U78:$V78,$U$5:$V$5), $T78) -> #N/A | X78: 45510 | Y78: 20240807 | Z78: 45510 | AA78: 20240808 | AB78: =IFERROR( VLOOKUP($F78, $X$7:$Y$106, 2, 0), VLOOKUP($F78, $Z$7:$AA$106, 2, 0)) -> #N/A | AD78: 45553 | AE78: 0 | AF78: 3.53 | AG78: 2.884 | AH78: 2.914 | AI78: 4.726 | AJ78: 5.34 | AK78: 4.862
D79: =IF(B79="", "", DATE(LEFT(B79,4), MID(B79,5,2), RIGHT(B79,2))) | I79: =IF(G79="", "", DATE(LEFT(G79,4), MID(G79,5,2), RIGHT(G79,2))) | J79: =I79-D79 -> #VALUE! | K79: =IF(AB79="", "", DATE(LEFT(AB79,4), MID(AB79,5,2), RIGHT(AB79,2)))-$F79 -> #N/A | L79: 91 | M79: 365 | N79: 730 | O79: =VLOOKUP($F79, $AD$7:$AK$106, 2, 0) -> #N/A | P79: =VLOOKUP($F79, $AD$7:$AK$106, 3, 0) -> #N/A | Q79: =VLOOKUP($F79, $AD$7:$AK$106, 4, 0) -> #N/A | R79: =VLOOKUP($F79, $AD$7:$AK$106, 5, 0) -> #N/A | S79: =CHOOSE(option!$D$2, history!$O79, FORECAST(history!$J79, history!$O79:$P79, history!$K79:$L79), FORECAST(history!$J79, history!$O79:$P79, history!$K79:$L79), FORECAST(history!$J79, history!$O79:$P79, history!$K79:$L79), history!$P79, history!$Q79 ) -> #N/A | T79: =VLOOKUP($F79, $AD$7:$AK$126, 6, 0) -> #N/A | U79: =VLOOKUP($F79, $AD$7:$AK$126, 7, 0) -> #N/A | V79: =VLOOKUP($F79, $AD$7:$AK$126, 8, 0) -> #N/A | W79: =IF($W$5, FORECAST($J79,$U79:$V79,$U$5:$V$5), $T79) -> #N/A | X79: 45509 | Y79: 20240806 | Z79: 45509 | AA79: 20240807 | AB79: =IFERROR( VLOOKUP($F79, $X$7:$Y$106, 2, 0), VLOOKUP($F79, $Z$7:$AA$106, 2, 0)) -> #N/A | AD79: 45552 | AE79: 0 | AF79: 3.53 | AG79: 2.884 | AH79: 2.914 | AI79: 4.821 | AJ79: 5.34 | AK79: 4.964
D80: =IF(B80="", "", DATE(LEFT(B80,4), MID(B80,5,2), RIGHT(B80,2))) | I80: =IF(G80="", "", DATE(LEFT(G80,4), MID(G80,5,2), RIGHT(G80,2))) | J80: =I80-D80 -> #VALUE! | K80: =IF(AB80="", "", DATE(LEFT(AB80,4), MID(AB80,5,2), RIGHT(AB80,2)))-$F80 -> #N/A | L80: 91 | M80: 365 | N80: 730 | O80: =VLOOKUP($F80, $AD$7:$AK$106, 2, 0) -> #N/A | P80: =VLOOKUP($F80, $AD$7:$AK$106, 3, 0) -> #N/A | Q80: =VLOOKUP($F80, $AD$7:$AK$106, 4, 0) -> #N/A | R80: =VLOOKUP($F80, $AD$7:$AK$106, 5, 0) -> #N/A | S80: =CHOOSE(option!$D$2, history!$O80, FORECAST(history!$J80, history!$O80:$P80, history!$K80:$L80), FORECAST(history!$J80, history!$O80:$P80, history!$K80:$L80), FORECAST(history!$J80, history!$O80:$P80, history!$K80:$L80), history!$P80, history!$Q80 ) -> #N/A | T80: =VLOOKUP($F80, $AD$7:$AK$126, 6, 0) -> #N/A | U80: =VLOOKUP($F80, $AD$7:$AK$126, 7, 0) -> #N/A | V80: =VLOOKUP($F80, $AD$7:$AK$126, 8, 0) -> #N/A | W80: =IF($W$5, FORECAST($J80,$U80:$V80,$U$5:$V$5), $T80) -> #N/A | X80: 45506 | Y80: 20240805 | Z80: 45506 | AA80: 20240806 | AB80: =IFERROR( VLOOKUP($F80, $X$7:$Y$106, 2, 0), VLOOKUP($F80, $Z$7:$AA$106, 2, 0)) -> #N/A | AD80: 45551 | AE80: 0 | AF80: 3.53 | AG80: 2.884 | AH80: 2.914 | AI80: 4.814 | AJ80: 5.34 | AK80: 4.966
D81: =IF(B81="", "", DATE(LEFT(B81,4), MID(B81,5,2), RIGHT(B81,2))) | I81: =IF(G81="", "", DATE(LEFT(G81,4), MID(G81,5,2), RIGHT(G81,2))) | J81: =I81-D81 -> #VALUE! | K81: =IF(AB81="", "", DATE(LEFT(AB81,4), MID(AB81,5,2), RIGHT(AB81,2)))-$F81 -> #N/A | L81: 91 | M81: 365 | N81: 730 | O81: =VLOOKUP($F81, $AD$7:$AK$106, 2, 0) -> #N/A | P81: =VLOOKUP($F81, $AD$7:$AK$106, 3, 0) -> #N/A | Q81: =VLOOKUP($F81, $AD$7:$AK$106, 4, 0) -> #N/A | R81: =VLOOKUP($F81, $AD$7:$AK$106, 5, 0) -> #N/A | S81: =CHOOSE(option!$D$2, history!$O81, FORECAST(history!$J81, history!$O81:$P81, history!$K81:$L81), FORECAST(history!$J81, history!$O81:$P81, history!$K81:$L81), FORECAST(history!$J81, history!$O81:$P81, history!$K81:$L81), history!$P81, history!$Q81 ) -> #N/A | T81: =VLOOKUP($F81, $AD$7:$AK$126, 6, 0) -> #N/A | U81: =VLOOKUP($F81, $AD$7:$AK$126, 7, 0) -> #N/A | V81: =VLOOKUP($F81, $AD$7:$AK$126, 8, 0) -> #N/A | W81: =IF($W$5, FORECAST($J81,$U81:$V81,$U$5:$V$5), $T81) -> #N/A | X81: 45505 | Y81: 20240802 | Z81: 45505 | AA81: 20240805 | AB81: =IFERROR( VLOOKUP($F81, $X$7:$Y$106, 2, 0), VLOOKUP($F81, $Z$7:$AA$106, 2, 0)) -> #N/A | AD81: 45550 | AE81: 3.538 | AF81: 3.53 | AG81: 2.884 | AH81: 2.914 | AI81: 4.877 | AJ81: 5.33 | AK81: 5.029
D82: =IF(B82="", "", DATE(LEFT(B82,4), MID(B82,5,2), RIGHT(B82,2))) | I82: =IF(G82="", "", DATE(LEFT(G82,4), MID(G82,5,2), RIGHT(G82,2))) | J82: =I82-D82 -> #VALUE! | K82: =IF(AB82="", "", DATE(LEFT(AB82,4), MID(AB82,5,2), RIGHT(AB82,2)))-$F82 -> #N/A | L82: 91 | M82: 365 | N82: 730 | O82: =VLOOKUP($F82, $AD$7:$AK$106, 2, 0) -> #N/A | P82: =VLOOKUP($F82, $AD$7:$AK$106, 3, 0) -> #N/A | Q82: =VLOOKUP($F82, $AD$7:$AK$106, 4, 0) -> #N/A | R82: =VLOOKUP($F82, $AD$7:$AK$106, 5, 0) -> #N/A | S82: =CHOOSE(option!$D$2, history!$O82, FORECAST(history!$J82, history!$O82:$P82, history!$K82:$L82), FORECAST(history!$J82, history!$O82:$P82, history!$K82:$L82), FORECAST(history!$J82, history!$O82:$P82, history!$K82:$L82), history!$P82, history!$Q82 ) -> #N/A | T82: =VLOOKUP($F82, $AD$7:$AK$126, 6, 0) -> #N/A | U82: =VLOOKUP($F82, $AD$7:$AK$126, 7, 0) -> #N/A | V82: =VLOOKUP($F82, $AD$7:$AK$126, 8, 0) -> #N/A | W82: =IF($W$5, FORECAST($J82,$U82:$V82,$U$5:$V$5), $T82) -> #N/A | X82: 45504 | Y82: 20240801 | Z82: 45504 | AA82: 20240802 | AB82: =IFERROR( VLOOKUP($F82, $X$7:$Y$106, 2, 0), VLOOKUP($F82, $Z$7:$AA$106, 2, 0)) -> #N/A | AD82: 45549 | AE82: 3.538 | AF82: 3.53 | AG82: 2.884 | AH82: 2.914 | AI82: 4.877 | AJ82: 5.33 | AK82: 5.029
D83: =IF(B83="", "", DATE(LEFT(B83,4), MID(B83,5,2), RIGHT(B83,2))) | I83: =IF(G83="", "", DATE(LEFT(G83,4), MID(G83,5,2), RIGHT(G83,2))) | J83: =I83-D83 -> #VALUE! | K83: =IF(AB83="", "", DATE(LEFT(AB83,4), MID(AB83,5,2), RIGHT(AB83,2)))-$F83 -> #N/A | L83: 91 | M83: 365 | N83: 730 | O83: =VLOOKUP($F83, $AD$7:$AK$106, 2, 0) -> #N/A | P83: =VLOOKUP($F83, $AD$7:$AK$106, 3, 0) -> #N/A | Q83: =VLOOKUP($F83, $AD$7:$AK$106, 4, 0) -> #N/A | R83: =VLOOKUP($F83, $AD$7:$AK$106, 5, 0) -> #N/A | S83: =CHOOSE(option!$D$2, history!$O83, FORECAST(history!$J83, history!$O83:$P83, history!$K83:$L83), FORECAST(history!$J83, history!$O83:$P83, history!$K83:$L83), FORECAST(history!$J83, history!$O83:$P83, history!$K83:$L83), history!$P83, history!$Q83 ) -> #N/A | T83: =VLOOKUP($F83, $AD$7:$AK$126, 6, 0) -> #N/A | U83: =VLOOKUP($F83, $AD$7:$AK$126, 7, 0) -> #N/A | V83: =VLOOKUP($F83, $AD$7:$AK$126, 8, 0) -> #N/A | W83: =IF($W$5, FORECAST($J83,$U83:$V83,$U$5:$V$5), $T83) -> #N/A | AB83: =IFERROR( VLOOKUP($F83, $X$7:$Y$106, 2, 0), VLOOKUP($F83, $Z$7:$AA$106, 2, 0)) -> #N/A | AD83: 45548 | AE83: 3.538 | AF83: 3.53 | AG83: 2.884 | AH83: 2.914 | AI83: 4.877 | AJ83: 5.33 | AK83: 5.029
D84: =IF(B84="", "", DATE(LEFT(B84,4), MID(B84,5,2), RIGHT(B84,2))) | I84: =IF(G84="", "", DATE(LEFT(G84,4), MID(G84,5,2), RIGHT(G84,2))) | J84: =I84-D84 -> #VALUE! | K84: =IF(AB84="", "", DATE(LEFT(AB84,4), MID(AB84,5,2), RIGHT(AB84,2)))-$F84 -> #N/A | L84: 91 | M84: 365 | N84: 730 | O84: =VLOOKUP($F84, $AD$7:$AK$106, 2, 0) -> #N/A | P84: =VLOOKUP($F84, $AD$7:$AK$106, 3, 0) -> #N/A | Q84: =VLOOKUP($F84, $AD$7:$AK$106, 4, 0) -> #N/A | R84: =VLOOKUP($F84, $AD$7:$AK$106, 5, 0) -> #N/A | S84: =CHOOSE(option!$D$2, history!$O84, FORECAST(history!$J84, history!$O84:$P84, history!$K84:$L84), FORECAST(history!$J84, history!$O84:$P84, history!$K84:$L84), FORECAST(history!$J84, history!$O84:$P84, history!$K84:$L84), history!$P84, history!$Q84 ) -> #N/A | T84: =VLOOKUP($F84, $AD$7:$AK$126, 6, 0) -> #N/A | U84: =VLOOKUP($F84, $AD$7:$AK$126, 7, 0) -> #N/A | V84: =VLOOKUP($F84, $AD$7:$AK$126, 8, 0) -> #N/A | W84: =IF($W$5, FORECAST($J84,$U84:$V84,$U$5:$V$5), $T84) -> #N/A | AB84: =IFERROR( VLOOKUP($F84, $X$7:$Y$106, 2, 0), VLOOKUP($F84, $Z$7:$AA$106, 2, 0)) -> #N/A | AD84: 45547 | AE84: 3.578 | AF84: 3.51 | AG84: 2.912 | AH84: 2.96 | AI84: 4.904 | AJ84: 5.33 | AK84: 5.058
D85: =IF(B85="", "", DATE(LEFT(B85,4), MID(B85,5,2), RIGHT(B85,2))) | I85: =IF(G85="", "", DATE(LEFT(G85,4), MID(G85,5,2), RIGHT(G85,2))) | J85: =I85-D85 -> #VALUE! | K85: =IF(AB85="", "", DATE(LEFT(AB85,4), MID(AB85,5,2), RIGHT(AB85,2)))-$F85 -> #N/A | L85: 91 | M85: 365 | N85: 730 | O85: =VLOOKUP($F85, $AD$7:$AK$106, 2, 0) -> #N/A | P85: =VLOOKUP($F85, $AD$7:$AK$106, 3, 0) -> #N/A | Q85: =VLOOKUP($F85, $AD$7:$AK$106, 4, 0) -> #N/A | R85: =VLOOKUP($F85, $AD$7:$AK$106, 5, 0) -> #N/A | S85: =CHOOSE(option!$D$2, history!$O85, FORECAST(history!$J85, history!$O85:$P85, history!$K85:$L85), FORECAST(history!$J85, history!$O85:$P85, history!$K85:$L85), FORECAST(history!$J85, history!$O85:$P85, history!$K85:$L85), history!$P85, history!$Q85 ) -> #N/A | T85: =VLOOKUP($F85, $AD$7:$AK$126, 6, 0) -> #N/A | U85: =VLOOKUP($F85, $AD$7:$AK$126, 7, 0) -> #N/A | V85: =VLOOKUP($F85, $AD$7:$AK$126, 8, 0) -> #N/A | W85: =IF($W$5, FORECAST($J85,$U85:$V85,$U$5:$V$5), $T85) -> #N/A | AB85: =IFERROR( VLOOKUP($F85, $X$7:$Y$106, 2, 0), VLOOKUP($F85, $Z$7:$AA$106, 2, 0)) -> #N/A | AD85: 45546 | AE85: 3.48 | AF85: 3.51 | AG85: 2.915 | AH85: 2.92 | AI85: 4.98 | AJ85: 5.33 | AK85: 5.128
D86: =IF(B86="", "", DATE(LEFT(B86,4), MID(B86,5,2), RIGHT(B86,2))) | I86: =IF(G86="", "", DATE(LEFT(G86,4), MID(G86,5,2), RIGHT(G86,2))) | J86: =I86-D86 -> #VALUE! | K86: =IF(AB86="", "", DATE(LEFT(AB86,4), MID(AB86,5,2), RIGHT(AB86,2)))-$F86 -> #N/A | L86: 91 | M86: 365 | N86: 730 | O86: =VLOOKUP($F86, $AD$7:$AK$106, 2, 0) -> #N/A | P86: =VLOOKUP($F86, $AD$7:$AK$106, 3, 0) -> #N/A | Q86: =VLOOKUP($F86, $AD$7:$AK$106, 4, 0) -> #N/A | R86: =VLOOKUP($F86, $AD$7:$AK$106, 5, 0) -> #N/A | S86: =CHOOSE(option!$D$2, history!$O86, FORECAST(history!$J86, history!$O86:$P86, history!$K86:$L86), FORECAST(history!$J86, history!$O86:$P86, history!$K86:$L86), FORECAST(history!$J86, history!$O86:$P86, history!$K86:$L86), history!$P86, history!$Q86 ) -> #N/A | T86: =VLOOKUP($F86, $AD$7:$AK$126, 6, 0) -> #N/A | U86: =VLOOKUP($F86, $AD$7:$AK$126, 7, 0) -> #N/A | V86: =VLOOKUP($F86, $AD$7:$AK$126, 8, 0) -> #N/A | W86: =IF($W$5, FORECAST($J86,$U86:$V86,$U$5:$V$5), $T86) -> #N/A | AB86: =IFERROR( VLOOKUP($F86, $X$7:$Y$106, 2, 0), VLOOKUP($F86, $Z$7:$AA$106, 2, 0)) -> #N/A | AD86: 45545 | AE86: 3.42 | AF86: 3.51 | AG86: 2.959 | AH86: 2.953 | AI86: 4.938 | AJ86: 5.33 | AK86: 5.104
D87: =IF(B87="", "", DATE(LEFT(B87,4), MID(B87,5,2), RIGHT(B87,2))) | I87: =IF(G87="", "", DATE(LEFT(G87,4), MID(G87,5,2), RIGHT(G87,2))) | J87: =I87-D87 -> #VALUE! | K87: =IF(AB87="", "", DATE(LEFT(AB87,4), MID(AB87,5,2), RIGHT(AB87,2)))-$F87 -> #N/A | L87: 91 | M87: 365 | N87: 730 | O87: =VLOOKUP($F87, $AD$7:$AK$106, 2, 0) -> #N/A | P87: =VLOOKUP($F87, $AD$7:$AK$106, 3, 0) -> #N/A | Q87: =VLOOKUP($F87, $AD$7:$AK$106, 4, 0) -> #N/A | R87: =VLOOKUP($F87, $AD$7:$AK$106, 5, 0) -> #N/A | S87: =CHOOSE(option!$D$2, history!$O87, FORECAST(history!$J87, history!$O87:$P87, history!$K87:$L87), FORECAST(history!$J87, history!$O87:$P87, history!$K87:$L87), FORECAST(history!$J87, history!$O87:$P87, history!$K87:$L87), history!$P87, history!$Q87 ) -> #N/A | T87: =VLOOKUP($F87, $AD$7:$AK$126, 6, 0) -> #N/A | U87: =VLOOKUP($F87, $AD$7:$AK$126, 7, 0) -> #N/A | V87: =VLOOKUP($F87, $AD$7:$AK$126, 8, 0) -> #N/A | W87: =IF($W$5, FORECAST($J87,$U87:$V87,$U$5:$V$5), $T87) -> #N/A | AB87: =IFERROR( VLOOKUP($F87, $X$7:$Y$106, 2, 0), VLOOKUP($F87, $Z$7:$AA$106, 2, 0)) -> #N/A | AD87: 45544 | AE87: 3.562 | AF87: 3.51 | AG87: 2.974 | AH87: 2.961 | AI87: 4.951 | AJ87: 5.33 | AK87: 5.124
D88: =IF(B88="", "", DATE(LEFT(B88,4), MID(B88,5,2), RIGHT(B88,2))) | I88: =IF(G88="", "", DATE(LEFT(G88,4), MID(G88,5,2), RIGHT(G88,2))) | J88: =I88-D88 -> #VALUE! | K88: =IF(AB88="", "", DATE(LEFT(AB88,4), MID(AB88,5,2), RIGHT(AB88,2)))-$F88 -> #N/A | L88: 91 | M88: 365 | N88: 730 | O88: =VLOOKUP($F88, $AD$7:$AK$106, 2, 0) -> #N/A | P88: =VLOOKUP($F88, $AD$7:$AK$106, 3, 0) -> #N/A | Q88: =VLOOKUP($F88, $AD$7:$AK$106, 4, 0) -> #N/A | R88: =VLOOKUP($F88, $AD$7:$AK$106, 5, 0) -> #N/A | S88: =CHOOSE(option!$D$2, history!$O88, FORECAST(history!$J88, history!$O88:$P88, history!$K88:$L88), FORECAST(history!$J88, history!$O88:$P88, history!$K88:$L88), FORECAST(history!$J88, history!$O88:$P88, history!$K88:$L88), history!$P88, history!$Q88 ) -> #N/A | T88: =VLOOKUP($F88, $AD$7:$AK$126, 6, 0) -> #N/A | U88: =VLOOKUP($F88, $AD$7:$AK$126, 7, 0) -> #N/A | V88: =VLOOKUP($F88, $AD$7:$AK$126, 8, 0) -> #N/A | W88: =IF($W$5, FORECAST($J88,$U88:$V88,$U$5:$V$5), $T88) -> #N/A | AB88: =IFERROR( VLOOKUP($F88, $X$7:$Y$106, 2, 0), VLOOKUP($F88, $Z$7:$AA$106, 2, 0)) -> #N/A | AD88: 45543 | AE88: 3.555 | AF88: 3.51 | AG88: 2.979 | AH88: 2.947 | AI88: 4.956 | AJ88: 5.34 | AK88: 5.131
D89: =IF(B89="", "", DATE(LEFT(B89,4), MID(B89,5,2), RIGHT(B89,2))) | I89: =IF(G89="", "", DATE(LEFT(G89,4), MID(G89,5,2), RIGHT(G89,2))) | J89: =I89-D89 -> #VALUE! | K89: =IF(AB89="", "", DATE(LEFT(AB89,4), MID(AB89,5,2), RIGHT(AB89,2)))-$F89 -> #N/A | L89: 91 | M89: 365 | N89: 730 | O89: =VLOOKUP($F89, $AD$7:$AK$106, 2, 0) -> #N/A | P89: =VLOOKUP($F89, $AD$7:$AK$106, 3, 0) -> #N/A | Q89: =VLOOKUP($F89, $AD$7:$AK$106, 4, 0) -> #N/A | R89: =VLOOKUP($F89, $AD$7:$AK$106, 5, 0) -> #N/A | S89: =CHOOSE(option!$D$2, history!$O89, FORECAST(history!$J89, history!$O89:$P89, history!$K89:$L89), FORECAST(history!$J89, history!$O89:$P89, history!$K89:$L89), FORECAST(history!$J89, history!$O89:$P89, history!$K89:$L89), history!$P89, history!$Q89 ) -> #N/A | T89: =VLOOKUP($F89, $AD$7:$AK$126, 6, 0) -> #N/A | U89: =VLOOKUP($F89, $AD$7:$AK$126, 7, 0) -> #N/A | V89: =VLOOKUP($F89, $AD$7:$AK$126, 8, 0) -> #N/A | W89: =IF($W$5, FORECAST($J89,$U89:$V89,$U$5:$V$5), $T89) -> #N/A | AB89: =IFERROR( VLOOKUP($F89, $X$7:$Y$106, 2, 0), VLOOKUP($F89, $Z$7:$AA$106, 2, 0)) -> #N/A | AD89: 45542 | AE89: 3.555 | AF89: 3.51 | AG89: 2.979 | AH89: 2.947 | AI89: 4.956 | AJ89: 5.34 | AK89: 5.131
D90: =IF(B90="", "", DATE(LEFT(B90,4), MID(B90,5,2), RIGHT(B90,2))) | I90: =IF(G90="", "", DATE(LEFT(G90,4), MID(G90,5,2), RIGHT(G90,2))) | J90: =I90-D90 -> #VALUE! | K90: =IF(AB90="", "", DATE(LEFT(AB90,4), MID(AB90,5,2), RIGHT(AB90,2)))-$F90 -> #N/A | L90: 91 | M90: 365 | N90: 730 | O90: =VLOOKUP($F90, $AD$7:$AK$106, 2, 0) -> #N/A | P90: =VLOOKUP($F90, $AD$7:$AK$106, 3, 0) -> #N/A | Q90: =VLOOKUP($F90, $AD$7:$AK$106, 4, 0) -> #N/A | R90: =VLOOKUP($F90, $AD$7:$AK$106, 5, 0) -> #N/A | S90: =CHOOSE(option!$D$2, history!$O90, FORECAST(history!$J90, history!$O90:$P90, history!$K90:$L90), FORECAST(history!$J90, history!$O90:$P90, history!$K90:$L90), FORECAST(history!$J90, history!$O90:$P90, history!$K90:$L90), history!$P90, history!$Q90 ) -> #N/A | T90: =VLOOKUP($F90, $AD$7:$AK$126, 6, 0) -> #N/A | U90: =VLOOKUP($F90, $AD$7:$AK$126, 7, 0) -> #N/A | V90: =VLOOKUP($F90, $AD$7:$AK$126, 8, 0) -> #N/A | W90: =IF($W$5, FORECAST($J90,$U90:$V90,$U$5:$V$5), $T90) -> #N/A | AB90: =IFERROR( VLOOKUP($F90, $X$7:$Y$106, 2, 0), VLOOKUP($F90, $Z$7:$AA$106, 2, 0)) -> #N/A | AD90: 45541 | AE90: 3.555 | AF90: 3.51 | AG90: 2.979 | AH90: 2.947 | AI90: 4.956 | AJ90: 5.34 | AK90: 5.131
D91: =IF(B91="", "", DATE(LEFT(B91,4), MID(B91,5,2), RIGHT(B91,2))) | I91: =IF(G91="", "", DATE(LEFT(G91,4), MID(G91,5,2), RIGHT(G91,2))) | J91: =I91-D91 -> #VALUE! | K91: =IF(AB91="", "", DATE(LEFT(AB91,4), MID(AB91,5,2), RIGHT(AB91,2)))-$F91 -> #N/A | L91: 91 | M91: 365 | N91: 730 | O91: =VLOOKUP($F91, $AD$7:$AK$106, 2, 0) -> #N/A | P91: =VLOOKUP($F91, $AD$7:$AK$106, 3, 0) -> #N/A | Q91: =VLOOKUP($F91, $AD$7:$AK$106, 4, 0) -> #N/A | R91: =VLOOKUP($F91, $AD$7:$AK$106, 5, 0) -> #N/A | S91: =CHOOSE(option!$D$2, history!$O91, FORECAST(history!$J91, history!$O91:$P91, history!$K91:$L91), FORECAST(history!$J91, history!$O91:$P91, history!$K91:$L91), FORECAST(history!$J91, history!$O91:$P91, history!$K91:$L91), history!$P91, history!$Q91 ) -> #N/A | T91: =VLOOKUP($F91, $AD$7:$AK$126, 6, 0) -> #N/A | U91: =VLOOKUP($F91, $AD$7:$AK$126, 7, 0) -> #N/A | V91: =VLOOKUP($F91, $AD$7:$AK$126, 8, 0) -> #N/A | W91: =IF($W$5, FORECAST($J91,$U91:$V91,$U$5:$V$5), $T91) -> #N/A | AB91: =IFERROR( VLOOKUP($F91, $X$7:$Y$106, 2, 0), VLOOKUP($F91, $Z$7:$AA$106, 2, 0)) -> #N/A | AD91: 45540 | AE91: 3.546 | AF91: 3.51 | AG91: 2.983 | AH91: 2.97 | AI91: 4.947 | AJ91: 5.33 | AK91: 5.123
D92: =IF(B92="", "", DATE(LEFT(B92,4), MID(B92,5,2), RIGHT(B92,2))) | I92: =IF(G92="", "", DATE(LEFT(G92,4), MID(G92,5,2), RIGHT(G92,2))) | J92: =I92-D92 -> #VALUE! | K92: =IF(AB92="", "", DATE(LEFT(AB92,4), MID(AB92,5,2), RIGHT(AB92,2)))-$F92 -> #N/A | L92: 91 | M92: 365 | N92: 730 | O92: =VLOOKUP($F92, $AD$7:$AK$106, 2, 0) -> #N/A | P92: =VLOOKUP($F92, $AD$7:$AK$106, 3, 0) -> #N/A | Q92: =VLOOKUP($F92, $AD$7:$AK$106, 4, 0) -> #N/A | R92: =VLOOKUP($F92, $AD$7:$AK$106, 5, 0) -> #N/A | S92: =CHOOSE(option!$D$2, history!$O92, FORECAST(history!$J92, history!$O92:$P92, history!$K92:$L92), FORECAST(history!$J92, history!$O92:$P92, history!$K92:$L92), FORECAST(history!$J92, history!$O92:$P92, history!$K92:$L92), history!$P92, history!$Q92 ) -> #N/A | T92: =VLOOKUP($F92, $AD$7:$AK$126, 6, 0) -> #N/A | U92: =VLOOKUP($F92, $AD$7:$AK$126, 7, 0) -> #N/A | V92: =VLOOKUP($F92, $AD$7:$AK$126, 8, 0) -> #N/A | W92: =IF($W$5, FORECAST($J92,$U92:$V92,$U$5:$V$5), $T92) -> #N/A | AB92: =IFERROR( VLOOKUP($F92, $X$7:$Y$106, 2, 0), VLOOKUP($F92, $Z$7:$AA$106, 2, 0)) -> #N/A | AD92: 45539 | AE92: 3.521 | AF92: 3.51 | AG92: 2.998 | AH92: 2.991 | AI92: 4.962 | AJ92: 5.34 | AK92: 5.149
D93: =IF(B93="", "", DATE(LEFT(B93,4), MID(B93,5,2), RIGHT(B93,2))) | I93: =IF(G93="", "", DATE(LEFT(G93,4), MID(G93,5,2), RIGHT(G93,2))) | J93: =I93-D93 -> #VALUE! | K93: =IF(AB93="", "", DATE(LEFT(AB93,4), MID(AB93,5,2), RIGHT(AB93,2)))-$F93 -> #N/A | L93: 91 | M93: 365 | N93: 730 | O93: =VLOOKUP($F93, $AD$7:$AK$106, 2, 0) -> #N/A | P93: =VLOOKUP($F93, $AD$7:$AK$106, 3, 0) -> #N/A | Q93: =VLOOKUP($F93, $AD$7:$AK$106, 4, 0) -> #N/A | R93: =VLOOKUP($F93, $AD$7:$AK$106, 5, 0) -> #N/A | S93: =CHOOSE(option!$D$2, history!$O93, FORECAST(history!$J93, history!$O93:$P93, history!$K93:$L93), FORECAST(history!$J93, history!$O93:$P93, history!$K93:$L93), FORECAST(history!$J93, history!$O93:$P93, history!$K93:$L93), history!$P93, history!$Q93 ) -> #N/A | T93: =VLOOKUP($F93, $AD$7:$AK$126, 6, 0) -> #N/A | U93: =VLOOKUP($F93, $AD$7:$AK$126, 7, 0) -> #N/A | V93: =VLOOKUP($F93, $AD$7:$AK$126, 8, 0) -> #N/A | W93: =IF($W$5, FORECAST($J93,$U93:$V93,$U$5:$V$5), $T93) -> #N/A | AB93: =IFERROR( VLOOKUP($F93, $X$7:$Y$106, 2, 0), VLOOKUP($F93, $Z$7:$AA$106, 2, 0)) -> #N/A | AD93: 45538 | AE93: 3.507 | AF93: 3.51 | AG93: 3.031 | AH93: 3.041 | AI93: 4.995 | AJ93: 5.32 | AK93: 5.167
