Workbook

Sheet 주요통화 시세
D2: 해외통화 시세
X4: =NOW() -> 43620.582
E5: 2 | F5: 1 | G5: 4 | H5: 32 | I5: 14 | J5: 15 | K5: 12 | L5: 3 | M5: 11 | N5: 51 | O5: 19 | P5: 47 | Q5: 10 | R5: 39 | S5: 24 | T5: 26 | U5: 40 | V5: 46 | W5: 52 | X5: 55 | Y5: 58
E6: =VLOOKUP(E$5,$BX:$BY,2,0) -> KRW | F6: =VLOOKUP(F$5,$BX:$BY,2,0) -> USD | G6: =VLOOKUP(G$5,$BX:$BY,2,0) -> EUR | H6: =VLOOKUP(H$5,$BX:$BY,2,0) -> JPY | I6: =VLOOKUP(I$5,$BX:$BY,2,0) -> CNY | J6: =VLOOKUP(J$5,$BX:$BY,2,0) -> CNH | K6: =VLOOKUP(K$5,$BX:$BY,2,0) -> CHF | L6: =VLOOKUP(L$5,$BX:$BY,2,0) -> AUD | ... Y6: =VLOOKUP(Y$5,$BX:$BY,2,0) -> TWD
D7: currency | BU7: 1 | CA7: =VLOOKUP(BU7,BT8:BU13,2,0) -> 직전대비 | CB7: ='주요통화 시세'!E6 -> KRW | CC7: ='주요통화 시세'!F6 -> USD | CD7: ='주요통화 시세'!G6 -> EUR | CE7: ='주요통화 시세'!H6 -> JPY | CF7: ='주요통화 시세'!I6 -> CNY | CG7: ='주요통화 시세'!J6 -> CNH | CH7: ='주요통화 시세'!K6 -> CHF | CI7: ='주요통화 시세'!L6 -> AUD | ... CV7: ='주요통화 시세'!Y6 -> TWD
B8: 2 | C8: =VLOOKUP($B8,$BX:$BY,2,0) -> KRW | E8: =_xll.IMDP("FX",$C8&E$6,"매입") | F8: =_xll.IMDP("FX",$C8&F$6,"매입") | G8: =_xll.IMDP("FX",$C8&G$6,"매입") | H8: =_xll.IMDP("FX",$C8&H$6,"매입") -> 9.14 | I8: =_xll.IMDP("FX",$C8&I$6,"매입") | J8: =_xll.IMDP("FX",$C8&J$6,"매입") | K8: =_xll.IMDP("FX",$C8&K$6,"매입") | L8: =_xll.IMDP("FX",$C8&L$6,"매입") | ... Y8: =_xll.IMDP("FX",$C8&Y$6,"매입") | BT8: 1 | BU8: 직전대비 | BW8: IMDP("FX",$AI9&AK$8,"BID직전가") | BX8: 1 | BY8: USD | CA8: =C8 -> KRW | CB8: =IF(ISERROR(E8-IF($BU$7=1,_xll.IMDP("FX",$CA8&CB$7,"BID직전가"),_xll.IMDP("FX",$CA8&CB$7,"뉴욕매입종가",VLOOKUP($BU$7,$BT$8:$BV$13,3,0),"FILL=TRUE"))),"",E8-IF($BU$7=1,_xll.IMDP("FX",$CA8&CB$7,"BID직전가"),_xll.IMDP("FX",$CA8&CB$7,"뉴욕매입종가",VLOOKUP($BU$7,$BT$8:$BV$13,3,0),"FILL=TRUE"))) | CC8: =IF(ISERROR(F8-IF($BU$7=1,_xll.IMDP("FX",$CA8&CC$7,"BID직전가"),_xll.IMDP("FX",$CA8&CC$7,"뉴욕매입종가",VLOOKUP($BU$7,$BT$8:$BV$13,3,0),"FILL=TRUE"))),"",F8-IF($BU$7=1,_xll.IMDP("FX",$CA8&CC$7,"BID직전가"),_xll.IMDP("FX",$CA8&CC$7,"뉴욕매입종가",VLOOKUP($BU$7,$BT$8:$BV$13,3,0),"FILL=TRUE"))) | CD8: =IF(ISERROR(G8-IF($BU$7=1,_xll.IMDP("FX",$CA8&CD$7,"BID직전가"),_xll.IMDP("FX",$CA8&CD$7,"뉴욕매입종가",VLOOKUP($BU$7,$BT$8:$BV$13,3,0),"FILL=TRUE"))),"",G8-IF($BU$7=1,_xll.IMDP("FX",$CA8&CD$7,"BID직전가"),_xll.IMDP("FX",$CA8&CD$7,"뉴욕매입종가",VLOOKUP($BU$7,$BT$8:$BV$13,3,0),"FILL=TRUE"))) | CE8: =IF(ISERROR(H8-IF($BU$7=1,_xll.IMDP("FX",$CA8&CE$7,"BID직전가"),_xll.IMDP("FX",$CA8&CE$7,"뉴욕매입종가",VLOOKUP($BU$7,$BT$8:$BV$13,3,0),"FILL=TRUE"))),"",H8-IF($BU$7=1,_xll.IMDP("FX",$CA8&CE$7,"BID직전가"),_xll.IMDP("FX",$CA8&CE$7,"뉴욕매입종가",VLOOKUP($BU$7,$BT$8:$BV$13,3,0),"FILL=TRUE"))) -> 0 | CF8: =IF(ISERROR(I8-IF($BU$7=1,_xll.IMDP("FX",$CA8&CF$7,"BID직전가"),_xll.IMDP("FX",$CA8&CF$7,"뉴욕매입종가",VLOOKUP($BU$7,$BT$8:$BV$13,3,0),"FILL=TRUE"))),"",I8-IF($BU$7=1,_xll.IMDP("FX",$CA8&CF$7,"BID직전가"),_xll.IMDP("FX",$CA8&CF$7,"뉴욕매입종가",VLOOKUP($BU$7,$BT$8:$BV$13,3,0),"FILL=TRUE"))) | CG8: =IF(ISERROR(J8-IF($BU$7=1,_xll.IMDP("FX",$CA8&CG$7,"BID직전가"),_xll.IMDP("FX",$CA8&CG$7,"뉴욕매입종가",VLOOKUP($BU$7,$BT$8:$BV$13,3,0),"FILL=TRUE"))),"",J8-IF($BU$7=1,_xll.IMDP("FX",$CA8&CG$7,"BID직전가"),_xll.IMDP("FX",$CA8&CG$7,"뉴욕매입종가",VLOOKUP($BU$7,$BT$8:$BV$13,3,0),"FILL=TRUE"))) | CH8: =IF(ISERROR(K8-IF($BU$7=1,_xll.IMDP("FX",$CA8&CH$7,"BID직전가"),_xll.IMDP("FX",$CA8&CH$7,"뉴욕매입종가",VLOOKUP($BU$7,$BT$8:$BV$13,3,0),"FILL=TRUE"))),"",K8-IF($BU$7=1,_xll.IMDP("FX",$CA8&CH$7,"BID직전가"),_xll.IMDP("FX",$CA8&CH$7,"뉴욕매입종가",VLOOKUP($BU$7,$BT$8:$BV$13,3,0),"FILL=TRUE"))) | CI8: =IF(ISERROR(L8-IF($BU$7=1,_xll.IMDP("FX",$CA8&CI$7,"BID직전가"),_xll.IMDP("FX",$CA8&CI$7,"뉴욕매입종가",VLOOKUP($BU$7,$BT$8:$BV$13,3,0),"FILL=TRUE"))),"",L8-IF($BU$7=1,_xll.IMDP("FX",$CA8&CI$7,"BID직전가"),_xll.IMDP("FX",$CA8&CI$7,"뉴욕매입종가",VLOOKUP($BU$7,$BT$8:$BV$13,3,0),"FILL=TRUE"))) | ... CV8: =IF(ISERROR(Y8-IF($BU$7=1,_xll.IMDP("FX",$CA8&CV$7,"BID직전가"),_xll.IMDP("FX",$CA8&CV$7,"뉴욕매입종가",VLOOKUP($BU$7,$BT$8:$BV$13,3,0),"FILL=TRUE"))),"",Y8-IF($BU$7=1,_xll.IMDP("FX",$CA8&CV$7,"BID직전가"),_xll.IMDP("FX",$CA8&CV$7,"뉴욕매입종가",VLOOKUP($BU$7,$BT$8:$BV$13,3,0),"FILL=TRUE")))
B9: 1 | C9: =VLOOKUP($B9,$BX:$BY,2,0) -> USD | E9: =_xll.IMDP("FX",$C9&E$6,"매입") -> 1181.5 | F9: =_xll.IMDP("FX",$C9&F$6,"매입") | G9: =_xll.IMDP("FX",$C9&G$6,"매입") -> 0.8889 | H9: =_xll.IMDP("FX",$C9&H$6,"매입") -> 107.957 | I9: =_xll.IMDP("FX",$C9&I$6,"매입") -> 6.9067 | J9: =_xll.IMDP("FX",$C9&J$6,"매입") -> 6.9261 | K9: =_xll.IMDP("FX",$C9&K$6,"매입") -> 0.9932 | L9: =_xll.IMDP("FX",$C9&L$6,"매입") -> 1.4345 | ... Y9: =_xll.IMDP("FX",$C9&Y$6,"매입") -> 31.43 | BT9: 2 | BU9: 1 Day | BV9: =WORKDAY(TODAY(),-1) -> 43619 | BW9: =WORKDAY(TODAY(),-1) -> 43619 | BX9: 2 | BY9: KRW | CA9: =C9 -> USD | CB9: =IF(ISERROR(E9-IF($BU$7=1,_xll.IMDP("FX",$CA9&CB$7,"BID직전가"),_xll.IMDP("FX",$CA9&CB$7,"뉴욕매입종가",VLOOKUP($BU$7,$BT$8:$BV$13,3,0),"FILL=TRUE"))),"",E9-IF($BU$7=1,_xll.IMDP("FX",$CA9&CB$7,"BID직전가"),_xll.IMDP("FX",$CA9&CB$7,"뉴욕매입종가",VLOOKUP($BU$7,$BT$8:$BV$13,3,0),"FILL=TRUE"))) -> 0 | CC9: =IF(ISERROR(F9-IF($BU$7=1,_xll.IMDP("FX",$CA9&CC$7,"BID직전가"),_xll.IMDP("FX",$CA9&CC$7,"뉴욕매입종가",VLOOKUP($BU$7,$BT$8:$BV$13,3,0),"FILL=TRUE"))),"",F9-IF($BU$7=1,_xll.IMDP("FX",$CA9&CC$7,"BID직전가"),_xll.IMDP("FX",$CA9&CC$7,"뉴욕매입종가",VLOOKUP($BU$7,$BT$8:$BV$13,3,0),"FILL=TRUE"))) | CD9: =IF(ISERROR(G9-IF($BU$7=1,_xll.IMDP("FX",$CA9&CD$7,"BID직전가"),_xll.IMDP("FX",$CA9&CD$7,"뉴욕매입종가",VLOOKUP($BU$7,$BT$8:$BV$13,3,0),"FILL=TRUE"))),"",G9-IF($BU$7=1,_xll.IMDP("FX",$CA9&CD$7,"BID직전가"),_xll.IMDP("FX",$CA9&CD$7,"뉴욕매입종가",VLOOKUP($BU$7,$BT$8:$BV$13,3,0),"FILL=TRUE"))) -> 0.0001 | CE9: =IF(ISERROR(H9-IF($BU$7=1,_xll.IMDP("FX",$CA9&CE$7,"BID직전가"),_xll.IMDP("FX",$CA9&CE$7,"뉴욕매입종가",VLOOKUP($BU$7,$BT$8:$BV$13,3,0),"FILL=TRUE"))),"",H9-IF($BU$7=1,_xll.IMDP("FX",$CA9&CE$7,"BID직전가"),_xll.IMDP("FX",$CA9&CE$7,"뉴욕매입종가",VLOOKUP($BU$7,$BT$8:$BV$13,3,0),"FILL=TRUE"))) -> 0.007 | CF9: =IF(ISERROR(I9-IF($BU$7=1,_xll.IMDP("FX",$CA9&CF$7,"BID직전가"),_xll.IMDP("FX",$CA9&CF$7,"뉴욕매입종가",VLOOKUP($BU$7,$BT$8:$BV$13,3,0),"FILL=TRUE"))),"",I9-IF($BU$7=1,_xll.IMDP("FX",$CA9&CF$7,"BID직전가"),_xll.IMDP("FX",$CA9&CF$7,"뉴욕매입종가",VLOOKUP($BU$7,$BT$8:$BV$13,3,0),"FILL=TRUE"))) -> 0.0003 | CG9: =IF(ISERROR(J9-IF($BU$7=1,_xll.IMDP("FX",$CA9&CG$7,"BID직전가"),_xll.IMDP("FX",$CA9&CG$7,"뉴욕매입종가",VLOOKUP($BU$7,$BT$8:$BV$13,3,0),"FILL=TRUE"))),"",J9-IF($BU$7=1,_xll.IMDP("FX",$CA9&CG$7,"BID직전가"),_xll.IMDP("FX",$CA9&CG$7,"뉴욕매입종가",VLOOKUP($BU$7,$BT$8:$BV$13,3,0),"FILL=TRUE"))) -> 0.0002 | CH9: =IF(ISERROR(K9-IF($BU$7=1,_xll.IMDP("FX",$CA9&CH$7,"BID직전가"),_xll.IMDP("FX",$CA9&CH$7,"뉴욕매입종가",VLOOKUP($BU$7,$BT$8:$BV$13,3,0),"FILL=TRUE"))),"",K9-IF($BU$7=1,_xll.IMDP("FX",$CA9&CH$7,"BID직전가"),_xll.IMDP("FX",$CA9&CH$7,"뉴욕매입종가",VLOOKUP($BU$7,$BT$8:$BV$13,3,0),"FILL=TRUE"))) -> 0 | CI9: =IF(ISERROR(L9-IF($BU$7=1,_xll.IMDP("FX",$CA9&CI$7,"BID직전가"),_xll.IMDP("FX",$CA9&CI$7,"뉴욕매입종가",VLOOKUP($BU$7,$BT$8:$BV$13,3,0),"FILL=TRUE"))),"",L9-IF($BU$7=1,_xll.IMDP("FX",$CA9&CI$7,"BID직전가"),_xll.IMDP("FX",$CA9&CI$7,"뉴욕매입종가",VLOOKUP($BU$7,$BT$8:$BV$13,3,0),"FILL=TRUE"))) -> -0.0003 | ... CV9: =IF(ISERROR(Y9-IF($BU$7=1,_xll.IMDP("FX",$CA9&CV$7,"BID직전가"),_xll.IMDP("FX",$CA9&CV$7,"뉴욕매입종가",VLOOKUP($BU$7,$BT$8:$BV$13,3,0),"FILL=TRUE"))),"",Y9-IF($BU$7=1,_xll.IMDP("FX",$CA9&CV$7,"BID직전가"),_xll.IMDP("FX",$CA9&CV$7,"뉴욕매입종가",VLOOKUP($BU$7,$BT$8:$BV$13,3,0),"FILL=TRUE"))) -> -0.02
B10: 4 | C10: =VLOOKUP($B10,$BX:$BY,2,0) -> EUR | E10: =_xll.IMDP("FX",$C10&E$6,"매입") -> 1328.6 | F10: =_xll.IMDP("FX",$C10&F$6,"매입") -> 1.1245 | G10: =_xll.IMDP("FX",$C10&G$6,"매입") | H10: =_xll.IMDP("FX",$C10&H$6,"매입") -> 121.41 | I10: =_xll.IMDP("FX",$C10&I$6,"매입") -> 7.7673 | J10: =_xll.IMDP("FX",$C10&J$6,"매입") -> 7.7875 | K10: =_xll.IMDP("FX",$C10&K$6,"매입") -> 1.11708 | L10: =_xll.IMDP("FX",$C10&L$6,"매입") -> 1.6141 | ... Y10: =_xll.IMDP("FX",$C10&Y$6,"매입") -> 35.364 | BT10: 3 | BU10: 5 Day | BV10: =TODAY()-5 -> 43615 | BW10: =WORKDAY(TODAY(),-5) -> 43613 | BX10: 3 | BY10: AUD | CA10: =C10 -> EUR | CB10: =IF(ISERROR(E10-IF($BU$7=1,_xll.IMDP("FX",$CA10&CB$7,"BID직전가"),_xll.IMDP("FX",$CA10&CB$7,"뉴욕매입종가",VLOOKUP($BU$7,$BT$8:$BV$13,3,0),"FILL=TRUE"))),"",E10-IF($BU$7=1,_xll.IMDP("FX",$CA10&CB$7,"BID직전가"),_xll.IMDP("FX",$CA10&CB$7,"뉴욕매입종가",VLOOKUP($BU$7,$BT$8:$BV$13,3,0),"FILL=TRUE"))) -> -0.14 | CC10: =IF(ISERROR(F10-IF($BU$7=1,_xll.IMDP("FX",$CA10&CC$7,"BID직전가"),_xll.IMDP("FX",$CA10&CC$7,"뉴욕매입종가",VLOOKUP($BU$7,$BT$8:$BV$13,3,0),"FILL=TRUE"))),"",F10-IF($BU$7=1,_xll.IMDP("FX",$CA10&CC$7,"BID직전가"),_xll.IMDP("FX",$CA10&CC$7,"뉴욕매입종가",VLOOKUP($BU$7,$BT$8:$BV$13,3,0),"FILL=TRUE"))) -> -0.00012 | CD10: =IF(ISERROR(G10-IF($BU$7=1,_xll.IMDP("FX",$CA10&CD$7,"BID직전가"),_xll.IMDP("FX",$CA10&CD$7,"뉴욕매입종가",VLOOKUP($BU$7,$BT$8:$BV$13,3,0),"FILL=TRUE"))),"",G10-IF($BU$7=1,_xll.IMDP("FX",$CA10&CD$7,"BID직전가"),_xll.IMDP("FX",$CA10&CD$7,"뉴욕매입종가",VLOOKUP($BU$7,$BT$8:$BV$13,3,0),"FILL=TRUE"))) | CE10: =IF(ISERROR(H10-IF($BU$7=1,_xll.IMDP("FX",$CA10&CE$7,"BID직전가"),_xll.IMDP("FX",$CA10&CE$7,"뉴욕매입종가",VLOOKUP($BU$7,$BT$8:$BV$13,3,0),"FILL=TRUE"))),"",H10-IF($BU$7=1,_xll.IMDP("FX",$CA10&CE$7,"BID직전가"),_xll.IMDP("FX",$CA10&CE$7,"뉴욕매입종가",VLOOKUP($BU$7,$BT$8:$BV$13,3,0),"FILL=TRUE"))) -> 0.01 | CF10: =IF(ISERROR(I10-IF($BU$7=1,_xll.IMDP("FX",$CA10&CF$7,"BID직전가"),_xll.IMDP("FX",$CA10&CF$7,"뉴욕매입종가",VLOOKUP($BU$7,$BT$8:$BV$13,3,0),"FILL=TRUE"))),"",I10-IF($BU$7=1,_xll.IMDP("FX",$CA10&CF$7,"BID직전가"),_xll.IMDP("FX",$CA10&CF$7,"뉴욕매입종가",VLOOKUP($BU$7,$BT$8:$BV$13,3,0),"FILL=TRUE"))) -> -0.0006 | CG10: =IF(ISERROR(J10-IF($BU$7=1,_xll.IMDP("FX",$CA10&CG$7,"BID직전가"),_xll.IMDP("FX",$CA10&CG$7,"뉴욕매입종가",VLOOKUP($BU$7,$BT$8:$BV$13,3,0),"FILL=TRUE"))),"",J10-IF($BU$7=1,_xll.IMDP("FX",$CA10&CG$7,"BID직전가"),_xll.IMDP("FX",$CA10&CG$7,"뉴욕매입종가",VLOOKUP($BU$7,$BT$8:$BV$13,3,0),"FILL=TRUE"))) -> -0.0012 | CH10: =IF(ISERROR(K10-IF($BU$7=1,_xll.IMDP("FX",$CA10&CH$7,"BID직전가"),_xll.IMDP("FX",$CA10&CH$7,"뉴욕매입종가",VLOOKUP($BU$7,$BT$8:$BV$13,3,0),"FILL=TRUE"))),"",K10-IF($BU$7=1,_xll.IMDP("FX",$CA10&CH$7,"BID직전가"),_xll.IMDP("FX",$CA10&CH$7,"뉴욕매입종가",VLOOKUP($BU$7,$BT$8:$BV$13,3,0),"FILL=TRUE"))) -> 3e-05 | CI10: =IF(ISERROR(L10-IF($BU$7=1,_xll.IMDP("FX",$CA10&CI$7,"BID직전가"),_xll.IMDP("FX",$CA10&CI$7,"뉴욕매입종가",VLOOKUP($BU$7,$BT$8:$BV$13,3,0),"FILL=TRUE"))),"",L10-IF($BU$7=1,_xll.IMDP("FX",$CA10&CI$7,"BID직전가"),_xll.IMDP("FX",$CA10&CI$7,"뉴욕매입종가",VLOOKUP($BU$7,$BT$8:$BV$13,3,0),"FILL=TRUE"))) -> 0 | ... CV10: =IF(ISERROR(Y10-IF($BU$7=1,_xll.IMDP("FX",$CA10&CV$7,"BID직전가"),_xll.IMDP("FX",$CA10&CV$7,"뉴욕매입종가",VLOOKUP($BU$7,$BT$8:$BV$13,3,0),"FILL=TRUE"))),"",Y10-IF($BU$7=1,_xll.IMDP("FX",$CA10&CV$7,"BID직전가"),_xll.IMDP("FX",$CA10&CV$7,"뉴욕매입종가",VLOOKUP($BU$7,$BT$8:$BV$13,3,0),"FILL=TRUE"))) -> -0.004
B11: 32 | C11: =VLOOKUP($B11,$BX:$BY,2,0) -> JPY | E11: =_xll.IMDP("FX",$C11&E$6,"매입") -> 1094.38 | F11: =_xll.IMDP("FX",$C11&F$6,"매입") -> 0.00925 | G11: =_xll.IMDP("FX",$C11&G$6,"매입") -> 0.8234 | H11: =_xll.IMDP("FX",$C11&H$6,"매입") | I11: =_xll.IMDP("FX",$C11&I$6,"매입") -> 0.0639 | J11: =_xll.IMDP("FX",$C11&J$6,"매입") -> 0.06405 | K11: =_xll.IMDP("FX",$C11&K$6,"매입") -> 0.9196 | L11: =_xll.IMDP("FX",$C11&L$6,"매입") -> 0.01328 | ... Y11: =_xll.IMDP("FX",$C11&Y$6,"매입") -> 0.2887 | BT11: 4 | BU11: Week | BV11: =TODAY()-7 -> 43613 | BW11: =WORKDAY(TODAY(),-7) -> 43609 | BX11: 4 | BY11: EUR | CA11: =C11 -> JPY | CB11: =IF(ISERROR(E11-IF($BU$7=1,_xll.IMDP("FX",$CA11&CB$7,"BID직전가"),_xll.IMDP("FX",$CA11&CB$7,"뉴욕매입종가",VLOOKUP($BU$7,$BT$8:$BV$13,3,0),"FILL=TRUE"))),"",E11-IF($BU$7=1,_xll.IMDP("FX",$CA11&CB$7,"BID직전가"),_xll.IMDP("FX",$CA11&CB$7,"뉴욕매입종가",VLOOKUP($BU$7,$BT$8:$BV$13,3,0),"FILL=TRUE"))) -> 0.3 | CC11: =IF(ISERROR(F11-IF($BU$7=1,_xll.IMDP("FX",$CA11&CC$7,"BID직전가"),_xll.IMDP("FX",$CA11&CC$7,"뉴욕매입종가",VLOOKUP($BU$7,$BT$8:$BV$13,3,0),"FILL=TRUE"))),"",F11-IF($BU$7=1,_xll.IMDP("FX",$CA11&CC$7,"BID직전가"),_xll.IMDP("FX",$CA11&CC$7,"뉴욕매입종가",VLOOKUP($BU$7,$BT$8:$BV$13,3,0),"FILL=TRUE"))) -> 0 | CD11: =IF(ISERROR(G11-IF($BU$7=1,_xll.IMDP("FX",$CA11&CD$7,"BID직전가"),_xll.IMDP("FX",$CA11&CD$7,"뉴욕매입종가",VLOOKUP($BU$7,$BT$8:$BV$13,3,0),"FILL=TRUE"))),"",G11-IF($BU$7=1,_xll.IMDP("FX",$CA11&CD$7,"BID직전가"),_xll.IMDP("FX",$CA11&CD$7,"뉴욕매입종가",VLOOKUP($BU$7,$BT$8:$BV$13,3,0),"FILL=TRUE"))) -> 0.00024 | CE11: =IF(ISERROR(H11-IF($BU$7=1,_xll.IMDP("FX",$CA11&CE$7,"BID직전가"),_xll.IMDP("FX",$CA11&CE$7,"뉴욕매입종가",VLOOKUP($BU$7,$BT$8:$BV$13,3,0),"FILL=TRUE"))),"",H11-IF($BU$7=1,_xll.IMDP("FX",$CA11&CE$7,"BID직전가"),_xll.IMDP("FX",$CA11&CE$7,"뉴욕매입종가",VLOOKUP($BU$7,$BT$8:$BV$13,3,0),"FILL=TRUE"))) | CF11: =IF(ISERROR(I11-IF($BU$7=1,_xll.IMDP("FX",$CA11&CF$7,"BID직전가"),_xll.IMDP("FX",$CA11&CF$7,"뉴욕매입종가",VLOOKUP($BU$7,$BT$8:$BV$13,3,0),"FILL=TRUE"))),"",I11-IF($BU$7=1,_xll.IMDP("FX",$CA11&CF$7,"BID직전가"),_xll.IMDP("FX",$CA11&CF$7,"뉴욕매입종가",VLOOKUP($BU$7,$BT$8:$BV$13,3,0),"FILL=TRUE"))) -> 0 | CG11: =IF(ISERROR(J11-IF($BU$7=1,_xll.IMDP("FX",$CA11&CG$7,"BID직전가"),_xll.IMDP("FX",$CA11&CG$7,"뉴욕매입종가",VLOOKUP($BU$7,$BT$8:$BV$13,3,0),"FILL=TRUE"))),"",J11-IF($BU$7=1,_xll.IMDP("FX",$CA11&CG$7,"BID직전가"),_xll.IMDP("FX",$CA11&CG$7,"뉴욕매입종가",VLOOKUP($BU$7,$BT$8:$BV$13,3,0),"FILL=TRUE"))) -> -1e-05 | CH11: =IF(ISERROR(K11-IF($BU$7=1,_xll.IMDP("FX",$CA11&CH$7,"BID직전가"),_xll.IMDP("FX",$CA11&CH$7,"뉴욕매입종가",VLOOKUP($BU$7,$BT$8:$BV$13,3,0),"FILL=TRUE"))),"",K11-IF($BU$7=1,_xll.IMDP("FX",$CA11&CH$7,"BID직전가"),_xll.IMDP("FX",$CA11&CH$7,"뉴욕매입종가",VLOOKUP($BU$7,$BT$8:$BV$13,3,0),"FILL=TRUE"))) -> -0.0004 | CI11: =IF(ISERROR(L11-IF($BU$7=1,_xll.IMDP("FX",$CA11&CI$7,"BID직전가"),_xll.IMDP("FX",$CA11&CI$7,"뉴욕매입종가",VLOOKUP($BU$7,$BT$8:$BV$13,3,0),"FILL=TRUE"))),"",L11-IF($BU$7=1,_xll.IMDP("FX",$CA11&CI$7,"BID직전가"),_xll.IMDP("FX",$CA11&CI$7,"뉴욕매입종가",VLOOKUP($BU$7,$BT$8:$BV$13,3,0),"FILL=TRUE"))) -> 1e-05 | ... CV11: =IF(ISERROR(Y11-IF($BU$7=1,_xll.IMDP("FX",$CA11&CV$7,"BID직전가"),_xll.IMDP("FX",$CA11&CV$7,"뉴욕매입종가",VLOOKUP($BU$7,$BT$8:$BV$13,3,0),"FILL=TRUE"))),"",Y11-IF($BU$7=1,_xll.IMDP("FX",$CA11&CV$7,"BID직전가"),_xll.IMDP("FX",$CA11&CV$7,"뉴욕매입종가",VLOOKUP($BU$7,$BT$8:$BV$13,3,0),"FILL=TRUE"))) -> 0
B12: 14 | C12: =VLOOKUP($B12,$BX:$BY,2,0) -> CNY | E12: =_xll.IMDP("FX",$C12&E$6,"매입") -> 171.04 | F12: =_xll.IMDP("FX",$C12&F$6,"매입") -> 0.1447 | G12: =_xll.IMDP("FX",$C12&G$6,"매입") -> 0.12866 | H12: =_xll.IMDP("FX",$C12&H$6,"매입") -> 15.609 | I12: =_xll.IMDP("FX",$C12&I$6,"매입") | J12: =_xll.IMDP("FX",$C12&J$6,"매입") -> 1.0021 | K12: =_xll.IMDP("FX",$C12&K$6,"매입") -> 0.1433 | L12: =_xll.IMDP("FX",$C12&L$6,"매입") -> 0.203 | ... Y12: =_xll.IMDP("FX",$C12&Y$6,"매입") -> 4.5527 | BT12: 5 | BU12: Month | BV12: =EDATE(TODAY(),-1) -> 43589 | BW12: =EDATE(TODAY(),-1) -> 43589 | BX12: 5 | BY12: GBP | CA12: =C12 -> CNY | CB12: =IF(ISERROR(E12-IF($BU$7=1,_xll.IMDP("FX",$CA12&CB$7,"BID직전가"),_xll.IMDP("FX",$CA12&CB$7,"뉴욕매입종가",VLOOKUP($BU$7,$BT$8:$BV$13,3,0),"FILL=TRUE"))),"",E12-IF($BU$7=1,_xll.IMDP("FX",$CA12&CB$7,"BID직전가"),_xll.IMDP("FX",$CA12&CB$7,"뉴욕매입종가",VLOOKUP($BU$7,$BT$8:$BV$13,3,0),"FILL=TRUE"))) -> 0.01 | CC12: =IF(ISERROR(F12-IF($BU$7=1,_xll.IMDP("FX",$CA12&CC$7,"BID직전가"),_xll.IMDP("FX",$CA12&CC$7,"뉴욕매입종가",VLOOKUP($BU$7,$BT$8:$BV$13,3,0),"FILL=TRUE"))),"",F12-IF($BU$7=1,_xll.IMDP("FX",$CA12&CC$7,"BID직전가"),_xll.IMDP("FX",$CA12&CC$7,"뉴욕매입종가",VLOOKUP($BU$7,$BT$8:$BV$13,3,0),"FILL=TRUE"))) -> 0 | CD12: =IF(ISERROR(G12-IF($BU$7=1,_xll.IMDP("FX",$CA12&CD$7,"BID직전가"),_xll.IMDP("FX",$CA12&CD$7,"뉴욕매입종가",VLOOKUP($BU$7,$BT$8:$BV$13,3,0),"FILL=TRUE"))),"",G12-IF($BU$7=1,_xll.IMDP("FX",$CA12&CD$7,"BID직전가"),_xll.IMDP("FX",$CA12&CD$7,"뉴욕매입종가",VLOOKUP($BU$7,$BT$8:$BV$13,3,0),"FILL=TRUE"))) -> 2e-05 | CE12: =IF(ISERROR(H12-IF($BU$7=1,_xll.IMDP("FX",$CA12&CE$7,"BID직전가"),_xll.IMDP("FX",$CA12&CE$7,"뉴욕매입종가",VLOOKUP($BU$7,$BT$8:$BV$13,3,0),"FILL=TRUE"))),"",H12-IF($BU$7=1,_xll.IMDP("FX",$CA12&CE$7,"BID직전가"),_xll.IMDP("FX",$CA12&CE$7,"뉴욕매입종가",VLOOKUP($BU$7,$BT$8:$BV$13,3,0),"FILL=TRUE"))) -> -0.003 | CF12: =IF(ISERROR(I12-IF($BU$7=1,_xll.IMDP("FX",$CA12&CF$7,"BID직전가"),_xll.IMDP("FX",$CA12&CF$7,"뉴욕매입종가",VLOOKUP($BU$7,$BT$8:$BV$13,3,0),"FILL=TRUE"))),"",I12-IF($BU$7=1,_xll.IMDP("FX",$CA12&CF$7,"BID직전가"),_xll.IMDP("FX",$CA12&CF$7,"뉴욕매입종가",VLOOKUP($BU$7,$BT$8:$BV$13,3,0),"FILL=TRUE"))) | CG12: =IF(ISERROR(J12-IF($BU$7=1,_xll.IMDP("FX",$CA12&CG$7,"BID직전가"),_xll.IMDP("FX",$CA12&CG$7,"뉴욕매입종가",VLOOKUP($BU$7,$BT$8:$BV$13,3,0),"FILL=TRUE"))),"",J12-IF($BU$7=1,_xll.IMDP("FX",$CA12&CG$7,"BID직전가"),_xll.IMDP("FX",$CA12&CG$7,"뉴욕매입종가",VLOOKUP($BU$7,$BT$8:$BV$13,3,0),"FILL=TRUE"))) -> 0 | CH12: =IF(ISERROR(K12-IF($BU$7=1,_xll.IMDP("FX",$CA12&CH$7,"BID직전가"),_xll.IMDP("FX",$CA12&CH$7,"뉴욕매입종가",VLOOKUP($BU$7,$BT$8:$BV$13,3,0),"FILL=TRUE"))),"",K12-IF($BU$7=1,_xll.IMDP("FX",$CA12&CH$7,"BID직전가"),_xll.IMDP("FX",$CA12&CH$7,"뉴욕매입종가",VLOOKUP($BU$7,$BT$8:$BV$13,3,0),"FILL=TRUE"))) -> 0 | CI12: =IF(ISERROR(L12-IF($BU$7=1,_xll.IMDP("FX",$CA12&CI$7,"BID직전가"),_xll.IMDP("FX",$CA12&CI$7,"뉴욕매입종가",VLOOKUP($BU$7,$BT$8:$BV$13,3,0),"FILL=TRUE"))),"",L12-IF($BU$7=1,_xll.IMDP("FX",$CA12&CI$7,"BID직전가"),_xll.IMDP("FX",$CA12&CI$7,"뉴욕매입종가",VLOOKUP($BU$7,$BT$8:$BV$13,3,0),"FILL=TRUE"))) -> 0.001 | ... CV12: =IF(ISERROR(Y12-IF($BU$7=1,_xll.IMDP("FX",$CA12&CV$7,"BID직전가"),_xll.IMDP("FX",$CA12&CV$7,"뉴욕매입종가",VLOOKUP($BU$7,$BT$8:$BV$13,3,0),"FILL=TRUE"))),"",Y12-IF($BU$7=1,_xll.IMDP("FX",$CA12&CV$7,"BID직전가"),_xll.IMDP("FX",$CA12&CV$7,"뉴욕매입종가",VLOOKUP($BU$7,$BT$8:$BV$13,3,0),"FILL=TRUE"))) -> -0.0001
B13: 15 | C13: =VLOOKUP($B13,$BX:$BY,2,0) -> CNH | E13: =_xll.IMDP("FX",$C13&E$6,"매입") -> 170.58 | F13: =_xll.IMDP("FX",$C13&F$6,"매입") -> 0.14391 | G13: =_xll.IMDP("FX",$C13&G$6,"매입") | H13: =_xll.IMDP("FX",$C13&H$6,"매입") -> 15.585 | I13: =_xll.IMDP("FX",$C13&I$6,"매입") -> 0.9968 | J13: =_xll.IMDP("FX",$C13&J$6,"매입") | K13: =_xll.IMDP("FX",$C13&K$6,"매입") | L13: =_xll.IMDP("FX",$C13&L$6,"매입") | ... Y13: =_xll.IMDP("FX",$C13&Y$6,"매입") -> 4.5411 | BT13: 6 | BU13: Year | BV13: =EDATE(TODAY(),-12) -> 43255 | BW13: =EDATE(TODAY(),-12) -> 43255 | BX13: 6 | BY13: NZD | CA13: =C13 -> CNH | CB13: =IF(ISERROR(E13-IF($BU$7=1,_xll.IMDP("FX",$CA13&CB$7,"BID직전가"),_xll.IMDP("FX",$CA13&CB$7,"뉴욕매입종가",VLOOKUP($BU$7,$BT$8:$BV$13,3,0),"FILL=TRUE"))),"",E13-IF($BU$7=1,_xll.IMDP("FX",$CA13&CB$7,"BID직전가"),_xll.IMDP("FX",$CA13&CB$7,"뉴욕매입종가",VLOOKUP($BU$7,$BT$8:$BV$13,3,0),"FILL=TRUE"))) -> 0.05 | CC13: =IF(ISERROR(F13-IF($BU$7=1,_xll.IMDP("FX",$CA13&CC$7,"BID직전가"),_xll.IMDP("FX",$CA13&CC$7,"뉴욕매입종가",VLOOKUP($BU$7,$BT$8:$BV$13,3,0),"FILL=TRUE"))),"",F13-IF($BU$7=1,_xll.IMDP("FX",$CA13&CC$7,"BID직전가"),_xll.IMDP("FX",$CA13&CC$7,"뉴욕매입종가",VLOOKUP($BU$7,$BT$8:$BV$13,3,0),"FILL=TRUE"))) -> -7e-05 | CD13: =IF(ISERROR(G13-IF($BU$7=1,_xll.IMDP("FX",$CA13&CD$7,"BID직전가"),_xll.IMDP("FX",$CA13&CD$7,"뉴욕매입종가",VLOOKUP($BU$7,$BT$8:$BV$13,3,0),"FILL=TRUE"))),"",G13-IF($BU$7=1,_xll.IMDP("FX",$CA13&CD$7,"BID직전가"),_xll.IMDP("FX",$CA13&CD$7,"뉴욕매입종가",VLOOKUP($BU$7,$BT$8:$BV$13,3,0),"FILL=TRUE"))) | CE13: =IF(ISERROR(H13-IF($BU$7=1,_xll.IMDP("FX",$CA13&CE$7,"BID직전가"),_xll.IMDP("FX",$CA13&CE$7,"뉴욕매입종가",VLOOKUP($BU$7,$BT$8:$BV$13,3,0),"FILL=TRUE"))),"",H13-IF($BU$7=1,_xll.IMDP("FX",$CA13&CE$7,"BID직전가"),_xll.IMDP("FX",$CA13&CE$7,"뉴욕매입종가",VLOOKUP($BU$7,$BT$8:$BV$13,3,0),"FILL=TRUE"))) -> -0.001 | CF13: =IF(ISERROR(I13-IF($BU$7=1,_xll.IMDP("FX",$CA13&CF$7,"BID직전가"),_xll.IMDP("FX",$CA13&CF$7,"뉴욕매입종가",VLOOKUP($BU$7,$BT$8:$BV$13,3,0),"FILL=TRUE"))),"",I13-IF($BU$7=1,_xll.IMDP("FX",$CA13&CF$7,"BID직전가"),_xll.IMDP("FX",$CA13&CF$7,"뉴욕매입종가",VLOOKUP($BU$7,$BT$8:$BV$13,3,0),"FILL=TRUE"))) -> 0 | CG13: =IF(ISERROR(J13-IF($BU$7=1,_xll.IMDP("FX",$CA13&CG$7,"BID직전가"),_xll.IMDP("FX",$CA13&CG$7,"뉴욕매입종가",VLOOKUP($BU$7,$BT$8:$BV$13,3,0),"FILL=TRUE"))),"",J13-IF($BU$7=1,_xll.IMDP("FX",$CA13&CG$7,"BID직전가"),_xll.IMDP("FX",$CA13&CG$7,"뉴욕매입종가",VLOOKUP($BU$7,$BT$8:$BV$13,3,0),"FILL=TRUE"))) | CH13: =IF(ISERROR(K13-IF($BU$7=1,_xll.IMDP("FX",$CA13&CH$7,"BID직전가"),_xll.IMDP("FX",$CA13&CH$7,"뉴욕매입종가",VLOOKUP($BU$7,$BT$8:$BV$13,3,0),"FILL=TRUE"))),"",K13-IF($BU$7=1,_xll.IMDP("FX",$CA13&CH$7,"BID직전가"),_xll.IMDP("FX",$CA13&CH$7,"뉴욕매입종가",VLOOKUP($BU$7,$BT$8:$BV$13,3,0),"FILL=TRUE"))) | CI13: =IF(ISERROR(L13-IF($BU$7=1,_xll.IMDP("FX",$CA13&CI$7,"BID직전가"),_xll.IMDP("FX",$CA13&CI$7,"뉴욕매입종가",VLOOKUP($BU$7,$BT$8:$BV$13,3,0),"FILL=TRUE"))),"",L13-IF($BU$7=1,_xll.IMDP("FX",$CA13&CI$7,"BID직전가"),_xll.IMDP("FX",$CA13&CI$7,"뉴욕매입종가",VLOOKUP($BU$7,$BT$8:$BV$13,3,0),"FILL=TRUE"))) | ... CV13: =IF(ISERROR(Y13-IF($BU$7=1,_xll.IMDP("FX",$CA13&CV$7,"BID직전가"),_xll.IMDP("FX",$CA13&CV$7,"뉴욕매입종가",VLOOKUP($BU$7,$BT$8:$BV$13,3,0),"FILL=TRUE"))),"",Y13-IF($BU$7=1,_xll.IMDP("FX",$CA13&CV$7,"BID직전가"),_xll.IMDP("FX",$CA13&CV$7,"뉴욕매입종가",VLOOKUP($BU$7,$BT$8:$BV$13,3,0),"FILL=TRUE"))) -> 0.0063
B14: 12 | C14: =VLOOKUP($B14,$BX:$BY,2,0) -> CHF | E14: =_xll.IMDP("FX",$C14&E$6,"매입") -> 1189.47 | F14: =_xll.IMDP("FX",$C14&F$6,"매입") -> 1.0062 | G14: =_xll.IMDP("FX",$C14&G$6,"매입") -> 0.8947 | H14: =_xll.IMDP("FX",$C14&H$6,"매입") -> 108.68 | I14: =_xll.IMDP("FX",$C14&I$6,"매입") -> 6.9525 | J14: =_xll.IMDP("FX",$C14&J$6,"매입") -> 6.9665 | K14: =_xll.IMDP("FX",$C14&K$6,"매입") | L14: =_xll.IMDP("FX",$C14&L$6,"매입") -> 1.4442 | ... Y14: =_xll.IMDP("FX",$C14&Y$6,"매입") -> 31.649 | BX14: 7 | BY14: AED | CA14: =C14 -> CHF | CB14: =IF(ISERROR(E14-IF($BU$7=1,_xll.IMDP("FX",$CA14&CB$7,"BID직전가"),_xll.IMDP("FX",$CA14&CB$7,"뉴욕매입종가",VLOOKUP($BU$7,$BT$8:$BV$13,3,0),"FILL=TRUE"))),"",E14-IF($BU$7=1,_xll.IMDP("FX",$CA14&CB$7,"BID직전가"),_xll.IMDP("FX",$CA14&CB$7,"뉴욕매입종가",VLOOKUP($BU$7,$BT$8:$BV$13,3,0),"FILL=TRUE"))) -> 0.02 | CC14: =IF(ISERROR(F14-IF($BU$7=1,_xll.IMDP("FX",$CA14&CC$7,"BID직전가"),_xll.IMDP("FX",$CA14&CC$7,"뉴욕매입종가",VLOOKUP($BU$7,$BT$8:$BV$13,3,0),"FILL=TRUE"))),"",F14-IF($BU$7=1,_xll.IMDP("FX",$CA14&CC$7,"BID직전가"),_xll.IMDP("FX",$CA14&CC$7,"뉴욕매입종가",VLOOKUP($BU$7,$BT$8:$BV$13,3,0),"FILL=TRUE"))) -> -0.0004 | CD14: =IF(ISERROR(G14-IF($BU$7=1,_xll.IMDP("FX",$CA14&CD$7,"BID직전가"),_xll.IMDP("FX",$CA14&CD$7,"뉴욕매입종가",VLOOKUP($BU$7,$BT$8:$BV$13,3,0),"FILL=TRUE"))),"",G14-IF($BU$7=1,_xll.IMDP("FX",$CA14&CD$7,"BID직전가"),_xll.IMDP("FX",$CA14&CD$7,"뉴욕매입종가",VLOOKUP($BU$7,$BT$8:$BV$13,3,0),"FILL=TRUE"))) -> 0.0002 | CE14: =IF(ISERROR(H14-IF($BU$7=1,_xll.IMDP("FX",$CA14&CE$7,"BID직전가"),_xll.IMDP("FX",$CA14&CE$7,"뉴욕매입종가",VLOOKUP($BU$7,$BT$8:$BV$13,3,0),"FILL=TRUE"))),"",H14-IF($BU$7=1,_xll.IMDP("FX",$CA14&CE$7,"BID직전가"),_xll.IMDP("FX",$CA14&CE$7,"뉴욕매입종가",VLOOKUP($BU$7,$BT$8:$BV$13,3,0),"FILL=TRUE"))) -> 0 | CF14: =IF(ISERROR(I14-IF($BU$7=1,_xll.IMDP("FX",$CA14&CF$7,"BID직전가"),_xll.IMDP("FX",$CA14&CF$7,"뉴욕매입종가",VLOOKUP($BU$7,$BT$8:$BV$13,3,0),"FILL=TRUE"))),"",I14-IF($BU$7=1,_xll.IMDP("FX",$CA14&CF$7,"BID직전가"),_xll.IMDP("FX",$CA14&CF$7,"뉴욕매입종가",VLOOKUP($BU$7,$BT$8:$BV$13,3,0),"FILL=TRUE"))) -> -0.0005 | CG14: =IF(ISERROR(J14-IF($BU$7=1,_xll.IMDP("FX",$CA14&CG$7,"BID직전가"),_xll.IMDP("FX",$CA14&CG$7,"뉴욕매입종가",VLOOKUP($BU$7,$BT$8:$BV$13,3,0),"FILL=TRUE"))),"",J14-IF($BU$7=1,_xll.IMDP("FX",$CA14&CG$7,"BID직전가"),_xll.IMDP("FX",$CA14&CG$7,"뉴욕매입종가",VLOOKUP($BU$7,$BT$8:$BV$13,3,0),"FILL=TRUE"))) -> -0.0018 | CH14: =IF(ISERROR(K14-IF($BU$7=1,_xll.IMDP("FX",$CA14&CH$7,"BID직전가"),_xll.IMDP("FX",$CA14&CH$7,"뉴욕매입종가",VLOOKUP($BU$7,$BT$8:$BV$13,3,0),"FILL=TRUE"))),"",K14-IF($BU$7=1,_xll.IMDP("FX",$CA14&CH$7,"BID직전가"),_xll.IMDP("FX",$CA14&CH$7,"뉴욕매입종가",VLOOKUP($BU$7,$BT$8:$BV$13,3,0),"FILL=TRUE"))) | CI14: =IF(ISERROR(L14-IF($BU$7=1,_xll.IMDP("FX",$CA14&CI$7,"BID직전가"),_xll.IMDP("FX",$CA14&CI$7,"뉴욕매입종가",VLOOKUP($BU$7,$BT$8:$BV$13,3,0),"FILL=TRUE"))),"",L14-IF($BU$7=1,_xll.IMDP("FX",$CA14&CI$7,"BID직전가"),_xll.IMDP("FX",$CA14&CI$7,"뉴욕매입종가",VLOOKUP($BU$7,$BT$8:$BV$13,3,0),"FILL=TRUE"))) -> 0.0002 | ... CV14: =IF(ISERROR(Y14-IF($BU$7=1,_xll.IMDP("FX",$CA14&CV$7,"BID직전가"),_xll.IMDP("FX",$CA14&CV$7,"뉴욕매입종가",VLOOKUP($BU$7,$BT$8:$BV$13,3,0),"FILL=TRUE"))),"",Y14-IF($BU$7=1,_xll.IMDP("FX",$CA14&CV$7,"BID직전가"),_xll.IMDP("FX",$CA14&CV$7,"뉴욕매입종가",VLOOKUP($BU$7,$BT$8:$BV$13,3,0),"FILL=TRUE"))) -> -0.003
B15: 3 | C15: =VLOOKUP($B15,$BX:$BY,2,0) -> AUD | E15: =_xll.IMDP("FX",$C15&E$6,"매입") -> 823.15 | F15: =_xll.IMDP("FX",$C15&F$6,"매입") -> 0.6967 | G15: =_xll.IMDP("FX",$C15&G$6,"매입") -> 0.6195 | H15: =_xll.IMDP("FX",$C15&H$6,"매입") -> 75.21 | I15: =_xll.IMDP("FX",$C15&I$6,"매입") -> 4.8166 | J15: =_xll.IMDP("FX",$C15&J$6,"매입") -> 4.8235 | K15: =_xll.IMDP("FX",$C15&K$6,"매입") -> 0.6919 | L15: =_xll.IMDP("FX",$C15&L$6,"매입") | ... Y15: =_xll.IMDP("FX",$C15&Y$6,"매입") -> 21.886 | BX15: 8 | BY15: ARS | CA15: =C15 -> AUD | CB15: =IF(ISERROR(E15-IF($BU$7=1,_xll.IMDP("FX",$CA15&CB$7,"BID직전가"),_xll.IMDP("FX",$CA15&CB$7,"뉴욕매입종가",VLOOKUP($BU$7,$BT$8:$BV$13,3,0),"FILL=TRUE"))),"",E15-IF($BU$7=1,_xll.IMDP("FX",$CA15&CB$7,"BID직전가"),_xll.IMDP("FX",$CA15&CB$7,"뉴욕매입종가",VLOOKUP($BU$7,$BT$8:$BV$13,3,0),"FILL=TRUE"))) -> -0.06 | CC15: =IF(ISERROR(F15-IF($BU$7=1,_xll.IMDP("FX",$CA15&CC$7,"BID직전가"),_xll.IMDP("FX",$CA15&CC$7,"뉴욕매입종가",VLOOKUP($BU$7,$BT$8:$BV$13,3,0),"FILL=TRUE"))),"",F15-IF($BU$7=1,_xll.IMDP("FX",$CA15&CC$7,"BID직전가"),_xll.IMDP("FX",$CA15&CC$7,"뉴욕매입종가",VLOOKUP($BU$7,$BT$8:$BV$13,3,0),"FILL=TRUE"))) -> 0.0001 | CD15: =IF(ISERROR(G15-IF($BU$7=1,_xll.IMDP("FX",$CA15&CD$7,"BID직전가"),_xll.IMDP("FX",$CA15&CD$7,"뉴욕매입종가",VLOOKUP($BU$7,$BT$8:$BV$13,3,0),"FILL=TRUE"))),"",G15-IF($BU$7=1,_xll.IMDP("FX",$CA15&CD$7,"BID직전가"),_xll.IMDP("FX",$CA15&CD$7,"뉴욕매입종가",VLOOKUP($BU$7,$BT$8:$BV$13,3,0),"FILL=TRUE"))) -> 0 | CE15: =IF(ISERROR(H15-IF($BU$7=1,_xll.IMDP("FX",$CA15&CE$7,"BID직전가"),_xll.IMDP("FX",$CA15&CE$7,"뉴욕매입종가",VLOOKUP($BU$7,$BT$8:$BV$13,3,0),"FILL=TRUE"))),"",H15-IF($BU$7=1,_xll.IMDP("FX",$CA15&CE$7,"BID직전가"),_xll.IMDP("FX",$CA15&CE$7,"뉴욕매입종가",VLOOKUP($BU$7,$BT$8:$BV$13,3,0),"FILL=TRUE"))) -> -0.01 | CF15: =IF(ISERROR(I15-IF($BU$7=1,_xll.IMDP("FX",$CA15&CF$7,"BID직전가"),_xll.IMDP("FX",$CA15&CF$7,"뉴욕매입종가",VLOOKUP($BU$7,$BT$8:$BV$13,3,0),"FILL=TRUE"))),"",I15-IF($BU$7=1,_xll.IMDP("FX",$CA15&CF$7,"BID직전가"),_xll.IMDP("FX",$CA15&CF$7,"뉴욕매입종가",VLOOKUP($BU$7,$BT$8:$BV$13,3,0),"FILL=TRUE"))) -> -0.0021 | CG15: =IF(ISERROR(J15-IF($BU$7=1,_xll.IMDP("FX",$CA15&CG$7,"BID직전가"),_xll.IMDP("FX",$CA15&CG$7,"뉴욕매입종가",VLOOKUP($BU$7,$BT$8:$BV$13,3,0),"FILL=TRUE"))),"",J15-IF($BU$7=1,_xll.IMDP("FX",$CA15&CG$7,"BID직전가"),_xll.IMDP("FX",$CA15&CG$7,"뉴욕매입종가",VLOOKUP($BU$7,$BT$8:$BV$13,3,0),"FILL=TRUE"))) -> 0.0022 | CH15: =IF(ISERROR(K15-IF($BU$7=1,_xll.IMDP("FX",$CA15&CH$7,"BID직전가"),_xll.IMDP("FX",$CA15&CH$7,"뉴욕매입종가",VLOOKUP($BU$7,$BT$8:$BV$13,3,0),"FILL=TRUE"))),"",K15-IF($BU$7=1,_xll.IMDP("FX",$CA15&CH$7,"BID직전가"),_xll.IMDP("FX",$CA15&CH$7,"뉴욕매입종가",VLOOKUP($BU$7,$BT$8:$BV$13,3,0),"FILL=TRUE"))) -> -0.0001 | CI15: =IF(ISERROR(L15-IF($BU$7=1,_xll.IMDP("FX",$CA15&CI$7,"BID직전가"),_xll.IMDP("FX",$CA15&CI$7,"뉴욕매입종가",VLOOKUP($BU$7,$BT$8:$BV$13,3,0),"FILL=TRUE"))),"",L15-IF($BU$7=1,_xll.IMDP("FX",$CA15&CI$7,"BID직전가"),_xll.IMDP("FX",$CA15&CI$7,"뉴욕매입종가",VLOOKUP($BU$7,$BT$8:$BV$13,3,0),"FILL=TRUE"))) | ... CV15: =IF(ISERROR(Y15-IF($BU$7=1,_xll.IMDP("FX",$CA15&CV$7,"BID직전가"),_xll.IMDP("FX",$CA15&CV$7,"뉴욕매입종가",VLOOKUP($BU$7,$BT$8:$BV$13,3,0),"FILL=TRUE"))),"",Y15-IF($BU$7=1,_xll.IMDP("FX",$CA15&CV$7,"BID직전가"),_xll.IMDP("FX",$CA15&CV$7,"뉴욕매입종가",VLOOKUP($BU$7,$BT$8:$BV$13,3,0),"FILL=TRUE"))) -> -0.009
B16: 11 | C16: =VLOOKUP($B16,$BX:$BY,2,0) -> CAD | E16: =_xll.IMDP("FX",$C16&E$6,"매입") -> 878.75 | F16: =_xll.IMDP("FX",$C16&F$6,"매입") -> 0.7433 | G16: =_xll.IMDP("FX",$C16&G$6,"매입") -> 0.6611 | H16: =_xll.IMDP("FX",$C16&H$6,"매입") -> 80.29 | I16: =_xll.IMDP("FX",$C16&I$6,"매입") -> 5.138 | J16: =_xll.IMDP("FX",$C16&J$6,"매입") -> 5.1475 | K16: =_xll.IMDP("FX",$C16&K$6,"매입") -> 0.7387 | L16: =_xll.IMDP("FX",$C16&L$6,"매입") -> 1.0669 | ... Y16: =_xll.IMDP("FX",$C16&Y$6,"매입") -> 23.392 | BU16: =_xll.IMDP("FX","USDEUR","매입") -> 0.8889 | BV16: =_xll.IMDP("FX","USDEUR","뉴욕매입종가",BV9) -> 0.8892 | BW16: =BU16-BV16 -> -0.0003 | BX16: 9 | BY16: BHD | CA16: =C16 -> CAD | CB16: =IF(ISERROR(E16-IF($BU$7=1,_xll.IMDP("FX",$CA16&CB$7,"BID직전가"),_xll.IMDP("FX",$CA16&CB$7,"뉴욕매입종가",VLOOKUP($BU$7,$BT$8:$BV$13,3,0),"FILL=TRUE"))),"",E16-IF($BU$7=1,_xll.IMDP("FX",$CA16&CB$7,"BID직전가"),_xll.IMDP("FX",$CA16&CB$7,"뉴욕매입종가",VLOOKUP($BU$7,$BT$8:$BV$13,3,0),"FILL=TRUE"))) -> -0.03 | CC16: =IF(ISERROR(F16-IF($BU$7=1,_xll.IMDP("FX",$CA16&CC$7,"BID직전가"),_xll.IMDP("FX",$CA16&CC$7,"뉴욕매입종가",VLOOKUP($BU$7,$BT$8:$BV$13,3,0),"FILL=TRUE"))),"",F16-IF($BU$7=1,_xll.IMDP("FX",$CA16&CC$7,"BID직전가"),_xll.IMDP("FX",$CA16&CC$7,"뉴욕매입종가",VLOOKUP($BU$7,$BT$8:$BV$13,3,0),"FILL=TRUE"))) -> -0.0004 | CD16: =IF(ISERROR(G16-IF($BU$7=1,_xll.IMDP("FX",$CA16&CD$7,"BID직전가"),_xll.IMDP("FX",$CA16&CD$7,"뉴욕매입종가",VLOOKUP($BU$7,$BT$8:$BV$13,3,0),"FILL=TRUE"))),"",G16-IF($BU$7=1,_xll.IMDP("FX",$CA16&CD$7,"BID직전가"),_xll.IMDP("FX",$CA16&CD$7,"뉴욕매입종가",VLOOKUP($BU$7,$BT$8:$BV$13,3,0),"FILL=TRUE"))) -> 0 | CE16: =IF(ISERROR(H16-IF($BU$7=1,_xll.IMDP("FX",$CA16&CE$7,"BID직전가"),_xll.IMDP("FX",$CA16&CE$7,"뉴욕매입종가",VLOOKUP($BU$7,$BT$8:$BV$13,3,0),"FILL=TRUE"))),"",H16-IF($BU$7=1,_xll.IMDP("FX",$CA16&CE$7,"BID직전가"),_xll.IMDP("FX",$CA16&CE$7,"뉴욕매입종가",VLOOKUP($BU$7,$BT$8:$BV$13,3,0),"FILL=TRUE"))) -> -0.012 | CF16: =IF(ISERROR(I16-IF($BU$7=1,_xll.IMDP("FX",$CA16&CF$7,"BID직전가"),_xll.IMDP("FX",$CA16&CF$7,"뉴욕매입종가",VLOOKUP($BU$7,$BT$8:$BV$13,3,0),"FILL=TRUE"))),"",I16-IF($BU$7=1,_xll.IMDP("FX",$CA16&CF$7,"BID직전가"),_xll.IMDP("FX",$CA16&CF$7,"뉴욕매입종가",VLOOKUP($BU$7,$BT$8:$BV$13,3,0),"FILL=TRUE"))) -> -0.0003 | CG16: =IF(ISERROR(J16-IF($BU$7=1,_xll.IMDP("FX",$CA16&CG$7,"BID직전가"),_xll.IMDP("FX",$CA16&CG$7,"뉴욕매입종가",VLOOKUP($BU$7,$BT$8:$BV$13,3,0),"FILL=TRUE"))),"",J16-IF($BU$7=1,_xll.IMDP("FX",$CA16&CG$7,"BID직전가"),_xll.IMDP("FX",$CA16&CG$7,"뉴욕매입종가",VLOOKUP($BU$7,$BT$8:$BV$13,3,0),"FILL=TRUE"))) -> 0.0028 | CH16: =IF(ISERROR(K16-IF($BU$7=1,_xll.IMDP("FX",$CA16&CH$7,"BID직전가"),_xll.IMDP("FX",$CA16&CH$7,"뉴욕매입종가",VLOOKUP($BU$7,$BT$8:$BV$13,3,0),"FILL=TRUE"))),"",K16-IF($BU$7=1,_xll.IMDP("FX",$CA16&CH$7,"BID직전가"),_xll.IMDP("FX",$CA16&CH$7,"뉴욕매입종가",VLOOKUP($BU$7,$BT$8:$BV$13,3,0),"FILL=TRUE"))) -> -0.0001 | CI16: =IF(ISERROR(L16-IF($BU$7=1,_xll.IMDP("FX",$CA16&CI$7,"BID직전가"),_xll.IMDP("FX",$CA16&CI$7,"뉴욕매입종가",VLOOKUP($BU$7,$BT$8:$BV$13,3,0),"FILL=TRUE"))),"",L16-IF($BU$7=1,_xll.IMDP("FX",$CA16&CI$7,"BID직전가"),_xll.IMDP("FX",$CA16&CI$7,"뉴욕매입종가",VLOOKUP($BU$7,$BT$8:$BV$13,3,0),"FILL=TRUE"))) -> 0.0007 | ... CV16: =IF(ISERROR(Y16-IF($BU$7=1,_xll.IMDP("FX",$CA16&CV$7,"BID직전가"),_xll.IMDP("FX",$CA16&CV$7,"뉴욕매입종가",VLOOKUP($BU$7,$BT$8:$BV$13,3,0),"FILL=TRUE"))),"",Y16-IF($BU$7=1,_xll.IMDP("FX",$CA16&CV$7,"BID직전가"),_xll.IMDP("FX",$CA16&CV$7,"뉴욕매입종가",VLOOKUP($BU$7,$BT$8:$BV$13,3,0),"FILL=TRUE"))) -> -0.001
B17: 51 | C17: =VLOOKUP($B17,$BX:$BY,2,0) -> SEK | E17: =_xll.IMDP("FX",$C17&E$6,"매입") -> 125.09 | F17: =_xll.IMDP("FX",$C17&F$6,"매입") -> 0.1054 | G17: =_xll.IMDP("FX",$C17&G$6,"매입") -> 0.09366 | H17: =_xll.IMDP("FX",$C17&H$6,"매입") -> 11.426 | I17: =_xll.IMDP("FX",$C17&I$6,"매입") -> 0.7266 | J17: =_xll.IMDP("FX",$C17&J$6,"매입") -> 0.7305 | K17: =_xll.IMDP("FX",$C17&K$6,"매입") -> 10.51 | L17: =_xll.IMDP("FX",$C17&L$6,"매입") -> 0.15179 | ... Y17: =_xll.IMDP("FX",$C17&Y$6,"매입") | BT17: =IF($BU$7=1,$BV$8,_xll.IMDP("FX",CA8&CC7,"뉴욕매입종가",VLOOKUP($BU$7,$BT$8:$BV$13,3,0))) -> 0 | BU17: =_xll.IMDP("FX","USDEUR","뉴욕종가대비") -> 0.0003 | BX17: 10 | BY17: BRL | CA17: =C17 -> SEK | CB17: =IF(ISERROR(E17-IF($BU$7=1,_xll.IMDP("FX",$CA17&CB$7,"BID직전가"),_xll.IMDP("FX",$CA17&CB$7,"뉴욕매입종가",VLOOKUP($BU$7,$BT$8:$BV$13,3,0),"FILL=TRUE"))),"",E17-IF($BU$7=1,_xll.IMDP("FX",$CA17&CB$7,"BID직전가"),_xll.IMDP("FX",$CA17&CB$7,"뉴욕매입종가",VLOOKUP($BU$7,$BT$8:$BV$13,3,0),"FILL=TRUE"))) -> 0.01 | CC17: =IF(ISERROR(F17-IF($BU$7=1,_xll.IMDP("FX",$CA17&CC$7,"BID직전가"),_xll.IMDP("FX",$CA17&CC$7,"뉴욕매입종가",VLOOKUP($BU$7,$BT$8:$BV$13,3,0),"FILL=TRUE"))),"",F17-IF($BU$7=1,_xll.IMDP("FX",$CA17&CC$7,"BID직전가"),_xll.IMDP("FX",$CA17&CC$7,"뉴욕매입종가",VLOOKUP($BU$7,$BT$8:$BV$13,3,0),"FILL=TRUE"))) -> 0 | CD17: =IF(ISERROR(G17-IF($BU$7=1,_xll.IMDP("FX",$CA17&CD$7,"BID직전가"),_xll.IMDP("FX",$CA17&CD$7,"뉴욕매입종가",VLOOKUP($BU$7,$BT$8:$BV$13,3,0),"FILL=TRUE"))),"",G17-IF($BU$7=1,_xll.IMDP("FX",$CA17&CD$7,"BID직전가"),_xll.IMDP("FX",$CA17&CD$7,"뉴욕매입종가",VLOOKUP($BU$7,$BT$8:$BV$13,3,0),"FILL=TRUE"))) -> 1e-05 | CE17: =IF(ISERROR(H17-IF($BU$7=1,_xll.IMDP("FX",$CA17&CE$7,"BID직전가"),_xll.IMDP("FX",$CA17&CE$7,"뉴욕매입종가",VLOOKUP($BU$7,$BT$8:$BV$13,3,0),"FILL=TRUE"))),"",H17-IF($BU$7=1,_xll.IMDP("FX",$CA17&CE$7,"BID직전가"),_xll.IMDP("FX",$CA17&CE$7,"뉴욕매입종가",VLOOKUP($BU$7,$BT$8:$BV$13,3,0),"FILL=TRUE"))) -> -0.001 | CF17: =IF(ISERROR(I17-IF($BU$7=1,_xll.IMDP("FX",$CA17&CF$7,"BID직전가"),_xll.IMDP("FX",$CA17&CF$7,"뉴욕매입종가",VLOOKUP($BU$7,$BT$8:$BV$13,3,0),"FILL=TRUE"))),"",I17-IF($BU$7=1,_xll.IMDP("FX",$CA17&CF$7,"BID직전가"),_xll.IMDP("FX",$CA17&CF$7,"뉴욕매입종가",VLOOKUP($BU$7,$BT$8:$BV$13,3,0),"FILL=TRUE"))) -> 0.0002 | CG17: =IF(ISERROR(J17-IF($BU$7=1,_xll.IMDP("FX",$CA17&CG$7,"BID직전가"),_xll.IMDP("FX",$CA17&CG$7,"뉴욕매입종가",VLOOKUP($BU$7,$BT$8:$BV$13,3,0),"FILL=TRUE"))),"",J17-IF($BU$7=1,_xll.IMDP("FX",$CA17&CG$7,"BID직전가"),_xll.IMDP("FX",$CA17&CG$7,"뉴욕매입종가",VLOOKUP($BU$7,$BT$8:$BV$13,3,0),"FILL=TRUE"))) -> -0.0001 | CH17: =IF(ISERROR(K17-IF($BU$7=1,_xll.IMDP("FX",$CA17&CH$7,"BID직전가"),_xll.IMDP("FX",$CA17&CH$7,"뉴욕매입종가",VLOOKUP($BU$7,$BT$8:$BV$13,3,0),"FILL=TRUE"))),"",K17-IF($BU$7=1,_xll.IMDP("FX",$CA17&CH$7,"BID직전가"),_xll.IMDP("FX",$CA17&CH$7,"뉴욕매입종가",VLOOKUP($BU$7,$BT$8:$BV$13,3,0),"FILL=TRUE"))) -> 0 | CI17: =IF(ISERROR(L17-IF($BU$7=1,_xll.IMDP("FX",$CA17&CI$7,"BID직전가"),_xll.IMDP("FX",$CA17&CI$7,"뉴욕매입종가",VLOOKUP($BU$7,$BT$8:$BV$13,3,0),"FILL=TRUE"))),"",L17-IF($BU$7=1,_xll.IMDP("FX",$CA17&CI$7,"BID직전가"),_xll.IMDP("FX",$CA17&CI$7,"뉴욕매입종가",VLOOKUP($BU$7,$BT$8:$BV$13,3,0),"FILL=TRUE"))) -> 4e-05 | ... CV17: =IF(ISERROR(Y17-IF($BU$7=1,_xll.IMDP("FX",$CA17&CV$7,"BID직전가"),_xll.IMDP("FX",$CA17&CV$7,"뉴욕매입종가",VLOOKUP($BU$7,$BT$8:$BV$13,3,0),"FILL=TRUE"))),"",Y17-IF($BU$7=1,_xll.IMDP("FX",$CA17&CV$7,"BID직전가"),_xll.IMDP("FX",$CA17&CV$7,"뉴욕매입종가",VLOOKUP($BU$7,$BT$8:$BV$13,3,0),"FILL=TRUE")))
B18: 19 | C18: =VLOOKUP($B18,$BX:$BY,2,0) -> DKK | E18: =_xll.IMDP("FX",$C18&E$6,"매입") -> 177.93 | F18: =_xll.IMDP("FX",$C18&F$6,"매입") -> 0.1501 | G18: =_xll.IMDP("FX",$C18&G$6,"매입") -> 0.13379 | H18: =_xll.IMDP("FX",$C18&H$6,"매입") -> 16.253 | I18: =_xll.IMDP("FX",$C18&I$6,"매입") | J18: =_xll.IMDP("FX",$C18&J$6,"매입") | K18: =_xll.IMDP("FX",$C18&K$6,"매입") -> 14.908 | L18: =_xll.IMDP("FX",$C18&L$6,"매입") -> 0.21592 | ... Y18: =_xll.IMDP("FX",$C18&Y$6,"매입") | BX18: 11 | BY18: CAD | CA18: =C18 -> DKK | CB18: =IF(ISERROR(E18-IF($BU$7=1,_xll.IMDP("FX",$CA18&CB$7,"BID직전가"),_xll.IMDP("FX",$CA18&CB$7,"뉴욕매입종가",VLOOKUP($BU$7,$BT$8:$BV$13,3,0),"FILL=TRUE"))),"",E18-IF($BU$7=1,_xll.IMDP("FX",$CA18&CB$7,"BID직전가"),_xll.IMDP("FX",$CA18&CB$7,"뉴욕매입종가",VLOOKUP($BU$7,$BT$8:$BV$13,3,0),"FILL=TRUE"))) -> 0 | CC18: =IF(ISERROR(F18-IF($BU$7=1,_xll.IMDP("FX",$CA18&CC$7,"BID직전가"),_xll.IMDP("FX",$CA18&CC$7,"뉴욕매입종가",VLOOKUP($BU$7,$BT$8:$BV$13,3,0),"FILL=TRUE"))),"",F18-IF($BU$7=1,_xll.IMDP("FX",$CA18&CC$7,"BID직전가"),_xll.IMDP("FX",$CA18&CC$7,"뉴욕매입종가",VLOOKUP($BU$7,$BT$8:$BV$13,3,0),"FILL=TRUE"))) -> -0.0005 | CD18: =IF(ISERROR(G18-IF($BU$7=1,_xll.IMDP("FX",$CA18&CD$7,"BID직전가"),_xll.IMDP("FX",$CA18&CD$7,"뉴욕매입종가",VLOOKUP($BU$7,$BT$8:$BV$13,3,0),"FILL=TRUE"))),"",G18-IF($BU$7=1,_xll.IMDP("FX",$CA18&CD$7,"BID직전가"),_xll.IMDP("FX",$CA18&CD$7,"뉴욕매입종가",VLOOKUP($BU$7,$BT$8:$BV$13,3,0),"FILL=TRUE"))) -> 0 | CE18: =IF(ISERROR(H18-IF($BU$7=1,_xll.IMDP("FX",$CA18&CE$7,"BID직전가"),_xll.IMDP("FX",$CA18&CE$7,"뉴욕매입종가",VLOOKUP($BU$7,$BT$8:$BV$13,3,0),"FILL=TRUE"))),"",H18-IF($BU$7=1,_xll.IMDP("FX",$CA18&CE$7,"BID직전가"),_xll.IMDP("FX",$CA18&CE$7,"뉴욕매입종가",VLOOKUP($BU$7,$BT$8:$BV$13,3,0),"FILL=TRUE"))) -> -0.003 | CF18: =IF(ISERROR(I18-IF($BU$7=1,_xll.IMDP("FX",$CA18&CF$7,"BID직전가"),_xll.IMDP("FX",$CA18&CF$7,"뉴욕매입종가",VLOOKUP($BU$7,$BT$8:$BV$13,3,0),"FILL=TRUE"))),"",I18-IF($BU$7=1,_xll.IMDP("FX",$CA18&CF$7,"BID직전가"),_xll.IMDP("FX",$CA18&CF$7,"뉴욕매입종가",VLOOKUP($BU$7,$BT$8:$BV$13,3,0),"FILL=TRUE"))) | CG18: =IF(ISERROR(J18-IF($BU$7=1,_xll.IMDP("FX",$CA18&CG$7,"BID직전가"),_xll.IMDP("FX",$CA18&CG$7,"뉴욕매입종가",VLOOKUP($BU$7,$BT$8:$BV$13,3,0),"FILL=TRUE"))),"",J18-IF($BU$7=1,_xll.IMDP("FX",$CA18&CG$7,"BID직전가"),_xll.IMDP("FX",$CA18&CG$7,"뉴욕매입종가",VLOOKUP($BU$7,$BT$8:$BV$13,3,0),"FILL=TRUE"))) | CH18: =IF(ISERROR(K18-IF($BU$7=1,_xll.IMDP("FX",$CA18&CH$7,"BID직전가"),_xll.IMDP("FX",$CA18&CH$7,"뉴욕매입종가",VLOOKUP($BU$7,$BT$8:$BV$13,3,0),"FILL=TRUE"))),"",K18-IF($BU$7=1,_xll.IMDP("FX",$CA18&CH$7,"BID직전가"),_xll.IMDP("FX",$CA18&CH$7,"뉴욕매입종가",VLOOKUP($BU$7,$BT$8:$BV$13,3,0),"FILL=TRUE"))) -> -0.05 | CI18: =IF(ISERROR(L18-IF($BU$7=1,_xll.IMDP("FX",$CA18&CI$7,"BID직전가"),_xll.IMDP("FX",$CA18&CI$7,"뉴욕매입종가",VLOOKUP($BU$7,$BT$8:$BV$13,3,0),"FILL=TRUE"))),"",L18-IF($BU$7=1,_xll.IMDP("FX",$CA18&CI$7,"BID직전가"),_xll.IMDP("FX",$CA18&CI$7,"뉴욕매입종가",VLOOKUP($BU$7,$BT$8:$BV$13,3,0),"FILL=TRUE"))) -> 7e-05 | ... CV18: =IF(ISERROR(Y18-IF($BU$7=1,_xll.IMDP("FX",$CA18&CV$7,"BID직전가"),_xll.IMDP("FX",$CA18&CV$7,"뉴욕매입종가",VLOOKUP($BU$7,$BT$8:$BV$13,3,0),"FILL=TRUE"))),"",Y18-IF($BU$7=1,_xll.IMDP("FX",$CA18&CV$7,"BID직전가"),_xll.IMDP("FX",$CA18&CV$7,"뉴욕매입종가",VLOOKUP($BU$7,$BT$8:$BV$13,3,0),"FILL=TRUE")))
B19: 47 | C19: =VLOOKUP($B19,$BX:$BY,2,0) -> PLN | E19: =_xll.IMDP("FX",$C19&E$6,"매입") -> 310.32 | F19: =_xll.IMDP("FX",$C19&F$6,"매입") -> 0.26235 | G19: =_xll.IMDP("FX",$C19&G$6,"매입") -> 0.23336 | H19: =_xll.IMDP("FX",$C19&H$6,"매입") -> 28.348 | I19: =_xll.IMDP("FX",$C19&I$6,"매입") -> 1.81 | J19: =_xll.IMDP("FX",$C19&J$6,"매입") | K19: =_xll.IMDP("FX",$C19&K$6,"매입") -> 0.2609 | L19: =_xll.IMDP("FX",$C19&L$6,"매입") -> 0.37643 | ... Y19: =_xll.IMDP("FX",$C19&Y$6,"매입") | BU19: =_xll.IMDP("FX","USDEUR","매입") -> 0.8889 | BV19: =_xll.IMDP("FX","USDEUR","뉴욕매입종가",BV10,"FILL=TRUE") -> 0.8982 | BW19: =BU19-BV19 -> -0.0093 | BX19: 12 | BY19: CHF | CA19: =C19 -> PLN | CB19: =IF(ISERROR(E19-IF($BU$7=1,_xll.IMDP("FX",$CA19&CB$7,"BID직전가"),_xll.IMDP("FX",$CA19&CB$7,"뉴욕매입종가",VLOOKUP($BU$7,$BT$8:$BV$13,3,0),"FILL=TRUE"))),"",E19-IF($BU$7=1,_xll.IMDP("FX",$CA19&CB$7,"BID직전가"),_xll.IMDP("FX",$CA19&CB$7,"뉴욕매입종가",VLOOKUP($BU$7,$BT$8:$BV$13,3,0),"FILL=TRUE"))) -> -0.01 | CC19: =IF(ISERROR(F19-IF($BU$7=1,_xll.IMDP("FX",$CA19&CC$7,"BID직전가"),_xll.IMDP("FX",$CA19&CC$7,"뉴욕매입종가",VLOOKUP($BU$7,$BT$8:$BV$13,3,0),"FILL=TRUE"))),"",F19-IF($BU$7=1,_xll.IMDP("FX",$CA19&CC$7,"BID직전가"),_xll.IMDP("FX",$CA19&CC$7,"뉴욕매입종가",VLOOKUP($BU$7,$BT$8:$BV$13,3,0),"FILL=TRUE"))) -> 1e-05 | CD19: =IF(ISERROR(G19-IF($BU$7=1,_xll.IMDP("FX",$CA19&CD$7,"BID직전가"),_xll.IMDP("FX",$CA19&CD$7,"뉴욕매입종가",VLOOKUP($BU$7,$BT$8:$BV$13,3,0),"FILL=TRUE"))),"",G19-IF($BU$7=1,_xll.IMDP("FX",$CA19&CD$7,"BID직전가"),_xll.IMDP("FX",$CA19&CD$7,"뉴욕매입종가",VLOOKUP($BU$7,$BT$8:$BV$13,3,0),"FILL=TRUE"))) -> 4e-05 | CE19: =IF(ISERROR(H19-IF($BU$7=1,_xll.IMDP("FX",$CA19&CE$7,"BID직전가"),_xll.IMDP("FX",$CA19&CE$7,"뉴욕매입종가",VLOOKUP($BU$7,$BT$8:$BV$13,3,0),"FILL=TRUE"))),"",H19-IF($BU$7=1,_xll.IMDP("FX",$CA19&CE$7,"BID직전가"),_xll.IMDP("FX",$CA19&CE$7,"뉴욕매입종가",VLOOKUP($BU$7,$BT$8:$BV$13,3,0),"FILL=TRUE"))) -> -0.004 | CF19: =IF(ISERROR(I19-IF($BU$7=1,_xll.IMDP("FX",$CA19&CF$7,"BID직전가"),_xll.IMDP("FX",$CA19&CF$7,"뉴욕매입종가",VLOOKUP($BU$7,$BT$8:$BV$13,3,0),"FILL=TRUE"))),"",I19-IF($BU$7=1,_xll.IMDP("FX",$CA19&CF$7,"BID직전가"),_xll.IMDP("FX",$CA19&CF$7,"뉴욕매입종가",VLOOKUP($BU$7,$BT$8:$BV$13,3,0),"FILL=TRUE"))) -> -0.0001 | CG19: =IF(ISERROR(J19-IF($BU$7=1,_xll.IMDP("FX",$CA19&CG$7,"BID직전가"),_xll.IMDP("FX",$CA19&CG$7,"뉴욕매입종가",VLOOKUP($BU$7,$BT$8:$BV$13,3,0),"FILL=TRUE"))),"",J19-IF($BU$7=1,_xll.IMDP("FX",$CA19&CG$7,"BID직전가"),_xll.IMDP("FX",$CA19&CG$7,"뉴욕매입종가",VLOOKUP($BU$7,$BT$8:$BV$13,3,0),"FILL=TRUE"))) | CH19: =IF(ISERROR(K19-IF($BU$7=1,_xll.IMDP("FX",$CA19&CH$7,"BID직전가"),_xll.IMDP("FX",$CA19&CH$7,"뉴욕매입종가",VLOOKUP($BU$7,$BT$8:$BV$13,3,0),"FILL=TRUE"))),"",K19-IF($BU$7=1,_xll.IMDP("FX",$CA19&CH$7,"BID직전가"),_xll.IMDP("FX",$CA19&CH$7,"뉴욕매입종가",VLOOKUP($BU$7,$BT$8:$BV$13,3,0),"FILL=TRUE"))) -> 0 | CI19: =IF(ISERROR(L19-IF($BU$7=1,_xll.IMDP("FX",$CA19&CI$7,"BID직전가"),_xll.IMDP("FX",$CA19&CI$7,"뉴욕매입종가",VLOOKUP($BU$7,$BT$8:$BV$13,3,0),"FILL=TRUE"))),"",L19-IF($BU$7=1,_xll.IMDP("FX",$CA19&CI$7,"BID직전가"),_xll.IMDP("FX",$CA19&CI$7,"뉴욕매입종가",VLOOKUP($BU$7,$BT$8:$BV$13,3,0),"FILL=TRUE"))) -> -6e-05 | ... CV19: =IF(ISERROR(Y19-IF($BU$7=1,_xll.IMDP("FX",$CA19&CV$7,"BID직전가"),_xll.IMDP("FX",$CA19&CV$7,"뉴욕매입종가",VLOOKUP($BU$7,$BT$8:$BV$13,3,0),"FILL=TRUE"))),"",Y19-IF($BU$7=1,_xll.IMDP("FX",$CA19&CV$7,"BID직전가"),_xll.IMDP("FX",$CA19&CV$7,"뉴욕매입종가",VLOOKUP($BU$7,$BT$8:$BV$13,3,0),"FILL=TRUE")))
B20: 10 | C20: =VLOOKUP($B20,$BX:$BY,2,0) -> BRL | E20: =_xll.IMDP("FX",$C20&E$6,"매입") -> 303.66 | F20: =_xll.IMDP("FX",$C20&F$6,"매입") -> 0.2567 | G20: =_xll.IMDP("FX",$C20&G$6,"매입") -> 0.22843 | H20: =_xll.IMDP("FX",$C20&H$6,"매입") -> 27.768 | I20: =_xll.IMDP("FX",$C20&I$6,"매입") -> 1.7751 | J20: =_xll.IMDP("FX",$C20&J$6,"매입") | K20: =_xll.IMDP("FX",$C20&K$6,"매입") -> 0.2553 | L20: =_xll.IMDP("FX",$C20&L$6,"매입") -> 0.36869 | ... Y20: =_xll.IMDP("FX",$C20&Y$6,"매입") -> 8.042 | BU20: =_xll.IMDP("FX","USDCAD","매입") -> 1.3444 | BV20: =_xll.IMDP("FX","USDCAD","뉴욕매입종가",BV9) -> 1.3435 | BW20: =BU20-BV20 -> 0.0009 | BX20: 13 | BY20: CLP | CA20: =C20 -> BRL | CB20: =IF(ISERROR(E20-IF($BU$7=1,_xll.IMDP("FX",$CA20&CB$7,"BID직전가"),_xll.IMDP("FX",$CA20&CB$7,"뉴욕매입종가",VLOOKUP($BU$7,$BT$8:$BV$13,3,0),"FILL=TRUE"))),"",E20-IF($BU$7=1,_xll.IMDP("FX",$CA20&CB$7,"BID직전가"),_xll.IMDP("FX",$CA20&CB$7,"뉴욕매입종가",VLOOKUP($BU$7,$BT$8:$BV$13,3,0),"FILL=TRUE"))) -> 0.41 | CC20: =IF(ISERROR(F20-IF($BU$7=1,_xll.IMDP("FX",$CA20&CC$7,"BID직전가"),_xll.IMDP("FX",$CA20&CC$7,"뉴욕매입종가",VLOOKUP($BU$7,$BT$8:$BV$13,3,0),"FILL=TRUE"))),"",F20-IF($BU$7=1,_xll.IMDP("FX",$CA20&CC$7,"BID직전가"),_xll.IMDP("FX",$CA20&CC$7,"뉴욕매입종가",VLOOKUP($BU$7,$BT$8:$BV$13,3,0),"FILL=TRUE"))) -> 0 | CD20: =IF(ISERROR(G20-IF($BU$7=1,_xll.IMDP("FX",$CA20&CD$7,"BID직전가"),_xll.IMDP("FX",$CA20&CD$7,"뉴욕매입종가",VLOOKUP($BU$7,$BT$8:$BV$13,3,0),"FILL=TRUE"))),"",G20-IF($BU$7=1,_xll.IMDP("FX",$CA20&CD$7,"BID직전가"),_xll.IMDP("FX",$CA20&CD$7,"뉴욕매입종가",VLOOKUP($BU$7,$BT$8:$BV$13,3,0),"FILL=TRUE"))) -> 0 | CE20: =IF(ISERROR(H20-IF($BU$7=1,_xll.IMDP("FX",$CA20&CE$7,"BID직전가"),_xll.IMDP("FX",$CA20&CE$7,"뉴욕매입종가",VLOOKUP($BU$7,$BT$8:$BV$13,3,0),"FILL=TRUE"))),"",H20-IF($BU$7=1,_xll.IMDP("FX",$CA20&CE$7,"BID직전가"),_xll.IMDP("FX",$CA20&CE$7,"뉴욕매입종가",VLOOKUP($BU$7,$BT$8:$BV$13,3,0),"FILL=TRUE"))) -> -0.005 | CF20: =IF(ISERROR(I20-IF($BU$7=1,_xll.IMDP("FX",$CA20&CF$7,"BID직전가"),_xll.IMDP("FX",$CA20&CF$7,"뉴욕매입종가",VLOOKUP($BU$7,$BT$8:$BV$13,3,0),"FILL=TRUE"))),"",I20-IF($BU$7=1,_xll.IMDP("FX",$CA20&CF$7,"BID직전가"),_xll.IMDP("FX",$CA20&CF$7,"뉴욕매입종가",VLOOKUP($BU$7,$BT$8:$BV$13,3,0),"FILL=TRUE"))) -> 0.0001 | CG20: =IF(ISERROR(J20-IF($BU$7=1,_xll.IMDP("FX",$CA20&CG$7,"BID직전가"),_xll.IMDP("FX",$CA20&CG$7,"뉴욕매입종가",VLOOKUP($BU$7,$BT$8:$BV$13,3,0),"FILL=TRUE"))),"",J20-IF($BU$7=1,_xll.IMDP("FX",$CA20&CG$7,"BID직전가"),_xll.IMDP("FX",$CA20&CG$7,"뉴욕매입종가",VLOOKUP($BU$7,$BT$8:$BV$13,3,0),"FILL=TRUE"))) | CH20: =IF(ISERROR(K20-IF($BU$7=1,_xll.IMDP("FX",$CA20&CH$7,"BID직전가"),_xll.IMDP("FX",$CA20&CH$7,"뉴욕매입종가",VLOOKUP($BU$7,$BT$8:$BV$13,3,0),"FILL=TRUE"))),"",K20-IF($BU$7=1,_xll.IMDP("FX",$CA20&CH$7,"BID직전가"),_xll.IMDP("FX",$CA20&CH$7,"뉴욕매입종가",VLOOKUP($BU$7,$BT$8:$BV$13,3,0),"FILL=TRUE"))) -> -3e-05 | CI20: =IF(ISERROR(L20-IF($BU$7=1,_xll.IMDP("FX",$CA20&CI$7,"BID직전가"),_xll.IMDP("FX",$CA20&CI$7,"뉴욕매입종가",VLOOKUP($BU$7,$BT$8:$BV$13,3,0),"FILL=TRUE"))),"",L20-IF($BU$7=1,_xll.IMDP("FX",$CA20&CI$7,"BID직전가"),_xll.IMDP("FX",$CA20&CI$7,"뉴욕매입종가",VLOOKUP($BU$7,$BT$8:$BV$13,3,0),"FILL=TRUE"))) -> -2e-05 | ... CV20: =IF(ISERROR(Y20-IF($BU$7=1,_xll.IMDP("FX",$CA20&CV$7,"BID직전가"),_xll.IMDP("FX",$CA20&CV$7,"뉴욕매입종가",VLOOKUP($BU$7,$BT$8:$BV$13,3,0),"FILL=TRUE"))),"",Y20-IF($BU$7=1,_xll.IMDP("FX",$CA20&CV$7,"BID직전가"),_xll.IMDP("FX",$CA20&CV$7,"뉴욕매입종가",VLOOKUP($BU$7,$BT$8:$BV$13,3,0),"FILL=TRUE"))) -> 0.01
B21: 39 | C21: =VLOOKUP($B21,$BX:$BY,2,0) -> MXN | E21: =_xll.IMDP("FX",$C21&E$6,"매입") -> 59.91 | F21: =_xll.IMDP("FX",$C21&F$6,"매입") -> 0.0507 | G21: =_xll.IMDP("FX",$C21&G$6,"매입") -> 0.04461 | H21: =_xll.IMDP("FX",$C21&H$6,"매입") -> 5.473 | I21: =_xll.IMDP("FX",$C21&I$6,"매입") | J21: =_xll.IMDP("FX",$C21&J$6,"매입") | K21: =_xll.IMDP("FX",$C21&K$6,"매입") -> 0.05028 | L21: =_xll.IMDP("FX",$C21&L$6,"매입") -> 0.07249 | ... Y21: =_xll.IMDP("FX",$C21&Y$6,"매입") | BU21: =_xll.IMDP("FX","USDCAD","매입") -> 1.3444 | BV21: =_xll.IMDP("FX","USDCAD","뉴욕매입종가",BV10,"FILL=TRUE") -> 1.3498 | BW21: =BU21-BV21 -> -0.0054 | BX21: 14 | BY21: CNY | CA21: =C21 -> MXN | CB21: =IF(ISERROR(E21-IF($BU$7=1,_xll.IMDP("FX",$CA21&CB$7,"BID직전가"),_xll.IMDP("FX",$CA21&CB$7,"뉴욕매입종가",VLOOKUP($BU$7,$BT$8:$BV$13,3,0),"FILL=TRUE"))),"",E21-IF($BU$7=1,_xll.IMDP("FX",$CA21&CB$7,"BID직전가"),_xll.IMDP("FX",$CA21&CB$7,"뉴욕매입종가",VLOOKUP($BU$7,$BT$8:$BV$13,3,0),"FILL=TRUE"))) -> 0.01 | CC21: =IF(ISERROR(F21-IF($BU$7=1,_xll.IMDP("FX",$CA21&CC$7,"BID직전가"),_xll.IMDP("FX",$CA21&CC$7,"뉴욕매입종가",VLOOKUP($BU$7,$BT$8:$BV$13,3,0),"FILL=TRUE"))),"",F21-IF($BU$7=1,_xll.IMDP("FX",$CA21&CC$7,"BID직전가"),_xll.IMDP("FX",$CA21&CC$7,"뉴욕매입종가",VLOOKUP($BU$7,$BT$8:$BV$13,3,0),"FILL=TRUE"))) -> -2e-05 | CD21: =IF(ISERROR(G21-IF($BU$7=1,_xll.IMDP("FX",$CA21&CD$7,"BID직전가"),_xll.IMDP("FX",$CA21&CD$7,"뉴욕매입종가",VLOOKUP($BU$7,$BT$8:$BV$13,3,0),"FILL=TRUE"))),"",G21-IF($BU$7=1,_xll.IMDP("FX",$CA21&CD$7,"BID직전가"),_xll.IMDP("FX",$CA21&CD$7,"뉴욕매입종가",VLOOKUP($BU$7,$BT$8:$BV$13,3,0),"FILL=TRUE"))) -> 0 | CE21: =IF(ISERROR(H21-IF($BU$7=1,_xll.IMDP("FX",$CA21&CE$7,"BID직전가"),_xll.IMDP("FX",$CA21&CE$7,"뉴욕매입종가",VLOOKUP($BU$7,$BT$8:$BV$13,3,0),"FILL=TRUE"))),"",H21-IF($BU$7=1,_xll.IMDP("FX",$CA21&CE$7,"BID직전가"),_xll.IMDP("FX",$CA21&CE$7,"뉴욕매입종가",VLOOKUP($BU$7,$BT$8:$BV$13,3,0),"FILL=TRUE"))) -> 0 | CF21: =IF(ISERROR(I21-IF($BU$7=1,_xll.IMDP("FX",$CA21&CF$7,"BID직전가"),_xll.IMDP("FX",$CA21&CF$7,"뉴욕매입종가",VLOOKUP($BU$7,$BT$8:$BV$13,3,0),"FILL=TRUE"))),"",I21-IF($BU$7=1,_xll.IMDP("FX",$CA21&CF$7,"BID직전가"),_xll.IMDP("FX",$CA21&CF$7,"뉴욕매입종가",VLOOKUP($BU$7,$BT$8:$BV$13,3,0),"FILL=TRUE"))) | CG21: =IF(ISERROR(J21-IF($BU$7=1,_xll.IMDP("FX",$CA21&CG$7,"BID직전가"),_xll.IMDP("FX",$CA21&CG$7,"뉴욕매입종가",VLOOKUP($BU$7,$BT$8:$BV$13,3,0),"FILL=TRUE"))),"",J21-IF($BU$7=1,_xll.IMDP("FX",$CA21&CG$7,"BID직전가"),_xll.IMDP("FX",$CA21&CG$7,"뉴욕매입종가",VLOOKUP($BU$7,$BT$8:$BV$13,3,0),"FILL=TRUE"))) | CH21: =IF(ISERROR(K21-IF($BU$7=1,_xll.IMDP("FX",$CA21&CH$7,"BID직전가"),_xll.IMDP("FX",$CA21&CH$7,"뉴욕매입종가",VLOOKUP($BU$7,$BT$8:$BV$13,3,0),"FILL=TRUE"))),"",K21-IF($BU$7=1,_xll.IMDP("FX",$CA21&CH$7,"BID직전가"),_xll.IMDP("FX",$CA21&CH$7,"뉴욕매입종가",VLOOKUP($BU$7,$BT$8:$BV$13,3,0),"FILL=TRUE"))) -> 0 | CI21: =IF(ISERROR(L21-IF($BU$7=1,_xll.IMDP("FX",$CA21&CI$7,"BID직전가"),_xll.IMDP("FX",$CA21&CI$7,"뉴욕매입종가",VLOOKUP($BU$7,$BT$8:$BV$13,3,0),"FILL=TRUE"))),"",L21-IF($BU$7=1,_xll.IMDP("FX",$CA21&CI$7,"BID직전가"),_xll.IMDP("FX",$CA21&CI$7,"뉴욕매입종가",VLOOKUP($BU$7,$BT$8:$BV$13,3,0),"FILL=TRUE"))) -> 1e-05 | ... CV21: =IF(ISERROR(Y21-IF($BU$7=1,_xll.IMDP("FX",$CA21&CV$7,"BID직전가"),_xll.IMDP("FX",$CA21&CV$7,"뉴욕매입종가",VLOOKUP($BU$7,$BT$8:$BV$13,3,0),"FILL=TRUE"))),"",Y21-IF($BU$7=1,_xll.IMDP("FX",$CA21&CV$7,"BID직전가"),_xll.IMDP("FX",$CA21&CV$7,"뉴욕매입종가",VLOOKUP($BU$7,$BT$8:$BV$13,3,0),"FILL=TRUE")))
B22: 24 | C22: =VLOOKUP($B22,$BX:$BY,2,0) -> HKD | E22: =_xll.IMDP("FX",$C22&E$6,"매입") -> 150.69 | F22: =_xll.IMDP("FX",$C22&F$6,"매입") -> 0.12749 | G22: =_xll.IMDP("FX",$C22&G$6,"매입") -> 0.11333 | H22: =_xll.IMDP("FX",$C22&H$6,"매입") -> 13.7683 | I22: =_xll.IMDP("FX",$C22&I$6,"매입") -> 0.8805 | J22: =_xll.IMDP("FX",$C22&J$6,"매입") -> 0.88284 | K22: =_xll.IMDP("FX",$C22&K$6,"매입") -> 12.667 | L22: =_xll.IMDP("FX",$C22&L$6,"매입") -> 0.1829 | ... Y22: =_xll.IMDP("FX",$C22&Y$6,"매입") -> 4.0104 | BX22: 15 | BY22: CNH | CA22: =C22 -> HKD | CB22: =IF(ISERROR(E22-IF($BU$7=1,_xll.IMDP("FX",$CA22&CB$7,"BID직전가"),_xll.IMDP("FX",$CA22&CB$7,"뉴욕매입종가",VLOOKUP($BU$7,$BT$8:$BV$13,3,0),"FILL=TRUE"))),"",E22-IF($BU$7=1,_xll.IMDP("FX",$CA22&CB$7,"BID직전가"),_xll.IMDP("FX",$CA22&CB$7,"뉴욕매입종가",VLOOKUP($BU$7,$BT$8:$BV$13,3,0),"FILL=TRUE"))) -> 0 | CC22: =IF(ISERROR(F22-IF($BU$7=1,_xll.IMDP("FX",$CA22&CC$7,"BID직전가"),_xll.IMDP("FX",$CA22&CC$7,"뉴욕매입종가",VLOOKUP($BU$7,$BT$8:$BV$13,3,0),"FILL=TRUE"))),"",F22-IF($BU$7=1,_xll.IMDP("FX",$CA22&CC$7,"BID직전가"),_xll.IMDP("FX",$CA22&CC$7,"뉴욕매입종가",VLOOKUP($BU$7,$BT$8:$BV$13,3,0),"FILL=TRUE"))) -> 0 | CD22: =IF(ISERROR(G22-IF($BU$7=1,_xll.IMDP("FX",$CA22&CD$7,"BID직전가"),_xll.IMDP("FX",$CA22&CD$7,"뉴욕매입종가",VLOOKUP($BU$7,$BT$8:$BV$13,3,0),"FILL=TRUE"))),"",G22-IF($BU$7=1,_xll.IMDP("FX",$CA22&CD$7,"BID직전가"),_xll.IMDP("FX",$CA22&CD$7,"뉴욕매입종가",VLOOKUP($BU$7,$BT$8:$BV$13,3,0),"FILL=TRUE"))) -> 2e-05 | CE22: =IF(ISERROR(H22-IF($BU$7=1,_xll.IMDP("FX",$CA22&CE$7,"BID직전가"),_xll.IMDP("FX",$CA22&CE$7,"뉴욕매입종가",VLOOKUP($BU$7,$BT$8:$BV$13,3,0),"FILL=TRUE"))),"",H22-IF($BU$7=1,_xll.IMDP("FX",$CA22&CE$7,"BID직전가"),_xll.IMDP("FX",$CA22&CE$7,"뉴욕매입종가",VLOOKUP($BU$7,$BT$8:$BV$13,3,0),"FILL=TRUE"))) -> -0.0002 | CF22: =IF(ISERROR(I22-IF($BU$7=1,_xll.IMDP("FX",$CA22&CF$7,"BID직전가"),_xll.IMDP("FX",$CA22&CF$7,"뉴욕매입종가",VLOOKUP($BU$7,$BT$8:$BV$13,3,0),"FILL=TRUE"))),"",I22-IF($BU$7=1,_xll.IMDP("FX",$CA22&CF$7,"BID직전가"),_xll.IMDP("FX",$CA22&CF$7,"뉴욕매입종가",VLOOKUP($BU$7,$BT$8:$BV$13,3,0),"FILL=TRUE"))) -> 0.0001 | CG22: =IF(ISERROR(J22-IF($BU$7=1,_xll.IMDP("FX",$CA22&CG$7,"BID직전가"),_xll.IMDP("FX",$CA22&CG$7,"뉴욕매입종가",VLOOKUP($BU$7,$BT$8:$BV$13,3,0),"FILL=TRUE"))),"",J22-IF($BU$7=1,_xll.IMDP("FX",$CA22&CG$7,"BID직전가"),_xll.IMDP("FX",$CA22&CG$7,"뉴욕매입종가",VLOOKUP($BU$7,$BT$8:$BV$13,3,0),"FILL=TRUE"))) -> 0.00013 | CH22: =IF(ISERROR(K22-IF($BU$7=1,_xll.IMDP("FX",$CA22&CH$7,"BID직전가"),_xll.IMDP("FX",$CA22&CH$7,"뉴욕매입종가",VLOOKUP($BU$7,$BT$8:$BV$13,3,0),"FILL=TRUE"))),"",K22-IF($BU$7=1,_xll.IMDP("FX",$CA22&CH$7,"BID직전가"),_xll.IMDP("FX",$CA22&CH$7,"뉴욕매입종가",VLOOKUP($BU$7,$BT$8:$BV$13,3,0),"FILL=TRUE"))) -> 0 | CI22: =IF(ISERROR(L22-IF($BU$7=1,_xll.IMDP("FX",$CA22&CI$7,"BID직전가"),_xll.IMDP("FX",$CA22&CI$7,"뉴욕매입종가",VLOOKUP($BU$7,$BT$8:$BV$13,3,0),"FILL=TRUE"))),"",L22-IF($BU$7=1,_xll.IMDP("FX",$CA22&CI$7,"BID직전가"),_xll.IMDP("FX",$CA22&CI$7,"뉴욕매입종가",VLOOKUP($BU$7,$BT$8:$BV$13,3,0),"FILL=TRUE"))) -> 0.0001 | ... CV22: =IF(ISERROR(Y22-IF($BU$7=1,_xll.IMDP("FX",$CA22&CV$7,"BID직전가"),_xll.IMDP("FX",$CA22&CV$7,"뉴욕매입종가",VLOOKUP($BU$7,$BT$8:$BV$13,3,0),"FILL=TRUE"))),"",Y22-IF($BU$7=1,_xll.IMDP("FX",$CA22&CV$7,"BID직전가"),_xll.IMDP("FX",$CA22&CV$7,"뉴욕매입종가",VLOOKUP($BU$7,$BT$8:$BV$13,3,0),"FILL=TRUE"))) -> 0
B23: 26 | C23: =VLOOKUP($B23,$BX:$BY,2,0) -> IDR | E23: =_xll.IMDP("FX",$C23&E$6,"매입") -> 8.27 | F23: =_xll.IMDP("FX",$C23&F$6,"매입") -> 0.00698 | G23: =_xll.IMDP("FX",$C23&G$6,"매입") -> 0.06223 | H23: =_xll.IMDP("FX",$C23&H$6,"매입") -> 0.00754 | I23: =_xll.IMDP("FX",$C23&I$6,"매입") -> 0.04834 | J23: =_xll.IMDP("FX",$C23&J$6,"매입") | K23: =_xll.IMDP("FX",$C23&K$6,"매입") -> 0.00691 | L23: =_xll.IMDP("FX",$C23&L$6,"매입") -> 0.01 | ... Y23: =_xll.IMDP("FX",$C23&Y$6,"매입") -> 0.02198 | BX23: 16 | BY23: COP | CA23: =C23 -> IDR | CB23: =IF(ISERROR(E23-IF($BU$7=1,_xll.IMDP("FX",$CA23&CB$7,"BID직전가"),_xll.IMDP("FX",$CA23&CB$7,"뉴욕매입종가",VLOOKUP($BU$7,$BT$8:$BV$13,3,0),"FILL=TRUE"))),"",E23-IF($BU$7=1,_xll.IMDP("FX",$CA23&CB$7,"BID직전가"),_xll.IMDP("FX",$CA23&CB$7,"뉴욕매입종가",VLOOKUP($BU$7,$BT$8:$BV$13,3,0),"FILL=TRUE"))) -> 0 | CC23: =IF(ISERROR(F23-IF($BU$7=1,_xll.IMDP("FX",$CA23&CC$7,"BID직전가"),_xll.IMDP("FX",$CA23&CC$7,"뉴욕매입종가",VLOOKUP($BU$7,$BT$8:$BV$13,3,0),"FILL=TRUE"))),"",F23-IF($BU$7=1,_xll.IMDP("FX",$CA23&CC$7,"BID직전가"),_xll.IMDP("FX",$CA23&CC$7,"뉴욕매입종가",VLOOKUP($BU$7,$BT$8:$BV$13,3,0),"FILL=TRUE"))) -> 0 | CD23: =IF(ISERROR(G23-IF($BU$7=1,_xll.IMDP("FX",$CA23&CD$7,"BID직전가"),_xll.IMDP("FX",$CA23&CD$7,"뉴욕매입종가",VLOOKUP($BU$7,$BT$8:$BV$13,3,0),"FILL=TRUE"))),"",G23-IF($BU$7=1,_xll.IMDP("FX",$CA23&CD$7,"BID직전가"),_xll.IMDP("FX",$CA23&CD$7,"뉴욕매입종가",VLOOKUP($BU$7,$BT$8:$BV$13,3,0),"FILL=TRUE"))) -> 0 | CE23: =IF(ISERROR(H23-IF($BU$7=1,_xll.IMDP("FX",$CA23&CE$7,"BID직전가"),_xll.IMDP("FX",$CA23&CE$7,"뉴욕매입종가",VLOOKUP($BU$7,$BT$8:$BV$13,3,0),"FILL=TRUE"))),"",H23-IF($BU$7=1,_xll.IMDP("FX",$CA23&CE$7,"BID직전가"),_xll.IMDP("FX",$CA23&CE$7,"뉴욕매입종가",VLOOKUP($BU$7,$BT$8:$BV$13,3,0),"FILL=TRUE"))) -> 0 | CF23: =IF(ISERROR(I23-IF($BU$7=1,_xll.IMDP("FX",$CA23&CF$7,"BID직전가"),_xll.IMDP("FX",$CA23&CF$7,"뉴욕매입종가",VLOOKUP($BU$7,$BT$8:$BV$13,3,0),"FILL=TRUE"))),"",I23-IF($BU$7=1,_xll.IMDP("FX",$CA23&CF$7,"BID직전가"),_xll.IMDP("FX",$CA23&CF$7,"뉴욕매입종가",VLOOKUP($BU$7,$BT$8:$BV$13,3,0),"FILL=TRUE"))) -> 0 | CG23: =IF(ISERROR(J23-IF($BU$7=1,_xll.IMDP("FX",$CA23&CG$7,"BID직전가"),_xll.IMDP("FX",$CA23&CG$7,"뉴욕매입종가",VLOOKUP($BU$7,$BT$8:$BV$13,3,0),"FILL=TRUE"))),"",J23-IF($BU$7=1,_xll.IMDP("FX",$CA23&CG$7,"BID직전가"),_xll.IMDP("FX",$CA23&CG$7,"뉴욕매입종가",VLOOKUP($BU$7,$BT$8:$BV$13,3,0),"FILL=TRUE"))) | CH23: =IF(ISERROR(K23-IF($BU$7=1,_xll.IMDP("FX",$CA23&CH$7,"BID직전가"),_xll.IMDP("FX",$CA23&CH$7,"뉴욕매입종가",VLOOKUP($BU$7,$BT$8:$BV$13,3,0),"FILL=TRUE"))),"",K23-IF($BU$7=1,_xll.IMDP("FX",$CA23&CH$7,"BID직전가"),_xll.IMDP("FX",$CA23&CH$7,"뉴욕매입종가",VLOOKUP($BU$7,$BT$8:$BV$13,3,0),"FILL=TRUE"))) -> 0 | CI23: =IF(ISERROR(L23-IF($BU$7=1,_xll.IMDP("FX",$CA23&CI$7,"BID직전가"),_xll.IMDP("FX",$CA23&CI$7,"뉴욕매입종가",VLOOKUP($BU$7,$BT$8:$BV$13,3,0),"FILL=TRUE"))),"",L23-IF($BU$7=1,_xll.IMDP("FX",$CA23&CI$7,"BID직전가"),_xll.IMDP("FX",$CA23&CI$7,"뉴욕매입종가",VLOOKUP($BU$7,$BT$8:$BV$13,3,0),"FILL=TRUE"))) -> 1e-05 | ... CV23: =IF(ISERROR(Y23-IF($BU$7=1,_xll.IMDP("FX",$CA23&CV$7,"BID직전가"),_xll.IMDP("FX",$CA23&CV$7,"뉴욕매입종가",VLOOKUP($BU$7,$BT$8:$BV$13,3,0),"FILL=TRUE"))),"",Y23-IF($BU$7=1,_xll.IMDP("FX",$CA23&CV$7,"BID직전가"),_xll.IMDP("FX",$CA23&CV$7,"뉴욕매입종가",VLOOKUP($BU$7,$BT$8:$BV$13,3,0),"FILL=TRUE"))) -> 0
B24: 40 | C24: =VLOOKUP($B24,$BX:$BY,2,0) -> MYR | E24: =_xll.IMDP("FX",$C24&E$6,"매입") -> 282.53 | F24: =_xll.IMDP("FX",$C24&F$6,"매입") -> 0.2389 | G24: =_xll.IMDP("FX",$C24&G$6,"매입") -> 0.2128 | H24: =_xll.IMDP("FX",$C24&H$6,"매입") -> 25.837 | I24: =_xll.IMDP("FX",$C24&I$6,"매입") -> 1.6531 | J24: =_xll.IMDP("FX",$C24&J$6,"매입") -> 1.6514 | K24: =_xll.IMDP("FX",$C24&K$6,"매입") -> 0.2373 | L24: =_xll.IMDP("FX",$C24&L$6,"매입") -> 0.3427 | ... Y24: =_xll.IMDP("FX",$C24&Y$6,"매입") -> 7.5285 | BX24: 17 | BY24: CZK | CA24: =C24 -> MYR | CB24: =IF(ISERROR(E24-IF($BU$7=1,_xll.IMDP("FX",$CA24&CB$7,"BID직전가"),_xll.IMDP("FX",$CA24&CB$7,"뉴욕매입종가",VLOOKUP($BU$7,$BT$8:$BV$13,3,0),"FILL=TRUE"))),"",E24-IF($BU$7=1,_xll.IMDP("FX",$CA24&CB$7,"BID직전가"),_xll.IMDP("FX",$CA24&CB$7,"뉴욕매입종가",VLOOKUP($BU$7,$BT$8:$BV$13,3,0),"FILL=TRUE"))) -> -0.2 | CC24: =IF(ISERROR(F24-IF($BU$7=1,_xll.IMDP("FX",$CA24&CC$7,"BID직전가"),_xll.IMDP("FX",$CA24&CC$7,"뉴욕매입종가",VLOOKUP($BU$7,$BT$8:$BV$13,3,0),"FILL=TRUE"))),"",F24-IF($BU$7=1,_xll.IMDP("FX",$CA24&CC$7,"BID직전가"),_xll.IMDP("FX",$CA24&CC$7,"뉴욕매입종가",VLOOKUP($BU$7,$BT$8:$BV$13,3,0),"FILL=TRUE"))) -> 0 | CD24: =IF(ISERROR(G24-IF($BU$7=1,_xll.IMDP("FX",$CA24&CD$7,"BID직전가"),_xll.IMDP("FX",$CA24&CD$7,"뉴욕매입종가",VLOOKUP($BU$7,$BT$8:$BV$13,3,0),"FILL=TRUE"))),"",G24-IF($BU$7=1,_xll.IMDP("FX",$CA24&CD$7,"BID직전가"),_xll.IMDP("FX",$CA24&CD$7,"뉴욕매입종가",VLOOKUP($BU$7,$BT$8:$BV$13,3,0),"FILL=TRUE"))) -> 0 | CE24: =IF(ISERROR(H24-IF($BU$7=1,_xll.IMDP("FX",$CA24&CE$7,"BID직전가"),_xll.IMDP("FX",$CA24&CE$7,"뉴욕매입종가",VLOOKUP($BU$7,$BT$8:$BV$13,3,0),"FILL=TRUE"))),"",H24-IF($BU$7=1,_xll.IMDP("FX",$CA24&CE$7,"BID직전가"),_xll.IMDP("FX",$CA24&CE$7,"뉴욕매입종가",VLOOKUP($BU$7,$BT$8:$BV$13,3,0),"FILL=TRUE"))) -> -0.004 | CF24: =IF(ISERROR(I24-IF($BU$7=1,_xll.IMDP("FX",$CA24&CF$7,"BID직전가"),_xll.IMDP("FX",$CA24&CF$7,"뉴욕매입종가",VLOOKUP($BU$7,$BT$8:$BV$13,3,0),"FILL=TRUE"))),"",I24-IF($BU$7=1,_xll.IMDP("FX",$CA24&CF$7,"BID직전가"),_xll.IMDP("FX",$CA24&CF$7,"뉴욕매입종가",VLOOKUP($BU$7,$BT$8:$BV$13,3,0),"FILL=TRUE"))) -> 0.0001 | CG24: =IF(ISERROR(J24-IF($BU$7=1,_xll.IMDP("FX",$CA24&CG$7,"BID직전가"),_xll.IMDP("FX",$CA24&CG$7,"뉴욕매입종가",VLOOKUP($BU$7,$BT$8:$BV$13,3,0),"FILL=TRUE"))),"",J24-IF($BU$7=1,_xll.IMDP("FX",$CA24&CG$7,"BID직전가"),_xll.IMDP("FX",$CA24&CG$7,"뉴욕매입종가",VLOOKUP($BU$7,$BT$8:$BV$13,3,0),"FILL=TRUE"))) -> -0.0002 | CH24: =IF(ISERROR(K24-IF($BU$7=1,_xll.IMDP("FX",$CA24&CH$7,"BID직전가"),_xll.IMDP("FX",$CA24&CH$7,"뉴욕매입종가",VLOOKUP($BU$7,$BT$8:$BV$13,3,0),"FILL=TRUE"))),"",K24-IF($BU$7=1,_xll.IMDP("FX",$CA24&CH$7,"BID직전가"),_xll.IMDP("FX",$CA24&CH$7,"뉴욕매입종가",VLOOKUP($BU$7,$BT$8:$BV$13,3,0),"FILL=TRUE"))) -> 0 | CI24: =IF(ISERROR(L24-IF($BU$7=1,_xll.IMDP("FX",$CA24&CI$7,"BID직전가"),_xll.IMDP("FX",$CA24&CI$7,"뉴욕매입종가",VLOOKUP($BU$7,$BT$8:$BV$13,3,0),"FILL=TRUE"))),"",L24-IF($BU$7=1,_xll.IMDP("FX",$CA24&CI$7,"BID직전가"),_xll.IMDP("FX",$CA24&CI$7,"뉴욕매입종가",VLOOKUP($BU$7,$BT$8:$BV$13,3,0),"FILL=TRUE"))) -> 0.0001 | ... CV24: =IF(ISERROR(Y24-IF($BU$7=1,_xll.IMDP("FX",$CA24&CV$7,"BID직전가"),_xll.IMDP("FX",$CA24&CV$7,"뉴욕매입종가",VLOOKUP($BU$7,$BT$8:$BV$13,3,0),"FILL=TRUE"))),"",Y24-IF($BU$7=1,_xll.IMDP("FX",$CA24&CV$7,"BID직전가"),_xll.IMDP("FX",$CA24&CV$7,"뉴욕매입종가",VLOOKUP($BU$7,$BT$8:$BV$13,3,0),"FILL=TRUE"))) -> 0
B25: 46 | C25: =VLOOKUP($B25,$BX:$BY,2,0) -> PHP | E25: =_xll.IMDP("FX",$C25&E$6,"매입") -> 22.78 | F25: =_xll.IMDP("FX",$C25&F$6,"매입") -> 0.01925 | G25: =_xll.IMDP("FX",$C25&G$6,"매입") -> 0.0171 | H25: =_xll.IMDP("FX",$C25&H$6,"매입") -> 2.0811 | I25: =_xll.IMDP("FX",$C25&I$6,"매입") -> 0.1328 | J25: =_xll.IMDP("FX",$C25&J$6,"매입") | K25: =_xll.IMDP("FX",$C25&K$6,"매입") -> 0.01912 | L25: =_xll.IMDP("FX",$C25&L$6,"매입") -> 0.02761 | ... Y25: =_xll.IMDP("FX",$C25&Y$6,"매입") -> 0.6062 | BX25: 18 | BY25: DEM | CA25: =C25 -> PHP | CB25: =IF(ISERROR(E25-IF($BU$7=1,_xll.IMDP("FX",$CA25&CB$7,"BID직전가"),_xll.IMDP("FX",$CA25&CB$7,"뉴욕매입종가",VLOOKUP($BU$7,$BT$8:$BV$13,3,0),"FILL=TRUE"))),"",E25-IF($BU$7=1,_xll.IMDP("FX",$CA25&CB$7,"BID직전가"),_xll.IMDP("FX",$CA25&CB$7,"뉴욕매입종가",VLOOKUP($BU$7,$BT$8:$BV$13,3,0),"FILL=TRUE"))) -> 0 | CC25: =IF(ISERROR(F25-IF($BU$7=1,_xll.IMDP("FX",$CA25&CC$7,"BID직전가"),_xll.IMDP("FX",$CA25&CC$7,"뉴욕매입종가",VLOOKUP($BU$7,$BT$8:$BV$13,3,0),"FILL=TRUE"))),"",F25-IF($BU$7=1,_xll.IMDP("FX",$CA25&CC$7,"BID직전가"),_xll.IMDP("FX",$CA25&CC$7,"뉴욕매입종가",VLOOKUP($BU$7,$BT$8:$BV$13,3,0),"FILL=TRUE"))) -> 0 | CD25: =IF(ISERROR(G25-IF($BU$7=1,_xll.IMDP("FX",$CA25&CD$7,"BID직전가"),_xll.IMDP("FX",$CA25&CD$7,"뉴욕매입종가",VLOOKUP($BU$7,$BT$8:$BV$13,3,0),"FILL=TRUE"))),"",G25-IF($BU$7=1,_xll.IMDP("FX",$CA25&CD$7,"BID직전가"),_xll.IMDP("FX",$CA25&CD$7,"뉴욕매입종가",VLOOKUP($BU$7,$BT$8:$BV$13,3,0),"FILL=TRUE"))) -> 0 | CE25: =IF(ISERROR(H25-IF($BU$7=1,_xll.IMDP("FX",$CA25&CE$7,"BID직전가"),_xll.IMDP("FX",$CA25&CE$7,"뉴욕매입종가",VLOOKUP($BU$7,$BT$8:$BV$13,3,0),"FILL=TRUE"))),"",H25-IF($BU$7=1,_xll.IMDP("FX",$CA25&CE$7,"BID직전가"),_xll.IMDP("FX",$CA25&CE$7,"뉴욕매입종가",VLOOKUP($BU$7,$BT$8:$BV$13,3,0),"FILL=TRUE"))) -> -0.0003 | CF25: =IF(ISERROR(I25-IF($BU$7=1,_xll.IMDP("FX",$CA25&CF$7,"BID직전가"),_xll.IMDP("FX",$CA25&CF$7,"뉴욕매입종가",VLOOKUP($BU$7,$BT$8:$BV$13,3,0),"FILL=TRUE"))),"",I25-IF($BU$7=1,_xll.IMDP("FX",$CA25&CF$7,"BID직전가"),_xll.IMDP("FX",$CA25&CF$7,"뉴욕매입종가",VLOOKUP($BU$7,$BT$8:$BV$13,3,0),"FILL=TRUE"))) -> 0 | CG25: =IF(ISERROR(J25-IF($BU$7=1,_xll.IMDP("FX",$CA25&CG$7,"BID직전가"),_xll.IMDP("FX",$CA25&CG$7,"뉴욕매입종가",VLOOKUP($BU$7,$BT$8:$BV$13,3,0),"FILL=TRUE"))),"",J25-IF($BU$7=1,_xll.IMDP("FX",$CA25&CG$7,"BID직전가"),_xll.IMDP("FX",$CA25&CG$7,"뉴욕매입종가",VLOOKUP($BU$7,$BT$8:$BV$13,3,0),"FILL=TRUE"))) | CH25: =IF(ISERROR(K25-IF($BU$7=1,_xll.IMDP("FX",$CA25&CH$7,"BID직전가"),_xll.IMDP("FX",$CA25&CH$7,"뉴욕매입종가",VLOOKUP($BU$7,$BT$8:$BV$13,3,0),"FILL=TRUE"))),"",K25-IF($BU$7=1,_xll.IMDP("FX",$CA25&CH$7,"BID직전가"),_xll.IMDP("FX",$CA25&CH$7,"뉴욕매입종가",VLOOKUP($BU$7,$BT$8:$BV$13,3,0),"FILL=TRUE"))) -> 2e-05 | CI25: =IF(ISERROR(L25-IF($BU$7=1,_xll.IMDP("FX",$CA25&CI$7,"BID직전가"),_xll.IMDP("FX",$CA25&CI$7,"뉴욕매입종가",VLOOKUP($BU$7,$BT$8:$BV$13,3,0),"FILL=TRUE"))),"",L25-IF($BU$7=1,_xll.IMDP("FX",$CA25&CI$7,"BID직전가"),_xll.IMDP("FX",$CA25&CI$7,"뉴욕매입종가",VLOOKUP($BU$7,$BT$8:$BV$13,3,0),"FILL=TRUE"))) -> 1e-05 | ... CV25: =IF(ISERROR(Y25-IF($BU$7=1,_xll.IMDP("FX",$CA25&CV$7,"BID직전가"),_xll.IMDP("FX",$CA25&CV$7,"뉴욕매입종가",VLOOKUP($BU$7,$BT$8:$BV$13,3,0),"FILL=TRUE"))),"",Y25-IF($BU$7=1,_xll.IMDP("FX",$CA25&CV$7,"BID직전가"),_xll.IMDP("FX",$CA25&CV$7,"뉴욕매입종가",VLOOKUP($BU$7,$BT$8:$BV$13,3,0),"FILL=TRUE"))) -> 0
