Workbook

Sheet Comdty Correlation Matrix
E2: Commodity Futures Correlation Matrix
E3: Start Date | F3: =TODAY()-365 -> 44586 | G3: End Date | H3: =WORKDAY(TODAY(),-1) -> 44950
E5: Correlation Matrix | F5: =$C$6 -> WTI | G5: =$C$7 -> Brent | H5: =$C$8 -> Natural Gas | I5: =$C$9 -> Heating Oil | J5: =$C$10 -> Gas Oil | K5: =$C$11 -> Gold | L5: =$C$12 -> Silver | M5: =$C$13 -> Copper | N5: =$C$14 -> Butter | O5: =$C$15 -> Cheese | P5: =$C$16 -> Soybean | Q5: =$C$17 -> Soybean Oil | R5: =$C$18 -> Corn | S5: =$C$19 -> Coffee | T5: =$C$20 -> Orange Juice | U5: =$C$21 -> Sugar | V5: =$C$22 -> US Dollar Index
B6: 1 | C6: =VLOOKUP($B6,$AJ$6:$AL$41,2,0) -> WTI | D6: =VLOOKUP($B6,$AJ$6:$AL$41,3,0) -> NYM:CL | F6: =raw!B2 -> 1 | G6: =raw!C2 -> 0.98607577 | H6: =raw!D2 -> 0.3005594 | I6: =raw!E2 -> 0.62867585 | J6: =raw!F2 -> 0.7272666 | K6: =raw!G2 -> 0.44131295 | L6: =raw!H2 -> 0.18077005 | M6: =raw!I2 -> 0.49054318 | ... V6: =raw!R2 -> -0.34379468 | AJ6: 1 | AK6: WTI | AL6: NYM:CL
B7: 3 | C7: =VLOOKUP($B7,$AJ$6:$AL$41,2,0) -> Brent | D7: =VLOOKUP($B7,$AJ$6:$AL$41,3,0) -> IPE:EB | F7: =raw!B3 -> 0.98607577 | G7: =raw!C3 -> 1 | H7: =raw!D3 -> 0.34048834 | I7: =raw!E3 -> 0.67926495 | J7: =raw!F3 -> 0.77144617 | K7: =raw!G3 -> 0.39399531 | L7: =raw!H3 -> 0.12326718 | M7: =raw!I3 -> 0.42467062 | ... V7: =raw!R3 -> -0.26770122 | AJ7: 2 | AK7: Dubai | AL7: NYM:DCB
B8: 5 | C8: =VLOOKUP($B8,$AJ$6:$AL$41,2,0) -> Natural Gas | D8: =VLOOKUP($B8,$AJ$6:$AL$41,3,0) -> NYM:NG | F8: =raw!B4 -> 0.3005594 | G8: =raw!C4 -> 0.34048834 | H8: =raw!D4 -> 1 | I8: =raw!E4 -> 0.45280399 | J8: =raw!F4 -> 0.42497202 | K8: =raw!G4 -> -0.3244233 | L8: =raw!H4 -> -0.55730327 | M8: =raw!I4 -> -0.33959904 | ... V8: =raw!R4 -> 0.43978279 | AJ8: 3 | AK8: Brent | AL8: IPE:EB
B9: 4 | C9: =VLOOKUP($B9,$AJ$6:$AL$41,2,0) -> Heating Oil | D9: =VLOOKUP($B9,$AJ$6:$AL$41,3,0) -> NYM:HO | F9: =raw!B5 -> 0.62867585 | G9: =raw!C5 -> 0.67926495 | H9: =raw!D5 -> 0.45280399 | I9: =raw!E5 -> 1 | J9: =raw!F5 -> 0.86529395 | K9: =raw!G5 -> -0.026525529 | L9: =raw!H5 -> -0.22400889 | M9: =raw!I5 -> -0.033267398 | ... V9: =raw!R5 -> 0.30201824 | AJ9: 4 | AK9: Heating Oil | AL9: NYM:HO
B10: 6 | C10: =VLOOKUP($B10,$AJ$6:$AL$41,2,0) -> Gas Oil | D10: =VLOOKUP($B10,$AJ$6:$AL$41,3,0) -> IPE:EP | F10: =raw!B6 -> 0.7272666 | G10: =raw!C6 -> 0.77144617 | H10: =raw!D6 -> 0.42497202 | I10: =raw!E6 -> 0.86529395 | J10: =raw!F6 -> 1 | K10: =raw!G6 -> 0.084966633 | L10: =raw!H6 -> -0.15362848 | M10: =raw!I6 -> 0.032906979 | ... V10: =raw!R6 -> 0.20468089 | AJ10: 5 | AK10: Natural Gas | AL10: NYM:NG
B11: 11 | C11: =VLOOKUP($B11,$AJ$6:$AL$41,2,0) -> Gold | D11: =VLOOKUP($B11,$AJ$6:$AL$41,3,0) -> COM:GC | F11: =raw!B7 -> 0.44131295 | G11: =raw!C7 -> 0.39399531 | H11: =raw!D7 -> -0.3244233 | I11: =raw!E7 -> -0.026525529 | J11: =raw!F7 -> 0.084966633 | K11: =raw!G7 -> 1 | L11: =raw!H7 -> 0.89084689 | M11: =raw!I7 -> 0.89440897 | ... V11: =raw!R7 -> -0.84629679 | AJ11: 6 | AK11: Gas Oil | AL11: IPE:EP
B12: 12 | C12: =VLOOKUP($B12,$AJ$6:$AL$41,2,0) -> Silver | D12: =VLOOKUP($B12,$AJ$6:$AL$41,3,0) -> COM:SI | F12: =raw!B8 -> 0.18077005 | G12: =raw!C8 -> 0.12326718 | H12: =raw!D8 -> -0.55730327 | I12: =raw!E8 -> -0.22400889 | J12: =raw!F8 -> -0.15362848 | K12: =raw!G8 -> 0.89084689 | L12: =raw!H8 -> 1 | M12: =raw!I8 -> 0.86289719 | ... V12: =raw!R8 -> -0.81783954 | AJ12: 7 | AK12: UK Natural Gas | AL12: IPE:MN
B13: 13 | C13: =VLOOKUP($B13,$AJ$6:$AL$41,2,0) -> Copper | D13: =VLOOKUP($B13,$AJ$6:$AL$41,3,0) -> COM:HG | F13: =raw!B9 -> 0.49054318 | G13: =raw!C9 -> 0.42467062 | H13: =raw!D9 -> -0.33959904 | I13: =raw!E9 -> -0.033267398 | J13: =raw!F9 -> 0.032906979 | K13: =raw!G9 -> 0.89440897 | L13: =raw!H9 -> 0.86289719 | M13: =raw!I9 -> 1 | ... V13: =raw!R9 -> -0.88673258 | AJ13: 8 | AK13: Coal | AL13: NYM:QLD
B14: 16 | C14: =VLOOKUP($B14,$AJ$6:$AL$41,2,0) -> Butter | D14: =VLOOKUP($B14,$AJ$6:$AL$41,3,0) -> CME$CB | F14: =raw!B10 -> -0.10731054 | G14: =raw!C10 -> -0.025441715 | H14: =raw!D10 -> 0.51743716 | I14: =raw!E10 -> 0.35386789 | J14: =raw!F10 -> 0.31241777 | K14: =raw!G10 -> -0.7459232 | L14: =raw!H10 -> -0.74102698 | M14: =raw!I10 -> -0.72355428 | ... V14: =raw!R10 -> 0.81637168 | AJ14: 9 | AK14: Fuel Oil 380cts | AL14: NYM:SE
B15: 17 | C15: =VLOOKUP($B15,$AJ$6:$AL$41,2,0) -> Cheese | D15: =VLOOKUP($B15,$AJ$6:$AL$41,3,0) -> CME$CSC | F15: =raw!B11 -> 0.63766745 | G15: =raw!C11 -> 0.63825333 | H15: =raw!D11 -> 0.39771092 | I15: =raw!E11 -> 0.69721445 | J15: =raw!F11 -> 0.62478589 | K15: =raw!G11 -> 0.12615115 | L15: =raw!H11 -> -0.037094255 | M15: =raw!I11 -> 0.10698548 | ... V15: =raw!R11 -> 0.068554876 | AJ15: 10 | AK15: Fuel Oil 180cts | AL15: NYM:UA
B16: 24 | C16: =VLOOKUP($B16,$AJ$6:$AL$41,2,0) -> Soybean | D16: =VLOOKUP($B16,$AJ$6:$AL$41,3,0) -> CBT$ZS | F16: =raw!B12 -> 0.79990283 | G16: =raw!C12 -> 0.76184898 | H16: =raw!D12 -> 0.14475211 | I16: =raw!E12 -> 0.33298959 | J16: =raw!F12 -> 0.422764 | K16: =raw!G12 -> 0.73522191 | L16: =raw!H12 -> 0.47632576 | M16: =raw!I12 -> 0.68569563 | ... V16: =raw!R12 -> -0.60851906 | AJ16: 11 | AK16: Gold | AL16: COM:GC
B17: 26 | C17: =VLOOKUP($B17,$AJ$6:$AL$41,2,0) -> Soybean Oil | D17: =VLOOKUP($B17,$AJ$6:$AL$41,3,0) -> CBT$ZL | F17: =raw!B13 -> 0.61672212 | G17: =raw!C13 -> 0.60190655 | H17: =raw!D13 -> 0.31109318 | I17: =raw!E13 -> 0.58794334 | J17: =raw!F13 -> 0.51116695 | K17: =raw!G13 -> 0.35030781 | L17: =raw!H13 -> 0.24801313 | M17: =raw!I13 -> 0.44908273 | ... V17: =raw!R13 -> -0.13981837 | AJ17: 12 | AK17: Silver | AL17: COM:SI
... B22: 36 | C22: =VLOOKUP($B22,$AJ$6:$AL$41,2,0) -> US Dollar Index | D22: =VLOOKUP($B22,$AJ$6:$AL$41,3,0) -> NYB:DX | F22: =raw!B18 -> -0.34379468 | G22: =raw!C18 -> -0.26770122 | H22: =raw!D18 -> 0.43978279 | I22: =raw!E18 -> 0.30201824 | J22: =raw!F18 -> 0.20468089 | K22: =raw!G18 -> -0.84629679 | L22: =raw!H18 -> -0.81783954 | M22: =raw!I18 -> -0.88673258 | ... V22: =raw!R18 -> 1 | AJ22: 17 | AK22: Cheese | AL22: CME$CSC
AJ23: 18 | AK23: Milk Class Ⅲ | AL23: CME$DC
AJ24: 19 | AK24: Milk Class Ⅳ | AL24: CME$GDK
AJ25: 20 | AK25: Nonfat Dry Milk | AL25: CME$GNF
AJ26: 21 | AK26: Feeder Cattle | AL26: CME$GF
AJ27: 22 | AK27: Live Cattle | AL27: CME$LE
AJ28: 23 | AK28: Lean Hogs | AL28: CME$HE
AJ29: 24 | AK29: Soybean | AL29: CBT$ZS
AJ30: 25 | AK30: soybean Meal | AL30: CBT$ZM
AJ31: 26 | AK31: Soybean Oil | AL31: CBT$ZL
AJ32: 27 | AK32: Corn | AL32: CBT$ZC
AJ33: 28 | AK33: Oats | AL33: CBT$ZO
AJ34: 29 | AK34: Raugh Rice | AL34: CBT$ZR
... AJ41: 36 | AK41: US Dollar Index | AL41: NYB:DX

Sheet raw
B1: =A2 -> WTI | C1: =A3 -> Brent | D1: =A4 -> Natural Gas | E1: =A5 -> Heating Oil | F1: =A6 -> Gas Oil | G1: =A7 -> Gold | H1: =A8 -> Silver | I1: =A9 -> Copper | J1: =A10 -> Butter | K1: =A11 -> Cheese | L1: =A12 -> Soybean | M1: =A13 -> Soybean Oil | N1: =A14 -> Corn | O1: =A15 -> Coffee | P1: =A16 -> Orange Juice | Q1: =A17 -> Sugar | R1: =A18 -> US Dollar Index
A2: ='Comdty Correlation Matrix'!C6 -> WTI | B2: =CORREL($B$26:$B$9986,B$26:B$9986) -> 1 | C2: =CORREL($B$26:$B$9986,C$26:C$9986) -> 0.98607577 | D2: =CORREL($B$26:$B$9986,D$26:D$9986) -> 0.3005594 | E2: =CORREL($B$26:$B$9986,E$26:E$9986) -> 0.62867585 | F2: =CORREL($B$26:$B$9986,F$26:F$9986) -> 0.7272666 | G2: =CORREL($B$26:$B$9986,G$26:G$9986) -> 0.44131295 | H2: =CORREL($B$26:$B$9986,H$26:H$9986) -> 0.18077005 | I2: =CORREL($B$26:$B$9986,I$26:I$9986) -> 0.49054318 | ... R2: =CORREL($B$26:$B$9986,R$26:R$9986) -> -0.34379468
A3: ='Comdty Correlation Matrix'!C7 -> Brent | B3: =CORREL($C$26:$C$9986,B$26:B$9986) -> 0.98607577 | C3: =CORREL($C$26:$C$9986,C$26:C$9986) -> 1 | D3: =CORREL($C$26:$C$9986,D$26:D$9986) -> 0.34048834 | E3: =CORREL($C$26:$C$9986,E$26:E$9986) -> 0.67926495 | F3: =CORREL($C$26:$C$9986,F$26:F$9986) -> 0.77144617 | G3: =CORREL($C$26:$C$9986,G$26:G$9986) -> 0.39399531 | H3: =CORREL($C$26:$C$9986,H$26:H$9986) -> 0.12326718 | I3: =CORREL($C$26:$C$9986,I$26:I$9986) -> 0.42467062 | ... R3: =CORREL($C$26:$C$9986,R$26:R$9986) -> -0.26770122
A4: ='Comdty Correlation Matrix'!C8 -> Natural Gas | B4: =CORREL($D$26:$D$9986,B$26:B$9986) -> 0.3005594 | C4: =CORREL($D$26:$D$9986,C$26:C$9986) -> 0.34048834 | D4: =CORREL($D$26:$D$9986,D$26:D$9986) -> 1 | E4: =CORREL($D$26:$D$9986,E$26:E$9986) -> 0.45280399 | F4: =CORREL($D$26:$D$9986,F$26:F$9986) -> 0.42497202 | G4: =CORREL($D$26:$D$9986,G$26:G$9986) -> -0.3244233 | H4: =CORREL($D$26:$D$9986,H$26:H$9986) -> -0.55730327 | I4: =CORREL($D$26:$D$9986,I$26:I$9986) -> -0.33959904 | ... R4: =CORREL($D$26:$D$9986,R$26:R$9986) -> 0.43978279
A5: ='Comdty Correlation Matrix'!C9 -> Heating Oil | B5: =CORREL($E$26:$E$9986,B$26:B$9986) -> 0.62867585 | C5: =CORREL($E$26:$E$9986,C$26:C$9986) -> 0.67926495 | D5: =CORREL($E$26:$E$9986,D$26:D$9986) -> 0.45280399 | E5: =CORREL($E$26:$E$9986,E$26:E$9986) -> 1 | F5: =CORREL($E$26:$E$9986,F$26:F$9986) -> 0.86529395 | G5: =CORREL($E$26:$E$9986,G$26:G$9986) -> -0.026525529 | H5: =CORREL($E$26:$E$9986,H$26:H$9986) -> -0.22400889 | I5: =CORREL($E$26:$E$9986,I$26:I$9986) -> -0.033267398 | ... R5: =CORREL($E$26:$E$9986,R$26:R$9986) -> 0.30201824
A6: ='Comdty Correlation Matrix'!C10 -> Gas Oil | B6: =CORREL($F$26:$F$9986,B$26:B$9986) -> 0.7272666 | C6: =CORREL($F$26:$F$9986,C$26:C$9986) -> 0.77144617 | D6: =CORREL($F$26:$F$9986,D$26:D$9986) -> 0.42497202 | E6: =CORREL($F$26:$F$9986,E$26:E$9986) -> 0.86529395 | F6: =CORREL($F$26:$F$9986,F$26:F$9986) -> 1 | G6: =CORREL($F$26:$F$9986,G$26:G$9986) -> 0.084966633 | H6: =CORREL($F$26:$F$9986,H$26:H$9986) -> -0.15362848 | I6: =CORREL($F$26:$F$9986,I$26:I$9986) -> 0.032906979 | ... R6: =CORREL($F$26:$F$9986,R$26:R$9986) -> 0.20468089
A7: ='Comdty Correlation Matrix'!C11 -> Gold | B7: =CORREL($G$26:$G$9986,B$26:B$9986) -> 0.44131295 | C7: =CORREL($G$26:$G$9986,C$26:C$9986) -> 0.39399531 | D7: =CORREL($G$26:$G$9986,D$26:D$9986) -> -0.3244233 | E7: =CORREL($G$26:$G$9986,E$26:E$9986) -> -0.026525529 | F7: =CORREL($G$26:$G$9986,F$26:F$9986) -> 0.084966633 | G7: =CORREL($G$26:$G$9986,G$26:G$9986) -> 1 | H7: =CORREL($G$26:$G$9986,H$26:H$9986) -> 0.89084689 | I7: =CORREL($G$26:$G$9986,I$26:I$9986) -> 0.89440897 | ... R7: =CORREL($G$26:$G$9986,R$26:R$9986) -> -0.84629679
A8: ='Comdty Correlation Matrix'!C12 -> Silver | B8: =CORREL($H$26:$H$9986,B$26:B$9986) -> 0.18077005 | C8: =CORREL($H$26:$H$9986,C$26:C$9986) -> 0.12326718 | D8: =CORREL($H$26:$H$9986,D$26:D$9986) -> -0.55730327 | E8: =CORREL($H$26:$H$9986,E$26:E$9986) -> -0.22400889 | F8: =CORREL($H$26:$H$9986,F$26:F$9986) -> -0.15362848 | G8: =CORREL($H$26:$H$9986,G$26:G$9986) -> 0.89084689 | H8: =CORREL($H$26:$H$9986,H$26:H$9986) -> 1 | I8: =CORREL($H$26:$H$9986,I$26:I$9986) -> 0.86289719 | ... R8: =CORREL($H$26:$H$9986,R$26:R$9986) -> -0.81783954
A9: ='Comdty Correlation Matrix'!C13 -> Copper | B9: =CORREL($I$26:$I$9986,B$26:B$9986) -> 0.49054318 | C9: =CORREL($I$26:$I$9986,C$26:C$9986) -> 0.42467062 | D9: =CORREL($I$26:$I$9986,D$26:D$9986) -> -0.33959904 | E9: =CORREL($I$26:$I$9986,E$26:E$9986) -> -0.033267398 | F9: =CORREL($I$26:$I$9986,F$26:F$9986) -> 0.032906979 | G9: =CORREL($I$26:$I$9986,G$26:G$9986) -> 0.89440897 | H9: =CORREL($I$26:$I$9986,H$26:H$9986) -> 0.86289719 | I9: =CORREL($I$26:$I$9986,I$26:I$9986) -> 1 | ... R9: =CORREL($I$26:$I$9986,R$26:R$9986) -> -0.88673258
A10: ='Comdty Correlation Matrix'!C14 -> Butter | B10: =CORREL($J$26:$J$9986,B$26:B$9986) -> -0.10731054 | C10: =CORREL($J$26:$J$9986,C$26:C$9986) -> -0.025441715 | D10: =CORREL($J$26:$J$9986,D$26:D$9986) -> 0.51743716 | E10: =CORREL($J$26:$J$9986,E$26:E$9986) -> 0.35386789 | F10: =CORREL($J$26:$J$9986,F$26:F$9986) -> 0.31241777 | G10: =CORREL($J$26:$J$9986,G$26:G$9986) -> -0.7459232 | H10: =CORREL($J$26:$J$9986,H$26:H$9986) -> -0.74102698 | I10: =CORREL($J$26:$J$9986,I$26:I$9986) -> -0.72355428 | ... R10: =CORREL($J$26:$J$9986,R$26:R$9986) -> 0.81637168
A11: ='Comdty Correlation Matrix'!C15 -> Cheese | B11: =CORREL($K$26:$K$9986,B$26:B$9986) -> 0.63766745 | C11: =CORREL($K$26:$K$9986,C$26:C$9986) -> 0.63825333 | D11: =CORREL($K$26:$K$9986,D$26:D$9986) -> 0.39771092 | E11: =CORREL($K$26:$K$9986,E$26:E$9986) -> 0.69721445 | F11: =CORREL($K$26:$K$9986,F$26:F$9986) -> 0.62478589 | G11: =CORREL($K$26:$K$9986,G$26:G$9986) -> 0.12615115 | H11: =CORREL($K$26:$K$9986,H$26:H$9986) -> -0.037094255 | I11: =CORREL($K$26:$K$9986,I$26:I$9986) -> 0.10698548 | ... R11: =CORREL($K$26:$K$9986,R$26:R$9986) -> 0.068554876
A12: ='Comdty Correlation Matrix'!C16 -> Soybean | B12: =CORREL($L$26:$L$9986,B$26:B$9986) -> 0.79990283 | C12: =CORREL($L$26:$L$9986,C$26:C$9986) -> 0.76184898 | D12: =CORREL($L$26:$L$9986,D$26:D$9986) -> 0.14475211 | E12: =CORREL($L$26:$L$9986,E$26:E$9986) -> 0.33298959 | F12: =CORREL($L$26:$L$9986,F$26:F$9986) -> 0.422764 | G12: =CORREL($L$26:$L$9986,G$26:G$9986) -> 0.73522191 | H12: =CORREL($L$26:$L$9986,H$26:H$9986) -> 0.47632576 | I12: =CORREL($L$26:$L$9986,I$26:I$9986) -> 0.68569563 | ... R12: =CORREL($L$26:$L$9986,R$26:R$9986) -> -0.60851906
A13: ='Comdty Correlation Matrix'!C17 -> Soybean Oil | B13: =CORREL($M$26:$M$9986,B$26:B$9986) -> 0.61672212 | C13: =CORREL($M$26:$M$9986,C$26:C$9986) -> 0.60190655 | D13: =CORREL($M$26:$M$9986,D$26:D$9986) -> 0.31109318 | E13: =CORREL($M$26:$M$9986,E$26:E$9986) -> 0.58794334 | F13: =CORREL($M$26:$M$9986,F$26:F$9986) -> 0.51116695 | G13: =CORREL($M$26:$M$9986,G$26:G$9986) -> 0.35030781 | H13: =CORREL($M$26:$M$9986,H$26:H$9986) -> 0.24801313 | I13: =CORREL($M$26:$M$9986,I$26:I$9986) -> 0.44908273 | ... R13: =CORREL($M$26:$M$9986,R$26:R$9986) -> -0.13981837
A14: ='Comdty Correlation Matrix'!C18 -> Corn | B14: =CORREL($N$26:$N$9986,B$26:B$9986) -> 0.68859332 | C14: =CORREL($N$26:$N$9986,C$26:C$9986) -> 0.66086123 | D14: =CORREL($N$26:$N$9986,D$26:D$9986) -> 0.090346509 | E14: =CORREL($N$26:$N$9986,E$26:E$9986) -> 0.60094902 | F14: =CORREL($N$26:$N$9986,F$26:F$9986) -> 0.58463478 | G14: =CORREL($N$26:$N$9986,G$26:G$9986) -> 0.46634561 | H14: =CORREL($N$26:$N$9986,H$26:H$9986) -> 0.33275393 | I14: =CORREL($N$26:$N$9986,I$26:I$9986) -> 0.50502927 | ... R14: =CORREL($N$26:$N$9986,R$26:R$9986) -> -0.21162405
A15: ='Comdty Correlation Matrix'!C19 -> Coffee | B15: =CORREL($O$26:$O$9986,B$26:B$9986) -> 0.60763533 | C15: =CORREL($O$26:$O$9986,C$26:C$9986) -> 0.5837265 | D15: =CORREL($O$26:$O$9986,D$26:D$9986) -> 0.29354976 | E15: =CORREL($O$26:$O$9986,E$26:E$9986) -> 0.15218418 | F15: =CORREL($O$26:$O$9986,F$26:F$9986) -> 0.3177575 | G15: =CORREL($O$26:$O$9986,G$26:G$9986) -> 0.18631752 | H15: =CORREL($O$26:$O$9986,H$26:H$9986) -> -0.043355761 | I15: =CORREL($O$26:$O$9986,I$26:I$9986) -> 0.32174197 | ... R15: =CORREL($O$26:$O$9986,R$26:R$9986) -> -0.30887194
A16: ='Comdty Correlation Matrix'!C20 -> Orange Juice | B16: =CORREL($P$26:$P$9986,B$26:B$9986) -> -0.51836859 | C16: =CORREL($P$26:$P$9986,C$26:C$9986) -> -0.48251993 | D16: =CORREL($P$26:$P$9986,D$26:D$9986) -> 0.05780858 | E16: =CORREL($P$26:$P$9986,E$26:E$9986) -> 0.10923031 | F16: =CORREL($P$26:$P$9986,F$26:F$9986) -> -0.07928693 | G16: =CORREL($P$26:$P$9986,G$26:G$9986) -> -0.42770794 | H16: =CORREL($P$26:$P$9986,H$26:H$9986) -> -0.25161867 | I16: =CORREL($P$26:$P$9986,I$26:I$9986) -> -0.4969146 | ... R16: =CORREL($P$26:$P$9986,R$26:R$9986) -> 0.60855966
A17: ='Comdty Correlation Matrix'!C21 -> Sugar | B17: =CORREL($Q$26:$Q$9986,B$26:B$9986) -> -0.019532806 | C17: =CORREL($Q$26:$Q$9986,C$26:C$9986) -> -0.055625933 | D17: =CORREL($Q$26:$Q$9986,D$26:D$9986) -> -0.23529167 | E17: =CORREL($Q$26:$Q$9986,E$26:E$9986) -> -0.01343142 | F17: =CORREL($Q$26:$Q$9986,F$26:F$9986) -> -0.072578105 | G17: =CORREL($Q$26:$Q$9986,G$26:G$9986) -> 0.44236077 | H17: =CORREL($Q$26:$Q$9986,H$26:H$9986) -> 0.57006648 | I17: =CORREL($Q$26:$Q$9986,I$26:I$9986) -> 0.36531282 | ... R17: =CORREL($Q$26:$Q$9986,R$26:R$9986) -> -0.25597443
A18: ='Comdty Correlation Matrix'!C22 -> US Dollar Index | B18: =CORREL($R$26:$R$9986,B$26:B$9986) -> -0.34379468 | C18: =CORREL($R$26:$R$9986,C$26:C$9986) -> -0.26770122 | D18: =CORREL($R$26:$R$9986,D$26:D$9986) -> 0.43978279 | E18: =CORREL($R$26:$R$9986,E$26:E$9986) -> 0.30201824 | F18: =CORREL($R$26:$R$9986,F$26:F$9986) -> 0.20468089 | G18: =CORREL($R$26:$R$9986,G$26:G$9986) -> -0.84629679 | H18: =CORREL($R$26:$R$9986,H$26:H$9986) -> -0.81783954 | I18: =CORREL($R$26:$R$9986,I$26:I$9986) -> -0.88673258 | ... R18: =CORREL($R$26:$R$9986,R$26:R$9986) -> 1
A22: 시작 | B22: ='Comdty Correlation Matrix'!F3 -> 44586 | C22: 종료 | D22: ='Comdty Correlation Matrix'!H3 -> 44950 | E22: Data 개수 | F22: 9999 | G22: 주기 | H22: 일 | I22: 정렬 | J22: D | K22: 영업일 | L22: 12 | M22: 시세산출 | N22: 종가
A23: ='Comdty Correlation Matrix'!D6 -> NYM:CL | C23: ='Comdty Correlation Matrix'!D7 -> IPE:EB | D23: ='Comdty Correlation Matrix'!D8 -> NYM:NG | E23: ='Comdty Correlation Matrix'!D9 -> NYM:HO | F23: ='Comdty Correlation Matrix'!D10 -> IPE:EP | G23: ='Comdty Correlation Matrix'!D11 -> COM:GC | H23: ='Comdty Correlation Matrix'!D12 -> COM:SI | I23: ='Comdty Correlation Matrix'!D13 -> COM:HG | J23: ='Comdty Correlation Matrix'!D14 -> CME$CB | K23: ='Comdty Correlation Matrix'!D15 -> CME$CSC | L23: ='Comdty Correlation Matrix'!D16 -> CBT$ZS | M23: ='Comdty Correlation Matrix'!D17 -> CBT$ZL | N23: ='Comdty Correlation Matrix'!D18 -> CBT$ZC | O23: ='Comdty Correlation Matrix'!D19 -> NYB:KC | P23: ='Comdty Correlation Matrix'!D20 -> NYB:OJ | Q23: ='Comdty Correlation Matrix'!D21 -> NYB:SB | R23: ='Comdty Correlation Matrix'!D22 -> NYB:DX
A24: =_xll.IMDH("FRN",A23,A25:B25,$B$22,$D$22,$F$22,"Per="&$H$22&",sort="&$J$22&",real=true,Bizday="&$L$22&",Quote="&$N$22&",Pos=20,Orient=V,Title=WTI,DtFmt=1,TmFmt=1,unit=true") -> WTI | C24: =_xll.IMDH("FRN",C23,C25,$B$22,$D$22,$F$22,"Per="&$H$22&",sort="&$J$22&",real=true,Bizday="&$L$22&",Quote="&$N$22&",Pos=20,Orient=V,Title="&A3&",DtFmt=1,TmFmt=1,unit=true") -> BRENT | D24: =_xll.IMDH("FRN",D23,D25,$B$22,$D$22,$F$22,"Per="&$H$22&",sort="&$J$22&",real=true,Bizday="&$L$22&",Quote="&$N$22&",Pos=20,Orient=V,Title="&A4&",DtFmt=1,TmFmt=1,unit=true") -> NATURAL GAS | E24: =_xll.IMDH("FRN",E23,E25,$B$22,$D$22,$F$22,"Per="&$H$22&",sort="&$J$22&",real=true,Bizday="&$L$22&",Quote="&$N$22&",Pos=20,Orient=V,Title="&A5&",DtFmt=1,TmFmt=1,unit=true") -> HEATING OIL | F24: =_xll.IMDH("FRN",F23,F25,$B$22,$D$22,$F$22,"Per="&$H$22&",sort="&$J$22&",real=true,Bizday="&$L$22&",Quote="&$N$22&",Pos=20,Orient=V,Title="&A6&",DtFmt=1,TmFmt=1,unit=true") -> GAS OIL | G24: =_xll.IMDH("FRN",G23,G25,$B$22,$D$22,$F$22,"Per="&$H$22&",sort="&$J$22&",real=true,Bizday="&$L$22&",Quote="&$N$22&",Pos=20,Orient=V,Title="&A7&",DtFmt=1,TmFmt=1,unit=true") -> GOLD | H24: =_xll.IMDH("FRN",H23,H25,$B$22,$D$22,$F$22,"Per="&$H$22&",sort="&$J$22&",real=true,Bizday="&$L$22&",Quote="&$N$22&",Pos=20,Orient=V,Title="&A8&",DtFmt=1,TmFmt=1,unit=true") -> SILVER | I24: =_xll.IMDH("FRN",I23,I25,$B$22,$D$22,$F$22,"Per="&$H$22&",sort="&$J$22&",real=true,Bizday="&$L$22&",Quote="&$N$22&",Pos=20,Orient=V,Title="&A9&",DtFmt=1,TmFmt=1,unit=true") -> COPPER | J24: =_xll.IMDH("FRN",J23,J25,$B$22,$D$22,$F$22,"Per="&$H$22&",sort="&$J$22&",real=true,Bizday="&$L$22&",Quote="&$N$22&",Pos=20,Orient=V,Title="&A10&",DtFmt=1,TmFmt=1,unit=true") -> BUTTER | K24: =_xll.IMDH("FRN",K23,K25,$B$22,$D$22,$F$22,"Per="&$H$22&",sort="&$J$22&",real=true,Bizday="&$L$22&",Quote="&$N$22&",Pos=20,Orient=V,Title="&A11&",DtFmt=1,TmFmt=1,unit=true") -> CHEESE | L24: =_xll.IMDH("FRN",L23,L25,$B$22,$D$22,$F$22,"Per="&$H$22&",sort="&$J$22&",real=true,Bizday="&$L$22&",Quote="&$N$22&",Pos=20,Orient=V,Title="&A12&",DtFmt=1,TmFmt=1,unit=true") -> SOYBEAN | M24: =_xll.IMDH("FRN",M23,M25,$B$22,$D$22,$F$22,"Per="&$H$22&",sort="&$J$22&",real=true,Bizday="&$L$22&",Quote="&$N$22&",Pos=20,Orient=V,Title="&A13&",DtFmt=1,TmFmt=1,unit=true") -> SOYBEAN OIL | N24: =_xll.IMDH("FRN",N23,N25,$B$22,$D$22,$F$22,"Per="&$H$22&",sort="&$J$22&",real=true,Bizday="&$L$22&",Quote="&$N$22&",Pos=20,Orient=V,Title="&A14&",DtFmt=1,TmFmt=1,unit=true") -> CORN | O24: =_xll.IMDH("FRN",O23,O25,$B$22,$D$22,$F$22,"Per="&$H$22&",sort="&$J$22&",real=true,Bizday="&$L$22&",Quote="&$N$22&",Pos=20,Orient=V,Title="&A15&",DtFmt=1,TmFmt=1,unit=true") -> COFFEE | P24: =_xll.IMDH("FRN",P23,P25,$B$22,$D$22,$F$22,"Per="&$H$22&",sort="&$J$22&",real=true,Bizday="&$L$22&",Quote="&$N$22&",Pos=20,Orient=V,Title="&A16&",DtFmt=1,TmFmt=1,unit=true") -> ORANGE JUICE | Q24: =_xll.IMDH("FRN",Q23,Q25,$B$22,$D$22,$F$22,"Per="&$H$22&",sort="&$J$22&",real=true,Bizday="&$L$22&",Quote="&$N$22&",Pos=20,Orient=V,Title="&A17&",DtFmt=1,TmFmt=1,unit=true") -> SUGAR | R24: =_xll.IMDH("FRN",R23,R25,$B$22,$D$22,$F$22,"Per="&$H$22&",sort="&$J$22&",real=true,Bizday="&$L$22&",Quote="&$N$22&",Pos=20,Orient=V,Title="&A18&",DtFmt=1,TmFmt=1,unit=true") -> US DOLLAR INDEX
A25: 일자 | B25: 현재가 | C25: 현재가 | D25: 현재가 | E25: 현재가 | F25: 현재가 | G25: 현재가 | H25: 현재가 | I25: 현재가 | J25: 현재가 | K25: 현재가 | L25: 현재가 | M25: 현재가 | N25: 현재가 | O25: 현재가 | P25: 현재가 | Q25: 현재가 | R25: 현재가
A26: 44950 | B26: 80.13 | C26: 86.13 | D26: 3.258 | E26: 3.4272 | F26: 985.75 | G26: 1935.4 | H26: 23.749 | I26: 4.2485 | J26: 243.35 | K26: 1.979 | L26: 1488.5 | M26: 60.98 | N26: 677 | O26: 159.85 | P26: 203.8 | Q26: 19.88 | R26: 101.675
A27: 44949 | B27: 81.62 | C27: 88.19 | D27: 3.447 | E27: 3.5509 | F27: 1012.25 | G27: 1928.6 | H27: 23.554 | I27: 4.2565 | J27: 243.35 | K27: 1.979 | L27: 1490.25 | M27: 62.04 | N27: 666.25 | O27: 158.55 | P27: 204.4 | Q27: 19.7 | R27: 101.916
A28: 44948
A29: 44947
A30: 44946 | B30: 81.31 | C30: 87.63 | D30: 3.174 | E30: 3.4668 | F30: 983.5 | G30: 1928.2 | H30: 23.935 | I30: 4.2515 | J30: 243.25 | K30: 1.978 | L30: 1506.5 | M30: 61.97 | N30: 676.25 | O30: 154.8 | P30: 203.5 | Q30: 19.72 | R30: 101.781
A31: 44945 | B31: 80.33 | C31: 86.16 | D31: 3.275 | E31: 3.3759 | F31: 943 | G31: 1923.9 | H31: 23.87 | I31: 4.2315 | J31: 241.25 | K31: 1.98 | L31: 1514.75 | M31: 63.15 | N31: 677.25 | O31: 154.6 | P31: 204.2 | Q31: 19.68 | R31: 101.831
A32: 44944 | B32: 79.48 | C32: 84.98 | D32: 3.311 | E32: 3.263 | F32: 953.5 | G32: 1907 | H32: 23.647 | I32: 4.2345 | J32: 241.4 | K32: 1.979 | L32: 1524.5 | M32: 64.12 | N32: 681.25 | O32: 155 | P32: 205.55 | Q32: 19.82 | R32: 102.107
A33: 44943 | B33: 80.18 | C33: 85.92 | D33: 3.586 | E33: 3.251 | F33: 927.25 | G33: 1909.9 | H33: 24.068 | I33: 4.223 | J33: 241.3 | K33: 1.981 | L33: 1539.75 | M33: 63.84 | N33: 685.25 | O33: 151.1 | P33: 206.2 | Q33: 20.14 | R33: 102.141
A34: 44942 | C34: 84.46 | F34: 934
A35: 44941
A36: 44940
A37: 44939 | B37: 79.86 | C37: 85.28 | D37: 3.419 | E37: 3.2559 | F37: 932.75 | G37: 1921.7 | H37: 24.372 | I37: 4.216 | J37: 241.4 | K37: 1.98 | L37: 1538.25 | M37: 63.25 | N37: 675 | O37: 151.7 | P37: 207.2 | Q37: 19.73 | R37: 101.946
A38: 44938 | B38: 78.39 | C38: 84.03 | D38: 3.695 | E38: 3.219 | F38: 905.5 | G38: 1898.8 | H38: 24.004 | I38: 4.1965 | J38: 241.1 | K38: 1.988 | L38: 1529.5 | M38: 63.25 | N38: 671 | O38: 149.4 | P38: 207.4 | Q38: 19.59 | R38: 101.995
A39: 44937 | B39: 77.41 | C39: 82.67 | D39: 3.671 | E39: 3.2179 | F39: 905.5 | G39: 1878.9 | H39: 23.481 | I39: 4.166 | J39: 237.75 | K39: 1.989 | L39: 1515 | M39: 62.39 | N39: 656 | O39: 143.9 | P39: 207.6 | Q39: 19.65 | R39: 102.928
A40: 44936 | B40: 75.12 | C40: 80.1 | D40: 3.639 | E40: 3.1357 | F40: 883.5 | G40: 1876.5 | H40: 23.665 | I40: 4.0775 | J40: 237.05 | K40: 1.99 | L40: 1510 | M40: 63.13 | N40: 655 | O40: 150.9 | P40: 208.65 | Q40: 19.64 | R40: 102.98
A41: 44935 | B41: 74.63 | C41: 79.65 | D41: 3.91 | E41: 3.036 | F41: 880.5 | G41: 1877.8 | H41: 23.871 | I41: 4.0265 | J41: 234.9 | K41: 2.008 | L41: 1503.5 | M41: 63.91 | N41: 652.75 | O41: 158.05 | P41: 208.9 | Q41: 19.17 | R41: 102.743
A42: 44934
A43: 44933
...
