Workbook

Sheet filter
R1: {=INDEX($R$3:$R$6,$R$2)} -> 월
B2: 자산/시장 | C2: 계열 | D2: 전략 | G2: 수익률 | J2: CODE | L2: 1 | M2: 2 | N2: 3 | R2: 2
B3: 1 | C3: 2 | D3: 3 | E3: 4 | F3: 5 | G3: 6 | I3: =IF( ISNUMBER(SEARCH($H$18, J3)), MAX($I$2:$I2)+1, 0 ) -> 1 | J3: KGG01P | L3: 개인 | R3: 일
B4: K | C4: G | D4: G | G4: P | I4: =IF( ISNUMBER(SEARCH($H$18, J4)), MAX($I$2:$I3)+1, 0 ) -> 2 | J4: X3G01P | L4: 기관 | R4: 월
B5: Q | C5: 2 | D5: S | G5: T | I5: =IF( ISNUMBER(SEARCH($H$18, J5)), MAX($I$2:$I4)+1, 0 ) -> 3 | J5: K2W01P | L5: 외국인합 | R5: 분기
B6: X | C6: 5 | D6: Z | G6: N | I6: =IF( ISNUMBER(SEARCH($H$18, J6)), MAX($I$2:$I5)+1, 0 ) -> 4 | J6: K2G01P | L6: 증권/선물 | R6: 년
B7: G | C7: 3 | D7: D | I7: =IF( ISNUMBER(SEARCH($H$18, J7)), MAX($I$2:$I6)+1, 0 ) -> 5 | J7: K2X01P | L7: 투신
B8: F | C8: T | D8: E | I8: =IF( ISNUMBER(SEARCH($H$18, J8)), MAX($I$2:$I7)+1, 0 ) -> 6 | J8: XGW01P | L8: 사모펀드
B9: O | C9: R | D9: T | I9: =IF( ISNUMBER(SEARCH($H$18, J9)), MAX($I$2:$I8)+1, 0 ) -> 7 | J9: XGG01P | L9: 은행
B10: M | D10: W | I10: =IF( ISNUMBER(SEARCH($H$18, J10)), MAX($I$2:$I9)+1, 0 ) -> 8 | J10: KGZ01P | L10: 보험
B11: T | D11: B | I11: =IF( ISNUMBER(SEARCH($H$18, J11)), MAX($I$2:$I10)+1, 0 ) -> 9 | J11: K2W02P | L11: 종신
D12: X | I12: =IF( ISNUMBER(SEARCH($H$18, J12)), MAX($I$2:$I11)+1, 0 ) -> 10 | J12: K2G02P | L12: 연기금
D13: V | I13: =IF( ISNUMBER(SEARCH($H$18, J13)), MAX($I$2:$I12)+1, 0 ) -> 11 | J13: KGS18P | L13: 기타
D14: A | I14: =IF( ISNUMBER(SEARCH($H$18, J14)), MAX($I$2:$I13)+1, 0 ) -> 12 | J14: K2W03P | L14: 외국인
D15: 9 | I15: =IF( ISNUMBER(SEARCH($H$18, J15)), MAX($I$2:$I14)+1, 0 ) -> 13 | J15: K2G03P | L15: 외인기타
I16: =IF( ISNUMBER(SEARCH($H$18, J16)), MAX($I$2:$I15)+1, 0 ) -> 14 | J16: KGS09P | L16: 국가/지방
I17: =IF( ISNUMBER(SEARCH($H$18, J17)), MAX($I$2:$I16)+1, 0 ) -> 15 | J17: K2B01P
B18: {=IF(filter!B$21=1, "?", INDEX(filter!B$4:B$15, filter!B$21))} -> ? | C18: {=IF(filter!C$21=1, "?", INDEX(filter!C$4:C$15, filter!C$21))} -> ? | D18: {=IF(filter!D$21=1, "?", INDEX(filter!D$4:D$15, filter!D$21))} -> ? | E18: ? | F18: ? | G18: {=IF(filter!G$21=1, "?", INDEX(filter!G$4:G$15, filter!G$21))} -> ? | H18: =CONCATENATE(filter!$B$18,filter!$C$18,filter!$D$18,filter!$E$18,filter!$F$18,filter!$G$18) -> ?????? | I18: =IF( ISNUMBER(SEARCH($H$18, J18)), MAX($I$2:$I17)+1, 0 ) -> 16 | J18: K2X03P
I19: =IF( ISNUMBER(SEARCH($H$18, J19)), MAX($I$2:$I18)+1, 0 ) -> 17 | J19: K2S07P
I20: =IF( ISNUMBER(SEARCH($H$18, J20)), MAX($I$2:$I19)+1, 0 ) -> 18 | J20: QGG01P
B21: 1 | C21: 1 | D21: 1 | G21: 1 | I21: =IF( ISNUMBER(SEARCH($H$18, J21)), MAX($I$2:$I20)+1, 0 ) -> 19 | J21: KGS14P
B22: 기초자산/시장 | C22: 계열 | D22: 전략 | G22: 수익률 | I22: =IF( ISNUMBER(SEARCH($H$18, J22)), MAX($I$2:$I21)+1, 0 ) -> 20 | J22: XGT01P
B23: 코스피 | C23: 일반 | D23: 일반 | G23: 가격지수 | I23: =IF( ISNUMBER(SEARCH($H$18, J23)), MAX($I$2:$I22)+1, 0 ) -> 21 | J23: QGS02P
B24: 코스닥 | C24: 코스피200 | D24: 산업/섹터 | G24: TR지수 | I24: =IF( ISNUMBER(SEARCH($H$18, J24)), MAX($I$2:$I23)+1, 0 ) -> 22 | J24: KGZ02P
B25: KRX | C25: 코스닥150 | D25: 사이즈 | G25: NTR지수 | I25: =IF( ISNUMBER(SEARCH($H$18, J25)), MAX($I$2:$I24)+1, 0 ) -> 23 | J25: K2X05P
B26: 글로벌/기타 | C26: KRX300 | D26: 배당 | I26: =IF( ISNUMBER(SEARCH($H$18, J26)), MAX($I$2:$I25)+1, 0 ) -> 24 | J26: K2S03P
B27: 선물 | C27: 국채 | D27: ESG | I27: =IF( ISNUMBER(SEARCH($H$18, J27)), MAX($I$2:$I26)+1, 0 ) -> 25 | J27: KGS10P
B28: 옵션 | C28: 통합 | D28: 트렌드 | I28: =IF( ISNUMBER(SEARCH($H$18, J28)), MAX($I$2:$I27)+1, 0 ) -> 26 | J28: Q5G01P
B29: 멀티에셋 | D29: 동일가중 | I29: =IF( ISNUMBER(SEARCH($H$18, J29)), MAX($I$2:$I28)+1, 0 ) -> 27 | J29: Q5W01P
B30: 일반상품/기타 | D30: 스마트베타 | I30: =IF( ISNUMBER(SEARCH($H$18, J30)), MAX($I$2:$I29)+1, 0 ) -> 28 | J30: Q5X01P
D31: 레버리지/인버스 | I31: =IF( ISNUMBER(SEARCH($H$18, J31)), MAX($I$2:$I30)+1, 0 ) -> 29 | J31: Q5X02P
D32: 목표변동성 | I32: =IF( ISNUMBER(SEARCH($H$18, J32)), MAX($I$2:$I31)+1, 0 ) -> 30 | J32: K2S04P
D33: 자산배분 | I33: =IF( ISNUMBER(SEARCH($H$18, J33)), MAX($I$2:$I32)+1, 0 ) -> 31 | J33: QGG03P
D34: 기타전략 | I34: =IF( ISNUMBER(SEARCH($H$18, J34)), MAX($I$2:$I33)+1, 0 ) -> 32 | J34: XGT02P
I35: =IF( ISNUMBER(SEARCH($H$18, J35)), MAX($I$2:$I34)+1, 0 ) -> 33 | J35: QGZ01P
I36: =IF( ISNUMBER(SEARCH($H$18, J36)), MAX($I$2:$I35)+1, 0 ) -> 34 | J36: K2S06P
I37: =IF( ISNUMBER(SEARCH($H$18, J37)), MAX($I$2:$I36)+1, 0 ) -> 35 | J37: K2X06P
I38: =IF( ISNUMBER(SEARCH($H$18, J38)), MAX($I$2:$I37)+1, 0 ) -> 36 | J38: KGS22P
I39: =IF( ISNUMBER(SEARCH($H$18, J39)), MAX($I$2:$I38)+1, 0 ) -> 37 | J39: XGT03P
I40: =IF( ISNUMBER(SEARCH($H$18, J40)), MAX($I$2:$I39)+1, 0 ) -> 38 | J40: KGS04P
...

Sheet KRX
B2: KRX 지수 종합
B4: 일자 | D4: =TODAY() -> 45539 | E4: 데이터 주기
D6: 한글종목명 | E6: 현재가 | F6: 전일대비 | G6: 등락률 | H6: 누적거래량 | I6: 누적거래대금 | J6: 시가 | K6: 고가 | L6: 저가 | M6: =INDEX(filter!$L$3:$L$16, filter!$L$2, 0)&"순매수금액" -> 개인순매수금액 | N6: {=INDEX(filter!$L$3:$L$16, filter!$M$2, 0)&"순매수금액"} -> 기관순매수금액 | O6: {=INDEX(filter!$L$3:$L$16, filter!$N$2, 0)&"순매수금액"} -> 외국인합순매수금액
M7: 순매수 금액 (백만)
B8: No. | C8: 코드 | D8: 지수명 | E8: 현재가 | F8: 대비 | G8: 등락률 | H8: 거래량 (천) | I8: 대금 (백만) | J8: 시가 | K8: 고가 | L8: 저가
B9: =IF( $C9<>"", 1, "") -> 1 | C9: =IFERROR( VLOOKUP(ROWS($B$8:B8), filter!$I:$J, 2, 0), "") -> KGG01P | D9: {=IF( $C9="", "", _xll.IMDP("IDX", $C9, D$6) )} -> 코스피 | E9: {=IF( $C9="", "", _xll.IMDP("IDX",$C9,E$6,$D$4,"Fill=true, Per="&filter!$R$1) )} -> 2664.63 | F9: {=IF( $C9="", "", _xll.IMDP("IDX",$C9,F$6,$D$4,"Fill=true, Per="&filter!$R$1) )} -> -9.68 | G9: {=IF( $C9="", "", _xll.IMDP("IDX",$C9,G$6,$D$4,"Fill=true, Per="&filter!$R$1) )} -> -0.36 | H9: {=IF( $C9="", "", _xll.IMDP("IDX",$C9,H$6,$D$4,"Fill=true, Per="&filter!$R$1) )} -> 570452 | I9: {=IF( $C9="", "", _xll.IMDP("IDX",$C9,I$6,$D$4,"Fill=true, Per="&filter!$R$1) )} -> 17648380 | J9: {=IF( $C9="", "", _xll.IMDP("IDX",$C9,J$6,$D$4,"Fill=true, Per="&filter!$R$1) )} -> 2683.8 | K9: {=IF( $C9="", "", _xll.IMDP("IDX",$C9,K$6,$D$4,"Fill=true, Per="&filter!$R$1) )} -> 2695.59 | L9: {=IF( $C9="", "", _xll.IMDP("IDX",$C9,L$6,$D$4,"Fill=true, Per="&filter!$R$1) )} -> 0 | M9: =IF( $C9="", "", _xll.IMDP("IDX",$C9,M$6,$D$4,"fill=true,Per="&filter!$R$1) ) -> 671103 | N9: {=IF( $C9="", "", _xll.IMDP("IDX",$C9,N$6,$D$4,"Fill=true, Per="&filter!$R$1) )} -> -662140 | O9: {=IF( $C9="", "", _xll.IMDP("IDX",$C9,O$6,$D$4,"Fill=true, Per="&filter!$R$1) )} -> -47958
B10: =IF( $C10<>"", B9+1, "") -> 2 | C10: =IFERROR( VLOOKUP(ROWS($B$8:B9), filter!$I:$J, 2, 0), "") -> X3G01P | D10: {=IF( $C10="", "", _xll.IMDP("IDX", $C10, D$6) )} -> KRX 300 | E10: {=IF( $C10="", "", _xll.IMDP("IDX",$C10,E$6,$D$4,"Fill=true, Per="&filter!$R$1) )} -> 1660.04 | F10: {=IF( $C10="", "", _xll.IMDP("IDX",$C10,F$6,$D$4,"Fill=true, Per="&filter!$R$1) )} -> -12.98 | G10: {=IF( $C10="", "", _xll.IMDP("IDX",$C10,G$6,$D$4,"Fill=true, Per="&filter!$R$1) )} -> -0.78 | H10: {=IF( $C10="", "", _xll.IMDP("IDX",$C10,H$6,$D$4,"Fill=true, Per="&filter!$R$1) )} -> 286369 | I10: {=IF( $C10="", "", _xll.IMDP("IDX",$C10,I$6,$D$4,"Fill=true, Per="&filter!$R$1) )} -> 18878330 | J10: {=IF( $C10="", "", _xll.IMDP("IDX",$C10,J$6,$D$4,"Fill=true, Per="&filter!$R$1) )} -> 1677.6 | K10: {=IF( $C10="", "", _xll.IMDP("IDX",$C10,K$6,$D$4,"Fill=true, Per="&filter!$R$1) )} -> 1684.41 | L10: {=IF( $C10="", "", _xll.IMDP("IDX",$C10,L$6,$D$4,"Fill=true, Per="&filter!$R$1) )} -> 0 | ... O10: {=IF( $C10="", "", _xll.IMDP("IDX",$C10,O$6,$D$4,"Fill=true, Per="&filter!$R$1) )}
B11: =IF( $C11<>"", B10+1, "") -> 3 | C11: =IFERROR( VLOOKUP(ROWS($B$8:B10), filter!$I:$J, 2, 0), "") -> K2W01P | D11: {=IF( $C11="", "", _xll.IMDP("IDX", $C11, D$6) )} -> 코스피 200 동일가중지수 | E11: {=IF( $C11="", "", _xll.IMDP("IDX",$C11,E$6,$D$4,"Fill=true, Per="&filter!$R$1) )} -> 2257.44 | F11: {=IF( $C11="", "", _xll.IMDP("IDX",$C11,F$6,$D$4,"Fill=true, Per="&filter!$R$1) )} -> 3.8 | G11: {=IF( $C11="", "", _xll.IMDP("IDX",$C11,G$6,$D$4,"Fill=true, Per="&filter!$R$1) )} -> 0.17 | H11: {=IF( $C11="", "", _xll.IMDP("IDX",$C11,H$6,$D$4,"Fill=true, Per="&filter!$R$1) )} -> 206271 | I11: {=IF( $C11="", "", _xll.IMDP("IDX",$C11,I$6,$D$4,"Fill=true, Per="&filter!$R$1) )} -> 14856197 | J11: {=IF( $C11="", "", _xll.IMDP("IDX",$C11,J$6,$D$4,"Fill=true, Per="&filter!$R$1) )} -> 2258.83 | K11: {=IF( $C11="", "", _xll.IMDP("IDX",$C11,K$6,$D$4,"Fill=true, Per="&filter!$R$1) )} -> 2266.33 | L11: {=IF( $C11="", "", _xll.IMDP("IDX",$C11,L$6,$D$4,"Fill=true, Per="&filter!$R$1) )} -> 0 | ... O11: {=IF( $C11="", "", _xll.IMDP("IDX",$C11,O$6,$D$4,"Fill=true, Per="&filter!$R$1) )}
B12: =IF( $C12<>"", B11+1, "") -> 4 | C12: =IFERROR( VLOOKUP(ROWS($B$8:B11), filter!$I:$J, 2, 0), "") -> K2G01P | D12: {=IF( $C12="", "", _xll.IMDP("IDX", $C12, D$6) )} -> 코스피 200 | E12: {=IF( $C12="", "", _xll.IMDP("IDX",$C12,E$6,$D$4,"Fill=true, Per="&filter!$R$1) )} -> 358.8 | F12: {=IF( $C12="", "", _xll.IMDP("IDX",$C12,F$6,$D$4,"Fill=true, Per="&filter!$R$1) )} -> -2.75 | G12: {=IF( $C12="", "", _xll.IMDP("IDX",$C12,G$6,$D$4,"Fill=true, Per="&filter!$R$1) )} -> -0.76 | H12: {=IF( $C12="", "", _xll.IMDP("IDX",$C12,H$6,$D$4,"Fill=true, Per="&filter!$R$1) )} -> 206271 | I12: {=IF( $C12="", "", _xll.IMDP("IDX",$C12,I$6,$D$4,"Fill=true, Per="&filter!$R$1) )} -> 14856197 | J12: {=IF( $C12="", "", _xll.IMDP("IDX",$C12,J$6,$D$4,"Fill=true, Per="&filter!$R$1) )} -> 362.57 | K12: {=IF( $C12="", "", _xll.IMDP("IDX",$C12,K$6,$D$4,"Fill=true, Per="&filter!$R$1) )} -> 363.87 | L12: {=IF( $C12="", "", _xll.IMDP("IDX",$C12,L$6,$D$4,"Fill=true, Per="&filter!$R$1) )} -> 0 | ... O12: {=IF( $C12="", "", _xll.IMDP("IDX",$C12,O$6,$D$4,"Fill=true, Per="&filter!$R$1) )} -> -28858
B13: =IF( $C13<>"", B12+1, "") -> 5 | C13: =IFERROR( VLOOKUP(ROWS($B$8:B12), filter!$I:$J, 2, 0), "") -> K2X01P | D13: {=IF( $C13="", "", _xll.IMDP("IDX", $C13, D$6) )} -> 코스피 200 레버리지지수 | E13: {=IF( $C13="", "", _xll.IMDP("IDX",$C13,E$6,$D$4,"Fill=true, Per="&filter!$R$1) )} -> 286.44 | F13: {=IF( $C13="", "", _xll.IMDP("IDX",$C13,F$6,$D$4,"Fill=true, Per="&filter!$R$1) )} -> -4.54 | G13: {=IF( $C13="", "", _xll.IMDP("IDX",$C13,G$6,$D$4,"Fill=true, Per="&filter!$R$1) )} -> -1.56 | H13: {=IF( $C13="", "", _xll.IMDP("IDX",$C13,H$6,$D$4,"Fill=true, Per="&filter!$R$1) )} -> 0 | I13: {=IF( $C13="", "", _xll.IMDP("IDX",$C13,I$6,$D$4,"Fill=true, Per="&filter!$R$1) )} -> 0 | J13: {=IF( $C13="", "", _xll.IMDP("IDX",$C13,J$6,$D$4,"Fill=true, Per="&filter!$R$1) )} -> 292.54 | K13: {=IF( $C13="", "", _xll.IMDP("IDX",$C13,K$6,$D$4,"Fill=true, Per="&filter!$R$1) )} -> 294.61 | L13: {=IF( $C13="", "", _xll.IMDP("IDX",$C13,L$6,$D$4,"Fill=true, Per="&filter!$R$1) )} -> 0 | ... O13: {=IF( $C13="", "", _xll.IMDP("IDX",$C13,O$6,$D$4,"Fill=true, Per="&filter!$R$1) )}
B14: =IF( $C14<>"", B13+1, "") -> 6 | C14: =IFERROR( VLOOKUP(ROWS($B$8:B13), filter!$I:$J, 2, 0), "") -> XGW01P | D14: {=IF( $C14="", "", _xll.IMDP("IDX", $C14, D$6) )} -> KRX 100 동일가중지수 | E14: {=IF( $C14="", "", _xll.IMDP("IDX",$C14,E$6,$D$4,"Fill=true, Per="&filter!$R$1) )} -> 2022.32 | F14: {=IF( $C14="", "", _xll.IMDP("IDX",$C14,F$6,$D$4,"Fill=true, Per="&filter!$R$1) )} -> 6.5 | G14: {=IF( $C14="", "", _xll.IMDP("IDX",$C14,G$6,$D$4,"Fill=true, Per="&filter!$R$1) )} -> 0.32 | H14: {=IF( $C14="", "", _xll.IMDP("IDX",$C14,H$6,$D$4,"Fill=true, Per="&filter!$R$1) )} -> 159601 | I14: {=IF( $C14="", "", _xll.IMDP("IDX",$C14,I$6,$D$4,"Fill=true, Per="&filter!$R$1) )} -> 14112981 | J14: {=IF( $C14="", "", _xll.IMDP("IDX",$C14,J$6,$D$4,"Fill=true, Per="&filter!$R$1) )} -> 2021.89 | K14: {=IF( $C14="", "", _xll.IMDP("IDX",$C14,K$6,$D$4,"Fill=true, Per="&filter!$R$1) )} -> 2034.99 | L14: {=IF( $C14="", "", _xll.IMDP("IDX",$C14,L$6,$D$4,"Fill=true, Per="&filter!$R$1) )} -> 0 | ... O14: {=IF( $C14="", "", _xll.IMDP("IDX",$C14,O$6,$D$4,"Fill=true, Per="&filter!$R$1) )}
B15: =IF( $C15<>"", B14+1, "") -> 7 | C15: =IFERROR( VLOOKUP(ROWS($B$8:B14), filter!$I:$J, 2, 0), "") -> XGG01P | D15: {=IF( $C15="", "", _xll.IMDP("IDX", $C15, D$6) )} -> KRX 100 | E15: {=IF( $C15="", "", _xll.IMDP("IDX",$C15,E$6,$D$4,"Fill=true, Per="&filter!$R$1) )} -> 5613.2 | F15: {=IF( $C15="", "", _xll.IMDP("IDX",$C15,F$6,$D$4,"Fill=true, Per="&filter!$R$1) )} -> -33.65 | G15: {=IF( $C15="", "", _xll.IMDP("IDX",$C15,G$6,$D$4,"Fill=true, Per="&filter!$R$1) )} -> -0.6 | H15: {=IF( $C15="", "", _xll.IMDP("IDX",$C15,H$6,$D$4,"Fill=true, Per="&filter!$R$1) )} -> 159601 | I15: {=IF( $C15="", "", _xll.IMDP("IDX",$C15,I$6,$D$4,"Fill=true, Per="&filter!$R$1) )} -> 14112981 | J15: {=IF( $C15="", "", _xll.IMDP("IDX",$C15,J$6,$D$4,"Fill=true, Per="&filter!$R$1) )} -> 5663.38 | K15: {=IF( $C15="", "", _xll.IMDP("IDX",$C15,K$6,$D$4,"Fill=true, Per="&filter!$R$1) )} -> 5694.64 | L15: {=IF( $C15="", "", _xll.IMDP("IDX",$C15,L$6,$D$4,"Fill=true, Per="&filter!$R$1) )} -> 0 | ... O15: {=IF( $C15="", "", _xll.IMDP("IDX",$C15,O$6,$D$4,"Fill=true, Per="&filter!$R$1) )}
B16: =IF( $C16<>"", B15+1, "") -> 8 | C16: =IFERROR( VLOOKUP(ROWS($B$8:B15), filter!$I:$J, 2, 0), "") -> KGZ01P | D16: {=IF( $C16="", "", _xll.IMDP("IDX", $C16, D$6) )} -> 코스피 대형주 | E16: {=IF( $C16="", "", _xll.IMDP("IDX",$C16,E$6,$D$4,"Fill=true, Per="&filter!$R$1) )} -> 2666.69 | F16: {=IF( $C16="", "", _xll.IMDP("IDX",$C16,F$6,$D$4,"Fill=true, Per="&filter!$R$1) )} -> -11.13 | G16: {=IF( $C16="", "", _xll.IMDP("IDX",$C16,G$6,$D$4,"Fill=true, Per="&filter!$R$1) )} -> -0.42 | H16: {=IF( $C16="", "", _xll.IMDP("IDX",$C16,H$6,$D$4,"Fill=true, Per="&filter!$R$1) )} -> 157146 | I16: {=IF( $C16="", "", _xll.IMDP("IDX",$C16,I$6,$D$4,"Fill=true, Per="&filter!$R$1) )} -> 12937457 | J16: {=IF( $C16="", "", _xll.IMDP("IDX",$C16,J$6,$D$4,"Fill=true, Per="&filter!$R$1) )} -> 2688.25 | K16: {=IF( $C16="", "", _xll.IMDP("IDX",$C16,K$6,$D$4,"Fill=true, Per="&filter!$R$1) )} -> 2702.56 | L16: {=IF( $C16="", "", _xll.IMDP("IDX",$C16,L$6,$D$4,"Fill=true, Per="&filter!$R$1) )} -> 0 | ... O16: {=IF( $C16="", "", _xll.IMDP("IDX",$C16,O$6,$D$4,"Fill=true, Per="&filter!$R$1) )} -> -89052
B17: =IF( $C17<>"", B16+1, "") -> 9 | C17: =IFERROR( VLOOKUP(ROWS($B$8:B16), filter!$I:$J, 2, 0), "") -> K2W02P | D17: {=IF( $C17="", "", _xll.IMDP("IDX", $C17, D$6) )} -> 코스피 100 동일가중지수 | E17: {=IF( $C17="", "", _xll.IMDP("IDX",$C17,E$6,$D$4,"Fill=true, Per="&filter!$R$1) )} -> 2023.16 | F17: {=IF( $C17="", "", _xll.IMDP("IDX",$C17,F$6,$D$4,"Fill=true, Per="&filter!$R$1) )} -> 11.87 | G17: {=IF( $C17="", "", _xll.IMDP("IDX",$C17,G$6,$D$4,"Fill=true, Per="&filter!$R$1) )} -> 0.59 | H17: {=IF( $C17="", "", _xll.IMDP("IDX",$C17,H$6,$D$4,"Fill=true, Per="&filter!$R$1) )} -> 154114 | I17: {=IF( $C17="", "", _xll.IMDP("IDX",$C17,I$6,$D$4,"Fill=true, Per="&filter!$R$1) )} -> 12678083 | J17: {=IF( $C17="", "", _xll.IMDP("IDX",$C17,J$6,$D$4,"Fill=true, Per="&filter!$R$1) )} -> 2016.41 | K17: {=IF( $C17="", "", _xll.IMDP("IDX",$C17,K$6,$D$4,"Fill=true, Per="&filter!$R$1) )} -> 2032.28 | L17: {=IF( $C17="", "", _xll.IMDP("IDX",$C17,L$6,$D$4,"Fill=true, Per="&filter!$R$1) )} -> 0 | ... O17: {=IF( $C17="", "", _xll.IMDP("IDX",$C17,O$6,$D$4,"Fill=true, Per="&filter!$R$1) )}
B18: =IF( $C18<>"", B17+1, "") -> 10 | C18: =IFERROR( VLOOKUP(ROWS($B$8:B17), filter!$I:$J, 2, 0), "") -> K2G02P | D18: {=IF( $C18="", "", _xll.IMDP("IDX", $C18, D$6) )} -> 코스피 100 | E18: {=IF( $C18="", "", _xll.IMDP("IDX",$C18,E$6,$D$4,"Fill=true, Per="&filter!$R$1) )} -> 2702.91 | F18: {=IF( $C18="", "", _xll.IMDP("IDX",$C18,F$6,$D$4,"Fill=true, Per="&filter!$R$1) )} -> -19.45 | G18: {=IF( $C18="", "", _xll.IMDP("IDX",$C18,G$6,$D$4,"Fill=true, Per="&filter!$R$1) )} -> -0.71 | H18: {=IF( $C18="", "", _xll.IMDP("IDX",$C18,H$6,$D$4,"Fill=true, Per="&filter!$R$1) )} -> 154114 | I18: {=IF( $C18="", "", _xll.IMDP("IDX",$C18,I$6,$D$4,"Fill=true, Per="&filter!$R$1) )} -> 12678083 | J18: {=IF( $C18="", "", _xll.IMDP("IDX",$C18,J$6,$D$4,"Fill=true, Per="&filter!$R$1) )} -> 2730.01 | K18: {=IF( $C18="", "", _xll.IMDP("IDX",$C18,K$6,$D$4,"Fill=true, Per="&filter!$R$1) )} -> 2741.91 | L18: {=IF( $C18="", "", _xll.IMDP("IDX",$C18,L$6,$D$4,"Fill=true, Per="&filter!$R$1) )} -> 0 | ... O18: {=IF( $C18="", "", _xll.IMDP("IDX",$C18,O$6,$D$4,"Fill=true, Per="&filter!$R$1) )}
B19: =IF( $C19<>"", B18+1, "") -> 11 | C19: =IFERROR( VLOOKUP(ROWS($B$8:B18), filter!$I:$J, 2, 0), "") -> KGS18P | D19: {=IF( $C19="", "", _xll.IMDP("IDX", $C19, D$6) )} -> 제조업 | E19: {=IF( $C19="", "", _xll.IMDP("IDX",$C19,E$6,$D$4,"Fill=true, Per="&filter!$R$1) )} -> 6941.78 | F19: {=IF( $C19="", "", _xll.IMDP("IDX",$C19,F$6,$D$4,"Fill=true, Per="&filter!$R$1) )} -> -74.18 | G19: {=IF( $C19="", "", _xll.IMDP("IDX",$C19,G$6,$D$4,"Fill=true, Per="&filter!$R$1) )} -> -1.06 | H19: {=IF( $C19="", "", _xll.IMDP("IDX",$C19,H$6,$D$4,"Fill=true, Per="&filter!$R$1) )} -> 308132 | I19: {=IF( $C19="", "", _xll.IMDP("IDX",$C19,I$6,$D$4,"Fill=true, Per="&filter!$R$1) )} -> 13640365 | J19: {=IF( $C19="", "", _xll.IMDP("IDX",$C19,J$6,$D$4,"Fill=true, Per="&filter!$R$1) )} -> 7048.04 | K19: {=IF( $C19="", "", _xll.IMDP("IDX",$C19,K$6,$D$4,"Fill=true, Per="&filter!$R$1) )} -> 7063.72 | L19: {=IF( $C19="", "", _xll.IMDP("IDX",$C19,L$6,$D$4,"Fill=true, Per="&filter!$R$1) )} -> 0 | ... O19: {=IF( $C19="", "", _xll.IMDP("IDX",$C19,O$6,$D$4,"Fill=true, Per="&filter!$R$1) )} -> -266184
B20: =IF( $C20<>"", B19+1, "") -> 12 | C20: =IFERROR( VLOOKUP(ROWS($B$8:B19), filter!$I:$J, 2, 0), "") -> K2W03P | D20: {=IF( $C20="", "", _xll.IMDP("IDX", $C20, D$6) )} -> 코스피 50 동일가중지수 | E20: {=IF( $C20="", "", _xll.IMDP("IDX",$C20,E$6,$D$4,"Fill=true, Per="&filter!$R$1) )} -> 1777.47 | F20: {=IF( $C20="", "", _xll.IMDP("IDX",$C20,F$6,$D$4,"Fill=true, Per="&filter!$R$1) )} -> 14.16 | G20: {=IF( $C20="", "", _xll.IMDP("IDX",$C20,G$6,$D$4,"Fill=true, Per="&filter!$R$1) )} -> 0.8 | H20: {=IF( $C20="", "", _xll.IMDP("IDX",$C20,H$6,$D$4,"Fill=true, Per="&filter!$R$1) )} -> 96808 | I20: {=IF( $C20="", "", _xll.IMDP("IDX",$C20,I$6,$D$4,"Fill=true, Per="&filter!$R$1) )} -> 9348389 | J20: {=IF( $C20="", "", _xll.IMDP("IDX",$C20,J$6,$D$4,"Fill=true, Per="&filter!$R$1) )} -> 1769.4 | K20: {=IF( $C20="", "", _xll.IMDP("IDX",$C20,K$6,$D$4,"Fill=true, Per="&filter!$R$1) )} -> 1789.87 | L20: {=IF( $C20="", "", _xll.IMDP("IDX",$C20,L$6,$D$4,"Fill=true, Per="&filter!$R$1) )} -> 0 | ... O20: {=IF( $C20="", "", _xll.IMDP("IDX",$C20,O$6,$D$4,"Fill=true, Per="&filter!$R$1) )}
B21: =IF( $C21<>"", B20+1, "") -> 13 | C21: =IFERROR( VLOOKUP(ROWS($B$8:B20), filter!$I:$J, 2, 0), "") -> K2G03P | D21: {=IF( $C21="", "", _xll.IMDP("IDX", $C21, D$6) )} -> 코스피 50 | E21: {=IF( $C21="", "", _xll.IMDP("IDX",$C21,E$6,$D$4,"Fill=true, Per="&filter!$R$1) )} -> 2478.36 | F21: {=IF( $C21="", "", _xll.IMDP("IDX",$C21,F$6,$D$4,"Fill=true, Per="&filter!$R$1) )} -> -18.56 | G21: {=IF( $C21="", "", _xll.IMDP("IDX",$C21,G$6,$D$4,"Fill=true, Per="&filter!$R$1) )} -> -0.74 | H21: {=IF( $C21="", "", _xll.IMDP("IDX",$C21,H$6,$D$4,"Fill=true, Per="&filter!$R$1) )} -> 96808 | I21: {=IF( $C21="", "", _xll.IMDP("IDX",$C21,I$6,$D$4,"Fill=true, Per="&filter!$R$1) )} -> 9348389 | J21: {=IF( $C21="", "", _xll.IMDP("IDX",$C21,J$6,$D$4,"Fill=true, Per="&filter!$R$1) )} -> 2504.14 | K21: {=IF( $C21="", "", _xll.IMDP("IDX",$C21,K$6,$D$4,"Fill=true, Per="&filter!$R$1) )} -> 2517.3 | L21: {=IF( $C21="", "", _xll.IMDP("IDX",$C21,L$6,$D$4,"Fill=true, Per="&filter!$R$1) )} -> 0 | ... O21: {=IF( $C21="", "", _xll.IMDP("IDX",$C21,O$6,$D$4,"Fill=true, Per="&filter!$R$1) )}
... B385: =IF( $C385<>"", B384+1, "") | C385: =IFERROR( VLOOKUP(ROWS($B$8:B384), filter!$I:$J, 2, 0), "") | D385: {=IF( $C385="", "", _xll.IMDP("IDX", $C385, D$6) )} | E385: {=IF( $C385="", "", _xll.IMDP("IDX",$C385,E$6,$D$4,"Fill=true, Per="&filter!$R$1) )} | F385: {=IF( $C385="", "", _xll.IMDP("IDX",$C385,F$6,$D$4,"Fill=true, Per="&filter!$R$1) )} | G385: {=IF( $C385="", "", _xll.IMDP("IDX",$C385,G$6,$D$4,"Fill=true, Per="&filter!$R$1) )} | H385: {=IF( $C385="", "", _xll.IMDP("IDX",$C385,H$6,$D$4,"Fill=true, Per="&filter!$R$1) )} | I385: {=IF( $C385="", "", _xll.IMDP("IDX",$C385,I$6,$D$4,"Fill=true, Per="&filter!$R$1) )} | J385: {=IF( $C385="", "", _xll.IMDP("IDX",$C385,J$6,$D$4,"Fill=true, Per="&filter!$R$1) )} | K385: {=IF( $C385="", "", _xll.IMDP("IDX",$C385,K$6,$D$4,"Fill=true, Per="&filter!$R$1) )} | L385: {=IF( $C385="", "", _xll.IMDP("IDX",$C385,L$6,$D$4,"Fill=true, Per="&filter!$R$1) )} | ... O385: {=IF( $C385="", "", _xll.IMDP("IDX",$C385,O$6,$D$4,"Fill=true, Per="&filter!$R$1) )}
