Workbook

Sheet Market Overview
Q1: KOSPI | AC1: =_xll.IMDH("IDX",$N$2,AC2:AF2,$C$5,$C$6,$C$7,"Per=일,sort=D,real=true,Bizday=2,Quote=종가,Pos=20,Orient=V,Title="&$E$2&",DtFmt=1,TmFmt=1,unit=true") -> KOSPI | AD1: 1347637067 | AE1: 2.3148855e+18 | AF1: 2.3148855e+18
B2: 업종코드 | C2: KOSPI | E2: KOSPI | N2: =IF($C$2="KOSPI",VLOOKUP($E$2,업종코드!$B$2:$C$43,2,0),VLOOKUP($E$2,업종코드!$B$44:$C$96,2,0)) -> 001 | Q2: KOSDAQ | Z2: 종목명 | AA2: KOSPI | AC2: 일자 | AD2: 기관순매수금액 | AE2: 외국인합순매수금액 | AF2: 개인순매수금액 | AJ2: 코드 | AK2: 종목명
Z3: 코드 | AA3: 001 | AC3: 43738 | AJ3: 001 | AK3: KOSPI
B4: 현재시간 | C4: =NOW() -> 43738.341 | E4: =E2 -> KOSPI | F4: =_xll.IMDP("IDX",$N$2,"현재가") -> 2049.93 | Z4: 기관 | AA4: =_xll.IMDP("IDX",$N$2,"기관순매수금액") -> -175508 | AC4: 43737 | AD4: -175508 | AE4: -24902 | AF4: 199479 | AJ4: 211 | AK4: KOSPI200
B5: 시 작 일 | C5: =TODAY()-365 -> 43373 | E5: 거래대금 | F5: =_xll.IMDP("IDX",$N$2,"누적거래대금") -> 3489260 | Z5: 외국인합 | AA5: =_xll.IMDP("IDX",$N$2,"외국인합순매수금액") -> -24902 | AC5: 43736 | AD5: -175508 | AE5: -24902 | AF5: 199479 | AJ5: 005 | AK5: 음식료품
B6: 종 료 일 | C6: =TODAY() -> 43738 | E6: 시가총액(억원) | F6: =_xll.IMDP("IDX",$N$2,"시가총액")/100000000 -> 13707048 | O6: =IF($C$2="KOSPI",VLOOKUP($C$2,업종코드!A2:C2,2,0),VLOOKUP($C$2,업종코드!A44:C44,2,0)) -> KOSPI | P6: =IF(ISERROR(O6),"",O6) -> KOSPI | Z6: 개인 | AA6: =_xll.IMDP("IDX",$N$2,"개인순매수금액") -> 199479 | AC6: 43735 | AD6: -175508 | AE6: -24902 | AF6: 199479 | AJ6: 006 | AK6: 섬유.의복
B7: 데이터 갯수 | C7: 30 | E7: 상장종목수 | F7: =_xll.IMDP("IDX",$N$2,"상장종목수") -> 901 | O7: =IF($C$2="KOSPI",VLOOKUP($C$2,업종코드!A3:C3,2,0),VLOOKUP($C$2,업종코드!A45:C45,2,0)) -> KOSPI200 | P7: =IF(ISERROR(O7),"",O7) -> KOSPI200 | Z7: 증권/선물 | AA7: =_xll.IMDP("IDX",$N$2,"증권/선물순매수금액") -> -50180 | AC7: 43734 | AD7: -384837 | AE7: 315989 | AF7: 51753 | AJ7: 007 | AK7: 종이.목재
O8: =IF($C$2="KOSPI",VLOOKUP($C$2,업종코드!A4:C4,2,0),VLOOKUP($C$2,업종코드!A46:C46,2,0)) -> 음식료품 | P8: =IF(ISERROR(O8),"",O8) -> 음식료품 | Z8: 보험 | AA8: =_xll.IMDP("IDX",$N$2,"보험순매수금액") -> -45009 | AC8: 43733 | AD8: 129147 | AE8: -366056 | AF8: 222585 | AJ8: 008 | AK8: 화학
O9: =IF($C$2="KOSPI",VLOOKUP($C$2,업종코드!A5:C5,2,0),VLOOKUP($C$2,업종코드!A47:C47,2,0)) -> 섬유.의복 | P9: =IF(ISERROR(O9),"",O9) -> 섬유.의복 | Z9: 투신 | AA9: =_xll.IMDP("IDX",$N$2,"투신순매수금액") -> -11165 | AC9: 43732 | AD9: 377963 | AE9: -216240 | AF9: -162029 | AJ9: 009 | AK9: 의약품
B10: =$C$2&"/"&$E$2&""&" "&"당일 투자자 순매수 현황" -> KOSPI/KOSPI 당일 투자자 순매수 현황 | O10: =IF($C$2="KOSPI",VLOOKUP($C$2,업종코드!A6:C6,2,0),VLOOKUP($C$2,업종코드!A48:C48,2,0)) -> 종이.목재 | P10: =IF(ISERROR(O10),"",O10) -> 종이.목재 | Z10: 사모펀드 | AA10: =_xll.IMDP("IDX",$N$2,"사모펀드순매수금액") -> -31189 | AC10: 43731 | AD10: 83894 | AE10: -68884 | AF10: -22348 | AJ10: 010 | AK10: 비금속광물
O11: =IF($C$2="KOSPI",VLOOKUP($C$2,업종코드!A7:C7,2,0),VLOOKUP($C$2,업종코드!A49:C49,2,0)) -> 화학 | P11: =IF(ISERROR(O11),"",O11) -> 화학 | Z11: 은행 | AA11: =_xll.IMDP("IDX",$N$2,"은행순매수금액") -> 3127 | AC11: 43730 | AD11: 181592 | AE11: 44515 | AF11: -214725 | AJ11: 011 | AK11: 철강.금속
O12: =IF($C$2="KOSPI",VLOOKUP($C$2,업종코드!A8:C8,2,0),VLOOKUP($C$2,업종코드!A50:C50,2,0)) -> 의약품 | P12: =IF(ISERROR(O12),"",O12) -> 의약품 | Z12: 종신금 | AA12: =_xll.IMDP("IDX",$N$2,"종신금순매수금액") -> 996 | AC12: 43729 | AD12: 181592 | AE12: 44515 | AF12: -214725 | AJ12: 012 | AK12: 기계
O13: =IF($C$2="KOSPI",VLOOKUP($C$2,업종코드!A9:C9,2,0),VLOOKUP($C$2,업종코드!A51:C51,2,0)) -> 비금속광물 | P13: =IF(ISERROR(O13),"",O13) -> 비금속광물 | Z13: 연기금 | AA13: =_xll.IMDP("IDX",$N$2,"연기금순매수금액") -> -42088 | AC13: 43728 | AD13: 181592 | AE13: 44515 | AF13: -214725 | AJ13: 013 | AK13: 전기.전자
O14: =IF($C$2="KOSPI",VLOOKUP($C$2,업종코드!A10:C10,2,0),VLOOKUP($C$2,업종코드!A52:C52,2,0)) -> 철강.금속 | P14: =IF(ISERROR(O14),"",O14) -> 철강.금속 | Z14: 국가/지방 | AA14: =_xll.IMDP("IDX",$N$2,"국가/지방순매수금액") -> 0 | AC14: 43727 | AD14: -99307 | AE14: 218143 | AF14: -101076 | AJ14: 014 | AK14: 의료정밀
O15: =IF($C$2="KOSPI",VLOOKUP($C$2,업종코드!A11:C11,2,0),VLOOKUP($C$2,업종코드!A53:C53,2,0)) -> 기계 | P15: =IF(ISERROR(O15),"",O15) -> 기계 | Z15: 기타 | AA15: =_xll.IMDP("IDX",$N$2,"기타순매수금액") -> 930 | AC15: 43726 | AD15: 107449 | AE15: 55855 | AF15: -161556 | AJ15: 015 | AK15: 운수.장비
O16: =IF($C$2="KOSPI",VLOOKUP($C$2,업종코드!A12:C12,2,0),VLOOKUP($C$2,업종코드!A54:C54,2,0)) -> 전기.전자 | P16: =IF(ISERROR(O16),"",O16) -> 전기.전자 | Z16: 외국인 | AA16: =_xll.IMDP("IDX",$N$2,"외국인순매수금액") -> -24893 | AC16: 43725 | AD16: 96186 | AE16: -80499 | AF16: -31325 | AJ16: 016 | AK16: 유통업
O17: =IF($C$2="KOSPI",VLOOKUP($C$2,업종코드!A13:C13,2,0),VLOOKUP($C$2,업종코드!A55:C55,2,0)) -> 의료정밀 | P17: =IF(ISERROR(O17),"",O17) -> 의료정밀 | Z17: 외국인기타 | AA17: =_xll.IMDP("IDX",$N$2,"외인기타순매수금액") -> -9 | AC17: 43724 | AD17: 198209 | AE17: -160249 | AF17: -45666 | AJ17: 017 | AK17: 전기.가스업
O18: =IF($C$2="KOSPI",VLOOKUP($C$2,업종코드!A14:C14,2,0),VLOOKUP($C$2,업종코드!A56:C56,2,0)) -> 운수.장비 | P18: =IF(ISERROR(O18),"",O18) -> 운수.장비 | AC18: 43723 | AD18: 613450 | AE18: -283728 | AF18: -334423 | AJ18: 018 | AK18: 건설업
O19: =IF($C$2="KOSPI",VLOOKUP($C$2,업종코드!A15:C15,2,0),VLOOKUP($C$2,업종코드!A57:C57,2,0)) -> 유통업 | P19: =IF(ISERROR(O19),"",O19) -> 유통업 | AC19: 43722 | AD19: 613450 | AE19: -283728 | AF19: -334423 | AJ19: 019 | AK19: 운수.창고
O20: =IF($C$2="KOSPI",VLOOKUP($C$2,업종코드!A16:C16,2,0),VLOOKUP($C$2,업종코드!A58:C58,2,0)) -> 전기.가스업 | P20: =IF(ISERROR(O20),"",O20) -> 전기.가스업 | AC20: 43721 | AD20: 613450 | AE20: -283728 | AF20: -334423 | AJ20: 020 | AK20: 통신업
O21: =IF($C$2="KOSPI",VLOOKUP($C$2,업종코드!A17:C17,2,0),VLOOKUP($C$2,업종코드!A59:C59,2,0)) -> 건설업 | P21: =IF(ISERROR(O21),"",O21) -> 건설업 | AC21: 43720 | AD21: 613450 | AE21: -283728 | AF21: -334423 | AJ21: 021 | AK21: 금융업
O22: =IF($C$2="KOSPI",VLOOKUP($C$2,업종코드!A18:C18,2,0),VLOOKUP($C$2,업종코드!A60:C60,2,0)) -> 운수.창고 | P22: =IF(ISERROR(O22),"",O22) -> 운수.창고 | AC22: 43719 | AD22: 613450 | AE22: -283728 | AF22: -334423 | AJ22: 022 | AK22: 은행
O23: =IF($C$2="KOSPI",VLOOKUP($C$2,업종코드!A19:C19,2,0),VLOOKUP($C$2,업종코드!A61:C61,2,0)) -> 통신업 | P23: =IF(ISERROR(O23),"",O23) -> 통신업 | AC23: 43718 | AD23: 171306 | AE23: 14629 | AF23: -191938 | AJ23: 024 | AK23: 증권
O24: =IF($C$2="KOSPI",VLOOKUP($C$2,업종코드!A20:C20,2,0),VLOOKUP($C$2,업종코드!A62:C62,2,0)) -> 금융업 | P24: =IF(ISERROR(O24),"",O24) -> 금융업 | AC24: 43717 | AD24: -74669 | AE24: 233532 | AF24: -173011 | AJ24: 025 | AK24: 보험
O25: =IF($C$2="KOSPI",VLOOKUP($C$2,업종코드!A21:C21,2,0),VLOOKUP($C$2,업종코드!A63:C63,2,0)) -> 은행 | P25: =IF(ISERROR(O25),"",O25) -> 은행 | AC25: 43716 | AD25: -19924 | AE25: 48317 | AF25: -33834 | AJ25: 026 | AK25: 서비스업
O26: =IF($C$2="KOSPI",VLOOKUP($C$2,업종코드!A22:C22,2,0),VLOOKUP($C$2,업종코드!A64:C64,2,0)) -> 증권 | P26: =IF(ISERROR(O26),"",O26) -> 증권 | AC26: 43715 | AD26: -19924 | AE26: 48317 | AF26: -33834 | AJ26: 027 | AK26: 제조업
O27: =IF($C$2="KOSPI",VLOOKUP($C$2,업종코드!A23:C23,2,0),VLOOKUP($C$2,업종코드!A65:C65,2,0)) -> 보험 | P27: =IF(ISERROR(O27),"",O27) -> 보험 | AC27: 43714 | AD27: -19924 | AE27: 48317 | AF27: -33834 | AJ27: 201 | AK27: 대형주
O28: =IF($C$2="KOSPI",VLOOKUP($C$2,업종코드!A24:C24,2,0),VLOOKUP($C$2,업종코드!A66:C66,2,0)) -> 서비스업 | P28: =IF(ISERROR(O28),"",O28) -> 서비스업 | AC28: 43713 | AD28: 92946 | AE28: 188027 | AF28: -284403 | AJ28: 202 | AK28: 중형주
O29: =IF($C$2="KOSPI",VLOOKUP($C$2,업종코드!A25:C25,2,0),VLOOKUP($C$2,업종코드!A67:C67,2,0)) -> 제조업 | P29: =IF(ISERROR(O29),"",O29) -> 제조업 | AC29: 43712 | AD29: 482954 | AE29: -350240 | AF29: -149629 | AJ29: 203 | AK29: 소형주
... O32: =IF($C$2="KOSPI",VLOOKUP($C$2,업종코드!A28:C28,2,0),VLOOKUP($C$2,업종코드!A70:C70,2,0)) -> 소형주 | P32: =IF(ISERROR(O32),"",O32) -> 소형주 | AC32: 43709 | AD32: 165160 | AE32: 224313 | AF32: -398217 | AJ32: 214 | AK32: K철강소재
O33: =IF($C$2="KOSPI",VLOOKUP($C$2,업종코드!A29:C29,2,0),VLOOKUP($C$2,업종코드!A71:C71,2,0)) -> K건설기계 | P33: =IF(ISERROR(O33),"",O33) -> K건설기계 | AJ33: 215 | AK33: K에너지화학
O34: =IF($C$2="KOSPI",VLOOKUP($C$2,업종코드!A30:C30,2,0),VLOOKUP($C$2,업종코드!A72:C72,2,0)) -> K조선운송 | P34: =IF(ISERROR(O34),"",O34) -> K조선운송 | AJ34: 216 | AK34: K정보통신
O35: =IF($C$2="KOSPI",VLOOKUP($C$2,업종코드!A31:C31,2,0),VLOOKUP($C$2,업종코드!A73:C73,2,0)) -> K철강소재 | P35: =IF(ISERROR(O35),"",O35) -> K철강소재 | AJ35: 217 | AK35: K금융
B36: =$C$2&"/"&$E$2&""&" "&"투자자 순매수 추이" -> KOSPI/KOSPI 투자자 순매수 추이 | O36: =IF($C$2="KOSPI",VLOOKUP($C$2,업종코드!A32:C32,2,0),VLOOKUP($C$2,업종코드!A74:C74,2,0)) -> K에너지화학 | P36: =IF(ISERROR(O36),"",O36) -> K에너지화학 | AJ36: 218 | AK36: K필수소비재
O37: =IF($C$2="KOSPI",VLOOKUP($C$2,업종코드!A33:C33,2,0),VLOOKUP($C$2,업종코드!A75:C75,2,0)) -> K정보통신 | P37: =IF(ISERROR(O37),"",O37) -> K정보통신 | AJ37: 219 | AK37: K자유소비재
O38: =IF($C$2="KOSPI",VLOOKUP($C$2,업종코드!A34:C34,2,0),VLOOKUP($C$2,업종코드!A76:C76,2,0)) -> K금융 | P38: =IF(ISERROR(O38),"",O38) -> K금융 | AJ38: 221 | AK38: KOSPI100
O39: =IF($C$2="KOSPI",VLOOKUP($C$2,업종코드!A35:C35,2,0),VLOOKUP($C$2,업종코드!A77:C77,2,0)) -> K필수소비재 | P39: =IF(ISERROR(O39),"",O39) -> K필수소비재 | AJ39: 222 | AK39: KOSPI50
O40: =IF($C$2="KOSPI",VLOOKUP($C$2,업종코드!A36:C36,2,0),VLOOKUP($C$2,업종코드!A78:C78,2,0)) -> K자유소비재 | P40: =IF(ISERROR(O40),"",O40) -> K자유소비재 | AJ40: 231 | AK40: KODI
O41: =IF($C$2="KOSPI",VLOOKUP($C$2,업종코드!A37:C37,2,0),VLOOKUP($C$2,업종코드!A79:C79,2,0)) -> KOSPI100 | P41: =IF(ISERROR(O41),"",O41) -> KOSPI100 | AJ41: 232 | AK41: 지배구조지수
O42: =IF($C$2="KOSPI",VLOOKUP($C$2,업종코드!A38:C38,2,0),VLOOKUP($C$2,업종코드!A80:C80,2,0)) -> KOSPI50 | P42: =IF(ISERROR(O42),"",O42) -> KOSPI50 | AJ42: 233 | AK42: 사회책임투자지수
...

Sheet 업종코드
A1: 업종 | B1: 종목명 | C1: 코드 | D1: 업종 | E1: 종목명 | F1: 코드
A2: KOSPI | B2: KOSPI | C2: 001 | D2: KOSDAQ | E2: KOSDAQ | F2: 801
A3: KOSPI | B3: KOSPI200 | C3: 211 | D3: KOSDAQ | E3: 우량기업부 | F3: 802
A4: KOSPI | B4: 음식료품 | C4: 005 | D4: KOSDAQ | E4: 벤처기업부 | F4: 803
A5: KOSPI | B5: 섬유.의복 | C5: 006 | D5: KOSDAQ | E5: 중견기업부 | F5: 804
A6: KOSPI | B6: 종이.목재 | C6: 007 | D6: KOSDAQ | E6: 기술성장기업부 | F6: 805
A7: KOSPI | B7: 화학 | C7: 008 | D7: KOSDAQ | E7: 기타서비스 | F7: 812
A8: KOSPI | B8: 의약품 | C8: 009 | D8: KOSDAQ | E8: IT종합 | F8: 815
A9: KOSPI | B9: 비금속광물 | C9: 010 | D9: KOSDAQ | E9: 제조 | F9: 824
A10: KOSPI | B10: 철강.금속 | C10: 011 | D10: KOSDAQ | E10: 건설 | F10: 826
A11: KOSPI | B11: 기계 | C11: 012 | D11: KOSDAQ | E11: 유통 | F11: 827
A12: KOSPI | B12: 전기.전자 | C12: 013 | D12: KOSDAQ | E12: 운송 | F12: 829
... A54: KOSDAQ | B54: 운송 | C54: 829 | D54: KOSDAQ | E54: 우선주 지수 | F54: 455
A55: KOSDAQ | B55: 금융 | C55: 831
A56: KOSDAQ | B56: 오락문화 | C56: 837
A57: KOSDAQ | B57: 통신방송 | C57: 841
A58: KOSDAQ | B58: IT S/W | C58: 842
A59: KOSDAQ | B59: IT H/W | C59: 843
A60: KOSDAQ | B60: 음식.담배 | C60: 856
A61: KOSDAQ | B61: 섬유.의류 | C61: 858
A62: KOSDAQ | B62: 종이.목재 | C62: 862
A63: KOSDAQ | B63: 출판.매체 | C63: 863
A64: KOSDAQ | B64: 화학 | C64: 865
A65: KOSDAQ | B65: 제약 | C65: 866
A66: KOSDAQ | B66: 비금속 | C66: 867
... A96: KOSDAQ | B96: 우선주 지수 | C96: 455

Sheet 도움말
